weight=7
dimensionsToSpawnIn=overworld
embed_into_distance=2
random_height_offset=0,0
unacceptable_target_blocks=flowing_water,water,flowing_lava,lava,ice,packed_ice,stained_hardened_clay-9,brick_block,double_stone_slab,stonebrick,red_sandstone,red_nether_brick,red_mushroom_block,brown_mushroom_block,planks,cobblestone,end_stone,obsidian,purpur_block,iron_bars,purpur_slab,purpur_pillar,netherrack,soul_sand,quartz_ore,stained_glass,glass
dimensions=18,19,12
allowable_overhang=0
max_leveling=2
leveling_buffer=-1
preventRotation=0
preserve_water=0
preserve_lava=0
uniqueMinDistance=3000
spawnMinDistance=0
spawnMaxDistance=0

adjoining_template=templateparser/Airfield1;0;10;14
adjoining_template=templateparser/Airfield1;2;10;14
adjoining_template=templateparser/Airfield1;4;10;14
adjoining_template=templateparser/Airfield1;6;10;14
adjoining_template=templateparser/Airfield1;8;10;14
adjoining_template=templateparser/Airfield1;10;10;14
adjoining_template=templateparser/Airfield1;12;10;14
adjoining_template=templateparser/Airfield1;14;10;14
adjoining_template=templateparser/Airfield1;16;10;14
adjoining_template=templateparser/Airfield1;18;10;14
adjoining_template=templateparser/Airfield1;20;10;14
adjoining_template=templateparser/Airfield1;22;10;14
adjoining_template=templateparser/Airfield1;22;10;14
adjoining_template=templateparser/Airfield1;24;10;14
adjoining_template=templateparser/Airfield1;26;10;14
adjoining_template=templateparser/Airfield1;28;10;14
adjoining_template=templateparser/Airfield1;-2;10;14
adjoining_template=templateparser/Airfield1;-4;10;14
adjoining_template=templateparser/Airfield1;-6;10;14
adjoining_template=templateparser/Airfield1;-8;10;14
adjoining_template=templateparser/Airfield1;-10;10;14
adjoining_template=templateparser/Airfield1;-12;10;14
adjoining_template=templateparser/Airfield1;-14;10;14
adjoining_template=templateparser/Airfield1;-16;10;14
adjoining_template=templateparser/Airfield1;-18;10;14
adjoining_template=templateparser/Airfield1;-20;10;14
adjoining_template=templateparser/Airfield1;-22;10;14
adjoining_template=templateparser/Airfield1;-24;10;14
adjoining_template=templateparser/Airfield1;-26;10;14
adjoining_template=templateparser/Airfield1;-28;10;14


rule1=0,100,preserveBlock
rule2=0,100,minecraft:cobblestone-0,minecraft:cobblestone-0,minecraft:cobblestone-0,minecraft:mossy_cobblestone-0
rule3=0,100,chisel:diorite1-11
rule4=0,100,minecraft:cobblestone_wall-0,minecraft:cobblestone_wall-0,minecraft:cobblestone_wall-1
rule5=0,100,chisel:planks-oak-7
rule6=0,100,minecraft:oak_stairs-7
rule7=0,100,minecraft:oak_stairs-1
rule8=0,100,minecraft:iron_bars-0
rule9=0,100,minecraft:wooden_door-2
rule10=0,100,minecraft:double_stone_slab-0
rule11=0,100,chisel:bookshelf_oak-9
rule12=0,100,minecraft:wooden_door-3
rule13=0,100,minecraft:wooden_door-1
rule14=0,100,minecraft:stone_brick_stairs-7
rule15=0,100,minecraft:stone_brick_stairs-6
rule16=0,100,ChestGenHook:chests/woodland_mansion:9-3
rule17=0,100,minecraft:bed-9
rule18=0,100,minecraft:bed-1
rule19=0,100,minecraft:vine-8
rule20=0,100,minecraft:vine-1
rule21=0,100,minecraft:oak_stairs-2
rule22=0,100,minecraft:oak_stairs-5
rule23=0,100,minecraft:wooden_door-8
rule24=0,100,chisel:planks-oak-7
rule25=0,100,minecraft:vine-4
rule26=2,100,minecraft:stone_button-4
rule27=0,100,minecraft:stained_glass_pane-7
rule28=0,100,minecraft:flower_pot-0
rule29=0,100,minecraft:vine-2
rule30=0,100,minecraft:stained_hardened_clay-9
rule31=0,100,minecraft:oak_stairs-0
rule32=0,100,minecraft:oak_stairs-6
rule33=0,100,minecraft:stone_slab-8
rule34=0,100,minecraft:double_stone_slab-8
rule35=0,100,minecraft:stonebrick-0
rule36=0,100,minecraft:stone_slab-13
rule37=0,100,minecraft:oak_stairs-4
rule38=0,100,minecraft:oak_stairs-3
rule39=0,100,minecraft:stone_slab-0
rule40=0,100,minecraft:stone_slab-5
rule41=0,100,chisel:technical-2
rule42=0,100,minecraft:ladder-5
rule43=0,100,minecraft:dark_oak_fence-0
rule44=0,100,chisel:factory-7
rule45=0,100,chisel:laboratory-0
rule46=0,100,minecraft:acacia_door-3
rule47=0,100,minecraft:stained_glass-7
rule48=0,100,minecraft:lever-5
rule49=0,100,chisel:futura-1
rule50=0,100,minecraft:acacia_door-8
rule51=0,100,minecraft:redstone_lamp-0

layer
1,1,1,1,1,1,1,1,1,1,1,1
1,1,1,1,1,1,1,1,1,1,1,1
1,1,1,1,1,2,2,2,2,2,1,1
1,1,1,1,1,2,3,3,3,2,1,1
1,1,1,1,1,2,3,3,3,2,1,1
1,1,1,1,1,2,3,3,3,2,1,1
1,1,1,1,1,2,2,3,2,2,1,1
1,2,2,2,2,2,2,3,2,1,1,1
1,2,3,3,3,3,3,3,2,1,1,1
1,2,3,3,3,3,3,3,2,1,1,1
1,2,3,3,3,3,3,3,2,1,1,1
1,2,3,3,3,3,3,3,2,1,1,1
1,2,3,3,3,3,3,3,2,1,1,1
1,2,3,3,3,3,3,3,2,1,1,1
1,2,3,3,3,3,3,3,2,1,1,1
1,2,3,3,3,3,3,3,2,1,1,1
1,2,3,3,3,3,3,3,2,1,1,1
1,2,2,2,2,2,2,2,2,1,1,1
1,1,1,1,1,1,1,1,1,1,1,1
endlayer

layer
1,1,1,1,1,1,1,1,1,1,1,1
1,1,1,1,1,1,1,1,1,1,1,1
1,1,1,1,1,2,2,2,2,2,1,1
1,1,1,1,1,2,3,3,3,2,1,1
1,1,1,1,1,2,3,3,3,2,1,1
1,1,1,1,1,2,3,3,3,2,1,1
1,1,1,1,1,2,2,3,2,2,1,1
1,2,2,2,2,2,2,3,2,1,1,1
1,2,3,3,3,3,3,3,2,1,1,1
1,2,3,3,3,3,3,3,2,1,1,1
1,2,3,3,3,3,3,3,2,1,1,1
1,2,3,3,3,3,3,3,2,1,1,1
1,2,3,3,3,3,3,3,2,1,1,1
1,2,3,3,3,3,3,3,2,1,1,1
1,2,3,3,3,3,3,3,2,1,1,1
1,2,3,3,3,3,3,3,2,1,1,1
1,2,3,3,3,3,3,3,2,1,1,1
1,2,2,2,2,2,2,2,2,1,1,1
1,1,1,1,1,1,1,1,1,1,1,1
endlayer

layer
1,1,1,1,1,1,1,1,1,1,1,1
1,1,1,1,1,1,1,1,1,1,1,1
1,1,1,1,1,4,2,2,2,4,1,1
1,1,1,1,1,2,1,6,5,2,1,1
1,1,1,1,1,2,1,8,7,2,1,1
1,1,1,1,1,2,1,1,1,2,1,1
1,1,1,1,1,4,2,9,2,4,1,1
1,2,2,2,2,2,2,1,2,1,1,1
1,2,11,1,1,10,1,1,2,1,1,1
1,2,1,1,1,10,1,1,12,1,1,1
1,2,7,1,1,13,1,1,2,1,1,1
1,2,15,14,1,10,1,1,2,1,1,1
1,2,10,10,10,10,1,1,2,1,1,1
1,2,17,1,16,10,1,1,2,1,1,1
1,2,18,1,1,10,1,1,2,1,1,1
1,2,1,1,1,13,1,1,2,1,1,1
1,2,11,1,11,10,1,1,2,1,1,1
1,2,2,2,2,2,2,2,2,1,1,1
1,1,1,1,1,1,1,1,1,1,1,1
endlayer

layer
1,1,1,1,1,1,1,1,1,1,1,1
1,1,1,1,1,1,1,19,1,1,1,1
1,1,1,1,1,4,2,2,2,4,1,1
1,1,1,1,1,2,5,21,1,2,20,1
1,1,1,1,1,2,22,8,1,2,1,1
1,1,1,1,1,2,1,1,1,2,1,1
1,1,1,19,19,4,2,23,2,4,1,1
25,24,24,24,24,24,24,1,24,1,1,1
1,24,11,1,1,5,1,1,24,26,1,1
1,24,1,1,1,5,1,1,23,1,1,1
25,24,1,1,1,23,1,1,24,26,1,1
1,24,1,28,1,5,1,1,27,1,1,1
1,24,5,5,5,5,1,1,27,1,1,1
1,24,1,1,1,5,1,1,24,26,1,1
1,24,1,1,1,5,1,1,24,26,1,1
25,24,1,1,1,23,1,1,27,1,1,1
25,24,11,1,11,5,1,1,27,1,1,1
1,24,24,24,24,24,24,24,24,26,1,1
1,1,1,1,29,1,1,1,29,1,1,1
endlayer

layer
1,1,1,1,1,1,1,1,1,1,1,1
1,1,1,1,1,1,19,19,1,1,1,1
1,1,1,1,1,4,30,30,30,4,1,1
1,1,1,1,1,30,1,1,1,30,20,1
1,1,1,1,25,30,31,8,1,30,1,1
1,1,1,1,1,30,5,32,1,30,1,1
34,34,33,33,19,4,30,30,30,4,1,1
14,35,24,24,24,24,24,24,24,1,1,1
14,35,36,1,1,5,1,1,24,20,1,1
34,34,33,1,1,5,1,1,32,1,1,1
14,35,36,1,1,5,1,1,24,20,1,1
14,35,36,1,1,5,1,1,27,1,1,1
34,34,5,5,5,5,1,1,27,1,1,1
14,35,36,1,1,5,1,1,24,1,1,1
14,35,36,1,1,5,1,1,24,20,1,1
34,34,33,1,1,5,1,1,27,1,1,1
14,35,36,1,1,5,1,1,27,1,1,1
14,35,24,24,24,24,24,24,24,20,1,1
34,34,33,33,29,1,29,1,29,1,1,1
endlayer

layer
1,1,1,1,1,1,1,1,1,1,1,1
1,1,1,1,1,1,1,19,1,1,1,1
1,1,1,1,1,4,30,30,30,4,1,1
1,1,1,1,1,30,1,1,1,30,20,1
1,1,1,1,25,30,1,8,37,30,1,1
1,1,1,1,1,30,1,38,5,30,1,1
1,1,39,39,34,34,30,30,30,4,1,1
1,1,40,40,35,35,24,24,24,1,1,1
1,1,40,40,35,35,36,1,24,20,1,1
1,1,39,39,34,34,33,1,24,1,1,1
1,1,40,40,35,35,36,1,24,20,1,1
1,1,40,40,35,35,36,1,32,1,1,1
1,1,39,39,34,34,33,1,32,1,1,1
1,1,40,40,35,35,36,1,24,1,1,1
1,1,40,40,35,35,36,1,24,20,1,1
1,1,39,39,34,34,33,1,32,1,1,1
1,1,40,40,35,35,36,1,32,1,1,1
1,1,40,40,35,35,24,24,24,1,1,1
1,1,39,39,34,34,33,33,1,1,1,1
endlayer

layer
1,1,1,1,1,1,1,1,1,1,1,1
1,1,1,1,1,1,1,19,19,1,1,1
1,1,1,1,1,4,30,30,30,4,1,1
1,1,1,1,25,30,1,6,5,30,1,1
1,1,1,1,1,30,1,8,7,30,1,1
1,1,1,1,1,30,1,1,1,30,1,1
1,1,1,1,1,4,30,30,30,34,1,1
1,1,1,1,1,1,40,40,35,15,1,1
1,1,1,1,1,1,40,40,35,15,1,1
1,1,1,1,1,1,39,39,34,34,1,1
1,1,1,1,1,1,40,40,35,15,1,1
1,1,1,1,1,1,40,40,35,15,1,1
1,1,1,1,1,1,39,39,34,34,1,1
1,1,1,1,1,1,40,40,35,15,1,1
1,1,1,1,1,1,40,40,35,15,1,1
1,1,1,1,1,1,39,39,34,34,1,1
1,1,1,1,1,1,40,40,35,15,1,1
1,1,1,1,1,1,40,40,35,15,1,1
1,1,1,1,1,1,39,39,34,34,1,1
endlayer

layer
1,1,1,1,1,1,1,1,1,1,1,1
1,1,1,1,1,1,19,19,1,1,1,1
1,1,1,1,1,4,30,41,30,4,1,1
1,1,1,1,25,30,5,21,1,30,1,1
1,1,1,1,1,41,1,8,1,41,1,1
1,1,1,1,1,30,1,1,1,30,20,1
1,1,1,1,1,4,30,41,30,4,1,1
1,1,1,1,1,1,1,1,1,1,1,1
1,1,1,1,1,1,1,1,1,1,1,1
1,1,1,1,1,1,1,1,1,1,1,1
1,1,1,1,1,1,1,1,1,1,1,1
1,1,1,1,1,1,1,1,1,1,1,1
1,1,1,1,1,1,1,1,1,1,1,1
1,1,1,1,1,1,1,1,1,1,1,1
1,1,1,1,1,1,1,1,1,1,1,1
1,1,1,1,1,1,1,1,1,1,1,1
1,1,1,1,1,1,1,1,1,1,1,1
1,1,1,1,1,1,1,1,1,1,1,1
1,1,1,1,1,1,1,1,1,1,1,1
endlayer

layer
1,1,1,1,1,1,1,1,1,1,1,1
1,1,1,1,1,1,19,19,1,1,1,1
1,1,1,1,1,4,30,30,30,4,1,1
1,1,1,1,1,30,42,1,1,30,1,1
1,1,1,1,1,30,1,8,1,30,1,1
1,1,1,1,25,30,1,1,1,30,20,1
1,1,1,1,1,4,30,30,30,4,1,1
1,1,1,1,1,1,1,1,1,1,1,1
1,1,1,1,1,1,1,1,1,1,1,1
1,1,1,1,1,1,1,1,1,1,1,1
1,1,1,1,1,1,1,1,1,1,1,1
1,1,1,1,1,1,1,1,1,1,1,1
1,1,1,1,1,1,1,1,1,1,1,1
1,1,1,1,1,1,1,1,1,1,1,1
1,1,1,1,1,1,1,1,1,1,1,1
1,1,1,1,1,1,1,1,1,1,1,1
1,1,1,1,1,1,1,1,1,1,1,1
1,1,1,1,1,1,1,1,1,1,1,1
1,1,1,1,1,1,1,1,1,1,1,1
endlayer

layer
1,1,1,1,1,1,1,1,1,1,1,1
1,1,1,1,1,1,19,19,1,1,1,1
1,1,1,1,1,4,30,41,30,4,1,1
1,1,1,1,1,30,42,1,1,30,1,1
1,1,1,1,1,41,1,8,1,41,1,1
1,1,1,1,25,30,1,1,1,30,20,1
1,1,1,1,1,4,30,41,30,4,1,1
1,1,1,1,1,1,1,29,1,1,1,1
1,1,1,1,1,1,1,1,1,1,1,1
1,1,1,1,1,1,1,1,1,1,1,1
1,1,1,1,1,1,1,1,1,1,1,1
1,1,1,1,1,1,1,1,1,1,1,1
1,1,1,1,1,1,1,1,1,1,1,1
1,1,1,1,1,1,1,1,1,1,1,1
1,1,1,1,1,1,1,1,1,1,1,1
1,1,1,1,1,1,1,1,1,1,1,1
1,1,1,1,1,1,1,1,1,1,1,1
1,1,1,1,1,1,1,1,1,1,1,1
1,1,1,1,1,1,1,1,1,1,1,1
endlayer

layer
1,1,1,1,1,1,4,1,4,1,1,1
1,1,1,1,1,33,34,33,34,33,1,1
1,1,1,1,33,33,35,35,35,33,33,1
1,1,1,4,34,35,42,34,34,35,34,4
1,1,1,1,33,35,34,34,34,35,33,1
1,1,1,4,34,35,34,34,34,35,34,4
1,1,1,1,33,33,35,35,35,33,33,1
1,1,1,1,1,33,34,33,34,33,1,1
1,1,1,1,1,1,4,1,4,1,1,1
1,1,1,1,1,1,1,1,1,1,1,1
1,1,1,1,1,1,1,1,1,1,1,1
1,1,1,1,1,1,1,1,1,1,1,1
1,1,1,1,1,1,1,1,1,1,1,1
1,1,1,1,1,1,1,1,1,1,1,1
1,1,1,1,1,1,1,1,1,1,1,1
1,1,1,1,1,1,1,1,1,1,1,1
1,1,1,1,1,1,1,1,1,1,1,1
1,1,1,1,1,1,1,1,1,1,1,1
1,1,1,1,1,1,1,1,1,1,1,1
endlayer

layer
1,1,1,1,8,8,8,8,8,8,8,1
1,1,1,8,8,1,1,1,1,1,8,8
1,1,1,8,1,43,30,30,30,43,1,8
1,1,1,8,25,30,1,1,45,30,1,8
1,1,1,8,1,46,1,21,45,30,20,8
1,1,1,8,1,30,1,1,45,30,1,8
1,1,1,8,1,43,30,30,30,43,1,8
1,1,1,8,8,1,1,1,1,1,8,8
1,1,1,1,8,8,8,8,8,8,8,1
1,1,1,1,1,1,1,1,1,1,1,1
1,1,1,1,1,1,1,1,1,1,1,1
1,1,1,1,1,1,1,1,1,1,1,1
1,1,1,1,1,1,1,1,1,1,1,1
1,1,1,1,1,1,1,1,1,1,1,1
1,1,1,1,1,1,1,1,1,1,1,1
1,1,1,1,1,1,1,1,1,1,1,1
1,1,1,1,1,1,1,1,1,1,1,1
1,1,1,1,1,1,1,1,1,1,1,1
1,1,1,1,1,1,1,1,1,1,1,1
endlayer

layer
1,1,1,1,1,1,1,1,1,1,1,1
1,1,1,1,1,1,1,1,1,1,1,1
1,1,1,1,1,43,47,47,47,43,1,1
1,1,1,1,1,47,1,1,48,47,1,1
1,1,1,1,1,50,1,1,49,47,1,1
1,1,1,1,1,47,1,1,48,47,1,1
1,1,1,1,1,43,47,47,47,43,1,1
1,1,1,1,1,1,1,1,1,1,1,1
1,1,1,1,1,1,1,1,1,1,1,1
1,1,1,1,1,1,1,1,1,1,1,1
1,1,1,1,1,1,1,1,1,1,1,1
1,1,1,1,1,1,1,1,1,1,1,1
1,1,1,1,1,1,1,1,1,1,1,1
1,1,1,1,1,1,1,1,1,1,1,1
1,1,1,1,1,1,1,1,1,1,1,1
1,1,1,1,1,1,1,1,1,1,1,1
1,1,1,1,1,1,1,1,1,1,1,1
1,1,1,1,1,1,1,1,1,1,1,1
1,1,1,1,1,1,1,1,1,1,1,1
endlayer

layer
1,1,1,1,1,1,1,1,1,1,1,1
1,1,1,1,1,1,1,1,1,1,1,1
1,1,1,1,1,43,47,47,47,43,1,1
1,1,1,1,1,47,1,1,1,47,1,1
1,1,1,1,1,47,1,1,1,47,1,1
1,1,1,1,1,47,1,1,1,47,1,1
1,1,1,1,1,43,47,47,47,43,1,1
1,1,1,1,1,1,1,1,1,1,1,1
1,1,1,1,1,1,1,1,1,1,1,1
1,1,1,1,1,1,1,1,1,1,1,1
1,1,1,1,1,1,1,1,1,1,1,1
1,1,1,1,1,1,1,1,1,1,1,1
1,1,1,1,1,1,1,1,1,1,1,1
1,1,1,1,1,1,1,1,1,1,1,1
1,1,1,1,1,1,1,1,1,1,1,1
1,1,1,1,1,1,1,1,1,1,1,1
1,1,1,1,1,1,1,1,1,1,1,1
1,1,1,1,1,1,1,1,1,1,1,1
1,1,1,1,1,1,1,1,1,1,1,1
endlayer

layer
1,1,1,1,1,1,1,1,1,1,1,1
1,1,1,1,1,1,40,40,40,1,1,1
1,1,1,1,1,40,44,44,44,40,1,1
1,1,1,1,40,44,2,2,2,44,40,1
1,1,1,1,40,44,2,51,2,44,40,1
1,1,1,1,40,44,2,2,2,44,40,1
1,1,1,1,1,40,44,44,44,40,1,1
1,1,1,1,1,1,40,40,40,1,1,1
1,1,1,1,1,1,1,1,1,1,1,1
1,1,1,1,1,1,1,1,1,1,1,1
1,1,1,1,1,1,1,1,1,1,1,1
1,1,1,1,1,1,1,1,1,1,1,1
1,1,1,1,1,1,1,1,1,1,1,1
1,1,1,1,1,1,1,1,1,1,1,1
1,1,1,1,1,1,1,1,1,1,1,1
1,1,1,1,1,1,1,1,1,1,1,1
1,1,1,1,1,1,1,1,1,1,1,1
1,1,1,1,1,1,1,1,1,1,1,1
1,1,1,1,1,1,1,1,1,1,1,1
endlayer

layer
1,1,1,1,1,1,1,1,1,1,1,1
1,1,1,1,1,1,1,1,1,1,1,1
1,1,1,1,1,1,39,39,39,1,1,1
1,1,1,1,1,39,43,1,43,39,1,1
1,1,1,1,1,39,1,4,1,39,1,1
1,1,1,1,1,39,43,1,43,39,1,1
1,1,1,1,1,1,39,39,39,1,1,1
1,1,1,1,1,1,1,1,1,1,1,1
1,1,1,1,1,1,1,1,1,1,1,1
1,1,1,1,1,1,1,1,1,1,1,1
1,1,1,1,1,1,1,1,1,1,1,1
1,1,1,1,1,1,1,1,1,1,1,1
1,1,1,1,1,1,1,1,1,1,1,1
1,1,1,1,1,1,1,1,1,1,1,1
1,1,1,1,1,1,1,1,1,1,1,1
1,1,1,1,1,1,1,1,1,1,1,1
1,1,1,1,1,1,1,1,1,1,1,1
1,1,1,1,1,1,1,1,1,1,1,1
1,1,1,1,1,1,1,1,1,1,1,1
endlayer

layer
1,1,1,1,1,1,1,1,1,1,1,1
1,1,1,1,1,1,1,1,1,1,1,1
1,1,1,1,1,1,1,1,1,1,1,1
1,1,1,1,1,1,8,1,1,1,1,1
1,1,1,1,1,1,1,43,43,1,1,1
1,1,1,1,1,1,8,1,1,1,1,1
1,1,1,1,1,1,1,1,1,1,1,1
1,1,1,1,1,1,1,1,1,1,1,1
1,1,1,1,1,1,1,1,1,1,1,1
1,1,1,1,1,1,1,1,1,1,1,1
1,1,1,1,1,1,1,1,1,1,1,1
1,1,1,1,1,1,1,1,1,1,1,1
1,1,1,1,1,1,1,1,1,1,1,1
1,1,1,1,1,1,1,1,1,1,1,1
1,1,1,1,1,1,1,1,1,1,1,1
1,1,1,1,1,1,1,1,1,1,1,1
1,1,1,1,1,1,1,1,1,1,1,1
1,1,1,1,1,1,1,1,1,1,1,1
1,1,1,1,1,1,1,1,1,1,1,1
endlayer

layer
1,1,1,1,1,1,1,1,1,1,1,1
1,1,1,1,1,1,1,1,1,1,1,1
1,1,1,1,1,1,1,1,1,1,1,1
1,1,1,1,1,1,1,8,8,1,1,1
1,1,1,1,1,1,1,8,1,1,1,1
1,1,1,1,1,1,1,8,8,1,1,1
1,1,1,1,1,1,1,1,1,1,1,1
1,1,1,1,1,1,1,1,1,1,1,1
1,1,1,1,1,1,1,1,1,1,1,1
1,1,1,1,1,1,1,1,1,1,1,1
1,1,1,1,1,1,1,1,1,1,1,1
1,1,1,1,1,1,1,1,1,1,1,1
1,1,1,1,1,1,1,1,1,1,1,1
1,1,1,1,1,1,1,1,1,1,1,1
1,1,1,1,1,1,1,1,1,1,1,1
1,1,1,1,1,1,1,1,1,1,1,1
1,1,1,1,1,1,1,1,1,1,1,1
1,1,1,1,1,1,1,1,1,1,1,1
1,1,1,1,1,1,1,1,1,1,1,1
endlayer

