weight=7
dimensionsToSpawnIn=overworld
embed_into_distance=1
random_height_offset=0,0
unacceptable_target_blocks=sand,flowing_water,water,flowing_lava,lava,ice,packed_ice,stained_hardened_clay-9,brick_block,double_stone_slab,stonebrick,red_sandstone,red_nether_brick,red_mushroom_block,brown_mushroom_block,planks,cobblestone,end_stone,obsidian,purpur_block,iron_bars,purpur_slab,purpur_pillar,netherrack,soul_sand,quartz_ore,stained_glass,glass
dimensions=7,11,14
allowable_overhang=0
max_leveling=1
leveling_buffer=-1
preventRotation=0
preserve_water=0
preserve_lava=0
preserve_plants=0
uniqueMinDistance=0
spawnMinDistance=0
spawnMaxDistance=0

rule1=0,100,minecraft:preserveBlock
rule2=0,100,minecraft:monster_egg-4,monster_egg-2,monster_egg-2,monster_egg-2,monster_egg-3,stonebrick-2,stonebrick-1,stonebrick-0,stonebrick-0,stonebrick-0
rule3=0,100,minecraft:stone_slab-5
rule4=0,100,minecraft:wooden_slab-0
rule5=0,100,MobSpawner:Zombie,MobSpawner:Silverfish,MobSpawner:Cave_Spider,air,air
rule6=0,100,minecraft:vine-4
rule7=0,100,minecraft:vine-8
rule8=0,100,minecraft:vine-1
rule9=0,100,minecraft:brick_block,minecraft:brick_block,minecraft:brick_block,minecraft:brick_block,minecraft:brick_block,minecraft:brick_stairs-0,minecraft:brick_stairs-1,minecraft:brick_stairs-2,minecraft:brick_stairs-3,minecraft:brick_stairs-4,minecraft:brick_stairs-5,minecraft:brick_stairs-6,minecraft:brick_stairs-7,minecraft:brick_stairs-8
rule10=0,100,minecraft:brick_stairs-3
rule11=0,100,minecraft:brick_stairs-2
rule12=0,100,minecraft:vine-2
rule13=0,100,minecraft:vine-3
rule14=0,100,minecraft:vine-9
rule15=0,100,minecraft:brick_stairs-7
rule16=0,100,minecraft:stone_slab-12
rule17=0,100,minecraft:brick_stairs-6
rule18=0,100,minecraft:oak_stairs-0
rule19=0,100,minecraft:fence-0
rule20=0,100,minecraft:oak_stairs-1
rule21=0,100,minecraft:wooden_slab-8
rule22=0,100,air

layer
1,1,1,1,1,1,1,1,1,1,1,1,1,1
1,2,2,2,2,2,2,3,3,3,2,2,2,1
1,2,4,4,4,4,4,4,4,4,4,4,3,1
1,2,4,4,4,4,4,4,4,4,4,4,3,1
1,2,4,4,4,4,4,4,4,4,4,4,2,1
1,2,4,4,5,22,22,4,4,4,4,4,2,1
1,2,4,4,22,22,22,22,4,4,1,6,2,1
1,2,4,4,22,22,22,22,22,22,22,22,3,1
1,2,4,4,7,7,7,7,22,7,7,7,2,1
1,2,2,2,2,2,2,2,2,2,2,2,2,1
1,1,1,1,1,1,1,1,1,1,1,1,1,1
endlayer

layer
1,22,7,22,22,22,22,22,22,22,22,22,7,1
6,9,9,2,9,11,22,22,22,22,22,10,9,8
6,9,13,12,12,22,22,22,22,22,22,6,22,8
6,9,8,22,22,22,22,22,22,22,22,22,22,22
6,9,8,22,22,22,22,22,22,22,22,6,9,8
0,9,8,22,22,22,22,22,22,22,22,6,9,8
6,9,22,22,22,22,22,22,22,22,22,6,9,8
6,9,8,22,22,22,22,22,22,22,22,22,22,8
6,9,14,7,7,7,7,7,22,7,7,7,22,8
22,9,9,9,9,9,9,9,9,9,9,9,9,22
1,12,12,12,12,12,12,12,12,12,12,12,12,1
endlayer

layer
1,7,7,7,7,22,22,22,22,22,22,7,7,1
6,9,9,2,9,11,22,22,22,22,22,9,9,8
6,9,13,12,22,22,22,22,22,22,22,6,22,8
0,9,8,22,22,22,22,22,22,22,22,22,22,22
6,9,8,22,22,22,22,22,22,22,22,6,9,8
6,9,8,22,22,22,22,22,22,22,22,6,9,8
6,9,8,22,22,22,22,22,22,22,22,6,9,8
6,9,8,22,22,22,22,22,22,22,22,22,22,8
6,9,8,7,7,7,7,7,22,7,7,7,22,8
22,9,9,9,9,9,9,9,9,9,9,9,9,8
1,12,12,12,12,12,12,12,12,12,12,12,12,1
endlayer

layer
0,7,7,0,7,0,0,0,0,0,0,0,7,0
6,9,9,16,9,9,9,16,16,16,16,15,9,8
6,9,12,0,0,0,0,0,0,0,0,6,9,8
6,9,8,0,0,0,0,0,0,0,0,0,9,0
6,9,8,0,0,0,0,0,0,0,0,6,9,0
0,9,0,0,0,0,0,0,0,0,0,0,9,8
6,9,8,0,0,0,0,0,0,0,0,6,9,8
6,9,8,0,0,0,0,0,0,0,0,0,9,8
6,9,8,7,0,7,0,0,0,0,7,7,9,8
6,9,9,9,16,9,17,15,9,16,9,9,9,8
0,12,12,12,0,12,0,0,12,0,0,12,12,0
endlayer

layer
0,0,0,0,0,0,0,0,0,0,0,0,0,0
0,18,0,0,19,0,0,0,0,19,0,0,18,0
0,19,0,0,19,0,0,0,0,19,0,0,19,0
0,19,0,0,19,0,0,0,0,19,0,0,19,0
0,19,0,0,19,0,0,0,0,19,0,0,19,0
0,19,19,19,19,19,19,19,19,19,19,19,19,0
0,19,0,0,19,0,0,0,0,19,0,0,19,0
0,19,0,0,19,0,0,0,0,19,0,0,19,0
0,19,0,0,19,0,0,0,0,19,0,0,19,0
0,20,0,0,19,0,0,0,0,19,0,0,20,0
0,0,0,0,0,0,0,0,0,0,0,0,0,0
endlayer

layer
0,0,0,0,0,0,0,0,0,0,0,0,0,0
0,0,0,0,0,0,0,0,0,0,0,0,0,0
0,4,0,0,0,0,0,0,0,0,0,0,4,0
0,4,0,0,0,0,0,0,0,0,0,0,4,0
0,21,0,0,19,0,0,0,0,19,0,0,21,0
0,19,0,0,19,0,0,0,0,19,0,0,19,0
0,21,0,0,19,0,0,0,0,19,0,0,21,0
0,4,0,0,0,0,0,0,0,0,0,0,4,0
0,4,0,0,0,0,0,0,0,0,0,0,4,0
0,0,0,0,0,0,0,0,0,0,0,0,0,0
0,0,0,0,0,0,0,0,0,0,0,0,0,0
endlayer

layer
0,0,0,0,0,0,0,0,0,0,0,0,0,0
0,0,0,0,0,0,0,0,0,0,0,0,0,0
0,0,0,0,0,0,0,0,0,0,0,0,0,0
0,0,0,0,0,0,0,0,0,0,0,0,0,0
0,0,0,0,0,0,0,0,0,0,0,0,0,0
0,4,4,4,4,4,4,4,4,4,4,4,4,0
0,0,0,0,0,0,0,0,0,0,0,0,0,0
0,0,0,0,0,0,0,0,0,0,0,0,0,0
0,0,0,0,0,0,0,0,0,0,0,0,0,0
0,0,0,0,0,0,0,0,0,0,0,0,0,0
0,0,0,0,0,0,0,0,0,0,0,0,0,0
endlayer

