weight=6
dimensionsToSpawnIn=overworld
embed_into_distance=2
random_height_offset=0,0
unacceptable_target_blocks=sand,flowing_water,water,flowing_lava,lava,ice,packed_ice,stained_hardened_clay-9,brick_block,double_stone_slab,stonebrick,red_sandstone,red_nether_brick,red_mushroom_block,brown_mushroom_block,planks,cobblestone,end_stone,obsidian,purpur_block,iron_bars,purpur_slab,purpur_pillar,netherrack,soul_sand,quartz_ore,stained_glass,glass
dimensions=26,13,15
allowable_overhang=0
max_leveling=2
leveling_buffer=-1
preventRotation=0
preserve_water=0
preserve_lava=0
uniqueMinDistance=500
spawnMinDistance=0
spawnMaxDistance=0

rule1=0,100,preserveBlock
rule2=0,100,chisel:brownstone-1,chisel:brownstone-0
rule3=0,80,minecraft:ladder-2
rule4=0,100,minecraft:vine-4
rule5=0,100,minecraft:vine-8
rule6=0,100,minecraft:vine-2
rule7=0,100,minecraft:iron_trapdoor-10
rule8=0,100,minecraft:stone_slab-8
rule9=0,100,minecraft:iron_trapdoor-11
rule10=0,100,minecraft:cobblestone_wall-0
rule11=0,100,minecraft:concrete-8,chisel:concrete_white-7,minecraft:concrete-8,chisel:concrete_white-7,chisel:concrete_white1-15
rule12=0,100,minecraft:iron_bars-0
rule13=0,100,minecraft:vine-6
rule14=0,100,minecraft:stone_slab-0

layer
1,1,1,1,1,1,1,1,1,1,1,1,1,1,1
1,1,1,1,1,1,1,1,1,1,1,1,1,1,1
1,1,1,1,1,1,1,1,1,1,1,1,1,1,1
1,1,1,1,1,1,1,1,1,1,1,1,1,1,1
1,1,1,1,1,1,1,1,1,1,1,1,1,1,1
1,1,1,1,1,1,1,1,1,1,1,1,1,1,1
1,1,1,1,1,1,1,2,1,1,1,1,1,1,1
1,1,1,1,1,1,1,1,1,1,1,1,1,1,1
1,1,1,1,1,1,1,1,1,1,1,1,1,1,1
1,1,1,1,1,1,1,1,1,1,1,1,1,1,1
1,1,1,1,1,1,1,1,1,1,1,1,1,1,1
1,1,1,1,1,1,1,1,1,1,1,1,1,1,1
1,1,1,1,1,1,1,1,1,1,1,1,1,1,1
endlayer

layer
1,1,1,1,1,1,1,1,1,1,1,1,1,1,1
1,1,1,1,1,1,1,1,1,1,1,1,1,1,1
1,1,1,1,1,1,1,1,1,1,1,1,1,1,1
1,1,1,1,1,1,1,1,1,1,1,1,1,1,1
1,1,1,1,1,1,1,1,1,1,1,1,1,1,1
1,1,1,1,1,1,1,1,1,1,1,1,1,1,1
1,1,1,1,1,1,1,2,1,1,1,1,1,1,1
1,1,1,1,1,1,1,1,1,1,1,1,1,1,1
1,1,1,1,1,1,1,1,1,1,1,1,1,1,1
1,1,1,1,1,1,1,1,1,1,1,1,1,1,1
1,1,1,1,1,1,1,1,1,1,1,1,1,1,1
1,1,1,1,1,1,1,1,1,1,1,1,1,1,1
1,1,1,1,1,1,1,1,1,1,1,1,1,1,1
endlayer

layer
1,1,1,1,1,1,1,1,1,1,1,1,1,1,1
1,1,1,1,1,1,1,1,1,1,1,1,1,1,1
1,1,1,1,1,1,1,1,1,1,1,1,1,1,1
1,1,1,1,1,1,1,1,1,1,1,1,1,1,1
1,1,1,1,1,1,1,1,1,1,1,1,1,1,1
1,1,1,1,1,1,1,1,1,1,1,1,1,1,1
1,1,1,1,1,1,1,2,3,1,1,1,1,1,1
1,1,1,1,1,1,1,1,1,1,1,1,1,1,1
1,1,1,1,1,1,1,1,1,1,1,1,1,1,1
1,1,1,1,1,1,1,1,1,1,1,1,1,1,1
1,1,1,1,1,1,1,1,1,1,1,1,1,1,1
1,1,1,1,1,1,1,1,1,1,1,1,1,1,1
1,1,1,1,1,1,1,1,1,1,1,1,1,1,1
endlayer

layer
1,1,1,1,1,1,1,1,1,1,1,1,1,1,1
1,1,1,1,1,1,1,1,1,1,1,1,1,1,1
1,1,1,1,1,1,1,1,1,1,1,1,1,1,1
1,1,1,1,1,1,1,1,1,1,1,1,1,1,1
1,1,1,1,1,1,1,1,1,1,1,1,1,1,1
1,1,1,1,1,1,1,1,1,1,1,1,1,1,1
1,1,1,1,1,1,1,2,3,1,1,1,1,1,1
1,1,1,1,1,1,1,1,1,1,1,1,1,1,1
1,1,1,1,1,1,1,1,1,1,1,1,1,1,1
1,1,1,1,1,1,1,1,1,1,1,1,1,1,1
1,1,1,1,1,1,1,1,1,1,1,1,1,1,1
1,1,1,1,1,1,1,1,1,1,1,1,1,1,1
1,1,1,1,1,1,1,1,1,1,1,1,1,1,1
endlayer

layer
1,1,1,1,1,1,1,1,1,1,1,1,1,1,1
1,1,1,1,1,1,1,1,1,1,1,1,1,1,1
1,1,1,1,1,1,1,1,1,1,1,1,1,1,1
1,1,1,1,1,1,1,1,1,1,1,1,1,1,1
1,1,1,1,1,1,1,1,1,1,1,1,1,1,1
1,1,1,1,1,1,1,1,1,1,1,1,1,1,1
1,1,1,1,1,1,1,2,3,1,1,1,1,1,1
1,1,1,1,1,1,1,1,1,1,1,1,1,1,1
1,1,1,1,1,1,1,1,1,1,1,1,1,1,1
1,1,1,1,1,1,1,1,1,1,1,1,1,1,1
1,1,1,1,1,1,1,1,1,1,1,1,1,1,1
1,1,1,1,1,1,1,1,1,1,1,1,1,1,1
1,1,1,1,1,1,1,1,1,1,1,1,1,1,1
endlayer

layer
1,1,1,1,1,1,1,1,1,1,1,1,1,1,1
1,1,1,1,1,1,1,1,1,1,1,1,1,1,1
1,1,1,1,1,1,1,1,1,1,1,1,1,1,1
1,1,1,1,1,1,1,1,1,1,1,1,1,1,1
1,1,1,1,1,1,1,1,1,1,1,1,1,1,1
1,1,1,1,1,1,1,1,1,1,1,1,1,1,1
1,1,1,1,1,1,1,2,3,1,1,1,1,1,1
1,1,1,1,1,1,1,1,1,1,1,1,1,1,1
1,1,1,1,1,1,1,1,1,1,1,1,1,1,1
1,1,1,1,1,1,1,1,1,1,1,1,1,1,1
1,1,1,1,1,1,1,1,1,1,1,1,1,1,1
1,1,1,1,1,1,1,1,1,1,1,1,1,1,1
1,1,1,1,1,1,1,1,1,1,1,1,1,1,1
endlayer

layer
1,1,1,1,1,1,1,1,1,1,1,1,1,1,1
1,1,1,1,1,1,1,1,1,1,1,1,1,1,1
1,1,1,1,1,1,1,1,1,1,1,1,1,1,1
1,1,1,1,1,1,1,1,1,1,1,1,1,1,1
1,1,1,1,1,1,1,1,1,1,1,1,1,1,1
1,1,1,1,1,1,1,1,1,1,1,1,1,1,1
1,1,1,1,1,1,1,2,3,1,1,1,1,1,1
1,1,1,1,1,1,1,1,1,1,1,1,1,1,1
1,1,1,1,1,1,1,1,1,1,1,1,1,1,1
1,1,1,1,1,1,1,1,1,1,1,1,1,1,1
1,1,1,1,1,1,1,1,1,1,1,1,1,1,1
1,1,1,1,1,1,1,1,1,1,1,1,1,1,1
1,1,1,1,1,1,1,1,1,1,1,1,1,1,1
endlayer

layer
1,1,1,1,1,1,1,1,1,1,1,1,1,1,1
1,1,1,1,1,1,1,1,1,1,1,1,1,1,1
1,1,1,1,1,1,1,1,1,1,1,1,1,1,1
1,1,1,1,1,1,1,1,1,1,1,1,1,1,1
1,1,1,1,1,1,1,1,1,1,1,1,1,1,1
1,1,1,1,1,1,1,1,1,1,1,1,1,1,1
1,1,1,1,1,1,1,2,3,1,1,1,1,1,1
1,1,1,1,1,1,1,1,1,1,1,1,1,1,1
1,1,1,1,1,1,1,1,1,1,1,1,1,1,1
1,1,1,1,1,1,1,1,1,1,1,1,1,1,1
1,1,1,1,1,1,1,1,1,1,1,1,1,1,1
1,1,1,1,1,1,1,1,1,1,1,1,1,1,1
1,1,1,1,1,1,1,1,1,1,1,1,1,1,1
endlayer

layer
1,1,1,1,1,1,1,1,1,1,1,1,1,1,1
1,1,1,1,1,1,1,1,1,1,1,1,1,1,1
1,1,1,1,1,1,1,1,1,1,1,1,1,1,1
1,1,1,1,1,1,1,1,1,1,1,1,1,1,1
1,1,1,1,1,1,1,1,1,1,1,1,1,1,1
1,1,1,1,1,1,1,1,1,1,1,1,1,1,1
1,1,1,1,1,1,4,2,3,1,1,1,1,1,1
1,1,1,1,1,1,1,1,1,1,1,1,1,1,1
1,1,1,1,1,1,1,1,1,1,1,1,1,1,1
1,1,1,1,1,1,1,1,1,1,1,1,1,1,1
1,1,1,1,1,1,1,1,1,1,1,1,1,1,1
1,1,1,1,1,1,1,1,1,1,1,1,1,1,1
1,1,1,1,1,1,1,1,1,1,1,1,1,1,1
endlayer

layer
1,1,1,1,1,1,1,1,1,1,1,1,1,1,1
1,1,1,1,1,1,1,1,1,1,1,1,1,1,1
1,1,1,1,1,1,1,1,1,1,1,1,1,1,1
1,1,1,1,1,1,1,1,1,1,1,1,1,1,1
1,1,1,1,1,1,1,1,1,1,1,1,1,1,1
1,1,1,1,1,1,1,5,1,1,1,1,1,1,1
1,1,1,1,1,1,4,2,3,1,1,1,1,1,1
1,1,1,1,1,1,1,1,1,1,1,1,1,1,1
1,1,1,1,1,1,1,1,1,1,1,1,1,1,1
1,1,1,1,1,1,1,1,1,1,1,1,1,1,1
1,1,1,1,1,1,1,1,1,1,1,1,1,1,1
1,1,1,1,1,1,1,1,1,1,1,1,1,1,1
1,1,1,1,1,1,1,1,1,1,1,1,1,1,1
endlayer

layer
1,1,1,1,1,1,1,1,1,1,1,1,1,1,1
1,1,1,1,1,1,1,1,1,1,1,1,1,1,1
1,1,1,1,1,1,1,1,1,1,1,1,1,1,1
1,1,1,1,1,1,1,1,1,1,1,1,1,1,1
1,1,1,1,1,1,1,1,1,1,1,1,1,1,1
1,1,1,1,1,1,1,5,1,1,1,1,1,1,1
1,1,1,1,1,1,4,2,3,1,1,1,1,1,1
1,1,1,1,1,1,1,6,1,1,1,1,1,1,1
1,1,1,1,1,1,1,1,1,1,1,1,1,1,1
1,1,1,1,1,1,1,1,1,1,1,1,1,1,1
1,1,1,1,1,1,1,1,1,1,1,1,1,1,1
1,1,1,1,1,1,1,1,1,1,1,1,1,1,1
1,1,1,1,1,1,1,1,1,1,1,1,1,1,1
endlayer

layer
1,1,1,1,1,1,1,1,1,1,1,1,1,1,1
1,1,1,1,1,1,1,1,1,1,1,1,1,1,1
1,1,1,1,1,1,1,1,1,1,1,1,1,1,1
1,1,1,1,1,1,1,1,1,1,1,1,1,1,1
1,1,1,1,1,1,1,1,1,1,1,1,1,1,1
1,1,1,1,1,1,1,5,1,1,1,1,1,1,1
1,1,1,1,1,1,4,2,3,1,1,1,1,1,1
1,1,1,1,1,1,1,6,1,1,1,1,1,1,1
1,1,1,1,1,1,1,1,1,1,1,1,1,1,1
1,1,1,1,1,1,1,1,1,1,1,1,1,1,1
1,1,1,1,1,1,1,1,1,1,1,1,1,1,1
1,1,1,1,1,1,1,1,1,1,1,1,1,1,1
1,1,1,1,1,1,1,1,1,1,1,1,1,1,1
endlayer

layer
1,1,1,1,1,1,1,1,1,1,1,1,1,1,1
1,1,1,1,1,1,1,1,1,1,1,1,1,1,1
1,1,1,1,1,1,1,1,1,1,1,1,1,1,1
1,1,1,1,1,1,1,1,1,1,1,1,1,1,1
1,1,1,1,1,1,1,1,1,1,1,1,1,1,1
1,1,1,1,1,1,1,5,1,1,1,1,1,1,1
1,1,1,1,1,1,4,2,3,1,1,1,1,1,1
1,1,1,1,1,1,1,6,1,1,1,1,1,1,1
1,1,1,1,1,1,1,1,1,1,1,1,1,1,1
1,1,1,1,1,1,1,1,1,1,1,1,1,1,1
1,1,1,1,1,1,1,1,1,1,1,1,1,1,1
1,1,1,1,1,1,1,1,1,1,1,1,1,1,1
1,1,1,1,1,1,1,1,1,1,1,1,1,1,1
endlayer

layer
1,1,1,1,1,1,1,1,1,1,1,1,1,1,1
1,1,1,1,1,1,1,1,1,1,1,1,1,1,1
1,1,1,1,1,1,1,1,1,1,1,1,1,1,1
1,1,1,1,1,1,1,1,1,1,1,1,1,1,1
1,1,1,1,1,1,1,1,1,1,1,1,1,1,1
1,1,1,1,1,1,1,5,1,1,1,1,1,1,1
1,1,1,1,1,1,4,2,3,1,1,1,1,1,1
1,1,1,1,1,1,1,1,1,1,1,1,1,1,1
1,1,1,1,1,1,1,1,1,1,1,1,1,1,1
1,1,1,1,1,1,1,1,1,1,1,1,1,1,1
1,1,1,1,1,1,1,1,1,1,1,1,1,1,1
1,1,1,1,1,1,1,1,1,1,1,1,1,1,1
1,1,1,1,1,1,1,1,1,1,1,1,1,1,1
endlayer

layer
1,1,1,1,1,1,1,1,1,1,1,1,1,1,1
1,1,1,1,1,1,1,1,1,1,1,1,1,1,1
1,1,1,1,1,1,1,1,1,1,1,1,1,1,1
1,1,1,1,1,1,1,1,1,1,1,1,1,1,1
1,1,1,1,1,1,1,1,1,1,1,1,1,1,1
1,1,1,1,1,1,1,5,1,1,1,1,1,1,1
1,1,1,1,1,1,4,2,3,1,1,1,1,1,1
1,1,1,1,1,1,1,6,1,1,1,1,1,1,1
1,1,1,1,1,1,1,1,1,1,1,1,1,1,1
1,1,1,1,1,1,1,1,1,1,1,1,1,1,1
1,1,1,1,1,1,1,1,1,1,1,1,1,1,1
1,1,1,1,1,1,1,1,1,1,1,1,1,1,1
1,1,1,1,1,1,1,1,1,1,1,1,1,1,1
endlayer

layer
1,1,1,1,1,1,1,1,1,1,1,1,1,1,1
1,1,1,1,1,1,1,1,1,1,1,1,1,1,1
1,1,1,1,1,1,1,1,1,1,1,1,1,1,1
1,1,1,1,1,1,1,1,1,1,1,1,1,1,1
1,1,1,1,1,1,1,1,1,1,1,1,1,1,1
1,1,1,1,1,1,1,5,1,1,1,1,1,1,1
1,1,1,1,1,1,4,2,3,1,1,1,1,1,1
1,1,1,1,1,1,1,6,1,1,1,1,1,1,1
1,1,1,1,1,1,1,1,1,1,1,1,1,1,1
1,1,1,1,1,1,1,1,1,1,1,1,1,1,1
1,1,1,1,1,1,1,1,1,1,1,1,1,1,1
1,1,1,1,1,1,1,1,1,1,1,1,1,1,1
1,1,1,1,1,1,1,1,1,1,1,1,1,1,1
endlayer

layer
1,1,1,1,1,1,1,1,1,1,1,1,1,1,1
1,1,1,1,1,1,1,1,1,1,1,1,1,1,1
1,1,1,1,1,1,1,1,1,1,1,1,1,1,1
1,1,1,1,1,1,1,1,1,1,1,1,1,1,1
1,1,1,1,1,1,1,1,1,1,1,1,1,1,1
1,1,1,1,1,1,1,5,1,1,1,1,1,1,1
1,1,1,1,1,1,1,2,3,1,1,1,1,1,1
1,1,1,1,1,1,1,6,1,1,1,1,1,1,1
1,1,1,1,1,1,1,1,1,1,1,1,1,1,1
1,1,1,1,1,1,1,1,1,1,1,1,1,1,1
1,1,1,1,1,1,1,1,1,1,1,1,1,1,1
1,1,1,1,1,1,1,1,1,1,1,1,1,1,1
1,1,1,1,1,1,1,1,1,1,1,1,1,1,1
endlayer

layer
1,1,1,1,1,1,1,1,1,1,1,1,1,1,1
1,1,1,1,1,1,1,1,1,1,1,1,1,1,1
1,1,1,1,1,1,1,1,1,1,1,1,1,1,1
1,1,1,1,1,1,1,1,1,1,1,1,1,1,1
1,1,1,1,1,1,1,1,1,1,1,1,1,1,1
1,1,1,1,1,1,1,1,1,1,1,1,1,1,1
1,1,1,1,1,1,4,2,3,1,1,1,1,1,1
1,1,1,1,1,1,1,6,1,1,1,1,1,1,1
1,1,1,1,1,1,1,1,1,1,1,1,1,1,1
1,1,1,1,1,1,1,1,1,1,1,1,1,1,1
1,1,1,1,1,1,1,1,1,1,1,1,1,1,1
1,1,1,1,1,1,1,1,1,1,1,1,1,1,1
1,1,1,1,1,1,1,1,1,1,1,1,1,6,1
endlayer

layer
1,1,1,1,1,1,1,1,1,1,1,1,1,1,1
1,1,1,1,1,1,1,1,1,1,1,1,1,1,1
1,1,1,1,1,1,1,1,1,1,1,1,1,1,1
1,1,1,1,1,1,1,1,1,1,1,1,1,1,1
1,1,1,1,1,1,1,1,1,1,1,1,1,1,1
1,1,1,1,1,1,1,5,1,1,1,1,1,1,1
1,1,1,1,1,1,4,2,3,1,1,1,1,1,1
1,1,1,1,1,1,1,6,1,1,1,1,1,1,1
1,1,1,1,1,1,1,1,1,1,1,1,1,1,1
1,1,1,1,6,1,1,1,1,1,1,1,1,1,1
1,1,1,1,1,1,1,1,1,1,1,1,1,1,1
1,1,1,1,1,1,1,1,1,1,6,1,1,1,1
1,1,1,1,1,1,1,1,1,1,1,1,1,6,1
endlayer

layer
1,1,1,1,1,1,1,1,1,1,1,1,7,5,7
1,1,1,1,1,1,1,1,1,7,1,7,8,8,8
1,1,1,1,1,1,7,1,7,8,8,8,1,1,1
1,1,1,7,1,7,8,8,8,1,1,1,1,1,1
7,1,7,8,8,8,1,1,1,1,1,1,1,1,1
8,8,8,1,1,1,1,5,1,1,1,1,1,1,1
1,1,1,1,1,1,1,2,3,1,1,1,1,1,1
8,8,8,1,1,1,1,6,1,1,1,1,1,1,1
9,1,9,8,8,8,1,1,1,1,1,1,1,1,1
1,1,1,9,6,9,8,8,8,1,1,1,1,1,1
1,1,1,1,1,1,9,1,9,8,8,8,1,1,1
1,1,1,1,1,1,1,1,1,9,6,9,8,8,8
1,1,1,1,1,1,1,1,1,1,1,1,9,6,9
endlayer

layer
1,1,1,1,1,1,1,1,1,1,1,1,1,5,1
1,1,1,1,1,1,1,1,1,5,1,1,10,1,10
1,1,1,1,1,1,5,1,1,10,1,10,8,8,8
1,1,1,1,5,1,10,1,10,8,8,8,1,1,1
1,5,1,10,1,10,8,8,8,8,1,1,1,1,1
10,1,10,8,8,8,1,1,8,8,1,1,1,1,1
1,1,1,1,1,1,4,2,3,8,1,1,1,1,1
10,1,10,8,8,8,1,1,8,8,1,1,1,1,1
1,1,4,10,1,10,8,8,8,8,1,1,1,1,1
1,1,1,6,6,1,10,1,10,8,8,8,1,1,1
1,1,1,1,1,1,1,1,1,10,1,10,8,8,8
1,1,1,1,1,1,1,1,1,6,6,1,10,1,10
1,1,1,1,1,1,1,1,1,1,1,1,1,6,6
endlayer

layer
1,1,1,1,1,1,1,1,1,1,1,1,1,5,1
1,1,1,1,1,1,1,1,1,5,5,1,11,11,11
1,1,1,1,1,1,5,5,1,11,11,11,12,1,12
1,1,1,1,5,1,11,11,11,12,6,12,1,1,1
1,5,1,11,11,11,12,10,12,1,1,1,1,1,1
11,11,11,12,1,12,1,10,1,12,1,1,1,1,1
1,12,1,1,1,1,4,2,3,12,1,1,1,1,1
11,11,11,12,1,12,1,10,1,12,1,1,1,1,1
1,1,13,11,11,11,12,10,12,1,1,1,1,1,1
1,1,1,6,6,1,11,11,11,12,1,12,1,1,1
1,1,1,1,1,1,1,1,1,11,11,11,12,5,12
1,1,1,1,1,1,1,1,1,6,6,1,11,11,11
1,1,1,1,1,1,1,1,1,1,1,1,1,6,6
endlayer

layer
1,1,1,1,1,1,1,1,1,1,1,1,1,5,1
1,1,1,1,1,1,1,1,1,5,1,1,11,11,11
1,1,1,1,1,1,1,1,1,11,11,11,12,6,12
1,1,1,5,5,1,11,11,11,12,6,12,1,1,1
1,5,1,11,11,11,12,1,12,1,1,1,1,1,1
11,11,11,12,1,12,1,1,1,1,1,1,1,1,1
1,12,1,1,1,1,4,2,3,1,1,1,1,1,1
11,11,11,12,1,12,1,6,1,1,1,1,1,1,1
1,6,1,11,11,11,12,1,12,1,1,1,1,1,1
1,1,1,1,6,1,11,11,11,12,1,12,1,1,1
1,1,1,1,1,1,1,6,4,11,11,11,12,5,12
1,1,1,1,1,1,1,1,1,1,6,1,11,11,11
1,1,1,1,1,1,1,1,1,1,1,1,1,1,6
endlayer

layer
1,1,1,1,1,1,1,1,1,1,1,1,1,5,1
1,1,1,1,1,1,1,1,1,5,1,4,11,11,11
1,1,1,1,1,1,1,1,1,11,11,11,12,6,12
1,1,1,1,5,1,11,11,11,12,6,12,1,1,1
5,5,1,11,11,11,12,1,12,1,1,1,1,1,1
11,11,11,12,1,12,1,1,1,1,1,1,1,1,1
1,12,1,1,1,1,1,2,3,1,1,1,1,1,1
11,11,11,12,1,12,1,1,1,1,1,1,1,1,1
1,6,1,11,11,11,12,1,12,1,1,1,1,1,1
1,1,1,6,6,1,11,11,11,12,1,12,1,1,1
1,1,1,1,1,1,1,6,4,11,11,11,12,5,12
1,1,1,1,1,1,1,1,1,1,6,1,11,11,11
1,1,1,1,1,1,1,1,1,1,1,1,1,6,6
endlayer

layer
1,1,1,1,1,1,1,1,1,1,1,1,1,5,1
1,1,1,1,1,1,1,1,1,5,1,4,11,11,11
1,1,1,1,1,1,1,1,1,11,11,11,12,6,12
1,1,1,1,1,4,11,11,11,12,1,12,1,1,1
5,1,1,11,11,11,12,10,12,1,1,1,1,1,1
11,11,11,12,1,12,1,10,1,1,1,1,1,1,1
1,12,1,1,1,1,4,2,3,1,1,1,1,1,1
11,11,11,12,1,12,1,10,1,1,1,1,1,1,1
1,6,13,11,11,11,12,10,12,1,1,1,1,1,1
1,1,1,6,6,1,11,11,11,12,1,12,1,1,1
1,1,1,1,1,1,1,6,4,11,11,11,12,5,12
1,1,1,1,1,1,1,1,1,6,1,1,11,11,11
1,1,1,1,1,1,1,1,1,1,1,1,1,1,6
endlayer

layer
1,1,1,1,1,1,1,1,1,1,1,1,1,1,1
1,1,1,1,1,1,1,1,1,1,1,1,11,11,11
1,1,1,1,1,1,1,1,1,11,11,11,12,6,12
1,1,1,1,1,4,11,11,11,12,1,12,1,1,1
5,1,1,11,11,11,12,6,12,1,1,1,1,1,1
11,11,11,12,1,12,1,1,1,1,1,1,1,1,1
1,12,1,1,1,1,1,14,1,1,1,1,1,1,1
11,11,11,12,1,12,1,1,1,1,1,1,1,1,1
1,1,13,11,11,11,12,1,12,1,1,1,1,1,1
1,1,1,1,6,1,11,11,11,12,1,12,1,1,1
1,1,1,1,1,1,1,6,1,11,11,11,12,1,12
1,1,1,1,1,1,1,1,1,6,1,1,11,11,11
1,1,1,1,1,1,1,1,1,1,1,1,1,6,1
endlayer

