weight=4
dimensionsToSpawnIn=overworld
embed_into_distance=6
random_height_offset=0,0
unacceptable_target_blocks=flowing_water,water,flowing_lava,lava,ice,packed_ice,stained_hardened_clay-9,brick_block,double_stone_slab,stonebrick,red_sandstone,red_nether_brick,red_mushroom_block,brown_mushroom_block,planks,cobblestone,end_stone,obsidian,purpur_block,iron_bars,purpur_slab,purpur_pillar,netherrack,soul_sand,quartz_ore,stained_glass,glass
dimensions=13,11,11
allowable_overhang=0
max_leveling=1
leveling_buffer=-1
preventRotation=0
preserve_water=0
preserve_lava=0
uniqueMinDistance=30000
spawnMinDistance=3000
spawnMaxDistance=0

rule1=0,100,preserveBlock
rule2=0,100,chisel:factory-2
rule3=0,100,preserveBlock,air,air
rule4=0,100,air
rule5=0,100,chisel:technical-11
rule6=0,100,minecraft:tnt-0
rule7=0,100,chisel:blockuranium-5
rule8=0,100,chisel:factory-8
rule9=0,100,chisel:technicalnew-3
rule10=0,100,chisel:ironpane-9

layer
1,1,1,1,1,1,1,1,1,1,1
1,1,1,1,1,1,1,1,1,1,1
1,1,1,1,1,1,1,1,1,1,1
1,1,1,1,1,1,1,1,1,1,1
1,1,1,1,1,1,1,1,1,1,1
1,1,1,1,1,1,1,1,1,1,1
1,1,1,1,1,1,1,1,1,1,1
1,1,1,1,1,1,1,1,1,1,1
1,1,1,1,1,1,1,1,1,1,1
1,1,1,1,1,1,1,1,1,1,1
1,1,1,1,1,1,1,1,1,1,1
endlayer

layer
1,1,1,1,1,1,1,1,1,1,1
1,1,1,1,1,1,1,1,1,1,1
1,1,1,3,3,3,3,3,1,1,1
1,1,3,1,1,1,1,1,3,1,1
1,1,3,1,2,2,2,1,3,1,1
1,1,3,1,2,2,2,1,3,1,1
1,1,3,1,2,2,2,1,3,1,1
1,1,3,1,1,1,1,1,3,1,1
1,1,1,3,3,3,3,3,1,1,1
1,1,1,1,1,1,1,1,1,1,1
1,1,1,1,1,1,1,1,1,1,1
endlayer

layer
1,1,1,1,1,1,1,1,1,1,1
1,1,1,3,3,3,3,3,1,1,1
1,1,3,4,4,4,4,4,3,1,1
1,3,4,4,2,2,2,4,4,3,1
1,3,4,2,5,6,5,2,4,3,1
1,3,4,2,6,6,6,2,4,3,1
1,3,4,2,5,6,5,2,4,3,1
1,3,4,4,2,2,2,4,4,3,1
1,1,3,4,4,4,4,4,3,1,1
1,1,1,3,3,3,3,3,1,1,1
1,1,1,1,1,1,1,1,1,1,1
endlayer

layer
1,1,1,1,1,1,1,1,1,1,1
1,1,1,4,4,4,4,4,1,1,1
1,1,4,4,4,4,4,4,4,1,1
1,4,4,4,2,2,2,4,4,4,1
1,4,4,2,6,6,6,2,4,4,1
1,4,4,2,6,7,6,2,4,4,1
1,4,4,2,6,6,6,2,4,4,1
1,4,4,4,2,2,2,4,4,4,1
1,1,4,4,4,4,4,4,4,1,1
1,1,1,4,4,4,4,4,1,1,1
1,1,1,1,1,1,1,1,1,1,1
endlayer

layer
1,1,1,1,3,3,3,1,1,1,1
1,1,3,4,4,4,4,4,3,1,1
1,3,4,4,4,4,4,4,4,3,1
1,4,4,4,2,2,2,4,4,4,1
3,4,4,2,5,6,5,2,4,4,1
3,4,4,2,6,6,6,2,4,4,1
3,4,4,2,5,6,5,2,4,4,1
1,4,4,4,2,2,2,4,4,4,1
1,3,4,4,4,4,4,4,4,3,1
1,1,3,4,4,4,4,4,3,1,1
1,1,1,1,3,3,3,1,1,1,1
endlayer

layer
1,1,1,1,3,3,3,1,1,1,1
1,3,3,4,4,4,4,4,3,3,1
1,3,4,4,4,4,4,4,4,3,1
1,4,4,4,4,2,4,4,4,4,1
3,4,4,4,2,8,2,4,4,4,3
3,4,4,2,8,9,8,2,4,4,3
3,4,4,4,2,8,2,4,4,4,3
1,4,4,4,4,2,4,4,4,4,1
1,3,4,4,4,4,4,4,4,3,1
1,3,3,4,4,4,4,4,3,3,1
1,1,1,1,3,3,3,1,1,1,1
endlayer

layer
1,1,1,1,4,4,4,1,1,1,1
1,4,4,4,4,4,4,4,4,4,1
1,4,4,4,4,4,4,4,4,4,1
1,4,4,4,4,4,4,4,4,4,1
4,4,4,4,10,2,10,4,4,4,4
4,4,4,4,2,2,2,4,4,4,4
4,4,4,4,10,2,10,4,4,4,4
1,4,4,4,4,4,4,4,4,4,1
1,4,4,4,4,4,4,4,4,4,1
1,4,4,4,4,4,4,4,4,4,1
1,1,1,1,4,4,4,1,1,1,1
endlayer

layer
1,1,1,1,4,4,4,1,1,1,1
1,1,4,4,4,4,4,4,4,1,1
1,4,4,4,4,4,4,4,4,4,1
1,4,4,4,4,2,4,4,4,4,1
4,4,4,4,4,4,4,4,4,4,4
4,4,4,2,4,2,4,2,4,4,4
4,4,4,4,4,4,4,4,4,4,4
1,4,4,4,4,2,4,4,4,4,1
1,4,4,4,4,4,4,4,4,4,1
1,1,4,4,4,4,4,4,4,1,1
1,1,1,1,4,4,4,1,1,1,1
endlayer

layer
1,1,1,1,1,1,1,1,1,1,1
1,1,1,1,4,4,4,1,1,1,1
1,1,1,4,4,4,4,4,1,1,1
1,1,4,2,2,2,2,2,4,1,1
1,4,4,2,4,4,4,2,4,4,1
1,4,4,2,4,4,4,2,4,4,1
1,4,4,2,4,4,4,2,4,4,1
1,1,4,2,2,2,2,2,4,1,1
1,1,1,4,4,4,4,4,1,1,1
1,1,1,1,4,4,4,1,1,1,1
1,1,1,1,1,1,1,1,1,1,1
endlayer

layer
1,1,1,1,1,1,1,1,1,1,1
1,1,1,1,1,1,1,1,1,1,1
1,1,1,1,4,4,4,1,1,1,1
1,1,1,4,4,4,4,4,1,1,1
1,1,4,4,4,4,4,4,4,1,1
1,1,4,4,4,4,4,4,4,1,1
1,1,4,4,4,4,4,4,4,1,1
1,1,1,4,4,4,4,4,1,1,1
1,1,1,1,4,4,4,1,1,1,1
1,1,1,1,1,1,1,1,1,1,1
1,1,1,1,1,1,1,1,1,1,1
endlayer

layer
1,1,1,1,1,1,1,1,1,1,1
1,1,1,1,1,1,1,1,1,1,1
1,1,1,1,4,4,4,1,1,1,1
1,1,1,4,4,4,4,4,1,1,1
1,1,4,4,4,4,4,4,4,1,1
1,1,4,4,4,4,4,4,4,1,1
1,1,4,4,4,4,4,4,4,1,1
1,1,1,4,4,4,4,4,1,1,1
1,1,1,1,4,4,4,1,1,1,1
1,1,1,1,1,1,1,1,1,1,1
1,1,1,1,1,1,1,1,1,1,1
endlayer

layer
1,1,1,1,1,1,1,1,1,1,1
1,1,1,1,1,1,1,1,1,1,1
1,1,1,1,4,4,4,1,1,1,1
1,1,1,4,4,4,4,4,1,1,1
1,1,4,4,4,4,4,4,4,1,1
1,1,4,4,4,4,4,4,4,1,1
1,1,4,4,4,4,4,4,4,1,1
1,1,1,4,4,4,4,4,1,1,1
1,1,1,1,4,4,4,1,1,1,1
1,1,1,1,1,1,1,1,1,1,1
1,1,1,1,1,1,1,1,1,1,1
endlayer

layer
1,1,1,1,1,1,1,1,1,1,1
1,1,1,1,1,1,1,1,1,1,1
1,1,1,1,4,4,4,1,1,1,1
1,1,1,4,4,4,4,4,1,1,1
1,1,4,4,4,4,4,4,4,1,1
1,1,4,4,4,4,4,4,4,1,1
1,1,4,4,4,4,4,4,4,1,1
1,1,1,4,4,4,4,4,1,1,1
1,1,1,1,4,4,4,1,1,1,1
1,1,1,1,1,1,1,1,1,1,1
1,1,1,1,1,1,1,1,1,1,1
endlayer


