weight=6
dimensionsToSpawnIn=overworld
embed_into_distance=2
random_height_offset=0,0
unacceptable_target_blocks=sand,flowing_water,water,flowing_lava,lava,ice,packed_ice,stained_hardened_clay-9,brick_block,double_stone_slab,stonebrick,red_sandstone,red_nether_brick,red_mushroom_block,brown_mushroom_block,planks,cobblestone,end_stone,obsidian,purpur_block,iron_bars,purpur_slab,purpur_pillar,netherrack,soul_sand,quartz_ore,stained_glass,glass
dimensions=11,11,12
allowable_overhang=0
max_leveling=2
leveling_buffer=-1
preventRotation=0
preserve_water=0
preserve_lava=0
uniqueMinDistance=0
spawnMinDistance=0
spawnMaxDistance=0

rule1=0,100,minecraft:monster_egg-4,monster_egg-2,monster_egg-2,monster_egg-2,monster_egg-3,stonebrick-2,stonebrick-1,stonebrick-0,stonebrick-0,stonebrick-0,stonebrick-2,stonebrick-1,stonebrick-0,stonebrick-0,stonebrick-0,cobblestone,cobblestone,cobblestone,cobblestone
rule2=0,100,preserveBlock
rule3=0,100,minecraft:monster_egg-4,monster_egg-2,monster_egg-2,monster_egg-2,monster_egg-3,stonebrick-2,stonebrick-1,stonebrick-0,stonebrick-0,stonebrick-0,stonebrick-2,stonebrick-1,stonebrick-0,stonebrick-0,stonebrick-0
rule4=0,100,minecraft:double_stone_slab-5
rule5=0,100,minecraft:stone_slab-5
rule6=0,100,minecraft:stained_glass_pane-7
rule7=0,100,minecraft:stained_glass_pane-7,preserveBlock
rule8=0,100,minecraft:stone_slab-13
rule9=0,100,minecraft:wooden_slab-0
rule10=0,100,minecraft:wooden_slab-8
rule11=0,100,minecraft:double_wooden_slab-0

layer
1,2,2,2,2,1,1,1,1,1,1,1
2,2,2,2,2,2,3,3,3,3,3,1
1,3,2,2,2,2,2,2,2,2,3,1
1,3,2,2,2,2,2,2,2,2,3,1
1,3,2,2,2,2,2,2,2,2,3,2
1,3,2,2,2,2,2,2,2,2,2,2
1,3,2,2,2,2,2,2,2,2,2,2
1,3,2,2,2,2,2,2,2,2,2,2
1,3,2,2,2,2,2,2,2,2,2,2
1,3,3,3,3,3,3,3,3,3,3,2
1,1,1,1,1,1,1,1,1,1,2,2
endlayer

layer
1,2,2,2,2,1,1,1,1,1,1,1
2,2,2,2,2,2,3,3,3,3,3,1
1,3,2,2,2,2,2,2,2,2,3,1
1,3,2,2,2,2,2,2,2,2,3,1
1,3,2,2,2,2,2,2,2,2,3,2
1,3,2,2,2,2,2,2,2,2,2,2
1,3,2,2,2,2,2,2,2,2,2,2
1,3,2,2,2,2,2,2,2,2,2,2
1,3,2,2,2,2,2,2,2,2,2,2
1,3,3,3,3,3,3,3,3,3,3,2
1,1,1,1,1,1,1,1,1,1,2,2
endlayer

layer
4,2,2,2,2,5,1,5,4,5,4,1
2,2,2,2,2,2,3,3,3,3,3,1
5,3,2,2,2,2,2,2,2,2,3,5
1,3,2,2,2,2,2,2,2,2,3,1
5,3,2,2,2,2,2,2,2,2,3,2
1,3,2,2,2,2,2,2,2,2,2,2
5,3,2,2,2,2,2,2,2,2,2,2
1,3,2,2,2,2,2,2,2,2,2,2
5,3,2,2,2,2,2,2,2,2,2,2
1,3,3,3,3,3,3,3,3,3,3,2
1,1,5,4,5,1,5,1,5,1,2,2
endlayer

layer
5,2,2,2,2,2,2,2,2,2,2,1
2,2,2,2,2,2,2,2,3,6,3,2
2,2,2,2,2,2,2,2,2,2,7,2
2,3,2,2,2,2,2,2,2,2,3,2
2,2,2,2,2,2,2,2,2,2,2,2
2,3,2,2,2,2,2,2,2,2,2,2
2,6,2,2,2,2,2,2,2,2,2,2
2,3,2,2,2,2,2,2,2,2,2,2
2,6,2,2,2,2,2,2,2,2,2,2
2,3,6,3,7,3,7,3,2,3,2,2
1,2,2,2,2,1,2,2,2,2,2,2
endlayer

layer
0,0,0,0,0,0,0,0,0,0,2,1
0,0,0,0,0,0,0,0,3,7,3,0
0,0,0,0,0,0,0,0,0,0,0,0
0,0,0,0,0,0,0,0,0,0,0,0
0,0,0,0,0,0,0,0,0,0,0,2
0,3,0,0,0,0,0,0,0,0,0,2
0,7,0,0,0,0,0,0,0,0,0,2
0,3,0,0,0,0,0,0,0,0,0,2
0,7,0,0,0,0,0,0,0,0,0,2
2,3,7,3,0,3,0,3,2,0,0,2
1,0,0,0,0,1,2,2,2,2,2,2
endlayer

layer
0,0,0,0,0,0,0,0,0,0,8,1
0,0,0,0,0,0,0,0,0,0,3,0
0,0,0,0,0,0,0,0,0,0,0,0
0,0,0,0,0,0,0,0,0,0,0,0
0,0,0,0,0,0,0,0,0,0,0,0
0,0,0,0,0,0,0,0,0,0,0,0
0,0,0,0,0,0,0,0,0,0,0,0
0,3,0,0,0,0,0,0,0,0,0,0
0,0,0,0,0,0,0,0,0,0,0,0
0,3,0,3,0,3,0,0,0,0,0,0
1,0,0,0,0,1,0,0,0,0,0,2
endlayer

layer
0,0,0,0,0,0,0,0,4,5,4,1
0,0,0,0,0,0,0,0,3,3,3,8
0,0,0,0,0,0,0,0,0,0,3,0
0,0,0,0,0,0,0,0,0,0,0,0
0,3,0,0,0,0,0,0,0,0,0,0
8,3,10,9,0,0,0,0,0,0,0,0
8,3,10,11,10,0,0,0,0,0,0,0
8,3,11,11,11,11,9,0,0,0,0,0
8,3,10,11,10,10,0,0,0,0,0,0
4,3,3,3,3,0,0,0,0,0,0,0
1,4,8,8,8,1,0,0,0,0,0,0
endlayer

layer
0,0,0,0,0,0,0,0,0,0,0,5
0,0,0,0,0,0,0,0,0,0,3,0
0,0,0,0,0,0,0,0,0,0,0,0
0,0,0,0,0,0,0,0,0,0,0,0
0,0,0,0,0,0,0,0,0,0,0,0
5,0,0,0,0,0,0,0,0,0,0,0
0,0,0,0,0,0,0,0,0,0,0,0
5,3,0,0,0,0,0,0,0,0,0,0
0,0,0,0,0,0,0,0,0,0,0,0
5,3,7,3,0,0,0,0,0,0,0,0
1,5,0,5,0,5,0,0,0,0,0,0
endlayer

layer
0,0,0,0,0,0,0,0,0,0,0,0
0,0,0,0,0,0,0,0,0,0,3,0
0,0,0,0,0,0,0,0,0,0,0,0
0,0,0,0,0,0,0,0,0,0,0,0
0,0,0,0,0,0,0,0,0,0,0,0
0,0,0,0,0,0,0,0,0,0,0,0
0,0,0,0,0,0,0,0,0,0,0,0
0,0,0,0,0,0,0,0,0,0,0,0
0,0,0,0,0,0,0,0,0,0,0,0
0,3,0,0,0,0,0,0,0,0,0,0
1,0,0,0,0,0,0,0,0,0,0,0
endlayer

layer
0,0,0,0,0,0,0,0,0,0,0,0
0,0,0,0,0,0,0,0,0,0,3,0
0,0,0,0,0,0,0,0,0,0,0,0
0,0,0,0,0,0,0,0,0,0,0,0
0,0,0,0,0,0,0,0,0,0,0,0
0,0,0,0,0,0,0,0,0,0,0,0
0,0,0,0,0,0,0,0,0,0,0,0
0,0,0,0,0,0,0,0,0,0,0,0
0,0,0,0,0,0,0,0,0,0,0,0
0,3,0,0,0,0,0,0,0,0,0,0
1,0,0,0,0,0,0,0,0,0,0,0
endlayer

layer
0,0,0,0,0,0,0,0,0,0,0,0
0,0,0,0,0,0,0,0,0,3,3,0
0,0,0,0,0,0,0,0,0,0,0,0
0,0,0,0,0,0,0,0,0,0,0,0
0,0,0,0,0,0,0,0,0,0,0,0
0,0,0,0,0,0,0,0,0,0,0,0
0,0,0,0,0,0,0,0,0,0,0,0
0,0,0,0,0,0,0,0,0,0,0,0
0,0,0,0,0,0,0,0,0,0,0,0
0,1,3,0,0,0,0,0,0,0,0,0
0,0,0,0,0,0,0,0,0,0,0,0
endlayer

