weight=6
dimensionsToSpawnIn=overworld
embed_into_distance=1
random_height_offset=0,0
unacceptable_target_blocks=sand,flowing_water,water,flowing_lava,lava,ice,packed_ice,stained_hardened_clay-9,brick_block,double_stone_slab,stonebrick,red_sandstone,red_nether_brick,red_mushroom_block,brown_mushroom_block,planks,cobblestone,end_stone,obsidian,purpur_block,iron_bars,purpur_slab,purpur_pillar,netherrack,soul_sand,quartz_ore,stained_glass,glass
dimensions=6,9,13
allowable_overhang=0
max_leveling=1
leveling_buffer=-1
preventRotation=0
preserve_water=0
preserve_lava=0
uniqueMinDistance=0
spawnMinDistance=0
spawnMaxDistance=0

rule1=0,100,minecraft:monster_egg-4,monster_egg-2,monster_egg-2,monster_egg-2,monster_egg-3,stonebrick-2,stonebrick-1,stonebrick-0,stonebrick-0,stonebrick-0,stonebrick-2,stonebrick-1,stonebrick-0,stonebrick-0,stonebrick-0,cobblestone,cobblestone,cobblestone,cobblestone
rule2=0,100,preserveBlock
rule3=0,100,minecraft:planks-0
rule4=0,100,minecraft:stone_brick_stairs-2
rule5=0,100,minecraft:wooden_slab-0
rule6=0,100,minecraft:stone_stairs-2
rule7=0,100,minecraft:double_wooden_slab-0
rule8=0,100,minecraft:stone_brick_stairs-3
rule9=0,100,minecraft:stone_slab-5
rule10=0,100,minecraft:stone_brick_stairs-1
rule11=0,100,minecraft:stone_stairs-1
rule12=0,100,minecraft:stonebrick-0
rule13=0,100,minecraft:stained_glass_pane-7,preserveBlock
rule14=0,100,minecraft:stained_glass_pane-7
rule15=0,100,minecraft:vine-4
rule16=0,100,minecraft:vine-8
rule17=0,100,minecraft:vine-2
rule18=0,100,minecraft:vine-1

layer
2,2,2,2,2,2,2,2,2,2,2,2,1
2,2,2,2,2,2,2,2,2,2,2,3,1
2,2,2,2,2,2,2,2,2,2,2,3,1
2,2,2,2,2,2,2,2,2,2,2,3,1
2,3,2,2,2,2,2,2,2,2,2,3,1
1,3,2,2,2,2,2,2,2,2,2,3,1
1,3,2,2,2,2,2,2,2,2,2,3,1
1,3,3,3,3,3,3,3,3,3,3,3,1
1,1,1,1,1,1,1,1,1,1,1,1,1
endlayer

layer
2,2,2,2,2,2,2,2,2,2,2,2,1
2,2,2,2,2,2,2,2,2,2,2,5,4
2,2,2,2,2,2,2,2,2,0,0,5,6
2,2,2,2,2,2,0,0,0,0,0,5,4
2,5,0,0,0,0,0,0,0,0,0,7,1
8,5,0,0,0,0,0,0,0,0,0,5,6
8,5,0,0,0,0,0,0,0,0,0,5,6
9,7,5,5,7,5,5,5,7,5,5,7,4
1,1,10,10,1,11,10,10,12,11,11,10,1
endlayer

layer
2,2,2,2,2,2,2,2,0,0,0,0,0
2,2,2,2,2,0,0,0,0,0,0,0,0
2,2,2,0,0,0,0,0,0,0,0,0,13
0,0,0,0,0,0,0,0,0,0,0,0,14
0,0,0,0,0,0,0,0,0,0,15,7,1
0,0,0,0,0,0,0,0,0,0,0,0,14
0,0,0,0,0,0,0,0,16,0,0,0,14
0,0,0,0,5,0,0,15,7,0,0,0,14
0,0,0,15,1,0,13,14,1,14,14,13,1
endlayer

layer
2,2,2,2,0,0,0,0,0,0,0,0,0
2,2,0,0,0,0,0,0,0,0,0,0,0
0,0,0,0,0,0,0,0,0,0,0,0,0
0,0,0,0,0,0,0,0,0,0,0,16,13
0,0,0,0,0,0,0,0,0,0,15,7,1
0,0,0,0,0,0,0,0,0,0,0,0,17
0,0,0,0,0,0,0,0,0,0,0,0,13
0,0,0,0,16,0,0,0,5,0,0,0,14
0,0,0,0,1,18,0,13,1,14,14,14,1
endlayer

layer
0,0,0,0,0,0,0,0,0,0,0,0,0
0,0,0,0,0,0,0,0,0,0,0,0,0
0,0,0,0,0,0,0,0,0,0,0,0,0
0,0,0,0,0,0,0,0,0,0,0,0,16
0,0,0,0,0,0,0,0,0,0,0,0,1
0,0,0,0,0,0,0,0,0,0,0,0,17
0,0,0,0,0,0,0,0,0,0,0,0,0
0,0,0,0,0,0,0,0,0,0,0,0,13
0,0,0,0,0,0,0,0,0,0,0,13,1
endlayer

layer
0,0,0,0,0,0,0,0,0,0,0,0,0
0,0,0,0,0,0,0,0,0,0,0,0,0
0,0,0,0,0,0,0,0,0,0,0,0,0
0,0,0,0,0,0,0,0,0,0,0,0,0
0,0,0,0,0,0,0,0,0,0,0,0,0
0,0,0,0,0,0,0,0,0,0,0,0,0
0,0,0,0,0,0,0,0,0,0,0,0,0
0,0,0,0,0,0,0,0,0,0,0,0,16
0,0,0,0,0,0,0,0,0,0,0,0,1
endlayer

