weight=6
dimensionsToSpawnIn=overworld
embed_into_distance=1
random_height_offset=0,0
unacceptable_target_blocks=sand,flowing_water,water,flowing_lava,lava,ice,packed_ice,stained_hardened_clay-9,brick_block,double_stone_slab,stonebrick,red_sandstone,red_nether_brick,red_mushroom_block,brown_mushroom_block,planks,cobblestone,end_stone,obsidian,purpur_block,iron_bars,purpur_slab,purpur_pillar,netherrack,soul_sand,quartz_ore,stained_glass,glass
dimensions=15,10,10
allowable_overhang=0
max_leveling=1
leveling_buffer=-1
preventRotation=0
preserve_water=0
preserve_lava=0
uniqueMinDistance=0
spawnMinDistance=0
spawnMaxDistance=0

rule1=0,100,minecraft:double_stone_slab-0
rule2=0,100,minecraft:monster_egg-4,monster_egg-2,monster_egg-2,monster_egg-2,monster_egg-3,stonebrick-2,stonebrick-1,stonebrick-0,stonebrick-0,stonebrick-0,stonebrick-2,stonebrick-1,stonebrick-0,stonebrick-0,stonebrick-0,cobblestone,cobblestone,cobblestone,cobblestone
rule3=0,100,preserveBlock
rule4=0,100,minecraft:double_stone_slab-5
rule5=0,100,minecraft:stone_brick_stairs-6
rule6=0,100,minecraft:stone_brick_stairs-7
rule7=0,100,minecraft:stone_stairs-6
rule8=0,100,minecraft:oak_stairs-0
rule9=0,100,minecraft:stone_brick_stairs-5
rule10=0,100,minecraft:planks-0
rule11=0,100,minecraft:stained_glass_pane-7,preserveBlock
rule12=0,100,minecraft:stained_glass_pane-7
rule13=0,100,minecraft:vine-2
rule14=0,100,minecraft:vine-1
rule15=0,100,minecraft:vine-8
rule16=0,100,minecraft:vine-4
rule17=0,100,minecraft:vine-12
rule18=0,100,minecraft:stone_slab-13
rule19=0,100,minecraft:stone_slab-5

layer
1,3,2,3,3,1,2,3,2,1
2,3,3,3,3,3,3,3,3,2
2,3,3,3,3,3,3,3,3,2
2,3,2,2,3,3,3,3,3,2
1,3,3,2,3,3,3,3,3,2
1,3,2,3,3,3,3,3,3,1
2,3,3,2,3,3,3,3,3,2
2,3,3,3,3,3,3,3,3,2
2,3,3,3,3,3,3,3,3,2
1,2,2,2,1,2,2,2,2,1
endlayer

layer
1,3,2,3,3,1,2,3,2,1
4,3,3,3,3,3,3,3,3,4
6,3,3,3,3,3,3,3,3,5
2,3,8,8,3,3,3,3,3,7
1,3,3,2,3,3,3,3,3,2
1,3,2,3,3,3,3,3,3,1
2,3,3,2,3,3,3,3,3,5
6,3,3,3,3,3,3,3,3,5
2,3,3,3,3,3,3,3,3,2
1,2,9,2,1,2,2,2,2,1
endlayer

layer
3,3,3,3,3,10,3,3,3,2
10,3,3,3,0,0,0,3,3,10
11,3,0,0,0,0,0,0,0,11
12,0,0,0,0,0,0,0,0,12
10,0,0,8,0,0,0,0,0,10
10,14,2,13,0,0,0,0,0,10
12,0,13,2,14,0,0,0,0,12
11,0,0,0,0,0,0,0,0,12
15,15,0,0,15,15,0,0,15,10
2,10,11,12,10,10,12,12,10,2
endlayer

layer
0,0,0,0,0,10,0,0,16,2
10,0,0,0,0,0,0,0,0,10
0,0,0,0,0,0,0,0,0,0
11,0,0,0,0,0,0,0,0,11
10,0,0,0,0,0,0,0,0,10
10,0,8,0,0,0,0,0,16,10
12,0,0,2,14,0,0,0,0,12
12,0,0,0,0,0,0,0,0,11
10,0,0,0,15,15,0,0,17,10
2,10,0,11,10,10,12,11,10,2
endlayer

layer
0,0,0,0,0,10,0,0,16,2
0,0,0,0,0,0,0,0,16,10
0,0,0,0,0,0,0,0,0,0
0,0,0,0,0,0,0,0,0,0
10,14,0,0,0,0,0,0,0,10
10,0,0,0,0,0,0,0,16,10
12,0,0,8,0,0,0,0,0,12
0,0,0,0,0,0,0,0,0,0
10,0,0,0,15,15,0,0,16,10
2,10,0,0,10,10,12,0,10,2
endlayer

layer
0,0,0,0,0,4,0,0,16,1
0,0,0,0,0,18,0,0,0,0
0,0,0,0,0,18,0,0,0,0
0,0,0,0,0,18,18,0,0,0
19,0,0,0,0,18,18,0,0,19
4,0,0,0,0,18,18,18,18,4
19,0,0,0,0,18,18,18,18,19
2,0,0,0,18,18,18,18,18,4
4,0,0,0,18,18,18,18,18,4
1,2,19,19,4,4,4,4,4,1
endlayer

layer
0,0,0,0,0,0,0,0,0,2
0,0,0,0,0,0,0,0,0,0
0,0,0,0,0,0,0,0,0,0
0,0,0,0,0,0,0,0,0,0
0,0,0,0,0,0,0,0,0,15
0,0,0,0,0,0,0,0,16,10
0,0,0,0,0,0,0,0,0,0
0,0,0,0,0,0,0,0,0,12
10,0,0,0,0,0,0,0,0,10
2,10,0,0,10,10,11,12,10,2
endlayer

layer
0,0,0,0,0,0,0,0,0,0
0,0,0,0,0,0,0,0,0,0
0,0,0,0,0,0,0,0,0,0
0,0,0,0,0,0,0,0,0,0
0,0,0,0,0,0,0,0,0,15
0,0,0,0,0,0,0,0,0,10
0,0,0,0,0,0,0,0,0,11
0,0,0,0,0,0,0,0,0,12
15,15,0,0,0,15,0,0,0,10
2,10,11,0,11,10,0,11,10,2
endlayer

layer
0,0,0,0,0,0,0,0,0,0
0,0,0,0,0,0,0,0,0,0
0,0,0,0,0,0,0,0,0,0
0,0,0,0,0,0,0,0,0,0
0,0,0,0,0,0,0,0,0,0
0,0,0,0,0,0,0,0,0,10
0,0,0,0,0,0,0,0,0,0
0,0,0,0,0,0,0,0,0,11
0,0,0,0,0,0,0,0,0,10
2,0,0,0,0,10,0,0,10,2
endlayer

layer
0,0,0,0,0,0,0,0,0,0
0,0,0,0,0,0,0,0,0,0
0,0,0,0,0,0,0,0,0,0
0,0,0,0,0,0,0,0,0,19
0,0,0,0,0,0,0,0,0,19
0,0,0,0,0,0,0,0,19,19
0,0,0,0,0,0,0,19,19,19
19,0,0,0,0,0,19,19,19,19
4,0,0,0,0,19,19,19,19,4
2,19,19,19,4,4,19,19,4,2
endlayer

layer
0,0,0,0,0,0,0,0,0,0
0,0,0,0,0,0,0,0,0,0
0,0,0,0,0,0,0,0,0,0
0,0,0,0,0,0,0,0,0,0
0,0,0,0,0,0,0,0,0,0
0,0,0,0,0,0,0,0,0,0
0,0,0,0,0,0,0,0,0,0
0,0,0,0,0,0,0,0,0,0
0,0,0,0,15,0,0,0,0,15
2,0,0,0,10,10,0,0,16,2
endlayer

layer
0,0,0,0,0,0,0,0,0,0
0,0,0,0,0,0,0,0,0,0
0,0,0,0,0,0,0,0,0,0
0,0,0,0,0,0,0,0,0,0
0,0,0,0,0,0,0,0,0,0
0,0,0,0,0,0,0,0,0,0
0,0,0,0,0,0,0,0,0,0
0,0,0,0,0,0,0,0,0,0
0,0,0,0,0,0,0,0,0,0
2,0,0,0,0,10,0,0,16,2
endlayer

layer
0,0,0,0,0,0,0,0,0,0
0,0,0,0,0,0,0,0,0,0
0,0,0,0,0,0,0,0,0,0
0,0,0,0,0,0,0,0,0,0
0,0,0,0,0,0,0,0,0,0
0,0,0,0,0,0,0,0,0,0
0,0,0,0,0,0,0,0,0,0
0,0,0,0,0,0,0,0,0,0
0,0,0,0,0,0,0,0,0,0
0,0,0,0,0,10,0,0,16,2
endlayer

layer
0,0,0,0,0,0,0,0,0,0
0,0,0,0,0,0,0,0,0,0
0,0,0,0,0,0,0,0,0,0
0,0,0,0,0,0,0,0,0,0
0,0,0,0,0,0,0,0,0,0
0,0,0,0,0,0,0,0,0,0
0,0,0,0,0,0,0,0,0,0
0,0,0,0,0,0,0,0,0,0
0,0,0,0,0,0,0,0,0,0
0,0,0,0,0,0,0,0,16,2
endlayer

layer
0,0,0,0,0,0,0,0,0,0
0,0,0,0,0,0,0,0,0,0
0,0,0,0,0,0,0,0,0,0
0,0,0,0,0,0,0,0,0,0
0,0,0,0,0,0,0,0,0,0
0,0,0,0,0,0,0,0,0,0
0,0,0,0,0,0,0,0,0,0
0,0,0,0,0,0,0,0,0,0
0,0,0,0,0,0,0,0,0,15
0,0,0,0,0,0,0,0,0,2
endlayer

