weight=6
dimensionsToSpawnIn=overworld
embed_into_distance=1
random_height_offset=0,0
unacceptable_target_blocks=sand,flowing_water,water,flowing_lava,lava,ice,packed_ice,stained_hardened_clay-9,brick_block,double_stone_slab,stonebrick,red_sandstone,red_nether_brick,red_mushroom_block,brown_mushroom_block,planks,cobblestone,end_stone,obsidian,purpur_block,iron_bars,purpur_slab,purpur_pillar,netherrack,soul_sand,quartz_ore,stained_glass,glass
dimensions=9,17,17
allowable_overhang=0
max_leveling=1
leveling_buffer=-1
preventRotation=0
preserve_water=0
preserve_lava=0
uniqueMinDistance=0
spawnMinDistance=0
spawnMaxDistance=0

rule1=0,100,preserveBlock
rule2=0,100,minecraft:monster_egg-4,monster_egg-2,monster_egg-2,monster_egg-2,monster_egg-3,stonebrick-2,stonebrick-1,stonebrick-0,stonebrick-0,stonebrick-0,stonebrick-2,stonebrick-1,stonebrick-0,stonebrick-0,stonebrick-0,preserveBlock,preserveBlock,preserveBlock,preserveBlock
rule3=0,100,minecraft:cobblestone-0
rule4=0,100,minecraft:stone_slab-0
rule5=0,100,minecraft:monster_egg-4,monster_egg-2,monster_egg-2,monster_egg-2,monster_egg-3,stonebrick-2,stonebrick-1,stonebrick-0,stonebrick-0,stonebrick-0,stonebrick-2,stonebrick-1,stonebrick-0,stonebrick-0,stonebrick-0
rule6=0,100,minecraft:planks-0
rule7=0,100,minecraft:oak_stairs-1
rule8=0,100,minecraft:oak_stairs-2
rule9=0,100,minecraft:vine-8
rule10=0,100,minecraft:vine-1
rule11=0,100,minecraft:vine-2
rule12=0,100,minecraft:oak_stairs-3
rule13=0,100,minecraft:oak_stairs-0
rule14=0,100,minecraft:vine-4
rule15=0,100,minecraft:stained_glass_pane-7,preserveBlock
rule16=0,100,minecraft:stained_glass_pane-7
rule17=0,100,minecraft:vine-6
rule18=0,100,minecraft:wooden_slab-0
rule19=0,100,minecraft:stone_slab-13
rule20=0,100,minecraft:double_stone_slab-5
rule21=0,100,minecraft:stone_slab-5
rule22=0,100,minecraft:double_wooden_slab-0

layer
2,2,1,1,1,1,1,1,1,1,1,1,1,1,1,1,1
2,2,2,2,2,2,2,2,2,2,2,2,1,1,1,1,1
1,2,2,2,2,2,2,2,2,2,1,2,2,2,1,1,1
1,2,2,2,2,2,2,2,2,2,2,2,2,1,2,1,1
1,2,2,2,2,2,2,2,2,2,2,2,2,2,2,2,1
1,2,2,2,2,2,2,2,2,2,2,2,2,2,2,2,1
1,2,2,2,2,2,2,2,2,2,2,2,2,2,2,2,2
1,2,2,2,2,2,2,2,2,2,2,2,2,2,2,2,1
1,2,2,2,2,2,2,2,2,2,2,2,2,2,2,2,1
1,2,2,2,2,2,2,2,2,2,2,2,2,2,2,2,1
1,2,2,2,2,2,2,2,2,2,2,2,2,2,2,2,2
1,2,2,2,2,2,2,2,2,2,2,2,2,2,2,2,1
1,2,2,2,2,2,2,2,2,2,2,2,2,2,2,2,1
1,2,2,2,2,2,2,2,2,2,2,2,2,2,2,2,1
1,2,2,2,2,2,2,2,2,2,2,2,2,2,2,2,1
2,2,2,2,2,2,2,2,2,2,2,2,2,2,2,2,2
2,2,1,1,1,1,1,1,1,1,1,1,1,1,1,2,2
endlayer

layer
3,3,1,1,1,1,1,1,1,1,1,1,1,1,1,1,1
5,5,5,3,3,5,5,4,4,0,0,0,0,0,1,1,1
1,5,6,7,7,7,7,0,6,0,0,0,0,0,0,0,1
1,5,8,0,0,0,0,0,0,0,0,0,0,0,0,0,1
1,3,8,0,0,0,0,0,0,0,0,0,0,0,0,0,1
1,3,8,0,0,0,0,0,0,0,0,0,0,0,0,9,1
1,5,8,0,0,0,0,0,0,0,0,0,0,0,0,5,5
1,5,8,0,0,0,0,0,0,0,0,0,0,0,0,0,1
1,3,6,0,0,0,0,0,6,10,0,0,0,0,0,1,1
1,3,8,0,0,0,0,0,11,0,0,0,0,0,0,0,1
1,5,8,0,0,0,0,0,0,0,0,0,0,0,6,5,5
1,5,8,0,0,0,0,0,0,0,0,0,0,0,0,5,1
1,5,8,0,0,0,0,0,0,0,0,0,0,0,0,5,1
1,3,8,0,0,0,0,0,9,0,0,0,0,0,12,3,1
1,3,6,13,13,13,13,13,6,13,13,13,13,13,6,3,1
5,5,3,5,3,3,5,5,3,3,5,5,5,3,3,5,5
3,5,1,1,1,1,1,1,1,1,1,1,1,1,1,5,3
endlayer

layer
3,5,9,0,0,0,0,0,0,0,0,0,0,0,1,1,1
5,5,5,4,4,4,4,0,9,0,0,0,0,0,0,0,1
17,5,6,16,16,16,15,14,6,0,0,0,0,0,0,0,0
0,4,16,0,0,0,0,0,11,0,0,0,0,0,0,0,0
0,4,16,0,0,0,0,0,0,0,0,0,0,0,0,0,0
0,4,16,0,0,0,0,0,0,0,0,0,0,0,0,9,0
0,4,16,0,0,0,0,0,0,0,0,0,0,0,0,5,4
0,4,16,0,0,0,0,0,0,0,0,0,0,0,0,0,10
0,3,6,0,0,0,0,0,6,10,0,0,0,0,0,0,0
0,4,16,0,0,0,0,0,0,0,0,0,0,0,0,0,0
0,4,16,0,0,0,0,0,0,0,0,0,0,0,18,5,4
0,4,16,0,0,0,0,0,0,0,0,0,0,0,0,4,0
0,4,16,0,0,0,0,0,0,0,0,0,0,0,0,4,0
0,4,16,0,0,0,0,0,9,0,0,0,0,0,16,4,0
0,3,6,16,16,16,16,16,6,16,16,16,16,16,6,4,9
5,5,5,4,4,4,4,4,3,4,4,4,4,4,3,5,3
5,3,0,0,0,0,0,0,11,0,0,0,0,0,0,5,5
endlayer

layer
5,3,9,0,0,0,0,0,0,0,0,0,0,0,0,0,1
5,5,5,0,0,0,0,0,9,0,0,0,0,0,0,0,0
17,3,6,15,15,0,0,14,6,0,0,0,0,0,0,0,0
0,0,16,0,0,0,0,0,0,0,0,0,0,0,0,0,0
0,0,15,0,0,0,0,0,0,0,0,0,0,0,0,0,0
0,0,0,0,0,0,0,0,0,0,0,0,0,0,0,9,0
0,0,0,0,0,0,0,0,0,0,0,0,0,0,0,5,10
0,0,16,0,0,0,0,0,9,0,0,0,0,0,0,19,10
14,5,6,0,0,0,0,14,6,10,0,0,0,0,0,0,0
0,11,16,0,0,0,0,0,11,0,0,0,0,0,0,19,0
0,0,16,0,0,0,0,0,0,0,0,0,0,0,0,5,0
0,0,0,0,0,0,0,0,0,0,0,0,0,0,0,0,0
0,0,0,0,0,0,0,0,0,0,0,0,0,0,0,0,0
0,0,15,0,0,0,0,0,9,0,0,0,0,0,15,0,0
0,5,6,16,15,0,0,16,6,16,15,0,0,15,6,0,9
5,5,5,0,0,0,0,14,5,0,0,0,0,0,5,5,3
5,3,0,0,0,0,0,0,11,0,0,0,0,0,14,5,5
endlayer

layer
0,3,9,0,0,0,0,0,0,0,0,0,0,0,0,0,0
3,5,20,0,0,0,0,0,9,0,0,0,0,0,0,0,0
14,5,6,15,0,0,0,14,6,0,0,0,0,0,0,0,0
0,0,15,0,0,0,0,0,0,0,0,0,0,0,0,0,0
0,0,0,0,0,0,0,0,0,0,0,0,0,0,0,0,0
0,0,0,0,0,0,0,0,0,0,0,0,0,0,0,0,0
0,0,0,0,0,0,0,0,0,0,0,0,0,0,0,5,10
0,0,15,0,0,0,0,0,0,0,0,0,0,0,0,20,10
14,5,6,0,0,0,0,0,6,0,0,0,0,0,0,21,0
0,0,16,0,0,0,0,0,0,0,0,0,0,0,0,20,0
0,0,16,0,0,0,0,0,0,0,0,0,0,0,0,5,0
0,0,0,0,0,0,0,0,0,0,0,0,0,0,0,0,0
0,0,0,0,0,0,0,0,0,0,0,0,0,0,0,0,0
0,0,0,0,0,0,0,0,0,0,0,0,0,0,0,0,0
0,5,6,16,0,0,0,15,6,16,15,0,0,0,6,0,9
3,5,5,0,0,0,0,0,5,0,0,0,0,0,5,5,5
5,5,0,0,0,0,0,0,11,0,0,0,0,0,14,3,5
endlayer

layer
0,0,0,0,0,0,0,0,0,0,0,0,0,0,0,0,0
0,3,21,21,21,21,0,0,9,0,0,0,0,0,0,0,0
14,5,18,18,18,18,18,18,22,0,0,0,0,0,0,0,0
0,21,18,0,0,0,0,0,18,0,0,0,0,0,0,0,0
0,21,18,0,0,0,0,0,18,0,0,0,0,0,0,0,0
0,0,0,0,0,0,0,0,18,0,0,0,0,0,0,21,0
0,21,18,0,0,0,0,0,18,18,18,18,18,18,18,20,0
0,21,18,0,0,0,0,0,18,0,0,0,0,0,0,0,0
14,5,18,18,18,0,0,18,6,0,0,0,0,0,0,0,0
0,21,18,0,0,0,0,0,18,0,0,0,18,0,0,0,0
0,21,18,0,0,0,0,0,18,18,18,18,18,18,18,20,0
0,21,18,0,0,0,0,0,18,18,0,0,0,0,18,21,0
0,0,18,0,0,0,0,0,18,0,0,0,0,0,18,21,0
0,0,18,0,0,0,0,0,18,0,0,0,0,0,18,21,0
0,5,18,18,18,0,18,18,18,18,18,18,18,18,18,21,0
5,5,5,21,21,0,21,21,5,21,21,21,0,0,5,5,5
5,5,0,0,0,0,0,0,11,0,0,0,0,0,14,5,5
endlayer

layer
0,0,0,0,0,0,0,0,0,0,0,0,0,0,0,0,0
0,9,0,0,0,0,0,0,0,0,0,0,0,0,0,0,0
14,3,0,0,0,0,0,0,0,0,0,0,0,0,0,0,0
0,11,0,0,0,0,0,0,0,0,0,0,0,0,0,0,0
0,0,0,0,0,0,0,0,0,0,0,0,0,0,0,0,0
0,0,0,0,0,0,0,0,0,0,0,0,0,0,0,0,0
0,0,0,0,0,0,0,0,0,0,0,0,0,0,0,0,0
0,0,0,0,0,0,0,0,0,0,0,0,0,0,0,21,0
14,5,10,0,0,0,0,0,6,10,0,0,0,0,0,19,0
0,11,0,0,0,0,0,0,11,0,0,0,0,0,0,21,0
0,0,0,0,0,0,0,0,0,0,0,0,0,0,0,0,0
0,0,0,0,0,0,0,0,0,0,0,0,0,0,0,0,0
0,0,0,0,0,0,0,0,0,0,0,0,0,0,0,0,0
0,0,0,0,0,0,0,0,0,0,0,0,0,0,0,0,0
0,9,0,0,0,0,0,0,0,0,0,0,0,0,0,9,9
3,5,10,0,0,0,0,14,3,0,0,0,0,0,14,3,3
0,11,0,0,0,0,0,0,11,0,0,0,0,0,0,0,0
endlayer

layer
0,0,0,0,0,0,0,0,0,0,0,0,0,0,0,0,0
0,9,0,0,0,0,0,0,0,0,0,0,0,0,0,0,0
14,3,0,0,0,0,0,0,0,0,0,0,0,0,0,0,0
0,0,0,0,0,0,0,0,0,0,0,0,0,0,0,0,0
0,0,0,0,0,0,0,0,0,0,0,0,0,0,0,0,0
0,0,0,0,0,0,0,0,0,0,0,0,0,0,0,0,0
0,0,0,0,0,0,0,0,0,0,0,0,0,0,0,0,0
0,0,0,0,0,0,0,0,0,0,0,0,0,0,0,0,0
0,5,0,0,0,0,0,14,6,0,0,0,0,0,0,0,0
0,11,0,0,0,0,0,0,0,0,0,0,0,0,0,0,0
0,0,0,0,0,0,0,0,0,0,0,0,0,0,0,0,0
0,0,0,0,0,0,0,0,0,0,0,0,0,0,0,0,0
0,0,0,0,0,0,0,0,0,0,0,0,0,0,0,0,0
0,0,0,0,0,0,0,0,0,0,0,0,0,0,0,0,0
0,0,0,0,0,0,0,0,0,0,0,0,0,0,0,0,0
0,3,0,0,0,0,0,14,3,10,0,0,0,0,0,3,0
0,0,0,0,0,0,0,0,11,0,0,0,0,0,0,0,0
endlayer

layer
0,0,0,0,0,0,0,0,0,0,0,0,0,0,0,0,0
0,0,0,0,0,0,0,0,0,0,0,0,0,0,0,0,0
0,0,0,0,0,0,0,0,0,0,0,0,0,0,0,0,0
0,0,0,0,0,0,0,0,0,0,0,0,0,0,0,0,0
0,0,0,0,0,0,0,0,0,0,0,0,0,0,0,0,0
0,0,0,0,0,0,0,0,0,0,0,0,0,0,0,0,0
0,0,0,0,0,0,0,0,0,0,0,0,0,0,0,0,0
0,0,0,0,0,0,0,0,0,0,0,0,0,0,0,0,0
0,3,10,0,0,0,0,0,0,0,0,0,0,0,0,0,0
0,0,0,0,0,0,0,0,0,0,0,0,0,0,0,0,0
0,0,0,0,0,0,0,0,0,0,0,0,0,0,0,0,0
0,0,0,0,0,0,0,0,0,0,0,0,0,0,0,0,0
0,0,0,0,0,0,0,0,0,0,0,0,0,0,0,0,0
0,0,0,0,0,0,0,0,0,0,0,0,0,0,0,0,0
0,0,0,0,0,0,0,0,0,0,0,0,0,0,0,0,0
14,3,10,0,0,0,0,0,0,0,0,0,0,0,0,0,0
0,11,0,0,0,0,0,0,0,0,0,0,0,0,0,0,0
endlayer

