weight=6
dimensionsToSpawnIn=overworld
embed_into_distance=1
random_height_offset=0,0
unacceptable_target_blocks=sand,flowing_water,water,flowing_lava,lava,ice,packed_ice,stained_hardened_clay-9,brick_block,double_stone_slab,stonebrick,red_sandstone,red_nether_brick,red_mushroom_block,brown_mushroom_block,planks,cobblestone,end_stone,obsidian,purpur_block,iron_bars,purpur_slab,purpur_pillar,netherrack,soul_sand,quartz_ore,stained_glass,glass
dimensions=19,27,13
allowable_overhang=0
max_leveling=1
leveling_buffer=-1
preventRotation=0
preserve_water=0
preserve_lava=0
uniqueMinDistance=0
spawnMinDistance=0
spawnMaxDistance=0

rule1=0,100,preserveBlock
rule2=0,100,minecraft:double_stone_slab-0
rule3=0,100,minecraft:planks-0
rule4=0,100,minecraft:planks-0,planks-0,planks-0,planks-0,planks-0,planks-0,preserveBlock
rule5=0,100,minecraft:monster_egg-4,monster_egg-2,monster_egg-2,monster_egg-2,monster_egg-3,stonebrick-2,stonebrick-1,stonebrick-0,stonebrick-0,stonebrick-0,stonebrick-2,stonebrick-1,stonebrick-0,stonebrick-0,stonebrick-0
rule6=0,100,minecraft:stained_glass_pane-7,stained_glass_pane-7,stained_glass_pane-7,preserveBlock
rule7=0,100,minecraft:stained_glass_pane-7
rule8=0,100,minecraft:stone_brick_stairs-0
rule9=0,100,minecraft:stone_slab-5
rule10=0,100,minecraft:stone-0
rule11=0,100,minecraft:vine-1
rule12=0,100,minecraft:stone_brick_stairs-2
rule13=0,100,minecraft:stone_brick_stairs-3
rule14=0,100,minecraft:vine-2
rule15=0,100,minecraft:oak_stairs-1
rule16=0,100,minecraft:vine-8
rule17=0,100,minecraft:stone_brick_stairs-1
rule18=0,100,minecraft:stone-0,stone-0,preserveBlock
rule19=0,100,minecraft:stonebrick-2
rule20=0,100,minecraft:vine-4
rule21=0,100,minecraft:stone_slab-0
rule22=0,100,minecraft:wooden_slab-8,preserveBlock
rule23=0,100,minecraft:wooden_slab-8
rule24=0,100,minecraft:double_wooden_slab-0
rule25=0,100,minecraft:double_stone_slab-5
rule26=0,100,minecraft:wooden_slab-0,preserveBlock
rule27=0,100,minecraft:double_stone_slab-3
rule28=0,100,minecraft:wooden_slab-0
rule29=0,100,minecraft:vine-5

layer
1,1,1,1,1,1,1,1,1,1,1,1,1
1,2,2,2,2,2,2,2,2,2,2,2,1
1,2,4,4,4,3,3,3,4,4,3,2,1
1,2,4,4,4,4,4,4,4,4,4,2,1
1,2,4,4,4,4,4,4,4,4,4,2,1
1,2,4,4,4,4,4,4,4,4,4,2,1
1,2,4,4,4,1,4,4,4,4,4,2,1
1,2,4,4,4,4,4,4,4,4,4,2,1
1,2,4,4,1,3,4,4,4,4,4,2,1
1,2,4,4,4,1,4,4,4,4,4,2,1
1,2,4,4,4,4,4,4,4,4,4,2,1
1,2,4,4,4,4,4,4,4,4,4,2,1
1,2,4,4,4,4,4,4,4,4,4,4,4
1,2,4,4,4,4,4,4,4,4,4,4,4
1,2,4,4,4,4,4,4,4,4,4,4,4
1,2,4,4,4,4,4,4,4,4,4,2,1
1,2,4,4,4,4,4,4,4,4,4,2,1
1,2,4,4,4,4,4,4,4,4,4,2,1
1,2,4,4,4,4,4,4,4,4,4,2,1
1,2,4,4,4,4,4,4,4,4,4,2,1
1,2,4,4,4,4,4,4,4,4,4,2,1
1,2,4,4,4,4,4,4,4,4,4,2,1
1,2,4,4,4,4,4,4,4,4,4,2,1
1,2,4,4,4,4,4,4,4,4,4,2,1
1,2,4,4,4,4,4,4,4,4,4,2,1
1,2,2,2,2,2,2,2,2,2,2,2,1
1,1,1,1,1,1,1,1,1,1,1,1,1
endlayer

layer
1,1,1,1,1,1,1,1,1,1,1,1,1
1,9,5,7,7,5,8,5,7,6,5,5,1
1,5,10,11,0,10,9,10,0,0,10,5,1
1,6,0,0,0,0,0,0,0,0,0,7,1
1,7,0,0,0,0,0,0,0,0,0,7,1
1,5,10,0,0,0,0,0,0,0,10,5,1
1,13,9,0,0,10,0,0,0,0,9,12,1
1,5,10,0,10,0,0,0,0,0,10,5,1
1,7,14,0,10,10,0,0,0,0,0,7,1
1,7,0,0,0,10,0,0,0,0,0,7,1
1,5,10,0,0,15,0,0,0,0,10,5,1
1,13,10,0,0,0,0,0,0,0,0,2,2
1,5,0,0,0,0,0,0,0,0,0,0,1
1,7,0,0,0,0,0,0,0,0,0,1,1
1,5,0,0,0,0,0,0,0,0,0,0,1
1,13,10,11,0,0,0,0,0,0,0,2,2
1,5,10,11,0,0,0,0,0,0,10,5,1
1,6,0,0,0,0,0,0,0,0,0,0,1
1,7,0,0,0,0,0,0,0,0,0,7,1
1,5,10,0,0,0,0,0,0,0,10,5,1
1,9,9,0,0,0,0,0,0,0,9,12,1
1,5,10,0,0,0,0,0,0,0,10,5,1
1,7,0,0,0,0,0,0,0,0,0,7,1
1,7,16,0,0,0,0,0,0,0,0,7,1
1,5,10,11,0,10,9,10,0,0,10,5,1
1,9,5,6,7,5,17,5,6,7,5,9,1
1,1,1,1,1,1,1,1,1,1,1,1,1
endlayer

layer
1,1,0,0,0,0,0,16,0,0,0,1,1
1,9,5,7,7,5,8,5,7,6,5,9,1
0,5,10,11,0,10,9,10,0,0,10,5,11
0,0,0,0,0,0,0,14,0,0,0,7,0
0,7,0,0,0,0,0,0,0,0,16,7,0
0,5,10,0,0,0,0,0,0,0,10,5,11
0,13,9,0,0,10,0,0,0,0,9,12,0
0,5,10,11,10,0,0,0,0,0,10,5,0
0,6,14,0,10,10,0,0,0,0,0,7,0
0,7,0,0,0,15,0,0,0,0,0,6,0
0,5,18,0,0,0,0,0,0,0,10,5,0
0,13,10,0,0,0,0,0,0,0,0,2,0
0,5,14,0,0,0,0,0,0,0,0,0,0
0,7,0,0,0,0,0,0,0,0,0,0,0
0,5,0,0,0,0,0,0,0,0,0,0,0
0,13,10,11,0,0,0,0,0,0,0,2,11
0,5,10,11,0,0,0,0,0,0,10,5,11
0,0,0,0,0,0,0,0,0,0,0,7,0
0,7,0,0,0,0,0,0,0,0,16,7,0
0,5,10,0,0,0,0,0,0,0,10,5,0
0,13,9,0,0,0,0,0,0,0,9,9,0
0,5,10,0,0,0,0,0,0,0,10,5,0
0,7,14,0,0,0,0,0,0,0,0,6,0
0,7,16,0,0,0,0,16,0,0,0,7,0
0,5,10,0,0,10,9,10,0,0,10,5,0
1,9,5,0,0,5,17,5,0,7,5,9,1
1,1,0,0,0,0,0,14,0,0,0,1,1
endlayer

layer
1,0,16,0,0,0,0,16,0,0,16,0,1
0,19,5,6,7,5,8,5,7,6,5,11,0
0,5,10,0,20,10,9,10,0,20,10,5,11
0,0,0,0,0,0,0,14,0,0,0,6,0
0,6,0,0,0,0,0,0,0,0,16,7,0
0,5,10,11,0,16,0,0,0,0,10,5,11
0,13,9,0,0,10,0,0,0,0,9,9,0
0,5,10,11,10,0,0,0,0,0,10,5,0
0,0,14,0,15,15,0,0,0,0,0,7,0
0,6,0,0,0,0,0,0,0,0,0,6,0
0,5,10,0,0,0,0,0,0,0,10,5,0
0,9,10,11,0,0,0,0,0,0,0,2,0
0,5,14,0,0,0,0,0,0,0,0,0,0
0,6,0,0,0,0,0,0,0,0,0,0,11
0,5,0,0,0,0,0,0,0,0,0,0,11
0,13,10,11,0,0,0,0,0,0,0,2,11
0,5,10,0,0,0,0,0,0,0,10,5,11
0,0,14,0,0,0,0,0,0,0,14,7,0
0,7,0,0,0,0,0,0,0,0,0,0,0
0,5,10,0,0,0,0,0,0,20,10,5,0
0,13,9,0,0,0,0,0,0,0,9,12,0
0,5,10,0,0,0,0,0,0,0,10,5,0
0,7,0,0,0,0,0,0,0,0,0,0,0
0,6,16,0,0,16,0,16,0,0,16,7,0
0,5,10,11,0,10,9,10,0,0,10,5,0
0,9,5,7,0,5,17,5,6,7,5,9,0
1,0,0,0,0,0,0,14,0,0,0,0,1
endlayer

layer
0,0,16,0,0,0,0,0,0,0,16,0,0
0,9,5,6,6,5,8,5,7,7,5,11,0
0,5,10,0,20,10,9,10,0,20,10,0,0
0,7,0,0,0,0,0,14,0,0,14,0,0
0,6,0,0,0,0,0,0,0,0,16,6,0
0,5,10,0,0,16,0,0,0,0,10,5,11
0,13,9,0,0,10,0,0,0,0,9,12,0
0,5,10,11,15,0,0,0,0,0,10,5,0
0,0,0,0,0,0,0,0,0,0,0,7,0
0,6,0,0,0,0,0,0,0,0,0,7,0
0,5,10,0,0,0,0,0,0,0,10,5,0
0,13,10,11,0,0,0,0,0,0,0,2,0
0,5,14,0,0,0,0,0,0,0,0,2,0
0,6,0,0,0,0,0,0,0,0,0,21,11
0,5,0,0,0,0,0,0,0,0,0,2,11
0,13,10,0,0,0,0,0,0,0,0,2,11
0,5,10,11,0,0,0,0,0,20,10,5,11
0,0,14,0,0,0,0,0,0,0,14,7,0
0,6,0,0,0,0,0,0,0,0,0,6,0
0,5,10,0,0,0,0,0,0,0,10,5,0
0,13,9,0,0,0,0,0,0,0,9,12,0
0,5,10,0,0,0,0,0,0,0,10,5,0
0,6,0,0,0,0,0,0,0,0,0,0,0
0,0,0,0,0,0,0,0,0,0,16,7,11
0,5,10,11,0,10,9,10,0,0,10,5,0
0,9,5,7,6,5,17,5,7,7,5,9,0
0,0,0,0,0,0,0,14,0,0,0,0,0
endlayer

layer
0,0,0,0,0,0,0,0,0,0,0,0,0
0,0,9,9,9,9,9,9,9,9,0,0,0
0,19,10,10,10,10,10,10,10,10,0,0,0
0,25,10,23,23,24,23,23,22,0,0,0,0
0,9,10,23,23,24,23,22,0,0,16,0,0
0,9,10,24,24,24,26,0,0,0,10,11,0
0,25,10,22,0,15,0,0,0,0,10,9,0
0,27,10,0,0,0,0,0,0,0,10,9,0
0,9,18,0,0,0,0,0,0,0,18,9,0
0,9,18,0,0,0,0,0,0,0,10,9,0
0,9,10,0,0,0,0,0,0,0,10,9,0
0,9,10,11,0,0,0,0,0,0,10,9,0
0,9,10,0,0,0,0,0,0,0,10,9,0
0,9,18,0,0,0,26,0,0,22,10,2,11
0,9,10,22,0,0,28,0,0,23,10,9,0
0,9,10,22,22,0,28,0,0,23,10,9,0
0,9,10,24,24,24,28,26,24,24,10,9,0
0,9,18,23,23,23,24,23,23,23,10,9,0
0,9,18,23,23,23,24,23,23,23,10,9,0
0,9,10,23,23,23,24,23,23,23,10,9,0
0,9,10,24,24,24,24,24,24,24,10,9,0
0,9,10,23,23,23,24,23,23,23,10,9,11
0,9,10,23,23,23,24,23,23,23,18,9,0
0,9,10,23,23,23,24,23,23,23,18,9,11
0,9,10,18,18,10,10,10,10,10,10,9,11
0,9,9,9,9,9,9,9,9,9,9,9,0
0,0,0,0,0,0,0,0,0,0,0,0,0
endlayer

layer
0,0,0,0,0,0,0,0,0,0,0,0,0
0,0,0,9,9,9,9,9,9,9,0,0,0
0,0,18,0,0,10,0,0,0,0,0,0,0
0,0,0,0,0,0,0,0,0,0,0,0,0
0,9,0,0,0,0,0,0,0,0,16,0,0
0,9,18,0,0,0,0,0,0,20,10,11,0
0,0,0,0,0,0,0,0,0,0,0,0,0
0,0,10,0,0,0,0,0,0,0,0,9,0
0,9,0,0,0,0,0,0,0,0,0,9,0
0,9,0,0,0,0,0,0,0,0,10,25,0
0,9,10,0,0,0,0,0,0,0,10,25,0
0,9,0,0,0,0,0,0,0,0,18,9,0
0,5,0,0,0,0,0,0,0,0,10,0,0
0,9,0,0,0,0,0,0,0,0,10,9,0
0,5,0,0,0,0,0,0,0,0,18,0,0
0,9,10,0,0,0,0,0,0,0,18,9,0
0,5,10,0,0,0,0,0,0,0,10,5,0
0,9,0,0,0,0,0,0,0,0,0,9,0
0,13,9,0,0,0,0,0,0,0,0,12,0
20,5,10,0,0,0,0,0,0,0,10,5,0
0,9,0,0,0,0,0,0,0,0,13,12,0
0,5,10,0,0,0,0,0,0,0,10,25,11
0,13,0,0,0,0,0,0,0,0,9,12,0
0,13,9,0,0,0,0,0,0,0,9,12,11
0,5,10,0,0,10,0,10,0,9,10,5,11
0,9,5,9,9,5,9,5,9,9,5,9,0
0,0,0,0,0,0,0,0,0,0,0,0,0
endlayer

layer
0,0,0,0,0,0,0,0,0,0,0,0,0
0,0,0,0,0,0,0,0,0,0,0,0,0
0,0,0,0,0,0,0,0,0,0,0,0,0
0,0,0,0,0,0,0,0,0,0,0,0,0
0,0,0,0,0,0,0,0,0,0,16,0,0
0,0,0,0,0,0,0,0,0,20,18,0,0
0,0,0,0,0,0,0,0,0,0,0,0,0
0,0,18,0,0,0,0,0,0,0,0,0,0
0,0,0,0,0,0,0,0,0,0,0,0,0
0,0,0,0,0,0,0,0,0,0,18,0,0
0,0,10,0,0,0,0,0,0,0,0,9,0
0,16,0,0,0,0,0,0,0,0,0,25,0
0,5,11,0,0,0,0,0,0,0,18,9,0
0,0,0,0,0,0,0,0,0,0,10,9,0
0,5,0,0,0,0,0,0,0,0,18,9,0
0,0,18,0,0,0,0,0,0,0,0,25,0
0,5,10,0,0,0,0,0,0,0,10,5,0
0,0,0,0,0,0,0,0,0,0,0,6,0
0,7,0,0,0,0,0,0,0,0,0,7,0
20,5,18,0,0,0,0,0,0,0,10,5,0
0,16,0,0,0,0,0,0,0,0,0,12,0
0,5,10,0,0,0,0,0,0,0,10,5,11
0,6,0,0,0,0,0,0,0,0,0,6,0
0,7,0,0,0,0,0,0,0,0,0,7,0
0,5,10,0,0,10,0,0,0,0,10,5,11
0,0,5,0,20,5,29,5,0,0,5,9,0
0,0,0,0,0,14,0,0,0,0,0,0,0
endlayer

layer
0,0,0,0,0,0,0,0,0,0,0,0,0
0,0,0,0,0,0,0,0,0,0,0,0,0
0,0,0,0,0,0,0,0,0,0,0,0,0
0,0,0,0,0,0,0,0,0,0,0,0,0
0,0,0,0,0,0,0,0,0,0,0,0,0
0,0,0,0,0,0,0,0,0,0,0,0,0
0,0,0,0,0,0,0,0,0,0,0,0,0
0,0,0,0,0,0,0,0,0,0,0,0,0
0,0,0,0,0,0,0,0,0,0,0,0,0
0,0,0,0,0,0,0,0,0,0,0,0,0
0,0,10,0,0,0,0,0,0,0,0,0,0
0,16,0,0,0,0,0,0,0,0,0,0,0
20,5,11,0,0,0,0,0,0,0,0,0,0
0,0,0,0,0,0,0,0,0,0,10,0,0
0,5,0,0,0,0,0,0,0,0,0,0,0
0,0,0,0,0,0,0,0,0,0,0,0,0
0,5,18,0,0,0,0,0,0,0,10,0,0
0,0,0,0,0,0,0,0,0,0,0,6,0
0,6,0,0,0,0,0,0,0,0,0,7,0
20,5,0,0,0,0,0,0,0,0,10,5,0
0,16,0,0,0,0,0,0,0,0,0,0,0
20,5,10,0,0,0,0,0,0,0,10,5,0
0,6,0,0,0,0,0,0,0,0,0,6,0
0,0,0,0,0,0,0,0,0,0,0,7,0
0,5,10,0,0,10,0,0,0,0,10,5,11
0,0,5,0,0,5,11,5,0,0,5,0,0
0,0,0,0,0,14,0,0,0,0,0,0,0
endlayer

layer
0,0,0,0,0,0,0,0,0,0,0,0,0
0,0,0,0,0,0,0,0,0,0,0,0,0
0,0,0,0,0,0,0,0,0,0,0,0,0
0,0,0,0,0,0,0,0,0,0,0,0,0
0,0,0,0,0,0,0,0,0,0,0,0,0
0,0,0,0,0,0,0,0,0,0,0,0,0
0,0,0,0,0,0,0,0,0,0,0,0,0
0,0,0,0,0,0,0,0,0,0,0,0,0
0,0,0,0,0,0,0,0,0,0,0,0,0
0,0,0,0,0,0,0,0,0,0,0,11,0
0,0,18,0,0,0,0,0,0,0,0,0,0
0,0,0,0,0,0,0,0,0,0,0,0,0
0,0,0,0,0,0,0,0,0,0,0,0,0
0,9,0,0,0,0,0,0,0,0,10,0,0
20,5,11,0,0,0,0,0,0,0,0,0,0
0,9,0,0,0,0,0,0,0,0,0,0,0
0,5,0,0,0,0,0,0,0,0,10,0,0
0,0,0,0,0,0,0,0,0,0,0,0,0
0,6,0,0,0,0,0,0,0,0,0,6,0
20,5,0,0,0,0,0,0,0,0,0,5,0
0,0,0,0,0,0,0,0,0,0,0,0,0
0,5,10,0,0,0,0,0,0,0,10,5,0
0,0,0,0,0,0,0,0,0,0,0,0,0
0,0,0,0,0,0,0,0,0,0,0,6,0
0,5,10,0,0,10,0,0,0,0,10,5,11
0,0,5,0,0,5,11,5,0,0,5,0,0
0,0,0,0,0,14,0,0,0,0,0,0,0
endlayer

layer
0,0,0,0,0,0,0,0,0,0,0,0,0
0,0,0,0,0,0,0,0,0,0,0,0,0
0,0,0,0,0,0,0,0,0,0,0,0,0
0,0,0,0,0,0,0,0,0,0,0,0,0
0,0,0,0,0,0,0,0,0,0,0,0,0
0,0,0,0,0,0,0,0,0,0,0,0,0
0,0,0,0,0,0,0,0,0,0,0,0,0
0,0,0,0,0,0,0,0,0,0,0,0,0
0,0,0,0,0,0,0,0,0,0,0,0,0
0,0,0,0,0,0,0,0,0,0,18,11,0
0,0,0,0,0,0,0,0,0,20,10,11,0
0,0,0,0,0,0,0,0,0,0,10,11,0
0,0,0,0,0,0,0,0,0,0,10,0,0
0,0,0,0,0,0,0,0,0,0,10,9,0
0,0,0,0,0,0,0,0,0,0,10,9,0
0,0,0,0,0,0,26,0,0,0,10,9,0
0,9,0,0,0,0,28,28,28,26,10,9,0
0,9,0,0,0,0,28,0,0,23,10,25,0
0,9,0,0,0,0,28,0,22,23,10,25,0
0,9,10,22,22,0,28,22,23,23,10,25,0
0,9,10,23,23,23,24,23,23,23,10,9,0
0,9,10,24,24,24,24,24,24,24,10,9,0
0,9,10,23,23,23,24,23,23,23,10,9,0
0,9,10,23,23,23,24,23,23,23,10,9,0
0,9,10,10,10,10,10,10,10,10,10,9,0
0,0,9,9,9,25,25,9,9,9,9,9,0
0,0,0,0,0,0,0,0,0,0,0,0,0
endlayer

layer
0,0,0,0,0,0,0,0,0,0,0,0,0
0,0,0,0,0,0,0,0,0,0,0,0,0
0,0,0,0,0,0,0,0,0,0,0,0,0
0,0,0,0,0,0,0,0,0,0,0,0,0
0,0,0,0,0,0,0,0,0,0,0,0,0
0,0,0,0,0,0,0,0,0,0,0,0,0
0,0,0,0,0,0,0,0,0,0,0,0,0
0,0,0,0,0,0,0,0,0,0,0,0,0
0,0,0,0,0,0,0,0,0,0,0,0,0
0,0,0,0,0,0,0,0,0,0,0,0,0
0,0,0,0,0,0,0,0,0,0,0,0,0
0,0,0,0,0,0,0,0,0,0,0,0,0
0,0,0,0,0,0,0,0,0,0,0,0,0
0,0,0,0,0,0,0,0,0,0,0,0,0
0,0,0,0,0,0,0,0,0,0,0,0,0
0,0,0,0,0,0,0,0,0,0,16,9,0
0,0,0,0,0,0,0,0,0,0,10,9,0
0,0,0,0,0,0,0,0,0,0,0,0,0
0,0,0,0,0,0,0,0,0,0,0,0,0
0,9,0,0,0,0,0,0,0,0,0,0,0
0,9,0,0,0,0,0,0,0,0,0,9,0
0,5,18,0,0,0,0,0,0,0,10,5,0
0,13,0,0,0,0,0,0,0,0,0,9,0
0,9,0,0,0,0,0,0,0,0,0,9,0
0,5,10,0,0,0,0,10,0,0,10,5,0
0,0,5,9,9,0,0,5,9,9,5,9,0
0,0,0,0,0,0,0,0,0,0,0,0,0
endlayer

layer
0,0,0,0,0,0,0,0,0,0,0,0,0
0,0,0,0,0,0,0,0,0,0,0,0,0
0,0,0,0,0,0,0,0,0,0,0,0,0
0,0,0,0,0,0,0,0,0,0,0,0,0
0,0,0,0,0,0,0,0,0,0,0,0,0
0,0,0,0,0,0,0,0,0,0,0,0,0
0,0,0,0,0,0,0,0,0,0,0,0,0
0,0,0,0,0,0,0,0,0,0,0,0,0
0,0,0,0,0,0,0,0,0,0,0,0,0
0,0,0,0,0,0,0,0,0,0,0,0,0
0,0,0,0,0,0,0,0,0,0,0,0,0
0,0,0,0,0,0,0,0,0,0,0,0,0
0,0,0,0,0,0,0,0,0,0,0,0,0
0,0,0,0,0,0,0,0,0,0,0,0,0
0,0,0,0,0,0,0,0,0,0,0,0,0
0,0,0,0,0,0,0,0,0,0,16,0,0
0,0,0,0,0,0,0,0,0,0,10,0,0
0,0,0,0,0,0,0,0,0,0,0,0,0
0,0,0,0,0,0,0,0,0,0,0,0,0
0,0,0,0,0,0,0,0,0,0,0,0,0
0,0,0,0,0,0,0,0,0,0,0,0,0
0,5,0,0,0,0,0,0,0,0,0,5,0
0,6,0,0,0,0,0,0,0,0,0,0,0
0,0,0,0,0,0,0,0,0,0,0,0,0
0,5,18,0,0,0,0,10,0,0,10,5,0
0,0,5,0,0,0,0,5,0,0,19,0,0
0,0,0,0,0,0,0,0,0,0,0,0,0
endlayer

layer
0,0,0,0,0,0,0,0,0,0,0,0,0
0,0,0,0,0,0,0,0,0,0,0,0,0
0,0,0,0,0,0,0,0,0,0,0,0,0
0,0,0,0,0,0,0,0,0,0,0,0,0
0,0,0,0,0,0,0,0,0,0,0,0,0
0,0,0,0,0,0,0,0,0,0,0,0,0
0,0,0,0,0,0,0,0,0,0,0,0,0
0,0,0,0,0,0,0,0,0,0,0,0,0
0,0,0,0,0,0,0,0,0,0,0,0,0
0,0,0,0,0,0,0,0,0,0,0,0,0
0,0,0,0,0,0,0,0,0,0,0,0,0
0,0,0,0,0,0,0,0,0,0,0,0,0
0,0,0,0,0,0,0,0,0,0,0,0,0
0,0,0,0,0,0,0,0,0,0,0,0,0
0,0,0,0,0,0,0,0,0,0,0,0,0
0,0,0,0,0,0,0,0,0,0,0,0,0
0,0,0,0,0,0,0,0,0,0,18,0,0
0,0,0,0,0,0,0,0,0,0,0,0,0
0,0,0,0,0,0,0,0,0,0,0,0,0
0,0,0,0,0,0,0,0,0,0,0,0,0
0,0,0,0,0,0,0,0,0,0,0,0,0
0,19,0,0,0,0,0,0,0,0,0,5,0
0,0,0,0,0,0,0,0,0,0,0,0,0
0,0,0,0,0,0,0,16,0,0,0,0,0
0,9,16,0,0,0,0,10,0,0,10,5,0
0,0,5,0,0,0,0,5,0,0,0,0,0
0,0,0,0,0,0,0,0,0,0,0,0,0
endlayer

layer
0,0,0,0,0,0,0,0,0,0,0,0,0
0,0,0,0,0,0,0,0,0,0,0,0,0
0,0,0,0,0,0,0,0,0,0,0,0,0
0,0,0,0,0,0,0,0,0,0,0,0,0
0,0,0,0,0,0,0,0,0,0,0,0,0
0,0,0,0,0,0,0,0,0,0,0,0,0
0,0,0,0,0,0,0,0,0,0,0,0,0
0,0,0,0,0,0,0,0,0,0,0,0,0
0,0,0,0,0,0,0,0,0,0,0,0,0
0,0,0,0,0,0,0,0,0,0,0,0,0
0,0,0,0,0,0,0,0,0,0,0,0,0
0,0,0,0,0,0,0,0,0,0,0,0,0
0,0,0,0,0,0,0,0,0,0,0,0,0
0,0,0,0,0,0,0,0,0,0,0,0,0
0,0,0,0,0,0,0,0,0,0,0,0,0
0,0,0,0,0,0,0,0,0,0,0,0,0
0,0,0,0,0,0,0,0,0,0,0,0,0
0,0,0,0,0,0,0,0,0,0,0,0,0
0,0,0,0,0,0,0,0,0,0,0,0,0
0,0,0,0,0,0,0,0,0,0,0,9,0
0,0,0,0,0,0,0,0,0,0,0,9,0
0,0,0,0,0,0,0,0,0,0,0,5,0
0,0,0,0,0,0,0,0,0,0,0,0,0
0,0,0,0,0,0,0,16,0,0,0,0,0
0,0,0,0,0,0,20,18,0,0,10,19,0
0,0,19,0,0,0,0,19,0,0,14,0,0
0,0,0,0,0,0,0,14,0,0,0,0,0
endlayer

layer
0,0,0,0,0,0,0,0,0,0,0,0,0
0,0,0,0,0,0,0,0,0,0,0,0,0
0,0,0,0,0,0,0,0,0,0,0,0,0
0,0,0,0,0,0,0,0,0,0,0,0,0
0,0,0,0,0,0,0,0,0,0,0,0,0
0,0,0,0,0,0,0,0,0,0,0,0,0
0,0,0,0,0,0,0,0,0,0,0,0,0
0,0,0,0,0,0,0,0,0,0,0,0,0
0,0,0,0,0,0,0,0,0,0,0,0,0
0,0,0,0,0,0,0,0,0,0,0,0,0
0,0,0,0,0,0,0,0,0,0,0,0,0
0,0,0,0,0,0,0,0,0,0,0,0,0
0,0,0,0,0,0,0,0,0,0,0,0,0
0,0,0,0,0,0,0,0,0,0,0,0,0
0,0,0,0,0,0,0,0,0,0,0,0,0
0,0,0,0,0,0,0,0,0,0,0,0,0
0,0,0,0,0,0,0,0,0,0,0,0,0
0,0,0,0,0,0,0,0,0,0,0,0,0
0,0,0,0,0,0,0,0,0,0,0,0,0
0,0,0,0,0,0,0,0,0,0,0,0,0
0,0,0,0,0,0,0,0,0,0,0,0,0
0,0,0,0,0,0,0,0,0,0,0,9,0
0,0,0,0,0,0,0,22,22,23,18,9,0
0,0,0,0,0,0,22,24,23,23,10,9,0
0,0,0,0,0,18,10,10,10,10,10,9,0
0,0,0,0,0,0,0,0,0,14,14,0,0
0,0,0,0,0,0,0,0,0,0,0,0,0
endlayer

layer
0,0,0,0,0,0,0,0,0,0,0,0,0
0,0,0,0,0,0,0,0,0,0,0,0,0
0,0,0,0,0,0,0,0,0,0,0,0,0
0,0,0,0,0,0,0,0,0,0,0,0,0
0,0,0,0,0,0,0,0,0,0,0,0,0
0,0,0,0,0,0,0,0,0,0,0,0,0
0,0,0,0,0,0,0,0,0,0,0,0,0
0,0,0,0,0,0,0,0,0,0,0,0,0
0,0,0,0,0,0,0,0,0,0,0,0,0
0,0,0,0,0,0,0,0,0,0,0,0,0
0,0,0,0,0,0,0,0,0,0,0,0,0
0,0,0,0,0,0,0,0,0,0,0,0,0
0,0,0,0,0,0,0,0,0,0,0,0,0
0,0,0,0,0,0,0,0,0,0,0,0,0
0,0,0,0,0,0,0,0,0,0,0,0,0
0,0,0,0,0,0,0,0,0,0,0,0,0
0,0,0,0,0,0,0,0,0,0,0,0,0
0,0,0,0,0,0,0,0,0,0,0,0,0
0,0,0,0,0,0,0,0,0,0,0,0,0
0,0,0,0,0,0,0,0,0,0,0,0,0
0,0,0,0,0,0,0,0,0,0,0,0,0
0,0,0,0,0,0,0,0,0,0,0,0,0
0,0,0,0,0,0,0,0,0,0,0,0,0
0,0,0,0,0,0,0,0,0,0,0,0,0
0,0,0,0,0,0,0,18,0,0,10,11,0
0,0,0,0,0,0,0,0,0,0,14,0,0
0,0,0,0,0,0,0,0,0,0,0,0,0
endlayer

layer
0,0,0,0,0,0,0,0,0,0,0,0,0
0,0,0,0,0,0,0,0,0,0,0,0,0
0,0,0,0,0,0,0,0,0,0,0,0,0
0,0,0,0,0,0,0,0,0,0,0,0,0
0,0,0,0,0,0,0,0,0,0,0,0,0
0,0,0,0,0,0,0,0,0,0,0,0,0
0,0,0,0,0,0,0,0,0,0,0,0,0
0,0,0,0,0,0,0,0,0,0,0,0,0
0,0,0,0,0,0,0,0,0,0,0,0,0
0,0,0,0,0,0,0,0,0,0,0,0,0
0,0,0,0,0,0,0,0,0,0,0,0,0
0,0,0,0,0,0,0,0,0,0,0,0,0
0,0,0,0,0,0,0,0,0,0,0,0,0
0,0,0,0,0,0,0,0,0,0,0,0,0
0,0,0,0,0,0,0,0,0,0,0,0,0
0,0,0,0,0,0,0,0,0,0,0,0,0
0,0,0,0,0,0,0,0,0,0,0,0,0
0,0,0,0,0,0,0,0,0,0,0,0,0
0,0,0,0,0,0,0,0,0,0,0,0,0
0,0,0,0,0,0,0,0,0,0,0,0,0
0,0,0,0,0,0,0,0,0,0,0,0,0
0,0,0,0,0,0,0,0,0,0,0,0,0
0,0,0,0,0,0,0,0,0,0,0,0,0
0,0,0,0,0,0,0,0,0,0,0,0,0
0,0,0,0,0,0,0,0,0,20,10,11,0
0,0,0,0,0,0,0,0,0,0,14,0,0
0,0,0,0,0,0,0,0,0,0,0,0,0
endlayer

layer
0,0,0,0,0,0,0,0,0,0,0,0,0
0,0,0,0,0,0,0,0,0,0,0,0,0
0,0,0,0,0,0,0,0,0,0,0,0,0
0,0,0,0,0,0,0,0,0,0,0,0,0
0,0,0,0,0,0,0,0,0,0,0,0,0
0,0,0,0,0,0,0,0,0,0,0,0,0
0,0,0,0,0,0,0,0,0,0,0,0,0
0,0,0,0,0,0,0,0,0,0,0,0,0
0,0,0,0,0,0,0,0,0,0,0,0,0
0,0,0,0,0,0,0,0,0,0,0,0,0
0,0,0,0,0,0,0,0,0,0,0,0,0
0,0,0,0,0,0,0,0,0,0,0,0,0
0,0,0,0,0,0,0,0,0,0,0,0,0
0,0,0,0,0,0,0,0,0,0,0,0,0
0,0,0,0,0,0,0,0,0,0,0,0,0
0,0,0,0,0,0,0,0,0,0,0,0,0
0,0,0,0,0,0,0,0,0,0,0,0,0
0,0,0,0,0,0,0,0,0,0,0,0,0
0,0,0,0,0,0,0,0,0,0,0,0,0
0,0,0,0,0,0,0,0,0,0,0,0,0
0,0,0,0,0,0,0,0,0,0,0,0,0
0,0,0,0,0,0,0,0,0,0,0,0,0
0,0,0,0,0,0,0,0,0,0,0,0,0
0,0,0,0,0,0,0,0,0,0,0,0,0
0,0,0,0,0,0,0,0,0,0,18,0,0
0,0,0,0,0,0,0,0,0,0,0,0,0
0,0,0,0,0,0,0,0,0,0,0,0,0
endlayer

