weight=6
dimensionsToSpawnIn=overworld
embed_into_distance=1
random_height_offset=0,0
unacceptable_target_blocks=sand,flowing_water,water,flowing_lava,lava,ice,packed_ice,stained_hardened_clay-9,brick_block,double_stone_slab,stonebrick,red_sandstone,red_nether_brick,red_mushroom_block,brown_mushroom_block,planks,cobblestone,end_stone,obsidian,purpur_block,iron_bars,purpur_slab,purpur_pillar,netherrack,soul_sand,quartz_ore,stained_glass,glass
dimensions=10,14,18
allowable_overhang=0
max_leveling=1
leveling_buffer=-1
preventRotation=0
preserve_water=0
preserve_lava=0
uniqueMinDistance=0
spawnMinDistance=0
spawnMaxDistance=0

rule1=0,100,minecraft:preserveBlock
rule2=0,100,minecraft:stone_slab-4
rule3=0,100,minecraft:brick_block-0,brick_block-0,brick_block-0,brick_block-0,brick_block-0,preserveBlock
rule4=0,100,minecraft:brick_stairs-2
rule5=0,100,minecraft:iron_bars-0
rule6=0,100,minecraft:vine-2
rule7=0,100,minecraft:vine-1
rule8=0,100,minecraft:vine-8
rule9=0,100,minecraft:brick_stairs-0
rule10=0,100,minecraft:vine-4
rule11=0,100,minecraft:brick_stairs-1
rule12=0,100,minecraft:brick_stairs-4
rule13=0,100,minecraft:stone_slab-12
rule14=0,100,minecraft:stone_slab-0

layer
1,1,1,1,1,1,1,1,1,1,1,1,1,1,1,1,1,1
1,3,3,3,3,3,3,3,3,3,2,1,1,1,1,1,1,1
1,3,3,3,3,3,3,3,3,3,3,3,3,3,3,3,4,1
1,3,3,3,3,3,3,3,3,3,3,3,3,3,3,3,4,1
1,3,3,3,3,3,3,3,3,3,3,3,3,3,3,3,3,1
1,3,3,3,3,3,3,3,3,3,3,3,3,3,3,3,3,1
1,3,3,3,3,3,3,3,3,3,3,3,3,3,3,3,3,1
1,3,3,3,3,3,3,3,3,3,3,3,3,3,3,3,2,1
1,3,3,3,3,3,3,3,3,3,3,3,3,3,3,3,2,1
1,3,3,3,3,3,3,3,3,3,3,3,3,3,3,3,2,1
1,3,3,3,3,3,3,3,3,3,3,3,3,3,3,3,3,1
1,3,3,3,3,3,3,3,3,3,3,3,3,3,3,3,2,1
1,3,3,3,3,3,3,3,3,3,3,3,3,3,3,3,3,1
1,1,1,1,1,1,1,1,1,1,1,1,1,1,1,1,1,1
endlayer

layer
1,1,1,1,1,1,1,1,1,1,1,1,1,1,1,1,1,1
1,3,3,3,3,3,3,3,3,5,0,1,1,1,1,1,1,1
1,3,0,0,6,0,0,6,0,0,0,5,5,5,5,5,0,1
1,3,7,0,0,0,0,0,0,0,0,0,0,0,0,0,0,1
1,3,0,0,0,8,0,0,0,0,0,0,0,8,0,0,0,1
1,3,0,9,9,3,0,0,0,0,0,0,0,3,0,0,5,1
1,3,7,0,0,3,0,0,0,0,0,0,10,3,7,0,5,1
1,3,0,0,0,3,0,0,0,0,0,0,0,3,7,0,0,1
1,3,7,0,0,3,0,0,0,0,0,0,0,0,0,0,0,1
1,3,0,0,0,3,0,0,0,0,0,0,0,0,0,5,5,1
1,3,0,0,0,3,7,0,0,0,0,0,0,0,0,5,5,1
1,3,0,0,0,3,0,0,8,0,0,0,0,0,0,0,0,1
1,3,3,3,3,3,3,3,3,3,3,3,5,5,5,5,5,1
1,1,1,1,1,1,1,1,1,1,1,1,1,1,1,1,1,1
endlayer

layer
1,0,8,0,8,8,8,0,0,0,0,0,1,1,1,1,1,1
10,3,0,0,3,3,3,3,0,5,0,0,0,1,1,1,1,1
10,3,0,0,6,0,6,6,0,0,0,5,5,5,0,0,0,1
0,3,7,0,0,0,0,0,0,0,0,0,0,0,0,0,0,1
10,3,0,0,0,8,0,0,0,0,0,0,0,0,0,0,0,0
10,0,0,0,0,11,0,0,0,0,0,0,10,3,7,0,5,0
10,3,7,9,9,2,7,0,0,0,0,0,10,3,7,0,5,0
0,3,7,0,0,2,0,0,0,0,0,0,10,3,7,0,0,0
10,3,7,0,0,3,0,0,0,0,0,0,0,0,0,0,0,0
10,0,0,0,0,3,0,0,0,0,0,0,0,0,0,5,5,0
0,0,0,0,10,3,7,0,0,0,0,0,0,0,0,5,5,1
10,3,0,0,0,3,0,8,8,0,0,0,0,0,0,0,0,1
0,3,0,0,3,3,0,3,3,0,0,3,5,0,5,5,0,1
1,6,6,0,6,0,6,6,0,6,6,0,0,1,1,1,1,1
endlayer

layer
0,8,8,8,0,8,8,8,0,0,0,0,0,0,0,0,0,1
10,3,0,0,2,3,3,3,0,5,0,0,0,0,0,0,0,0
10,3,0,0,0,0,6,6,0,0,0,5,0,0,0,0,0,0
10,3,7,0,0,0,0,0,0,0,0,0,0,0,0,0,0,0
10,3,0,0,0,8,0,0,0,0,0,0,0,8,0,0,0,0
10,0,0,0,0,3,0,0,0,0,0,0,10,3,7,0,5,0
10,3,0,0,0,3,7,0,0,0,0,0,0,3,7,0,5,0
10,3,7,9,9,3,0,0,0,0,0,0,10,3,0,0,0,0
10,3,0,0,0,12,0,0,0,0,0,0,0,0,0,0,0,0
10,0,0,0,0,9,0,0,0,0,0,0,0,0,0,5,5,0
0,0,0,0,10,3,7,0,0,0,0,0,0,0,0,5,5,0
10,3,0,0,0,3,0,8,8,0,0,0,0,0,0,0,0,0
10,3,0,0,13,3,0,3,3,0,0,3,5,0,5,5,0,0
0,6,6,0,6,6,6,6,6,6,6,6,0,0,0,0,0,1
endlayer

layer
0,8,8,8,0,8,8,0,0,0,0,0,0,0,0,0,0,0
10,3,3,3,3,3,3,9,2,0,0,0,0,0,0,0,0,0
0,3,3,3,3,3,3,3,3,5,0,0,0,0,0,0,0,0
10,3,3,13,3,3,3,3,3,5,5,0,0,0,0,0,0,0
10,3,3,13,13,3,3,3,3,3,5,0,0,8,0,0,0,0
10,3,3,0,0,3,3,3,3,3,5,0,10,3,7,0,0,0
10,3,3,0,0,3,3,3,3,3,5,5,5,3,7,0,0,0
10,3,3,0,0,3,3,3,3,3,3,5,10,3,0,0,0,0
10,3,3,2,2,3,3,3,3,3,3,5,0,0,0,0,0,0
10,3,3,0,0,3,3,3,3,3,3,0,0,0,0,0,0,0
10,3,3,2,10,3,3,3,3,3,3,5,5,5,0,0,0,0
10,3,3,3,2,3,3,3,3,3,3,0,0,0,0,0,0,0
10,3,3,3,3,3,3,3,3,3,3,4,2,0,0,0,0,0
0,6,6,6,6,6,6,0,6,6,6,0,0,0,0,0,0,0
endlayer

layer
0,8,0,8,0,0,0,0,0,0,0,0,0,0,0,0,0,0
10,3,3,3,5,5,5,0,0,0,0,0,0,0,0,0,0,0
10,3,0,6,0,0,0,0,0,0,0,0,0,0,0,0,0,0
10,3,7,0,0,0,0,0,0,0,0,0,0,0,0,0,0,0
10,3,0,0,0,0,0,0,0,0,0,0,0,0,0,0,0,0
10,3,0,0,0,0,0,0,0,0,0,0,10,3,7,0,0,0
10,3,7,0,0,0,0,0,0,0,0,0,0,5,0,0,0,0
10,3,7,0,0,0,0,0,0,0,0,0,0,5,0,0,0,0
0,3,0,0,0,0,0,0,0,0,0,0,0,0,0,0,0,0
10,3,0,0,0,0,0,0,0,0,0,0,0,0,0,0,0,0
10,3,0,0,0,0,0,0,0,0,0,0,0,0,0,0,0,0
10,3,7,0,0,8,0,0,0,0,0,0,0,0,0,0,0,0
0,3,3,2,3,3,3,5,5,5,5,0,0,0,0,0,0,0
0,6,6,6,0,6,6,0,0,0,0,0,0,0,0,0,0,0
endlayer

layer
0,8,8,8,0,0,0,0,0,0,0,0,0,0,0,0,0,0
10,3,3,3,7,5,5,0,0,0,0,0,0,0,0,0,0,0
10,3,6,6,0,0,0,0,0,0,0,0,0,0,0,0,0,0
0,3,7,0,0,0,0,0,0,0,0,0,0,0,0,0,0,0
10,3,0,0,0,0,0,0,0,0,0,0,0,8,0,0,0,0
10,8,0,0,0,0,0,0,0,0,0,0,10,3,7,0,0,0
10,3,0,0,0,0,0,0,0,0,0,0,0,5,0,0,0,0
10,3,7,0,0,0,0,0,0,0,0,0,0,5,0,0,0,0
10,3,0,0,0,0,0,0,0,0,0,0,0,0,0,0,0,0
10,0,0,0,0,0,0,0,0,0,0,0,0,0,0,0,0,0
10,8,0,0,0,0,0,0,0,0,0,0,0,0,0,0,0,0
10,3,7,0,0,8,0,0,0,0,0,0,0,0,0,0,0,0
10,3,0,0,3,3,7,0,5,5,0,0,0,0,0,0,0,0
0,6,0,6,6,6,0,0,0,0,0,0,0,0,0,0,0,0
endlayer

layer
0,8,8,8,0,0,0,0,0,0,0,0,0,0,0,0,0,0
10,3,3,3,7,5,5,0,0,0,0,0,0,0,0,0,0,0
10,3,6,6,0,0,0,0,0,0,0,0,0,0,0,0,0,0
10,3,7,0,0,0,0,0,0,0,0,0,0,0,0,0,0,0
10,3,0,0,0,0,0,0,0,0,0,0,0,0,0,0,0,0
10,8,0,0,0,0,0,0,0,0,0,0,0,5,0,0,0,0
10,3,7,0,0,0,0,0,0,0,0,0,0,5,0,0,0,0
10,3,7,0,0,0,0,0,0,0,0,0,0,0,0,0,0,0
10,3,0,0,0,0,0,0,0,0,0,0,0,0,0,0,0,0
10,0,0,0,0,0,0,0,0,0,0,0,0,0,0,0,0,0
10,8,0,0,0,0,0,0,0,0,0,0,0,0,0,0,0,0
10,3,7,0,8,8,0,0,0,0,0,0,0,0,0,0,0,0
10,3,0,0,3,3,7,0,5,0,0,0,0,0,0,0,0,0
0,6,0,6,6,6,0,0,0,0,0,0,0,0,0,0,0,0
endlayer

layer
0,0,8,0,0,0,0,0,0,0,0,0,0,0,0,0,0,0
10,3,3,4,0,0,0,0,0,0,0,0,0,0,0,0,0,0
10,3,3,3,2,2,2,2,0,0,0,0,0,0,0,0,0,0
10,3,3,3,3,0,0,0,0,0,0,0,0,0,0,0,0,0
10,3,3,3,3,5,5,5,5,5,0,0,0,0,0,0,0,0
10,3,3,3,3,5,5,5,0,0,0,0,0,0,0,0,0,0
10,3,3,3,3,3,5,5,5,0,0,0,0,0,0,0,0,0
0,3,3,3,3,3,5,0,0,0,0,0,0,0,0,0,0,0
10,3,3,3,3,3,2,2,2,2,0,0,0,0,0,0,0,0
10,3,3,3,3,3,3,5,5,5,5,5,0,0,0,0,0,0
10,3,3,3,3,3,3,5,0,0,0,0,0,0,0,0,0,0
10,3,3,3,3,3,3,5,0,0,0,0,0,0,0,0,0,0
0,11,11,3,3,11,3,5,0,0,0,0,0,0,0,0,0,0
0,0,0,6,6,0,0,0,0,0,0,0,0,0,0,0,0,0
endlayer

layer
0,0,0,0,0,0,0,0,0,0,0,0,0,0,0,0,0,0
0,14,14,14,0,0,0,0,0,0,0,0,0,0,0,0,0,0
0,14,0,0,0,0,0,0,0,0,0,0,0,0,0,0,0,0
0,14,0,0,0,0,0,0,0,0,0,0,0,0,0,0,0,0
0,14,0,0,0,0,0,0,0,0,0,0,0,0,0,0,0,0
0,14,0,0,0,0,0,0,0,0,0,0,0,0,0,0,0,0
0,14,0,0,0,0,0,0,0,0,0,0,0,0,0,0,0,0
0,14,0,0,0,0,0,0,0,0,0,0,0,0,0,0,0,0
0,14,0,0,0,0,0,0,0,0,0,0,0,0,0,0,0,0
0,14,0,0,0,0,0,0,0,0,0,0,0,0,0,0,0,0
0,14,0,0,0,0,0,0,0,0,0,0,0,0,0,0,0,0
0,14,0,0,0,0,0,0,0,0,0,0,0,0,0,0,0,0
0,14,14,14,14,14,0,0,0,0,0,0,0,0,0,0,0,0
0,0,0,0,0,0,0,0,0,0,0,0,0,0,0,0,0,0
endlayer

