weight=5
dimensionsToSpawnIn=overworld
embed_into_distance=2
random_height_offset=0,0
unacceptable_target_blocks=sand,flowing_water,water,flowing_lava,lava,ice,packed_ice,stained_hardened_clay-9,brick_block,double_stone_slab,stonebrick,red_sandstone,red_nether_brick,red_mushroom_block,brown_mushroom_block,planks,cobblestone,end_stone,obsidian,purpur_block,iron_bars,purpur_slab,purpur_pillar,netherrack,soul_sand,quartz_ore,stained_glass,glass
dimensions=62,15,15
allowable_overhang=0
max_leveling=2
leveling_buffer=-1
preventRotation=0
preserve_water=0
preserve_lava=0
uniqueMinDistance=500
spawnMinDistance=0
spawnMaxDistance=0

rule1=0,100,preserveBlock
rule2=0,100,chisel:technical-12
rule3=0,100,chisel:ironpane-2,chisel:ironpane-2,chisel:ironpane-2,chisel:ironpane-2,chisel:ironpane-2,chisel:ironpane-2,chisel:ironpane-2,chisel:ironpane-2,chisel:ironpane-2,chisel:ironpane-2,preserveBlock
rule4=0,100,concrete-14
rule5=0,100,vine-8
rule6=0,100,vine-1
rule7=0,100,vine-4
rule8=0,100,vine-2
rule9=0,100,vine-10
rule10=0,100,ladder-4
rule11=0,100,stone_slab-0
rule12=0,100,concrete-0
rule13=0,100,vine-3
rule14=0,100,quartz_stairs-6
rule15=0,100,quartz_block-0
rule16=0,100,quartz_stairs-7
rule17=0,100,vine-6
rule18=0,100,cobblestone_wall-0
rule19=0,100,quartz_stairs-2
rule20=0,100,quartz_stairs-3
rule21=0,100,quartz_stairs-4
rule22=0,100,quartz_stairs-5
rule23=0,100,cobblestone_wall-1
rule24=0,100,quartz_stairs-0
rule25=0,100,quartz_stairs-1
rule26=0,100,stone_slab-13
rule27=0,100,vine-5
rule28=0,100,vine-12
rule29=0,100,vine-9
rule30=0,100,IInventory;minecraft:chest;minecraft:iron_nugget#1#0#2+minecraft:web#1#0#3+minecraft:comparator#1#0#5+minecraft:iron_nugget#1#0#8+minecraft:iron_nugget#1#0#9+minecraft:repeater#2#0#10+minecraft:quartz#2#0#11+minecraft:diamond#1#0#14+minecraft:repeater#1#0#16+minecraft:quartz#1#0#19+minecraft:iron_nugget#2#0#20+minecraft:repeater#1#0#22+minecraft:iron_nugget#3#0#24-5,IInventory;minecraft:chest;minecraft:iron_nugget#1#0#1+minecraft:quartz#1#0#2+minecraft:repeater#1#0#4+minecraft:quartz#2#0#6+minecraft:iron_nugget#1#0#7+minecraft:repeater#1#0#9+minecraft:repeater#2#0#11+minecraft:web#1#0#13+minecraft:iron_nugget#1#0#14+minecraft:iron_nugget#2#0#15+minecraft:iron_nugget#1#0#17+minecraft:quartz#1#0#18+minecraft:comparator#1#0#19+minecraft:iron_nugget#3#0#21+minecraft:repeater#1#0#24-5,IInventory;minecraft:chest;minecraft:iron_nugget#1#0#1+minecraft:quartz#2#0#4+minecraft:repeater#1#0#5+minecraft:iron_nugget#1#0#7+minecraft:comparator#1#0#10+minecraft:iron_nugget#1#0#11+minecraft:diamond#1#0#12+minecraft:iron_nugget#1#0#14+minecraft:repeater#1#0#15+minecraft:iron_nugget#3#0#16+minecraft:repeater#1#0#17+minecraft:repeater#1#0#18+minecraft:quartz#1#0#21+minecraft:iron_nugget#1#0#22+minecraft:web#1#0#24-5,IInventory;minecraft:chest;minecraft:iron_nugget#1#0#0+minecraft:repeater#4#0#2+minecraft:comparator#1#0#4+minecraft:web#1#0#8+minecraft:iron_nugget#1#0#10+minecraft:iron_nugget#2#0#12+minecraft:quartz#2#0#14+minecraft:repeater#1#0#15+minecraft:iron_nugget#2#0#19+minecraft:iron_nugget#1#0#22+minecraft:iron_nugget#1#0#24+minecraft:quartz#1#0#25-5,IInventory;minecraft:chest;minecraft:iron_nugget#1#0#1+minecraft:iron_nugget#3#0#5+minecraft:iron_nugget#1#0#6+minecraft:iron_nugget#2#0#10+minecraft:quartz#2#0#11+minecraft:iron_nugget#1#0#12+minecraft:repeater#1#0#13+minecraft:iron_nugget#1#0#15+minecraft:web#1#0#16+minecraft:iron_nugget#1#0#18+minecraft:comparator#1#0#20+minecraft:diamond#1#0#23+minecraft:repeater#1#0#26-5,air,air,air
rule31=0,100,chisel:blockcopper-4,chisel:technical1-0,chisel:technical1-0

layer
1,1,1,1,1,1,1,1,1,1,1,1,1,1,1
1,2,2,2,2,2,2,2,2,2,2,2,2,2,1
1,2,1,1,1,1,1,1,1,1,1,1,1,2,1
1,2,1,1,1,1,1,1,1,1,1,1,1,2,1
1,2,1,1,4,1,1,1,1,1,4,1,1,2,1
1,2,1,1,1,1,1,1,1,1,1,1,1,2,1
1,2,1,1,1,1,1,1,1,1,1,1,1,2,1
1,2,1,1,1,1,1,2,1,1,1,1,1,2,1
1,2,1,1,1,1,1,1,1,1,1,1,1,2,1
1,2,1,1,1,1,1,1,1,1,1,1,1,2,1
1,2,1,1,4,1,1,1,1,1,4,1,1,2,1
1,2,1,1,1,1,1,1,1,1,1,1,1,2,1
1,2,1,1,1,1,1,1,1,1,1,1,1,2,1
1,2,2,2,2,2,2,2,2,2,2,2,2,2,1
1,1,1,1,1,1,1,1,1,1,1,1,1,1,1
endlayer

layer
1,1,1,1,1,1,1,1,1,1,1,1,1,1,1
1,2,2,2,2,2,2,2,2,2,2,2,2,2,1
1,2,1,1,1,1,1,1,1,1,1,1,1,2,1
1,2,1,1,1,1,1,1,1,1,1,1,1,2,1
1,2,1,1,4,1,1,1,1,1,4,1,1,2,1
1,2,1,1,1,1,1,1,1,1,1,1,1,2,1
1,2,1,1,1,1,1,1,1,1,1,1,1,2,1
1,2,1,1,1,1,1,2,1,1,1,1,1,2,1
1,2,1,1,1,1,1,1,1,1,1,1,1,2,1
1,2,1,1,1,1,1,1,1,1,1,1,1,2,1
1,2,1,1,4,1,1,1,1,1,4,1,1,2,1
1,2,1,1,1,1,1,1,1,1,1,1,1,2,1
1,2,1,1,1,1,1,1,1,1,1,1,1,2,1
1,2,2,2,2,2,2,2,2,2,2,2,2,2,1
1,1,1,1,1,1,1,1,1,1,1,1,1,1,1
endlayer

layer
1,1,1,1,1,1,1,1,1,1,1,1,1,1,1
1,2,3,3,3,3,3,2,3,3,3,3,3,2,1
1,3,1,1,1,1,1,1,1,1,1,1,1,3,1
1,3,1,1,1,1,1,1,1,1,1,1,1,3,1
1,3,1,1,4,1,1,1,1,1,4,1,1,3,1
1,3,1,1,1,1,1,1,1,1,1,1,1,3,1
1,3,1,1,1,1,1,1,1,1,1,1,1,3,1
1,2,1,1,1,1,1,2,1,1,1,1,1,2,1
1,3,1,1,1,1,1,1,1,1,1,1,1,3,1
1,3,1,1,1,1,1,1,1,1,1,1,1,3,1
1,3,1,1,4,1,1,1,1,1,4,1,1,3,1
1,3,1,1,1,1,1,1,1,1,1,1,1,3,1
1,3,1,1,1,1,1,1,1,1,1,1,1,3,1
1,2,3,3,3,3,3,2,3,3,3,3,3,2,1
1,1,1,1,1,1,1,1,1,1,1,1,1,1,1
endlayer

layer
1,5,0,0,0,0,0,5,0,0,0,0,0,5,1
7,2,3,3,3,3,3,2,3,3,3,3,3,2,6
0,3,0,0,0,0,0,8,0,0,0,0,0,3,0
0,3,0,0,0,0,5,0,5,0,5,0,0,3,0
0,3,0,7,4,4,0,0,0,4,4,0,0,3,0
0,3,0,0,4,6,0,8,8,0,4,0,0,3,0
0,3,0,7,0,6,0,0,0,7,0,0,0,3,0
7,2,6,0,0,0,0,2,0,0,0,0,7,2,6
0,3,0,0,0,0,0,0,0,0,0,6,0,3,0
0,3,0,7,4,5,5,0,5,0,4,0,0,3,0
0,3,0,0,4,4,0,0,0,4,4,6,0,3,0
0,3,0,0,0,8,8,0,9,8,9,0,0,3,0
0,3,0,0,0,0,0,5,0,0,0,0,0,3,0
7,2,3,3,3,3,3,2,3,3,3,3,3,2,6
1,8,0,0,0,0,0,8,0,0,0,0,0,0,1
endlayer

layer
0,5,0,0,0,0,0,5,0,0,0,0,0,5,0
7,2,3,3,3,3,3,2,3,3,3,3,3,2,6
0,3,0,0,0,0,0,8,0,0,0,0,0,3,0
0,3,0,0,0,5,5,0,5,5,5,0,0,3,0
0,3,0,7,4,6,4,0,4,6,4,0,0,3,0
0,3,0,0,0,6,0,8,8,0,0,6,0,3,0
0,3,0,7,4,6,0,10,0,7,4,0,0,3,0
7,2,6,7,0,0,0,2,0,0,0,6,7,2,6
0,3,0,7,4,0,0,0,0,0,4,6,0,3,0
0,3,0,7,5,5,5,0,5,0,0,0,0,3,0
0,3,0,0,4,6,4,0,4,0,4,6,0,3,0
0,3,0,0,0,8,8,0,9,8,9,0,0,3,0
0,3,0,0,0,0,0,5,0,0,0,0,0,3,0
7,2,3,3,3,3,3,2,3,3,3,3,3,2,6
0,8,0,0,0,0,0,8,0,0,0,0,0,0,0
endlayer

layer
0,0,0,0,0,0,0,0,0,0,0,0,0,0,0
0,11,0,0,0,0,0,11,5,5,0,0,0,11,0
0,0,0,0,0,0,0,0,0,0,0,0,0,0,0
0,0,0,0,5,5,5,5,5,5,5,0,0,0,0
0,0,0,7,4,6,0,4,0,6,4,0,0,0,0
0,7,0,7,0,6,0,8,8,0,0,6,0,0,0
0,0,0,0,5,6,0,10,0,7,0,0,0,0,0
0,11,0,7,4,0,0,2,0,0,4,6,0,11,0
0,0,0,7,0,0,0,0,0,0,8,6,0,0,0
0,0,0,7,5,5,5,0,0,0,0,0,0,0,0
0,0,0,7,4,6,0,4,0,0,4,6,0,0,0
0,0,0,0,8,8,0,0,9,8,9,0,0,0,0
0,0,0,0,0,0,0,0,0,0,0,0,0,0,0
0,11,0,0,0,0,0,11,0,8,0,0,0,11,0
0,0,0,0,0,0,0,0,0,0,0,0,0,0,0
endlayer

layer
0,0,0,0,0,0,0,0,0,0,0,0,0,0,0
0,0,0,0,0,0,0,5,5,5,0,0,0,0,0
0,0,0,0,0,0,0,0,0,0,0,0,0,0,0
0,0,0,0,5,5,5,0,5,5,5,0,0,0,0
0,0,0,7,4,6,4,0,4,6,4,6,0,0,0
0,7,0,7,0,6,0,8,8,0,0,6,0,0,0
0,0,0,0,4,6,0,10,0,7,4,0,0,0,0
0,0,0,7,0,6,0,2,0,0,0,0,0,0,0
0,0,0,7,4,0,0,0,0,0,4,6,0,0,0
0,0,0,7,5,5,5,0,0,0,0,6,0,0,0
0,0,0,7,4,6,4,7,4,0,4,6,0,0,0
0,0,0,0,8,8,0,0,9,8,9,0,0,0,0
0,0,0,0,0,0,0,0,0,0,0,0,0,0,0
0,0,0,0,0,0,0,0,0,8,0,0,0,0,0
0,0,0,0,0,0,0,0,0,0,0,0,0,0,0
endlayer

layer
0,0,0,0,0,0,0,0,0,0,0,0,0,0,0
0,0,0,0,0,0,0,5,5,5,0,0,0,0,0
0,0,0,0,0,0,0,0,0,0,0,0,0,0,0
0,0,0,0,5,5,5,5,5,5,5,0,0,0,0
0,0,0,7,4,4,0,0,0,4,4,6,0,0,0
0,7,0,7,4,6,0,8,0,0,4,6,0,0,0
0,0,0,7,0,6,0,0,0,7,0,0,0,0,0
0,0,0,7,0,6,0,2,0,7,0,0,0,0,0
0,0,0,7,0,0,0,0,0,0,0,6,0,0,0
0,0,0,7,4,5,5,0,0,0,4,6,0,0,0
0,0,0,7,4,4,0,0,0,4,4,6,0,0,0
0,0,0,0,8,8,8,0,9,8,9,0,0,0,0
0,0,0,0,0,0,0,0,0,0,0,0,0,0,0
0,0,0,0,0,0,0,0,0,8,0,0,0,0,0
0,0,0,0,0,0,0,0,0,0,0,0,0,0,0
endlayer

layer
0,0,0,0,0,0,0,0,0,0,0,0,0,0,0
0,0,0,0,0,0,0,5,5,5,0,0,0,0,0
0,0,0,0,0,0,0,0,0,0,0,0,0,0,0
0,0,0,0,5,5,5,5,5,5,5,0,0,0,0
0,0,0,7,4,0,0,0,0,0,4,6,0,0,0
0,7,0,7,8,6,0,8,0,0,8,6,0,0,0
0,0,0,7,0,6,0,0,0,7,0,0,0,0,0
0,0,0,7,0,6,0,2,0,7,0,6,0,0,0
0,0,0,7,0,0,0,0,0,0,0,6,0,0,0
0,0,0,7,0,5,5,0,0,0,5,6,0,0,0
0,0,0,7,4,0,0,0,0,7,4,6,0,0,0
0,0,0,0,8,8,8,0,9,0,9,0,0,0,0
0,0,0,0,0,0,0,0,0,0,0,0,0,0,0
0,0,0,0,0,0,0,0,8,8,0,0,0,0,0
0,0,0,0,0,0,0,0,0,0,0,0,0,0,0
endlayer

layer
0,0,0,0,0,0,0,0,0,0,0,0,0,0,0
0,0,0,0,0,0,0,5,5,5,0,0,0,0,0
0,0,0,0,0,0,7,0,0,0,6,0,0,0,0
0,0,0,0,5,5,5,5,5,5,5,0,0,0,0
0,0,0,7,4,4,4,4,4,4,4,6,0,0,0
0,7,0,7,4,6,0,8,0,0,4,6,0,0,0
0,7,0,7,4,6,0,10,0,7,4,0,0,0,0
0,7,0,7,4,6,0,2,0,7,4,6,0,0,0
0,0,0,7,4,0,0,0,0,0,4,6,0,0,0
0,0,0,7,4,5,5,0,0,0,4,6,0,0,0
0,0,0,7,4,4,4,4,4,4,4,6,0,0,0
0,0,0,0,8,8,8,0,9,0,9,0,0,0,0
0,0,0,0,0,0,0,0,0,0,0,0,0,0,0
0,0,0,0,0,0,0,0,8,8,8,0,0,0,0
0,0,0,0,0,0,0,0,0,0,0,0,0,0,0
endlayer

layer
0,0,0,0,0,0,0,0,0,0,0,0,0,0,0
0,0,0,0,0,0,0,5,5,5,0,0,0,0,0
0,0,0,0,0,0,7,0,0,0,6,0,0,0,0
0,0,0,0,5,5,5,0,0,5,5,0,0,0,0
0,0,0,7,12,6,0,0,0,0,12,6,0,0,0
0,7,0,7,0,13,0,0,0,0,0,6,0,0,0
0,7,0,7,0,6,0,0,0,7,0,6,0,0,0
0,7,0,0,0,0,0,2,0,7,0,6,0,0,0
0,0,0,7,0,0,0,0,0,0,0,6,0,0,0
0,0,0,7,5,5,0,0,0,0,5,6,0,0,0
0,0,0,7,12,0,6,7,0,0,12,6,0,0,0
0,0,0,0,8,8,8,0,9,0,9,0,0,0,0
0,0,0,0,0,0,0,0,0,0,0,0,0,0,0
0,0,0,0,0,0,0,0,8,8,8,0,0,0,0
0,0,0,0,0,0,0,0,0,0,0,0,0,0,0
endlayer

layer
0,0,0,0,0,0,0,0,0,0,0,0,0,0,0
0,0,0,0,0,0,0,5,5,5,0,0,0,0,0
0,0,0,0,0,0,7,16,15,14,6,0,0,0,0
0,0,0,0,5,5,5,0,0,5,5,0,0,0,0
0,0,0,7,12,12,0,0,0,12,12,6,0,0,0
0,7,0,7,12,13,0,8,0,17,12,6,0,0,0
0,7,0,7,0,6,0,10,0,7,0,6,0,0,0
0,7,0,0,0,0,0,2,0,7,0,6,0,0,0
0,0,0,7,0,0,0,0,0,0,0,6,0,0,0
0,0,0,7,12,5,0,5,0,0,12,6,0,0,0
0,0,0,7,12,12,6,7,0,12,12,6,0,0,0
0,0,0,0,8,8,8,0,9,0,9,0,0,0,0
0,0,0,0,0,0,0,7,0,0,0,0,0,0,0
0,0,0,0,0,0,0,0,8,8,8,0,0,0,0
0,0,0,0,0,0,0,0,0,0,0,0,0,0,0
endlayer

layer
0,0,0,0,0,0,0,0,0,0,0,0,0,0,0
0,0,0,0,0,0,0,5,5,5,0,0,0,0,0
0,0,0,0,0,0,7,15,15,15,6,0,0,0,0
0,0,0,0,5,5,5,0,18,5,5,0,0,0,0
0,0,0,7,12,7,12,0,12,6,12,6,0,0,0
0,7,0,7,5,13,0,8,0,17,8,6,0,0,0
0,7,0,7,12,6,0,10,0,7,12,6,0,0,0
0,7,0,0,0,0,0,2,0,7,0,6,0,0,0
0,0,0,7,12,0,0,0,0,7,12,6,0,0,0
0,0,0,7,5,5,0,5,0,0,5,6,0,0,0
0,0,0,7,12,0,12,7,12,0,12,6,0,0,0
0,0,0,0,8,0,8,0,9,0,9,0,0,0,0
0,0,0,0,0,0,0,7,0,0,0,0,0,0,0
0,0,0,0,0,0,0,0,8,8,8,0,0,0,0
0,0,0,0,0,0,0,0,0,0,0,0,0,0,0
endlayer

layer
0,0,0,0,0,0,0,0,0,0,0,0,0,0,0
0,0,0,0,0,0,0,0,5,0,0,0,0,0,0
0,0,0,0,0,0,0,20,15,19,0,0,0,0,0
0,0,0,0,5,5,5,0,5,5,5,0,0,0,0
0,0,0,7,12,7,7,12,6,6,12,6,0,0,0
0,7,0,7,5,13,0,8,8,17,8,6,0,0,0
0,7,0,7,0,6,0,0,0,7,5,6,0,0,0
0,7,0,0,12,0,0,2,0,7,12,6,0,0,0
0,0,0,7,0,0,0,0,0,7,0,0,0,0,0
0,0,0,7,5,5,5,5,0,0,5,6,0,0,0
0,0,0,7,12,0,0,12,0,0,12,6,0,0,0
0,0,0,0,8,0,8,0,9,0,9,0,0,0,0
0,0,0,0,0,0,0,7,0,0,0,6,0,0,0
0,0,0,0,0,0,0,0,8,8,8,0,0,0,0
0,0,0,0,0,0,0,0,0,0,0,0,0,0,0
endlayer

layer
0,0,0,0,0,0,0,0,0,0,0,0,0,0,0
0,0,0,0,0,0,0,0,0,0,0,0,0,0,0
0,0,0,0,0,0,0,0,0,0,0,0,0,0,0
0,0,0,0,5,5,5,0,5,5,5,0,0,0,0
0,0,0,7,12,7,12,0,12,6,12,6,0,0,0
0,7,0,7,5,13,0,8,8,17,8,6,0,0,0
0,7,0,7,12,6,0,0,0,7,12,6,0,0,0
0,7,0,7,0,0,0,2,0,0,0,0,0,0,0
0,0,8,7,12,0,0,0,0,7,12,6,0,0,0
0,0,0,7,5,5,5,5,0,0,5,6,0,0,0
0,0,0,7,12,0,12,0,12,0,12,6,0,0,0
0,0,0,0,8,0,8,8,9,0,9,0,0,0,0
0,0,0,0,0,0,0,7,16,15,14,6,0,0,0
0,0,0,0,0,0,0,0,8,8,8,0,0,0,0
0,0,0,0,0,0,0,0,0,0,0,0,0,0,0
endlayer

layer
0,0,0,0,0,0,0,0,0,0,0,0,0,0,0
0,0,0,0,0,0,0,0,0,0,0,0,0,0,0
0,0,0,0,0,0,0,0,0,0,0,0,0,0,0
0,0,0,0,5,5,5,0,5,5,5,0,0,0,0
0,0,0,7,12,12,0,0,0,12,12,6,0,0,0
0,7,0,7,12,13,0,8,8,17,12,6,0,0,0
0,7,0,7,0,6,0,10,0,7,0,6,0,0,0
0,7,0,7,0,0,0,2,0,0,0,0,0,0,0
0,0,8,7,0,0,0,0,0,7,0,6,0,0,0
0,0,0,7,12,5,5,5,0,0,12,6,0,0,0
0,0,0,7,12,12,0,0,7,12,12,6,0,0,0
0,0,0,0,8,0,8,8,9,18,9,0,0,0,0
0,0,0,0,0,0,0,7,15,15,15,6,0,0,0
0,0,0,0,0,0,0,0,8,8,8,0,0,0,0
0,0,0,0,0,0,0,0,0,0,0,0,0,0,0
endlayer

layer
0,0,0,0,0,0,0,0,0,0,0,0,0,0,0
0,0,0,0,0,0,0,0,0,0,0,0,0,0,0
0,0,0,0,0,0,0,0,0,0,0,0,0,0,0
0,0,0,0,5,5,5,0,5,5,5,0,0,0,0
0,0,0,7,12,6,0,0,0,0,12,6,0,0,0
0,7,0,0,0,13,0,8,8,17,0,6,0,0,0
0,7,0,7,0,6,0,10,0,7,0,6,0,0,0
0,7,0,7,0,0,0,2,0,0,0,0,0,0,0
0,0,8,7,0,0,0,0,0,7,0,6,0,0,0
0,0,0,7,0,5,5,5,0,0,5,6,0,0,0
0,0,0,7,12,6,0,0,0,7,12,6,0,0,0
0,0,0,0,8,0,8,8,8,8,8,0,0,0,0
0,0,0,0,0,0,0,0,20,15,19,0,0,0,0
0,0,0,0,0,0,0,0,0,8,0,0,0,0,0
0,0,0,0,0,0,0,0,0,0,0,0,0,0,0
endlayer

layer
0,0,0,0,0,0,0,0,0,0,0,0,0,0,0
0,0,0,0,0,0,0,0,0,0,0,0,0,0,0
0,0,0,0,0,0,0,0,0,0,0,0,0,0,0
0,0,0,0,5,5,5,0,5,5,5,0,0,0,0
0,0,5,7,12,12,12,12,12,12,12,6,0,0,0
0,7,0,0,12,13,0,8,8,17,12,6,0,0,0
0,7,0,7,12,6,0,0,0,7,12,6,0,0,0
0,7,0,7,12,0,0,2,0,0,12,0,0,0,0
0,0,8,7,12,0,0,0,0,7,12,6,0,0,0
0,0,0,7,12,5,5,5,0,0,12,6,0,0,0
0,0,0,7,12,12,12,12,12,12,12,6,0,0,0
0,0,0,0,8,0,8,8,8,8,8,0,0,0,0
0,0,0,0,0,0,0,0,0,0,0,0,0,0,0
0,0,0,0,0,0,0,0,0,0,0,0,0,0,0
0,0,0,0,0,0,0,0,0,0,0,0,0,0,0
endlayer

layer
0,0,0,0,0,0,0,0,0,0,0,0,0,0,0
0,0,0,0,0,0,0,0,0,0,0,0,0,0,0
0,0,0,0,0,0,0,0,0,0,0,0,0,0,0
0,0,0,0,5,0,5,0,0,5,5,0,0,0,0
0,0,5,7,4,0,0,0,0,7,4,6,0,0,0
0,7,0,0,0,6,0,8,8,17,0,6,0,0,0
0,7,0,0,0,6,0,0,0,7,8,0,0,0,0
0,7,0,0,0,0,0,2,0,0,8,0,0,0,0
0,0,8,7,0,0,0,0,0,7,0,6,0,0,0
0,0,0,0,5,5,5,5,0,0,0,6,0,0,0
0,0,7,7,4,0,0,0,0,0,4,6,0,0,0
0,0,0,0,8,0,8,8,0,8,8,0,0,0,0
0,0,0,0,0,0,0,0,0,0,0,0,0,0,0
0,0,0,0,0,0,0,0,0,0,0,0,0,0,0
0,0,0,0,0,0,0,0,0,0,0,0,0,0,0
endlayer

layer
0,0,0,0,0,0,0,0,0,0,0,0,0,0,0
0,0,0,0,0,0,0,0,0,0,0,0,0,0,0
0,0,0,0,0,0,0,0,0,0,0,0,0,0,0
0,0,0,0,5,0,5,0,0,5,5,0,0,0,0
0,0,5,7,4,4,0,0,0,4,4,6,0,0,0
0,7,21,0,4,6,0,8,8,17,4,6,0,0,0
0,7,15,0,0,6,0,10,0,7,8,0,0,0,0
0,7,22,0,0,0,0,2,0,0,8,0,0,0,0
0,0,8,7,0,0,0,0,0,7,0,6,0,0,0
0,0,0,0,4,5,5,5,0,0,4,6,0,0,0
0,0,7,7,4,4,0,0,0,4,4,6,0,0,0
0,0,0,0,8,0,8,8,0,8,8,0,0,0,0
0,0,0,0,0,0,0,0,0,0,0,0,0,0,0
0,0,0,0,0,0,0,0,0,0,0,0,0,0,0
0,0,0,0,0,0,0,0,0,0,0,0,0,0,0
endlayer

layer
0,0,0,0,0,0,0,0,0,0,0,0,0,0,0
0,0,0,0,0,0,0,0,0,0,0,0,0,0,0
0,0,0,0,0,0,5,0,0,0,0,0,0,0,0
0,0,0,0,5,0,5,0,0,0,5,0,0,0,0
0,0,5,7,4,6,4,0,4,0,4,6,0,0,0
0,7,15,0,8,6,0,8,8,7,0,6,0,0,0
0,7,15,23,4,6,0,0,0,7,4,0,0,0,0
0,7,15,0,0,0,0,2,0,0,8,0,0,0,0
0,0,8,7,4,0,0,0,0,7,4,6,0,0,0
0,0,0,0,0,5,5,5,0,0,8,6,0,0,0
0,0,7,7,4,6,4,0,4,0,4,6,0,0,0
0,0,0,0,8,0,8,8,0,8,8,0,0,0,0
0,0,0,0,0,0,0,0,0,0,0,0,0,0,0
0,0,0,0,0,0,0,0,0,0,0,0,0,0,0
0,0,0,0,0,0,0,0,0,0,0,0,0,0,0
endlayer

layer
0,0,0,0,0,0,0,0,0,0,0,0,0,0,0
0,0,0,0,0,0,0,0,0,0,0,0,0,0,0
0,0,0,0,0,0,5,0,0,0,0,0,0,0,0
0,0,0,0,5,0,5,0,0,0,5,0,0,0,0
0,0,0,7,4,6,0,4,0,0,4,6,0,0,0
0,0,24,0,8,6,0,8,8,7,0,6,0,0,0
0,7,15,0,0,6,0,10,0,7,0,0,0,0,0
0,0,25,0,4,0,0,2,0,0,4,0,0,0,0
0,0,7,7,0,0,0,0,0,7,0,6,0,0,0
0,0,0,0,0,5,0,5,0,0,8,6,0,0,0
0,0,7,7,4,6,0,4,0,0,4,6,0,0,0
0,0,0,0,8,0,8,8,0,8,8,0,0,0,0
0,0,0,0,0,0,0,0,0,0,0,0,0,0,0
0,0,0,0,0,0,0,0,0,0,0,0,0,0,0
0,0,0,0,0,0,0,0,0,0,0,0,0,0,0
endlayer

layer
0,0,0,0,0,0,0,0,0,0,0,0,0,0,0
0,0,0,0,0,0,0,0,0,0,0,0,0,0,0
0,0,0,0,0,0,5,5,0,0,0,0,0,0,0
0,0,0,0,5,0,5,0,0,0,5,0,0,0,0
0,0,0,7,4,6,4,0,4,0,4,6,0,0,0
0,0,0,0,8,6,0,0,8,7,0,6,0,0,0
0,0,0,0,4,6,0,10,0,7,4,0,0,0,0
0,0,0,0,0,0,0,2,0,0,0,0,0,0,0
0,0,7,7,4,0,0,0,0,7,4,6,0,0,0
0,0,0,0,0,5,0,0,0,0,8,6,0,0,0
0,0,7,7,4,6,4,0,4,0,4,6,0,0,0
0,0,0,0,8,0,8,0,0,8,8,0,0,0,0
0,0,0,0,0,0,0,0,0,0,0,0,0,0,0
0,0,0,0,0,0,0,0,0,0,0,0,0,0,0
0,0,0,0,0,0,0,0,0,0,0,0,0,0,0
endlayer

layer
0,0,0,0,0,0,0,0,0,0,0,0,0,0,0
0,0,0,0,0,0,0,0,0,0,0,0,0,0,0
0,0,0,0,0,0,5,5,0,0,0,0,0,0,0
0,0,0,0,5,0,0,0,0,0,5,0,0,0,0
0,0,0,7,4,4,0,0,0,4,4,0,0,0,0
0,0,0,0,4,6,0,0,0,7,4,6,0,0,0
0,0,0,0,0,0,0,10,0,0,0,0,0,0,0
0,0,0,0,0,0,0,2,0,0,0,0,0,0,0
0,0,7,0,0,0,0,0,0,0,0,0,0,0,0
0,0,0,0,4,5,0,0,0,0,4,6,0,0,0
0,0,7,7,4,4,0,0,0,4,4,0,0,0,0
0,0,0,0,8,0,0,0,0,8,8,0,0,0,0
0,0,0,0,0,0,0,0,0,0,0,0,0,0,0
0,0,0,0,0,0,0,0,0,0,0,0,0,0,0
0,0,0,0,0,0,0,0,0,0,0,0,0,0,0
endlayer

layer
0,0,0,0,0,0,0,0,0,0,0,0,0,0,0
0,0,0,0,0,0,0,0,0,0,0,0,0,0,0
0,0,0,0,0,0,5,5,0,0,0,0,0,0,0
0,0,0,0,5,0,0,0,0,0,5,0,0,0,0
0,0,0,7,4,0,0,0,0,7,4,0,0,0,0
0,0,0,0,8,0,0,0,0,0,0,0,0,0,0
0,0,0,0,0,0,0,0,0,0,0,0,0,0,0
0,0,0,0,0,0,0,2,0,0,0,0,0,0,0
0,0,7,0,0,0,0,0,0,0,0,0,0,0,0
0,0,0,0,5,0,0,0,0,0,5,0,0,0,0
0,0,7,7,4,0,0,0,0,7,4,0,0,0,0
0,0,0,0,8,0,0,0,0,0,8,0,0,0,0
0,0,0,0,0,0,0,0,0,0,0,0,0,0,0
0,0,0,0,0,0,0,0,0,0,0,0,0,0,0
0,0,0,0,0,0,0,0,0,0,0,0,0,0,0
endlayer

layer
0,0,0,0,0,0,0,0,0,0,0,0,0,0,0
0,0,0,0,0,0,0,0,0,0,0,0,0,0,0
0,0,0,0,0,0,5,5,5,0,0,0,0,0,0
0,0,0,26,26,26,26,26,26,26,26,26,0,0,0
0,0,0,26,4,4,4,4,4,4,4,26,0,0,0
0,0,0,26,4,12,12,12,12,12,4,26,0,0,0
0,0,0,26,4,12,2,0,2,12,4,26,0,0,0
0,0,0,26,4,12,2,2,2,12,4,26,6,0,0
0,0,7,26,4,12,2,2,2,12,4,26,0,0,0
0,0,0,26,4,12,12,12,12,12,4,26,0,0,0
0,0,7,26,4,4,4,4,4,4,4,26,0,0,0
0,0,0,26,26,26,26,26,26,26,26,26,0,0,0
0,0,0,0,0,0,0,0,0,0,0,0,0,0,0
0,0,0,0,0,0,0,0,0,0,0,0,0,0,0
0,0,0,0,0,0,0,0,0,0,0,0,0,0,0
endlayer

layer
0,0,0,0,0,0,0,0,0,0,0,0,0,0,0
0,0,0,0,0,0,0,0,0,0,0,0,0,0,0
0,0,0,0,0,0,5,5,5,0,0,0,0,0,0
0,0,0,3,3,3,3,3,3,3,3,3,0,0,0
0,0,0,3,0,5,0,0,0,5,0,3,0,0,0
0,0,0,3,7,12,0,7,0,12,6,3,0,0,0
0,0,0,3,7,0,6,10,17,0,6,3,0,0,0
0,0,0,3,7,8,27,2,0,8,0,3,6,0,0
0,0,7,3,7,0,29,9,28,0,6,3,0,0,0
0,0,0,3,0,12,6,0,0,12,6,3,0,0,0
0,0,7,3,0,8,8,0,0,8,0,3,0,0,0
0,0,0,3,3,3,3,3,3,3,3,3,0,0,0
0,0,0,0,0,0,0,0,0,0,0,0,0,0,0
0,0,0,0,0,0,0,0,0,0,0,0,0,0,0
0,0,0,0,0,0,0,0,0,0,0,0,0,0,0
endlayer

layer
0,0,0,0,0,0,0,0,0,0,0,0,0,0,0
0,0,0,0,0,0,0,0,0,0,0,0,0,0,0
0,0,0,0,0,0,5,5,5,0,0,0,0,0,0
0,0,0,0,0,0,0,0,0,0,0,0,0,0,0
0,0,0,0,0,5,0,0,0,5,0,0,0,0,0
0,0,0,0,7,12,12,7,12,12,6,0,0,0,0
0,0,0,0,7,12,6,0,17,12,6,0,0,0,0
0,0,0,0,7,8,27,2,0,8,0,0,6,0,0
0,0,7,0,7,12,29,9,28,12,6,0,0,0,0
0,0,7,0,0,12,12,0,12,12,6,0,0,0,0
0,0,7,0,0,8,8,0,0,8,0,0,0,0,0
0,0,0,8,0,0,0,0,0,0,0,0,0,0,0
0,0,0,0,0,0,0,0,0,0,0,0,0,0,0
0,0,0,0,0,0,0,0,0,0,0,0,0,0,0
0,0,0,0,0,0,0,0,0,0,0,0,0,0,0
endlayer

layer
0,0,0,0,0,0,0,0,0,0,0,0,0,0,0
0,0,0,0,0,0,0,0,0,0,0,0,0,0,0
0,0,0,0,0,0,5,5,5,0,0,0,0,0,0
0,0,0,0,0,0,0,0,0,0,0,0,0,0,0
0,0,0,0,0,5,5,0,0,5,0,0,0,0,0
0,0,0,0,7,12,0,12,0,12,6,0,0,0,0
0,0,0,0,7,0,6,10,8,0,6,0,0,0,0
0,0,0,5,7,12,27,2,0,12,0,0,6,0,0
0,0,7,0,7,0,29,9,28,0,6,0,0,0,0
0,0,7,0,0,12,0,12,0,12,6,0,0,0,0
0,0,7,0,0,8,0,0,0,8,0,0,0,0,0
0,0,0,8,0,0,0,0,0,0,0,0,0,0,0
0,0,0,0,0,0,0,0,0,0,0,0,0,0,0
0,0,0,0,0,0,0,0,0,0,0,0,0,0,0
0,0,0,0,0,0,0,0,0,0,0,0,0,0,0
endlayer

layer
0,0,0,0,0,0,0,0,0,0,0,0,0,0,0
0,0,0,0,0,0,0,0,0,0,0,0,0,0,0
0,0,0,0,0,0,5,5,5,0,0,0,0,0,0
0,0,0,0,0,0,0,0,0,0,0,0,0,0,0
0,0,0,0,0,5,5,0,0,5,0,0,0,0,0
0,0,0,0,7,12,12,0,12,12,6,0,0,0,0
0,0,0,0,7,12,6,10,8,12,6,0,6,0,0
0,0,0,5,7,0,27,2,0,0,0,0,6,0,0
0,0,7,0,7,12,29,8,28,12,6,0,0,0,0
0,0,7,0,0,12,12,7,12,12,6,0,0,0,0
0,0,7,0,0,8,0,0,0,8,0,0,0,0,0
0,0,0,8,0,0,0,0,0,0,0,0,0,0,0
0,0,0,0,0,0,0,0,0,0,0,0,0,0,0
0,0,0,0,0,0,0,0,0,0,0,0,0,0,0
0,0,0,0,0,0,0,0,0,0,0,0,0,0,0
endlayer

layer
0,0,0,0,0,0,0,0,0,0,0,0,0,0,0
0,0,0,0,0,0,0,0,0,0,0,0,0,0,0
0,0,0,0,0,0,5,5,5,0,0,0,0,0,0
0,0,0,0,0,0,0,0,0,0,0,0,0,0,0
0,0,0,0,0,5,0,0,0,5,0,0,0,0,0
0,0,0,0,7,12,0,0,7,12,6,0,0,0,0
0,0,0,0,7,0,6,0,8,8,6,0,6,0,0
0,0,0,5,7,0,27,2,0,0,0,0,6,0,0
0,0,7,0,7,5,29,0,7,0,6,0,0,0,0
0,0,7,0,0,12,6,0,0,12,6,0,0,0,0
0,0,7,0,0,8,0,0,0,8,0,0,0,0,0
0,0,0,8,0,0,0,0,0,0,0,0,0,0,0
0,0,0,0,0,0,0,0,0,0,0,0,0,0,0
0,0,0,0,0,0,0,0,0,0,0,0,0,0,0
0,0,0,0,0,0,0,0,0,0,0,0,0,0,0
endlayer

layer
0,0,0,0,0,0,0,0,0,0,0,0,0,0,0
0,0,0,0,0,0,0,0,0,0,0,0,0,0,0
0,0,0,0,0,0,5,5,5,0,0,0,0,0,0
0,0,0,0,0,7,0,0,0,6,0,0,0,0,0
0,0,0,0,0,5,0,0,0,5,0,0,0,0,0
0,0,0,0,7,12,12,12,12,12,6,0,0,0,0
0,0,0,0,7,12,6,0,8,12,6,0,6,0,0
0,0,0,5,7,12,27,2,0,12,0,0,6,0,0
0,0,7,0,7,12,29,0,7,12,6,0,0,0,0
0,0,7,0,0,12,12,12,12,12,6,0,0,0,0
0,0,7,0,0,8,0,0,0,8,0,0,0,0,0
0,0,0,8,0,0,0,0,0,0,0,0,0,0,0
0,0,0,0,0,0,0,0,0,0,0,0,0,0,0
0,0,0,0,0,0,0,0,0,0,0,0,0,0,0
0,0,0,0,0,0,0,0,0,0,0,0,0,0,0
endlayer

layer
0,0,0,0,0,0,0,0,0,0,0,0,0,0,0
0,0,0,0,0,0,0,0,0,0,0,0,0,0,0
0,0,0,0,0,0,5,5,5,0,0,0,0,0,0
0,0,0,0,0,7,0,0,0,6,0,0,0,0,0
0,0,0,0,0,5,5,0,0,5,0,0,0,0,0
0,0,0,0,7,4,0,0,0,4,6,0,0,0,0
0,0,0,0,7,0,6,0,8,0,6,0,6,0,0
0,0,0,5,0,0,27,2,0,0,0,0,6,0,0
0,0,7,21,0,0,29,0,7,0,6,0,6,0,0
0,0,7,15,0,4,0,7,0,4,6,0,0,0,0
0,0,7,22,0,8,8,0,8,8,0,0,0,0,0
0,0,0,8,0,0,0,0,0,0,0,0,0,0,0
0,0,0,0,0,0,0,0,0,0,0,0,0,0,0
0,0,0,0,0,0,0,0,0,0,0,0,0,0,0
0,0,0,0,0,0,0,0,0,0,0,0,0,0,0
endlayer

layer
0,0,0,0,0,0,0,0,0,0,0,0,0,0,0
0,0,0,0,0,0,0,0,0,0,0,0,0,0,0
0,0,0,0,0,0,5,5,5,0,0,0,0,0,0
0,0,0,0,0,7,16,15,14,6,0,0,0,0,0
0,0,0,0,0,5,5,0,0,5,0,0,0,0,0
0,0,0,0,7,4,4,0,4,4,6,0,0,0,0
0,0,0,0,7,4,6,10,8,4,6,0,6,0,0
0,0,0,5,0,0,27,2,0,0,0,0,6,0,0
0,0,7,15,0,4,29,0,7,4,6,0,6,0,0
0,0,7,15,18,4,4,7,4,4,6,0,0,0,0
0,0,7,15,0,8,8,0,8,8,0,0,0,0,0
0,0,0,8,0,0,0,0,0,0,0,0,0,0,0
0,0,0,0,0,0,0,0,0,0,0,0,0,0,0
0,0,0,0,0,0,0,0,0,0,0,0,0,0,0
0,0,0,0,0,0,0,0,0,0,0,0,0,0,0
endlayer

layer
0,0,0,0,0,0,0,0,0,0,0,0,0,0,0
0,0,0,0,0,0,0,0,0,0,0,0,0,0,0
0,0,0,0,0,0,5,5,5,0,0,0,0,0,0
0,0,0,0,0,7,15,15,15,6,0,0,0,0,0
0,0,0,0,0,5,5,23,0,5,0,0,0,0,0
0,0,0,0,7,4,0,4,0,4,6,0,0,0,0
0,0,0,0,7,0,6,0,8,0,0,0,6,0,0
0,0,0,0,7,4,27,2,0,4,0,0,6,0,0
0,0,0,24,0,0,6,0,7,0,6,0,6,0,0
0,0,7,15,7,4,7,4,0,4,6,8,0,0,0
0,0,0,25,0,8,8,8,8,8,0,0,0,0,0
0,0,0,0,0,0,0,0,0,0,0,0,0,0,0
0,0,0,0,0,0,0,0,0,0,0,0,0,0,0
0,0,0,0,0,0,0,0,0,0,0,0,0,0,0
0,0,0,0,0,0,0,0,0,0,0,0,0,0,0
endlayer

layer
0,0,0,0,0,0,0,0,0,0,0,0,0,0,0
0,0,0,0,0,0,0,0,0,0,0,0,0,0,0
0,0,0,0,0,0,0,5,0,0,0,0,0,0,0
0,0,0,0,0,0,20,15,19,0,0,0,0,0,0
0,0,0,0,0,5,5,0,0,5,0,0,0,0,0
0,0,0,0,7,4,4,0,4,4,6,0,0,0,0
0,0,0,0,7,4,6,0,8,4,0,0,6,0,0
0,0,0,0,7,0,27,2,0,0,0,0,6,0,0
0,0,0,0,0,4,6,0,7,4,6,0,6,0,0
0,0,0,0,7,4,4,0,4,4,6,8,0,0,0
0,0,0,0,0,8,8,8,8,8,0,0,0,0,0
0,0,0,0,0,0,0,0,0,0,0,0,0,0,0
0,0,0,0,0,0,0,0,0,0,0,0,0,0,0
0,0,0,0,0,0,0,0,0,0,0,0,0,0,0
0,0,0,0,0,0,0,0,0,0,0,0,0,0,0
endlayer

layer
0,0,0,0,0,0,0,0,0,0,0,0,0,0,0
0,0,0,0,0,0,0,0,0,0,0,0,0,0,0
0,0,0,0,0,0,0,0,0,0,0,0,0,0,0
0,0,0,0,0,0,0,0,0,0,0,0,0,0,0
0,0,0,0,0,5,5,0,0,5,0,0,0,0,0
0,0,0,0,7,4,0,0,0,4,6,0,0,0,0
0,0,0,0,0,0,6,10,8,0,0,0,6,0,0
0,0,0,0,7,0,27,2,0,0,0,0,6,0,0
0,0,0,0,0,0,6,0,7,0,0,0,6,0,0
0,0,0,0,7,4,6,0,0,4,6,8,0,0,0
0,0,0,0,0,8,8,8,0,8,0,0,0,0,0
0,0,0,0,0,0,0,0,0,0,0,0,0,0,0
0,0,0,0,0,0,0,0,0,0,0,0,0,0,0
0,0,0,0,0,0,0,0,0,0,0,0,0,0,0
0,0,0,0,0,0,0,0,0,0,0,0,0,0,0
endlayer

layer
0,0,0,0,0,0,0,0,0,0,0,0,0,0,0
0,0,0,0,0,0,0,0,0,0,0,0,0,0,0
0,0,0,0,0,0,0,0,0,0,0,0,0,0,0
0,0,0,0,0,0,0,0,0,0,0,0,0,0,0
0,0,0,0,0,5,5,0,0,5,0,0,0,0,0
0,0,0,0,7,4,4,4,4,4,6,0,0,0,0
0,0,0,0,0,4,6,10,8,4,0,0,6,0,0
0,0,0,0,7,4,27,2,0,4,0,0,6,0,0
0,0,0,0,0,4,6,0,7,4,0,0,6,0,0
0,0,0,0,7,4,4,4,4,4,6,8,0,0,0
0,0,0,0,0,8,8,8,0,8,0,0,0,0,0
0,0,0,0,0,0,0,0,0,0,0,0,0,0,0
0,0,0,0,0,0,0,0,0,0,0,0,0,0,0
0,0,0,0,0,0,0,0,0,0,0,0,0,0,0
0,0,0,0,0,0,0,0,0,0,0,0,0,0,0
endlayer

layer
0,0,0,0,0,0,0,0,0,0,0,0,0,0,0
0,0,0,0,0,0,0,0,0,0,0,0,0,0,0
0,0,0,0,0,0,0,0,0,0,0,0,0,0,0
0,0,0,0,0,0,0,0,0,0,0,0,0,0,0
0,0,0,0,0,5,0,0,0,5,0,0,0,0,0
0,0,0,0,7,12,0,0,0,12,6,5,0,0,0
0,0,0,0,0,0,6,10,8,8,0,0,6,0,0
0,0,0,0,0,0,7,2,0,0,0,0,6,0,0
0,0,0,0,0,0,0,0,7,0,0,0,6,0,0
0,0,0,0,7,12,0,0,0,12,6,8,0,0,0
0,0,0,0,0,8,8,8,0,8,0,0,0,0,0
0,0,0,0,0,0,0,0,0,0,0,0,0,0,0
0,0,0,0,0,0,0,0,0,0,0,0,0,0,0
0,0,0,0,0,0,0,0,0,0,0,0,0,0,0
0,0,0,0,0,0,0,0,0,0,0,0,0,0,0
endlayer

layer
0,0,0,0,0,0,0,0,0,0,0,0,0,0,0
0,0,0,0,0,0,0,0,0,0,0,0,0,0,0
0,0,0,0,0,0,0,0,0,0,0,0,0,0,0
0,0,0,0,0,0,0,0,0,0,0,0,0,0,0
0,0,0,0,0,5,0,0,5,5,0,0,0,0,0
0,0,0,0,7,12,12,0,12,12,6,5,0,0,0
0,0,0,0,0,12,6,0,8,12,0,21,6,0,0
0,0,0,0,0,0,0,2,0,0,0,15,6,0,0
0,0,0,0,0,12,0,0,7,12,0,22,6,0,0
0,0,0,0,7,12,12,0,12,12,6,8,0,0,0
0,0,0,0,0,8,8,8,0,8,0,0,0,0,0
0,0,0,0,0,0,0,0,0,0,0,0,0,0,0
0,0,0,0,0,0,0,0,0,0,0,0,0,0,0
0,0,0,0,0,0,0,0,0,0,0,0,0,0,0
0,0,0,0,0,0,0,0,0,0,0,0,0,0,0
endlayer

layer
0,0,0,0,0,0,0,0,0,0,0,0,0,0,0
0,0,0,0,0,0,0,0,0,0,0,0,0,0,0
0,0,0,0,0,0,0,0,0,0,0,0,0,0,0
0,0,0,0,0,0,0,0,0,0,0,0,0,0,0
0,0,0,0,0,5,0,0,5,0,0,0,0,0,0
0,0,0,0,7,12,0,12,7,12,6,5,0,0,0
0,0,0,0,0,0,0,10,8,0,0,15,6,0,0
0,0,0,0,0,12,0,2,0,12,18,15,6,0,0
0,0,0,0,0,0,0,0,7,0,0,15,6,0,0
0,0,0,0,7,12,0,12,0,12,6,8,0,0,0
0,0,0,0,0,0,0,8,0,8,0,0,0,0,0
0,0,0,0,0,0,0,0,0,0,0,0,0,0,0
0,0,0,0,0,0,0,0,0,0,0,0,0,0,0
0,0,0,0,0,0,0,0,0,0,0,0,0,0,0
0,0,0,0,0,0,0,0,0,0,0,0,0,0,0
endlayer

layer
0,0,0,0,0,0,0,0,0,0,0,0,0,0,0
0,0,0,0,0,0,0,0,0,0,0,0,0,0,0
0,0,0,0,0,0,0,0,0,0,0,0,0,0,0
0,0,0,0,0,0,0,0,0,0,0,0,0,0,0
0,0,0,0,0,5,0,0,5,0,0,0,0,0,0
0,0,0,0,7,12,12,0,12,12,6,0,0,0,0
0,0,0,0,0,12,0,0,8,12,0,24,0,0,0
0,0,0,0,0,0,0,2,0,0,0,15,6,0,0
0,0,0,0,0,12,5,0,7,12,0,25,0,0,0
0,0,0,0,7,12,12,0,12,12,6,0,0,0,0
0,0,0,0,0,0,0,0,0,8,0,0,0,0,0
0,0,0,0,0,0,0,0,0,0,0,0,0,0,0
0,0,0,0,0,0,0,0,0,0,0,0,0,0,0
0,0,0,0,0,0,0,0,0,0,0,0,0,0,0
0,0,0,0,0,0,0,0,0,0,0,0,0,0,0
endlayer

layer
0,0,0,0,0,0,0,0,0,0,0,0,0,0,0
0,0,0,0,0,0,0,0,0,0,0,0,0,0,0
0,0,0,0,0,0,0,0,0,0,0,0,0,0,0
0,0,0,0,0,0,0,0,0,0,0,0,0,0,0
0,0,0,0,0,5,0,0,0,0,0,0,0,0,0
0,0,0,0,7,12,6,0,0,12,0,0,0,0,0
0,0,0,0,0,0,0,0,0,0,0,0,0,0,0
0,0,0,0,0,0,0,2,0,0,0,0,0,0,0
0,0,0,0,0,0,0,0,0,0,0,0,0,0,0
0,0,0,0,7,12,0,0,0,12,6,0,0,0,0
0,0,0,0,0,0,0,0,0,8,0,0,0,0,0
0,0,0,0,0,0,0,0,0,0,0,0,0,0,0
0,0,0,0,0,0,0,0,0,0,0,0,0,0,0
0,0,0,0,0,0,0,0,0,0,0,0,0,0,0
0,0,0,0,0,0,0,0,0,0,0,0,0,0,0
endlayer

layer
0,0,0,0,0,0,0,0,0,0,0,0,0,0,0
0,0,0,0,0,0,0,0,0,0,0,0,0,0,0
0,0,0,0,0,0,0,0,0,0,0,0,0,0,0
0,0,0,0,0,0,0,0,0,0,0,0,0,0,0
0,0,0,0,26,26,26,26,26,26,0,0,0,0,0
0,0,0,0,26,12,12,12,12,12,26,0,0,0,0
0,0,0,0,26,12,4,0,4,12,26,0,0,0,0
0,0,0,0,26,12,4,2,4,12,26,0,0,0,0
0,0,0,0,26,12,4,4,4,12,26,0,0,0,0
0,0,0,0,26,12,12,12,12,12,26,0,0,0,0
0,0,0,0,26,26,26,26,26,26,26,0,0,0,0
0,0,0,0,0,0,0,0,0,0,0,0,0,0,0
0,0,0,0,0,0,0,0,0,0,0,0,0,0,0
0,0,0,0,0,0,0,0,0,0,0,0,0,0,0
0,0,0,0,0,0,0,0,0,0,0,0,0,0,0
endlayer

layer
0,0,0,0,0,0,0,0,0,0,0,0,0,0,0
0,0,0,0,0,0,0,0,0,0,0,0,0,0,0
0,0,0,0,0,0,0,0,0,0,0,0,0,0,0
0,0,0,0,0,0,0,0,0,0,0,0,0,0,0
0,0,0,0,3,3,3,3,3,3,0,0,0,0,0
0,0,0,0,3,0,5,5,5,0,3,0,0,0,0
0,0,0,0,3,7,4,0,4,6,3,0,0,0,0
0,0,0,0,3,7,0,0,0,0,3,0,0,0,0
0,0,0,0,3,7,4,7,4,6,3,0,0,0,0
0,0,0,0,3,0,8,8,8,0,3,0,0,0,0
0,0,0,0,3,3,3,3,3,3,3,0,0,0,0
0,0,0,0,0,0,0,0,0,0,0,0,0,0,0
0,0,0,0,0,0,0,0,0,0,0,0,0,0,0
0,0,0,0,0,0,0,0,0,0,0,0,0,0,0
0,0,0,0,0,0,0,0,0,0,0,0,0,0,0
endlayer

layer
0,0,0,0,0,0,0,0,0,0,0,0,0,0,0
0,0,0,0,0,0,0,0,0,0,0,0,0,0,0
0,0,0,0,0,0,0,0,0,0,0,0,0,0,0
0,0,0,0,0,0,0,0,0,0,0,0,0,0,0
0,0,0,0,0,0,0,0,0,0,0,0,0,0,0
0,0,0,0,0,0,5,5,5,0,0,0,0,0,0
0,0,0,0,0,7,4,0,4,6,0,0,0,0,0
0,0,0,0,0,7,4,0,4,0,0,0,0,0,0
0,0,0,0,0,7,4,4,4,6,0,0,0,0,0
0,0,0,0,0,0,8,8,8,0,0,0,0,0,0
0,0,0,0,0,0,0,0,0,0,0,0,0,0,0
0,0,0,0,0,0,0,0,0,0,0,0,0,0,0
0,0,0,0,0,0,0,0,0,0,0,0,0,0,0
0,0,0,0,0,0,0,0,0,0,0,0,0,0,0
0,0,0,0,0,0,0,0,0,0,0,0,0,0,0
endlayer

layer
0,0,0,0,0,0,0,0,0,0,0,0,0,0,0
0,0,0,0,0,0,0,0,0,0,0,0,0,0,0
0,0,0,0,0,0,0,0,0,0,0,0,0,0,0
0,0,0,0,0,0,0,0,0,0,0,0,0,0,0
0,0,0,0,0,0,0,0,0,0,0,0,0,0,0
0,0,0,0,0,0,5,5,5,0,0,0,0,0,0
0,0,0,0,0,7,4,0,4,6,0,0,0,0,0
0,0,0,0,0,7,0,0,5,0,0,0,0,0,0
0,0,0,0,0,7,4,0,4,6,0,0,0,0,0
0,0,0,0,0,0,8,8,8,0,0,0,0,0,0
0,0,0,0,0,0,0,0,0,0,0,0,0,0,0
0,0,0,0,0,0,0,0,0,0,0,0,0,0,0
0,0,0,0,0,0,0,0,0,0,0,0,0,0,0
0,0,0,0,0,0,0,0,0,0,0,0,0,0,0
0,0,0,0,0,0,0,0,0,0,0,0,0,0,0
endlayer

layer
0,0,0,0,0,0,0,0,0,0,0,0,0,0,0
0,0,0,0,0,0,0,0,0,0,0,0,0,0,0
0,0,0,0,0,0,0,0,0,0,0,0,0,0,0
0,0,0,0,0,0,0,0,0,0,0,0,0,0,0
0,0,0,0,0,0,0,0,0,0,0,0,0,0,0
0,0,0,0,0,0,5,5,5,0,0,0,0,0,0
0,0,0,0,0,7,4,4,4,6,0,0,0,0,0
0,0,0,0,0,7,4,0,4,0,0,0,0,0,0
0,0,0,0,0,7,4,4,4,6,0,0,0,0,0
0,0,0,0,0,0,8,8,8,0,0,0,0,0,0
0,0,0,0,0,0,0,0,0,0,0,0,0,0,0
0,0,0,0,0,0,0,0,0,0,0,0,0,0,0
0,0,0,0,0,0,0,0,0,0,0,0,0,0,0
0,0,0,0,0,0,0,0,0,0,0,0,0,0,0
0,0,0,0,0,0,0,0,0,0,0,0,0,0,0
endlayer

layer
0,0,0,0,0,0,0,0,0,0,0,0,0,0,0
0,0,0,0,0,0,0,0,0,0,0,0,0,0,0
0,0,0,0,0,0,0,0,0,0,0,0,0,0,0
0,0,0,0,0,0,0,0,0,0,0,0,0,0,0
0,0,0,0,0,0,0,0,0,0,0,0,0,0,0
0,0,0,0,0,0,5,0,5,0,0,0,0,0,0
0,0,0,0,0,7,4,0,4,6,0,0,0,0,0
0,0,0,0,0,0,0,0,0,0,0,0,0,0,0
0,0,0,0,0,7,4,0,4,6,0,0,0,0,0
0,0,0,0,0,0,8,0,8,0,0,0,0,0,0
0,0,0,0,0,0,0,0,0,0,0,0,0,0,0
0,0,0,0,0,0,0,0,0,0,0,0,0,0,0
0,0,0,0,0,0,0,0,0,0,0,0,0,0,0
0,0,0,0,0,0,0,0,0,0,0,0,0,0,0
0,0,0,0,0,0,0,0,0,0,0,0,0,0,0
endlayer

layer
0,0,0,0,0,0,0,0,0,0,0,0,0,0,0
0,0,0,0,0,0,0,0,0,0,0,0,0,0,0
0,0,0,0,0,0,0,0,0,0,0,0,0,0,0
0,0,0,0,0,0,0,0,0,0,0,0,0,0,0
0,0,0,0,0,0,0,0,0,0,0,0,0,0,0
0,0,0,0,0,0,5,18,5,0,0,0,0,0,0
0,0,0,0,0,7,12,12,12,6,0,0,0,0,0
0,0,0,0,0,18,12,0,12,18,0,0,0,0,0
0,0,0,0,0,7,12,12,12,6,0,0,0,0,0
0,0,0,0,0,0,8,23,8,0,0,0,0,0,0
0,0,0,0,0,0,0,0,0,0,0,0,0,0,0
0,0,0,0,0,0,0,0,0,0,0,0,0,0,0
0,0,0,0,0,0,0,0,0,0,0,0,0,0,0
0,0,0,0,0,0,0,0,0,0,0,0,0,0,0
0,0,0,0,0,0,0,0,0,0,0,0,0,0,0
endlayer

layer
0,0,0,0,0,0,0,0,0,0,0,0,0,0,0
0,0,0,0,0,0,0,0,0,0,0,0,0,0,0
0,0,0,0,0,0,0,0,0,0,0,0,0,0,0
0,0,0,0,0,0,0,0,0,0,0,0,0,0,0
0,0,0,0,0,0,0,0,0,0,0,0,0,0,0
0,0,0,0,0,0,5,18,5,0,0,0,0,0,0
0,0,0,0,0,7,12,0,12,0,0,0,0,0,0
0,0,0,0,0,23,0,0,0,23,0,0,0,0,0
0,0,0,0,0,7,12,0,12,6,0,0,0,0,0
0,0,0,0,0,0,8,18,8,0,0,0,0,0,0
0,0,0,0,0,0,0,0,0,0,0,0,0,0,0
0,0,0,0,0,0,0,0,0,0,0,0,0,0,0
0,0,0,0,0,0,0,0,0,0,0,0,0,0,0
0,0,0,0,0,0,0,0,0,0,0,0,0,0,0
0,0,0,0,0,0,0,0,0,0,0,0,0,0,0
endlayer

layer
0,0,0,0,0,0,0,0,0,0,0,0,0,0,0
0,0,0,0,0,0,0,0,0,0,0,0,0,0,0
0,0,0,0,0,0,0,0,0,0,0,0,0,0,0
0,0,0,0,0,0,0,0,0,0,0,0,0,0,0
0,0,0,0,0,0,0,0,0,0,0,0,0,0,0
0,0,0,0,0,0,5,23,5,0,0,0,0,0,0
0,0,0,0,0,7,12,12,12,0,0,0,0,0,0
0,0,0,0,0,18,12,0,12,18,0,0,0,0,0
0,0,0,0,0,7,12,12,12,6,0,0,0,0,0
0,0,0,0,0,0,8,23,8,0,0,0,0,0,0
0,0,0,0,0,0,0,0,0,0,0,0,0,0,0
0,0,0,0,0,0,0,0,0,0,0,0,0,0,0
0,0,0,0,0,0,0,0,0,0,0,0,0,0,0
0,0,0,0,0,0,0,0,0,0,0,0,0,0,0
0,0,0,0,0,0,0,0,0,0,0,0,0,0,0
endlayer

layer
0,0,0,0,0,0,0,0,0,0,0,0,0,0,0
0,0,0,0,0,0,0,0,0,0,0,0,0,0,0
0,0,0,0,0,0,0,0,0,0,0,0,0,0,0
0,0,0,0,0,0,0,0,0,0,0,0,0,0,0
0,0,0,0,0,0,0,0,0,0,0,0,0,0,0
0,0,0,0,0,0,5,18,5,0,0,0,0,0,0
0,0,0,0,0,0,12,7,12,0,0,0,0,0,0
0,0,0,0,0,23,5,0,0,18,0,0,0,0,0
0,0,0,0,0,7,12,30,12,6,0,0,0,0,0
0,0,0,0,0,0,8,18,8,0,0,0,0,0,0
0,0,0,0,0,0,0,0,0,0,0,0,0,0,0
0,0,0,0,0,0,0,0,0,0,0,0,0,0,0
0,0,0,0,0,0,0,0,0,0,0,0,0,0,0
0,0,0,0,0,0,0,0,0,0,0,0,0,0,0
0,0,0,0,0,0,0,0,0,0,0,0,0,0,0
endlayer

layer
0,0,0,0,0,0,0,0,0,0,0,0,0,0,0
0,0,0,0,0,0,0,0,0,0,0,0,0,0,0
0,0,0,0,0,0,0,0,0,0,0,0,0,0,0
0,0,0,0,0,0,0,0,0,0,0,0,0,0,0
0,0,0,0,0,0,0,0,0,0,0,0,0,0,0
0,0,0,0,0,0,5,23,5,0,0,0,0,0,0
0,0,0,0,0,0,12,12,12,0,0,0,0,0,0
0,0,0,0,0,18,12,0,12,18,0,0,0,0,0
0,0,0,0,0,7,12,12,12,6,0,0,0,0,0
0,0,0,0,0,0,8,18,8,0,0,0,0,0,0
0,0,0,0,0,0,0,0,0,0,0,0,0,0,0
0,0,0,0,0,0,0,0,0,0,0,0,0,0,0
0,0,0,0,0,0,0,0,0,0,0,0,0,0,0
0,0,0,0,0,0,0,0,0,0,0,0,0,0,0
0,0,0,0,0,0,0,0,0,0,0,0,0,0,0
endlayer

layer
0,0,0,0,0,0,0,0,0,0,0,0,0,0,0
0,0,0,0,0,0,0,0,0,0,0,0,0,0,0
0,0,0,0,0,0,0,0,0,0,0,0,0,0,0
0,0,0,0,0,0,0,0,0,0,0,0,0,0,0
0,0,0,0,0,0,0,0,0,0,0,0,0,0,0
0,0,0,0,0,0,0,18,0,0,0,0,0,0,0
0,0,0,0,0,0,0,0,0,0,0,0,0,0,0
0,0,0,0,0,18,0,4,0,23,0,0,0,0,0
0,0,0,0,0,0,0,0,0,0,0,0,0,0,0
0,0,0,0,0,0,0,18,0,0,0,0,0,0,0
0,0,0,0,0,0,0,0,0,0,0,0,0,0,0
0,0,0,0,0,0,0,0,0,0,0,0,0,0,0
0,0,0,0,0,0,0,0,0,0,0,0,0,0,0
0,0,0,0,0,0,0,0,0,0,0,0,0,0,0
0,0,0,0,0,0,0,0,0,0,0,0,0,0,0
endlayer

layer
0,0,0,0,0,0,0,0,0,0,0,0,0,0,0
0,0,0,0,0,0,0,0,0,0,0,0,0,0,0
0,0,0,0,0,0,0,0,0,0,0,0,0,0,0
0,0,0,0,0,0,0,0,0,0,0,0,0,0,0
0,0,0,0,0,0,0,0,0,0,0,0,0,0,0
0,0,0,0,0,0,0,31,0,0,0,0,0,0,0
0,0,0,0,0,0,0,0,0,0,0,0,0,0,0
0,0,0,0,0,31,0,4,0,31,0,0,0,0,0
0,0,0,0,0,0,0,0,0,0,0,0,0,0,0
0,0,0,0,0,0,0,31,0,0,0,0,0,0,0
0,0,0,0,0,0,0,0,0,0,0,0,0,0,0
0,0,0,0,0,0,0,0,0,0,0,0,0,0,0
0,0,0,0,0,0,0,0,0,0,0,0,0,0,0
0,0,0,0,0,0,0,0,0,0,0,0,0,0,0
0,0,0,0,0,0,0,0,0,0,0,0,0,0,0
endlayer

layer
0,0,0,0,0,0,0,0,0,0,0,0,0,0,0
0,0,0,0,0,0,0,0,0,0,0,0,0,0,0
0,0,0,0,0,0,0,0,0,0,0,0,0,0,0
0,0,0,0,0,0,0,0,0,0,0,0,0,0,0
0,0,0,0,0,0,0,0,0,0,0,0,0,0,0
0,0,0,0,0,0,0,0,0,0,0,0,0,0,0
0,0,0,0,0,0,0,0,0,0,0,0,0,0,0
0,0,0,0,0,0,0,4,0,0,0,0,0,0,0
0,0,0,0,0,0,0,0,0,0,0,0,0,0,0
0,0,0,0,0,0,0,0,0,0,0,0,0,0,0
0,0,0,0,0,0,0,0,0,0,0,0,0,0,0
0,0,0,0,0,0,0,0,0,0,0,0,0,0,0
0,0,0,0,0,0,0,0,0,0,0,0,0,0,0
0,0,0,0,0,0,0,0,0,0,0,0,0,0,0
0,0,0,0,0,0,0,0,0,0,0,0,0,0,0
endlayer

layer
0,0,0,0,0,0,0,0,0,0,0,0,0,0,0
0,0,0,0,0,0,0,0,0,0,0,0,0,0,0
0,0,0,0,0,0,0,0,0,0,0,0,0,0,0
0,0,0,0,0,0,0,0,0,0,0,0,0,0,0
0,0,0,0,0,0,0,0,0,0,0,0,0,0,0
0,0,0,0,0,0,0,0,0,0,0,0,0,0,0
0,0,0,0,0,0,0,0,0,0,0,0,0,0,0
0,0,0,0,0,0,0,4,0,0,0,0,0,0,0
0,0,0,0,0,0,0,0,0,0,0,0,0,0,0
0,0,0,0,0,0,0,0,0,0,0,0,0,0,0
0,0,0,0,0,0,0,0,0,0,0,0,0,0,0
0,0,0,0,0,0,0,0,0,0,0,0,0,0,0
0,0,0,0,0,0,0,0,0,0,0,0,0,0,0
0,0,0,0,0,0,0,0,0,0,0,0,0,0,0
0,0,0,0,0,0,0,0,0,0,0,0,0,0,0
endlayer

layer
0,0,0,0,0,0,0,0,0,0,0,0,0,0,0
0,0,0,0,0,0,0,0,0,0,0,0,0,0,0
0,0,0,0,0,0,0,0,0,0,0,0,0,0,0
0,0,0,0,0,0,0,0,0,0,0,0,0,0,0
0,0,0,0,0,0,0,0,0,0,0,0,0,0,0
0,0,0,0,0,0,0,0,0,0,0,0,0,0,0
0,0,0,0,0,0,0,0,0,0,0,0,0,0,0
0,0,0,0,0,0,0,18,0,0,0,0,0,0,0
0,0,0,0,0,0,0,0,0,0,0,0,0,0,0
0,0,0,0,0,0,0,0,0,0,0,0,0,0,0
0,0,0,0,0,0,0,0,0,0,0,0,0,0,0
0,0,0,0,0,0,0,0,0,0,0,0,0,0,0
0,0,0,0,0,0,0,0,0,0,0,0,0,0,0
0,0,0,0,0,0,0,0,0,0,0,0,0,0,0
0,0,0,0,0,0,0,0,0,0,0,0,0,0,0
endlayer

layer
0,0,0,0,0,0,0,0,0,0,0,0,0,0,0
0,0,0,0,0,0,0,0,0,0,0,0,0,0,0
0,0,0,0,0,0,0,0,0,0,0,0,0,0,0
0,0,0,0,0,0,0,0,0,0,0,0,0,0,0
0,0,0,0,0,0,0,0,0,0,0,0,0,0,0
0,0,0,0,0,0,0,0,0,0,0,0,0,0,0
0,0,0,0,0,0,0,0,0,0,0,0,0,0,0
0,0,0,0,0,0,0,18,0,0,0,0,0,0,0
0,0,0,0,0,0,0,0,0,0,0,0,0,0,0
0,0,0,0,0,0,0,0,0,0,0,0,0,0,0
0,0,0,0,0,0,0,0,0,0,0,0,0,0,0
0,0,0,0,0,0,0,0,0,0,0,0,0,0,0
0,0,0,0,0,0,0,0,0,0,0,0,0,0,0
0,0,0,0,0,0,0,0,0,0,0,0,0,0,0
0,0,0,0,0,0,0,0,0,0,0,0,0,0,0
endlayer

layer
0,0,0,0,0,0,0,0,0,0,0,0,0,0,0
0,0,0,0,0,0,0,0,0,0,0,0,0,0,0
0,0,0,0,0,0,0,0,0,0,0,0,0,0,0
0,0,0,0,0,0,0,0,0,0,0,0,0,0,0
0,0,0,0,0,0,0,0,0,0,0,0,0,0,0
0,0,0,0,0,0,0,0,0,0,0,0,0,0,0
0,0,0,0,0,0,0,0,0,0,0,0,0,0,0
0,0,0,0,0,0,0,23,0,0,0,0,0,0,0
0,0,0,0,0,0,0,0,0,0,0,0,0,0,0
0,0,0,0,0,0,0,0,0,0,0,0,0,0,0
0,0,0,0,0,0,0,0,0,0,0,0,0,0,0
0,0,0,0,0,0,0,0,0,0,0,0,0,0,0
0,0,0,0,0,0,0,0,0,0,0,0,0,0,0
0,0,0,0,0,0,0,0,0,0,0,0,0,0,0
0,0,0,0,0,0,0,0,0,0,0,0,0,0,0
endlayer

layer
0,0,0,0,0,0,0,0,0,0,0,0,0,0,0
0,0,0,0,0,0,0,0,0,0,0,0,0,0,0
0,0,0,0,0,0,0,0,0,0,0,0,0,0,0
0,0,0,0,0,0,0,0,0,0,0,0,0,0,0
0,0,0,0,0,0,0,0,0,0,0,0,0,0,0
0,0,0,0,0,0,0,0,0,0,0,0,0,0,0
0,0,0,0,0,0,0,0,0,0,0,0,0,0,0
0,0,0,0,0,0,0,31,0,0,0,0,0,0,0
0,0,0,0,0,0,0,0,0,0,0,0,0,0,0
0,0,0,0,0,0,0,0,0,0,0,0,0,0,0
0,0,0,0,0,0,0,0,0,0,0,0,0,0,0
0,0,0,0,0,0,0,0,0,0,0,0,0,0,0
0,0,0,0,0,0,0,0,0,0,0,0,0,0,0
0,0,0,0,0,0,0,0,0,0,0,0,0,0,0
0,0,0,0,0,0,0,0,0,0,0,0,0,0,0
endlayer

