weight=1
dimensionsToSpawnIn=overworld
embed_into_distance=2
random_height_offset=0,0
unacceptable_target_blocks=sand,flowing_water,water,flowing_lava,lava,ice,packed_ice,stained_hardened_clay-9,brick_block,double_stone_slab,stonebrick,red_sandstone,red_nether_brick,red_mushroom_block,brown_mushroom_block,planks,cobblestone,end_stone,obsidian,purpur_block,iron_bars,purpur_slab,purpur_pillar,netherrack,soul_sand,quartz_ore,stained_glass,glass
dimensions=28,25,5
allowable_overhang=0
max_leveling=2
leveling_buffer=-1
preventRotation=0
preserve_water=0
preserve_lava=0
uniqueMinDistance=5000
spawnMinDistance=0
spawnMaxDistance=0

rule1=0,100,preserveBlock
rule2=0,100,minecraft:stone-6
rule3=0,100,minecraft:dark_oak_fence-0,minecraft:dark_oak_fence-0,minecraft:dark_oak_fence-0,minecraft:dark_oak_fence-0,minecraft:dark_oak_fence-0,minecraft:dark_oak_fence-0,minecraft:dark_oak_fence-0,minecraft:dark_oak_fence-0,minecraft:dark_oak_fence-0,minecraft:dark_oak_fence-0,minecraft:dark_oak_fence-0,minecraft:dark_oak_fence-0,preserveBlock
rule4=0,100,minecraft:vine-1
rule5=0,100,chisel:factory-1
rule6=0,100,minecraft:ladder-3,minecraft:ladder-3,minecraft:ladder-3,air
rule7=0,100,minecraft:vine-3
rule8=0,100,minecraft:vine-11
rule9=0,100,minecraft:vine-8
rule10=0,100,minecraft:vine-2
rule11=0,100,minecraft:vine-4
rule12=0,100,chisel:technical-12
rule13=0,100,chisel:blocklead-6
rule14=0,100,minecraft:iron_bars-0
rule15=0,100,minecraft:stone_slab-8
rule16=0,100,minecraft:stained_glass_pane-7
rule17=0,100,air
rule18=0,100,minecraft:stone_slab-0

layer
1,1,1,1,1
1,1,1,1,1
1,1,1,1,1
1,1,1,1,1
2,2,2,2,2
2,2,2,2,2
2,2,2,2,2
2,2,2,2,2
2,2,2,2,2
1,1,1,1,1
1,1,1,1,1
1,1,1,1,1
1,1,1,1,1
1,1,1,1,1
1,1,1,1,1
1,1,1,1,1
1,1,1,1,1
1,1,1,1,1
1,1,1,1,1
1,1,1,1,1
1,1,1,1,1
1,1,1,1,1
1,1,1,1,1
1,1,1,1,1
1,1,1,1,1
endlayer

layer
1,1,1,1,1
1,1,1,1,1
1,1,1,1,1
1,1,1,1,1
2,2,2,2,2
2,2,2,2,2
2,2,2,2,2
2,2,2,2,2
2,2,2,2,2
1,1,1,1,1
1,1,1,1,1
1,1,1,1,1
1,1,1,1,1
1,1,1,1,1
1,1,1,1,1
1,1,1,1,1
1,1,1,1,1
1,1,1,1,1
1,1,1,1,1
1,1,1,1,1
1,1,1,1,1
1,1,1,1,1
1,1,1,1,1
1,1,1,1,1
1,1,1,1,1
endlayer

layer
1,1,1,1,1
1,1,1,1,1
1,1,1,1,1
1,1,1,1,1
2,2,2,2,2
2,2,2,2,2
2,2,2,2,2
2,2,2,2,2
2,2,2,2,2
1,1,1,1,1
1,1,1,1,1
1,1,1,1,1
1,1,1,1,1
1,1,1,1,1
1,1,1,1,1
1,1,1,1,1
1,1,1,1,1
1,1,1,1,1
1,1,1,1,1
1,1,1,1,1
1,1,1,1,1
1,1,1,1,1
1,1,1,1,1
1,1,1,1,1
1,1,1,1,1
endlayer

layer
1,1,1,1,1
1,1,1,1,1
1,1,1,1,1
1,1,1,1,1
1,1,1,1,1
1,3,0,3,1
1,3,6,5,4
1,3,3,3,1
1,1,1,1,1
1,1,1,1,1
1,1,1,1,1
1,1,1,1,1
1,1,1,1,1
1,1,1,1,1
1,1,1,1,1
1,1,1,1,1
1,1,1,1,1
1,1,1,1,1
1,1,1,1,1
1,1,1,1,1
1,1,1,1,1
1,1,1,1,1
1,1,1,1,1
1,1,1,1,1
1,1,1,1,1
endlayer

layer
1,1,1,1,1
1,1,1,1,1
1,1,1,1,1
1,1,1,1,1
1,1,1,1,1
1,3,0,3,1
1,3,6,5,4
1,3,3,3,1
1,1,1,1,1
1,1,1,1,1
1,1,1,1,1
1,1,1,1,1
1,1,1,1,1
1,1,1,1,1
1,1,1,1,1
1,1,1,1,1
1,1,1,1,1
1,1,1,1,1
1,1,1,1,1
1,1,1,1,1
1,1,1,1,1
1,1,1,1,1
1,1,1,1,1
1,1,1,1,1
1,1,1,1,1
endlayer

layer
1,1,1,1,1
1,1,1,1,1
1,1,1,1,1
1,1,1,1,1
1,1,1,1,1
1,3,3,3,1
1,3,6,5,4
1,3,3,3,1
1,1,1,1,1
1,1,1,1,1
1,1,1,1,1
1,1,1,1,1
1,1,1,1,1
1,1,1,1,1
1,1,1,1,1
1,1,1,1,1
1,1,1,1,1
1,1,1,1,1
1,1,1,1,1
1,1,1,1,1
1,1,1,1,1
1,1,1,1,1
1,1,1,1,1
1,1,1,1,1
1,1,1,1,1
endlayer

layer
1,1,1,1,1
1,1,1,1,1
1,1,9,1,1
1,1,1,1,1
1,1,1,1,1
1,3,3,3,1
1,3,6,5,4
1,3,3,3,1
1,1,1,1,1
1,1,1,1,1
1,1,1,1,1
1,1,1,1,1
1,1,1,1,1
1,1,1,1,1
1,1,1,1,1
1,1,1,1,1
1,1,1,1,1
1,1,1,1,1
1,1,1,1,1
1,1,1,1,1
1,1,1,1,1
1,1,1,1,1
1,1,1,1,1
1,1,1,1,1
1,1,1,1,1
endlayer

layer
1,1,1,1,1
1,1,1,1,1
1,1,9,1,1
1,1,1,1,1
1,1,1,10,1
1,3,3,3,1
1,3,6,5,4
1,3,3,3,1
1,1,1,1,1
1,1,1,1,1
1,1,1,1,1
1,1,1,1,1
1,1,1,1,1
1,1,1,1,1
1,1,1,1,1
1,1,1,1,1
1,1,1,1,1
1,1,1,1,1
1,1,1,1,1
1,1,1,1,1
1,1,1,1,1
1,1,1,1,1
1,1,1,1,1
1,1,1,1,1
1,1,1,1,1
endlayer

layer
1,1,1,1,1
1,1,1,1,1
1,1,9,1,1
1,11,1,1,4
1,1,0,10,1
1,3,3,3,1
1,3,6,5,4
1,3,3,3,1
1,1,1,1,1
1,1,1,1,1
1,1,1,1,1
1,1,1,1,1
1,1,1,1,1
1,1,1,1,1
1,1,1,1,1
1,1,1,1,1
1,1,1,1,1
1,1,1,1,1
1,1,1,1,1
1,1,1,1,1
1,1,1,1,1
1,1,1,1,1
1,1,1,1,1
1,1,1,1,1
1,1,1,1,1
endlayer

layer
1,1,1,1,1
1,1,1,1,1
1,1,9,9,1
1,11,12,12,4
1,1,0,10,1
1,3,3,3,1
1,3,6,5,0
1,3,3,3,1
1,1,1,1,1
1,1,1,1,1
1,1,1,1,1
1,1,1,1,1
1,1,1,1,1
1,1,1,1,1
1,1,1,1,1
1,1,1,1,1
1,1,1,1,1
1,1,1,1,1
1,1,1,1,1
1,1,1,1,1
1,1,1,1,1
1,1,1,1,1
1,1,1,1,1
1,1,1,1,1
1,1,1,1,1
endlayer

layer
1,1,1,1,1
1,1,1,1,1
1,1,0,9,1
1,11,13,13,4
1,1,10,10,1
1,3,3,3,1
1,3,6,5,4
1,3,3,3,1
1,1,1,1,1
1,1,1,1,1
1,1,1,1,1
1,1,1,1,1
1,1,1,1,1
1,1,1,1,1
1,1,1,1,1
1,1,1,1,1
1,1,1,1,1
1,1,1,1,1
1,1,1,1,1
1,1,1,1,1
1,1,1,1,1
1,1,1,1,1
1,1,1,1,1
1,1,1,1,1
1,1,1,1,1
endlayer

layer
1,1,1,1,1
1,1,1,1,1
1,1,9,9,1
1,11,13,13,4
1,1,0,10,1
1,3,3,3,1
1,3,6,5,0
1,3,3,3,1
1,1,1,1,1
1,1,1,1,1
1,1,1,1,1
1,1,1,1,1
1,1,1,1,1
1,1,1,1,1
1,1,1,1,1
1,1,1,1,1
1,1,1,1,1
1,1,1,1,1
1,1,1,1,1
1,1,1,1,1
1,1,1,1,1
1,1,1,1,1
1,1,1,1,1
1,1,1,1,1
1,1,1,1,1
endlayer

layer
1,1,1,1,1
1,1,1,1,1
1,1,0,9,1
1,0,13,13,4
1,1,10,0,1
1,3,3,3,1
1,3,6,5,4
1,3,3,3,1
1,1,1,1,1
1,1,1,1,1
1,1,1,1,1
1,1,1,1,1
1,1,1,1,1
1,1,1,1,1
1,1,1,1,1
1,1,1,1,1
1,1,1,1,1
1,1,1,1,1
1,1,1,1,1
1,1,1,1,1
1,1,1,1,1
1,1,1,1,1
1,1,1,1,1
1,1,1,1,1
1,1,1,1,1
endlayer

layer
1,1,1,1,1
1,1,1,1,1
1,1,9,9,1
1,1,12,12,4
1,1,10,0,1
1,3,3,3,1
1,3,6,5,0
1,3,3,3,1
1,1,1,1,1
1,1,1,1,1
1,1,1,1,1
1,1,1,1,1
1,1,1,1,1
1,1,1,1,1
1,1,1,1,1
1,1,1,1,1
1,1,1,1,1
1,1,1,1,1
1,1,1,1,1
1,1,1,1,1
1,1,1,1,1
1,1,1,1,1
1,1,1,1,1
1,1,1,1,1
1,1,1,1,1
endlayer

layer
1,1,1,1,1
1,1,1,1,1
1,1,0,0,1
1,1,14,14,0
1,1,0,0,1
1,3,3,3,1
1,3,6,5,0
1,3,3,3,1
1,1,1,1,1
1,1,1,1,1
1,1,1,1,1
1,1,1,1,1
1,1,1,1,1
1,1,1,1,1
1,1,1,1,1
1,1,1,1,1
1,1,1,1,1
1,1,1,1,1
1,1,1,1,1
1,1,1,1,1
1,1,1,1,1
1,1,1,1,1
1,1,1,1,1
1,1,1,1,1
1,1,1,1,1
endlayer

layer
0,0,0,0,0
0,0,0,0,0
0,0,0,0,0
0,0,14,14,0
0,0,0,0,0
0,3,3,3,0
0,3,6,5,4
0,3,3,3,0
0,0,0,0,0
0,0,0,0,0
0,0,0,0,0
0,0,0,0,0
0,0,0,0,0
0,0,0,0,0
0,0,0,0,0
0,0,0,0,0
0,0,0,0,0
0,0,0,0,0
0,0,0,0,0
0,0,0,0,0
0,0,0,0,0
0,0,0,0,0
0,0,0,0,0
0,0,0,0,0
0,0,0,0,0
endlayer

layer
0,0,0,0,0
0,0,0,0,0
0,0,0,0,0
0,0,14,14,0
0,0,0,0,0
0,3,3,3,0
0,3,6,5,4
0,3,3,3,0
0,0,0,0,0
0,0,0,0,0
0,0,0,0,0
0,0,0,0,0
0,0,0,0,0
0,0,0,0,0
0,0,0,0,0
0,0,0,0,0
0,0,0,0,0
0,0,0,0,0
0,0,0,0,0
0,0,0,0,0
0,0,0,0,0
0,0,0,0,0
0,0,9,0,0
0,0,0,0,0
0,0,10,0,0
endlayer

layer
0,0,0,0,0
0,0,0,0,0
0,0,0,0,0
0,0,14,14,0
0,0,0,0,0
0,3,3,3,0
0,3,6,5,0
0,3,3,3,0
0,0,0,0,0
0,0,0,0,0
0,0,0,0,0
0,0,0,0,0
0,0,0,0,0
0,0,0,0,0
0,0,0,0,0
0,0,0,0,0
0,0,0,0,0
0,0,0,0,0
0,0,0,0,0
0,0,0,0,0
0,0,0,0,0
0,0,0,0,0
0,0,9,0,0
0,0,0,0,0
0,0,10,0,0
endlayer

layer
0,0,0,0,0
0,0,0,0,0
0,0,0,0,0
0,0,14,14,0
0,0,0,0,0
0,3,3,3,0
0,3,6,5,4
0,3,3,3,0
0,0,0,0,0
0,0,0,0,0
0,0,0,0,0
0,0,0,0,0
0,0,0,0,0
0,0,0,0,0
0,0,0,0,0
0,0,0,0,0
0,0,0,0,0
0,0,0,0,0
0,0,0,0,0
0,0,0,0,0
0,0,0,0,0
0,0,0,0,0
0,0,9,0,0
0,11,0,4,0
0,0,10,0,0
endlayer

layer
0,0,0,0,0
0,0,0,0,0
0,0,0,0,0
0,0,14,14,0
0,0,0,0,0
0,3,3,3,0
0,3,6,5,4
0,3,3,3,0
0,0,0,0,0
0,0,0,0,0
0,0,0,0,0
0,0,0,0,0
0,0,0,0,0
0,0,0,0,0
0,0,0,0,0
0,0,0,0,0
0,0,0,0,0
0,0,0,0,0
0,0,0,0,0
0,0,0,0,0
0,0,0,0,0
0,0,0,0,0
0,0,9,0,0
0,11,0,4,0
0,0,10,0,0
endlayer

layer
0,0,0,0,0
0,0,0,0,0
0,0,0,0,0
0,0,14,14,0
0,0,0,0,0
0,3,3,3,0
0,3,6,5,4
0,3,3,3,0
0,0,0,0,0
0,0,0,0,0
0,0,0,0,0
0,0,0,0,0
0,0,0,0,0
0,0,0,0,0
0,0,0,0,0
0,0,0,0,0
0,0,0,0,0
0,0,0,0,0
0,0,0,0,0
0,0,0,0,0
0,0,0,0,0
0,0,0,0,0
0,0,9,0,0
0,11,12,4,0
0,0,10,0,0
endlayer

layer
0,0,0,0,0
0,0,0,0,0
0,0,0,0,0
0,0,14,14,0
0,0,0,0,0
0,3,3,3,0
0,3,6,5,4
0,3,3,3,0
0,0,0,0,0
0,0,0,0,0
0,0,0,0,0
0,0,0,0,0
0,0,0,0,0
0,0,0,0,0
0,0,0,0,0
0,0,0,0,0
0,0,0,0,0
0,0,0,0,0
0,0,0,0,0
0,0,0,0,0
0,0,0,0,0
0,0,0,0,0
0,0,0,0,0
0,0,14,0,0
0,0,0,0,0
endlayer

layer
0,0,0,0,0
0,0,0,0,0
0,0,0,0,0
0,0,14,14,0
0,0,0,0,0
0,3,3,3,15
0,3,6,12,15
0,3,12,12,15
0,0,15,15,15
0,0,15,15,15
0,0,0,0,0
0,0,0,0,0
0,0,0,0,0
0,0,0,0,0
0,0,0,0,0
0,0,0,0,0
0,0,0,0,0
0,0,0,0,0
0,0,0,0,0
0,0,0,0,0
0,0,0,0,0
0,0,0,0,0
0,0,0,0,0
0,0,14,0,0
0,0,0,0,0
endlayer

layer
0,0,0,0,0
0,0,0,0,0
0,0,0,0,0
0,0,14,14,0
0,0,0,0,0
0,3,3,5,16
0,3,0,0,16
0,3,12,0,16
0,0,16,17,16
0,0,16,16,16
0,0,0,0,0
0,0,0,0,0
0,0,0,0,0
0,0,0,0,0
0,0,0,0,0
0,0,0,0,0
0,0,0,0,0
0,0,0,0,0
0,0,0,0,0
0,0,0,0,0
0,0,0,0,0
0,0,0,0,0
0,0,0,0,0
0,0,14,0,0
0,0,0,0,0
endlayer

layer
0,0,0,0,0
0,0,0,0,0
0,0,0,0,0
0,0,14,14,0
0,0,3,3,0
0,3,3,5,16
0,3,0,0,16
0,3,12,0,16
0,11,16,0,16
0,0,16,16,16
0,0,0,0,0
0,0,0,0,0
0,0,0,0,0
0,0,0,0,0
0,0,0,0,0
0,0,0,0,0
0,0,0,0,0
0,0,0,0,0
0,0,0,0,0
0,0,0,0,0
0,0,0,0,0
0,0,0,0,0
0,0,0,0,0
0,11,14,0,0
0,0,0,0,0
endlayer

layer
0,0,0,0,0
0,0,3,3,0
0,0,3,3,0
0,0,14,14,0
0,0,3,3,0
0,3,3,12,18
0,3,5,12,18
0,3,12,12,18
0,11,12,12,18
0,11,12,12,18
0,0,3,3,0
0,0,3,3,0
0,0,3,3,0
0,0,3,3,0
0,0,3,3,0
0,0,3,3,0
0,0,3,3,0
0,0,3,3,0
0,0,3,3,0
0,0,3,3,0
0,0,3,3,0
0,0,3,3,0
0,0,3,3,0
0,11,12,12,4
0,0,3,3,0
endlayer

layer
0,0,3,3,0
0,0,3,3,0
0,0,3,3,0
0,0,3,3,0
0,0,3,3,0
0,3,3,3,0
0,3,3,3,0
0,3,3,3,0
0,0,3,3,0
0,0,3,3,0
0,0,3,3,0
0,0,3,3,0
0,0,3,3,0
0,0,3,3,0
0,0,3,3,0
0,0,3,3,0
0,0,3,3,0
0,0,3,3,0
0,0,3,3,0
0,0,3,3,0
0,0,3,3,0
0,0,3,3,0
0,0,3,3,0
0,0,3,3,0
0,0,0,0,0
endlayer

layer
0,0,0,0,0
0,0,3,3,0
0,0,3,3,0
0,0,0,0,0
0,0,3,3,0
0,3,3,3,0
0,3,3,3,0
0,3,3,3,0
0,0,0,0,0
0,0,0,0,0
0,0,0,0,0
0,0,0,0,0
0,0,0,0,0
0,0,0,0,0
0,0,0,0,0
0,0,0,0,0
0,0,0,0,0
0,0,0,0,0
0,0,0,0,0
0,0,0,0,0
0,0,0,0,0
0,0,0,0,0
0,0,0,0,0
0,0,0,0,0
0,0,0,0,0
endlayer

