weight=4
dimensionsToSpawnIn=overworld
embed_into_distance=2
random_height_offset=0,0
acceptable_target_blocks=grass,dirt
unacceptable_target_blocks=flowing_water,water,flowing_lava,lava,ice,packed_ice,stained_hardened_clay-9,brick_block,double_stone_slab,stonebrick,red_sandstone,red_nether_brick,red_mushroom_block,brown_mushroom_block,planks,cobblestone,end_stone,obsidian,purpur_block,iron_bars,purpur_slab,purpur_pillar,netherrack,soul_sand,quartz_ore,stained_glass,glass
dimensions=6,15,15
allowable_overhang=0
max_leveling=1
leveling_buffer=-1
preventRotation=0
preserve_water=0
preserve_lava=0
uniqueMinDistance=0
spawnMinDistance=0
spawnMaxDistance=0

rule1=0,100,minecraft:stonebrick-2,stonebrick-1,stonebrick-0,stonebrick-0,stonebrick-0,stonebrick-2,stonebrick-1,stonebrick-0,stonebrick-0,stonebrick-0,stonebrick-2,dirt-0,dirt-0,dirt-0,dirt-0,dirt-0,dirt-0,dirt-0,dirt-0,dirt-0,dirt-0,dirt-0,dirt-0,dirt-0,dirt-0,dirt-0
rule2=0,100,minecraft:dirt-0
rule3=0,100,ChestGenHook:entities/zombie_pigman:9-2,ChestGenHook:entities/stray:9-4,ChestGenHook:entities/zombie_pigman:9-5,dirt-0,dirt-0,dirt-0,dirt-0,dirt-0
rule4=0,100,MobSpawner:Silverfish,MobSpawner:Zombie_Villager,MobSpawner:Cave_Spider,ChestGenHook:entities/stray:9-2,ChestGenHook:entities/slime:9-3,ChestGenHook:entities/zombie_pigman:9-4,dirt-0,dirt-0,dirt-0,dirt-0,dirt-0
rule5=0,100,minecraft:monster_egg-4,monster_egg-2,monster_egg-2,monster_egg-2,monster_egg-3,stonebrick-2,stonebrick-1,stonebrick-0,stonebrick-0,stonebrick-0,stonebrick-2,stonebrick-1,stonebrick-0,stonebrick-0,stonebrick-0,stonebrick-2,stonebrick-1,stonebrick-0,stonebrick-0,stonebrick-0,stonebrick-2,stonebrick-1,stonebrick-0,stonebrick-0,stonebrick-0
rule6=0,100,minecraft:grass-0
rule7=0,100,minecraft:dirt-1
rule8=1,80,minecraft:fence-0
rule9=0,100,minecraft:stone_stairs-3
rule10=0,100,minecraft:stone_slab-0
rule11=0,100,minecraft:stone_brick_stairs-0
rule12=0,100,minecraft:stone_brick_stairs-5
rule13=0,100,minecraft:stone_brick_stairs-4
rule14=0,100,minecraft:stone_brick_stairs-1
rule15=0,100,minecraft:stone_slab-5

layer
1,1,1,1,1,1,1,1,1,1,1,1,1,1,1
1,2,2,2,2,2,2,2,2,2,2,2,2,2,1
1,2,2,4,3,2,2,4,3,2,2,4,3,2,1
1,2,2,2,2,2,2,2,2,2,2,2,2,2,1
1,2,2,4,3,2,2,2,2,2,2,4,3,2,1
1,2,2,2,2,2,2,2,2,2,2,2,2,2,1
1,2,2,4,3,2,2,4,3,2,2,2,2,2,1
1,2,2,2,2,2,2,2,2,2,2,2,2,2,1
1,2,2,2,2,2,2,4,3,2,2,2,2,2,1
1,2,2,2,2,2,2,2,2,2,2,2,2,2,1
1,2,2,4,3,2,2,4,3,2,2,4,3,2,1
1,2,2,2,2,2,2,2,2,2,2,2,2,2,1
1,2,2,4,3,2,2,2,2,2,2,4,3,2,1
1,2,2,2,2,2,2,2,2,2,2,2,2,2,1
1,1,1,1,1,1,1,1,1,1,1,1,1,1,1
endlayer

layer
5,5,5,5,5,5,5,5,5,5,5,5,5,5,5
5,6,6,6,6,6,6,6,6,6,6,6,6,6,5
5,6,6,7,7,6,6,7,7,6,6,7,7,6,5
5,6,6,6,6,6,6,6,6,6,6,6,6,6,5
5,6,6,7,7,6,6,6,6,6,6,7,7,6,5
5,6,6,6,6,6,6,6,6,6,6,6,6,6,5
5,6,6,7,7,6,6,7,7,6,6,6,6,6,5
5,6,6,6,6,6,6,6,6,6,6,6,6,6,5
5,6,6,6,6,6,6,7,7,6,6,6,6,6,5
5,6,6,6,6,6,6,6,6,6,6,6,6,6,5
5,6,6,7,7,6,6,7,7,6,6,7,7,6,5
5,6,6,6,6,6,6,6,6,6,6,6,6,6,5
5,6,6,7,7,6,6,6,6,6,6,7,7,6,5
5,6,6,6,6,6,6,6,6,6,6,6,6,6,5
5,5,5,5,5,5,5,5,5,5,5,5,5,5,5
endlayer

layer
5,8,8,8,8,8,8,5,8,8,8,8,8,8,5
8,0,0,0,0,0,0,0,0,0,0,0,0,0,8
8,0,9,0,0,0,9,0,0,0,9,0,0,0,8
8,0,0,0,0,0,0,0,0,0,0,0,0,0,8
8,0,9,0,0,0,0,0,0,0,9,0,0,0,8
8,0,0,0,0,0,0,0,0,0,0,0,0,0,5
8,0,9,0,0,0,9,0,0,0,0,0,0,0,0
5,0,0,0,0,0,0,0,0,0,0,0,0,0,0
8,0,0,0,0,0,9,0,0,0,0,0,0,0,0
8,0,0,0,0,0,0,0,0,0,0,0,0,0,5
8,0,9,0,0,0,9,0,0,0,9,0,0,0,8
8,0,0,0,0,0,0,0,0,0,0,0,0,0,8
8,0,9,0,0,0,0,0,0,0,9,0,0,0,8
8,0,0,0,0,0,0,0,0,0,0,0,0,0,8
5,8,8,8,8,8,8,5,8,8,8,8,8,8,5
endlayer

layer
5,8,8,8,8,8,8,5,8,8,8,8,8,8,5
8,0,0,0,0,0,0,0,0,0,0,0,0,0,8
8,0,0,0,0,0,0,0,0,0,0,0,0,0,8
8,0,0,0,0,0,0,0,0,0,0,0,0,0,8
8,0,0,0,0,0,0,0,0,0,0,0,0,0,8
8,0,0,0,0,0,0,0,0,0,0,0,0,0,5
8,0,0,0,0,0,0,0,0,0,0,0,0,0,0
5,0,0,0,0,0,0,0,0,0,0,0,0,0,0
8,0,0,0,0,0,0,0,0,0,0,0,0,0,0
8,0,0,0,0,0,0,0,0,0,0,0,0,0,5
8,0,0,0,0,0,0,0,0,0,0,0,0,0,8
8,0,0,0,0,0,0,0,0,0,0,0,0,0,8
8,0,0,0,0,0,0,0,0,0,0,0,0,0,8
8,0,0,0,0,0,0,0,0,0,0,0,0,0,8
5,8,8,8,8,8,8,5,8,8,8,8,8,8,5
endlayer

layer
10,0,0,0,0,0,0,10,0,0,0,0,0,0,10
0,0,0,0,0,0,0,0,0,0,0,0,0,0,0
0,0,0,0,0,0,0,0,0,0,0,0,0,0,0
0,0,0,0,0,0,0,0,0,0,0,0,0,0,0
0,0,0,0,0,0,0,0,0,0,0,0,0,0,0
0,0,0,0,0,0,0,0,0,0,0,0,0,0,11
0,0,0,0,0,0,0,0,0,0,0,0,0,0,12
10,0,0,0,0,0,0,0,0,0,0,0,0,0,0
0,0,0,0,0,0,0,0,0,0,0,0,0,0,13
0,0,0,0,0,0,0,0,0,0,0,0,0,0,14
0,0,0,0,0,0,0,0,0,0,0,0,0,0,0
0,0,0,0,0,0,0,0,0,0,0,0,0,0,0
0,0,0,0,0,0,0,0,0,0,0,0,0,0,0
0,0,0,0,0,0,0,0,0,0,0,0,0,0,0
10,0,0,0,0,0,0,10,0,0,0,0,0,0,10
endlayer

layer
0,0,0,0,0,0,0,0,0,0,0,0,0,0,0
0,0,0,0,0,0,0,0,0,0,0,0,0,0,0
0,0,0,0,0,0,0,0,0,0,0,0,0,0,0
0,0,0,0,0,0,0,0,0,0,0,0,0,0,0
0,0,0,0,0,0,0,0,0,0,0,0,0,0,0
0,0,0,0,0,0,0,0,0,0,0,0,0,0,0
0,0,0,0,0,0,0,0,0,0,0,0,0,0,15
0,0,0,0,0,0,0,0,0,0,0,0,0,0,15
0,0,0,0,0,0,0,0,0,0,0,0,0,0,15
0,0,0,0,0,0,0,0,0,0,0,0,0,0,0
0,0,0,0,0,0,0,0,0,0,0,0,0,0,0
0,0,0,0,0,0,0,0,0,0,0,0,0,0,0
0,0,0,0,0,0,0,0,0,0,0,0,0,0,0
0,0,0,0,0,0,0,0,0,0,0,0,0,0,0
0,0,0,0,0,0,0,0,0,0,0,0,0,0,0
endlayer

