weight=3
dimensionsToSpawnIn=overworld
embed_into_distance=1
random_height_offset=0,0
unacceptable_target_blocks=flowing_water,water,flowing_lava,lava,ice,packed_ice,stained_hardened_clay-9,brick_block,double_stone_slab,stonebrick,red_sandstone,red_nether_brick,red_mushroom_block,brown_mushroom_block,planks,cobblestone,end_stone,obsidian,purpur_block,iron_bars,purpur_slab,purpur_pillar,netherrack,soul_sand,quartz_ore,stained_glass,glass
dimensions=8,15,17
allowable_overhang=0
max_leveling=1
leveling_buffer=-1
preventRotation=0
preserve_water=0
preserve_lava=0
preserve_plants=0
uniqueMinDistance=5000
spawnMinDistance=0
spawnMaxDistance=0


rule1=0,100,preserveBlock
rule2=0,100,chisel:technicalnew-5
rule3=0,100,minecraft:farmland-7
rule4=0,100,minecraft:water-0
rule5=0,100,minecraft:dirt-0
rule6=0,100,MobSpawner:Zombie,MobSpawner:Silverfish
rule7=0,100,MobSpawner:Cave_Spider,MobSpawner:Cave_Spider,MobSpawner:Silverfish
rule8=0,100,chisel:glass-2
rule9=0,100,minecraft:stone_slab-0
rule10=0,100,minecraft:pumpkin_stem-7
rule11=0,100,minecraft:pumpkin-0
rule12=0,100,minecraft:melon_stem-7
rule13=0,100,minecraft:melon_block-0
rule14=0,100,minecraft:wheat-7
rule15=0,100,minecraft:iron_door-0
rule16=0,100,minecraft:iron_door-1
rule17=0,100,minecraft:iron_door-3
rule18=2,100,minecraft:stone_button-2
rule19=0,100,minecraft:iron_door-8
rule20=2,100,minecraft:stone_button-1
rule21=2,100,minecraft:stone_button-4
rule22=0,100,minecraft:iron_door-9
rule23=2,100,minecraft:stone_button-3
rule24=2,100,air

layer
1,1,1,1,2,2,2,2,2,2,2,2,2,1,1,1,1
1,1,1,1,2,2,2,2,2,2,2,2,2,1,1,1,1
1,1,1,1,2,2,2,2,2,2,2,2,2,1,1,1,1
1,1,1,1,2,2,5,3,4,3,3,2,2,1,1,1,1
1,1,1,1,2,2,3,3,4,3,3,2,2,1,1,1,1
1,1,1,1,2,2,3,3,4,5,3,2,2,1,1,1,1
2,2,2,2,2,2,5,3,4,3,5,2,2,2,2,2,2
2,2,2,2,2,6,2,2,4,2,2,6,2,2,2,2,2
2,2,2,3,3,3,3,3,3,3,3,3,3,3,2,2,2
2,2,2,3,3,3,3,3,3,3,3,3,3,3,2,2,2
2,2,2,4,4,4,4,4,4,4,4,4,4,4,2,2,2
2,2,2,3,3,3,3,3,3,3,3,3,3,3,2,2,2
2,2,2,3,3,3,3,3,3,3,3,3,3,3,2,2,2
2,2,2,2,2,2,2,2,7,2,2,2,2,2,2,2,2
2,2,2,2,2,2,2,2,2,2,2,2,2,2,2,2,2
endlayer

layer
1,1,1,1,2,2,2,2,2,2,2,2,2,1,1,1,1
1,1,1,1,2,2,2,2,2,2,2,2,2,1,1,1,1
1,1,1,1,8,9,9,9,9,9,9,9,8,1,1,1,1
1,1,1,1,8,9,11,10,9,24,24,9,8,1,1,1,1
1,1,1,1,8,9,24,24,9,12,24,9,8,1,1,1,1
1,1,1,1,8,9,10,24,9,13,12,9,8,1,1,1,1
2,2,8,8,2,9,11,24,9,24,13,9,2,8,8,2,2
2,2,9,9,9,9,9,9,9,9,9,9,9,9,9,2,2
2,2,9,14,14,14,14,14,14,14,14,14,14,14,9,2,2
2,2,9,14,14,14,14,14,14,14,14,14,14,14,9,2,2
2,2,9,9,9,9,9,9,9,9,9,9,9,9,9,2,2
2,2,9,14,14,14,14,14,14,14,14,14,14,14,9,2,2
2,2,9,14,14,14,14,14,14,14,14,14,14,14,9,2,2
2,2,9,9,9,9,9,9,9,9,9,9,9,9,9,2,2
2,2,8,8,8,8,8,8,2,8,8,8,8,8,8,2,2
endlayer

layer
1,1,1,1,2,0,0,0,0,0,0,0,2,1,1,1,1
1,1,1,1,2,8,8,2,15,2,8,8,2,1,1,1,1
1,1,1,1,8,24,24,24,24,24,24,24,8,1,1,1,1
1,1,1,1,8,24,24,24,24,24,24,24,8,1,1,1,1
1,1,1,1,8,24,24,24,24,24,24,24,8,1,1,1,1
1,1,1,1,8,24,24,24,24,24,24,24,8,1,1,1,1
2,2,8,8,2,24,24,24,24,24,24,24,2,8,8,2,2
0,8,24,24,24,24,24,24,24,24,24,24,24,24,24,8,0
0,8,24,24,24,24,24,24,24,24,24,24,24,24,24,8,0
0,2,24,24,24,24,24,24,24,24,24,24,24,24,24,2,0
0,17,24,24,24,24,24,24,24,24,24,24,24,24,24,16,0
0,2,24,24,24,24,24,24,24,24,24,24,24,24,24,2,0
0,8,24,24,24,24,24,24,24,24,24,24,24,24,24,8,0
0,8,24,24,24,24,24,24,24,24,24,24,24,24,24,8,0
2,2,8,8,8,8,8,8,2,8,8,8,8,8,8,2,2
endlayer

layer
1,1,1,1,2,0,0,18,0,0,0,0,2,1,1,1,1
1,1,1,1,2,8,8,2,19,2,8,8,2,1,1,1,1
1,1,1,1,8,24,24,24,24,20,24,24,8,1,1,1,1
1,1,1,1,8,24,24,24,24,24,24,24,8,1,1,1,1
1,1,1,1,8,24,24,24,24,24,24,24,8,1,1,1,1
1,1,1,1,8,24,24,24,24,24,24,24,8,1,1,1,1
2,2,8,8,2,24,24,24,24,24,24,24,2,8,8,2,2
0,8,24,24,24,24,24,24,24,24,24,24,24,24,24,8,0
0,8,24,24,24,24,24,24,24,24,24,24,24,24,24,8,0
0,2,21,24,24,24,24,24,24,24,24,24,24,24,24,2,21
0,22,24,24,24,24,24,24,24,24,24,24,24,24,24,22,0
23,2,24,24,24,24,24,24,24,24,24,24,24,24,23,2,0
0,8,24,24,24,24,24,24,24,24,24,24,24,24,24,8,0
0,8,24,24,24,24,24,24,24,24,24,24,24,24,24,8,0
2,2,8,8,8,8,8,8,2,8,8,8,8,8,8,2,2
endlayer

layer
1,1,1,1,0,2,0,0,0,0,0,2,0,1,1,1,1
1,1,1,1,0,2,8,8,2,8,8,2,0,1,1,1,1
1,1,1,1,0,8,24,24,24,24,24,8,0,1,1,1,1
1,1,1,1,0,8,24,24,24,24,24,8,0,1,1,1,1
1,1,1,1,0,8,24,24,24,24,24,8,0,1,1,1,1
1,1,1,1,0,8,24,24,24,24,24,8,0,1,1,1,1
0,0,0,0,8,2,24,24,24,24,24,2,8,0,0,0,0
2,2,8,8,2,24,24,24,24,24,24,24,2,8,8,2,2
0,8,24,24,24,24,24,24,24,24,24,24,24,24,24,8,0
0,8,24,24,24,24,24,24,24,24,24,24,24,24,24,8,0
0,2,24,24,24,24,24,24,24,24,24,24,24,24,24,2,0
0,8,24,24,24,24,24,24,24,24,24,24,24,24,24,8,0
0,8,24,24,24,24,24,24,24,24,24,24,24,24,24,8,0
2,2,8,8,8,8,8,8,2,8,8,8,8,8,8,2,2
0,0,0,0,0,0,0,0,0,0,0,0,0,0,0,0,0
endlayer

layer
1,1,1,0,0,2,0,0,0,0,0,2,0,0,1,1,1
1,1,1,0,0,2,8,8,8,8,8,2,0,0,1,1,1
1,1,1,0,0,8,24,24,24,24,24,8,0,0,1,1,1
1,1,1,0,0,8,24,24,24,24,24,8,0,0,1,1,1
1,1,1,0,0,8,24,24,24,24,24,8,0,0,1,1,1
0,0,0,0,0,8,24,24,24,24,24,8,0,0,0,0,0
0,0,0,0,0,8,24,24,24,24,24,8,0,0,0,0,0
2,2,8,8,8,2,24,24,24,24,24,2,8,8,8,2,2
0,8,24,24,24,24,24,24,24,24,24,24,24,24,24,8,0
0,8,24,24,24,24,24,24,24,24,24,24,24,24,24,8,0
0,8,24,24,24,24,24,24,24,24,24,24,24,24,24,8,0
0,8,24,24,24,24,24,24,24,24,24,24,24,24,24,8,0
0,8,24,24,24,24,24,24,24,24,24,24,24,24,24,8,0
2,2,8,8,8,8,8,8,2,8,8,8,8,8,8,2,2
0,0,0,0,0,0,0,0,0,0,0,0,0,0,0,0,0
endlayer

layer
0,0,0,0,0,0,2,0,0,0,2,0,0,0,0,0,0
0,0,0,0,0,0,2,8,8,8,2,0,0,0,0,0,0
0,0,0,0,0,0,8,24,24,24,8,0,0,0,0,0,0
0,0,0,0,0,0,8,24,24,24,8,0,0,0,0,0,0
0,0,0,0,0,0,8,24,24,24,8,0,0,0,0,0,0
0,0,0,0,0,0,8,24,24,24,8,0,0,0,0,0,0
0,0,0,0,0,0,8,24,24,24,8,0,0,0,0,0,0
0,0,0,0,0,0,8,24,24,24,8,0,0,0,0,0,0
2,2,8,8,8,8,2,24,24,24,2,8,8,8,8,2,2
0,8,24,24,24,24,24,24,24,24,24,24,24,24,24,8,0
0,8,24,24,24,24,24,24,24,24,24,24,24,24,24,8,0
0,8,24,24,24,24,24,24,24,24,24,24,24,24,24,8,0
2,2,8,8,8,8,8,8,2,8,8,8,8,8,8,2,2
0,0,0,0,0,0,0,0,0,0,0,0,0,0,0,0,0
0,0,0,0,0,0,0,0,0,0,0,0,0,0,0,0,0
endlayer

layer
0,0,0,0,0,0,0,2,2,2,0,0,0,0,0,0,0
0,0,0,0,0,0,0,2,2,2,0,0,0,0,0,0,0
0,0,0,0,0,0,0,8,8,8,0,0,0,0,0,0,0
0,0,0,0,0,0,0,8,8,8,0,0,0,0,0,0,0
0,0,0,0,0,0,0,8,8,8,0,0,0,0,0,0,0
0,0,0,0,0,0,0,8,8,8,0,0,0,0,0,0,0
0,0,0,0,0,0,0,8,8,8,0,0,0,0,0,0,0
0,0,0,0,0,0,0,8,8,8,0,0,0,0,0,0,0
0,0,0,0,0,0,0,8,8,8,0,0,0,0,0,0,0
2,2,8,8,8,8,8,2,8,2,8,8,8,8,8,2,2
2,2,8,8,8,8,8,8,2,8,8,8,8,8,8,2,2
2,2,8,8,8,8,8,8,2,8,8,8,8,8,8,2,2
0,0,0,0,0,0,0,0,0,0,0,0,0,0,0,0,0
0,0,0,0,0,0,0,0,0,0,0,0,0,0,0,0,0
0,0,0,0,0,0,0,0,0,0,0,0,0,0,0,0,0
endlayer

