weight=5
dimensionsToSpawnIn=overworld
embed_into_distance=1
random_height_offset=0,0
unacceptable_target_blocks=sand,flowing_water,water,flowing_lava,lava,ice,packed_ice,stained_hardened_clay-9,brick_block,double_stone_slab,stonebrick,red_sandstone,red_nether_brick,red_mushroom_block,brown_mushroom_block,planks,cobblestone,end_stone,obsidian,purpur_block,iron_bars,purpur_slab,purpur_pillar,netherrack,soul_sand,quartz_ore,stained_glass,glass
dimensions=37,11,21
allowable_overhang=0
max_leveling=1
leveling_buffer=-1
preventRotation=0
preserve_water=0
preserve_lava=0
uniqueMinDistance=10000
spawnMinDistance=0
spawnMaxDistance=0

rule1=0,100,preserveBlock
rule2=0,100,minecraft:stone_brick_stairs-6
rule3=0,100,minecraft:stone_brick_stairs-2
rule4=0,100,minecraft:stone_slab-5
rule5=0,100,minecraft:stone_brick_stairs-7
rule6=0,100,minecraft:stone_slab-8
rule7=0,100,minecraft:stone_slab-13
rule8=0,100,minecraft:stone_brick_stairs-3
rule9=0,100,chisel:technical-12
rule10=0,100,minecraft:vine-8
rule11=0,100,minecraft:cobblestone_wall-0
rule12=0,100,minecraft:double_stone_slab-0
rule13=0,100,minecraft:vine-2
rule14=0,100,minecraft:stone-6
rule15=0,100,minecraft:stone_brick_stairs-4
rule16=0,100,minecraft:stonebrick-0
rule17=0,100,minecraft:iron_bars-0
rule18=0,100,minecraft:stone_brick_stairs-5
rule19=0,100,chisel:technical-15
rule20=0,100,chisel:laboratory-11
rule21=0,100,minecraft:stone_brick_stairs-1
rule22=0,100,minecraft:stone_brick_stairs-0
rule23=0,100,chisel:factory-5
rule24=0,100,minecraft:stone_slab-0
rule25=0,100,chisel:laboratory-12
rule26=0,100,minecraft:vine-1
rule27=0,100,minecraft:quartz_block-0
rule28=0,100,chisel:factory-2
rule29=0,100,chisel:technicalnew-6
rule30=0,100,minecraft:vine-4
rule31=0,100,minecraft:vine-3
rule32=0,100,minecraft:stained_hardened_clay-1
rule33=2,100,minecraft:stone_button-2
rule34=0,100,minecraft:vine-12
rule35=2,100,minecraft:stone_button-4
rule36=2,100,minecraft:stone_button-3
rule37=2,100,minecraft:stone_button-1
rule38=0,100,minecraft:quartz_block-2
rule39=0,100,minecraft:vine-6
rule40=0,100,minecraft:quartz_stairs-0
rule41=0,100,minecraft:quartz_stairs-2
rule42=0,100,minecraft:quartz_stairs-3
rule43=0,100,minecraft:quartz_stairs-1
rule44=0,100,chisel:technical-1
rule45=0,100,chisel:factory-8
rule46=0,100,chisel:technicalnew-3
rule47=0,100,chisel:laboratory-15
rule48=0,100,chisel:laboratory-4
rule49=0,100,chisel:technical-11
rule50=0,100,chisel:blockelectrum-4
rule51=0,100,minecraft:stone_slab-15
rule52=0,100,minecraft:quartz_stairs-4
rule53=0,100,minecraft:quartz_stairs-6
rule54=0,100,minecraft:stone_slab-7
rule55=0,100,minecraft:quartz_stairs-7
rule56=0,100,minecraft:quartz_stairs-5
rule57=0,100,minecraft:vine-5
rule58=0,100,minecraft:quartz_block-3
rule59=0,100,minecraft:quartz_block-4
rule60=0,100,minecraft:dark_oak_stairs-2
rule61=0,100,minecraft:dark_oak_stairs-7
rule62=0,100,minecraft:dark_oak_fence_gate-3
rule63=0,100,minecraft:dark_oak_fence_gate-1
rule64=0,100,minecraft:wooden_slab-5
rule65=0,100,chisel:factory-9

layer
1,1,1,1,1,1,1,1,1,1,1,1,1,1,1,1,1,1,1,1,1
1,1,1,5,4,3,4,3,2,1,1,1,1,1,5,4,3,4,3,2,1
1,1,1,1,6,6,6,6,1,1,1,1,1,1,1,6,6,6,6,1,1
1,1,1,5,4,3,4,3,2,1,1,1,1,1,5,4,3,4,3,2,1
1,1,1,1,1,1,1,1,1,1,1,1,1,1,1,1,1,1,1,1,1
1,1,1,1,1,1,1,1,1,1,1,1,1,1,1,1,1,1,1,1,1
1,1,1,1,1,1,1,1,1,1,1,1,1,1,1,1,1,1,1,1,1
1,1,1,5,4,3,4,3,2,1,1,1,1,1,5,4,3,4,3,2,1
1,1,1,1,6,6,6,6,1,1,1,1,1,1,1,6,6,6,6,1,1
1,1,1,5,4,3,4,3,2,1,1,1,1,1,5,4,3,4,3,2,1
1,1,1,1,1,1,1,1,1,1,1,1,1,1,1,1,1,1,1,1,1
endlayer

layer
1,1,1,1,1,1,1,1,1,1,1,1,1,1,1,1,1,1,1,1,1
1,1,1,8,5,7,5,7,3,1,1,1,1,1,8,5,7,5,7,3,1
1,1,1,1,9,9,9,9,1,6,6,6,6,6,1,9,9,9,9,1,1
1,1,1,8,5,7,5,7,3,6,1,1,1,6,8,5,7,5,7,3,1
1,1,1,1,1,1,1,1,1,6,1,1,1,6,1,1,1,1,1,1,1
1,1,1,1,1,1,1,1,1,6,1,1,1,6,1,1,1,1,1,1,1
1,1,1,1,1,1,1,1,1,6,1,1,1,6,1,1,1,1,1,1,1
1,1,1,8,5,7,5,7,3,6,1,1,1,6,8,5,7,5,7,3,1
1,1,1,1,9,9,9,9,1,6,6,6,6,6,1,9,9,9,9,1,1
1,1,1,8,5,7,5,7,3,1,1,1,1,1,8,5,7,5,7,3,1
1,1,1,1,1,1,1,1,1,1,1,1,1,1,1,1,1,1,1,1,1
endlayer

layer
1,1,1,1,1,1,10,1,1,1,1,1,1,1,1,1,10,1,1,1,1
1,1,1,1,1,7,1,7,1,1,1,1,1,1,1,7,1,7,1,1,1
1,1,1,1,11,11,11,11,6,3,8,4,3,8,6,11,11,11,11,1,1
1,1,1,6,6,6,6,6,12,11,11,11,11,11,11,11,12,6,6,6,1
1,1,1,1,1,1,1,1,6,11,1,1,1,11,1,1,6,1,1,1,1
1,1,1,6,6,6,6,6,12,11,11,11,11,11,11,11,12,6,6,6,1
1,1,1,1,1,1,1,1,6,11,1,1,1,11,1,1,6,1,1,1,1
1,1,1,6,6,6,6,6,12,11,11,11,11,11,11,11,12,6,6,6,1
1,1,1,1,11,11,11,11,6,3,8,4,3,8,6,11,11,11,11,1,1
1,1,1,1,1,7,1,7,1,1,1,1,1,1,1,7,1,7,1,1,1
1,1,1,1,1,1,1,1,1,1,1,1,1,1,1,1,13,1,1,1,1
endlayer

layer
1,1,1,1,1,11,10,11,1,1,1,1,1,1,1,11,10,11,1,1,1
1,1,1,7,5,14,9,14,2,7,7,7,7,7,5,14,9,14,2,7,1
1,1,1,15,15,16,16,16,12,12,12,12,12,12,12,16,16,16,2,15,1
1,1,11,14,9,9,9,9,9,9,9,9,9,9,9,9,9,9,9,14,11
1,1,17,14,1,1,1,1,9,1,9,1,9,1,1,1,9,1,1,14,17
1,1,11,14,9,9,9,9,9,1,9,1,9,1,1,1,9,9,9,14,11
1,1,17,14,1,1,1,1,9,1,9,1,9,1,1,1,9,1,1,14,17
1,1,11,14,9,9,9,9,9,9,9,9,9,9,9,9,9,9,9,14,11
1,1,1,18,18,16,16,16,12,12,12,12,12,12,12,16,16,16,18,18,1
1,1,1,7,5,14,9,14,2,7,7,7,7,7,5,14,9,14,2,7,1
1,1,1,1,1,11,13,11,1,1,1,1,1,1,1,11,13,11,1,1,1
endlayer

layer
1,1,7,7,15,11,15,11,17,15,17,15,17,15,17,11,15,11,15,7,7
1,1,7,19,19,14,19,14,19,14,14,14,16,14,19,14,19,14,19,19,7
1,1,5,19,19,19,19,19,19,3,20,8,19,19,19,19,19,19,19,19,2
1,1,11,14,19,19,19,19,19,3,22,22,21,21,21,21,21,19,19,14,11
1,1,5,19,19,19,19,19,19,19,19,19,3,1,1,1,8,19,19,19,2
1,1,11,14,19,19,19,19,19,19,19,19,3,1,1,1,8,19,19,14,11
1,1,5,19,19,19,19,19,19,19,19,19,3,1,1,1,8,19,19,19,2
1,1,11,14,19,19,19,19,19,21,21,8,3,22,22,22,22,19,19,14,11
1,1,5,19,19,19,19,19,19,3,23,8,19,19,19,19,19,19,19,19,2
1,1,7,19,19,14,19,14,19,14,14,14,16,14,19,14,19,14,19,19,7
1,1,7,7,18,11,18,11,18,17,18,17,18,17,18,11,18,11,18,7,7
endlayer

layer
1,1,1,1,24,24,24,24,24,24,24,24,24,24,24,24,24,24,24,1,1
1,1,1,24,4,4,25,25,25,25,25,4,4,4,4,4,4,4,4,24,1
1,1,24,22,1,1,25,22,1,1,25,1,1,1,1,1,1,1,1,4,24
1,1,24,9,21,21,25,9,3,1,1,1,1,1,65,1,1,10,1,4,24
1,1,24,3,1,1,18,8,1,1,8,16,1,1,1,1,1,16,3,4,24
1,1,24,3,1,17,1,8,1,1,1,1,65,1,65,1,65,1,1,4,24
1,1,24,3,1,1,1,8,1,1,8,16,1,1,1,1,1,16,3,4,24
1,1,24,9,22,22,22,9,3,1,1,1,1,1,65,1,1,1,1,4,24
1,1,24,21,1,1,1,21,1,1,1,1,1,1,1,1,1,1,1,4,24
1,1,1,24,4,4,4,4,4,4,4,4,4,4,4,4,4,4,4,24,1
1,1,1,1,24,24,24,24,24,24,24,24,24,24,24,24,24,24,24,1,1
endlayer

layer
1,1,1,1,1,1,1,1,1,1,1,1,1,1,1,1,1,1,1,1,1
1,1,1,1,1,1,1,1,1,1,1,1,1,1,1,1,1,1,1,1,1
1,1,1,1,1,1,1,1,1,1,1,1,1,1,10,1,1,1,1,1,1
1,1,1,28,1,1,1,28,1,1,1,1,1,10,27,26,1,1,1,1,1
1,1,1,1,1,1,25,1,1,1,1,8,2,6,15,6,5,3,1,1,1
1,1,30,1,1,17,1,1,1,1,1,1,27,5,29,2,27,1,1,1,1
1,1,1,10,1,1,1,1,1,1,1,8,2,6,18,6,5,3,1,1,1
1,1,30,28,1,1,1,28,1,1,1,1,1,13,27,31,1,1,1,1,1
1,1,1,13,1,1,1,13,1,1,1,1,1,1,1,1,1,1,1,1,1
1,1,1,1,1,1,1,1,1,1,1,1,1,1,1,1,1,1,1,1,1
1,1,1,1,1,1,1,1,1,1,1,1,1,1,1,1,1,1,1,1,1
endlayer

layer
1,1,1,1,1,1,1,1,1,1,1,1,1,1,1,1,1,1,1,1,1
1,1,1,1,1,1,1,1,1,1,1,1,1,1,1,1,1,1,1,1,1
1,1,1,1,1,1,1,1,1,1,1,1,1,1,10,1,1,1,1,1,1
1,1,1,28,1,1,1,28,1,1,1,1,1,10,27,26,1,1,1,1,1
1,1,1,13,1,1,25,1,1,1,1,1,4,32,32,32,4,1,1,1,1
1,1,30,1,1,17,1,1,1,1,1,1,27,32,29,32,27,1,1,1,1
1,1,1,1,1,1,1,1,1,1,1,1,4,32,32,32,4,1,1,1,1
1,1,1,28,1,1,1,28,1,1,1,1,1,13,27,31,1,1,1,1,1
1,1,1,1,1,13,13,1,1,1,1,1,1,1,1,1,1,1,1,1,1
1,1,1,1,1,1,1,1,1,1,1,1,1,1,1,1,1,1,1,1,1
1,1,1,1,1,1,1,1,1,1,1,1,1,1,1,1,1,1,1,1,1
endlayer

layer
1,1,1,1,1,1,1,1,1,1,1,1,1,1,1,1,1,1,1,1,1
1,1,1,1,1,1,1,1,1,1,1,1,1,1,1,1,1,1,1,1,1
1,1,1,33,1,1,10,33,1,1,1,1,1,1,10,1,1,1,1,1,1
1,1,36,9,28,28,28,9,35,1,1,1,1,34,27,10,1,1,1,1,1
1,1,1,28,24,24,25,28,1,1,1,1,1,32,32,32,10,1,1,1,1
1,1,30,28,24,17,24,28,1,1,1,1,27,32,29,32,27,1,1,1,1
1,1,1,28,24,24,24,28,1,1,1,1,1,32,32,32,1,1,1,1,1
1,1,36,9,28,28,28,9,35,1,1,1,1,13,27,31,1,1,1,1,1
1,1,1,37,1,13,13,37,1,1,1,1,1,1,13,1,1,1,1,1,1
1,1,1,1,1,1,1,1,1,1,1,1,1,1,1,1,1,1,1,1,1
1,1,1,1,1,1,1,1,1,1,1,1,1,1,1,1,1,1,1,1,1
endlayer

layer
1,1,1,1,1,1,1,1,1,1,1,1,1,1,1,1,1,1,1,1,1
1,1,1,1,1,1,1,1,1,1,1,1,1,1,1,1,1,1,1,1,1
1,1,1,1,1,1,1,1,1,1,1,1,1,1,10,1,1,1,1,1,1
1,1,1,28,1,1,5,28,1,1,1,1,1,34,38,1,1,1,1,1,1
1,1,1,18,1,1,25,1,1,1,1,1,34,32,32,32,10,1,1,1,1
1,1,1,1,1,17,1,1,1,1,1,1,38,32,29,32,38,1,1,1,1
1,1,1,10,1,1,1,15,1,1,1,1,1,32,32,32,13,1,1,1,1
1,1,1,28,2,1,1,28,1,1,1,1,1,1,38,13,1,1,1,1,1
1,1,1,1,1,1,1,1,1,1,1,1,1,1,13,1,1,1,1,1,1
1,1,1,1,1,1,1,1,1,1,1,1,1,1,1,1,1,1,1,1,1
1,1,1,1,1,1,1,1,1,1,1,1,1,1,1,1,1,1,1,1,1
endlayer

layer
1,1,1,1,1,1,1,1,1,1,1,1,1,1,1,1,1,1,1,1,1
1,1,1,1,1,1,1,1,1,1,1,1,1,1,1,1,1,1,1,1,1
1,1,1,1,1,1,1,1,1,1,1,1,1,1,1,1,1,1,1,1,1
1,1,1,28,1,5,3,28,1,1,1,1,1,34,27,1,1,1,1,1,1
1,1,1,22,1,1,25,1,1,1,1,1,30,32,32,32,26,1,1,1,1
1,1,1,18,1,17,1,15,1,1,1,30,27,32,29,32,27,1,1,1,1
1,1,1,10,1,1,1,21,1,1,1,1,1,32,32,32,13,1,1,1,1
1,1,1,28,8,2,1,28,1,1,1,1,1,39,27,13,1,1,1,1,1
1,1,1,13,1,1,1,13,1,1,1,1,1,1,1,1,1,1,1,1,1
1,1,1,1,1,1,1,1,1,1,1,1,1,1,1,1,1,1,1,1,1
1,1,1,1,1,1,1,1,1,1,1,1,1,1,1,1,1,1,1,1,1
endlayer

layer
1,1,1,1,1,1,1,1,1,1,1,1,1,1,1,1,1,1,1,1,1
1,1,1,1,1,1,1,1,1,1,1,1,1,1,1,1,1,1,1,1,1
1,1,1,10,1,1,1,1,1,1,1,1,1,1,1,1,1,1,1,1,1
1,1,1,28,5,3,1,28,1,1,1,1,1,34,38,1,1,1,1,1,1
1,1,1,13,1,1,25,15,1,1,1,1,30,32,32,32,26,1,1,1,1
1,1,1,22,1,17,1,21,1,1,1,30,38,32,29,32,38,26,1,1,1
1,1,1,18,1,1,1,1,1,1,1,1,30,32,32,32,1,1,1,1,1
1,1,30,28,1,8,2,28,26,1,1,1,1,13,38,31,1,1,1,1,1
1,1,1,13,1,1,1,1,1,1,1,1,1,1,1,1,1,1,1,1,1
1,1,1,1,1,1,1,1,1,1,1,1,1,1,1,1,1,1,1,1,1
1,1,1,1,1,1,1,1,1,1,1,1,1,1,1,1,1,1,1,1,1
endlayer

layer
1,1,1,1,1,1,1,1,1,1,1,1,1,1,1,1,1,1,1,1,1
1,1,1,1,1,1,1,1,1,1,1,1,1,1,1,1,1,1,1,1,1
1,1,1,1,1,10,1,1,1,1,1,1,1,1,1,1,1,1,1,1,1
1,1,1,28,3,1,1,28,1,1,1,1,1,10,38,1,1,1,1,1,1
1,1,1,13,1,1,25,21,1,1,1,1,30,32,32,32,10,1,1,1,1
1,1,1,1,1,17,1,1,1,1,1,1,38,32,29,32,38,26,1,1,1
1,1,1,22,1,1,1,1,1,1,1,1,30,32,32,32,1,1,1,1,1
1,1,1,28,1,1,8,28,1,1,1,1,1,13,38,31,1,1,1,1,1
1,1,1,1,1,1,1,1,1,1,1,1,1,1,1,1,1,1,1,1,1
1,1,1,1,1,1,1,1,1,1,1,1,1,1,1,1,1,1,1,1,1
1,1,1,1,1,1,1,1,1,1,1,1,1,1,1,1,1,1,1,1,1
endlayer

layer
1,1,1,1,1,1,1,1,1,1,1,1,1,1,1,1,1,1,1,1,1
1,1,1,1,1,1,1,1,1,1,1,1,1,1,1,1,1,1,1,1,1
1,1,1,33,10,10,1,33,1,1,1,1,1,1,10,1,1,1,1,1,1
1,1,36,9,28,28,28,9,35,1,1,1,1,1,27,10,1,1,1,1,1
1,1,1,28,24,24,25,28,26,1,1,1,30,32,32,32,26,1,1,1,1
1,1,1,28,24,17,24,28,1,1,1,1,27,32,29,32,27,26,1,1,1
1,1,1,28,24,24,24,28,1,1,1,1,1,32,32,32,26,1,1,1,1
1,1,36,9,28,28,28,9,35,1,1,1,1,1,27,31,1,1,1,1,1
1,1,1,37,1,13,1,37,1,1,1,1,1,1,1,1,1,1,1,1,1
1,1,1,1,1,1,1,1,1,1,1,1,1,1,1,1,1,1,1,1,1
1,1,1,1,1,1,1,1,1,1,1,1,1,1,1,1,1,1,1,1,1
endlayer

layer
1,1,1,1,1,1,1,1,1,1,1,1,1,1,1,1,1,1,1,1,1
1,1,1,1,1,1,1,1,1,1,1,1,1,1,1,1,1,1,1,1,1
1,1,1,1,1,1,1,10,1,1,1,1,1,1,10,1,1,1,1,1,1
1,1,30,28,1,1,5,28,26,1,1,1,1,10,27,10,1,1,1,1,1
1,1,1,18,1,1,25,1,1,1,1,1,10,32,32,32,26,1,1,1,1
1,1,1,1,1,17,1,1,1,1,1,1,27,32,29,32,27,26,1,1,1
1,1,1,1,1,1,1,15,1,1,1,1,1,32,32,32,26,1,1,1,1
1,1,1,28,2,1,30,28,1,1,1,1,1,1,27,26,1,1,1,1,1
1,1,1,13,1,1,1,13,1,1,1,1,1,1,1,1,1,1,1,1,1
1,1,1,1,1,1,1,1,1,1,1,1,1,1,1,1,1,1,1,1,1
1,1,1,1,1,1,1,1,1,1,1,1,1,1,1,1,1,1,1,1,1
endlayer

layer
1,1,1,1,1,1,1,1,1,1,1,1,1,1,1,1,1,1,1,1,1
1,1,1,1,1,1,1,1,1,1,1,1,1,1,1,1,1,1,1,1,1
1,1,1,1,1,1,1,1,1,1,1,1,1,1,1,1,1,1,1,1,1
1,1,30,28,1,5,3,28,1,1,1,1,1,10,40,1,1,1,1,1,1
1,1,1,22,1,1,25,1,1,1,1,1,1,32,32,32,1,1,1,1,1
1,1,1,18,1,17,1,15,1,1,1,1,42,32,32,32,41,1,1,1,1
1,1,1,1,1,1,1,21,1,1,1,1,1,32,32,32,26,1,1,1,1
1,1,1,28,8,2,30,28,1,1,1,1,1,1,43,13,1,1,1,1,1
1,1,1,13,1,1,1,1,1,1,1,1,1,1,1,1,1,1,1,1,1
1,1,1,1,1,1,1,1,1,1,1,1,1,1,1,1,1,1,1,1,1
1,1,1,1,1,1,1,1,1,1,1,1,1,1,1,1,1,1,1,1,1
endlayer

layer
1,1,1,1,1,1,1,1,1,1,1,1,1,1,1,1,1,1,1,1,1
1,1,1,1,1,1,1,1,1,1,1,1,1,1,1,1,1,1,1,1,1
1,1,1,1,1,1,1,1,1,1,1,1,1,1,1,1,1,1,1,1,1
1,1,30,28,5,3,30,28,26,1,1,1,1,10,10,1,1,1,1,1,1
1,1,1,13,1,1,25,15,1,1,1,1,1,32,27,32,26,1,1,1,1
1,1,1,22,1,17,1,21,5,25,25,2,1,27,44,27,26,1,1,1,1
1,1,1,18,1,1,1,1,1,13,1,1,1,32,27,32,26,1,1,1,1
1,1,1,28,1,8,2,28,1,1,1,1,1,1,1,1,1,1,1,1,1
1,1,1,1,1,1,1,1,1,1,1,1,1,1,1,1,1,1,1,1,1
1,1,1,1,1,1,1,1,1,1,1,1,1,1,1,1,1,1,1,1,1
1,1,1,1,1,1,1,1,1,1,1,1,1,1,1,1,1,1,1,1,1
endlayer

layer
1,1,1,1,1,1,1,1,1,1,1,1,1,1,1,1,1,1,1,1,1
1,1,1,1,1,1,1,1,1,1,1,1,1,1,1,1,1,1,1,1,1
1,1,1,1,1,1,10,1,1,1,1,1,1,1,1,1,1,1,1,1,1
1,1,1,28,3,1,30,28,1,1,1,1,1,10,10,10,1,1,1,1,1
1,1,1,13,1,1,25,21,26,1,1,1,1,27,45,27,26,1,1,1,1
1,1,1,1,1,17,1,1,25,26,1,25,1,45,46,45,26,1,1,1,1
1,1,1,22,1,1,1,1,1,1,1,13,13,27,45,27,26,1,1,1,1
1,1,1,28,1,1,8,28,1,1,1,1,1,1,1,1,1,1,1,1,1
1,1,1,1,1,1,1,1,1,1,1,1,1,1,1,1,1,1,1,1,1
1,1,1,1,1,1,1,1,1,1,1,1,1,1,1,1,1,1,1,1,1
1,1,1,1,1,1,1,1,1,1,1,1,1,1,1,1,1,1,1,1,1
endlayer

layer
1,1,1,1,1,1,1,1,1,1,1,1,1,1,1,1,1,1,1,1,1
1,1,1,1,1,1,1,1,1,1,1,1,1,1,1,1,1,1,1,1,1
1,1,1,33,1,10,10,33,1,1,1,1,1,1,1,1,1,1,1,1,1
1,1,36,9,28,28,28,9,35,1,1,1,1,1,10,10,1,1,1,1,1
1,1,1,28,24,24,25,28,26,1,1,10,1,32,47,32,26,1,1,1,1
1,1,30,28,24,17,24,28,25,26,1,25,1,48,44,48,26,1,1,1,1
1,1,30,28,24,24,24,28,26,1,1,13,13,32,48,32,26,1,1,1,1
1,1,36,9,28,28,28,9,35,1,1,1,1,1,1,1,1,1,1,1,1
1,1,1,37,1,13,1,37,1,1,1,1,1,1,1,1,1,1,1,1,1
1,1,1,1,1,1,1,1,1,1,1,1,1,1,1,1,1,1,1,1,1
1,1,1,1,1,1,1,1,1,1,1,1,1,1,1,1,1,1,1,1,1
endlayer

layer
1,1,1,1,1,1,1,1,1,1,1,1,1,1,1,1,1,1,1,1,1
1,1,1,1,1,1,1,1,1,1,1,1,1,1,1,1,1,1,1,1,1
1,1,1,1,1,1,1,1,1,1,1,1,1,1,1,1,1,1,1,1,1
1,1,1,28,26,1,5,28,1,1,1,1,1,1,10,1,1,1,1,1,1
1,1,1,18,1,1,22,1,1,1,1,1,1,24,38,24,1,1,1,1,1
1,1,1,1,1,17,16,20,3,1,1,8,14,38,49,38,26,1,1,1,1
1,1,1,1,1,1,1,15,1,1,1,1,13,24,38,24,1,1,1,1,1
1,1,30,28,2,1,30,28,1,1,1,1,1,1,1,1,1,1,1,1,1
1,1,1,13,1,1,1,1,1,1,1,1,1,1,1,1,1,1,1,1,1
1,1,1,1,1,1,1,1,1,1,1,1,1,1,1,1,1,1,1,1,1
1,1,1,1,1,1,1,1,1,1,1,1,1,1,1,1,1,1,1,1,1
endlayer

layer
1,1,1,1,1,1,1,1,1,1,1,1,1,1,1,1,1,1,1,1,1
1,1,1,1,1,1,1,1,1,1,1,1,1,1,1,1,1,1,1,1,1
1,1,1,1,1,1,1,1,1,1,1,1,1,1,1,1,1,1,1,1,1
1,1,1,28,26,5,3,28,1,1,1,1,1,1,10,1,1,1,1,1,1
1,1,1,22,1,1,1,1,1,1,1,1,1,1,27,26,1,1,1,1,1
1,1,1,18,1,17,1,15,1,1,1,1,1,27,50,27,26,1,1,1,1
1,1,1,1,1,1,1,21,1,1,1,1,1,1,27,1,1,1,1,1,1
1,1,30,28,8,2,30,28,26,1,1,1,1,1,1,1,1,1,1,1,1
1,1,1,13,1,1,1,1,1,1,1,1,1,1,1,1,1,1,1,1,1
1,1,1,1,1,1,1,1,1,1,1,1,1,1,1,1,1,1,1,1,1
1,1,1,1,1,1,1,1,1,1,1,1,1,1,1,1,1,1,1,1,1
endlayer

layer
1,1,1,1,1,1,1,1,1,1,1,1,1,1,1,1,1,1,1,1,1
1,1,1,1,1,1,1,1,1,1,1,1,1,1,1,1,1,1,1,1,1
1,1,1,10,1,1,1,10,1,1,1,1,1,1,1,1,1,1,1,1,1
1,1,30,28,5,3,1,28,1,1,1,1,1,1,1,1,1,1,1,1,1
1,1,1,1,1,1,1,15,26,1,1,1,1,51,27,51,1,1,1,1,1
1,1,1,22,1,17,1,21,1,1,1,1,1,27,51,27,26,1,1,1,1
1,1,1,18,1,1,1,1,1,1,1,1,1,51,27,51,1,1,1,1,1
1,1,30,28,1,8,2,28,26,1,1,1,1,1,1,1,1,1,1,1,1
1,1,1,1,1,1,1,1,1,1,1,1,1,1,1,1,1,1,1,1,1
1,1,1,1,1,1,1,1,1,1,1,1,1,1,1,1,1,1,1,1,1
1,1,1,1,1,1,1,1,1,1,1,1,1,1,1,1,1,1,1,1,1
endlayer

layer
1,1,1,1,1,1,1,1,1,1,1,1,1,1,1,1,1,1,1,1,1
1,1,1,1,1,1,1,1,1,1,1,1,1,1,1,1,1,1,1,1,1
1,1,1,1,10,1,1,1,1,1,1,1,1,1,1,1,1,1,1,1,1
1,1,1,28,3,1,1,28,1,1,1,1,1,1,1,1,1,1,1,1,1
1,1,1,1,1,1,1,21,26,1,1,1,1,51,52,51,26,1,1,1,1
1,1,1,1,1,17,1,1,1,1,1,1,1,55,54,53,0,1,1,1,1
1,1,1,22,1,1,1,1,26,1,1,1,1,51,56,51,1,1,1,1,1
1,1,1,28,1,1,8,28,1,1,1,1,1,1,1,1,1,1,1,1,1
1,1,1,1,1,1,13,1,1,1,1,1,1,1,1,1,1,1,1,1,1
1,1,1,1,1,1,1,1,1,1,1,1,1,1,1,1,1,1,1,1,1
1,1,1,1,1,1,1,1,1,1,1,1,1,1,1,1,1,1,1,1,1
endlayer

layer
1,1,1,1,1,1,1,1,1,1,1,1,1,1,1,1,1,1,1,1,1
1,1,1,1,1,1,1,1,1,1,1,1,1,1,1,1,1,1,1,1,1
1,1,1,33,10,1,1,33,1,1,1,1,1,1,1,1,1,1,1,1,1
1,1,36,9,28,28,28,9,35,1,1,1,1,1,10,1,1,1,1,1,1
1,1,30,28,24,24,24,28,26,1,1,1,1,27,40,27,26,1,1,1,1
1,1,1,28,24,17,24,28,6,6,6,6,1,42,1,41,1,1,1,1,1
1,1,1,28,24,24,24,28,26,1,1,1,1,27,43,27,1,1,1,1,1
1,1,36,9,28,28,28,9,35,1,1,1,1,13,1,1,1,1,1,1,1
1,1,1,37,1,1,13,37,1,1,1,1,1,1,1,1,1,1,1,1,1
1,1,1,1,1,1,1,1,1,1,1,1,1,1,1,1,1,1,1,1,1
1,1,1,1,1,1,1,1,1,1,1,1,1,1,1,1,1,1,1,1,1
endlayer

layer
1,1,1,1,1,1,1,1,1,1,1,1,1,1,1,1,1,1,1,1,1
1,1,1,1,1,1,1,1,1,1,1,1,1,1,1,1,1,1,1,1,1
1,1,1,1,1,1,1,1,1,1,1,1,1,1,1,1,1,1,1,1,1
1,1,1,28,57,1,5,28,17,17,17,17,1,1,10,10,1,1,1,1,1
1,1,1,18,1,1,1,14,28,28,28,14,30,38,58,38,1,1,1,1,1
1,1,1,1,1,17,1,1,1,24,24,24,1,59,1,59,26,1,1,1,1
1,1,1,1,1,1,1,14,28,28,28,14,26,38,58,38,26,1,1,1,1
1,1,1,28,2,1,1,28,17,17,17,17,1,13,1,1,1,1,1,1,1
1,1,1,1,1,1,1,1,1,1,1,1,1,1,1,1,1,1,1,1,1
1,1,1,1,1,1,1,1,1,1,1,1,1,1,1,1,1,1,1,1,1
1,1,1,1,1,1,1,1,1,1,1,1,1,1,1,1,1,1,1,1,1
endlayer

layer
1,1,1,1,1,1,1,1,1,1,1,1,1,1,1,1,1,1,1,1,1
1,1,1,1,1,1,1,1,1,1,1,1,1,1,1,1,1,1,1,1,1
1,1,1,1,1,1,1,1,1,1,1,1,1,1,1,1,1,1,1,1,1
1,1,30,28,26,5,3,28,1,1,1,1,1,1,1,10,1,1,1,1,1
1,1,1,22,1,1,1,11,1,11,1,11,30,27,52,27,1,1,1,1,1
1,1,1,18,1,17,1,1,1,1,1,1,30,55,1,53,1,1,1,1,1
1,1,1,1,1,1,1,11,1,11,1,11,1,27,56,27,26,1,1,1,1
1,1,1,28,8,2,1,28,1,1,1,1,1,13,1,1,1,1,1,1,1
1,1,1,1,1,1,1,1,1,1,1,1,1,1,1,1,1,1,1,1,1
1,1,1,1,1,1,1,1,1,1,1,1,1,1,1,1,1,1,1,1,1
1,1,1,1,1,1,1,1,1,1,1,1,1,1,1,1,1,1,1,1,1
endlayer

layer
1,1,1,1,1,1,1,1,1,1,1,1,1,1,1,1,1,1,1,1,1
1,1,1,1,1,1,1,1,1,1,1,1,1,1,1,1,1,1,1,1,1
1,1,1,10,1,1,1,1,1,1,1,1,1,1,1,1,1,1,1,1,1
1,1,30,28,5,3,1,28,1,1,1,1,1,1,1,1,1,1,1,1,1
1,1,1,1,1,1,1,11,1,11,1,11,1,54,27,54,1,1,1,1,1
1,1,1,22,1,17,1,1,1,1,1,1,30,27,1,27,26,1,1,1,1
1,1,1,18,1,1,1,11,1,11,1,11,1,54,27,54,1,1,1,1,1
1,1,1,28,1,8,2,28,1,1,1,1,1,1,13,1,1,1,1,1,1
1,1,1,13,1,1,1,1,1,1,1,1,1,1,1,1,1,1,1,1,1
1,1,1,1,1,1,1,1,1,1,1,1,1,1,1,1,1,1,1,1,1
1,1,1,1,1,1,1,1,1,1,1,1,1,1,1,1,1,1,1,1,1
endlayer

layer
1,1,1,1,1,1,1,1,1,1,1,1,1,1,1,1,1,1,1,1,1
1,1,1,1,1,1,1,1,1,1,1,1,1,1,1,1,1,1,1,1,1
1,1,1,1,1,1,10,1,1,1,1,1,1,1,1,1,1,1,1,1,1
1,1,1,28,3,1,30,28,17,17,17,17,1,1,1,1,1,1,1,1,1
1,1,1,1,1,1,1,14,28,28,28,14,26,1,40,1,1,1,1,1,1
1,1,1,1,1,17,1,6,6,6,6,6,1,42,27,41,1,1,1,1,1
1,1,1,22,1,1,1,14,28,28,28,14,1,1,43,1,1,1,1,1,1
1,1,1,28,1,1,8,28,17,17,17,17,1,1,1,1,1,1,1,1,1
1,1,1,1,1,1,1,1,1,1,1,1,1,1,1,1,1,1,1,1,1
1,1,1,1,1,1,1,1,1,1,1,1,1,1,1,1,1,1,1,1,1
1,1,1,1,1,1,1,1,1,1,1,1,1,1,1,1,1,1,1,1,1
endlayer

layer
1,1,1,1,1,1,1,1,1,1,1,1,1,1,1,1,1,1,1,1,1
1,1,1,1,1,1,1,1,1,1,1,1,1,1,1,1,1,1,1,1,1
1,1,1,33,10,10,10,33,1,1,1,1,1,1,1,1,1,1,1,1,1
1,1,36,9,28,28,28,9,35,1,1,1,1,1,1,1,1,1,1,1,1
1,1,30,28,24,24,24,28,1,1,1,1,1,1,1,1,1,1,1,1,1
1,1,30,28,24,17,24,28,24,24,24,24,1,1,27,1,1,1,1,1,1
1,1,1,28,24,24,24,28,1,1,1,1,1,1,1,1,1,1,1,1,1
1,1,36,9,28,28,28,9,35,1,1,1,1,1,1,1,1,1,1,1,1
1,1,1,37,1,1,1,37,1,1,1,1,1,1,1,1,1,1,1,1,1
1,1,1,1,1,1,1,1,1,1,1,1,1,1,1,1,1,1,1,1,1
1,1,1,1,1,1,1,1,1,1,1,1,1,1,1,1,1,1,1,1,1
endlayer

layer
1,1,1,1,1,1,1,1,1,1,1,1,1,1,1,1,1,1,1,1,1
1,1,1,1,1,1,1,1,1,1,1,1,1,1,1,1,1,1,1,1,1
1,1,1,1,1,1,10,1,1,1,1,1,1,1,1,1,1,1,1,1,1
1,1,1,28,17,17,17,28,1,1,1,1,1,1,1,1,1,1,1,1,1
1,1,30,17,1,1,1,17,1,1,1,1,1,1,1,1,1,1,1,1,1
1,1,1,17,1,17,1,17,1,1,1,1,1,1,11,1,1,1,1,1,1
1,1,30,17,1,1,1,17,1,1,1,1,1,1,1,1,1,1,1,1,1
1,1,1,28,17,17,17,28,1,1,1,1,1,1,1,1,1,1,1,1,1
1,1,1,1,13,1,1,1,1,1,1,1,1,1,1,1,1,1,1,1,1
1,1,1,1,1,1,1,1,1,1,1,1,1,1,1,1,1,1,1,1,1
1,1,1,1,1,1,1,1,1,1,1,1,1,1,1,1,1,1,1,1,1
endlayer

layer
1,1,1,1,1,1,1,1,1,1,1,1,1,1,1,1,1,1,1,1,1
1,1,1,1,1,1,1,1,1,1,1,1,1,1,1,1,1,1,1,1,1
1,1,1,33,1,1,10,33,1,1,1,1,1,1,1,1,1,1,1,1,1
1,1,36,9,9,9,9,9,35,1,1,1,1,1,1,1,1,1,1,1,1
1,1,30,9,1,1,1,9,1,1,1,1,1,1,1,1,1,1,1,1,1
1,1,1,9,1,17,1,9,1,1,1,1,1,1,17,1,1,1,1,1,1
1,1,30,9,1,1,1,9,1,1,1,1,1,1,1,1,1,1,1,1,1
1,1,36,9,9,9,9,9,35,1,1,1,1,1,1,1,1,1,1,1,1
1,1,1,37,13,13,1,37,1,1,1,1,1,1,1,1,1,1,1,1,1
1,1,1,1,1,1,1,1,1,1,1,1,1,1,1,1,1,1,1,1,1
1,1,1,1,1,1,1,1,1,1,1,1,1,1,1,1,1,1,1,1,1
endlayer

layer
1,1,1,1,1,1,1,1,1,1,1,1,1,1,1,1,1,1,1,1,1
1,1,1,1,1,1,1,1,1,1,1,1,1,1,1,1,1,1,1,1,1
1,1,1,1,1,1,1,1,1,1,1,1,1,1,1,1,1,1,1,1,1
1,1,1,12,24,24,24,12,1,1,1,1,1,1,1,1,1,1,1,1,1
1,1,1,24,1,18,1,24,1,1,1,1,1,1,1,1,1,1,1,1,1
1,1,1,24,2,17,5,24,1,1,1,1,1,1,17,1,1,1,26,1,1
1,1,1,24,1,15,1,24,1,1,1,1,1,1,1,1,1,1,1,1,1
1,1,1,12,24,24,24,12,1,1,1,1,1,1,1,1,1,1,1,1,1
1,1,1,1,1,1,1,1,1,1,1,1,1,1,1,1,1,1,1,1,1
1,1,1,1,1,1,1,1,1,1,1,1,1,1,1,1,1,1,1,1,1
1,1,1,1,1,1,1,1,1,1,1,1,1,1,1,1,1,1,1,1,1
endlayer

layer
1,1,1,1,1,1,1,1,1,1,1,1,1,1,1,1,1,1,1,1,1
1,1,1,1,1,1,1,1,1,1,1,1,1,1,1,1,1,1,1,1,1
1,1,1,1,1,1,1,1,1,1,1,1,1,1,1,1,1,1,1,1,1
1,10,1,1,10,1,10,1,1,1,1,1,1,1,1,1,1,1,1,1,1
1,6,1,1,24,16,24,1,1,1,1,1,1,1,1,1,1,1,1,1,1
1,6,1,1,16,16,16,26,1,1,1,1,1,6,11,6,1,1,26,1,1
1,6,1,1,24,16,24,1,1,1,1,1,1,1,1,1,1,1,1,1,1
13,13,1,1,1,13,13,1,1,1,1,1,1,1,1,1,1,1,1,1,1
1,1,1,1,1,1,1,1,1,1,1,1,1,1,1,1,1,1,1,1,1
1,1,1,1,1,1,1,1,1,1,1,1,1,1,1,1,1,1,1,1,1
1,1,1,1,1,1,1,1,1,1,1,1,1,1,1,1,1,1,1,1,1
endlayer

layer
1,1,1,1,1,1,1,1,1,1,1,1,1,1,1,1,1,1,1,1,1
1,1,1,1,1,1,1,1,1,1,1,1,1,1,1,1,1,1,1,1,1
1,1,1,1,1,1,1,1,1,1,1,1,1,1,1,1,1,1,1,1,1
10,10,1,1,10,1,10,1,1,1,1,1,1,1,1,1,1,1,1,1,1
9,9,7,7,16,15,16,7,7,7,7,7,7,7,7,7,7,7,1,1,1
9,9,1,1,5,1,2,12,17,17,17,17,17,9,44,9,30,14,26,1,1
9,9,7,7,16,18,16,7,7,7,7,7,7,7,7,7,7,7,1,1,1
13,13,1,1,13,1,13,1,1,1,1,1,1,1,1,1,1,1,1,1,1
1,1,1,1,1,1,1,1,1,1,1,1,1,1,1,1,1,1,1,1,1
1,1,1,1,1,1,1,1,1,1,1,1,1,1,1,1,1,1,1,1,1
1,1,1,1,1,1,1,1,1,1,1,1,1,1,1,1,1,1,1,1,1
endlayer

layer
1,1,1,1,1,1,1,1,1,1,1,1,1,1,1,1,1,1,1,1,1
1,1,1,1,1,1,1,1,1,1,1,1,1,1,1,1,1,1,1,1,1
1,1,1,1,1,1,1,1,1,1,1,1,1,1,1,1,1,1,1,1,1
10,10,1,1,1,1,1,1,1,1,1,1,1,1,1,1,1,1,1,1,1
9,9,11,62,11,62,11,62,11,62,11,62,11,62,11,62,61,60,1,1,1
9,9,24,24,16,1,1,1,1,1,1,1,1,1,1,1,1,1,1,1,1
9,9,11,1,11,63,11,63,11,63,11,63,11,63,11,63,61,60,1,1,1
1,13,1,1,1,1,1,1,1,1,1,1,1,1,1,1,1,1,1,1,1
1,1,1,1,1,1,1,1,1,1,1,1,1,1,1,1,1,1,1,1,1
1,1,1,1,1,1,1,1,1,1,1,1,1,1,1,1,1,1,1,1,1
1,1,1,1,1,1,1,1,1,1,1,1,1,1,1,1,1,1,1,1,1
endlayer

layer
1,1,1,1,1,1,1,1,1,1,1,1,1,1,1,1,1,1,1,1,1
1,1,1,1,1,1,1,1,1,1,1,1,1,1,1,1,1,1,1,1,1
1,1,1,1,1,1,1,1,1,1,1,1,1,1,1,1,1,1,1,1,1
1,1,1,1,1,1,1,1,1,1,1,1,1,1,1,1,1,1,1,1,1
24,9,4,8,11,1,11,1,11,1,11,1,11,1,11,61,60,1,1,1,1
24,9,1,1,16,1,1,1,1,1,1,1,1,1,1,1,1,1,1,1,1
24,9,4,8,11,1,11,1,11,1,11,1,11,1,11,61,60,1,1,1,1
1,13,1,1,1,1,1,1,1,1,1,1,1,1,1,1,1,1,1,1,1
1,1,1,1,1,1,1,1,1,1,1,1,1,1,1,1,1,1,1,1,1
1,1,1,1,1,1,1,1,1,1,1,1,1,1,1,1,1,1,1,1,1
1,1,1,1,1,1,1,1,1,1,1,1,1,1,1,1,1,1,1,1,1
endlayer

layer
1,1,1,1,1,1,1,1,1,1,1,1,1,1,1,1,1,1,1,1,1
1,1,1,1,1,1,1,1,1,1,1,1,1,1,1,1,1,1,1,1,1
1,1,1,1,1,1,1,1,1,1,1,1,1,1,1,1,1,1,1,1,1
1,1,1,1,1,1,1,1,1,1,1,1,1,1,1,1,1,1,1,1,1
1,1,1,1,64,64,64,64,64,64,64,64,64,64,64,64,1,1,1,1,1
1,1,1,1,24,1,24,1,24,1,24,1,24,1,24,1,1,1,1,1,1
1,1,1,1,64,64,64,64,64,64,64,64,64,64,64,64,1,1,1,1,1
1,1,1,1,1,1,1,1,1,1,1,1,1,1,1,1,1,1,1,1,1
1,1,1,1,1,1,1,1,1,1,1,1,1,1,1,1,1,1,1,1,1
1,1,1,1,1,1,1,1,1,1,1,1,1,1,1,1,1,1,1,1,1
1,1,1,1,1,1,1,1,1,1,1,1,1,1,1,1,1,1,1,1,1
endlayer

