weight=4
dimensionsToSpawnIn=overworld
embed_into_distance=1
random_height_offset=0,0
unacceptable_target_blocks=sand,flowing_water,water,flowing_lava,lava,ice,packed_ice,stained_hardened_clay-9,brick_block,double_stone_slab,stonebrick,red_sandstone,red_nether_brick,red_mushroom_block,brown_mushroom_block,planks,cobblestone,end_stone,obsidian,purpur_block,iron_bars,purpur_slab,purpur_pillar,netherrack,soul_sand,quartz_ore,stained_glass,glass
dimensions=18,13,15
allowable_overhang=0
max_leveling=1
leveling_buffer=-1
preventRotation=0
preserve_water=0
preserve_lava=0
preserve_plants=0
uniqueMinDistance=0
spawnMinDistance=0
spawnMaxDistance=0

rule1=0,100,preserveBlock
rule2=0,100,minecraft:double_stone_slab-0
rule3=0,100,minecraft:stonebrick-0
rule4=0,95,minecraft:stone_slab-8
rule5=0,100,minecraft:stone_brick_stairs-0
rule6=0,100,minecraft:stone_brick_stairs-5
rule7=0,100,minecraft:cobblestone_wall-0,minecraft:cobblestone_wall-1
rule8=0,100,minecraft:vine-4
rule9=0,100,minecraft:vine-8
rule10=0,100,minecraft:vine-2
rule11=0,100,minecraft:vine-1
rule12=0,90,chisel:ironpane-3
rule13=0,100,minecraft:stone_brick_stairs-4
rule14=0,100,minecraft:stone_brick_stairs-1
rule15=0,100,chisel:basalt-15
rule16=0,100,minecraft:iron_door-2
rule17=0,100,ChestGenHook:chests/simple_dungeon:5-2
rule18=0,100,MobSpawner:Zombie
rule19=0,50,minecraft:ladder-3
rule20=0,100,chisel:technicalnew-3
rule21=0,100,minecraft:iron_door-0
rule22=0,100,chisel:ironpane-5
rule23=0,100,minecraft:iron_door-9
rule24=1,100,minecraft:stone_button-5
rule25=0,100,chisel:futura-1
rule26=0,100,minecraft:heavy_weighted_pressure_plate-0
rule27=0,100,minecraft:stone_slab-0
rule28=0,100,minecraft:stone_brick_stairs-2
rule29=0,100,minecraft:stone_brick_stairs-6
rule30=0,100,minecraft:stone_brick_stairs-7
rule31=0,100,minecraft:trapdoor-1
rule32=0,100,minecraft:stone_slab-8

layer
1,1,1,1,1,1,1,1,1,1,1,1,1,1,1
1,1,1,1,1,1,1,1,1,1,1,1,1,1,1
1,1,2,3,1,1,1,1,1,1,1,1,2,1,1
1,1,1,3,1,1,1,1,1,1,1,1,1,1,1
1,1,1,1,1,1,1,1,1,1,1,1,1,1,1
1,1,1,1,1,1,1,1,1,1,1,1,1,1,1
1,1,2,1,1,1,1,1,1,1,1,1,2,1,1
1,1,1,1,1,1,1,1,1,1,1,1,1,1,1
1,1,1,1,1,1,1,1,1,1,1,1,1,1,1
1,1,1,1,1,1,1,1,1,1,1,1,1,1,1
1,1,2,1,1,1,1,1,1,1,1,1,2,1,1
1,1,1,1,1,1,1,1,1,1,1,1,1,1,1
1,1,1,1,1,1,1,1,1,1,1,1,1,1,1
endlayer

layer
1,1,1,1,1,1,1,1,1,1,1,1,1,1,1
1,1,1,1,1,1,1,1,1,1,1,1,1,1,1
1,1,2,1,1,1,1,1,1,1,1,1,2,1,1
1,1,4,5,1,1,1,1,1,1,1,1,4,1,1
1,1,4,6,1,1,1,1,1,1,1,1,4,1,1
1,1,4,1,1,1,1,1,1,1,1,1,4,1,1
1,1,2,1,1,1,1,1,1,1,1,1,2,1,1
1,1,4,1,1,1,1,1,1,1,1,1,4,1,1
1,1,4,1,1,1,1,1,1,1,1,1,4,1,1
1,1,4,1,1,1,1,1,1,1,1,1,4,1,1
1,1,2,1,1,1,1,1,1,1,1,1,2,1,1
1,1,1,1,1,1,1,1,1,1,1,1,1,1,1
1,1,1,1,1,1,1,1,1,1,1,1,1,1,1
endlayer

layer
1,1,1,1,1,1,1,1,1,1,1,1,1,1,1
1,1,1,1,1,1,1,1,1,1,1,1,1,1,1
1,1,7,1,1,1,1,1,1,1,1,1,7,1,1
1,1,1,1,1,1,1,1,1,1,1,1,1,1,1
1,1,1,5,1,1,1,1,1,1,1,1,1,1,1
1,1,1,6,1,1,1,1,1,1,1,1,1,1,1
1,1,7,1,1,1,1,1,1,1,1,1,7,1,1
1,1,1,1,1,1,1,1,1,1,1,1,1,1,1
1,1,1,1,1,1,1,1,1,1,1,1,1,1,1
1,1,1,1,1,1,1,1,1,1,1,1,1,1,1
1,8,7,1,1,1,1,1,1,1,1,1,7,1,1
1,1,1,1,1,1,1,1,1,1,1,1,1,1,1
1,1,1,1,1,1,1,1,1,1,1,1,1,1,1
endlayer

layer
1,1,1,1,1,1,1,1,1,1,1,1,1,1,1
1,1,1,1,1,1,1,1,1,1,1,1,9,1,1
1,1,7,1,1,1,1,1,1,1,1,1,7,1,1
1,1,1,1,1,1,1,1,1,1,1,1,1,1,1
1,1,1,1,1,1,1,1,1,1,1,1,1,1,1
1,1,1,5,1,1,1,1,1,1,1,1,1,1,1
1,1,7,6,1,1,1,1,1,1,1,1,7,1,1
1,1,1,1,1,1,1,1,1,1,1,1,1,1,1
1,1,1,1,1,1,1,1,1,1,1,1,1,1,1
1,1,1,1,1,1,1,1,1,1,1,1,1,1,1
1,8,7,1,1,1,1,1,1,1,1,1,7,1,1
1,1,10,1,1,1,1,1,1,1,1,1,1,1,1
1,1,1,1,1,1,1,1,1,1,1,1,1,1,1
endlayer

layer
1,1,1,1,1,1,1,1,1,1,1,1,1,1,1
1,1,9,1,1,1,1,1,1,1,1,1,9,1,1
1,8,2,4,4,4,4,4,4,4,4,4,2,11,1
1,1,4,1,4,4,4,4,1,1,1,1,4,1,1
1,1,4,1,4,4,4,4,1,1,1,1,4,1,1
1,1,4,1,4,4,4,4,1,1,1,1,4,1,1
1,8,2,5,4,4,4,4,1,1,1,1,2,11,1
1,1,4,4,4,4,4,4,1,1,1,1,4,1,1
1,1,4,4,4,4,4,4,1,1,1,1,4,1,1
1,1,4,4,4,4,4,4,1,1,1,1,4,1,1
1,8,2,4,4,4,4,4,4,4,4,4,2,11,1
1,1,10,1,1,1,1,1,1,1,1,1,10,1,1
1,1,1,1,1,1,1,1,1,1,1,1,1,1,1
endlayer

layer
1,1,1,1,1,1,1,1,1,1,1,1,1,1,1
1,1,1,1,1,1,1,1,1,1,1,1,9,1,1
1,1,7,12,12,12,12,7,1,1,1,1,7,1,1
1,1,12,1,1,1,1,12,1,1,1,1,1,1,1
1,1,12,1,1,1,1,12,1,1,1,1,1,1,1
1,1,12,1,1,1,1,12,1,1,1,1,1,1,1
1,1,7,1,1,1,1,12,1,1,1,1,7,1,1
1,1,12,1,1,13,1,12,1,1,1,1,1,1,1
1,1,12,1,1,14,1,12,1,1,1,1,1,1,1
1,1,12,1,1,1,1,12,1,1,1,1,1,1,1
1,1,7,12,12,12,12,7,1,1,1,1,7,1,1
1,1,1,1,1,1,1,1,1,1,1,1,1,1,1
1,1,1,1,1,1,1,1,1,1,1,1,1,1,1
endlayer

layer
1,1,1,1,1,1,1,1,1,1,1,1,1,1,1
1,1,1,1,1,1,1,1,1,1,1,1,9,1,1
1,1,7,1,1,1,1,7,1,1,1,1,7,1,1
1,1,1,1,1,1,1,1,1,1,1,1,1,1,1
1,1,1,1,1,1,1,1,1,1,1,1,1,1,1
1,1,1,1,1,1,1,1,1,1,1,1,1,1,1
1,8,7,1,1,13,1,1,1,1,1,1,7,1,1
1,1,1,1,1,14,1,1,1,1,1,1,1,1,1
1,1,1,1,1,1,1,1,1,1,1,1,1,1,1
1,1,1,1,1,1,1,1,1,1,1,1,1,1,1
1,1,7,1,1,1,1,7,1,1,1,1,7,11,1
1,1,1,1,1,1,1,1,1,1,1,1,1,1,1
1,1,1,1,1,1,1,1,1,1,1,1,1,1,1
endlayer

layer
1,1,1,1,1,1,1,1,1,1,1,1,1,1,1
1,1,1,1,1,1,1,1,1,1,1,1,9,1,1
1,1,7,1,1,1,1,7,1,1,1,1,7,1,1
1,1,1,1,1,1,1,1,1,1,1,1,1,1,1
1,1,1,1,1,1,1,1,1,1,1,1,1,1,1
1,1,1,1,1,13,1,1,1,1,1,1,1,1,1
1,8,7,1,1,14,1,1,1,1,1,1,7,1,1
1,1,1,1,1,1,1,1,1,1,1,1,1,1,1
1,1,1,1,1,1,1,1,1,1,1,1,1,1,1
1,1,1,1,1,1,1,1,1,1,1,1,1,1,1
1,1,7,1,1,1,1,7,1,1,1,1,7,11,1
1,1,1,1,1,1,1,10,1,1,1,1,10,1,1
1,1,1,1,1,1,1,1,1,1,1,1,1,1,1
endlayer

layer
1,1,1,1,1,1,1,1,1,1,1,1,1,1,1
1,1,9,1,1,1,1,9,1,1,1,1,9,1,1
1,8,2,4,4,4,4,2,4,4,4,4,2,11,1
1,1,4,4,4,4,4,4,1,1,1,1,4,1,1
1,1,4,4,4,4,4,4,1,1,1,1,4,1,1
1,1,4,4,4,14,4,4,1,1,1,1,4,1,1
1,8,2,4,4,1,4,4,1,1,1,1,2,11,1
1,1,4,4,4,1,4,4,1,1,1,1,4,1,1
1,1,4,4,4,1,4,4,1,1,1,1,4,1,1
1,1,4,4,4,4,4,4,1,1,1,1,4,1,1
1,8,2,4,4,4,4,2,4,4,4,4,2,11,1
1,1,10,1,1,1,1,10,1,1,1,1,10,1,1
1,1,1,1,1,1,1,1,1,1,1,1,1,1,1
endlayer

layer
1,1,1,1,1,1,1,1,1,1,1,1,1,1,1
1,1,1,1,1,1,1,1,1,1,1,1,1,1,1
1,1,7,12,12,12,12,7,1,1,1,1,7,1,1
1,1,12,1,1,1,1,12,1,1,1,1,1,1,1
1,1,12,1,1,1,1,12,1,1,1,1,1,1,1
1,1,12,1,1,1,1,12,1,1,1,1,1,1,1
1,1,7,1,1,1,1,12,1,1,1,1,7,1,1
1,1,12,13,1,1,1,12,1,1,1,1,1,1,1
1,1,12,14,1,1,1,12,1,1,1,1,1,1,1
1,1,12,1,1,1,1,12,1,1,1,1,1,1,1
1,1,7,12,12,12,12,7,1,1,1,1,7,1,1
1,1,1,1,1,1,1,1,1,1,1,1,1,1,1
1,1,1,1,1,1,1,1,1,1,1,1,1,1,1
endlayer

layer
1,1,1,1,1,1,1,1,1,1,1,1,1,1,1
1,1,1,1,1,1,1,1,1,1,1,1,1,1,1
1,1,7,1,1,1,1,7,1,1,1,1,7,1,1
1,1,1,1,1,1,1,1,1,1,1,1,1,1,1
1,1,1,1,1,1,1,1,1,1,1,1,1,1,1
1,1,1,1,1,1,1,1,1,1,1,1,1,1,1
1,1,7,13,1,1,1,1,1,1,1,1,7,1,1
1,1,1,14,1,1,1,1,1,1,1,1,1,1,1
1,1,1,1,1,1,1,1,1,1,1,1,1,1,1
1,1,1,1,1,1,1,1,1,1,1,1,1,1,1
1,1,7,1,1,1,1,7,1,1,1,1,7,1,1
1,1,1,1,1,1,1,1,1,1,1,1,1,1,1
1,1,1,1,1,1,1,1,1,1,1,1,1,1,1
endlayer

layer
1,4,4,4,4,4,4,4,4,4,4,4,4,4,1
4,4,4,4,4,4,4,4,4,4,4,4,4,4,4
4,4,2,4,4,4,4,2,4,4,4,4,2,4,4
4,4,4,4,4,4,4,4,4,4,4,4,4,4,4
4,4,4,4,4,4,4,4,4,4,4,4,4,4,4
4,4,4,4,4,4,4,4,4,4,4,4,4,4,4
4,4,2,14,4,4,4,4,4,4,4,4,2,4,4
4,4,4,1,4,4,4,4,4,4,4,4,4,4,4
4,4,4,1,4,4,4,4,4,4,4,4,4,4,4
4,4,4,1,4,4,4,4,4,4,4,4,4,4,4
4,4,2,4,4,4,4,2,4,4,4,4,2,4,4
4,4,4,4,4,4,4,4,4,4,4,4,4,4,4
1,4,4,4,4,4,4,4,4,4,4,4,4,4,1
endlayer

layer
12,12,12,12,12,12,12,12,12,12,12,12,12,12,12
12,1,1,1,1,9,1,1,1,1,1,9,1,1,12
12,1,15,15,15,15,15,16,15,15,15,15,15,1,12
12,1,15,1,1,1,1,1,1,1,1,1,15,11,12
12,1,15,1,1,1,1,1,1,1,1,1,15,1,12
12,1,15,1,1,1,13,13,13,1,1,1,15,1,12
12,1,15,1,12,1,19,15,18,17,1,1,15,1,12
12,1,15,1,12,1,6,6,6,1,1,1,15,1,12
12,1,15,1,12,1,1,1,1,1,1,1,15,11,12
12,8,15,1,12,1,1,1,1,1,1,20,15,11,12
12,8,15,15,15,15,15,21,15,15,15,15,15,1,12
12,1,10,1,1,10,1,1,1,1,1,10,1,1,12
12,12,12,12,12,12,12,12,12,12,12,12,12,12,12
endlayer

layer
1,1,1,1,1,1,1,1,1,1,1,1,1,1,1
1,1,1,1,1,1,1,1,1,1,1,9,1,1,1
1,1,15,15,22,22,15,23,15,22,22,15,15,11,1
1,1,15,1,1,1,1,1,1,1,1,1,15,1,1
1,1,22,1,1,1,1,1,1,1,1,1,22,1,1
1,1,22,1,1,1,1,1,24,1,1,1,22,1,1
1,1,15,1,1,1,19,15,25,1,1,1,15,11,1
1,1,22,1,1,1,1,1,26,1,1,1,22,1,1
1,1,22,1,1,1,1,1,1,1,1,1,22,1,1
1,8,15,1,1,1,1,1,1,1,1,1,15,1,1
1,8,15,15,22,22,15,23,15,22,22,15,15,1,1
1,1,10,1,1,1,1,10,1,1,1,10,10,1,1
1,1,1,1,1,1,1,1,1,1,1,1,1,1,1
endlayer

layer
1,1,1,1,1,1,1,1,1,1,1,1,1,1,1
1,1,1,1,1,1,1,9,9,1,1,9,1,1,1
1,1,15,15,27,27,15,15,15,27,27,15,15,11,1
1,1,15,1,1,1,1,1,1,1,1,1,15,11,1
1,1,27,1,1,1,1,1,1,1,1,1,27,1,1
1,1,27,1,1,1,1,1,1,1,1,1,27,1,1
1,1,15,1,1,1,19,15,28,1,1,1,15,1,1
1,1,27,1,1,1,1,1,1,1,1,1,27,1,1
1,1,27,1,1,1,1,1,1,1,1,1,27,1,1
1,8,15,1,1,1,1,1,1,1,1,1,15,11,1
1,8,15,15,27,27,15,15,15,27,27,15,15,11,1
1,1,1,1,1,1,1,10,10,1,1,1,10,1,1
1,1,1,1,1,1,1,1,1,1,1,1,1,1,1
endlayer

layer
1,1,1,1,1,1,1,1,1,1,1,1,1,1,1
1,1,13,13,13,13,13,13,13,13,13,13,13,1,1
1,30,15,15,15,15,15,15,15,15,15,15,15,29,1
1,30,15,32,32,32,32,32,32,32,32,32,15,29,1
1,30,15,32,32,32,32,32,32,32,32,32,15,29,1
1,30,15,32,32,32,32,32,32,32,32,32,15,29,1
1,30,15,32,32,32,19,15,32,32,32,32,15,29,1
1,30,15,32,32,32,32,32,32,32,32,32,15,29,1
1,30,15,32,32,32,32,32,32,32,32,32,15,29,1
1,30,15,32,32,32,32,32,32,32,32,32,15,29,1
1,30,15,15,15,15,15,15,15,15,15,15,15,29,1
1,1,6,6,6,6,6,6,6,6,6,6,6,1,1
1,1,1,1,1,1,1,1,1,1,1,1,1,1,1
endlayer

layer
1,1,1,1,1,1,1,1,1,1,1,1,1,1,1
1,1,12,12,12,12,12,12,12,12,12,12,12,1,1
1,12,15,15,15,15,15,15,15,15,15,15,15,12,1
1,12,15,1,1,1,1,1,1,1,1,1,15,12,1
1,12,15,1,1,1,1,1,1,1,1,1,15,12,1
1,12,15,1,1,1,1,1,1,1,1,1,15,12,1
1,12,15,1,1,1,31,27,1,1,1,1,15,12,1
1,12,15,1,1,1,1,1,1,1,1,1,15,12,1
1,12,15,1,1,1,1,1,1,1,1,1,15,12,1
1,12,15,1,1,1,1,1,1,1,1,1,15,12,1
1,12,15,15,15,15,15,15,15,15,15,15,15,12,1
1,1,12,12,12,12,12,12,12,12,12,12,12,1,1
1,1,1,1,1,1,1,1,1,1,1,1,1,1,1
endlayer

layer
1,1,1,1,1,1,1,1,1,1,1,1,1,1,1
1,1,1,1,1,1,1,1,1,1,1,1,1,1,1
1,1,27,27,27,27,27,27,27,27,27,27,27,1,1
1,1,27,1,1,1,1,1,1,1,1,1,27,1,1
1,1,27,1,1,1,1,1,1,1,1,1,27,1,1
1,1,27,1,1,1,1,1,1,1,1,1,27,1,1
1,1,27,1,1,1,1,1,1,1,1,1,27,1,1
1,1,27,1,1,1,1,1,1,1,1,1,27,1,1
1,1,27,1,1,1,1,1,1,1,1,1,27,1,1
1,1,27,1,1,1,1,1,1,1,1,1,27,1,1
1,1,27,27,27,27,27,27,27,27,27,27,27,1,1
1,1,1,1,1,1,1,1,1,1,1,1,1,1,1
1,1,1,1,1,1,1,1,1,1,1,1,1,1,1
endlayer

