weight=3
dimensionsToSpawnIn=overworld
embed_into_distance=3
random_height_offset=0,0
unacceptable_target_blocks=sand,flowing_water,water,flowing_lava,lava,ice,packed_ice,stained_hardened_clay-9,brick_block,double_stone_slab,stonebrick,red_sandstone,red_nether_brick,red_mushroom_block,brown_mushroom_block,planks,cobblestone,end_stone,obsidian,purpur_block,iron_bars,purpur_slab,purpur_pillar,netherrack,soul_sand,quartz_ore,stained_glass,glass
dimensions=13,10,12
allowable_overhang=0
max_leveling=1
leveling_buffer=-1
preventRotation=0
preserve_water=0
preserve_lava=0
preserve_plants=0
uniqueMinDistance=2000
spawnMinDistance=0
spawnMaxDistance=0

rule1=0,100,preserveBlock
rule2=0,100,minecraft:dirt-2
rule3=0,100,minecraft:water-0
rule4=0,100,minecraft:dirt-1
rule5=0,100,minecraft:stone-6
rule6=0,100,minecraft:tallgrass-1,brown_mushroom-0,red_mushroom-0,air,air
rule7=0,100,minecraft:cobblestone_wall-0,minecraft:cobblestone_wall-1
rule8=0,100,minecraft:vine-1
rule9=0,100,minecraft:vine-2
rule10=0,100,minecraft:vine-4
rule11=0,100,minecraft:vine-8
rule12=0,80,minecraft:iron_bars-0
rule13=0,100,minecraft:stonebrick-0
rule14=0,100,chisel:technical-15
rule15=0,100,chisel:ironpane-3
rule16=0,100,minecraft:ladder-3
rule17=0,100,minecraft:stone_brick_stairs-4
rule18=0,100,minecraft:stone_slab-13
rule19=0,100,minecraft:stone_brick_stairs-6
rule20=0,100,minecraft:stone_brick_stairs-7
rule21=0,100,minecraft:stone_brick_stairs-5
rule22=0,100,minecraft:stone_slab-5
rule23=0,100,air

layer
1,1,1,1,1,1,1,1,1,1,1,1
1,1,1,1,2,2,2,2,2,2,1,1
1,1,1,2,2,2,2,2,2,2,2,1
1,1,1,2,2,3,3,3,2,2,2,1
1,1,1,2,3,3,3,3,3,2,2,1
1,1,1,2,3,3,4,3,3,2,2,1
1,1,1,2,2,3,2,3,3,2,2,1
1,1,1,2,2,2,2,3,2,2,2,1
1,1,1,1,2,2,2,2,2,2,1,1
1,1,1,1,1,1,1,1,1,1,1,1
endlayer

layer
1,1,1,1,5,5,5,5,5,5,1,1
1,1,1,5,6,6,6,6,6,2,5,1
1,1,5,6,7,6,6,6,6,6,2,5
1,1,5,6,6,23,23,23,6,6,6,5
1,1,5,6,23,23,23,23,23,6,6,5
1,1,5,6,23,23,5,8,23,6,6,5
1,1,5,6,6,23,6,23,23,7,6,5
1,1,5,6,6,6,6,23,6,6,6,5
1,1,1,5,7,6,6,6,6,6,5,1
1,1,1,1,5,5,5,5,5,5,1,1
endlayer

layer
1,1,1,1,5,5,5,5,5,5,1,1
1,1,1,5,23,23,23,9,23,6,5,1
1,1,5,23,7,7,23,23,23,23,6,5
1,1,5,23,23,7,23,23,23,23,23,5
1,1,5,23,23,23,23,23,23,23,10,5
1,1,5,8,23,23,5,8,23,23,23,5
1,1,5,23,23,23,7,7,7,7,7,5
1,1,5,23,23,23,23,23,23,23,7,5
1,1,1,5,7,23,23,11,23,23,5,1
1,1,1,1,5,5,5,5,5,5,1,1
endlayer

layer
1,1,1,1,5,5,5,5,5,5,12,1
1,1,1,5,23,9,23,9,23,23,5,12
1,1,5,23,23,23,23,23,23,23,23,5
13,13,5,23,23,7,23,23,23,23,23,5
1,1,5,23,23,23,23,23,23,23,10,5
1,1,5,8,23,23,5,8,23,23,23,5
13,13,5,23,23,23,11,23,23,23,23,5
1,1,5,7,7,23,23,23,23,7,7,5
1,1,1,5,7,23,23,11,23,7,5,1
1,1,1,1,5,5,5,5,5,5,1,1
endlayer

layer
1,1,1,1,5,5,5,5,5,5,12,1
1,1,1,5,23,23,7,9,23,23,5,12
13,13,5,23,23,23,7,23,23,23,23,5
15,1,14,7,7,7,7,23,23,23,10,5
13,13,5,23,7,23,7,23,23,23,10,5
13,13,5,23,23,23,5,23,23,23,23,5
15,1,14,7,23,23,11,23,23,23,23,5
13,13,5,7,23,23,23,23,23,23,23,5
1,1,1,5,23,23,11,11,23,7,5,1
1,1,1,1,5,5,5,5,5,5,1,1
endlayer

layer
1,1,1,1,5,5,5,5,5,1,1,1
1,1,1,5,23,23,23,23,23,23,1,1
1,1,5,23,23,23,23,23,23,23,23,5
13,13,5,23,23,23,23,23,23,8,10,5
1,1,5,23,7,23,7,7,23,23,10,5
1,12,23,7,7,23,5,7,23,23,23,5
13,13,5,7,23,23,11,7,7,23,23,5
1,1,5,23,23,23,23,23,7,7,23,5
1,1,1,5,23,23,11,11,23,7,5,1
1,1,1,1,5,5,5,5,5,5,1,1
endlayer

layer
1,1,1,1,1,1,12,12,1,1,1,1
1,1,1,1,5,5,5,5,1,1,1,1
1,1,10,5,5,5,5,5,5,1,1,1
1,1,10,5,5,5,5,5,5,8,5,1
1,1,12,5,5,5,12,12,5,5,5,1
1,1,12,5,5,5,5,12,5,5,5,1
1,1,1,5,5,5,11,5,5,5,5,1
1,1,1,5,5,5,5,5,5,5,5,1
1,1,1,1,5,5,5,5,5,5,1,1
1,1,1,1,1,1,12,12,1,1,1,1
endlayer

layer
1,1,1,1,1,1,1,1,1,1,1,1
1,1,1,1,1,7,1,7,1,1,1,1
1,1,1,1,1,11,1,1,11,1,1,1
1,1,1,7,10,5,1,1,5,8,7,1
1,1,1,1,1,1,1,16,5,1,1,1
1,1,1,1,1,1,1,1,1,1,1,1
1,1,1,7,1,5,1,1,5,1,7,1
1,1,1,1,1,1,1,1,1,1,1,1
1,1,1,1,1,7,1,1,7,1,1,1
1,1,1,1,1,1,1,1,1,1,1,1
endlayer

layer
1,1,1,1,1,1,1,1,1,1,1,1
1,1,1,1,1,7,1,7,1,1,1,1
1,1,1,1,1,11,1,1,11,1,1,1
1,1,1,7,10,5,1,10,5,8,1,1
1,1,1,1,1,1,1,16,5,1,1,1
1,1,1,1,1,1,1,1,1,1,1,1
1,1,1,7,1,5,1,1,5,1,7,1
1,1,1,1,1,1,1,1,1,1,1,1
1,1,1,1,1,7,1,1,7,1,1,1
1,1,1,1,1,1,1,1,1,1,1,1
endlayer

layer
1,1,1,1,1,1,1,1,1,1,1,1
1,1,1,1,1,7,1,7,1,1,1,1
1,1,1,1,1,17,18,18,17,1,1,1
1,1,1,7,20,5,5,5,5,19,1,1
1,1,1,1,18,5,12,16,5,18,1,1
1,1,1,1,18,5,12,12,5,18,1,1
1,1,1,7,20,5,5,5,5,19,7,1
1,1,1,1,1,21,18,18,21,1,1,1
1,1,1,1,1,7,1,1,7,1,1,1
1,1,1,1,1,1,1,1,1,1,1,1
endlayer

layer
1,1,1,1,1,1,1,1,1,1,1,1
1,1,1,1,1,1,1,12,1,1,1,1
1,1,1,1,1,7,1,1,7,1,1,1
1,1,1,12,7,1,1,1,1,7,1,1
1,1,1,1,1,1,1,1,1,1,1,1
1,1,1,1,1,1,1,1,1,1,1,1
1,1,1,12,7,1,1,22,1,7,12,1
1,1,1,1,1,7,1,1,7,1,1,1
1,1,1,1,1,12,1,1,12,1,1,1
1,1,1,1,1,1,1,1,1,1,1,1
endlayer

layer
1,1,1,1,1,1,1,1,1,1,1,1
1,1,1,1,1,1,1,1,1,1,1,1
1,1,1,1,1,7,1,1,7,1,1,1
1,1,1,1,7,1,1,1,1,7,1,1
1,1,1,1,1,1,1,1,1,1,1,1
1,1,1,1,1,1,1,1,1,18,1,1
1,1,1,1,7,1,1,1,1,7,1,1
1,1,1,1,1,7,1,18,1,1,1,1
1,1,1,1,1,1,1,1,1,1,1,1
1,1,1,1,1,1,1,1,1,1,1,1
endlayer

layer
1,1,1,1,1,1,1,1,1,1,1,1
1,1,1,1,1,1,1,1,1,1,1,1
1,1,1,1,1,1,22,22,22,1,1,1
1,1,1,1,22,13,13,13,13,22,1,1
1,1,1,1,22,13,13,13,13,22,1,1
1,1,1,1,22,13,13,13,13,1,1,1
1,1,1,1,22,13,13,22,1,1,1,1
1,1,1,1,1,22,22,1,1,1,1,1
1,1,1,1,1,1,1,1,1,1,1,1
1,1,1,1,1,1,1,1,1,1,1,1
endlayer

