weight=3
dimensionsToSpawnIn=overworld
embed_into_distance=0
acceptable_target_blocks=stone,grass,dirt,sand
unacceptable_target_blocks=flowing_water,water,flowing_lava,lava,ice,packed_ice,stained_hardened_clay-9,brick_block,double_stone_slab,stonebrick,red_sandstone,red_nether_brick,red_mushroom_block,brown_mushroom_block,planks,cobblestone,end_stone,obsidian,purpur_block,iron_bars,purpur_slab,purpur_pillar,netherrack,soul_sand,quartz_ore,stained_glass,glass
dimensions=34,11,18
allowable_overhang=0
max_leveling=1
leveling_buffer=-1
preserve_water=0
preserve_lava=0
preserve_plants=0

adjoining_template=generic/Tubes;25;100;-15
adjoining_template=templateparser/BlockHenge1;10;100;15
adjoining_template=templateparser/BlockHenge1;-11;100;2
adjoining_template=templateparser/BlockHenge1;-6;100;15
adjoining_template=templateparser/BlockHenge1;-15;100;-12
adjoining_template=templateparser/BlockHenge1;-4;100;-16
adjoining_template=templateparser/BlockHenge1;9;100;-15
adjoining_template=templateparser/BlockHenge1;15;100;-3

rule1=1,90,chisel:brownstone-1,chisel:brownstone-1,chisel:brownstone-1,chisel:brownstone-1,chisel:brownstone-1,chisel:brownstone-0,iron_bars-0,iron_bars-0,iron_bars-0,iron_bars-0
rule2=1,20,iron_block
rule3=1,20,iron_block
rule4=2,80,chisel:brownstone-1,chisel:brownstone-1,chisel:brownstone-1,chisel:brownstone-1,chisel:brownstone-1,chisel:brownstone-0,iron_bars-0,iron_bars-0,iron_bars-0,iron_bars-0
rule5=0,100,air
rule6=1,80,chisel:brownstone-1,chisel:brownstone-1,chisel:brownstone-1,chisel:brownstone-1,chisel:brownstone-1,chisel:brownstone-0,iron_bars-0,iron_bars-0,iron_bars-0,iron_bars-0
rule7=2,20,iron_block

layer
1,1,1,1,1,1,1,1,1,1,1,1,1,1,1,1,1,1
1,1,1,1,1,1,1,1,1,1,1,1,1,1,1,1,1,1
1,1,1,1,1,1,1,1,1,1,1,1,1,1,1,1,1,1
1,1,1,1,1,1,1,1,1,1,1,1,1,1,1,1,1,1
1,1,1,1,1,1,1,1,1,1,1,1,1,1,1,1,1,1
1,1,1,1,1,1,1,1,1,1,1,1,1,1,1,1,1,1
1,1,1,1,1,1,1,1,1,1,1,1,1,1,1,1,1,1
1,1,1,1,1,1,1,1,1,1,1,1,1,1,1,1,1,1
1,1,1,1,1,1,1,1,1,1,1,1,1,1,1,1,1,1
1,1,1,1,1,1,1,1,1,1,1,1,1,1,1,1,1,1
1,1,1,1,1,1,1,1,1,1,1,1,1,1,1,1,1,1
endlayer

layer
5,5,5,5,5,5,5,5,5,5,5,5,5,5,5,5,5,5
5,5,5,5,5,5,5,5,5,5,5,5,5,5,5,5,5,5
5,5,5,5,5,6,6,6,6,6,6,6,6,5,5,5,5,5
5,5,5,5,5,6,6,6,6,6,6,6,6,5,5,5,5,5
5,5,5,5,5,6,6,6,6,6,6,6,6,5,5,5,5,5
5,5,5,5,5,6,6,6,6,6,6,6,6,5,5,5,5,5
5,5,5,5,5,5,5,5,5,5,5,5,5,5,5,5,5,5
5,5,6,6,5,5,5,5,5,5,5,5,5,5,5,5,5,5
5,5,6,6,5,5,5,5,5,5,5,5,5,5,5,5,5,5
5,5,5,5,5,5,5,5,5,5,5,5,5,5,5,5,5,5
5,5,5,5,5,5,5,5,5,5,5,5,5,5,5,5,5,5
endlayer

layer
5,5,5,5,5,5,5,5,5,5,5,5,5,5,5,5,5,5
5,5,5,5,5,5,5,5,5,5,5,5,5,5,5,5,5,5
5,5,5,5,5,6,6,6,6,6,6,6,6,5,5,5,5,5
5,5,5,5,5,6,6,6,6,6,6,6,6,5,5,5,5,5
5,5,5,5,5,6,6,6,6,6,6,6,6,5,5,5,5,5
5,5,5,5,5,6,6,6,6,6,6,6,6,5,5,5,5,5
5,5,5,5,5,5,5,5,5,5,5,5,5,5,5,5,5,5
5,5,6,6,5,5,5,5,5,5,5,5,5,5,5,5,5,5
5,5,6,6,5,5,5,5,5,5,5,5,5,5,5,5,5,5
5,5,5,5,5,5,5,5,5,5,5,5,5,5,5,5,5,5
5,5,5,5,5,5,5,5,5,5,5,5,5,5,5,5,5,5
endlayer

layer
5,5,5,5,5,5,5,5,5,5,5,5,5,5,5,5,5,5
5,5,5,5,5,5,5,5,5,5,5,5,5,5,5,5,5,5
5,5,5,5,5,6,6,6,6,6,6,6,6,5,5,5,5,5
5,5,5,5,5,6,6,6,6,6,6,6,6,5,5,5,5,5
5,5,5,5,5,6,6,6,6,6,6,6,6,5,5,5,5,5
5,5,5,5,5,6,6,6,6,6,6,6,6,5,5,5,5,5
5,5,5,5,5,5,5,5,5,5,5,5,5,5,5,5,5,5
5,5,6,6,5,5,5,5,5,5,5,5,5,5,5,5,5,5
5,5,6,6,5,5,5,5,5,5,5,5,5,5,5,5,5,5
5,5,5,5,5,5,5,5,5,5,5,5,5,5,5,5,5,5
5,5,5,5,5,5,5,5,5,5,5,5,5,5,5,5,5,5
endlayer

layer
5,5,5,5,5,5,5,5,5,5,5,5,5,5,5,5,5,5
5,5,5,5,5,5,5,5,5,5,5,5,5,5,5,5,5,5
5,5,5,5,5,6,6,6,6,6,6,6,6,5,5,5,5,5
5,5,5,5,5,6,6,6,6,6,6,6,6,5,5,5,5,5
5,5,5,5,5,6,6,6,6,6,6,6,6,5,5,5,5,5
5,5,5,5,5,6,6,6,6,6,6,6,6,5,5,5,5,5
5,5,5,5,5,5,5,5,5,5,5,5,5,5,5,5,5,5
5,5,6,6,5,5,5,5,5,5,5,5,5,5,5,5,5,5
5,5,6,6,5,5,5,5,5,5,5,5,5,5,5,5,5,5
5,5,5,5,5,5,5,5,5,5,5,5,5,5,5,5,5,5
5,5,5,5,5,5,5,5,5,5,5,5,5,5,5,5,5,5
endlayer

layer
5,5,5,5,5,5,5,5,5,5,5,5,5,5,5,5,5,5
5,5,5,5,5,5,5,5,5,5,5,5,5,5,5,5,5,5
5,5,5,5,5,6,6,6,6,6,6,6,6,5,5,5,5,5
5,5,5,5,5,6,6,6,6,6,6,6,6,5,5,5,5,5
5,5,5,5,5,6,6,6,6,6,6,6,6,5,5,5,5,5
5,5,5,5,5,6,6,6,6,6,6,6,6,5,5,5,5,5
5,5,5,5,5,5,5,5,5,5,5,5,5,5,5,5,5,5
5,5,6,6,5,5,5,5,5,5,5,5,5,5,5,5,5,5
5,5,6,6,5,5,5,5,5,5,5,5,5,5,5,5,5,5
5,5,5,5,5,5,5,5,5,5,5,5,5,5,5,5,5,5
5,5,5,5,5,5,5,5,5,5,5,5,5,5,5,5,5,5
endlayer

layer
5,5,5,5,5,5,5,5,5,5,5,5,5,5,5,5,5,5
5,5,5,5,5,5,5,5,5,5,5,5,5,5,5,5,5,5
5,5,5,5,5,6,6,6,6,6,6,6,6,5,5,5,5,5
5,5,5,5,5,6,6,6,6,6,6,6,6,5,5,5,5,5
5,5,5,5,5,6,6,6,6,6,6,6,6,5,5,5,5,5
5,5,5,5,5,6,6,6,6,6,6,6,6,5,5,5,5,5
5,5,5,5,5,5,5,5,5,5,5,5,5,5,5,5,5,5
5,5,6,6,5,5,5,5,5,5,5,5,5,5,5,5,5,5
5,5,6,6,5,5,5,5,5,5,5,5,5,5,5,5,5,5
5,5,5,5,5,5,5,5,5,5,5,5,5,5,5,5,5,5
5,5,5,5,5,5,5,5,5,5,5,5,5,5,5,5,5,5
endlayer

layer
5,5,5,5,5,5,5,5,5,5,5,5,5,5,5,5,5,5
5,5,5,5,5,5,5,5,5,5,5,5,5,5,5,5,5,5
5,5,5,5,5,6,6,6,6,6,6,6,6,5,5,5,5,5
5,5,5,5,5,6,6,6,6,6,6,6,6,5,5,5,5,5
5,5,5,5,5,6,6,6,6,6,6,6,6,5,5,5,5,5
5,5,5,5,5,6,6,6,6,6,6,6,6,5,5,5,5,5
5,5,5,5,5,5,5,5,5,5,5,5,5,5,5,5,5,5
5,5,6,6,5,5,5,5,5,5,5,5,5,5,5,5,5,5
5,5,6,6,5,5,5,5,5,5,5,5,5,5,5,5,5,5
5,5,5,5,5,5,5,5,5,5,5,5,5,5,5,5,5,5
5,5,5,5,5,5,5,5,5,5,5,5,5,5,5,5,5,5
endlayer

layer
5,5,5,5,5,5,5,5,5,5,5,5,5,5,5,5,5,5
5,5,5,5,5,5,5,5,5,5,5,5,5,5,5,5,5,5
5,5,5,5,5,6,6,6,6,6,6,6,6,5,5,5,5,5
5,5,5,5,5,6,6,6,6,6,6,6,6,5,5,5,5,5
5,5,5,5,5,6,6,6,6,6,6,6,6,5,5,5,5,5
5,5,5,5,5,6,6,6,6,6,6,6,6,5,5,5,5,5
5,5,5,5,5,5,5,5,5,5,5,5,5,5,5,5,5,5
5,5,6,6,5,5,5,5,5,5,5,5,5,5,5,5,5,5
5,5,6,6,5,5,5,5,5,5,5,5,5,5,5,5,5,5
5,5,5,5,5,5,5,5,5,5,5,5,5,5,5,5,5,5
5,5,5,5,5,5,5,5,5,5,5,5,5,5,5,5,5,5
endlayer

layer
5,5,5,5,5,5,5,5,5,5,5,5,5,5,5,5,5,5
5,5,5,5,5,5,5,5,5,5,5,5,5,5,5,5,5,5
5,5,5,5,5,6,6,6,6,6,6,6,6,4,4,4,4,5
5,5,5,5,5,6,6,6,6,6,6,6,6,4,4,4,4,5
5,5,5,5,5,6,6,6,6,6,6,6,6,4,4,4,4,5
5,5,5,5,5,6,6,6,6,6,6,6,6,4,4,4,4,5
5,5,5,5,5,5,5,5,5,5,5,5,5,5,5,5,5,5
5,5,6,6,5,5,5,5,5,5,5,5,5,5,5,5,5,5
5,5,6,6,5,5,5,5,5,5,5,5,5,5,5,5,5,5
5,5,5,5,5,5,5,5,5,5,5,5,5,5,5,5,5,5
5,5,5,5,5,5,5,5,5,5,5,5,5,5,5,5,5,5
endlayer

layer
5,5,5,5,5,5,5,5,5,5,5,5,5,5,5,5,5,5
5,5,5,5,5,5,5,5,5,5,5,5,5,5,5,5,5,5
5,5,5,5,5,6,6,6,6,6,6,6,6,4,4,4,4,5
5,5,5,5,5,6,6,6,6,6,6,6,6,4,4,4,4,5
5,5,5,5,5,6,6,6,6,6,6,6,6,4,4,4,4,5
5,5,5,5,5,6,6,6,6,6,6,6,6,4,4,4,4,5
5,5,5,5,5,5,5,5,5,5,5,5,5,5,5,5,5,5
5,5,6,6,5,5,5,5,5,5,5,5,5,5,5,5,5,5
5,5,6,6,5,5,5,5,5,5,5,5,5,5,5,5,5,5
5,5,5,5,5,5,5,5,5,5,5,5,5,5,5,5,5,5
5,5,5,5,5,5,5,5,5,5,5,5,5,5,5,5,5,5
endlayer

layer
5,5,5,5,5,5,5,5,5,5,5,5,5,5,5,5,5,5
5,5,5,5,5,5,5,5,5,5,5,5,5,5,5,5,5,5
5,5,5,5,5,6,6,6,6,6,6,6,6,4,4,4,4,5
5,5,5,5,5,6,6,6,6,6,6,6,6,4,4,4,4,5
5,5,5,5,5,6,6,6,6,6,6,6,6,4,4,4,4,5
5,5,5,5,5,6,6,6,6,6,6,6,6,4,4,4,4,5
5,5,5,5,5,5,5,5,5,5,5,5,5,5,5,5,5,5
5,5,6,6,5,5,5,5,5,5,5,5,5,5,5,5,5,5
5,5,6,6,5,5,5,5,5,5,5,5,5,5,5,5,5,5
5,5,5,5,5,5,5,5,5,5,5,5,5,5,5,5,5,5
5,5,5,5,5,5,5,5,5,5,5,5,5,5,5,5,5,5
endlayer

layer
5,5,5,5,5,5,5,5,5,5,5,5,5,5,5,5,5,5
5,5,5,5,5,5,5,5,5,5,5,5,5,5,5,5,5,5
5,5,5,5,5,6,6,6,6,6,6,6,6,4,4,4,4,5
5,5,5,5,5,6,6,6,6,6,6,6,6,4,4,4,4,5
5,5,5,5,5,6,6,6,6,6,6,6,6,4,4,4,4,5
5,5,5,5,5,6,6,6,6,6,6,6,6,4,4,4,4,5
5,5,5,5,5,5,5,5,5,5,5,5,5,5,5,5,5,5
5,5,6,6,5,5,5,5,5,5,5,5,5,5,5,5,5,5
5,5,6,6,5,5,5,5,5,5,5,5,5,5,5,5,5,5
5,5,5,5,5,5,5,5,5,5,5,5,5,5,5,5,5,5
5,5,5,5,5,5,5,5,5,5,5,5,5,5,5,5,5,5
endlayer

layer
5,5,5,5,5,5,5,5,5,5,5,5,5,5,5,5,5,5
5,5,5,5,5,5,5,5,5,5,5,5,5,5,5,5,5,5
5,4,4,4,4,6,6,6,6,6,6,6,6,4,4,4,4,5
5,4,4,4,4,6,6,6,6,6,6,6,6,4,4,4,4,5
5,4,4,4,4,6,6,6,6,6,6,6,6,4,4,4,4,5
5,4,4,4,4,6,6,6,6,6,6,6,6,4,4,4,4,5
5,4,4,4,4,5,5,5,5,5,5,5,5,5,5,5,5,5
5,4,6,6,4,5,5,5,5,5,5,5,5,5,5,5,5,5
5,4,6,6,4,5,5,5,5,5,5,5,5,5,5,5,5,5
5,4,4,4,4,5,5,5,5,5,5,5,5,5,5,5,5,5
5,5,5,5,5,5,5,5,5,5,5,5,5,5,5,5,5,5
endlayer

layer
5,5,5,5,5,5,5,5,5,5,5,5,5,5,5,5,5,5
5,5,5,5,5,5,5,5,5,5,5,5,5,5,5,5,5,5
5,4,4,4,4,6,6,6,6,6,6,6,6,4,4,4,4,5
5,4,4,4,4,6,6,6,6,6,6,6,6,4,4,4,4,5
5,4,4,4,4,6,6,6,6,6,6,6,6,4,4,4,4,5
5,4,4,4,4,6,6,6,6,6,6,6,6,4,4,4,4,5
5,4,4,4,4,5,5,5,5,5,5,5,5,5,5,5,5,5
5,4,6,6,4,5,5,5,5,5,5,5,5,5,5,5,5,5
5,4,6,6,4,5,5,5,5,5,5,5,5,5,5,5,5,5
5,4,4,4,4,5,5,5,5,5,5,5,5,5,5,5,5,5
5,5,5,5,5,5,5,5,5,5,5,5,5,5,5,5,5,5
endlayer

layer
5,5,5,5,5,5,5,5,5,5,5,5,5,5,5,5,5,5
5,5,5,5,5,5,5,5,5,5,5,5,5,5,5,5,5,5
5,4,4,4,4,6,6,6,6,6,6,6,6,4,4,4,4,5
5,4,4,4,4,6,6,6,6,6,6,6,6,4,4,4,4,5
5,4,4,4,4,6,6,6,6,6,6,6,6,4,4,4,4,5
5,4,4,4,4,6,6,6,6,6,6,6,6,4,4,4,4,5
5,4,4,4,4,5,5,5,5,5,5,5,5,5,5,5,5,5
5,4,6,6,4,5,5,5,5,5,5,5,5,5,5,5,5,5
5,4,6,6,4,5,5,5,5,5,5,5,5,5,5,5,5,5
5,4,4,4,4,5,5,5,5,5,5,5,5,5,5,5,5,5
5,5,5,5,5,5,5,5,5,5,5,5,5,5,5,5,5,5
endlayer

layer
5,5,5,5,5,5,5,5,5,5,5,5,5,5,5,5,5,5
5,5,5,5,5,5,5,5,5,5,5,5,5,5,5,5,5,5
5,4,4,4,4,6,6,6,6,6,6,6,6,4,4,4,4,5
5,4,4,4,4,6,6,6,6,6,6,6,6,4,4,4,4,5
5,4,4,4,4,6,6,6,6,6,6,6,6,4,4,4,4,5
5,4,4,4,4,6,6,6,6,6,6,6,6,4,4,4,4,5
5,4,4,4,4,5,5,5,5,5,5,5,5,5,5,5,5,5
5,4,6,6,4,5,5,5,5,5,5,5,5,5,5,5,5,5
5,4,6,6,4,5,5,5,5,5,5,5,5,5,5,5,5,5
5,4,4,4,4,5,5,5,5,5,5,5,5,5,5,5,5,5
5,5,5,5,5,5,5,5,5,5,5,5,5,5,5,5,5,5
endlayer

layer
5,5,5,5,5,5,5,5,5,5,5,5,5,5,5,5,5,5
5,5,5,5,5,5,5,5,5,5,5,5,5,5,5,5,5,5
5,5,5,5,5,6,6,6,6,6,6,6,6,5,5,5,5,5
5,5,5,5,5,6,6,6,6,6,6,6,6,5,5,5,5,5
5,5,5,5,5,6,6,6,6,6,6,6,6,5,5,5,5,5
5,5,5,5,5,6,6,6,6,6,6,6,6,5,5,5,5,5
5,5,5,5,5,5,5,5,5,5,5,5,5,5,5,5,5,5
5,5,6,6,5,5,5,5,5,5,5,5,5,5,5,5,5,5
5,5,6,6,5,5,5,5,5,5,5,5,5,5,5,5,5,5
5,5,5,5,5,5,5,5,5,5,5,5,5,5,5,5,5,5
5,5,5,5,5,5,5,5,5,5,5,5,5,5,5,5,5,5
endlayer

layer
5,5,5,5,5,4,4,4,4,4,4,4,4,5,5,5,5,5
5,5,5,5,5,4,4,4,4,4,4,4,4,5,5,5,5,5
5,5,5,5,5,6,6,6,6,6,6,6,6,5,5,5,5,5
5,5,5,5,5,6,6,6,6,6,6,6,6,5,5,5,5,5
5,5,5,5,5,6,6,6,6,6,6,6,6,5,5,5,5,5
5,5,5,5,5,6,6,6,6,6,6,6,6,5,5,5,5,5
5,5,5,5,5,4,4,4,4,4,4,4,4,5,5,5,5,5
5,5,6,6,5,4,4,4,4,4,4,4,4,5,5,5,5,5
5,5,6,6,5,5,5,5,5,5,5,5,5,5,5,5,5,5
5,5,5,5,5,5,5,5,5,5,5,5,5,5,5,5,5,5
5,5,5,5,5,5,5,5,5,5,5,5,5,5,5,5,5,5
endlayer

layer
5,5,5,5,5,4,4,4,4,4,4,4,4,5,5,5,5,5
5,5,5,5,5,4,4,4,4,4,4,4,4,5,5,5,5,5
5,5,5,5,5,4,4,6,6,6,6,6,4,5,5,5,5,5
5,5,5,5,5,4,4,6,6,6,6,4,4,5,5,5,5,5
5,5,5,5,5,4,4,6,6,6,6,4,4,5,5,5,5,5
5,5,5,5,5,4,4,6,6,6,6,4,4,5,5,5,5,5
5,5,5,5,5,4,4,4,4,4,4,4,4,5,5,5,5,5
5,5,6,6,5,4,4,4,4,4,4,4,4,5,5,5,5,5
5,5,6,6,5,5,5,5,5,5,5,5,5,5,5,5,5,5
5,5,5,5,5,5,5,5,5,5,5,5,5,5,5,5,5,5
5,5,5,5,5,5,5,5,5,5,5,5,5,5,5,5,5,5
endlayer

layer
5,5,5,5,5,4,4,4,4,4,4,4,4,5,5,5,5,5
5,5,5,5,5,4,4,4,4,4,4,4,4,5,5,5,5,5
5,5,5,5,5,4,4,6,6,6,6,6,4,5,5,5,5,5
5,5,5,5,5,4,4,6,6,6,6,4,4,5,5,5,5,5
5,5,5,5,5,4,4,6,6,6,6,4,4,5,5,5,5,5
5,5,5,5,5,4,4,6,6,6,6,4,4,5,5,5,5,5
5,5,5,5,5,4,4,4,4,4,4,4,4,5,5,5,5,5
5,5,6,6,5,4,4,4,4,4,4,4,4,5,5,5,5,5
5,5,6,6,5,5,5,5,5,5,5,5,5,5,5,5,5,5
5,5,5,5,5,5,5,5,5,5,5,5,5,5,5,5,5,5
5,5,5,5,5,5,5,5,5,5,5,5,5,5,5,5,5,5
endlayer

layer
5,5,5,5,5,4,4,4,4,4,4,4,4,5,5,5,5,5
5,5,5,5,5,4,4,4,4,4,4,4,4,5,5,5,5,5
5,5,5,5,5,4,4,6,6,6,6,6,4,5,5,5,5,5
5,5,5,5,5,4,4,6,6,6,6,4,4,5,5,5,5,5
5,5,5,5,5,4,4,6,6,6,6,4,4,5,5,5,5,5
5,5,5,5,5,4,4,6,6,6,6,4,4,5,5,5,5,5
5,5,5,5,5,4,4,4,4,4,4,4,4,5,5,5,5,5
5,5,6,6,5,4,4,3,4,4,3,4,4,5,5,5,5,5
5,5,6,6,5,5,5,5,5,5,5,5,5,5,5,5,5,5
5,5,5,5,5,5,5,5,5,5,5,5,5,5,5,5,5,5
5,5,5,5,5,5,5,5,5,5,5,5,5,5,5,5,5,5
endlayer

layer
5,5,5,5,5,4,4,4,4,4,4,4,4,5,5,5,5,5
5,5,5,5,5,4,4,4,4,4,4,4,4,5,5,5,5,5
5,5,5,5,5,4,4,6,6,6,6,6,4,5,5,5,5,5
5,5,5,5,5,4,4,6,6,6,6,4,4,5,5,5,5,5
5,5,5,5,5,4,4,6,6,6,6,4,4,5,5,5,5,5
5,5,5,5,5,4,4,6,6,6,6,4,4,5,5,5,5,5
5,5,5,5,5,4,4,4,4,4,4,4,4,5,5,5,5,5
5,5,6,6,5,4,4,4,4,4,4,4,4,5,5,5,5,5
5,5,6,6,5,5,5,5,5,5,5,5,5,5,5,5,5,5
5,5,5,5,5,5,5,5,5,5,5,5,5,5,5,5,5,5
5,5,5,5,5,5,5,5,5,5,5,5,5,5,5,5,5,5
endlayer

layer
5,5,5,5,5,4,4,4,4,4,4,4,4,5,5,5,5,5
5,5,5,5,5,4,4,4,4,4,4,4,4,5,5,5,5,5
5,5,5,5,5,4,4,6,6,6,6,6,4,5,5,5,5,5
5,5,5,5,5,4,4,6,6,6,6,4,4,5,5,5,5,5
5,5,5,5,5,4,4,6,6,6,6,4,4,5,5,5,5,5
5,5,5,5,5,4,4,6,6,6,6,4,4,5,5,5,5,5
5,5,5,5,5,4,4,4,4,4,4,4,4,5,5,5,5,5
5,5,6,6,5,4,4,4,4,4,4,4,4,5,5,5,5,5
5,5,6,6,5,5,5,5,5,5,5,5,5,5,5,5,5,5
5,5,5,5,5,5,5,5,5,5,5,5,5,5,5,5,5,5
5,5,5,5,5,5,5,5,5,5,5,5,5,5,5,5,5,5
endlayer

layer
5,5,5,5,5,4,4,4,4,4,4,4,4,5,5,5,5,5
5,5,5,5,5,4,4,4,4,4,4,4,4,5,5,5,5,5
5,5,5,5,5,4,4,6,6,6,6,6,4,5,5,5,5,5
5,5,5,5,5,4,4,6,6,6,6,4,4,5,5,5,5,5
5,5,5,5,5,4,4,6,6,6,6,4,4,5,5,5,5,5
5,5,5,5,5,4,4,6,6,6,6,4,4,5,5,5,5,5
5,5,5,5,5,4,4,4,4,4,4,4,4,5,5,5,5,5
5,5,6,6,5,4,4,4,4,4,4,4,4,5,5,5,5,5
5,5,6,6,5,5,5,5,5,5,5,5,5,5,5,5,5,5
5,5,5,5,5,5,5,5,5,5,5,5,5,5,5,5,5,5
5,5,5,5,5,5,5,5,5,5,5,5,5,5,5,5,5,5
endlayer

layer
5,5,5,5,5,4,4,4,4,4,4,4,4,5,5,5,5,5
5,5,5,5,5,4,4,4,4,4,4,4,4,5,5,5,5,5
5,5,5,5,5,4,4,6,6,6,6,6,4,5,5,5,5,5
5,5,5,5,5,4,4,6,6,6,6,4,4,5,5,5,5,5
5,5,5,5,5,4,4,6,6,6,6,4,4,5,5,5,5,5
5,5,5,5,5,4,4,6,6,6,6,4,4,5,5,5,5,5
5,5,5,5,5,4,4,4,4,4,4,4,4,5,5,5,5,5
5,5,6,6,5,4,4,4,4,4,4,4,4,5,5,5,5,5
5,5,6,6,5,5,5,5,5,5,5,5,5,5,5,5,5,5
5,5,5,5,5,5,5,5,5,5,5,5,5,5,5,5,5,5
5,5,5,5,5,5,5,5,5,5,5,5,5,5,5,5,5,5
endlayer

layer
5,5,5,5,5,5,5,5,5,5,5,5,5,5,5,5,5,5
5,5,5,5,5,5,5,5,5,5,5,5,5,5,5,5,5,5
5,5,5,5,5,5,5,5,5,5,5,5,5,5,5,5,5,5
5,5,5,5,5,5,5,5,5,5,5,5,5,5,5,5,5,5
5,5,5,5,5,5,5,5,5,5,5,5,5,5,5,5,5,5
5,5,5,5,5,5,5,5,5,5,5,5,5,5,5,5,5,5
5,5,5,5,5,5,5,5,5,5,5,5,5,5,5,5,5,5
5,5,6,6,5,5,5,5,5,5,5,5,5,5,5,5,5,5
5,5,6,6,5,5,5,5,5,5,5,5,5,5,5,5,5,5
5,5,5,5,5,5,5,5,5,5,5,5,5,5,5,5,5,5
5,5,5,5,5,5,5,5,5,5,5,5,5,5,5,5,5,5
endlayer

layer
5,5,5,5,5,5,5,5,5,5,5,5,5,5,5,5,5,5
5,5,5,5,5,5,5,5,5,5,5,5,5,5,5,5,5,5
5,5,5,5,5,5,5,5,5,5,5,5,5,5,5,5,5,5
5,5,5,5,5,5,5,5,5,5,5,5,5,5,5,5,5,5
5,5,5,5,5,5,5,5,5,5,5,5,5,5,5,5,5,5
5,5,5,5,5,5,5,5,5,5,5,5,5,5,5,5,5,5
5,5,7,7,5,5,5,5,5,5,5,5,5,5,5,5,5,5
5,7,6,6,7,5,5,5,5,5,5,5,5,5,5,5,5,5
5,7,6,6,7,5,5,5,5,5,5,5,5,5,5,5,5,5
5,5,7,7,5,5,5,5,5,5,5,5,5,5,5,5,5,5
5,5,5,5,5,5,5,5,5,5,5,5,5,5,5,5,5,5
endlayer

layer
5,5,5,5,5,5,5,5,5,5,5,5,5,5,5,5,5,5
5,5,5,5,5,5,5,5,5,5,5,5,5,5,5,5,5,5
5,5,5,5,5,5,5,5,5,5,5,5,5,5,5,5,5,5
5,5,5,5,5,5,5,5,5,5,5,5,5,5,5,5,5,5
5,5,5,5,5,5,5,5,5,5,5,5,5,5,5,5,5,5
5,5,5,5,5,5,5,5,5,5,5,5,5,5,5,5,5,5
5,5,7,7,5,5,5,5,5,5,5,5,5,5,5,5,5,5
5,7,6,6,7,5,5,5,5,5,5,5,5,5,5,5,5,5
5,7,6,6,7,5,5,5,5,5,5,5,5,5,5,5,5,5
5,5,7,7,5,5,5,5,5,5,5,5,5,5,5,5,5,5
5,5,5,5,5,5,5,5,5,5,5,5,5,5,5,5,5,5
endlayer

layer
5,5,5,5,5,5,5,5,5,5,5,5,5,5,5,5,5,5
5,5,5,5,5,5,5,5,5,5,5,5,5,5,5,5,5,5
5,5,5,5,5,5,5,5,5,5,5,5,5,5,5,5,5,5
5,5,5,5,5,5,5,5,5,5,5,5,5,5,5,5,5,5
5,5,5,5,5,5,5,5,5,5,5,5,5,5,5,5,5,5
5,5,5,5,5,5,5,5,5,5,5,5,5,5,5,5,5,5
5,5,7,7,5,5,5,5,5,5,5,5,5,5,5,5,5,5
5,7,6,6,7,5,5,5,5,5,5,5,5,5,5,5,5,5
5,7,6,6,7,5,5,5,5,5,5,5,5,5,5,5,5,5
5,5,7,7,5,5,5,5,5,5,5,5,5,5,5,5,5,5
5,5,5,5,5,5,5,5,5,5,5,5,5,5,5,5,5,5
endlayer

layer
5,5,5,5,5,5,5,5,5,5,5,5,5,5,5,5,5,5
5,5,5,5,5,5,5,5,5,5,5,5,5,5,5,5,5,5
5,5,5,5,5,5,5,5,5,5,5,5,5,5,5,5,5,5
5,5,5,5,5,5,5,5,5,5,5,5,5,5,5,5,5,5
5,5,5,5,5,5,5,5,5,5,5,5,5,5,5,5,5,5
5,5,5,5,5,5,5,5,5,5,5,5,5,5,5,5,5,5
5,5,5,5,5,5,5,5,5,5,5,5,5,5,5,5,5,5
5,5,3,3,5,5,5,5,5,5,5,5,5,5,5,5,5,5
5,5,3,3,5,5,5,5,5,5,5,5,5,5,5,5,5,5
5,5,5,5,5,5,5,5,5,5,5,5,5,5,5,5,5,5
5,5,5,5,5,5,5,5,5,5,5,5,5,5,5,5,5,5
endlayer

layer
5,5,5,5,5,5,5,5,5,5,5,5,5,5,5,5,5,5
5,5,5,5,5,5,5,5,5,5,5,5,5,5,5,5,5,5
5,5,5,5,5,5,5,5,5,5,5,5,5,5,5,5,5,5
5,5,5,5,5,5,5,5,5,5,5,5,5,5,5,5,5,5
5,5,5,5,5,5,5,5,5,5,5,5,5,5,5,5,5,5
5,5,5,5,5,5,5,5,5,5,5,5,5,5,5,5,5,5
5,5,5,5,5,5,5,5,5,5,5,5,5,5,5,5,5,5
5,5,3,3,5,5,5,5,5,5,5,5,5,5,5,5,5,5
5,5,3,3,5,5,5,5,5,5,5,5,5,5,5,5,5,5
5,5,5,5,5,5,5,5,5,5,5,5,5,5,5,5,5,5
5,5,5,5,5,5,5,5,5,5,5,5,5,5,5,5,5,5
endlayer

layer
5,5,5,5,5,5,5,5,5,5,5,5,5,5,5,5,5,5
5,5,5,5,5,5,5,5,5,5,5,5,5,5,5,5,5,5
5,5,5,5,5,5,5,5,5,5,5,5,5,5,5,5,5,5
5,5,5,5,5,5,5,5,5,5,5,5,5,5,5,5,5,5
5,5,5,5,5,5,5,5,5,5,5,5,5,5,5,5,5,5
5,5,5,5,5,5,5,5,5,5,5,5,5,5,5,5,5,5
5,5,5,5,5,5,5,5,5,5,5,5,5,5,5,5,5,5
5,5,3,3,5,5,5,5,5,5,5,5,5,5,5,5,5,5
5,5,3,3,5,5,5,5,5,5,5,5,5,5,5,5,5,5
5,5,5,5,5,5,5,5,5,5,5,5,5,5,5,5,5,5
5,5,5,5,5,5,5,5,5,5,5,5,5,5,5,5,5,5
endlayer

layer
5,5,5,5,5,5,5,5,5,5,5,5,5,5,5,5,5,5
5,5,5,5,5,5,5,5,5,5,5,5,5,5,5,5,5,5
5,5,5,5,5,5,5,5,5,5,5,5,5,5,5,5,5,5
5,5,5,5,5,5,5,5,5,5,5,5,5,5,5,5,5,5
5,5,5,5,5,5,5,5,5,5,5,5,5,5,5,5,5,5
5,5,5,5,5,5,5,5,5,5,5,5,5,5,5,5,5,5
5,5,5,5,5,5,5,5,5,5,5,5,5,5,5,5,5,5
5,5,3,3,5,5,5,5,5,5,5,5,5,5,5,5,5,5
5,5,3,3,5,5,5,5,5,5,5,5,5,5,5,5,5,5
5,5,5,5,5,5,5,5,5,5,5,5,5,5,5,5,5,5
5,5,5,5,5,5,5,5,5,5,5,5,5,5,5,5,5,5
endlayer