weight=6
dimensionsToSpawnIn=overworld
embed_into_distance=8
random_height_offset=0,0
unacceptable_target_blocks=flowing_water,water,flowing_lava,lava,ice,packed_ice,stained_hardened_clay-9,brick_block,double_stone_slab,stonebrick,red_sandstone,red_nether_brick,red_mushroom_block,brown_mushroom_block,planks,cobblestone,end_stone,obsidian,purpur_block,iron_bars,purpur_slab,purpur_pillar,netherrack,soul_sand,quartz_ore,stained_glass,glass
dimensions=11,31,15
allowable_overhang=0
max_leveling=5
leveling_buffer=-1
preventRotation=1
preserve_water=0
preserve_lava=0
uniqueMinDistance=0
spawnMinDistance=0
spawnMaxDistance=0

adjoining_template=templateparser/STP1;0;10;16
adjoining_template=templateparser/STP1;0;10;-16

rule1=0,100,preserveBlock
rule2=0,100,minecraft:monster_egg-4,monster_egg-2,monster_egg-2,monster_egg-2,monster_egg-3,stonebrick-2,stonebrick-1,stonebrick-0,stonebrick-2,stonebrick-1,stonebrick-0
rule3=0,100,chisel:blocksteel-4
rule4=0,100,chisel:brownstone-1,chisel:brownstone-1,chisel:brownstone-0
rule5=0,100,minecraft:iron_bars-0
rule6=0,100,minecraft:water-0,chisel:limestone2-7
rule7=0,100,chisel:technical-15
rule8=0,100,chisel:technical-15
rule9=0,100,chisel:technical-12
rule10=0,100,air
rule11=0,100,minecraft:ladder-4,preserveBlock
rule12=0,100,minecraft:trapdoor-15
rule13=0,100,minecraft:trapdoor-13
rule14=0,100,minecraft:trapdoor-12
rule15=0,100,minecraft:trapdoor-14
rule16=0,100,minecraft:stone_slab-0
rule17=0,100,minecraft:stone_slab-8
rule18=0,100,minecraft:cobblestone_wall-0,minecraft:cobblestone_wall-1

layer
1,1,1,1,1,1,1,1,1,1,1,1,1,1,1
1,1,1,1,1,1,1,1,1,1,1,1,1,1,1
1,1,1,1,1,1,1,1,1,1,1,1,1,1,1
1,1,1,1,1,1,1,1,1,1,1,1,1,1,1
1,1,1,1,1,1,1,1,1,1,1,1,1,1,1
1,1,1,1,1,1,2,2,2,1,1,1,1,1,1
1,1,1,1,1,2,2,2,2,2,1,1,1,1,1
1,1,1,1,1,2,2,3,2,2,1,1,1,1,1
1,1,1,1,1,2,2,2,2,2,1,1,1,1,1
1,1,1,1,1,1,2,2,2,1,1,1,1,1,1
1,1,1,1,1,1,1,1,1,1,1,1,1,1,1
1,1,1,1,1,1,1,1,1,1,1,1,1,1,1
1,1,1,1,1,1,1,1,1,1,1,1,1,1,1
1,1,1,1,1,1,1,1,1,1,1,1,1,1,1
1,1,1,1,1,1,1,1,1,1,1,1,1,1,1
1,1,1,1,1,1,1,1,1,1,1,1,1,1,1
1,1,1,1,1,1,1,1,1,1,1,1,1,1,1
1,1,1,1,1,1,1,1,1,1,1,1,1,1,1
1,1,1,1,1,1,1,1,1,1,1,1,1,1,1
1,1,1,1,1,1,1,1,1,1,1,1,1,1,1
1,1,1,1,1,1,1,1,1,1,1,1,1,1,1
1,1,1,1,1,1,2,2,2,1,1,1,1,1,1
1,1,1,1,1,2,2,2,2,2,1,1,1,1,1
1,1,1,1,1,2,2,3,2,2,1,1,1,1,1
1,1,1,1,1,2,2,2,2,2,1,1,1,1,1
1,1,1,1,1,1,2,2,2,1,1,1,1,1,1
1,1,1,1,1,1,1,1,1,1,1,1,1,1,1
1,1,1,1,1,1,1,1,1,1,1,1,1,1,1
1,1,1,1,1,1,1,1,1,1,1,1,1,1,1
1,1,1,1,1,1,1,1,1,1,1,1,1,1,1
1,1,1,1,1,1,1,1,1,1,1,1,1,1,1
endlayer

layer
1,1,1,1,1,1,1,1,1,1,1,1,1,1,1
1,1,1,1,1,1,1,1,1,1,1,1,1,1,1
1,1,1,1,1,1,1,1,1,1,1,1,1,1,1
1,1,1,1,1,1,1,1,1,1,1,1,1,1,1
1,1,1,1,1,1,1,1,1,1,1,1,1,1,1
1,1,1,1,1,1,2,2,2,1,1,1,1,1,1
1,1,1,1,1,2,6,6,6,2,1,1,1,1,1
1,1,1,1,1,2,6,6,6,2,1,1,1,1,1
1,1,1,1,1,2,6,6,6,2,1,1,1,1,1
1,1,1,1,1,1,2,2,2,1,1,1,1,1,1
1,1,1,1,1,1,1,1,1,1,1,1,1,1,1
1,1,1,1,1,1,1,1,1,1,1,1,1,1,1
1,1,1,1,1,1,1,1,1,1,1,1,1,1,1
1,1,1,1,1,1,1,1,1,1,1,1,1,1,1
1,1,1,1,1,1,1,1,1,1,1,1,1,1,1
1,1,1,1,1,1,1,1,1,1,1,1,1,1,1
1,1,1,1,1,1,1,1,1,1,1,1,1,1,1
1,1,1,1,1,1,1,1,1,1,1,1,1,1,1
1,1,1,1,1,1,1,1,1,1,1,1,1,1,1
1,1,1,1,1,1,1,1,1,1,1,1,1,1,1
1,1,1,1,1,1,1,1,1,1,1,1,1,1,1
1,1,1,1,1,1,2,2,2,1,1,1,1,1,1
1,1,1,1,1,2,6,6,6,2,1,1,1,1,1
1,1,1,1,1,2,6,6,6,2,1,1,1,1,1
1,1,1,1,1,2,6,6,6,2,1,1,1,1,1
1,1,1,1,1,1,2,2,2,1,1,1,1,1,1
1,1,1,1,1,1,1,1,1,1,1,1,1,1,1
1,1,1,1,1,1,1,1,1,1,1,1,1,1,1
1,1,1,1,1,1,1,1,1,1,1,1,1,1,1
1,1,1,1,1,1,1,1,1,1,1,1,1,1,1
1,1,1,1,1,1,1,1,1,1,1,1,1,1,1
endlayer

layer
1,1,1,1,1,1,1,1,1,1,1,1,1,1,1
1,1,1,1,1,1,1,1,1,1,1,1,1,1,1
1,1,1,1,1,1,1,1,1,1,1,1,1,1,1
1,1,1,1,1,1,1,1,1,1,1,1,1,1,1
1,1,1,1,1,1,1,1,1,1,1,1,1,1,1
1,1,1,1,1,2,2,2,2,2,1,1,1,1,1
1,1,1,1,1,2,10,10,10,2,1,1,1,1,1
1,1,1,1,1,2,10,10,10,2,1,1,1,1,1
1,1,1,1,1,2,10,10,10,2,1,1,1,1,1
1,1,1,1,1,2,2,2,2,2,1,1,1,1,1
1,1,1,1,1,1,1,1,1,1,1,1,1,1,1
1,1,1,1,1,1,1,1,1,1,1,1,1,1,1
1,1,1,1,1,1,1,1,1,1,1,1,1,1,1
1,1,1,1,1,1,1,1,1,1,1,1,1,1,1
1,1,1,1,1,1,1,1,1,1,1,1,1,1,1
1,1,1,1,1,1,1,1,1,1,1,1,1,1,1
1,1,1,1,1,1,1,1,1,1,1,1,1,1,1
1,1,1,1,1,1,1,1,1,1,1,1,1,1,1
1,1,1,1,1,1,1,1,1,1,1,1,1,1,1
1,1,1,1,1,1,1,1,1,1,1,1,1,1,1
1,1,1,1,1,1,1,1,1,1,1,1,1,1,1
1,1,1,1,1,2,2,2,2,2,1,1,1,1,1
1,1,1,1,1,2,10,10,10,2,1,1,1,1,1
1,1,1,1,1,2,10,10,10,2,1,1,1,1,1
1,1,1,1,1,2,10,10,10,2,1,1,1,1,1
1,1,1,1,1,2,2,2,2,2,1,1,1,1,1
1,1,1,1,1,1,1,1,1,1,1,1,1,1,1
1,1,1,1,1,1,1,1,1,1,1,1,1,1,1
1,1,1,1,1,1,1,1,1,1,1,1,1,1,1
1,1,1,1,1,1,1,1,1,1,1,1,1,1,1
1,1,1,1,1,1,1,1,1,1,1,1,1,1,1
endlayer

layer
1,1,1,1,1,1,1,1,1,1,1,1,1,1,1
1,1,1,1,1,1,1,1,1,1,1,1,1,1,1
1,1,1,1,1,1,1,1,1,1,1,1,1,1,1
1,1,1,1,1,1,1,1,1,1,1,1,1,1,1
1,1,1,1,1,1,1,1,1,1,1,1,1,1,1
1,1,1,1,1,2,2,2,2,2,1,1,1,1,1
1,1,1,1,1,2,10,10,10,2,1,1,1,1,1
1,1,1,1,1,2,10,10,10,2,1,1,1,1,1
1,1,1,1,1,2,10,10,10,2,1,1,1,1,1
1,1,1,1,1,2,2,2,2,2,1,1,1,1,1
1,1,1,1,1,1,1,1,1,1,1,1,1,1,1
1,1,1,1,1,1,1,1,1,1,1,1,1,1,1
1,1,1,1,1,1,1,1,1,1,1,1,1,1,1
1,1,1,1,1,1,1,1,1,1,1,1,1,1,1
1,1,1,1,1,1,1,1,1,1,1,1,1,1,1
1,1,1,1,1,1,1,1,1,1,1,1,1,1,1
1,1,1,1,1,1,1,1,1,1,1,1,1,1,1
1,1,1,1,1,1,1,1,1,1,1,1,1,1,1
1,1,1,1,1,1,1,1,1,1,1,1,1,1,1
1,1,1,1,1,1,1,1,1,1,1,1,1,1,1
1,1,1,1,1,1,1,1,1,1,1,1,1,1,1
1,1,1,1,1,2,2,2,2,2,1,1,1,1,1
1,1,1,1,1,2,10,10,10,2,1,1,1,1,1
1,1,1,1,1,2,10,10,10,2,1,1,1,1,1
1,1,1,1,1,2,10,10,10,2,1,1,1,1,1
1,1,1,1,1,2,2,2,2,2,1,1,1,1,1
1,1,1,1,1,1,1,1,1,1,1,1,1,1,1
1,1,1,1,1,1,1,1,1,1,1,1,1,1,1
1,1,1,1,1,1,1,1,1,1,1,1,1,1,1
1,1,1,1,1,1,1,1,1,1,1,1,1,1,1
1,1,1,1,1,1,1,1,1,1,1,1,1,1,1
endlayer

layer
1,1,1,1,1,1,1,1,1,1,1,1,1,1,1
1,1,1,1,1,4,4,4,4,4,1,1,1,1,1
1,1,1,4,4,4,4,4,4,4,4,4,1,1,1
1,1,4,4,4,4,4,4,4,4,4,4,4,1,1
1,1,4,4,4,4,4,4,4,4,4,4,4,1,1
1,4,4,4,4,4,4,4,4,4,4,4,4,4,1
1,4,4,4,4,4,5,5,5,4,4,4,4,4,1
1,4,4,4,4,4,5,10,5,4,4,4,4,4,1
1,4,4,4,4,4,5,5,5,4,4,4,4,4,1
1,4,4,4,4,4,4,4,4,4,4,4,4,4,1
1,1,4,4,4,4,4,4,4,4,4,4,4,1,1
1,1,4,4,4,4,4,4,4,4,4,4,4,1,1
1,1,1,4,4,4,4,4,4,4,4,4,1,1,1
1,1,1,1,1,4,4,4,4,4,1,1,1,1,1
1,1,1,1,1,1,1,1,1,1,1,1,1,1,1
1,1,1,1,1,1,1,1,1,1,1,1,1,1,1
1,1,1,1,1,1,1,1,1,1,1,1,1,1,1
1,1,1,1,1,4,4,4,4,4,1,1,1,1,1
1,1,1,4,4,4,4,4,4,4,4,4,1,1,1
1,1,4,4,4,4,4,4,4,4,4,4,4,1,1
1,1,4,4,4,4,4,4,4,4,4,4,4,1,1
1,4,4,4,4,4,4,4,4,4,4,4,4,4,1
1,4,4,4,4,4,5,5,5,4,4,4,4,4,1
1,4,4,4,4,4,5,10,5,4,4,4,4,4,1
1,4,4,4,4,4,5,5,5,4,4,4,4,4,1
1,4,4,4,4,4,4,4,4,4,4,4,4,4,1
1,1,4,4,4,4,4,4,4,4,4,4,4,1,1
1,1,4,4,4,4,4,4,4,4,4,4,4,1,1
1,1,1,4,4,4,4,4,4,4,4,4,1,1,1
1,1,1,1,1,4,4,4,4,4,1,1,1,1,1
1,1,1,1,1,1,1,1,1,1,1,1,1,1,1
endlayer

layer
1,1,1,1,1,4,4,4,4,4,1,1,1,1,1
1,1,1,4,4,10,10,10,10,10,4,4,1,1,1
1,1,4,10,10,10,10,10,10,10,10,10,4,1,1
1,4,10,10,10,10,10,10,10,10,10,10,10,4,1
1,4,10,10,10,10,10,10,10,10,10,10,10,4,1
4,10,10,10,10,10,10,10,10,10,10,10,10,10,4
4,10,10,10,10,10,7,7,7,10,10,10,10,10,4
4,10,10,10,10,10,7,10,7,10,10,10,10,10,4
4,10,10,10,10,10,7,7,7,10,10,10,10,10,4
4,10,10,10,10,10,10,10,10,10,10,10,10,10,4
1,4,10,10,10,10,10,10,10,10,10,10,10,4,1
1,4,10,10,10,10,10,10,10,10,10,10,10,4,1
1,1,4,10,10,10,10,10,10,10,10,10,4,1,1
1,1,1,4,4,10,10,10,10,10,4,4,1,1,1
1,1,1,1,1,4,4,4,4,4,1,1,1,1,1
1,1,1,1,1,1,1,1,1,1,1,1,1,1,1
1,1,1,1,1,4,4,4,4,4,1,1,1,1,1
1,1,1,4,4,10,10,10,10,10,4,4,1,1,1
1,1,4,10,10,10,10,10,10,10,10,10,4,1,1
1,4,10,10,10,10,10,10,10,10,10,10,10,4,1
1,4,10,10,10,10,10,10,10,10,10,10,10,4,1
4,10,10,10,10,10,10,10,10,10,10,10,10,10,4
4,10,10,10,10,10,7,7,7,10,10,10,10,10,4
4,10,10,10,10,10,7,10,7,10,10,10,10,10,4
4,10,10,10,10,10,7,7,7,10,10,10,10,10,4
4,10,10,10,10,10,10,10,10,10,10,10,10,10,4
1,4,10,10,10,10,10,10,10,10,10,10,10,4,1
1,4,10,10,10,10,10,10,10,10,10,10,10,4,1
1,1,4,10,10,10,10,10,10,10,10,10,4,1,1
1,1,1,4,4,10,10,10,10,10,4,4,1,9,9
1,1,1,1,1,4,4,4,4,4,1,1,1,9,1
endlayer

layer
1,1,1,1,1,4,4,4,4,4,1,1,1,1,1
1,1,1,4,4,10,10,10,10,10,4,4,1,1,1
1,1,4,10,10,10,10,10,10,10,10,10,4,1,1
1,4,10,10,10,10,10,10,10,10,10,10,10,4,1
1,4,10,10,10,10,10,10,10,10,10,10,10,4,1
4,10,10,10,10,10,10,10,10,10,10,10,10,10,4
4,10,10,10,10,10,10,10,10,10,10,10,10,10,4
4,10,10,10,10,10,10,4,10,10,10,10,10,10,4
4,10,10,10,10,10,10,10,10,10,10,10,10,10,4
4,10,10,10,10,10,10,10,10,10,10,10,10,10,4
1,4,10,10,10,10,10,10,10,10,10,10,10,4,1
1,4,10,10,10,10,10,10,10,10,10,10,10,4,1
1,1,4,10,10,10,10,10,10,10,10,10,4,1,1
1,1,1,4,4,10,10,10,10,10,4,4,1,1,1
1,1,1,1,1,4,4,4,4,4,1,1,1,1,1
1,1,1,1,1,1,1,1,1,1,1,1,1,1,1
1,1,1,1,1,4,4,4,4,4,1,1,1,1,1
1,1,1,4,4,10,10,10,10,10,4,4,1,1,1
1,1,4,10,10,10,10,10,10,10,10,10,4,1,1
1,4,10,10,10,10,10,10,10,10,10,10,10,4,1
1,4,10,10,10,10,10,10,10,10,10,10,10,4,1
4,10,10,10,10,10,10,10,10,10,10,10,10,10,4
4,10,10,10,10,10,10,10,10,10,10,10,10,10,4
4,10,10,10,10,10,10,4,10,10,10,10,10,10,4
4,10,10,10,10,10,10,10,10,10,10,10,10,10,4
4,10,10,10,10,10,10,10,10,10,10,10,10,10,4
1,4,10,10,10,10,10,10,10,10,10,10,10,4,1
1,4,10,10,10,10,10,10,10,10,10,10,10,4,1
1,1,4,10,10,10,10,10,10,10,10,10,4,1,1
1,1,1,4,4,10,10,10,10,10,4,4,1,9,9
1,1,1,1,1,4,4,4,4,4,1,1,1,9,1
endlayer

layer
1,1,1,1,1,4,4,4,4,4,1,1,1,1,1
1,1,1,4,4,10,10,10,10,10,4,4,1,4,1
1,1,4,10,10,10,10,10,10,10,10,10,4,1,1
1,4,10,10,10,10,10,10,10,10,10,10,10,4,1
1,4,10,10,10,10,10,10,10,10,10,10,10,4,1
4,10,10,10,10,10,10,10,10,10,10,10,10,10,4
4,10,10,10,10,10,10,10,10,10,10,10,10,10,4
4,10,10,10,10,10,10,4,10,10,10,10,10,10,4
4,10,10,10,10,10,10,10,10,10,10,10,10,10,4
4,10,10,10,10,10,10,10,10,10,10,10,10,10,4
1,4,10,10,10,10,10,10,10,10,10,10,10,4,1
1,4,10,10,10,10,10,10,10,10,10,10,10,4,1
1,1,4,10,10,10,10,10,10,10,10,10,4,1,1
1,1,1,4,4,10,10,10,10,10,4,4,1,1,1
1,1,1,1,1,4,4,4,4,4,1,1,1,1,1
1,1,1,1,1,1,1,1,1,1,1,1,1,1,1
1,1,1,1,1,4,4,4,4,4,1,1,1,1,1
1,1,1,4,4,10,10,10,10,10,4,4,1,4,1
1,1,4,10,10,10,10,10,10,10,10,10,4,1,1
1,4,10,10,10,10,10,10,10,10,10,10,10,4,1
1,4,10,10,10,10,10,10,10,10,10,10,10,4,1
4,10,10,10,10,10,10,10,10,10,10,10,10,10,4
4,10,10,10,10,10,10,10,10,10,10,10,10,10,4
4,10,10,10,10,10,10,4,10,10,10,10,10,10,4
4,10,10,10,10,10,10,10,10,10,10,10,10,10,4
4,10,10,10,10,10,10,10,10,10,10,10,10,10,4
1,4,10,10,10,10,10,10,10,10,10,10,10,4,1
1,4,10,10,10,10,10,10,10,10,10,10,10,4,1
1,1,4,10,10,10,10,10,10,10,10,10,4,1,1
1,1,1,4,4,10,10,10,10,10,4,4,1,9,9
1,1,1,1,1,4,4,4,4,4,1,1,1,9,1
endlayer

layer
1,1,1,1,1,4,4,8,4,4,1,1,1,11,1
1,1,1,4,4,10,12,10,12,10,4,4,1,4,5
1,1,4,10,10,10,10,10,10,10,10,10,4,1,1
1,4,10,10,10,10,10,10,10,10,10,10,10,4,1
1,4,10,10,10,10,10,10,10,10,10,10,10,4,1
4,10,10,10,10,10,10,10,10,10,10,10,10,10,4
4,14,10,10,10,10,10,10,10,10,10,10,10,13,4
8,10,10,10,10,10,10,4,10,10,10,10,10,10,8
4,14,10,10,10,10,10,10,10,10,10,10,10,13,4
4,10,10,10,10,10,10,10,10,10,10,10,10,10,4
1,4,10,10,10,10,10,10,10,10,10,10,10,4,1
1,4,10,10,10,10,10,10,10,10,10,10,10,4,1
1,1,4,10,10,10,10,10,10,10,10,10,4,1,1
1,1,1,4,4,10,15,10,15,10,4,4,1,1,1
1,1,1,1,1,4,4,8,4,4,1,1,1,1,1
1,1,1,1,1,1,1,1,1,1,1,1,1,1,1
1,1,1,1,1,4,4,8,4,4,1,1,1,11,1
1,1,1,4,4,10,12,10,12,10,4,4,1,4,5
1,1,4,10,10,10,10,10,10,10,10,10,4,1,1
1,4,10,10,10,10,10,10,10,10,10,10,10,4,1
1,4,10,10,10,10,10,10,10,10,10,10,10,4,1
4,10,10,10,10,10,10,10,10,10,10,10,10,10,4
4,14,10,10,10,10,10,10,10,10,10,10,10,13,4
8,10,10,10,10,10,10,4,10,10,10,10,10,10,8
4,14,10,10,10,10,10,10,10,10,10,10,10,13,4
4,10,10,10,10,10,10,10,10,10,10,10,10,10,4
1,4,10,10,10,10,10,10,10,10,10,10,10,4,1
1,4,10,10,10,10,10,10,10,10,10,10,10,4,1
1,1,4,10,10,10,10,10,10,10,10,10,4,1,1
1,1,1,4,4,10,15,10,15,10,4,4,1,9,5
1,1,1,1,1,4,4,8,4,4,1,1,1,5,1
endlayer

layer
1,1,1,1,1,1,16,16,16,1,1,1,1,11,1
1,1,1,1,1,10,10,10,10,10,1,1,17,4,5
1,1,1,10,10,10,10,10,10,10,10,17,4,17,1
1,1,10,10,10,10,10,10,10,10,17,4,17,1,1
1,1,10,10,10,10,10,10,10,17,4,17,10,1,1
1,10,10,10,10,10,10,10,17,4,17,10,10,10,1
16,10,10,10,10,10,10,17,4,17,10,10,10,10,16
16,10,10,10,10,10,10,4,17,10,10,10,10,10,16
16,10,10,10,10,10,10,10,10,10,10,10,10,10,16
1,10,10,10,10,10,10,10,10,10,10,10,10,10,1
1,1,10,10,10,10,10,10,10,10,10,10,10,1,1
1,1,10,10,10,10,10,10,10,10,10,10,10,1,1
1,1,1,10,10,10,10,10,10,10,10,10,1,1,1
1,1,1,1,1,10,10,10,10,10,1,1,1,1,1
1,1,1,1,1,1,16,16,16,1,1,1,1,1,1
1,1,1,1,1,1,1,1,1,1,1,1,1,1,1
1,1,1,1,1,1,16,16,16,1,1,1,1,11,1
1,1,1,1,1,10,10,10,10,10,1,1,17,4,5
1,1,1,10,10,10,10,10,10,10,10,17,4,17,1
1,1,10,10,10,10,10,10,10,10,17,4,17,1,1
1,1,10,10,10,10,10,10,10,17,4,17,10,1,1
1,10,10,10,10,10,10,10,17,4,17,10,10,10,1
16,10,10,10,10,10,10,17,4,17,10,10,10,10,16
16,10,10,10,10,10,10,4,17,10,10,10,10,10,16
16,10,10,10,10,10,10,10,10,10,10,10,10,10,16
1,10,10,10,10,10,10,10,10,10,10,10,10,10,1
1,1,10,10,10,10,10,10,10,10,10,10,10,1,1
1,1,10,10,10,10,10,10,10,10,10,10,10,1,1
1,1,1,10,10,10,10,10,10,10,10,10,1,1,1
1,1,1,1,1,10,10,10,10,10,1,1,1,16,5
1,1,1,1,1,1,16,16,16,1,1,1,1,5,1
endlayer

layer
1,1,1,1,1,1,1,1,1,1,1,1,1,1,1
1,1,1,1,1,10,10,10,10,10,1,1,1,5,5
1,1,1,10,10,10,10,10,10,10,10,1,1,1,1
1,1,10,10,10,10,10,10,10,10,1,1,1,1,1
1,1,10,10,10,10,10,10,10,1,1,1,10,1,1
1,10,10,10,10,10,10,10,1,1,1,10,10,10,1
1,10,10,10,10,10,10,1,1,1,10,10,10,10,1
1,10,10,10,10,10,10,18,1,10,10,10,10,10,1
1,10,10,10,10,10,10,10,10,10,10,10,10,10,1
1,10,10,10,10,10,10,10,10,10,10,10,10,10,1
1,1,10,10,10,10,10,10,10,10,10,10,10,1,1
1,1,10,10,10,10,10,10,10,10,10,10,10,1,1
1,1,1,10,10,10,10,10,10,10,10,10,1,1,1
1,1,1,1,1,10,10,10,10,10,1,1,1,1,1
1,1,1,1,1,1,1,1,1,1,1,1,1,1,1
1,1,1,1,1,1,1,1,1,1,1,1,1,1,1
1,1,1,1,1,1,1,1,1,1,1,1,1,1,1
1,1,1,1,1,10,10,10,10,10,1,1,1,5,5
1,1,1,10,10,10,10,10,10,10,10,1,1,1,1
1,1,10,10,10,10,10,10,10,10,1,1,1,1,1
1,1,10,10,10,10,10,10,10,1,1,1,10,1,1
1,10,10,10,10,10,10,10,1,1,1,10,10,10,1
1,10,10,10,10,10,10,1,1,1,10,10,10,10,1
1,10,10,10,10,10,10,18,1,10,10,10,10,10,1
1,10,10,10,10,10,10,10,10,10,10,10,10,10,1
1,10,10,10,10,10,10,10,10,10,10,10,10,10,1
1,1,10,10,10,10,10,10,10,10,10,10,10,1,1
1,1,10,10,10,10,10,10,10,10,10,10,10,1,1
1,1,1,10,10,10,10,10,10,10,10,10,1,1,1
1,1,1,1,1,10,10,10,10,10,1,1,1,1,1
1,1,1,1,1,1,1,1,1,1,1,1,1,1,1
endlayer

