weight=3
dimensionsToSpawnIn=overworld
embed_into_distance=2
random_height_offset=0,0
unacceptable_target_blocks=sand,flowing_water,water,flowing_lava,lava,ice,packed_ice,stained_hardened_clay-9,brick_block,double_stone_slab,stonebrick,red_sandstone,red_nether_brick,red_mushroom_block,brown_mushroom_block,planks,cobblestone,end_stone,obsidian,purpur_block,iron_bars,purpur_slab,purpur_pillar,netherrack,soul_sand,quartz_ore,stained_glass,glass
dimensions=28,19,12
allowable_overhang=0
max_leveling=2
leveling_buffer=-1
preventRotation=0
preserve_water=0
preserve_lava=0
uniqueMinDistance=4000
spawnMinDistance=0
spawnMaxDistance=0

rule1=0,100,preserveBlock
rule2=0,100,chisel:factory-1
rule3=0,100,chisel:factory-14
rule4=1,50,chisel:factory-1
rule5=0,100,iron_bars,iron_bars,iron_bars,iron_bars,air
rule6=0,100,minecraft:ladder-5,air
rule7=0,100,minecraft:dirt-0
rule8=0,100,water
rule9=1,90,minecraft:cobblestone_wall-0
rule10=0,100,monster_egg-4,monster_egg-2,monster_egg-2,monster_egg-2,monster_egg-3,stonebrick-2,stonebrick-1,stonebrick-0,stonebrick-0,stonebrick-0,stonebrick-2,stonebrick-1,stonebrick-0,stonebrick-0,stonebrick-0
rule11=2,100,minecraft:stone_button-2
rule12=2,100,minecraft:stone_button-3
rule13=2,100,minecraft:stone_button-4
rule14=2,100,minecraft:stone_button-1
rule15=0,100,minecraft:stone_slab-13
rule16=0,100,minecraft:double_stone_slab-5
rule17=0,100,minecraft:stone_slab-11
rule18=0,100,minecraft:stone_slab-3
rule19=0,100,minecraft:stone_slab-0

layer
1,1,1,1,1,1,1,1,1,1,1,1
1,1,1,2,2,2,2,1,1,1,1,1
1,1,2,2,2,2,2,2,1,1,1,1
1,1,2,2,2,2,2,2,1,1,1,1
1,1,2,2,2,2,2,2,1,3,1,1
1,1,2,2,2,2,2,2,1,1,1,1
1,1,1,2,2,2,2,1,1,1,3,1
1,1,1,1,1,1,1,1,1,1,1,1
1,1,1,1,1,1,1,1,1,1,1,3
1,1,1,1,1,1,1,1,1,3,1,1
1,1,1,4,2,2,2,1,1,1,1,1
1,1,4,2,2,2,2,2,1,1,1,1
1,1,2,2,2,2,2,2,1,1,1,1
1,1,2,2,2,2,2,2,1,1,1,1
1,1,2,2,2,2,2,2,1,1,1,1
1,1,1,2,2,2,2,1,1,1,1,1
1,1,1,5,6,5,1,1,1,1,1,1
1,1,1,5,1,5,1,1,1,1,1,1
1,1,1,1,1,1,1,1,1,3,3,1
endlayer

layer
1,1,1,1,1,1,1,1,1,1,1,1
1,1,1,2,2,2,2,1,1,1,1,1
1,1,2,2,2,2,2,2,1,1,1,1
1,1,2,2,2,2,2,2,1,1,1,1
1,1,2,2,2,2,2,2,1,3,1,1
1,1,2,2,2,2,2,2,1,1,1,1
1,1,1,2,2,2,2,1,1,1,3,1
1,1,1,1,1,1,1,1,1,1,1,1
1,1,1,1,1,1,1,1,1,1,1,3
1,1,1,1,1,1,1,1,1,3,1,1
1,1,1,4,2,2,2,1,1,1,1,1
1,1,4,2,2,2,2,2,1,1,1,1
1,1,2,2,2,2,2,2,1,1,1,1
1,1,2,2,2,2,2,2,1,1,1,1
1,1,2,2,2,2,2,2,1,1,1,1
1,1,1,2,2,2,2,1,1,1,1,1
1,1,1,5,6,5,1,1,1,1,1,1
1,1,1,5,1,5,1,1,1,1,1,1
1,1,1,1,1,1,1,1,1,3,3,1
endlayer

layer
1,1,1,1,1,1,1,1,1,1,1,1
1,1,1,2,2,2,2,1,1,1,1,1
1,1,2,7,7,7,7,2,1,1,1,1
1,1,2,7,7,7,7,2,1,1,1,1
1,1,2,7,7,7,7,2,1,3,1,1
1,1,2,7,7,7,7,2,1,1,1,1
1,1,1,2,2,2,2,1,1,1,3,1
1,1,1,1,1,1,1,1,1,1,1,1
1,1,1,1,1,1,1,1,1,1,1,3
1,1,1,1,1,1,1,1,1,3,1,1
1,1,1,4,4,2,2,1,1,1,1,1
1,1,4,1,1,1,7,2,1,1,1,1
1,1,4,1,1,7,7,2,1,1,1,1
1,1,2,1,7,7,7,2,1,1,1,1
1,1,2,1,7,7,7,2,1,1,1,1
1,1,1,2,2,2,2,1,1,1,1,1
1,1,1,5,6,5,1,1,1,1,1,1
1,1,1,5,1,5,1,1,1,1,1,1
1,1,1,1,1,1,1,1,1,3,3,1
endlayer

layer
1,1,1,1,1,1,1,1,1,1,1,1
1,1,1,2,2,2,2,1,1,1,1,1
1,1,2,7,7,7,7,2,1,1,1,1
1,1,2,8,8,7,7,2,1,1,1,1
1,1,2,8,8,8,7,2,1,3,1,1
1,1,2,7,7,8,8,2,1,1,1,1
1,1,1,2,2,2,2,1,1,1,3,1
1,1,1,1,1,1,1,1,1,1,1,1
1,1,1,1,1,1,1,1,1,1,1,3
1,1,1,1,1,1,1,1,1,3,1,1
1,1,1,4,4,2,2,1,1,1,1,1
1,1,4,1,1,1,1,2,1,1,1,1
1,1,4,1,1,1,1,2,1,1,1,1
1,1,4,1,1,1,7,2,1,1,1,1
1,1,2,1,1,7,7,2,1,1,1,1
1,1,1,2,2,2,2,1,1,1,1,1
1,1,1,5,6,5,1,1,1,1,1,1
1,1,1,5,5,5,1,1,1,1,1,1
1,1,1,1,1,1,1,1,1,9,5,1
endlayer

layer
1,1,1,1,1,1,1,1,1,1,1,1
1,1,1,2,2,2,2,1,1,1,1,1
1,1,2,8,8,8,7,2,1,1,1,1
1,1,2,8,8,8,8,2,1,1,1,1
1,1,2,8,8,8,8,2,1,3,1,1
1,1,2,7,8,8,8,2,1,1,1,1
1,1,1,2,2,2,2,1,1,1,3,1
1,1,1,1,1,1,1,1,1,1,1,1
1,1,1,1,1,1,1,1,1,1,1,3
1,1,1,1,1,1,1,1,1,3,1,1
1,1,1,4,2,2,2,1,1,1,1,1
1,1,4,1,1,1,1,2,1,1,1,1
1,1,4,1,1,1,1,2,1,1,1,1
1,1,4,1,1,1,1,2,1,1,1,1
1,1,2,1,1,1,1,2,1,1,1,1
1,1,1,2,2,2,2,1,1,1,1,1
1,1,1,5,6,5,1,1,1,1,1,1
1,1,1,5,5,5,1,1,1,1,1,1
1,1,1,1,1,1,1,1,1,5,1,1
endlayer

layer
1,1,1,1,1,1,1,1,1,1,1,1
1,1,1,2,2,2,2,1,1,1,1,1
1,1,2,8,8,8,8,2,1,1,1,1
1,1,2,8,8,8,8,2,1,1,1,1
1,1,2,8,8,8,8,2,1,3,1,1
1,1,2,8,8,8,8,2,1,1,1,1
1,1,1,2,2,2,2,1,1,1,3,1
1,1,1,1,10,10,1,1,1,1,1,1
1,1,1,1,10,10,1,1,1,1,1,3
1,1,1,1,10,10,1,1,1,3,1,1
1,1,1,2,2,2,2,1,1,1,1,1
1,1,4,1,1,1,1,2,1,1,1,1
1,1,2,1,1,1,1,2,1,1,1,1
1,1,2,1,1,1,1,2,1,1,1,1
1,1,2,1,1,1,1,2,1,1,1,1
1,1,1,2,2,2,2,1,1,1,1,1
1,1,1,5,6,5,1,1,1,1,1,1
1,1,1,5,5,5,1,1,1,1,1,1
1,1,1,1,1,1,1,1,1,1,1,1
endlayer

layer
1,1,1,1,1,1,1,1,1,1,1,1
1,1,1,2,2,2,2,1,1,1,1,1
1,1,2,8,8,8,8,2,1,1,1,1
1,1,2,8,8,8,8,2,1,1,1,1
1,1,2,8,8,8,8,2,1,3,1,1
1,1,2,8,8,8,8,2,1,1,1,1
1,1,1,2,2,2,2,1,1,1,3,1
1,1,1,1,1,1,1,1,1,1,1,1
1,1,1,1,1,1,1,1,1,3,3,3
1,1,1,1,1,1,1,1,1,3,1,1
1,1,1,2,2,2,2,1,1,1,1,1
1,1,2,1,1,1,1,2,1,1,1,1
1,1,2,1,1,1,1,2,1,1,1,1
1,1,2,1,1,1,1,2,1,1,1,1
1,1,2,1,1,1,1,2,1,1,1,1
1,1,1,2,2,2,2,1,1,1,1,1
1,1,1,5,6,5,1,1,1,1,1,1
1,1,1,5,5,5,1,1,1,1,1,1
1,1,1,1,1,1,1,1,1,1,1,1
endlayer

layer
1,1,1,1,1,1,1,1,1,1,1,1
1,1,1,2,2,2,4,1,1,1,1,1
1,1,2,1,1,1,1,2,1,1,1,1
1,1,2,1,1,1,1,2,1,1,1,1
1,1,2,1,1,1,1,2,1,3,1,1
1,1,2,1,1,1,1,2,1,1,1,1
1,1,1,2,2,2,2,1,1,1,3,1
1,1,1,1,1,1,1,1,1,1,1,1
1,1,1,1,1,1,1,1,1,1,1,3
1,1,1,1,1,1,1,1,1,1,1,1
1,1,1,2,2,2,2,1,1,1,1,1
1,1,2,1,1,1,1,2,1,1,1,1
1,1,2,1,1,1,1,2,1,1,1,1
1,1,2,1,1,1,1,2,1,1,1,1
1,1,2,1,1,1,1,2,1,1,1,1
1,1,1,2,2,2,2,1,1,1,1,1
1,1,1,5,6,5,1,1,1,1,1,1
1,1,1,5,5,5,1,1,1,1,1,1
1,1,1,1,1,1,1,1,1,1,1,1
endlayer

layer
1,1,1,1,1,1,1,1,1,1,1,1
1,1,1,2,2,4,4,1,1,1,1,1
1,1,2,1,1,1,1,4,1,1,1,1
1,1,2,1,1,1,1,2,1,1,1,1
1,1,2,1,1,1,1,2,1,3,1,1
1,1,2,1,1,1,1,2,1,1,1,1
1,1,1,2,2,2,2,1,1,1,3,1
1,1,1,1,1,1,1,1,1,1,1,1
1,1,1,1,1,1,1,1,1,1,1,3
1,1,1,1,1,1,1,1,1,1,1,1
1,1,1,2,2,2,2,1,1,1,1,1
1,1,2,1,1,1,1,2,1,1,1,1
1,1,2,1,1,1,1,2,1,1,1,1
1,1,2,1,1,1,1,2,1,1,1,1
1,1,2,1,1,1,1,2,1,1,1,1
1,1,1,2,2,2,2,1,1,1,1,1
1,1,1,5,6,5,1,1,1,1,1,1
1,1,1,5,5,5,1,1,1,1,1,1
1,1,1,1,1,1,1,1,1,1,1,1
endlayer

layer
1,1,1,1,1,1,1,1,1,1,1,1
1,1,1,2,2,2,4,1,1,1,1,1
1,1,2,1,1,1,1,4,1,1,1,1
1,1,2,1,1,1,1,2,1,1,1,1
1,1,2,1,1,1,1,2,1,3,1,1
1,1,2,1,1,1,1,2,1,1,1,1
1,1,1,2,2,2,2,1,1,1,3,1
1,1,1,1,1,1,1,1,1,1,3,1
1,1,1,1,1,1,1,1,1,1,3,3
1,1,1,1,1,1,1,1,1,1,1,1
1,1,1,2,2,2,2,1,1,1,1,1
1,1,2,1,1,1,1,2,1,1,1,1
1,1,2,1,1,1,1,2,1,1,1,1
1,1,2,1,1,1,1,2,1,1,1,1
1,1,2,1,1,1,1,2,1,1,1,1
1,1,1,2,2,2,2,1,1,1,1,1
1,1,1,5,6,5,1,1,1,1,1,1
1,1,1,5,5,5,1,1,1,1,1,1
1,1,1,1,1,1,1,1,1,1,1,1
endlayer

layer
1,1,1,11,1,1,1,1,1,1,1,1
1,1,1,2,2,4,4,1,1,1,1,1
1,12,2,1,1,1,1,4,1,1,1,1
1,1,2,1,1,1,1,4,1,1,1,1
1,1,2,1,1,1,1,2,1,3,1,1
1,12,2,1,1,1,1,2,13,1,1,1
1,1,1,2,2,2,2,1,1,1,3,1
1,1,1,14,10,10,14,1,1,1,1,1
1,1,1,1,10,10,1,1,1,1,1,1
1,1,1,11,10,10,11,1,1,1,1,1
1,1,1,2,2,2,2,1,1,1,1,1
1,12,2,1,1,1,1,2,13,1,1,1
1,1,2,1,1,1,1,2,1,1,1,1
1,1,2,1,1,1,1,4,1,1,1,1
1,12,2,1,1,1,1,2,13,1,1,1
1,1,1,2,2,2,2,1,1,1,1,1
1,1,1,5,6,5,14,1,1,1,1,1
1,1,1,5,5,5,1,1,1,1,1,1
1,1,1,1,1,1,1,1,1,1,1,1
endlayer

layer
1,1,1,1,1,1,1,1,1,1,1,1
1,1,1,2,2,2,4,1,1,1,1,1
1,1,2,1,1,1,1,4,1,1,1,1
2,3,2,1,1,1,1,2,1,1,1,1
2,3,2,1,1,1,1,2,1,3,1,1
1,1,2,1,1,1,1,2,1,3,3,1
1,1,1,2,2,2,2,1,1,1,3,1
1,1,1,1,1,1,1,1,1,1,1,1
1,1,1,1,1,1,1,1,1,1,1,1
1,1,1,1,1,1,1,1,1,1,1,1
1,1,1,2,2,2,2,1,1,1,1,1
1,1,2,1,1,1,1,2,1,1,1,1
2,3,2,1,1,1,1,4,1,1,1,1
2,3,2,1,1,1,1,4,1,1,1,1
1,1,2,1,1,1,1,4,1,1,1,1
1,1,1,2,2,2,2,1,1,1,1,1
1,1,1,5,6,5,1,1,1,1,1,1
1,1,1,5,5,5,1,1,1,1,1,1
1,1,1,1,1,1,1,1,1,1,1,1
endlayer

layer
1,1,1,1,1,1,1,1,1,1,1,1
1,1,1,2,2,2,4,1,1,1,1,1
2,3,2,1,1,1,1,2,1,1,1,1
5,1,1,1,1,1,1,2,1,1,1,1
5,1,1,1,1,1,1,2,1,1,1,1
2,3,2,1,1,1,1,2,1,1,1,1
1,1,1,2,2,2,2,1,1,1,3,1
1,1,1,1,1,1,1,1,1,1,1,1
1,1,1,1,1,1,1,1,1,1,1,1
1,1,1,1,1,1,1,1,1,1,1,1
1,1,1,2,2,2,2,1,1,1,1,1
2,3,2,1,1,1,1,2,1,1,1,1
5,1,1,1,1,1,1,2,1,1,1,1
5,1,1,1,1,1,1,4,1,1,1,1
2,3,2,1,1,1,1,4,1,1,1,1
1,1,1,2,2,2,4,1,1,1,1,1
1,1,1,5,6,5,1,1,1,1,1,1
1,1,1,5,5,5,1,1,1,1,1,1
1,1,1,1,1,1,1,1,1,1,1,1
endlayer

layer
1,1,1,1,1,1,1,1,1,1,1,1
1,1,1,2,2,2,2,1,1,1,1,1
2,3,2,1,1,1,1,2,1,1,1,1
5,1,1,1,1,1,1,2,1,1,1,1
5,1,1,1,1,1,1,2,1,1,1,1
2,3,2,1,1,1,1,2,1,1,1,1
1,1,1,2,2,2,2,1,1,1,3,1
1,1,1,1,1,1,1,1,1,1,1,1
1,1,1,1,1,1,1,1,1,1,1,1
1,1,1,1,1,1,1,1,1,1,1,1
1,1,1,2,2,2,2,1,1,1,1,1
2,3,2,1,1,1,1,2,1,1,1,1
5,1,1,1,1,1,1,2,1,1,1,1
5,1,1,1,1,1,1,4,1,1,1,1
2,3,2,1,1,1,1,4,1,1,1,1
1,1,1,2,2,2,4,1,1,1,1,1
1,1,1,5,6,5,1,1,1,1,1,1
1,1,1,5,5,5,1,1,1,1,1,1
1,1,1,1,1,1,1,1,1,1,1,1
endlayer

layer
1,1,1,1,1,1,1,1,1,1,1,1
1,1,1,2,2,2,2,1,1,1,1,1
1,1,2,1,1,1,1,2,1,1,1,1
2,3,2,1,1,1,1,2,1,1,1,1
2,3,2,1,1,1,1,2,1,1,1,1
1,1,2,1,1,1,1,2,1,1,1,1
1,1,1,2,2,2,2,1,1,1,3,1
1,1,1,1,1,1,1,1,1,1,1,1
1,1,1,1,1,1,1,1,1,1,1,1
1,1,1,1,1,1,1,1,1,1,1,1
1,1,1,2,2,2,2,1,1,1,1,1
1,1,2,1,1,1,1,2,1,1,1,1
2,3,2,1,1,1,1,2,1,1,1,1
2,3,2,1,1,1,1,2,1,1,1,1
1,1,2,1,1,1,1,4,1,1,1,1
1,1,1,2,2,2,2,1,1,1,1,1
1,1,1,5,6,5,1,1,1,1,1,1
1,1,1,5,5,5,1,1,1,1,1,1
1,1,1,1,1,1,1,1,1,1,1,1
endlayer

layer
1,1,1,11,1,1,11,1,1,1,1,1
1,1,1,2,2,2,2,1,1,1,1,1
1,12,2,1,1,1,1,2,13,1,1,1
1,1,2,1,1,1,1,2,5,1,1,1
1,1,2,1,1,1,1,2,5,1,1,1
1,12,2,1,1,1,1,2,13,1,1,1
1,1,1,2,2,2,2,1,1,1,3,1
1,1,1,14,10,10,14,1,1,1,1,1
1,1,1,1,10,10,1,1,1,1,1,1
1,1,1,11,10,10,11,1,1,1,1,1
1,1,1,2,2,2,2,1,1,1,1,1
1,12,2,1,1,1,1,2,13,1,1,1
1,1,2,1,1,1,1,2,1,1,1,1
1,1,2,1,1,1,1,2,1,1,1,1
1,12,2,1,1,1,1,2,13,1,1,1
1,1,1,2,2,2,2,1,1,1,1,1
1,1,1,5,6,5,14,1,1,1,1,1
1,1,1,5,5,5,1,1,1,1,1,1
1,1,1,1,1,1,1,1,1,1,1,1
endlayer

layer
1,1,1,1,1,1,1,1,1,1,1,1
1,1,1,2,2,2,2,1,1,1,1,1
1,1,2,1,1,1,1,2,1,1,1,1
1,1,4,1,1,1,1,2,5,1,1,1
1,1,4,1,1,1,1,2,5,1,1,1
1,1,4,1,1,1,1,2,1,1,1,1
1,1,1,2,2,4,2,1,1,1,3,1
1,1,1,1,1,1,1,1,1,1,1,1
1,1,1,1,1,1,1,1,1,1,1,1
1,1,1,1,1,1,1,1,1,1,1,1
1,1,1,2,2,2,2,1,1,1,1,1
1,1,2,1,1,1,1,2,1,1,1,1
1,1,2,1,1,1,1,2,5,1,1,1
1,1,2,1,1,1,1,2,1,1,1,1
1,1,2,1,1,1,1,2,5,1,1,1
1,1,1,2,2,2,2,1,1,1,1,1
1,1,1,5,6,5,1,1,1,1,1,1
1,1,1,5,5,5,1,1,1,1,1,1
1,1,1,1,1,1,1,1,1,1,1,1
endlayer

layer
1,1,1,1,1,1,1,1,1,1,1,1
1,1,1,2,2,2,2,1,1,1,1,1
1,1,4,1,1,1,1,2,1,1,1,1
1,1,2,1,1,1,1,2,1,1,1,1
1,1,4,1,1,1,1,2,1,1,1,1
1,1,4,1,1,1,1,2,1,1,1,1
1,1,1,4,4,2,2,1,1,1,3,1
1,1,1,1,1,1,1,1,1,1,1,1
1,1,1,1,1,1,1,1,1,1,1,1
1,1,1,1,1,1,1,1,1,1,1,1
1,1,1,2,2,2,2,1,1,1,1,1
1,1,2,1,1,1,1,2,1,1,1,1
1,1,2,1,1,1,1,2,5,1,1,1
1,1,2,1,1,1,1,2,1,1,1,1
1,1,2,1,1,1,1,2,5,1,1,1
1,1,1,2,2,2,2,1,1,1,1,1
1,1,1,5,6,5,1,1,1,1,1,1
1,1,1,5,5,5,1,1,1,1,1,1
1,1,1,1,1,1,1,1,1,1,1,1
endlayer

layer
1,1,1,1,1,1,1,1,1,1,1,1
1,1,1,2,2,2,2,1,1,1,1,1
1,1,2,1,1,1,1,2,1,1,1,1
1,1,2,1,1,1,1,2,1,1,1,1
1,1,2,1,1,1,1,2,1,1,1,1
1,1,2,1,1,1,1,2,1,1,1,1
1,1,1,4,2,2,2,1,1,1,3,1
1,1,1,1,1,1,1,1,1,1,1,1
1,1,1,1,1,1,1,1,1,1,1,1
1,1,1,1,1,1,1,1,1,1,1,1
1,1,1,2,2,2,2,1,1,1,1,1
1,1,2,1,1,1,1,2,1,1,1,1
1,1,2,1,1,1,1,2,1,1,1,1
1,1,2,1,1,1,1,2,1,1,1,1
1,1,2,1,1,1,1,2,1,1,1,1
1,1,1,2,2,2,2,1,1,1,1,1
1,1,1,5,6,5,1,1,1,1,1,1
1,1,1,5,5,5,1,1,1,1,1,1
1,1,1,1,1,1,1,1,1,1,1,1
endlayer

layer
1,1,1,11,1,1,11,1,1,1,1,1
1,1,1,2,2,2,2,1,1,1,1,1
1,12,2,1,1,1,1,2,13,1,1,1
1,1,2,1,1,1,1,2,1,1,1,1
1,1,2,1,1,1,1,2,1,1,1,1
1,12,2,1,1,1,1,2,13,1,1,1
1,1,1,2,2,2,2,1,1,1,3,1
1,1,1,9,1,1,9,1,1,1,1,1
1,1,1,9,1,1,9,1,1,1,1,1
1,1,1,9,1,1,9,1,1,1,1,1
1,1,1,2,2,2,2,1,1,1,1,1
1,12,2,1,1,1,1,2,13,1,1,1
1,1,2,1,1,1,1,2,1,1,1,1
1,1,2,1,1,1,1,2,1,1,1,1
1,12,2,1,1,1,1,2,13,1,1,1
1,1,1,2,2,2,2,1,1,1,1,1
1,1,1,5,6,5,14,1,1,1,1,1
1,1,1,5,5,5,1,1,1,1,1,1
1,1,1,1,1,1,1,1,1,1,1,1
endlayer

layer
1,1,15,15,16,16,15,15,1,1,1,1
1,15,15,2,2,2,2,15,15,1,1,1
1,15,2,2,2,2,2,2,15,1,1,1
1,15,2,2,2,2,2,2,16,1,1,1
1,16,2,2,2,2,2,2,16,1,1,1
1,15,2,2,2,2,2,2,15,1,1,1
1,15,15,2,2,2,2,15,15,1,3,1
1,15,15,15,10,10,15,15,15,1,1,1
1,15,15,15,10,10,15,15,15,1,1,1
1,15,15,15,10,10,15,15,15,1,1,1
1,15,15,2,2,2,2,15,15,1,1,1
1,15,2,2,2,2,2,2,15,1,1,1
1,16,2,2,2,2,2,2,16,1,1,1
1,16,2,2,2,2,2,2,16,1,1,1
1,15,2,2,2,2,2,2,15,1,1,1
1,15,15,2,2,2,2,15,15,1,1,1
1,1,15,16,6,16,15,15,1,1,1,1
1,1,1,5,5,5,1,1,1,1,1,1
1,1,1,1,1,1,1,1,1,1,1,1
endlayer

layer
1,1,5,5,5,5,5,5,1,1,1,1
1,5,5,1,1,1,1,5,5,1,1,1
1,5,1,1,1,1,1,1,5,1,1,1
1,5,1,1,1,1,1,1,5,1,1,1
1,5,1,1,1,1,1,1,5,1,1,1
1,5,1,10,10,10,10,1,5,1,1,1
1,5,1,10,1,1,10,1,5,1,3,1
1,5,1,10,1,1,10,1,5,1,1,1
1,5,1,10,1,1,10,1,5,1,1,1
1,5,1,10,1,1,10,1,5,1,1,1
1,5,1,10,10,1,10,1,5,1,1,1
1,5,1,1,1,1,1,1,5,1,1,1
1,5,1,1,1,1,1,1,5,1,1,1
1,5,1,1,1,1,1,1,5,1,1,1
1,5,1,1,1,1,1,1,5,1,1,1
1,5,5,1,1,1,1,5,5,1,1,1
1,1,5,5,1,5,5,5,1,1,1,1
1,1,1,5,5,5,1,1,1,1,1,1
1,1,1,1,1,1,1,1,1,1,1,1
endlayer

layer
1,1,1,1,1,1,1,1,1,1,1,1
1,1,1,1,1,1,1,1,1,1,1,1
1,1,1,1,1,1,1,1,1,1,1,1
1,1,1,1,1,1,1,1,1,1,1,1
1,1,1,1,1,1,1,1,1,1,1,1
1,1,1,10,10,10,10,1,1,1,1,1
1,1,1,10,1,1,10,1,1,1,3,1
1,1,1,10,1,1,10,1,1,1,1,1
1,1,1,10,1,1,10,1,1,1,1,1
1,1,1,10,1,12,10,1,1,1,1,1
1,1,1,10,10,1,10,1,1,1,1,1
1,1,1,1,1,1,1,1,1,1,1,1
1,1,1,1,1,1,1,1,1,1,1,1
1,1,1,1,1,1,1,1,1,1,1,1
1,1,1,1,1,1,1,1,1,1,1,1
1,1,1,1,1,1,1,1,1,1,1,1
1,1,1,1,1,1,1,1,1,1,1,1
1,1,1,1,1,1,1,1,1,1,1,1
1,1,1,1,1,1,1,1,1,1,1,1
endlayer

layer
1,1,1,1,1,1,1,1,1,1,1,1
1,1,1,1,1,1,1,1,1,1,1,1
1,1,1,1,1,1,1,1,1,1,1,1
1,1,1,1,1,1,1,1,1,1,1,1
1,1,1,1,1,1,1,1,1,1,1,1
1,1,1,10,10,10,10,1,1,1,1,1
1,1,1,10,17,17,10,3,3,3,3,1
1,1,1,10,17,17,10,1,1,1,1,1
1,1,1,10,17,17,10,1,1,1,1,1
1,1,1,10,17,17,10,1,1,1,1,1
1,1,1,10,10,10,10,1,1,1,1,1
1,1,1,1,1,1,1,1,1,1,1,1
1,1,1,1,1,1,1,1,1,1,1,1
1,1,1,1,1,1,1,1,1,1,1,1
1,1,1,1,1,1,1,1,1,1,1,1
1,1,1,1,1,1,1,1,1,1,1,1
1,1,1,1,1,1,1,1,1,1,1,1
1,1,1,1,1,1,1,1,1,1,1,1
1,1,1,1,1,1,1,1,1,1,1,1
endlayer

layer
1,1,1,1,1,1,1,1,1,1,1,1
1,1,1,1,1,1,1,1,1,1,1,1
1,1,1,1,1,1,1,1,1,1,1,1
1,1,1,1,1,1,1,1,1,1,1,1
1,1,1,1,1,1,1,1,1,1,1,1
1,1,1,18,18,18,18,1,1,1,1,1
1,1,1,18,19,19,18,1,1,1,1,1
1,1,1,18,3,19,18,1,1,1,1,1
1,1,1,18,3,19,18,1,1,1,1,1
1,1,1,18,19,19,18,1,1,1,1,1
1,1,1,18,18,18,18,1,1,1,1,1
1,1,1,1,1,1,1,1,1,1,1,1
1,1,1,1,1,1,1,1,1,1,1,1
1,1,1,1,1,1,1,1,1,1,1,1
1,1,1,1,1,1,1,1,1,1,1,1
1,1,1,1,1,1,1,1,1,1,1,1
1,1,1,1,1,1,1,1,1,1,1,1
1,1,1,1,1,1,1,1,1,1,1,1
1,1,1,1,1,1,1,1,1,1,1,1
endlayer

layer
1,1,1,1,1,1,1,1,1,1,1,1
1,1,1,1,1,1,1,1,1,1,1,1
1,1,1,1,1,1,1,1,1,1,1,1
1,1,1,1,1,1,1,1,1,1,1,1
1,1,1,1,1,1,1,1,1,1,1,1
1,1,1,1,1,1,1,1,1,1,1,1
1,1,1,1,1,1,1,1,1,1,1,1
1,1,1,1,9,1,1,1,1,1,1,1
1,1,1,1,9,1,1,1,1,1,1,1
1,1,1,1,1,1,1,1,1,1,1,1
1,1,1,1,1,1,1,1,1,1,1,1
1,1,1,1,1,1,1,1,1,1,1,1
1,1,1,1,1,1,1,1,1,1,1,1
1,1,1,1,1,1,1,1,1,1,1,1
1,1,1,1,1,1,1,1,1,1,1,1
1,1,1,1,1,1,1,1,1,1,1,1
1,1,1,1,1,1,1,1,1,1,1,1
1,1,1,1,1,1,1,1,1,1,1,1
1,1,1,1,1,1,1,1,1,1,1,1
endlayer

layer
1,1,1,1,1,1,1,1,1,1,1,1
1,1,1,1,1,1,1,1,1,1,1,1
1,1,1,1,1,1,1,1,1,1,1,1
1,1,1,1,1,1,1,1,1,1,1,1
1,1,1,1,1,1,1,1,1,1,1,1
1,1,1,1,1,1,1,1,1,1,1,1
1,1,1,1,1,1,1,1,1,1,1,1
1,1,1,1,9,1,1,1,1,1,1,1
1,1,1,1,9,1,1,1,1,1,1,1
1,1,1,1,1,1,1,1,1,1,1,1
1,1,1,1,1,1,1,1,1,1,1,1
1,1,1,1,1,1,1,1,1,1,1,1
1,1,1,1,1,1,1,1,1,1,1,1
1,1,1,1,1,1,1,1,1,1,1,1
1,1,1,1,1,1,1,1,1,1,1,1
1,1,1,1,1,1,1,1,1,1,1,1
1,1,1,1,1,1,1,1,1,1,1,1
1,1,1,1,1,1,1,1,1,1,1,1
1,1,1,1,1,1,1,1,1,1,1,1
endlayer

layer
1,1,1,1,1,1,1,1,1,1,1,1
1,1,1,1,1,1,1,1,1,1,1,1
1,1,1,1,1,1,1,1,1,1,1,1
1,1,1,1,1,1,1,1,1,1,1,1
1,1,1,1,1,1,1,1,1,1,1,1
1,1,1,1,1,1,1,1,1,1,1,1
1,1,1,1,1,1,1,1,1,1,1,1
1,1,1,1,9,1,1,1,1,1,1,1
1,1,1,1,9,1,1,1,1,1,1,1
1,1,1,1,1,1,1,1,1,1,1,1
1,1,1,1,1,1,1,1,1,1,1,1
1,1,1,1,1,1,1,1,1,1,1,1
1,1,1,1,1,1,1,1,1,1,1,1
1,1,1,1,1,1,1,1,1,1,1,1
1,1,1,1,1,1,1,1,1,1,1,1
1,1,1,1,1,1,1,1,1,1,1,1
1,1,1,1,1,1,1,1,1,1,1,1
1,1,1,1,1,1,1,1,1,1,1,1
1,1,1,1,1,1,1,1,1,1,1,1
endlayer