weight=6
dimensionsToSpawnIn=overworld
embed_into_distance=1
random_height_offset=0,0
unacceptable_target_blocks=sand,flowing_water,water,flowing_lava,lava,ice,packed_ice,stained_hardened_clay-9,brick_block,double_stone_slab,stonebrick,red_sandstone,red_nether_brick,red_mushroom_block,brown_mushroom_block,planks,cobblestone,end_stone,obsidian,purpur_block,iron_bars,purpur_slab,purpur_pillar,netherrack,soul_sand,quartz_ore,stained_glass,glass
dimensions=7,12,14
allowable_overhang=0
max_leveling=1
leveling_buffer=-1
preventRotation=0
preserve_water=0
preserve_lava=0
preserve_plants=0
uniqueMinDistance=0
spawnMinDistance=0
spawnMaxDistance=0

rule1=0,100,preserveBlock
rule2=0,100,minecraft:stone_stairs-2
rule3=0,100,minecraft:stone_stairs-0
rule4=0,100,minecraft:brick_block-0
rule5=0,100,minecraft:stone_stairs-3
rule6=0,100,minecraft:stone_slab-4
rule7=0,100,minecraft:brick_stairs-0
rule8=0,100,minecraft:brick_stairs-3
rule9=0,100,minecraft:brick_stairs-2
rule10=0,100,minecraft:stone_slab-12
rule11=0,100,minecraft:brick_stairs-1
rule12=0,100,minecraft:vine-8
rule13=0,100,minecraft:vine-12
rule14=0,100,minecraft:brick_stairs-4
rule15=0,100,minecraft:brick_stairs-7
rule16=0,100,minecraft:brick_stairs-6
rule17=0,100,minecraft:brick_stairs-5
rule18=0,100,minecraft:web-0
rule19=0,100,minecraft:stone_stairs-1
rule20=0,100,minecraft:vine-2
rule21=0,100,minecraft:cobblestone-0

layer
1,1,1,1,1,1,1,1,1,1,21,1,1,1
1,1,1,1,1,1,21,21,1,1,21,21,1,1
1,1,1,1,1,21,21,21,21,21,1,21,21,1
1,1,1,1,21,1,1,1,1,1,1,1,21,1
1,1,1,21,21,1,1,1,1,1,2,1,21,1
1,1,1,21,21,1,21,21,21,1,1,1,21,1
1,1,1,1,21,1,21,1,1,1,1,1,21,1
1,1,21,21,1,1,1,1,1,1,1,1,21,1
1,21,1,1,1,1,1,1,1,1,1,1,21,1
1,21,1,1,1,1,1,1,1,1,1,1,21,1
1,1,21,21,1,21,21,21,1,21,21,21,1,1
1,1,1,1,1,1,1,1,1,1,1,1,1,1
endlayer

layer
1,1,1,1,1,1,1,1,1,1,2,1,1,1
1,1,1,1,1,1,3,3,1,1,3,3,1,1
1,1,1,1,1,4,4,4,4,4,1,4,4,1
1,1,1,1,4,1,1,1,1,1,1,1,4,1
1,1,1,5,4,1,1,1,1,1,2,1,4,1
1,1,1,5,4,1,3,3,3,1,1,1,4,1
1,1,1,1,4,1,5,1,1,1,1,1,6,1
1,1,4,4,1,1,1,1,1,1,1,1,7,1
1,4,1,1,1,1,1,1,1,1,1,1,4,1
1,4,1,1,1,1,1,1,1,1,1,1,4,1
1,1,4,6,1,8,4,4,1,4,4,4,1,1
1,1,1,1,1,1,1,1,1,1,1,1,1,1
endlayer

layer
1,1,1,1,1,1,1,1,1,1,1,1,1,1
1,1,1,1,1,1,1,1,1,1,1,1,1,1
1,1,1,1,1,4,6,8,10,4,1,9,4,1
1,1,1,1,4,1,1,1,1,1,1,1,4,1
1,1,1,1,6,1,1,1,1,1,1,1,4,1
1,1,1,1,7,1,1,1,1,12,1,1,11,1
1,1,1,1,4,1,1,1,13,1,1,1,1,1
1,1,4,9,1,1,1,1,1,1,1,1,1,1
1,11,1,1,1,1,1,1,1,1,1,1,7,1
1,14,1,1,1,1,1,1,1,1,1,1,4,1
1,1,9,1,1,15,4,9,1,9,6,4,1,1
1,1,1,1,1,1,1,1,1,1,1,1,1,1
endlayer

layer
1,1,1,1,1,1,1,1,1,1,1,1,1,1
1,1,1,1,5,3,1,1,1,1,1,1,3,3
1,1,1,3,5,4,16,10,15,9,6,1,4,2
1,1,1,5,4,1,1,1,1,1,1,1,4,2
1,1,1,1,17,1,1,1,1,1,1,1,4,2
1,1,1,1,14,1,1,1,1,12,1,1,17,1
1,5,3,1,4,1,1,12,13,1,1,1,1,1
3,5,6,1,1,1,1,1,1,1,1,1,1,1
5,6,1,1,1,1,1,1,1,1,1,1,14,1
5,9,1,1,1,1,1,1,1,1,1,18,6,2
19,5,16,10,15,10,15,10,6,4,15,4,2,19
1,19,19,1,1,1,1,1,1,19,1,19,19,1
endlayer

layer
1,1,1,1,1,1,1,1,1,1,1,1,1,1
1,1,1,1,1,1,1,1,1,1,1,1,1,1
1,1,1,1,1,5,3,3,3,3,1,1,2,1
1,1,1,1,5,3,10,1,1,1,1,1,2,1
1,1,1,1,5,10,1,1,1,1,1,1,2,1
1,1,1,1,5,1,1,1,1,12,1,1,2,1
1,1,1,1,5,1,1,12,13,1,1,1,2,1
1,1,3,1,3,4,1,1,1,1,1,1,6,1
1,3,5,4,4,4,1,1,20,1,1,18,2,1
1,1,1,4,4,4,1,1,1,1,18,19,2,1
1,1,19,19,19,19,19,19,19,19,19,2,1,1
1,1,1,1,1,1,1,1,1,1,1,1,1,1
endlayer

layer
1,1,1,1,1,1,1,1,1,1,1,1,1,1
1,1,1,1,1,1,1,1,1,1,1,1,1,1
1,1,1,1,1,1,1,1,1,1,1,1,1,1
1,1,1,1,1,1,3,3,3,3,3,2,1,1
1,1,1,1,1,3,5,1,1,1,1,2,1,1
1,1,1,1,1,5,1,1,1,12,1,2,1,1
1,1,1,1,1,5,1,12,13,1,1,2,1,1
1,1,1,1,1,5,1,1,1,1,1,2,1,1
1,1,1,3,3,5,1,1,20,1,2,19,1,1
1,1,1,19,19,19,19,19,19,19,19,1,1,1
1,1,1,1,1,1,1,1,1,1,1,1,1,1
1,1,1,1,1,1,1,1,1,1,1,1,1,1
endlayer

layer
1,1,1,1,1,1,1,1,1,1,1,1,1,1
1,1,1,1,1,1,1,1,1,1,1,1,1,1
1,1,1,1,1,1,1,1,1,1,1,1,1,1
1,1,1,1,1,1,1,1,1,1,1,1,1,1
1,1,1,1,1,1,1,1,1,3,2,1,1,1
1,1,1,1,1,1,1,1,1,12,2,1,1,1
1,1,1,1,1,1,1,12,13,21,2,1,1,1
1,1,1,1,1,1,5,21,21,21,19,1,1,1
1,1,1,1,1,1,5,19,20,19,1,1,1,1
1,1,1,1,1,1,1,1,1,1,1,1,1,1
1,1,1,1,1,1,1,1,1,1,1,1,1,1
1,1,1,1,1,1,1,1,1,1,1,1,1,1
endlayer

