weight=6
dimensionsToSpawnIn=overworld
embed_into_distance=1
random_height_offset=0,0
unacceptable_target_blocks=sand,flowing_water,water,flowing_lava,lava,ice,packed_ice,stained_hardened_clay-9,brick_block,double_stone_slab,stonebrick,red_sandstone,red_nether_brick,red_mushroom_block,brown_mushroom_block,planks,cobblestone,end_stone,obsidian,purpur_block,iron_bars,purpur_slab,purpur_pillar,netherrack,soul_sand,quartz_ore,stained_glass,glass
dimensions=8,14,8
allowable_overhang=0
max_leveling=1
leveling_buffer=-1
preventRotation=0
preserve_water=0
preserve_lava=0
preserve_plants=0
uniqueMinDistance=0
spawnMinDistance=0
spawnMaxDistance=0

rule1=0,100,preserveBlock
rule2=0,100,minecraft:stone_stairs-0
rule3=0,100,minecraft:brick_block-0
rule4=0,100,minecraft:jungle_fence-0
rule5=0,100,minecraft:dark_oak_fence-0
rule6=0,30,minecraft:brick_block-0
rule7=0,100,minecraft:vine-8
rule8=0,100,minecraft:vine-5
rule9=0,100,minecraft:iron_bars-0
rule10=0,100,minecraft:web-0
rule11=0,100,minecraft:vine-2
rule12=0,100,minecraft:stone_stairs-3
rule13=0,100,chisel:planks-dark-oak-13
rule14=0,100,minecraft:vine-1

layer
1,1,1,1,1,1,1,1
1,3,3,1,3,3,1,1
1,3,3,1,3,3,3,1
1,3,3,3,1,1,3,1
1,3,3,3,1,3,3,3
1,3,3,1,1,1,3,3
1,3,1,1,1,1,1,3
1,3,1,1,1,1,1,1
1,3,1,1,1,1,1,3
1,3,1,1,1,1,3,3
1,3,1,1,1,1,1,1
1,3,1,1,1,1,3,1
3,3,1,1,1,3,1,1
3,3,3,3,3,1,1,1
endlayer

layer
1,1,1,1,1,1,1,1
1,4,3,1,3,2,1,1
1,3,6,1,5,3,3,1
1,3,6,6,1,1,3,1
1,3,6,6,1,7,3,5
1,3,6,1,1,1,8,3
1,3,1,1,1,1,1,3
1,6,1,1,1,1,1,1
1,3,1,1,1,1,1,3
1,6,1,1,1,1,3,3
1,3,1,1,1,1,1,1
1,3,1,1,1,1,3,1
6,3,1,1,1,3,1,1
6,6,3,3,6,1,1,1
endlayer

layer
1,1,1,1,1,1,1,1
1,3,9,1,3,1,1,1
1,3,10,1,1,1,3,1
1,3,6,1,1,1,5,1
1,3,1,1,1,7,9,5
1,9,1,1,1,1,8,3
1,1,1,1,1,1,1,6
1,1,1,1,1,1,1,1
1,6,1,1,1,1,1,6
1,1,1,1,1,1,1,6
1,3,1,1,1,1,1,1
1,1,1,1,1,1,3,1
1,3,1,1,1,3,1,1
1,6,3,6,1,1,1,1
endlayer

layer
1,1,1,1,1,1,1,1
1,3,6,6,3,1,1,1
1,3,10,1,1,1,3,1
1,1,1,1,1,1,5,1
1,3,1,1,1,7,3,5
1,3,1,1,1,1,8,3
1,3,1,1,1,1,1,11
1,3,1,1,1,1,1,1
1,3,1,1,1,1,1,1
1,3,1,1,1,1,1,1
1,3,1,1,1,1,1,1
1,3,1,1,1,1,6,1
1,3,1,1,1,3,1,1
1,1,1,1,1,1,1,1
endlayer

layer
2,2,2,2,1,1,1,1
12,5,5,5,1,1,1,1
12,5,13,13,13,13,1,1
12,5,13,5,5,1,1,1
12,5,13,13,1,7,1,1
12,3,13,13,13,13,14,9
12,13,13,13,13,1,1,1
12,13,13,13,5,1,1,1
12,13,13,5,1,1,1,1
12,13,13,13,13,13,1,1
1,1,1,1,1,1,1,1
1,1,1,1,1,1,1,1
1,9,1,1,1,6,1,1
1,1,1,1,1,1,1,1
endlayer

layer
1,1,1,1,1,1,1,1
1,12,2,2,2,1,1,1
1,12,5,1,1,1,1,1
1,12,5,1,1,1,1,1
1,12,5,1,1,1,1,1
1,1,5,1,1,1,1,1
1,12,5,1,1,1,1,1
1,12,5,1,1,1,1,1
1,1,1,1,1,1,1,1
1,1,1,1,1,1,1,1
1,1,1,1,1,1,1,1
1,1,1,1,1,1,1,1
1,1,1,1,1,1,1,1
1,1,1,1,1,1,1,1
endlayer

layer
1,1,1,1,1,1,1,1
1,1,1,1,1,1,1,1
1,1,12,2,1,1,1,1
1,1,12,1,1,1,1,1
1,1,12,1,1,1,1,1
1,1,12,1,1,1,1,1
1,1,12,1,1,1,1,1
1,1,12,1,1,1,1,1
1,1,1,1,1,1,1,1
1,1,1,1,1,1,1,1
1,1,1,1,1,1,1,1
1,1,1,1,1,1,1,1
1,1,1,1,1,1,1,1
1,1,1,1,1,1,1,1
endlayer

layer
1,1,1,1,1,1,1,1
1,1,1,1,1,1,1,1
1,1,1,1,1,1,1,1
1,1,1,12,2,1,1,1
1,1,1,12,1,1,1,1
1,1,1,12,1,1,1,1
1,1,1,1,1,1,1,1
1,1,1,1,1,1,1,1
1,1,1,1,1,1,1,1
1,1,1,1,1,1,1,1
1,1,1,1,1,1,1,1
1,1,1,1,1,1,1,1
1,1,1,1,1,1,1,1
1,1,1,1,1,1,1,1
endlayer

