weight=6
dimensionsToSpawnIn=overworld
embed_into_distance=1
random_height_offset=0,0
unacceptable_target_blocks=sand,flowing_water,water,flowing_lava,lava,ice,packed_ice,stained_hardened_clay-9,brick_block,double_stone_slab,stonebrick,red_sandstone,red_nether_brick,red_mushroom_block,brown_mushroom_block,planks,cobblestone,end_stone,obsidian,purpur_block,iron_bars,purpur_slab,purpur_pillar,netherrack,soul_sand,quartz_ore,stained_glass,glass
dimensions=6,11,9
allowable_overhang=0
max_leveling=1
leveling_buffer=-1
preventRotation=0
preserve_water=0
preserve_lava=0
preserve_plants=0
uniqueMinDistance=0
spawnMinDistance=0
spawnMaxDistance=0

rule1=0,100,preserveBlock
rule2=0,100,minecraft:dark_oak_fence-0
rule3=0,100,minecraft:brick_block-0
rule4=1,70,minecraft:dirt-1
rule5=0,100,minecraft:brick_stairs-0,minecraft:brick_stairs-1,minecraft:brick_stairs-2,minecraft:brick_stairs-3,minecraft:brick_stairs-4,minecraft:brick_stairs-5,minecraft:brick_stairs-6,minecraft:brick_stairs-7,minecraft:brick_stairs-8
rule6=0,100,minecraft:dirt-1
rule7=0,100,minecraft:brick_block-0
rule8=0,100,minecraft:stone_stairs-2
rule9=0,100,minecraft:stone_stairs-3
rule10=0,50,minecraft:brick_block-0
rule11=0,100,minecraft:brick_block-0
rule12=0,100,minecraft:stone_stairs-1
rule13=0,100,minecraft:stone_slab-12

layer
1,3,1,3,1,3,3,3,1
1,3,3,3,1,3,1,1,1
1,3,3,1,1,3,1,1,1
3,1,3,1,1,1,3,1,1
1,1,3,1,1,3,3,1,1
1,1,1,1,3,3,3,3,1
3,1,1,1,3,3,3,3,1
1,3,1,3,3,3,3,3,3
1,3,3,3,3,3,3,3,3
1,1,3,1,3,3,3,3,3
1,1,1,1,1,1,1,1,1
endlayer

layer
1,2,1,2,1,2,2,2,1
1,3,3,3,1,3,1,1,1
1,5,4,1,1,3,1,1,1
5,1,4,1,1,1,3,1,1
1,1,4,1,1,3,3,1,1
1,1,1,1,6,6,6,3,1
3,1,1,1,6,6,6,6,1
1,5,1,6,6,6,6,6,3
1,5,3,6,6,6,6,6,3
1,1,2,1,6,6,6,3,5
1,1,1,1,1,1,1,1,1
endlayer

layer
1,1,2,1,1,1,1,1,1
1,5,3,5,1,3,1,1,1
1,5,4,1,1,3,1,1,1
5,1,1,1,1,1,3,1,1
1,1,1,1,1,1,3,1,1
1,1,1,1,1,1,1,3,1
5,1,1,1,1,1,6,3,1
1,3,1,1,1,6,6,6,3
1,5,3,3,6,6,6,6,5
1,1,2,1,3,3,1,5,5
1,1,1,1,1,1,1,1,1
endlayer

layer
1,1,1,1,1,1,1,1,1
1,3,3,3,5,5,1,1,1
1,1,1,1,1,3,1,1,1
3,1,1,1,1,1,3,1,1
5,1,1,1,1,1,1,1,1
5,1,1,1,1,1,1,1,1
3,1,1,1,1,1,1,3,7
1,3,1,1,1,1,1,1,5
1,3,3,5,1,1,1,1,3
1,1,5,5,5,3,5,5,3
1,1,1,1,1,1,1,1,1
endlayer

layer
1,1,1,1,1,1,1,1,1
1,1,1,1,1,8,1,1,1
1,1,1,1,1,8,1,1,1
9,1,1,1,1,1,8,1,1
9,1,1,1,1,1,1,1,1
9,3,1,1,1,1,1,1,1
9,1,1,1,1,1,1,1,8
1,9,1,1,1,1,1,1,8
1,9,1,1,1,1,1,1,8
1,1,10,1,11,1,11,10,8
1,1,1,1,1,1,1,1,12
endlayer

layer
1,1,1,1,1,1,1,1,1
1,1,1,1,1,1,1,1,1
1,1,1,1,1,1,1,1,1
1,1,1,1,1,1,1,1,1
1,1,1,1,1,1,1,1,1
1,3,13,13,1,1,1,8,1
1,1,1,13,13,1,13,8,1
1,1,1,1,13,13,13,8,1
1,1,9,1,1,1,1,8,1
1,1,12,1,1,1,1,8,1
1,1,1,1,1,1,1,8,1
endlayer

