weight=6
dimensionsToSpawnIn=overworld
embed_into_distance=36
random_height_offset=0,0
unacceptable_target_blocks=sand,flowing_water,water,flowing_lava,lava,ice,packed_ice,stained_hardened_clay-9,brick_block,double_stone_slab,stonebrick,red_sandstone,red_nether_brick,red_mushroom_block,brown_mushroom_block,planks,cobblestone,end_stone,obsidian,purpur_block,iron_bars,purpur_slab,purpur_pillar,netherrack,soul_sand,quartz_ore,stained_glass,glass
dimensions=36,7,7
allowable_overhang=0
max_leveling=2
leveling_buffer=-1
preventRotation=0
preserve_water=0
preserve_lava=0
uniqueMinDistance=0
spawnMinDistance=0
spawnMaxDistance=0

rule1=0,100,preserveBlock
rule2=0,100,chisel:brownstone-0,chisel:brownstone-1,chisel:brownstone-0,chisel:brownstone-1,iron_bars-0
rule3=0,100,chisel:factory-14
rule4=0,100,chisel:technical-15
rule5=0,100,chisel:blockcopper-4,chisel:blockiron-4,chisel:blocksteel-4
rule6=0,100,air
rule7=0,100,chisel:factory-2
rule8=0,100,chisel:factory-1
rule9=0,100,minecraft:vine-4
rule10=0,100,minecraft:vine-2
rule11=0,100,minecraft:vine-8
rule12=0,100,minecraft:vine-3
rule13=0,100,minecraft:vine-6
rule14=0,100,chisel:brownstone-0,chisel:brownstone-1
rule15=0,100,chisel:technical-12

layer
3,3,2,2,2,1,1
1,2,4,4,4,2,1
2,4,4,4,4,4,2
2,4,4,5,4,4,2
2,4,4,4,4,4,2
1,2,4,4,4,2,1
1,1,2,2,2,1,1
endlayer

layer
1,3,2,2,2,1,1
1,2,6,6,6,2,1
2,6,6,6,6,6,2
2,6,6,6,6,6,2
2,6,6,6,6,6,2
1,2,6,6,6,2,1
1,1,2,2,2,1,1
endlayer

layer
1,3,2,2,2,1,1
1,2,6,6,6,2,1
2,6,6,6,6,6,2
2,6,6,6,6,6,2
2,6,6,6,6,6,2
1,2,6,6,6,2,1
1,1,2,2,2,1,1
endlayer

layer
1,3,3,2,2,1,1
1,2,3,6,6,2,1
2,6,3,6,6,6,2
3,3,3,6,6,6,2
2,6,6,6,6,6,2
1,2,6,6,6,2,1
1,1,2,2,2,1,1
endlayer

layer
1,1,2,2,2,1,1
1,2,6,6,6,2,1
2,6,6,6,6,6,2
2,6,6,6,6,6,2
2,6,6,6,3,3,3
1,2,6,6,3,2,3
1,1,2,2,3,3,3
endlayer

layer
1,1,2,2,2,1,1
1,2,6,6,6,2,1
2,6,6,6,6,6,2
2,6,6,6,6,6,2
2,6,6,6,6,6,2
1,2,6,6,6,2,1
1,1,2,2,2,1,1
endlayer

layer
1,1,2,2,2,1,1
1,2,6,6,6,2,1
2,6,6,6,6,6,2
2,6,6,7,6,6,2
2,6,6,7,6,6,2
1,2,6,7,6,2,1
1,1,2,7,2,1,1
endlayer

layer
1,1,2,7,2,1,1
1,2,6,7,6,2,1
2,6,6,7,6,6,2
2,6,6,7,6,6,2
2,6,6,6,6,6,2
1,2,6,6,6,2,1
1,1,2,2,2,1,1
endlayer

layer
1,1,2,2,2,1,1
1,2,6,6,6,2,1
2,6,6,6,6,6,2
2,6,6,7,6,6,2
2,6,6,6,6,6,2
1,2,6,6,6,2,1
1,1,2,2,2,1,1
endlayer

layer
1,1,2,2,2,1,1
1,2,6,6,6,2,1
2,6,6,6,6,6,2
2,6,6,7,6,6,2
8,8,8,8,8,8,8
8,2,6,6,6,2,8
1,1,2,2,2,1,8
endlayer

layer
7,1,2,2,2,1,1
1,2,6,6,6,2,1
2,6,6,6,6,6,2
2,6,6,7,6,6,2
2,6,6,6,6,6,2
8,2,6,6,6,2,1
1,1,2,2,2,1,8
endlayer

layer
7,1,2,2,2,1,1
1,2,6,6,6,2,1
2,6,6,6,6,6,2
2,6,6,7,6,6,2
2,6,6,6,6,6,2
1,2,6,6,6,2,1
1,1,2,2,2,1,8
endlayer

layer
7,1,2,2,2,1,1
1,2,6,6,6,2,1
2,6,6,6,6,6,2
2,6,6,7,6,6,2
2,6,6,7,6,6,2
1,2,6,7,6,2,1
1,1,2,7,2,1,8
endlayer

layer
7,1,2,2,2,1,1
7,7,6,6,6,2,1
2,7,6,6,6,6,2
2,7,6,6,6,6,2
2,7,6,6,6,6,2
7,7,6,6,6,2,1
1,1,2,2,2,8,8
endlayer

layer
1,1,2,2,2,1,1
1,2,6,6,3,2,1
2,6,6,6,3,6,2
2,6,6,6,3,6,2
2,6,6,6,3,6,2
7,2,6,6,6,2,1
1,1,2,2,2,8,1
endlayer

layer
1,1,2,2,2,1,1
1,2,6,6,6,2,1
2,6,6,6,6,6,2
8,8,8,6,6,6,2
2,6,6,6,3,6,2
7,2,6,6,6,2,1
1,1,2,2,2,8,1
endlayer

layer
1,1,2,2,2,1,1
1,2,6,6,6,2,1
2,6,6,6,6,6,2
2,6,8,6,6,6,2
2,6,6,6,3,6,2
7,2,6,6,6,2,1
1,1,2,2,2,1,1
endlayer

layer
8,8,8,2,2,8,8
8,2,8,6,6,2,8
2,6,8,8,8,8,8
2,6,8,6,6,6,2
2,6,6,6,3,6,2
1,2,6,6,6,2,1
1,1,2,2,2,1,1
endlayer

layer
1,1,2,2,2,1,1
1,2,6,6,6,2,1
2,6,6,6,6,6,2
2,6,6,6,6,6,2
2,6,6,6,3,6,2
1,2,6,6,6,2,1
1,1,2,2,2,1,1
endlayer

layer
1,1,2,2,2,1,1
1,2,6,6,6,2,1
2,6,6,6,6,6,2
2,6,6,6,6,6,2
2,6,6,6,3,6,2
1,2,6,6,6,2,1
1,1,2,2,2,1,1
endlayer

layer
1,1,2,2,2,1,1
1,2,6,6,6,2,1
2,6,6,6,6,6,2
2,6,6,6,6,6,2
2,6,6,3,3,3,3
1,2,6,6,6,2,3
1,1,2,2,2,1,3
endlayer

layer
1,1,2,2,2,7,1
1,2,6,6,6,2,1
2,6,6,6,6,6,2
2,6,6,6,6,6,2
2,6,6,3,6,6,2
1,2,6,6,6,2,1
8,1,2,2,2,1,1
endlayer

layer
1,1,2,3,2,7,1
1,2,6,3,6,2,1
2,6,6,3,6,6,2
2,6,6,3,6,6,2
2,6,6,3,6,6,2
1,2,6,3,6,2,1
8,1,2,3,2,1,1
endlayer

layer
1,1,2,2,2,7,7
1,2,6,6,6,2,7
2,6,6,6,6,6,2
2,6,6,6,6,6,2
2,6,6,6,6,6,2
1,2,6,6,6,2,1
8,1,2,2,2,1,1
endlayer

layer
1,1,2,2,2,1,1
1,2,6,6,6,2,7
2,6,6,6,6,6,2
2,6,6,6,6,6,2
8,8,8,6,6,6,2
8,2,6,6,6,2,1
8,1,2,2,2,1,1
endlayer

layer
1,1,2,2,2,1,1
7,2,6,6,6,2,7
7,7,7,7,7,7,7
2,6,6,6,7,6,2
2,6,8,6,7,6,2
1,2,6,6,7,2,1
1,1,2,2,7,7,7
endlayer

layer
1,1,2,2,2,1,1
7,2,6,6,6,2,1
2,6,6,6,6,6,2
2,6,6,6,6,6,2
2,6,8,6,6,6,2
1,2,6,6,6,2,1
1,1,2,2,2,1,7
endlayer

layer
1,1,2,2,2,1,1
7,2,2,2,2,2,1
2,2,2,2,2,2,2
2,2,2,2,2,2,2
2,2,8,2,2,2,2
1,2,2,2,2,2,1
1,1,2,2,2,1,7
endlayer

layer
1,1,2,2,2,1,1
1,2,6,6,6,2,1
2,6,6,6,6,9,2
2,6,6,6,6,9,2
2,6,8,6,6,6,2
1,2,6,6,6,2,1
1,1,2,2,2,1,7
endlayer

layer
1,1,2,2,2,1,1
1,2,10,6,6,2,1
2,6,6,6,6,6,2
2,6,6,6,6,6,2
8,8,8,6,6,6,2
8,2,6,6,6,2,1
8,1,2,2,2,1,1
endlayer

layer
1,1,2,2,2,1,1
1,2,10,10,10,2,1
2,6,6,6,6,6,2
2,6,9,6,6,6,2
2,11,6,6,6,6,2
1,2,6,6,6,2,1
1,1,2,2,2,1,1
endlayer

layer
1,1,2,8,2,1,1
1,2,6,8,12,2,1
2,6,10,8,6,6,2
2,6,9,8,8,8,8
2,6,6,8,6,6,2
1,2,6,8,6,2,1
1,1,2,8,2,1,1
endlayer

layer
1,1,2,2,2,1,1
1,2,6,6,6,2,1
2,6,10,6,13,6,2
2,6,6,6,6,6,2
2,6,6,6,6,6,2
1,2,6,6,6,2,1
1,1,2,2,2,1,1
endlayer

layer
1,1,2,2,2,1,1
1,1,2,2,2,1,1
2,2,12,6,13,2,2
2,2,6,6,6,2,2
2,2,6,11,6,2,2
1,7,2,2,2,1,1
1,1,2,2,2,1,1
endlayer

layer
1,1,1,1,1,1,1
1,1,1,14,1,1,1
1,1,14,15,14,1,1
1,14,15,6,15,14,1
1,1,14,15,14,1,1
1,1,1,14,1,1,1
1,1,1,1,1,1,1
endlayer

layer
1,1,1,1,1,1,1
1,1,1,14,1,1,1
1,1,14,15,14,1,1
1,14,15,4,15,14,1
1,1,14,15,14,1,1
1,1,1,14,1,1,1
1,1,1,1,1,1,1
endlayer

