weight=8
dimensionsToSpawnIn=overworld
embed_into_distance=17
random_height_offset=0,0
unacceptable_target_blocks=flowing_water,water,flowing_lava,lava,ice,packed_ice,stained_hardened_clay-9,brick_block,double_stone_slab,stonebrick,red_sandstone,red_nether_brick,red_mushroom_block,brown_mushroom_block,planks,cobblestone,end_stone,obsidian,purpur_block,iron_bars,purpur_slab,purpur_pillar,netherrack,soul_sand,quartz_ore,stained_glass,glass
dimensions=18,48,48
allowable_overhang=0
max_leveling=5
leveling_buffer=-1
preventRotation=0
preserve_water=0
preserve_lava=0
uniqueMinDistance=7000
spawnMinDistance=1000
spawnMaxDistance=0

rule1=0,100,preserveBlock
rule2=0,100,chisel:laboratory-0
rule3=0,100,chisel:laboratory-11
rule4=0,100,chisel:technicalnew-2
rule5=0,100,chisel:factory-6
rule6=0,100,minecraft:water-8
rule7=0,100,chisel:factory-2
rule8=0,100,minecraft:stone_slab-0
rule9=0,100,chisel:factory-4
rule10=0,100,chisel:concrete_lightgray-11
rule11=0,100,MobSpawner:Zombie,MobSpawner:Wither_Skeleton
rule12=0,100,chisel:factory-15
rule13=0,100,chisel:blockcopper-6,chisel:blockgold-6,chisel:blockiron-6,chisel:blocklead-6,chisel:blocknickel-6,chisel:blocksilver-6,chisel:blocksteel-6,chisel:blockplatinum-4,chisel:blockuranium-4,chisel:blockaluminum-1,chisel:blockcopper-1,chisel:blockiron-1,chisel:blocknickel-1,chisel:blocksilver-1
rule14=0,100,chisel:factory-13
rule15=0,100,chisel:factory-9
rule16=0,100,chisel:concrete_gray-11
rule17=0,100,minecraft:lever-1
rule18=0,100,minecraft:lever-3
rule19=0,100,minecraft:stained_glass_pane-7
rule20=0,100,chisel:factory-8
rule21=0,100,minecraft:stone_slab-8
rule22=0,100,minecraft:double_stone_slab-0
rule23=0,100,minecraft:lever-2
rule24=0,100,minecraft:quartz_stairs-3
rule25=2,100,minecraft:stone_button-4
rule26=0,100,chisel:technical-13
rule27=0,100,minecraft:quartz_stairs-2
rule28=0,100,minecraft:lever-4
rule29=0,100,chisel:concrete_gray-15
rule30=2,100,minecraft:stone_button-3
rule31=0,100,minecraft:cobblestone_wall-0
rule32=2,100,minecraft:stone_button-2
rule33=0,100,minecraft:quartz_stairs-1
rule34=0,100,chisel:concrete_black-15
rule35=2,100,minecraft:stone_button-1
rule36=0,100,minecraft:quartz_stairs-0
rule37=0,100,chisel:voidstone-5
rule38=0,100,chisel:energizedvoidstone-5
rule39=0,100,chisel:concrete_black-11
rule40=0,100,minecraft:stained_glass-7
rule41=0,100,minecraft:heavy_weighted_pressure_plate-0
rule42=0,100,chisel:laboratory-15
rule43=0,100,chisel:futura-0
rule44=0,100,minecraft:lever-5
rule45=0,100,chisel:technical-11
rule46=0,100,minecraft:lever-13
rule47=0,100,minecraft:lever-6
rule48=0,100,minecraft:lever-9
rule49=0,100,minecraft:lever-10
rule50=1,100,minecraft:stone_button-5
rule51=0,100,minecraft:water-0

layer
1,1,1,1,1,1,1,1,1,1,1,1,1,1,1,1,1,1,1,1,1,1,1,1,1,1,1,1,1,1,1,1,1,1,1,1,1,1,1,1,1,1,1,1,1,1,1,1
1,1,1,1,1,1,1,1,1,1,1,1,1,1,1,1,2,2,2,2,2,1,1,1,1,1,1,1,1,1,1,1,1,1,1,1,1,1,1,1,1,1,1,1,1,1,1,1
1,1,3,3,3,3,3,3,3,3,3,3,3,3,3,3,3,3,3,3,3,3,3,3,3,3,3,3,3,3,3,3,3,3,3,3,3,3,3,3,3,3,3,3,3,3,1,1
1,1,3,3,3,3,3,3,3,3,3,3,3,3,3,3,3,3,3,3,3,3,3,3,3,3,3,3,3,3,3,3,3,3,3,3,3,3,3,3,3,3,3,3,3,3,1,1
1,1,3,3,3,3,3,3,3,3,3,3,3,3,3,3,3,3,3,3,3,3,3,3,3,3,3,3,3,3,3,3,3,3,3,3,3,3,3,3,3,3,3,3,3,3,1,1
1,1,3,3,3,3,3,3,3,3,3,3,3,3,3,3,3,3,3,3,3,3,3,3,3,3,3,3,3,3,3,3,3,3,3,3,3,3,3,3,3,3,3,3,3,3,1,1
1,1,3,3,3,3,3,3,3,3,3,3,3,3,3,3,3,3,3,3,3,3,3,3,3,3,3,3,3,3,3,3,3,3,3,3,3,3,3,3,3,3,3,3,3,3,1,1
1,1,3,3,3,3,3,3,3,3,3,3,3,3,3,3,3,3,3,3,3,3,3,3,3,3,3,3,3,3,3,3,3,3,3,3,3,3,3,3,3,3,3,3,3,3,1,1
1,1,3,3,3,3,3,3,3,3,3,3,3,3,3,3,3,3,3,3,3,3,3,3,3,3,3,3,3,3,3,3,3,3,3,3,3,3,3,3,3,3,3,3,3,3,1,1
1,1,3,3,3,3,3,3,3,3,3,3,3,3,3,3,3,3,3,3,3,3,3,3,3,3,3,3,3,3,3,3,3,3,3,3,3,3,3,3,3,3,3,3,3,3,1,1
1,1,3,3,3,3,3,3,3,3,3,3,3,3,3,3,3,3,3,3,3,3,3,3,3,3,3,3,3,3,3,3,3,3,3,3,3,3,3,3,3,3,3,3,3,3,1,1
1,1,3,3,3,3,3,3,3,3,3,3,3,3,3,3,3,3,3,3,3,3,3,3,3,3,3,3,3,3,3,3,3,3,3,3,3,3,3,3,3,3,3,3,3,3,1,1
1,1,3,3,3,3,3,3,3,3,3,3,3,3,3,3,3,3,3,3,3,3,3,3,3,3,3,3,3,3,3,3,3,3,3,3,3,3,3,3,3,3,3,3,3,3,1,1
1,1,3,3,3,3,3,3,3,3,3,3,3,3,3,3,3,3,3,3,3,3,3,3,3,3,3,3,3,3,3,3,3,3,3,3,3,3,3,3,3,3,3,3,3,3,1,1
1,1,3,3,3,3,3,3,3,3,3,3,3,3,3,3,3,3,3,3,3,3,3,3,3,3,3,3,3,3,3,3,3,3,3,3,3,3,3,3,3,3,3,3,3,3,1,1
1,1,3,3,3,3,3,3,3,3,3,3,3,3,3,3,3,3,3,3,3,3,3,3,3,3,3,3,3,3,3,3,3,3,3,3,3,3,3,3,3,3,3,3,3,3,1,1
1,1,3,3,3,3,3,3,3,3,3,3,3,3,3,3,3,3,3,3,3,3,3,3,3,3,3,3,3,3,3,3,3,3,3,3,3,3,3,3,3,3,3,3,3,3,1,1
1,1,3,3,3,3,3,3,3,3,3,3,3,3,3,3,3,3,3,3,3,3,3,3,3,3,3,3,3,3,3,3,3,3,3,3,3,3,3,3,3,3,3,3,3,3,2,1
1,1,3,3,3,3,3,3,3,3,3,3,3,3,3,3,3,3,3,3,3,3,3,3,3,3,3,3,3,3,3,3,3,3,3,3,3,3,3,3,3,3,3,3,3,3,2,1
1,1,3,3,3,3,3,3,3,3,3,3,3,3,3,3,3,3,3,3,3,3,3,3,3,3,3,3,3,3,3,3,3,3,3,3,3,3,3,3,3,3,3,3,3,3,2,1
1,1,3,3,3,3,3,3,3,3,3,3,3,3,3,3,3,3,3,3,3,3,3,3,3,3,3,3,3,3,3,3,3,3,3,3,3,3,3,3,3,3,3,3,3,3,2,1
1,1,3,3,3,3,3,3,3,3,3,3,3,3,3,3,3,3,3,3,3,3,3,3,3,3,3,3,3,3,3,3,3,3,3,3,3,3,3,3,3,3,3,3,3,3,2,1
1,1,3,3,3,3,3,3,3,3,3,3,3,3,3,3,3,3,3,3,3,3,3,3,3,3,3,3,3,3,3,3,3,3,3,3,3,3,3,3,3,3,3,3,3,3,1,1
1,1,3,3,3,3,3,3,3,3,3,3,3,3,3,3,3,3,3,3,3,3,3,3,3,3,3,3,3,3,3,3,3,3,3,3,3,3,3,3,3,3,3,3,3,3,1,1
1,1,3,3,3,3,3,3,3,3,3,3,3,3,3,3,3,3,3,3,3,3,3,3,3,3,3,3,3,3,3,3,3,3,3,3,3,3,3,3,3,3,3,3,3,3,1,1
1,1,3,3,3,3,3,3,3,3,3,3,3,3,3,3,3,3,3,3,3,3,3,3,3,3,3,3,3,3,3,3,3,3,3,3,3,3,3,3,3,3,3,3,3,3,1,1
1,2,3,3,3,3,3,3,3,3,3,3,3,3,3,3,3,3,3,3,3,3,3,3,3,3,3,3,3,3,3,3,3,3,3,3,3,3,3,3,3,3,3,3,3,3,1,1
1,2,3,3,3,3,3,3,3,3,3,3,3,3,3,3,3,3,3,3,3,3,3,3,3,3,3,3,3,3,3,3,3,3,3,3,3,3,3,3,3,3,3,3,3,3,1,1
1,2,3,3,3,3,3,3,3,3,3,3,3,3,3,3,3,3,3,3,3,3,3,3,3,3,3,3,3,3,3,3,3,3,3,3,3,3,3,3,3,3,3,3,3,3,1,1
1,2,3,3,3,3,3,3,3,3,3,3,3,3,3,3,3,3,3,3,3,3,3,3,3,3,3,3,3,3,3,3,3,3,3,3,3,3,3,3,3,3,3,3,3,3,1,1
1,2,3,3,3,3,3,3,3,3,3,3,3,3,3,3,3,3,3,3,3,3,3,3,3,3,3,3,3,3,3,3,3,3,3,3,3,3,3,3,3,3,3,3,3,3,1,1
1,1,3,3,3,3,3,3,3,3,3,3,3,3,3,3,3,3,3,3,3,3,3,3,3,3,3,3,3,3,3,3,3,3,3,3,3,3,3,3,3,3,3,3,3,3,1,1
1,1,3,3,3,3,3,3,3,3,3,3,3,3,3,3,3,3,3,3,3,3,3,3,3,3,3,3,3,3,3,3,3,3,3,3,3,3,3,3,3,3,3,3,3,3,1,1
1,1,3,3,3,3,3,3,3,3,3,3,3,3,3,3,3,3,3,3,3,3,3,3,3,3,3,3,3,3,3,3,3,3,3,3,3,3,3,3,3,3,3,3,3,3,1,1
1,1,3,3,3,3,3,3,3,3,3,3,3,3,3,3,3,3,3,3,3,3,3,3,3,3,3,3,3,3,3,3,3,3,3,3,3,3,3,3,3,3,3,3,3,3,1,1
1,1,3,3,3,3,3,3,3,3,3,3,3,3,3,3,3,3,3,3,3,3,3,3,3,3,3,3,3,3,3,3,3,3,3,3,3,3,3,3,3,3,3,3,3,3,1,1
1,1,3,3,3,3,3,3,3,3,3,3,3,3,3,3,3,3,3,3,3,3,3,3,3,3,3,3,3,3,3,3,3,3,3,3,3,3,3,3,3,3,3,3,3,3,1,1
1,1,3,3,3,3,3,3,3,3,3,3,3,3,3,3,3,3,3,3,3,3,3,3,3,3,3,3,3,3,3,3,3,3,3,3,3,3,3,3,3,3,3,3,3,3,1,1
1,1,3,3,3,3,3,3,3,3,3,3,3,3,3,3,3,3,3,3,3,3,3,3,3,3,3,3,3,3,3,3,3,3,3,3,3,3,3,3,3,3,3,3,3,3,1,1
1,1,3,3,3,3,3,3,3,3,3,3,3,3,3,3,3,3,3,3,3,3,3,3,3,3,3,3,3,3,3,3,3,3,3,3,3,3,3,3,3,3,3,3,3,3,1,1
1,1,3,3,3,3,3,3,3,3,3,3,3,3,3,3,3,3,3,3,3,3,3,3,3,3,3,3,3,3,3,3,3,3,3,3,3,3,3,3,3,3,3,3,3,3,1,1
1,1,3,3,3,3,3,3,3,3,3,3,3,3,3,3,3,3,3,3,3,3,3,3,3,3,3,3,3,3,3,3,3,3,3,3,3,3,3,3,3,3,3,3,3,3,1,1
1,1,3,3,3,3,3,3,3,3,3,3,3,3,3,3,3,3,3,3,3,3,3,3,3,3,3,3,3,3,3,3,3,3,3,3,3,3,3,3,3,3,3,3,3,3,1,1
1,1,3,3,3,3,3,3,3,3,3,3,3,3,3,3,3,3,3,3,3,3,3,3,3,3,3,3,3,3,3,3,3,3,3,3,3,3,3,3,3,3,3,3,3,3,1,1
1,1,3,3,3,3,3,3,3,3,3,3,3,3,3,3,3,3,3,3,3,3,3,3,3,3,3,3,3,3,3,3,3,3,3,3,3,3,3,3,3,3,3,3,3,3,1,1
1,1,3,3,3,3,3,3,3,3,3,3,3,3,3,3,3,3,3,3,3,3,3,3,3,3,3,3,3,3,3,3,3,3,3,3,3,3,3,3,3,3,3,3,3,3,1,1
1,1,1,1,1,1,1,1,1,1,1,1,1,1,1,1,1,1,1,1,1,1,1,1,1,1,1,2,2,2,2,2,2,1,1,1,1,1,1,1,1,1,1,1,1,1,1,1
1,1,1,1,1,1,1,1,1,1,1,1,1,1,1,1,1,1,1,1,1,1,1,1,1,1,1,1,1,1,1,1,1,1,1,1,1,1,1,1,1,1,1,1,1,1,1,1
endlayer

layer
1,1,1,1,1,1,1,1,1,1,1,1,1,1,1,1,1,1,1,1,1,1,1,1,1,1,1,1,1,1,1,1,1,1,1,1,1,1,1,1,1,1,1,1,1,1,1,1
1,1,2,2,1,2,1,1,1,2,1,2,1,1,1,2,4,4,4,4,4,2,3,3,2,3,2,1,1,1,2,1,2,1,1,1,2,1,2,1,1,1,2,1,2,1,1,1
1,2,6,2,3,5,3,3,3,3,3,3,3,3,3,2,0,0,0,0,0,2,3,3,3,3,3,3,3,3,3,3,3,3,3,3,3,3,3,3,3,3,5,3,0,2,1,1
1,2,2,2,3,5,3,3,3,3,3,3,3,3,3,5,0,0,0,0,0,5,3,3,3,3,3,3,3,3,3,3,3,3,3,3,3,3,3,3,3,3,5,3,2,0,2,1
1,1,3,3,3,5,3,3,3,3,3,3,3,3,3,5,0,0,0,0,0,5,3,3,3,3,3,3,3,3,3,3,3,3,3,3,3,3,3,3,3,3,5,3,3,3,1,1
1,2,5,5,5,5,3,3,3,3,3,3,3,3,3,5,0,0,0,0,0,5,3,3,3,3,3,3,3,3,3,3,3,3,3,3,3,3,3,3,3,3,5,5,5,5,2,1
1,1,3,3,3,3,3,3,3,3,3,3,3,3,3,5,0,0,0,0,0,5,3,3,3,3,3,3,3,3,3,3,3,3,3,3,3,3,3,3,3,3,3,3,3,3,1,1
1,1,3,3,3,3,3,3,3,3,3,3,3,3,3,5,0,0,0,0,0,5,3,3,3,3,3,3,3,3,3,3,3,3,3,3,3,3,3,3,3,3,3,3,3,3,1,1
1,1,3,3,3,3,3,3,3,3,3,3,3,3,3,5,0,0,0,0,0,5,3,3,3,3,3,3,3,3,3,3,3,3,3,3,3,3,3,3,3,3,3,3,3,3,1,1
1,2,3,3,3,3,3,3,3,3,3,3,7,3,3,5,0,0,0,0,0,5,3,3,3,3,3,3,3,3,3,3,3,3,3,3,3,3,3,3,3,3,3,3,3,3,2,1
1,1,3,3,3,3,3,3,3,3,3,3,3,3,3,5,8,8,8,8,8,5,3,3,3,3,3,3,3,3,3,3,3,3,3,3,3,3,3,3,3,3,3,3,3,3,1,1
1,1,3,3,3,3,3,3,3,3,3,3,3,3,3,5,8,8,8,8,8,5,3,3,3,3,3,3,3,3,3,3,3,3,3,3,3,3,3,3,3,3,3,3,3,3,2,1
1,1,3,3,3,3,3,3,3,3,3,3,3,3,3,5,5,5,5,5,5,5,3,3,3,3,3,3,3,3,3,3,3,3,3,3,3,3,3,3,3,3,3,3,3,3,1,1
1,1,3,3,3,3,3,3,3,3,3,3,3,3,3,3,3,3,3,3,3,3,3,3,3,3,3,3,3,3,3,3,3,3,3,3,3,3,3,3,3,3,3,3,3,3,1,1
1,1,3,3,3,3,3,3,3,3,3,3,3,3,3,3,3,3,3,3,3,3,3,5,3,3,3,5,3,3,3,3,3,3,3,3,3,3,3,3,3,3,3,3,3,3,1,1
1,2,3,3,3,3,3,3,3,3,3,3,3,3,3,3,3,3,3,3,3,3,3,3,3,9,3,3,3,3,3,3,3,3,3,3,3,3,3,3,3,3,3,3,3,3,2,1
1,1,3,3,3,3,3,3,3,3,3,3,3,3,3,3,3,3,3,3,3,3,3,3,9,9,9,3,3,3,3,3,3,3,3,5,5,5,5,5,5,5,5,5,5,2,1,1
1,2,3,3,3,3,3,3,3,3,3,3,3,3,3,5,5,5,3,3,3,3,3,3,3,9,3,3,3,3,3,3,3,3,3,5,8,8,0,0,0,0,0,0,0,0,4,1
1,1,3,3,3,3,3,3,3,3,3,3,3,3,3,5,3,5,3,3,3,3,3,5,3,3,3,5,3,3,3,3,3,3,3,5,8,8,0,0,0,0,0,10,10,10,4,1
1,1,3,3,12,3,3,3,3,3,3,3,3,3,3,5,3,5,3,3,3,3,3,3,3,3,3,3,3,3,3,3,3,3,3,5,8,8,0,0,0,0,0,10,11,10,4,1
1,1,3,3,3,3,3,3,3,3,3,3,3,3,3,5,3,5,3,3,3,3,3,3,3,3,3,3,3,3,3,3,3,3,3,5,8,8,0,0,0,0,0,10,10,10,4,1
1,2,3,3,3,3,3,3,3,3,3,3,3,3,3,5,3,5,3,3,3,3,3,5,3,3,3,5,3,3,3,3,3,3,3,5,8,8,0,0,0,0,0,0,0,0,4,1
1,1,3,3,3,3,3,3,3,3,3,3,3,3,3,5,3,5,3,3,3,3,3,3,3,9,3,3,3,3,3,3,3,3,3,5,5,5,5,5,5,5,5,5,5,2,1,1
1,1,3,3,3,3,3,3,3,3,3,3,3,3,3,5,3,5,3,3,3,3,3,3,9,9,9,3,3,3,3,3,3,3,3,3,3,3,3,3,3,3,3,3,3,3,1,1
1,1,3,3,3,3,3,3,3,3,3,3,3,3,3,5,3,5,3,3,3,3,3,3,3,9,3,3,3,3,3,3,3,3,3,3,3,3,3,3,3,3,3,3,3,3,1,1
1,1,2,5,5,5,5,5,5,5,5,5,5,3,3,5,3,5,3,3,3,3,3,5,3,3,3,5,3,3,3,3,3,3,3,3,3,3,3,3,3,3,3,3,3,3,1,1
1,4,0,0,0,0,0,0,0,0,8,8,5,3,3,5,3,5,3,3,3,3,3,3,3,3,3,3,3,3,3,3,3,3,3,3,3,3,3,3,3,3,3,3,3,3,2,1
1,4,0,0,0,0,0,13,13,0,8,8,5,3,3,5,5,5,3,3,3,3,3,3,3,3,3,3,3,3,3,3,3,3,3,3,3,3,3,3,3,3,3,3,3,3,1,1
1,4,0,0,0,0,0,13,13,0,8,8,5,3,3,3,3,3,3,3,3,3,3,3,3,3,3,3,3,3,3,3,3,3,3,3,3,3,3,3,3,3,3,3,3,3,1,1
1,4,0,0,0,0,0,0,0,0,8,8,5,3,3,3,3,3,3,3,3,3,3,3,3,3,3,3,3,3,3,3,3,3,3,3,3,3,3,3,3,3,3,3,3,3,1,1
1,4,0,0,0,0,0,0,0,0,8,8,5,3,3,3,3,3,3,3,3,3,3,3,3,3,3,3,3,3,3,3,3,3,3,3,3,3,3,3,3,3,3,3,3,3,2,1
1,1,2,5,5,5,5,5,5,5,5,5,5,3,3,3,3,3,3,3,3,3,3,3,3,3,3,3,3,3,3,3,3,3,3,3,3,3,3,3,3,3,3,3,3,3,1,1
1,2,3,3,3,3,3,3,3,3,3,3,3,5,5,5,5,5,3,3,3,3,3,3,3,3,3,3,3,3,3,3,3,3,3,3,3,3,3,3,3,3,3,3,3,3,2,1
1,1,3,3,3,3,3,3,3,3,3,3,3,5,3,3,3,5,3,3,3,3,3,3,3,3,3,3,3,3,3,3,3,3,3,3,3,3,3,3,3,3,3,3,3,3,1,1
1,1,3,3,3,3,3,3,3,3,3,3,3,5,3,3,3,5,3,3,3,3,3,3,3,3,3,3,3,3,3,3,3,3,3,3,3,3,3,3,3,3,3,3,3,3,1,1
1,1,3,3,3,3,3,3,3,3,3,3,3,5,3,3,3,5,3,3,3,3,3,3,3,3,5,5,5,5,5,5,5,3,3,3,3,3,3,3,3,3,3,3,3,3,1,1
1,2,3,3,3,3,3,3,3,3,3,3,3,5,5,5,5,5,3,3,3,3,3,3,3,3,5,8,8,8,8,8,5,3,3,3,3,3,3,3,3,3,3,3,3,3,1,1
1,1,3,3,3,3,3,3,3,3,3,3,3,3,3,3,3,3,3,3,12,3,7,3,3,3,5,8,8,8,8,8,5,3,3,3,3,3,3,3,3,3,3,3,3,3,1,1
1,2,3,3,3,3,3,3,3,3,3,3,3,3,3,3,3,3,3,3,3,3,3,3,3,3,5,0,0,0,0,0,5,3,3,3,3,3,3,3,3,3,3,3,3,3,2,1
1,1,3,3,3,3,3,3,3,3,3,3,3,3,3,3,3,3,3,3,3,3,3,3,3,3,5,0,0,0,0,0,5,3,3,3,3,3,3,3,3,3,3,3,3,3,1,1
1,1,3,3,3,3,3,3,3,3,3,3,3,3,3,3,3,3,3,3,3,3,3,3,3,3,5,0,0,0,0,0,5,3,3,3,3,3,3,3,3,3,3,3,3,3,1,1
1,1,3,3,3,3,3,3,3,3,3,3,3,3,3,3,3,3,3,3,3,3,3,3,3,3,5,0,0,0,0,0,5,3,3,3,3,3,3,3,3,3,3,3,3,3,1,1
1,2,5,5,5,5,3,3,3,3,3,3,3,3,3,3,3,3,3,3,3,3,3,3,3,3,5,0,0,0,0,0,5,3,3,3,3,3,3,3,3,3,5,5,5,5,2,1
1,1,3,3,3,5,3,3,3,3,3,3,3,3,3,3,3,3,3,3,3,3,3,3,3,3,5,0,0,0,0,0,5,3,3,3,3,3,3,3,3,3,5,3,3,3,1,1
1,2,0,2,3,5,3,3,3,3,3,3,3,3,3,3,3,3,3,3,3,3,3,3,3,3,5,0,0,0,0,0,5,3,3,3,3,3,3,3,3,3,5,3,2,2,2,1
1,1,2,0,3,5,3,3,3,3,3,3,3,3,3,3,3,3,3,3,3,3,3,3,3,3,2,0,0,0,0,0,2,3,3,3,3,3,3,3,3,3,5,3,2,6,2,1
1,1,1,2,1,2,1,1,1,2,1,2,1,1,1,2,1,2,1,1,1,2,1,2,3,3,2,4,4,4,4,4,2,1,1,1,2,1,2,1,1,1,2,1,2,2,1,1
1,1,1,1,1,1,1,1,1,1,1,1,1,1,1,1,1,1,1,1,1,1,1,1,1,1,1,1,1,1,1,1,1,1,1,1,1,1,1,1,1,1,1,1,1,1,1,1
endlayer

layer
1,1,1,1,1,1,1,1,1,1,1,1,1,1,1,1,1,1,1,1,1,1,3,3,3,3,1,1,1,1,1,1,1,1,1,1,1,1,1,1,1,1,1,1,1,1,1,1
1,1,9,2,1,2,5,5,5,2,4,2,5,5,5,2,4,4,4,4,4,2,5,5,2,4,2,5,5,5,2,4,2,5,5,5,2,4,2,5,5,5,2,1,4,9,1,1
1,9,6,2,4,0,0,0,0,0,0,0,0,0,0,2,0,0,0,0,0,2,0,0,0,0,0,0,0,0,0,0,0,0,0,0,0,0,0,0,0,0,0,4,2,6,9,1
1,2,2,11,14,0,0,0,0,0,0,0,0,0,0,0,0,0,0,0,0,0,0,0,0,0,0,0,0,0,0,0,0,0,0,0,0,0,0,2,0,0,0,14,11,2,4,1
1,1,4,14,0,0,0,0,0,0,0,0,0,0,0,0,0,0,0,0,0,0,0,13,13,0,16,16,0,0,0,0,0,0,0,0,0,0,2,15,2,0,0,0,14,4,3,3
1,2,0,0,0,0,0,0,0,0,0,0,0,0,0,0,0,0,0,0,0,0,0,13,13,0,16,16,0,16,16,0,0,0,0,0,0,0,17,2,0,0,0,0,0,0,2,1
1,5,0,0,0,0,0,0,0,0,0,0,0,0,0,0,0,0,0,0,0,0,0,13,13,0,16,16,0,16,16,0,0,0,0,0,0,0,0,0,0,0,0,0,0,0,5,1
1,5,0,0,0,0,0,0,0,0,0,0,0,0,0,0,0,0,0,0,0,0,0,0,0,0,0,0,0,16,16,0,0,0,0,0,0,0,0,0,0,0,18,2,0,0,5,1
1,5,0,0,20,0,20,0,0,0,0,0,0,0,0,0,0,0,0,0,0,0,0,0,0,0,0,0,0,0,0,0,0,0,0,19,0,0,0,19,0,0,2,15,2,0,5,1
1,2,0,0,0,0,0,0,4,0,0,0,7,0,0,4,0,0,0,0,0,0,0,0,0,0,0,0,0,0,0,0,0,0,0,3,8,8,8,3,0,0,0,2,0,0,2,1
3,4,0,0,20,0,20,0,0,0,0,0,0,0,0,0,0,0,0,0,0,0,0,0,0,0,0,0,0,0,0,0,0,0,0,4,21,21,21,4,0,0,0,0,0,0,4,1
1,2,0,0,0,0,0,0,0,0,0,0,0,0,0,0,0,0,0,0,0,0,0,0,0,0,0,0,0,0,21,0,0,0,0,0,0,0,0,0,0,0,18,2,0,0,2,1
1,5,0,0,20,0,20,0,0,0,0,0,0,0,0,0,0,0,0,0,0,0,0,0,0,0,0,0,0,21,22,21,0,0,0,0,0,0,0,0,0,0,2,15,2,0,5,1
1,5,0,0,0,0,0,0,4,19,19,19,4,0,0,4,0,0,0,0,0,0,0,0,0,23,0,0,0,0,21,0,0,0,0,2,0,0,0,0,0,0,0,2,0,0,5,1
1,5,0,0,20,0,20,0,0,21,21,21,0,0,0,0,0,0,0,0,0,0,0,0,2,2,2,0,0,0,0,0,0,0,0,2,25,24,0,0,0,0,0,0,0,0,5,1
1,2,0,0,0,0,0,0,27,21,22,21,24,0,0,0,0,0,0,0,0,0,18,2,26,26,26,2,0,0,0,0,0,0,0,2,0,0,0,0,0,0,0,0,0,0,2,1
3,4,0,0,0,2,0,0,0,21,22,21,0,0,0,0,0,0,0,0,0,0,0,2,26,26,26,2,28,0,0,0,0,0,0,4,0,0,0,4,0,0,0,0,0,2,1,1
1,2,0,0,0,2,0,0,27,21,22,21,24,0,0,0,0,0,0,0,0,0,18,2,26,26,26,2,0,0,0,0,0,0,0,0,0,0,0,0,0,0,0,0,0,0,4,1
1,5,0,0,0,2,0,0,0,21,21,21,0,0,0,0,2,0,0,0,0,0,0,0,2,2,2,0,0,0,0,29,29,0,0,0,0,0,0,0,0,0,0,10,10,10,4,1
1,5,0,0,12,2,0,0,4,19,19,19,4,0,0,0,14,0,0,0,0,0,0,0,0,17,0,0,0,0,0,29,29,0,0,0,0,0,0,0,0,0,0,10,10,10,4,1
1,5,0,0,0,2,0,0,0,0,0,0,0,0,0,0,2,0,0,0,0,0,0,0,0,23,0,0,0,0,0,29,29,0,0,0,0,0,0,0,0,0,0,10,10,10,4,1
1,2,0,0,0,0,0,0,0,0,0,0,0,0,0,0,14,0,0,0,0,0,0,0,2,2,2,0,0,0,0,0,0,0,0,0,0,0,0,0,0,0,0,0,0,0,4,1
3,4,0,0,0,0,0,0,0,0,0,0,0,0,0,0,2,0,0,0,0,0,18,2,26,26,26,2,0,0,0,0,0,0,0,4,0,0,0,4,0,0,0,0,0,2,1,3
1,2,0,0,0,0,0,0,0,0,0,0,0,0,0,0,2,0,0,0,0,0,0,2,26,26,26,2,28,0,0,0,0,0,0,0,0,8,0,0,0,0,0,0,0,0,5,2
1,2,0,0,0,0,0,0,0,0,0,0,0,0,0,0,19,0,0,0,0,0,18,2,26,26,26,2,0,0,0,0,0,27,30,2,0,21,0,2,25,24,0,0,0,0,2,1
3,1,2,0,0,0,0,0,4,0,0,0,4,0,0,0,2,0,0,0,0,0,0,0,2,2,2,0,0,0,0,0,0,0,0,2,0,0,0,2,0,0,0,0,0,0,4,3
1,4,0,0,0,0,0,0,0,0,0,0,0,0,0,0,31,0,0,0,0,0,0,0,0,17,0,0,0,0,0,0,0,0,0,2,0,0,0,2,0,0,0,0,0,0,2,1
1,4,0,0,0,0,0,13,13,0,0,0,0,0,0,0,0,0,0,0,0,0,0,0,0,0,0,0,0,0,0,0,0,27,30,2,0,0,0,2,25,24,0,0,0,0,5,1
1,4,0,0,0,0,0,0,13,0,0,0,0,0,0,0,0,0,0,0,0,33,0,0,33,32,32,23,32,0,0,0,0,0,0,4,0,21,0,4,0,0,0,0,0,0,5,1
1,4,0,0,0,0,0,0,0,0,0,0,0,0,0,0,0,0,0,0,0,0,0,0,0,2,14,14,2,0,0,0,0,0,0,0,0,8,0,0,0,0,0,0,0,0,5,1
1,4,0,0,0,0,0,0,0,0,0,0,0,0,0,0,0,0,0,0,0,2,2,2,2,4,14,14,2,0,0,0,0,0,0,0,0,0,0,34,34,0,0,0,0,0,2,1
1,1,2,0,0,0,0,0,4,0,0,0,4,0,0,0,0,0,0,0,0,0,0,0,0,35,35,35,0,0,0,0,0,0,0,0,0,0,0,34,34,0,0,0,0,0,4,3
1,2,0,0,0,0,0,0,0,0,0,0,0,0,0,0,0,0,0,0,0,36,0,0,36,0,0,0,31,0,0,0,0,0,0,0,0,0,0,0,0,0,0,0,0,0,2,1
1,5,0,0,10,10,0,0,0,0,14,0,0,0,38,0,37,0,0,0,0,0,0,0,0,0,0,0,0,0,0,0,0,0,0,0,0,0,0,0,0,0,0,0,0,0,5,1
1,5,0,0,10,10,0,0,0,0,0,0,0,0,0,38,37,0,0,0,0,0,0,0,0,0,0,0,0,0,0,0,0,0,0,7,3,0,0,4,0,0,0,0,0,0,5,1
1,5,0,0,10,10,0,0,0,0,0,0,0,0,37,0,37,0,0,0,0,0,0,0,0,0,0,0,0,0,0,0,0,0,0,0,0,0,0,0,0,0,0,0,0,0,5,1
1,2,0,0,0,0,0,0,0,0,0,0,0,0,0,0,0,0,0,0,0,0,0,0,0,0,0,0,0,0,0,0,0,0,0,0,0,0,16,16,0,0,0,0,0,0,2,1
1,4,0,0,0,0,0,0,4,21,21,21,4,0,0,0,0,0,0,0,12,0,7,0,0,0,0,0,0,0,0,0,0,0,0,0,0,0,16,16,0,0,0,0,0,0,4,3
1,2,0,0,0,0,0,0,3,8,8,8,3,0,0,0,0,0,0,0,0,0,0,0,0,0,0,0,0,0,0,0,0,0,0,0,0,0,0,0,0,13,13,13,0,0,2,1
1,5,0,0,0,0,0,0,19,0,0,0,19,0,33,0,33,0,33,0,33,0,0,0,0,0,0,0,0,0,0,0,0,0,0,0,39,39,39,39,0,13,13,13,0,0,5,1
1,5,0,0,0,0,0,0,0,0,0,0,0,22,21,21,21,21,21,21,21,22,0,0,0,0,0,0,0,0,0,0,0,0,0,0,39,11,11,39,0,0,0,0,0,0,5,1
1,5,0,0,0,0,0,0,0,0,0,0,0,21,11,22,22,22,22,22,11,21,0,0,0,0,0,0,0,0,0,0,0,0,0,0,39,39,39,39,0,0,0,0,0,0,5,1
1,2,0,0,0,0,0,34,34,34,0,0,0,22,21,21,21,21,21,21,21,22,0,0,0,0,0,0,0,0,0,0,0,0,0,0,0,0,0,0,0,0,0,0,0,0,2,1
3,3,4,14,0,0,0,34,34,34,0,0,0,0,36,0,36,0,36,0,36,0,0,0,0,0,0,0,0,0,0,0,0,0,0,0,0,0,0,0,0,0,0,0,14,4,1,1
1,4,2,11,14,0,0,0,0,0,0,0,0,0,0,0,0,0,0,0,0,0,0,0,0,0,0,0,0,0,0,0,0,0,0,0,0,0,0,0,0,0,0,14,11,2,2,1
1,9,6,2,4,0,0,0,0,0,0,0,0,0,0,0,0,0,0,0,0,0,0,0,0,0,2,0,0,0,0,0,2,0,0,0,0,0,0,0,0,0,0,4,2,6,9,1
1,1,9,4,1,2,5,5,5,2,4,2,5,5,5,2,4,2,5,5,5,2,4,2,5,5,2,4,4,4,4,4,2,5,5,5,2,4,2,5,5,5,2,1,2,9,1,1
1,1,1,1,1,1,1,1,1,1,1,1,1,1,1,1,1,1,1,1,1,1,1,1,3,3,1,1,1,1,1,1,1,1,1,1,1,1,1,1,1,1,1,1,1,1,1,1
endlayer

layer
1,1,1,1,1,1,3,3,3,1,1,1,3,3,3,1,1,1,1,1,1,1,3,3,3,3,1,3,3,3,1,1,1,3,3,3,1,1,1,3,3,3,1,1,1,1,1,1
1,1,2,2,4,2,31,4,31,2,4,2,31,4,31,2,4,4,4,4,4,2,4,2,2,4,2,31,4,31,2,4,2,31,4,31,2,4,2,31,4,31,2,4,2,2,1,1
1,2,6,19,0,0,0,0,0,0,0,0,0,0,0,2,0,0,0,0,0,2,0,0,0,0,0,0,0,0,0,0,0,0,0,0,0,0,0,0,0,0,0,0,19,6,2,1
1,2,19,2,0,0,0,0,0,0,0,0,0,0,0,0,0,0,0,0,0,0,0,0,0,0,0,0,0,0,0,0,0,0,0,0,0,0,0,19,0,0,0,0,2,19,2,1
1,4,0,0,0,0,0,0,0,0,0,0,0,0,0,0,0,0,0,0,0,0,0,13,13,0,16,16,0,0,0,0,0,0,0,0,0,0,19,40,19,0,0,0,0,0,4,3
1,2,0,0,0,0,0,0,0,0,0,0,0,0,0,0,0,0,0,0,0,0,0,13,0,0,16,16,0,16,16,0,0,0,0,0,0,0,0,19,0,0,0,0,0,0,2,1
3,31,0,0,0,0,0,0,0,0,0,0,0,0,0,0,0,0,0,0,0,0,0,0,0,0,16,16,0,16,16,0,0,0,0,0,0,0,0,0,0,0,0,0,0,0,31,3
3,4,0,0,0,0,0,0,0,0,0,0,0,0,0,0,0,0,0,0,0,0,0,0,0,0,0,0,0,16,16,0,0,0,0,0,0,0,0,0,0,0,0,19,0,0,4,3
3,31,0,0,20,0,20,0,0,0,0,0,0,0,0,0,0,0,0,0,0,0,0,0,0,0,0,0,0,0,0,0,0,0,0,19,0,0,0,19,0,0,19,40,19,0,31,3
1,2,0,0,0,0,0,0,31,0,0,0,7,0,0,31,0,0,0,0,0,0,0,0,0,0,0,0,0,0,0,0,0,0,0,19,0,0,0,19,0,0,0,19,0,0,2,1
3,4,0,0,20,0,20,0,0,0,0,0,0,0,0,0,0,0,0,0,0,0,0,0,0,0,0,0,0,0,0,0,0,0,0,31,0,0,0,31,0,0,0,0,0,0,4,3
1,2,0,0,0,0,0,0,0,0,0,0,0,0,0,0,0,0,0,0,0,0,0,0,0,0,0,0,0,0,41,0,0,0,0,3,8,8,8,3,0,0,0,19,0,0,2,1
3,31,0,0,20,0,20,0,0,0,0,0,0,0,0,0,0,0,0,0,0,0,0,0,0,0,0,0,0,41,42,41,0,0,0,3,21,21,21,3,0,0,19,40,19,0,31,3
3,4,0,0,0,0,0,0,31,0,19,0,31,0,0,31,0,0,0,0,0,0,0,0,0,0,0,0,0,0,41,0,0,0,0,19,0,0,0,0,0,0,0,19,0,0,4,3
3,31,0,0,20,0,20,0,0,0,19,0,0,0,0,0,0,0,0,0,0,0,0,0,19,19,19,0,0,0,0,0,0,0,0,19,0,0,0,0,0,0,0,0,0,0,31,3
1,2,0,0,0,0,0,0,0,41,43,41,0,0,0,0,0,0,0,0,0,0,0,19,19,0,19,19,0,0,0,0,0,0,0,19,0,0,0,0,0,0,0,0,0,0,2,1
3,4,0,0,0,2,0,0,0,0,43,0,0,0,0,0,0,0,0,0,0,0,0,19,0,11,0,19,0,0,0,0,0,0,0,31,0,0,0,31,0,0,0,0,0,2,1,1
1,2,0,0,0,44,0,0,0,41,43,41,0,0,0,0,2,0,0,0,0,0,0,19,19,0,19,19,0,0,0,0,0,0,0,0,0,0,0,0,0,0,0,0,0,0,4,1
3,31,0,0,0,46,0,0,0,0,19,0,0,0,0,2,45,2,0,0,0,0,0,0,19,19,19,0,0,0,0,29,29,0,0,0,0,0,0,0,0,0,0,0,0,0,4,1
3,4,0,0,12,46,0,0,31,0,19,0,31,0,0,14,11,14,0,0,0,0,0,0,0,0,0,0,0,0,0,29,29,0,0,0,0,0,0,0,0,0,0,0,0,0,4,1
3,31,0,0,0,44,0,0,0,0,0,0,0,0,30,2,45,2,25,0,0,0,0,0,0,0,0,0,0,0,0,29,29,0,0,0,0,0,0,0,0,0,0,0,0,0,4,1
1,2,0,0,0,0,0,0,0,0,0,0,0,0,0,14,45,14,0,0,0,0,0,0,19,19,19,0,0,0,0,0,0,0,0,0,0,0,0,0,0,0,0,0,0,0,4,1
3,4,0,0,0,0,0,0,0,0,0,0,0,0,30,2,45,2,25,0,0,0,0,19,19,0,19,19,0,0,0,0,0,0,0,31,0,0,0,31,0,0,0,0,0,2,1,3
1,2,0,0,0,0,0,0,0,0,0,0,0,0,0,2,11,2,0,0,0,0,0,19,0,11,0,19,0,0,0,0,0,0,0,0,0,0,0,0,0,0,0,0,0,0,2,1
1,2,0,0,0,0,0,0,0,0,0,0,0,0,0,19,2,19,0,0,0,0,0,19,19,0,19,19,0,0,0,0,0,0,0,19,0,47,0,19,0,0,0,0,0,0,2,1
3,1,2,0,0,0,0,0,31,0,0,0,31,0,0,2,19,2,0,0,0,0,0,0,19,19,19,0,0,0,0,0,0,0,0,19,0,42,0,19,0,0,0,0,0,0,4,3
1,4,0,0,0,0,0,0,0,0,0,0,0,0,0,31,0,31,0,0,0,0,0,0,0,0,0,0,0,0,0,0,0,0,0,19,0,42,0,19,0,0,0,0,0,0,2,1
1,4,0,0,0,0,0,0,0,0,0,0,0,0,0,0,0,0,0,0,0,0,0,0,0,0,0,0,0,0,0,0,0,0,0,19,0,42,0,19,0,0,0,0,0,0,31,3
1,4,0,0,0,0,0,0,0,0,0,0,0,0,0,0,0,0,0,0,0,0,0,0,0,32,32,32,32,0,0,0,0,0,0,31,0,47,0,31,0,0,0,0,0,0,4,3
1,4,0,0,0,0,0,0,0,0,0,0,0,0,0,0,0,0,0,0,0,0,0,0,0,2,14,14,2,0,0,0,0,0,0,0,0,0,0,0,0,0,0,0,0,0,31,3
1,4,0,0,0,0,0,0,0,0,0,0,0,0,0,0,0,0,0,0,0,19,19,19,19,4,43,43,2,0,0,0,0,0,0,0,0,0,0,34,34,0,0,0,0,0,2,1
1,1,2,0,0,0,0,0,31,0,0,0,31,0,0,0,0,0,0,0,0,0,0,0,0,0,0,0,48,0,0,0,0,0,0,0,0,0,0,34,34,0,0,0,0,0,4,3
1,2,0,0,0,0,0,0,0,0,0,0,0,0,0,0,0,0,0,0,0,0,0,0,0,0,0,0,0,0,0,0,0,0,0,0,0,0,0,0,0,0,0,0,0,0,2,1
3,31,0,0,10,10,0,0,0,0,8,0,0,0,38,0,0,0,0,0,0,0,0,0,0,0,0,0,0,0,0,0,0,0,0,0,0,0,0,0,0,0,0,0,0,0,31,3
3,4,0,0,10,10,0,0,0,0,0,0,0,0,0,38,0,0,0,0,0,0,0,0,0,0,0,0,0,0,0,0,0,0,0,7,3,0,0,31,0,0,0,0,0,0,4,3
3,31,0,0,10,10,0,0,3,21,21,21,3,0,37,0,0,0,0,0,0,0,0,0,0,0,0,0,0,0,0,0,0,0,0,0,0,0,0,0,0,0,0,0,0,0,31,3
1,2,0,0,0,0,0,0,3,8,8,8,3,0,0,0,0,0,0,0,0,0,0,0,0,0,0,0,0,0,0,0,0,0,0,0,0,0,16,16,0,0,0,0,0,0,2,1
3,4,0,0,0,0,0,0,31,0,0,0,31,0,0,0,0,0,0,0,12,0,7,0,0,0,0,0,0,0,0,0,0,0,0,0,0,0,16,16,0,0,0,0,0,0,4,3
1,2,0,0,0,0,0,0,19,0,0,0,19,0,0,0,0,0,0,0,0,0,0,0,0,0,0,0,0,0,0,0,0,0,0,0,0,0,0,0,0,13,13,0,0,0,2,1
3,31,0,0,0,0,0,0,19,0,0,0,19,0,0,0,0,0,0,0,0,0,0,0,0,0,0,0,0,0,0,0,0,0,0,0,39,39,39,39,0,0,13,13,0,0,31,3
3,4,0,0,0,0,0,0,0,0,0,0,0,0,41,0,41,0,41,0,41,0,0,0,0,0,0,0,0,0,0,0,0,0,0,0,39,39,39,39,0,0,0,0,0,0,4,3
3,31,0,0,0,0,0,0,0,0,0,0,0,0,22,42,42,42,42,42,22,0,0,0,0,0,0,0,0,0,0,0,0,0,0,0,39,39,39,39,0,0,0,0,0,0,31,3
1,2,0,0,0,0,0,34,34,34,0,0,0,0,41,0,41,0,41,0,41,0,0,0,0,0,0,0,0,0,0,0,0,0,0,0,0,0,0,0,0,0,0,0,0,0,2,1
3,4,0,0,0,0,0,34,34,34,0,0,0,0,0,0,0,0,0,0,0,0,0,0,0,0,0,0,0,0,0,0,0,0,0,0,0,0,0,0,0,0,0,0,0,0,4,1
1,2,19,2,0,0,0,0,0,0,0,0,0,0,0,0,0,0,0,0,0,0,0,0,0,0,0,0,0,0,0,0,0,0,0,0,0,0,0,0,0,0,0,0,2,19,2,1
1,2,6,19,0,0,0,0,0,0,0,0,0,0,0,0,0,0,0,0,0,0,0,0,0,0,2,0,0,0,0,0,2,0,0,0,0,0,0,0,0,0,0,0,19,6,2,1
1,1,2,2,4,2,31,4,31,2,4,2,31,4,31,2,4,2,31,4,31,2,4,2,2,4,2,4,4,4,4,4,2,31,4,31,2,4,2,31,4,31,2,4,2,2,1,1
1,1,1,1,1,1,3,3,3,1,1,1,3,3,3,1,1,1,3,3,3,1,1,1,3,3,1,1,1,1,1,1,1,3,3,3,1,1,1,3,3,3,1,1,1,1,1,1
endlayer

layer
1,1,1,1,3,1,1,9,1,1,3,1,1,9,1,1,1,1,1,1,1,1,3,3,3,3,1,1,9,1,1,3,1,1,9,1,1,3,1,1,9,1,1,3,1,1,1,1
1,1,2,2,21,2,4,19,4,2,21,2,4,19,4,2,4,4,4,4,4,2,21,2,2,21,2,4,19,4,2,21,2,4,19,4,2,21,2,4,19,4,2,21,2,2,1,1
1,2,6,19,0,0,0,0,0,0,0,0,0,0,0,2,0,0,0,0,0,2,0,0,0,0,0,0,0,0,0,0,0,0,0,0,0,0,0,0,0,0,0,0,19,6,2,1
1,2,19,2,0,0,0,0,0,0,0,0,0,0,0,0,0,0,0,0,0,0,0,0,0,0,0,0,0,0,0,0,0,0,0,0,0,0,0,19,0,0,0,0,2,19,2,1
3,21,0,0,0,0,0,0,0,0,0,0,0,0,0,0,0,0,0,0,0,0,0,0,0,0,0,0,0,0,0,0,0,0,0,0,0,0,19,40,19,0,0,0,0,0,21,3
1,2,0,0,0,0,0,0,0,0,0,0,0,0,0,0,0,0,0,0,0,0,0,0,0,0,0,0,0,0,0,0,0,0,0,0,0,0,0,19,0,0,0,0,0,0,2,1
1,4,0,0,0,0,0,0,0,0,0,0,0,0,0,0,0,0,0,0,0,0,0,0,0,0,0,0,0,0,0,0,0,0,0,0,0,0,0,0,0,0,0,0,0,0,4,1
9,19,0,0,0,0,0,0,0,0,0,0,0,0,0,0,0,0,0,0,0,0,0,0,0,0,0,0,0,0,0,0,0,0,0,0,0,0,0,0,0,0,0,19,0,0,19,9
1,4,0,0,0,0,0,0,0,0,0,0,0,0,0,0,0,0,0,0,0,0,0,0,0,0,0,0,0,0,0,0,0,0,0,0,0,0,0,0,0,0,19,40,19,0,4,1
1,2,0,0,0,0,0,0,31,0,0,0,7,0,0,31,0,0,0,0,0,0,0,0,0,0,0,0,0,0,0,0,0,0,0,0,0,0,0,0,0,0,0,19,0,0,2,1
3,21,0,0,0,0,0,0,0,0,0,0,0,0,0,0,0,0,0,0,0,0,0,0,0,0,0,0,0,0,0,0,0,0,0,0,0,0,0,0,0,0,0,0,0,0,21,3
1,2,0,0,0,0,0,0,0,0,0,0,0,0,0,0,0,0,0,0,0,0,0,0,0,0,0,0,0,0,0,0,0,0,0,19,0,0,0,19,0,0,0,19,0,0,2,1
1,4,0,0,0,0,0,0,0,0,0,0,0,0,0,0,0,0,0,0,0,0,0,0,0,0,0,0,0,0,0,0,0,0,0,19,0,0,0,19,0,0,19,40,19,0,4,1
9,19,0,0,0,0,0,0,31,0,19,0,31,0,0,31,0,0,0,0,0,0,0,0,0,0,0,0,0,0,0,0,0,0,0,3,8,8,8,3,0,0,0,19,0,0,19,9
1,4,0,0,0,0,0,0,0,0,19,0,0,0,0,0,0,0,0,0,0,0,0,0,19,19,19,0,0,0,0,0,0,0,0,3,21,21,21,3,0,0,0,0,0,0,4,1
1,2,0,0,0,0,0,0,0,0,43,0,0,0,0,0,0,0,0,0,0,0,0,19,19,0,19,19,0,0,0,0,0,0,0,19,0,0,0,0,0,0,0,0,0,0,2,1
3,21,0,0,0,2,0,0,0,0,43,0,0,0,0,0,0,0,0,0,0,0,0,19,0,0,0,19,0,0,0,0,0,0,0,31,0,0,0,31,0,0,0,0,0,2,1,1
1,2,0,0,0,0,0,0,0,0,43,0,0,0,0,0,0,0,0,0,0,0,0,19,19,0,19,19,0,0,0,0,0,0,0,0,0,0,0,0,0,0,0,0,0,0,4,1
1,4,0,0,0,0,0,0,0,0,19,0,0,0,0,0,2,0,0,0,0,0,0,0,19,19,19,0,0,0,0,0,0,0,0,0,0,0,0,0,0,0,0,0,0,0,4,1
9,19,0,0,12,0,0,0,31,0,19,0,31,0,0,0,14,0,0,0,0,0,0,0,0,0,0,0,0,0,0,0,0,0,0,0,0,0,0,0,0,0,0,0,0,0,4,1
1,4,0,0,0,0,0,0,0,0,0,0,0,0,0,0,2,0,0,0,0,0,0,0,0,0,0,0,0,0,0,0,0,0,0,0,0,0,0,0,0,0,0,0,0,0,4,1
1,2,0,0,0,0,0,0,0,0,0,0,0,0,0,0,14,0,0,0,0,0,0,0,19,19,19,0,0,0,0,0,0,0,0,0,0,0,0,0,0,0,0,0,0,0,4,1
3,21,0,0,0,0,0,0,0,0,0,0,0,0,0,0,2,0,0,0,0,0,0,19,19,0,19,19,0,0,0,0,0,0,0,31,0,0,0,31,0,0,0,0,0,2,1,3
1,2,0,0,0,0,0,0,0,0,0,0,0,0,0,0,14,0,0,0,0,0,0,19,0,0,0,19,0,0,0,0,0,0,0,0,0,0,0,0,0,0,0,0,0,0,2,1
1,2,0,0,0,0,0,0,0,0,0,0,0,0,0,0,19,0,0,0,0,0,0,19,19,0,19,19,0,0,0,0,0,0,0,19,0,0,0,19,0,0,0,0,0,0,2,1
3,1,2,0,0,0,0,0,31,0,0,0,31,0,0,0,2,0,0,0,0,0,0,0,19,19,19,0,0,0,0,0,0,0,0,19,0,0,0,19,0,0,0,0,0,0,21,3
1,4,0,0,0,0,0,0,0,0,0,0,0,0,0,0,31,0,0,0,0,0,0,0,0,0,0,0,0,0,0,0,0,0,0,19,0,0,0,19,0,0,0,0,0,0,2,1
1,4,0,0,0,0,0,0,0,0,0,0,0,0,0,0,0,0,0,0,0,0,0,0,0,0,0,0,0,0,0,0,0,0,0,19,0,0,0,19,0,0,0,0,0,0,4,1
1,4,0,0,0,0,0,0,0,0,0,0,0,0,0,0,0,0,0,0,0,0,0,0,0,32,23,49,32,0,0,0,0,0,0,31,0,0,0,31,0,0,0,0,0,0,19,9
1,4,0,0,0,0,0,0,0,0,0,0,0,0,0,0,0,0,0,0,0,0,0,0,0,2,14,14,2,0,0,0,0,0,0,0,0,0,0,0,0,0,0,0,0,0,4,1
1,4,0,0,0,0,0,0,0,0,0,0,0,0,0,0,0,0,0,0,0,19,19,19,19,4,43,43,2,0,0,0,0,0,0,0,0,0,0,0,0,0,0,0,0,0,2,1
1,1,2,0,0,0,0,0,31,0,0,0,31,0,0,0,0,0,0,0,0,0,0,0,0,35,0,0,0,0,0,0,0,0,0,0,0,0,0,0,0,0,0,0,0,0,21,3
1,2,0,0,0,0,0,0,0,0,0,0,0,0,0,0,0,0,0,0,0,0,0,0,0,0,0,0,0,0,0,0,0,0,0,0,0,0,0,0,0,0,0,0,0,0,2,1
1,4,0,0,0,0,0,0,3,21,21,21,3,0,0,0,0,0,0,0,0,0,0,0,0,0,0,0,0,0,0,0,0,0,0,0,0,0,0,0,0,0,0,0,0,0,4,1
9,19,0,0,0,0,0,0,3,8,8,8,3,0,0,38,0,0,0,0,0,0,0,0,0,0,0,0,0,0,0,0,0,0,0,7,3,0,0,31,0,0,0,0,0,0,19,9
1,4,0,0,0,0,0,0,19,0,0,0,19,0,0,0,0,0,0,0,0,0,0,0,0,0,0,0,0,0,0,0,0,0,0,0,0,0,0,0,0,0,0,0,0,0,4,1
1,2,0,0,0,0,0,0,19,0,0,0,19,0,0,0,0,0,0,0,0,0,0,0,0,0,0,0,0,0,0,0,0,0,0,0,0,0,0,0,0,0,0,0,0,0,2,1
3,21,0,0,0,0,0,0,0,0,0,0,0,0,0,0,0,0,0,0,12,0,7,0,0,0,0,0,0,0,0,0,0,0,0,0,0,0,0,0,0,0,0,0,0,0,21,3
1,2,0,0,0,0,0,0,0,0,0,0,0,0,0,0,0,0,0,0,0,0,0,0,0,0,0,0,0,0,0,0,0,0,0,0,0,0,0,0,0,0,0,0,0,0,2,1
1,4,0,0,0,0,0,0,0,0,0,0,0,0,0,0,0,0,0,0,0,0,0,0,0,0,0,0,0,0,0,0,0,0,0,0,39,39,39,39,0,0,0,0,0,0,4,1
9,19,0,0,0,0,0,0,0,0,0,0,0,0,0,0,0,0,0,0,0,0,0,0,0,0,0,0,0,0,0,0,0,0,0,0,39,39,39,39,0,0,0,0,0,0,19,9
1,4,0,0,0,0,0,0,0,0,0,0,0,0,0,0,0,0,0,0,0,0,0,0,0,0,0,0,0,0,0,0,0,0,0,0,39,39,39,39,0,0,0,0,0,0,4,1
1,2,0,0,0,0,0,0,0,0,0,0,0,0,0,0,0,0,0,0,0,0,0,0,0,0,0,0,0,0,0,0,0,0,0,0,0,0,0,0,0,0,0,0,0,0,2,1
3,21,0,0,0,0,0,0,0,0,0,0,0,0,0,0,0,0,0,0,0,0,0,0,0,0,0,0,0,0,0,0,0,0,0,0,0,0,0,0,0,0,0,0,0,0,21,3
1,2,19,2,0,0,0,0,0,0,0,0,0,0,0,0,0,0,0,0,0,0,0,0,0,0,0,0,0,0,0,0,0,0,0,0,0,0,0,0,0,0,0,0,2,19,2,1
1,2,6,19,0,0,0,0,0,0,0,0,0,0,0,0,0,0,0,0,0,0,0,0,0,0,2,0,0,0,0,0,2,0,0,0,0,0,0,0,0,0,0,0,19,6,2,1
1,1,2,2,21,2,4,19,4,2,21,2,4,19,4,2,21,2,4,19,4,2,21,2,2,21,2,4,4,4,4,4,2,4,19,4,2,21,2,4,19,4,2,21,2,2,1,1
1,1,1,1,3,1,1,9,1,1,3,1,1,9,1,1,3,1,1,9,1,1,3,1,3,3,1,1,1,1,1,1,1,1,9,1,1,3,1,1,9,1,1,3,1,1,1,1
endlayer

layer
1,1,1,1,3,1,3,3,3,1,3,1,3,3,3,1,3,1,1,1,1,1,3,3,3,3,1,3,3,3,1,3,1,3,3,3,1,3,1,3,3,3,1,3,1,1,1,1
1,1,2,2,21,2,31,4,31,2,21,2,31,4,31,2,21,1,1,1,1,2,21,2,2,21,2,31,4,31,2,21,2,31,4,31,2,21,2,31,4,31,2,21,2,2,1,1
1,2,6,19,0,0,0,0,0,0,0,0,0,0,0,2,2,2,2,2,2,2,0,0,0,0,0,0,0,0,0,0,0,0,0,0,0,0,0,0,0,0,0,0,19,6,2,1
1,2,19,2,0,0,0,0,0,0,0,0,0,0,0,0,0,0,0,0,0,0,0,0,0,0,0,0,0,0,0,0,0,0,0,0,0,0,0,19,0,0,0,0,2,19,2,1
3,21,0,0,0,0,0,0,0,0,0,0,0,0,0,0,0,0,0,0,0,0,0,0,0,0,0,0,0,0,0,0,0,0,0,0,0,0,19,40,19,0,0,0,0,0,21,3
1,2,0,0,0,0,0,0,0,0,0,0,0,0,0,0,0,0,0,0,0,0,0,0,0,0,0,0,0,0,0,0,0,0,0,0,0,0,0,19,0,0,0,0,0,0,2,1
3,31,0,0,0,0,0,0,0,0,0,0,0,0,0,0,0,0,0,0,0,0,0,0,0,0,0,0,0,0,0,0,0,0,0,0,0,0,0,0,0,0,0,0,0,0,31,3
3,4,0,0,0,0,0,0,0,0,0,0,0,0,0,0,0,0,0,0,0,0,0,0,0,0,0,0,0,0,0,0,0,0,0,0,0,0,0,0,0,0,0,19,0,0,4,3
3,31,0,0,0,0,0,0,0,0,0,0,0,0,0,0,0,0,0,0,0,0,0,0,0,0,0,0,0,0,0,0,0,0,0,0,0,0,0,0,0,0,19,40,19,0,31,3
1,2,0,0,0,0,0,0,4,21,21,21,7,21,21,4,0,0,0,0,0,0,0,0,0,0,0,0,0,0,0,0,0,0,0,0,0,0,0,0,0,0,0,19,0,0,2,1
3,21,0,0,0,0,0,0,21,21,21,21,21,21,21,21,0,0,0,0,0,0,0,0,0,0,0,0,0,0,0,0,0,0,0,0,0,0,0,0,0,0,0,0,0,0,21,3
1,2,0,0,0,0,0,0,21,21,21,21,21,21,21,21,0,0,0,0,0,0,0,0,0,0,0,0,0,0,0,0,0,0,0,0,0,0,0,0,0,0,0,19,0,0,2,1
3,31,0,0,0,0,0,0,21,21,21,21,21,21,21,21,0,0,0,0,0,0,0,0,0,0,0,0,0,0,0,0,0,0,0,0,0,0,0,0,0,0,19,40,19,0,31,3
3,4,0,0,0,0,0,0,4,21,21,21,4,21,21,4,0,0,0,0,0,0,0,0,0,0,0,0,0,0,0,0,0,0,0,19,0,0,0,19,0,0,0,19,0,0,4,3
3,31,0,0,0,0,0,0,21,21,21,21,21,0,0,0,0,0,0,0,0,0,0,0,19,19,19,0,0,0,0,0,0,0,0,19,0,0,0,19,0,0,0,0,0,0,31,3
1,2,0,0,0,0,0,0,21,21,21,21,21,0,0,0,0,0,0,0,0,0,0,19,19,0,19,19,0,0,0,0,0,0,0,3,8,8,8,3,0,0,0,0,0,0,2,1
3,21,0,0,0,2,25,0,21,21,21,21,21,0,0,0,0,0,0,0,0,0,0,19,0,0,0,19,0,0,0,0,0,0,0,4,21,21,21,4,0,0,0,0,0,2,21,3
1,2,0,0,0,0,0,0,21,21,21,21,21,0,0,0,0,0,0,0,0,0,0,19,19,0,19,19,0,0,0,0,0,0,0,21,21,21,21,21,0,0,0,0,0,2,1,1
3,31,0,0,0,0,0,0,21,21,21,21,21,0,0,0,0,0,0,0,0,0,0,0,19,19,19,0,0,0,0,0,0,0,0,21,21,21,21,21,0,0,0,0,0,2,1,1
3,4,0,0,12,0,0,0,4,21,21,21,4,0,0,0,0,0,0,0,0,0,0,0,0,0,0,0,0,0,0,0,0,0,0,21,21,21,21,21,0,0,0,0,0,2,1,1
3,31,0,0,0,0,0,0,21,21,21,21,21,0,0,0,50,0,0,0,0,0,0,0,0,0,0,0,0,0,0,0,0,0,0,21,21,21,21,21,0,0,0,0,0,2,1,1
1,2,0,0,0,0,0,0,21,21,21,21,21,0,0,0,0,0,0,0,0,0,0,0,19,19,19,0,0,0,0,0,0,0,0,21,21,21,21,21,0,0,0,0,0,2,1,1
3,21,0,0,0,0,0,0,21,21,21,21,21,0,0,0,50,0,0,0,0,0,0,19,19,0,19,19,0,0,0,0,0,0,0,4,21,21,21,4,0,0,0,0,0,2,21,3
1,2,0,0,0,0,0,0,21,21,21,21,21,0,0,0,0,0,0,0,0,0,0,19,0,0,0,19,0,0,0,0,0,0,0,21,21,21,21,21,0,0,0,0,0,0,2,1
1,2,0,0,0,0,0,0,21,21,21,21,21,0,0,0,0,0,0,0,0,0,0,19,19,0,19,19,0,0,0,0,0,0,0,21,21,21,21,21,0,0,0,0,0,0,2,1
3,21,2,0,0,0,0,0,4,21,21,21,4,0,0,0,0,0,0,0,0,0,0,0,19,19,19,0,0,0,0,0,0,0,0,21,21,21,21,21,0,0,0,0,0,0,21,3
1,1,2,0,0,0,0,0,21,21,21,21,21,0,0,0,0,0,0,0,0,0,0,0,0,0,0,0,0,0,0,0,0,0,0,21,21,21,21,21,0,0,0,0,0,0,2,1
1,1,2,0,0,0,0,0,21,21,21,21,21,0,0,0,0,0,0,0,0,0,0,0,0,0,0,0,0,0,0,0,0,0,0,21,21,21,21,21,0,0,0,0,0,0,31,3
1,1,2,0,0,0,0,0,21,21,21,21,21,0,0,0,0,0,0,0,0,0,0,0,0,0,0,0,0,0,0,0,0,0,0,4,21,21,21,4,0,0,0,0,0,0,4,3
1,1,2,0,0,0,0,0,21,21,21,21,21,0,0,0,0,0,0,0,0,0,0,0,0,0,0,0,0,0,0,0,0,0,0,21,21,21,21,21,0,0,0,0,0,0,31,3
1,1,2,0,0,0,0,0,21,21,21,21,21,0,0,0,0,0,0,0,0,0,0,0,0,4,0,0,0,0,0,0,0,0,0,21,21,21,21,21,0,0,0,0,0,0,2,1
3,21,2,0,0,0,0,0,4,21,21,21,4,0,0,0,0,0,0,0,0,0,0,0,0,0,0,0,0,0,0,0,0,0,0,21,21,21,21,21,0,0,0,0,0,0,21,3
1,2,0,0,0,0,0,0,3,8,8,8,3,0,0,0,0,0,0,0,0,0,0,0,0,0,0,0,0,0,0,0,0,0,0,21,21,21,21,21,0,0,0,0,0,0,2,1
3,31,0,0,0,0,0,0,19,0,0,0,19,0,0,0,0,0,0,0,0,0,0,0,0,0,0,0,0,0,0,0,0,0,0,21,0,21,21,21,0,0,0,0,0,0,31,3
3,4,0,0,0,0,0,0,19,0,0,0,19,0,0,0,0,0,0,0,0,0,0,0,0,0,0,0,0,0,0,0,0,0,0,7,3,21,21,4,0,0,0,0,0,0,4,3
3,31,0,0,0,0,0,0,0,0,0,0,0,0,0,0,0,0,0,0,0,0,0,0,0,0,0,0,0,0,0,0,0,0,0,0,0,0,0,0,0,0,0,0,0,0,31,3
1,2,0,0,0,0,0,0,0,0,0,0,0,0,0,0,0,0,0,0,0,0,0,0,0,0,0,0,0,0,0,0,0,0,0,0,0,0,0,0,0,0,0,0,0,0,2,1
3,21,0,0,0,0,0,0,0,0,0,0,0,0,0,0,0,0,0,0,12,0,7,0,0,0,0,0,0,0,0,0,0,0,0,0,0,0,0,0,0,0,0,0,0,0,21,3
1,2,0,0,0,0,0,0,0,0,0,0,0,0,0,0,0,0,0,0,0,0,0,0,0,0,0,0,0,0,0,0,0,0,0,0,0,0,0,0,0,0,0,0,0,0,2,1
3,31,0,0,0,0,0,0,0,0,0,0,0,0,0,0,0,0,0,0,0,0,0,0,0,0,0,0,0,0,0,0,0,0,0,0,0,0,0,0,0,0,0,0,0,0,31,3
3,4,0,0,0,0,0,0,0,0,0,0,0,0,0,0,0,0,0,0,0,0,0,0,0,0,0,0,0,0,0,0,0,0,0,0,0,0,0,0,0,0,0,0,0,0,4,3
3,31,0,0,0,0,0,0,0,0,0,0,0,0,0,0,0,0,0,0,0,0,0,0,0,0,0,0,0,0,0,0,0,0,0,0,0,0,0,0,0,0,0,0,0,0,31,3
1,2,0,0,0,0,0,0,0,0,0,0,0,0,0,0,0,0,0,0,0,0,0,0,0,0,0,0,0,0,0,0,0,0,0,0,0,0,0,0,0,0,0,0,0,0,2,1
3,21,0,0,0,0,0,0,0,0,0,0,0,0,0,0,0,0,0,0,0,0,0,0,0,0,0,0,0,0,0,0,0,0,0,0,0,0,0,0,0,0,0,0,0,0,21,3
1,2,19,2,0,0,0,0,0,0,0,0,0,0,0,0,0,0,0,0,0,0,0,0,0,0,0,0,0,0,0,0,0,0,0,0,0,0,0,0,0,0,0,0,2,19,2,1
1,2,6,19,0,0,0,0,0,0,0,0,0,0,0,0,0,0,0,0,0,0,0,0,0,0,2,2,2,2,2,2,2,0,0,0,0,0,0,0,0,0,0,0,19,6,2,1
1,1,2,2,21,2,31,4,31,2,21,2,31,4,31,2,21,2,31,4,31,2,21,2,2,21,2,1,1,1,1,21,2,31,4,31,2,21,2,31,4,31,2,21,2,2,1,1
1,1,1,1,3,1,3,3,3,1,3,1,3,3,3,1,3,1,3,3,3,1,3,1,3,3,1,1,1,1,1,3,1,3,3,3,1,3,1,3,3,3,1,3,1,1,1,1
endlayer

layer
1,1,1,1,3,1,2,2,2,1,3,1,2,2,2,1,3,1,2,2,2,1,3,3,3,3,1,2,2,2,1,3,1,2,2,2,1,3,1,2,2,2,1,3,1,1,1,1
1,1,9,4,21,4,4,2,4,4,21,4,4,2,4,4,21,4,4,2,4,4,21,4,4,21,4,4,2,4,4,21,4,4,2,4,4,21,4,4,2,4,4,21,4,9,1,1
1,9,6,2,0,0,0,0,0,0,0,0,0,0,0,0,0,0,0,0,0,0,0,0,0,0,0,0,0,0,0,0,0,0,0,0,0,0,0,0,0,0,0,0,2,6,9,1
1,4,2,4,0,0,0,0,0,0,0,0,0,0,0,0,0,0,0,0,0,0,0,0,0,0,0,0,0,0,0,0,0,0,0,0,0,0,0,2,0,0,0,0,4,2,4,1
3,21,0,0,0,0,0,0,0,0,0,0,0,0,0,0,0,0,0,0,0,0,0,0,0,0,0,0,0,0,0,0,0,0,0,0,0,0,2,15,2,0,0,0,0,0,21,3
1,4,0,0,0,0,0,0,0,0,0,0,0,0,0,0,0,0,0,0,0,0,0,0,0,0,0,0,0,0,0,0,0,0,0,0,0,0,0,2,0,0,0,0,0,0,4,1
2,4,0,0,0,0,0,0,0,0,0,0,0,0,0,0,0,0,0,0,0,0,0,0,0,0,0,0,0,0,0,0,0,0,0,0,0,0,0,0,0,0,0,0,0,0,4,2
2,2,0,0,0,0,0,0,0,0,0,0,0,0,0,0,0,0,0,0,0,0,0,0,0,0,0,0,0,0,0,0,0,0,0,0,0,0,0,0,0,0,0,2,0,0,2,2
2,4,0,0,0,0,0,0,0,0,0,0,0,0,0,0,0,0,0,0,0,0,0,0,0,0,0,0,0,0,0,0,0,0,0,0,0,0,0,0,0,0,2,15,2,0,4,2
1,4,0,0,0,0,0,0,22,3,3,3,7,3,3,22,0,0,0,0,0,0,0,0,0,0,0,0,0,0,0,0,0,0,0,0,0,0,0,0,0,0,0,2,0,0,4,1
3,21,0,0,0,0,0,0,3,0,0,0,0,0,0,3,0,0,0,0,0,0,0,0,0,0,0,0,0,0,0,0,0,0,0,0,0,0,0,0,0,0,0,0,0,0,21,3
1,4,0,0,0,0,0,0,3,0,0,0,0,0,0,3,0,0,0,0,0,0,0,0,0,0,0,0,0,0,0,0,0,0,0,0,0,0,0,0,0,0,0,2,0,0,4,1
2,4,0,0,0,0,0,0,3,0,0,0,0,0,0,3,0,0,0,0,0,0,0,0,0,0,0,0,0,0,0,0,0,0,0,0,0,0,0,0,0,0,2,15,2,0,4,2
2,2,0,0,0,0,0,0,22,0,0,0,22,3,3,22,0,0,0,0,0,0,0,0,0,0,0,0,0,0,0,0,0,0,0,0,0,0,0,0,0,0,0,2,0,0,2,2
2,4,0,0,0,0,0,0,3,0,0,0,3,0,0,0,0,0,0,0,0,0,0,0,19,19,19,0,0,0,0,0,0,0,0,0,0,0,0,0,0,0,0,0,0,0,4,2
1,4,0,0,0,0,0,0,3,0,0,0,3,0,0,0,0,0,0,0,0,0,0,19,19,0,19,19,0,0,0,0,0,0,0,19,0,0,0,19,0,0,0,0,0,0,4,1
3,21,0,0,0,2,0,0,3,0,0,0,3,0,0,0,0,0,0,0,0,0,0,19,0,0,0,19,0,0,0,0,0,0,0,22,0,0,0,22,0,0,0,0,0,0,21,3
1,4,0,0,0,0,0,0,3,0,0,0,3,0,0,0,0,0,0,0,0,0,0,19,19,0,19,19,0,0,0,0,0,0,0,3,0,0,0,3,0,0,0,0,0,0,4,1
2,4,0,0,0,0,0,0,3,0,0,0,3,0,0,0,0,0,0,0,0,0,0,0,19,19,19,0,0,0,0,0,0,0,0,3,0,0,0,3,0,0,0,0,0,0,4,2
2,2,0,0,12,0,0,0,22,0,0,0,22,0,0,0,0,0,0,0,0,0,0,0,0,0,0,0,0,0,0,0,0,0,0,3,0,0,0,3,0,0,0,0,0,0,2,2
2,4,0,0,0,0,0,0,3,0,0,0,3,0,0,0,0,0,0,0,0,0,0,0,0,0,0,0,0,0,0,0,0,0,0,3,0,0,0,3,0,0,0,0,0,0,4,2
1,4,0,0,0,0,0,0,3,0,0,0,3,0,0,0,0,0,0,0,0,0,0,0,19,19,19,0,0,0,0,0,0,0,0,3,0,0,0,3,0,0,0,0,0,0,4,1
3,21,0,0,0,0,0,0,3,0,0,0,3,0,0,0,0,0,0,0,0,0,0,19,19,0,19,19,0,0,0,0,0,0,0,22,0,0,0,22,0,0,0,0,0,0,21,3
1,4,0,0,0,0,0,0,3,0,0,0,3,0,0,0,0,0,0,0,0,0,0,19,0,0,0,19,0,0,0,0,0,0,0,3,0,0,0,3,0,0,0,0,0,0,4,1
1,4,0,0,0,0,0,0,3,0,0,0,3,0,0,0,0,0,0,0,0,0,0,19,19,0,19,19,0,0,0,0,0,0,0,3,0,0,0,3,0,0,0,0,0,0,4,1
3,21,0,0,0,0,0,0,22,0,0,0,22,0,0,0,0,0,0,0,0,0,0,0,19,19,19,0,0,0,0,0,0,0,0,3,0,0,0,3,0,0,0,0,0,0,21,3
1,4,0,0,0,0,0,0,3,0,0,0,3,0,0,0,0,0,0,0,0,0,0,0,0,0,0,0,0,0,0,0,0,0,0,3,0,0,0,3,0,0,0,0,0,0,4,1
2,4,0,0,0,0,0,0,3,0,0,0,3,0,0,0,0,0,0,0,0,0,0,0,0,0,0,0,0,0,0,0,0,0,0,3,0,0,0,3,0,0,0,0,0,0,4,2
2,2,0,0,0,0,0,0,3,0,0,0,3,0,0,0,0,0,0,0,0,0,0,0,0,0,0,0,0,0,0,0,0,0,0,22,0,0,0,22,0,0,0,0,0,0,2,2
2,4,0,0,0,0,0,0,3,0,0,0,3,0,0,0,0,0,0,0,0,0,0,0,0,0,0,0,0,0,0,0,0,0,0,3,0,0,0,3,0,0,0,0,0,0,4,2
1,4,0,0,0,0,0,0,3,0,0,0,3,0,0,0,0,0,0,0,0,0,0,0,0,4,0,0,0,0,0,0,0,0,0,3,0,0,0,3,0,0,0,0,0,0,4,1
3,21,0,0,0,0,0,0,22,0,0,0,22,0,0,0,0,0,0,0,0,0,0,0,0,0,0,0,0,0,0,0,0,0,0,3,0,0,0,3,0,0,0,0,0,0,21,3
1,4,0,0,0,0,0,0,19,0,0,0,19,0,0,0,0,0,0,0,0,0,0,0,0,0,0,0,0,0,0,0,0,0,0,3,0,0,0,3,0,0,0,0,0,0,4,1
2,4,0,0,0,0,0,0,0,0,0,0,0,0,0,0,0,0,0,0,0,0,0,0,0,0,0,0,0,0,0,0,0,0,0,3,0,0,0,3,0,0,0,0,0,0,4,2
2,2,0,0,0,0,0,0,0,0,0,0,0,0,0,0,0,0,0,0,0,0,0,0,0,0,0,0,0,0,0,0,0,0,0,7,3,3,3,22,0,0,0,0,0,0,2,2
2,4,0,0,0,0,0,0,0,0,0,0,0,0,0,0,0,0,0,0,0,0,0,0,0,0,0,0,0,0,0,0,0,0,0,0,0,0,0,0,0,0,0,0,0,0,4,2
1,4,0,0,0,0,0,0,0,0,0,0,0,0,0,0,0,0,0,0,0,0,0,0,0,0,0,0,0,0,0,0,0,0,0,0,0,0,0,0,0,0,0,0,0,0,4,1
3,21,0,0,0,0,0,0,0,0,0,0,0,0,0,0,0,0,0,0,12,0,7,0,0,0,0,0,0,0,0,0,0,0,0,0,0,0,0,0,0,0,0,0,0,0,21,3
1,4,0,0,0,0,0,0,0,0,0,0,0,0,0,0,0,0,0,0,0,0,0,0,0,0,0,0,0,0,0,0,0,0,0,0,0,0,0,0,0,0,0,0,0,0,4,1
2,4,0,0,0,0,0,0,0,0,0,0,0,0,0,0,0,0,0,0,0,0,0,0,0,0,0,0,0,0,0,0,0,0,0,0,0,0,0,0,0,0,0,0,0,0,4,2
2,2,0,0,0,0,0,0,0,0,0,0,0,0,0,0,0,0,0,0,0,0,0,0,0,0,0,0,0,0,0,0,0,0,0,0,0,0,0,0,0,0,0,0,0,0,2,2
2,4,0,0,0,0,0,0,0,0,0,0,0,0,0,0,0,0,0,0,0,0,0,0,0,0,0,0,0,0,0,0,0,0,0,0,0,0,0,0,0,0,0,0,0,0,4,2
1,4,0,0,0,0,0,0,0,0,0,0,0,0,0,0,0,0,0,0,0,0,0,0,0,0,0,0,0,0,0,0,0,0,0,0,0,0,0,0,0,0,0,0,0,0,4,1
3,21,0,0,0,0,0,0,0,0,0,0,0,0,0,0,0,0,0,0,0,0,0,0,0,0,0,0,0,0,0,0,0,0,0,0,0,0,0,0,0,0,0,0,0,0,21,3
1,4,2,4,0,0,0,0,0,0,0,0,0,0,0,0,0,0,0,0,0,0,0,0,0,0,0,0,0,0,0,0,0,0,0,0,0,0,0,0,0,0,0,0,4,2,4,1
1,9,6,2,0,0,0,0,0,0,0,0,0,0,0,0,0,0,0,0,0,0,0,0,0,0,0,0,0,0,0,0,0,0,0,0,0,0,0,0,0,0,0,0,2,6,9,1
1,1,9,4,21,4,4,2,4,4,21,4,4,2,4,4,21,4,4,2,4,4,21,4,4,21,4,4,2,4,4,21,4,4,2,4,4,21,4,4,2,4,4,21,4,9,1,1
1,1,1,1,3,1,2,2,2,1,3,1,2,2,2,1,3,1,2,2,2,1,3,1,3,3,1,2,2,2,1,3,1,2,2,2,1,3,1,2,2,2,1,3,1,1,1,1
endlayer

layer
1,1,1,1,3,3,2,6,2,3,3,3,2,6,2,3,3,3,2,6,2,3,3,3,3,3,3,2,6,2,3,3,3,2,6,2,3,3,3,2,6,2,3,3,1,1,1,1
1,1,2,2,21,21,2,19,2,21,21,21,2,19,2,21,21,21,2,19,2,21,21,21,21,21,21,2,19,2,21,21,21,2,19,2,21,21,21,2,19,2,21,21,2,2,1,1
1,2,6,19,0,0,0,0,0,0,0,0,0,0,0,0,0,0,0,0,0,0,0,0,0,0,0,0,0,0,0,0,0,0,0,0,0,0,0,0,0,0,0,0,19,6,2,1
1,2,19,2,0,0,0,0,0,0,0,0,0,0,0,0,0,0,0,0,0,0,0,0,0,0,0,0,0,0,0,0,0,0,0,0,0,0,0,0,0,0,0,0,2,19,2,1
3,21,0,0,0,0,0,0,0,0,0,0,0,0,0,0,0,0,0,0,0,0,0,0,0,0,0,0,0,0,0,0,0,0,0,0,0,0,0,4,0,0,0,0,0,0,21,3
3,21,0,0,0,0,0,0,0,0,0,0,0,0,0,0,0,0,0,0,0,0,0,0,0,0,0,0,0,0,0,0,0,0,0,0,0,0,0,0,0,0,0,0,0,0,21,3
2,2,0,0,0,0,0,0,0,0,0,0,0,0,0,0,0,0,0,0,0,0,0,0,0,0,0,0,0,0,0,0,0,0,0,0,0,0,0,0,0,0,0,0,0,0,2,2
6,19,0,0,0,0,0,0,0,0,0,0,0,0,0,0,0,0,0,0,0,0,0,0,0,0,0,0,0,0,0,0,0,0,0,0,0,0,0,0,0,0,0,0,0,0,19,6
2,2,0,0,0,0,0,0,0,0,0,0,0,0,0,0,0,0,0,0,0,0,0,0,0,0,0,0,0,0,0,0,0,0,0,0,0,0,0,0,0,0,0,4,0,0,2,2
3,21,0,0,0,0,0,0,31,19,19,19,7,19,19,31,0,0,0,0,0,0,0,0,0,0,0,0,0,0,0,0,0,0,0,0,0,0,0,0,0,0,0,0,0,0,21,3
3,21,0,0,0,0,0,0,19,0,0,0,0,0,0,19,0,0,0,0,0,0,0,0,0,0,0,0,0,0,0,0,0,0,0,0,0,0,0,0,0,0,0,0,0,0,21,3
3,21,0,0,0,0,0,0,19,0,0,0,0,0,0,19,0,0,0,0,0,0,0,0,0,0,0,0,0,0,0,0,0,0,0,0,0,0,0,0,0,0,0,0,0,0,21,3
2,2,0,0,0,0,0,0,19,0,0,0,0,0,0,19,0,0,0,0,0,0,0,0,0,0,0,0,0,0,0,0,0,0,0,0,0,0,0,0,0,0,0,4,0,0,2,2
6,19,0,0,0,0,0,0,31,0,0,0,31,19,19,31,0,0,0,0,0,0,0,0,0,0,0,0,0,0,0,0,0,0,0,0,0,0,0,0,0,0,0,0,0,0,19,6
2,2,0,0,0,0,0,0,19,0,0,0,19,0,0,0,0,0,0,0,0,0,0,0,2,2,2,0,0,0,0,0,0,0,0,0,0,0,0,0,0,0,0,0,0,0,2,2
3,21,0,0,0,0,0,0,19,0,0,0,19,0,0,0,0,0,0,0,0,0,0,2,26,26,26,2,0,0,0,0,0,0,0,0,0,0,0,0,0,0,0,0,0,0,21,3
3,21,0,0,0,2,0,0,19,0,0,0,19,0,0,0,0,0,0,0,0,0,0,2,26,26,26,2,0,0,0,0,0,0,0,31,0,0,0,31,0,0,0,0,0,0,21,3
3,21,0,0,0,0,0,0,19,0,0,0,19,0,0,0,0,0,0,0,0,0,0,2,26,26,26,2,0,0,0,0,0,0,0,19,0,0,0,19,0,0,0,0,0,0,21,3
2,2,0,0,0,0,0,0,19,0,0,0,19,0,0,0,0,0,0,0,0,0,0,0,2,2,2,0,0,0,0,0,0,0,0,19,0,0,0,19,0,0,0,0,0,0,2,2
6,19,0,0,12,0,0,0,31,0,0,0,31,0,0,0,0,0,0,0,0,0,0,0,0,0,0,0,0,0,0,0,0,0,0,19,0,0,0,19,0,0,0,0,0,0,19,6
2,2,0,0,0,0,0,0,19,0,0,0,19,0,0,0,0,0,0,0,0,0,0,0,0,0,0,0,0,0,0,0,0,0,0,19,0,0,0,19,0,0,0,0,0,0,2,2
3,21,0,0,0,0,0,0,19,0,0,0,19,0,0,0,0,0,0,0,0,0,0,0,2,2,2,0,0,0,0,0,0,0,0,19,0,0,0,19,0,0,0,0,0,0,21,3
3,21,0,0,0,0,0,0,19,0,0,0,19,0,0,0,0,0,0,0,0,0,0,2,26,26,26,2,0,0,0,0,0,0,0,31,0,0,0,31,0,0,0,0,0,0,21,3
3,21,0,0,0,0,0,0,19,0,0,0,19,0,0,0,0,0,0,0,0,0,0,2,26,26,26,2,0,0,0,0,0,0,0,19,0,0,0,19,0,0,0,0,0,0,21,3
3,21,0,0,0,0,0,0,19,0,0,0,19,0,0,0,0,0,0,0,0,0,0,2,26,26,26,2,0,0,0,0,0,0,0,19,0,0,0,19,0,0,0,0,0,0,21,3
3,21,0,0,0,0,0,0,31,0,0,0,31,0,0,0,0,0,0,0,0,0,0,0,2,2,2,0,0,0,0,0,0,0,0,19,0,0,0,19,0,0,0,0,0,0,21,3
3,21,0,0,0,0,0,0,19,0,0,0,19,0,0,0,0,0,0,0,0,0,0,0,0,0,0,0,0,0,0,0,0,0,0,19,0,0,0,19,0,0,0,0,0,0,21,3
2,2,0,0,0,0,0,0,19,0,0,0,19,0,0,0,0,0,0,0,0,0,0,0,0,0,0,0,0,0,0,0,0,0,0,19,0,0,0,19,0,0,0,0,0,0,2,2
6,19,0,0,0,0,0,0,19,0,0,0,19,0,0,0,0,0,0,0,0,0,0,0,0,0,0,0,0,0,0,0,0,0,0,31,0,0,0,31,0,0,0,0,0,0,19,6
2,2,0,0,0,0,0,0,19,0,0,0,19,0,0,0,0,0,0,0,0,0,0,0,0,0,0,0,0,0,0,0,0,0,0,19,0,0,0,19,0,0,0,0,0,0,2,2
3,21,0,0,0,0,0,0,19,0,0,0,19,0,0,0,0,0,0,0,0,0,0,0,0,4,0,0,0,0,0,0,0,0,0,19,0,0,0,19,0,0,0,0,0,0,21,3
3,21,0,0,0,0,0,0,31,0,0,0,31,0,0,0,0,0,0,0,0,0,0,0,0,0,0,0,0,0,0,0,0,0,0,19,0,0,0,19,0,0,0,0,0,0,21,3
3,21,0,0,0,0,0,0,0,0,0,0,0,0,0,0,0,0,0,0,0,0,0,0,0,0,0,0,0,0,0,0,0,0,0,19,0,0,0,19,0,0,0,0,0,0,21,3
2,2,0,0,0,0,0,0,0,0,0,0,0,0,0,0,0,0,0,0,0,0,0,0,0,0,0,0,0,0,0,0,0,0,0,19,0,0,0,19,0,0,0,0,0,0,2,2
6,19,0,0,0,0,0,0,0,0,0,0,0,0,0,0,0,0,0,0,0,0,0,0,0,0,0,0,0,0,0,0,0,0,0,7,19,19,19,31,0,0,0,0,0,0,19,6
2,2,0,0,0,0,0,0,0,0,0,0,0,0,0,0,0,0,0,0,0,0,0,0,0,0,0,0,0,0,0,0,0,0,0,0,0,0,0,0,0,0,0,0,0,0,2,2
3,21,0,0,0,0,0,0,0,0,0,0,0,0,0,0,0,0,0,0,0,0,0,0,0,0,0,0,0,0,0,0,0,0,0,0,0,0,0,0,0,0,0,0,0,0,21,3
3,21,0,0,0,0,0,0,0,0,0,0,0,0,0,0,0,0,0,0,12,0,7,0,0,0,0,0,0,0,0,0,0,0,0,0,0,0,0,0,0,0,0,0,0,0,21,3
3,21,0,0,0,0,0,0,0,0,0,0,0,0,0,0,0,0,0,0,0,0,0,0,0,0,0,0,0,0,0,0,0,0,0,0,0,0,0,0,0,0,0,0,0,0,21,3
2,2,0,0,0,0,0,0,0,0,0,0,0,0,0,0,0,0,0,0,0,0,0,0,0,0,0,0,0,0,0,0,0,0,0,0,0,0,0,0,0,0,0,0,0,0,2,2
6,19,0,0,0,0,0,0,0,0,0,0,0,0,0,0,0,0,0,0,0,0,0,0,0,0,0,0,0,0,0,0,0,0,0,0,0,0,0,0,0,0,0,0,0,0,19,6
2,2,0,0,0,0,0,0,0,0,0,0,0,0,0,0,0,0,0,0,0,0,0,0,0,0,0,0,0,0,0,0,0,0,0,0,0,0,0,0,0,0,0,0,0,0,2,2
3,21,0,0,0,0,0,0,0,0,0,0,0,0,0,0,0,0,0,0,0,0,0,0,0,0,0,0,0,0,0,0,0,0,0,0,0,0,0,0,0,0,0,0,0,0,21,3
3,21,0,0,0,0,0,0,0,0,0,0,0,0,0,0,0,0,0,0,0,0,0,0,0,0,0,0,0,0,0,0,0,0,0,0,0,0,0,0,0,0,0,0,0,0,21,3
1,2,19,2,0,0,0,0,0,0,0,0,0,0,0,0,0,0,0,0,0,0,0,0,0,0,0,0,0,0,0,0,0,0,0,0,0,0,0,0,0,0,0,0,2,19,2,1
1,2,6,19,0,0,0,0,0,0,0,0,0,0,0,0,0,0,0,0,0,0,0,0,0,0,0,0,0,0,0,0,0,0,0,0,0,0,0,0,0,0,0,0,19,6,2,1
1,1,2,2,21,21,2,19,2,21,21,21,2,19,2,21,21,21,2,19,2,21,21,21,21,21,21,2,19,2,21,21,21,2,19,2,21,21,21,2,19,2,21,21,2,2,1,1
1,1,1,1,3,3,2,6,2,3,3,3,2,6,2,3,3,3,2,6,2,3,3,3,3,3,3,2,6,2,3,3,3,2,6,2,3,3,3,2,6,2,3,3,1,1,1,1
endlayer

layer
1,1,1,1,26,3,2,6,2,3,26,3,2,6,2,3,26,3,2,6,2,3,26,3,3,26,3,2,6,2,3,26,3,2,6,2,3,26,3,2,6,2,3,26,1,1,1,1
1,1,2,2,21,21,2,19,2,21,21,21,2,19,2,21,21,21,2,19,2,21,21,21,21,21,21,2,19,2,21,21,21,2,19,2,21,21,21,2,19,2,21,21,2,2,1,1
1,2,6,19,0,0,0,0,0,0,0,0,0,0,0,0,0,0,0,0,4,0,0,0,0,0,0,0,0,0,0,0,0,0,0,0,0,0,0,0,0,0,0,0,19,6,2,1
1,2,19,2,0,0,0,0,0,0,0,0,0,0,0,0,0,0,0,0,4,0,0,0,0,0,0,0,0,0,0,0,0,0,0,0,0,0,0,0,0,0,0,0,2,19,2,1
26,21,0,0,0,0,0,0,0,0,0,0,0,0,0,0,0,0,0,0,4,4,4,4,4,4,4,4,4,4,4,4,4,4,4,4,4,4,4,4,4,4,4,4,4,4,2,26
3,21,0,0,0,0,0,0,0,0,0,0,0,0,0,0,0,0,0,0,0,0,0,0,0,0,0,0,0,0,0,0,0,0,0,0,0,0,0,35,0,0,0,4,0,0,21,3
2,2,0,0,0,0,0,0,0,0,0,0,0,0,0,0,0,0,0,0,0,0,0,0,0,0,0,0,0,0,0,0,0,0,0,0,0,0,0,0,0,0,0,4,0,0,2,2
6,19,0,0,0,0,0,0,0,0,0,0,0,0,0,0,0,0,0,0,0,0,0,0,0,0,0,0,0,0,0,0,0,0,0,0,0,0,0,0,0,0,0,4,0,0,19,6
2,2,0,0,0,0,0,0,0,0,0,0,0,0,0,0,0,0,0,0,0,0,0,0,0,0,0,0,0,0,0,0,0,0,0,0,0,0,0,0,0,0,0,4,0,0,2,2
3,21,0,0,0,0,0,0,0,0,0,0,7,0,0,0,0,0,0,0,0,0,0,0,0,0,0,0,0,0,0,0,0,0,0,0,0,0,0,0,0,0,0,4,0,0,21,3
26,21,0,0,0,0,0,0,0,0,0,0,0,0,0,0,0,0,0,0,0,0,0,0,0,0,0,0,0,0,0,0,0,0,0,0,0,0,0,0,0,0,0,4,0,0,21,26
3,21,0,0,0,0,0,0,0,0,0,0,0,0,0,0,0,0,0,0,0,0,0,0,0,0,0,0,0,0,0,0,0,0,0,0,0,0,0,0,0,0,0,4,0,0,21,3
2,2,0,0,0,0,0,0,0,0,0,0,0,0,0,0,0,0,0,0,0,0,0,0,0,0,0,0,0,0,0,0,0,0,0,0,0,0,0,0,0,0,0,4,0,0,2,2
6,19,0,0,0,0,0,0,0,0,0,0,0,0,0,0,0,0,0,0,0,0,0,0,0,0,0,0,0,0,0,0,0,0,0,0,0,0,0,0,0,0,0,0,0,0,19,6
2,2,0,0,0,0,0,0,0,0,0,0,0,0,0,0,0,0,0,0,0,0,0,0,0,0,0,0,0,0,0,0,0,0,0,0,0,0,0,0,0,0,0,0,0,0,2,2
3,21,0,0,0,0,0,0,0,0,0,0,0,0,0,0,0,0,0,0,0,0,0,0,8,8,8,0,0,0,0,0,0,0,0,0,0,0,0,0,0,0,0,0,0,0,21,3
26,21,0,0,0,2,0,0,0,0,0,0,0,0,0,0,0,0,0,0,0,0,0,0,8,4,8,0,0,0,0,0,0,0,0,0,0,0,0,0,0,0,0,0,0,0,21,26
3,21,0,0,0,0,0,0,0,0,0,0,0,0,0,0,0,0,0,0,0,0,0,0,8,8,8,0,0,0,0,0,0,0,0,0,0,0,0,0,0,0,0,0,0,0,21,3
2,2,0,0,0,0,0,0,0,0,0,0,0,0,0,0,0,0,0,0,0,0,0,0,0,0,0,0,0,0,0,0,0,0,0,0,0,0,0,0,0,0,0,0,0,0,2,2
6,19,0,0,12,0,0,0,0,0,0,0,0,0,0,0,0,0,0,0,0,0,0,0,0,0,0,0,0,0,0,0,0,0,0,0,0,0,0,0,0,0,0,0,0,0,19,6
2,2,0,0,0,0,0,0,0,0,0,0,0,0,0,0,0,0,0,0,0,0,0,0,0,0,0,0,0,0,0,0,0,0,0,0,0,0,0,0,0,0,0,0,0,0,2,2
3,21,0,0,0,0,0,0,0,0,0,0,0,0,0,0,0,0,0,0,0,0,0,0,0,0,0,0,0,0,0,0,0,0,0,0,0,0,0,0,0,0,0,0,0,0,21,3
26,21,0,0,0,0,0,0,0,0,0,0,0,0,0,0,0,0,0,0,0,0,0,0,8,8,8,0,0,0,0,0,0,0,0,0,0,0,0,0,0,0,0,0,0,0,21,26
3,21,0,0,0,0,0,0,0,0,0,0,0,0,0,0,0,0,0,0,0,0,0,0,8,4,8,0,0,0,0,0,0,0,0,0,0,0,0,0,0,0,0,0,0,0,21,3
3,21,0,0,0,0,0,0,0,0,0,0,0,0,0,0,0,0,0,0,0,0,0,0,8,8,8,0,0,0,0,0,0,0,0,0,0,0,0,0,0,0,0,0,0,0,21,3
26,21,0,0,0,0,0,0,0,0,0,0,0,0,0,0,0,0,0,0,0,0,0,0,0,0,0,0,0,0,0,0,0,0,0,0,0,0,0,0,0,0,0,0,0,0,21,26
3,21,0,0,0,0,0,0,0,0,0,0,0,0,0,0,0,0,0,0,0,0,0,0,0,0,0,0,0,0,0,0,0,0,0,0,0,0,0,0,0,0,0,0,0,0,21,3
2,2,0,0,0,0,0,0,0,0,0,0,0,0,0,0,0,0,0,0,0,0,0,0,0,0,0,0,0,0,0,0,0,0,0,0,0,0,0,0,0,0,0,0,0,0,2,2
6,19,0,0,0,0,0,0,0,0,0,0,0,0,0,0,0,0,0,0,0,0,0,0,0,0,0,0,0,0,0,0,0,0,0,0,0,0,0,0,0,0,0,0,0,0,19,6
2,2,0,0,0,0,0,0,0,0,0,0,0,0,0,0,0,0,0,0,0,0,0,0,0,0,0,0,0,0,0,0,0,0,0,0,0,0,0,0,0,0,0,0,0,0,2,2
3,21,0,0,0,0,0,0,0,0,0,0,0,0,0,0,0,0,0,0,0,0,0,0,0,4,0,0,0,0,0,0,0,0,0,0,0,0,0,0,0,0,0,0,0,0,21,3
26,21,0,0,0,0,0,0,0,0,0,0,0,0,0,0,0,0,0,0,0,0,0,0,0,0,0,0,0,0,0,0,0,0,0,0,0,0,0,0,0,0,0,0,0,0,21,26
3,21,0,0,0,0,0,0,0,0,0,0,0,0,0,0,0,0,0,0,0,0,0,0,0,0,0,0,0,0,0,0,0,0,0,0,0,0,0,0,0,0,0,0,0,0,21,3
2,2,0,0,0,0,0,0,0,0,0,0,0,0,0,0,0,0,0,0,0,0,0,0,0,0,0,0,0,0,0,0,0,0,0,0,0,0,0,0,0,0,0,0,0,0,2,2
6,19,0,0,0,0,0,0,0,0,0,0,0,0,0,0,0,0,0,0,0,0,0,0,0,0,0,0,0,0,0,0,0,0,0,7,0,0,0,0,0,0,0,0,0,0,19,6
2,2,0,0,0,0,0,0,0,0,0,0,0,0,0,0,0,0,0,0,0,0,0,0,0,0,0,0,0,0,0,0,0,0,0,0,0,0,0,0,0,0,0,0,0,0,2,2
3,21,0,0,0,0,0,0,0,0,0,0,0,0,0,0,0,0,0,0,0,0,0,0,0,0,0,0,0,0,0,0,0,0,0,0,0,0,0,0,0,0,0,0,0,0,21,3
26,21,0,0,0,0,0,0,0,0,0,0,0,0,0,0,0,0,0,0,12,0,7,0,0,0,0,0,0,0,0,0,0,0,0,0,0,0,0,0,0,0,0,0,0,0,21,26
3,21,0,0,0,0,0,0,0,0,0,0,0,0,0,0,0,0,0,0,0,0,0,0,0,0,0,0,0,0,0,0,0,0,0,0,0,0,0,0,0,0,0,0,0,0,21,3
2,2,0,0,0,0,0,0,0,0,0,0,0,0,0,0,0,0,0,0,0,0,0,0,0,0,0,0,0,0,0,0,0,0,0,0,0,0,0,0,0,0,0,0,0,0,2,2
6,19,0,0,0,0,0,0,0,0,0,0,0,0,0,0,0,0,0,0,0,0,0,0,0,0,0,0,0,0,0,0,0,0,0,0,0,0,0,0,0,0,0,0,0,0,19,6
2,2,0,0,0,0,0,0,0,0,0,0,0,0,0,0,0,0,0,0,0,0,0,0,0,0,0,0,0,0,0,0,0,0,0,0,0,0,0,0,0,0,0,0,0,0,2,2
3,21,0,0,0,0,0,0,0,0,0,0,0,0,0,0,0,0,0,0,0,0,0,0,0,0,0,0,0,0,0,0,0,0,0,0,0,0,0,0,0,0,0,0,0,0,21,3
26,21,0,0,0,0,0,0,0,0,0,0,0,0,0,0,0,0,0,0,0,0,0,0,0,0,0,0,0,0,0,0,0,0,0,0,0,0,0,0,0,0,0,0,0,0,21,26
1,2,19,2,0,0,0,0,0,0,0,0,0,0,0,0,0,0,0,0,0,0,0,0,0,0,0,0,0,0,0,0,0,0,0,0,0,0,0,0,0,0,0,0,2,19,2,1
1,2,6,19,0,0,0,0,0,0,0,0,0,0,0,0,0,0,0,0,0,0,0,0,0,0,0,0,0,0,0,0,0,0,0,0,0,0,0,0,0,0,0,0,19,6,2,1
1,1,2,2,21,21,2,19,2,21,21,21,2,19,2,21,21,21,2,19,2,21,21,21,21,21,21,2,19,2,21,21,21,2,19,2,21,21,21,2,19,2,21,21,2,2,1,1
1,1,1,1,26,3,2,6,2,3,26,3,2,6,2,3,26,3,2,6,2,3,26,3,3,26,3,2,6,2,3,26,3,2,6,2,3,26,3,2,6,2,3,26,1,1,1,1
endlayer

layer
1,1,1,1,3,26,2,6,2,26,3,26,2,6,2,26,3,26,2,6,2,26,3,26,26,3,26,2,6,2,26,3,26,2,6,2,26,3,26,2,6,2,26,3,1,1,1,1
1,1,2,2,21,21,2,19,2,21,21,21,2,19,2,21,21,21,2,19,2,21,21,21,21,21,21,2,19,2,21,21,21,2,19,2,21,21,21,2,19,2,21,21,2,2,1,1
1,2,6,19,0,0,0,0,0,0,0,0,0,0,0,0,0,0,0,0,0,0,0,0,0,0,0,0,0,0,0,0,0,0,0,0,0,0,0,0,0,0,0,0,19,6,2,1
1,2,19,2,0,0,0,0,0,0,0,0,0,0,0,0,0,0,0,0,0,0,0,0,0,0,0,0,0,0,0,0,0,0,0,0,0,0,0,0,0,0,0,0,2,19,2,1
3,21,0,0,0,0,0,0,0,0,0,0,0,0,0,0,0,0,0,0,0,0,0,0,0,0,0,0,0,0,0,0,0,0,0,0,0,0,0,0,0,0,0,0,0,0,21,3
26,21,0,0,0,0,0,0,0,0,0,0,0,0,0,0,0,0,0,0,0,0,0,0,0,0,0,0,0,0,0,0,0,0,0,0,0,0,0,0,0,0,0,0,0,0,21,26
2,2,0,0,0,0,0,0,0,0,0,0,0,0,0,0,0,0,0,0,0,0,0,0,0,0,0,0,0,0,0,0,0,0,0,0,0,0,0,0,0,0,0,0,0,0,2,2
6,19,0,0,0,0,0,0,0,0,0,0,0,0,0,0,0,0,0,0,0,0,0,0,0,0,0,0,0,0,0,0,0,0,0,0,0,0,0,0,0,0,0,0,0,0,19,6
2,2,0,0,0,0,0,0,0,0,0,0,0,0,0,0,0,0,0,0,0,0,0,0,0,0,0,0,0,0,0,0,0,0,0,0,0,0,0,0,0,0,0,0,0,0,2,2
26,21,0,0,0,0,0,0,0,0,0,0,7,0,0,0,0,0,0,0,0,0,0,0,0,0,0,0,0,0,0,0,0,0,0,0,0,0,0,0,0,0,0,0,0,0,21,26
3,21,0,0,0,0,0,0,0,0,0,0,0,0,0,0,0,0,0,0,0,0,0,0,0,0,0,0,0,0,0,0,0,0,0,0,0,0,0,0,0,0,0,0,0,0,21,3
26,21,0,0,0,0,0,0,0,0,0,0,0,0,0,0,0,0,0,0,0,0,0,0,0,0,0,0,0,0,0,0,0,0,0,0,0,0,0,0,0,0,0,0,0,0,21,26
2,2,0,0,0,0,0,0,0,0,0,0,0,0,0,0,0,0,0,0,0,0,0,0,0,0,0,0,0,0,0,0,0,0,0,0,0,0,0,0,0,0,0,0,0,0,2,2
6,19,0,0,0,0,0,0,0,0,0,0,0,0,0,0,0,0,0,0,0,0,0,0,0,0,0,0,0,0,0,0,0,0,0,0,0,0,0,0,0,0,0,0,0,0,19,6
2,2,0,0,0,0,0,0,0,0,0,0,0,0,0,0,0,0,0,0,0,0,0,0,0,0,0,0,0,0,0,0,0,0,0,0,0,0,0,0,0,0,0,0,0,0,2,2
26,21,0,0,0,0,0,0,0,0,0,0,0,0,0,0,0,0,0,0,0,0,0,0,0,0,0,0,0,0,0,0,0,0,0,0,0,0,0,0,0,0,0,0,0,0,21,26
3,21,0,0,0,2,0,0,0,0,0,0,0,0,0,0,0,0,0,0,0,0,0,0,0,4,0,0,0,0,0,0,0,0,0,0,0,0,0,0,0,0,0,0,0,0,21,3
26,21,0,0,0,0,0,0,0,0,0,0,0,0,0,0,0,0,0,0,0,0,0,0,0,4,0,0,0,0,0,0,0,0,0,0,0,0,0,0,0,0,0,0,0,0,21,26
2,2,0,0,0,0,0,0,0,0,0,0,0,0,0,0,0,0,0,0,0,0,0,0,0,4,0,0,0,0,0,0,0,0,0,0,0,0,0,0,0,0,0,0,0,0,2,2
6,19,0,0,12,0,0,0,0,0,0,0,0,0,0,0,0,0,0,0,0,0,0,0,0,4,0,0,0,0,0,0,0,0,0,0,0,0,0,0,0,0,0,0,0,0,19,6
2,2,0,0,0,0,0,0,0,0,0,0,0,0,0,0,0,0,0,0,0,0,0,0,0,4,0,0,0,0,0,0,0,0,0,0,0,0,0,0,0,0,0,0,0,0,2,2
26,21,0,0,0,0,0,0,0,0,0,0,0,0,0,0,0,0,0,0,0,0,0,0,0,4,0,0,0,0,0,0,0,0,0,0,0,0,0,0,0,0,0,0,0,0,21,26
3,21,0,0,0,0,0,0,0,0,0,0,0,0,0,0,0,0,0,0,0,0,0,0,0,4,0,0,0,0,0,0,0,0,0,0,0,0,0,0,0,0,0,0,0,0,21,3
26,21,0,0,0,0,0,0,0,0,0,0,0,0,0,0,0,0,0,0,0,0,0,0,0,4,0,0,0,0,0,0,0,0,0,0,0,0,0,0,0,0,0,0,0,0,21,26
26,21,0,0,0,0,0,0,0,0,0,0,0,0,0,0,0,0,0,0,0,0,0,0,0,4,0,0,0,0,0,0,0,0,0,0,0,0,0,0,0,0,0,0,0,0,21,26
3,21,0,0,0,0,0,0,0,0,0,0,0,0,0,0,0,0,0,0,0,0,0,0,0,4,0,0,0,0,0,0,0,0,0,0,0,0,0,0,0,0,0,0,0,0,21,3
26,21,0,0,0,0,0,0,0,0,0,0,0,0,0,0,0,0,0,0,0,0,0,0,0,4,0,0,0,0,0,0,0,0,0,0,0,0,0,0,0,0,0,0,0,0,21,26
2,2,0,0,0,0,0,0,0,0,0,0,0,0,0,0,0,0,0,0,0,0,0,0,0,4,0,0,0,0,0,0,0,0,0,0,0,0,0,0,0,0,0,0,0,0,2,2
6,19,0,0,0,0,0,0,0,0,0,0,0,0,0,0,0,0,0,0,0,0,0,0,0,4,0,0,0,0,0,0,0,0,0,0,0,0,0,0,0,0,0,0,0,0,19,6
2,2,0,0,0,0,0,0,0,0,0,0,0,0,0,0,0,0,0,0,0,0,0,0,0,4,0,0,0,0,0,0,0,0,0,0,0,0,0,0,0,0,0,0,0,0,2,2
26,21,0,0,0,0,0,0,0,0,0,0,0,0,0,0,0,0,0,0,0,0,0,0,0,4,0,0,0,0,0,0,0,0,0,0,0,0,0,0,0,0,0,0,0,0,21,26
3,21,0,0,0,0,0,0,0,0,0,0,0,0,0,0,0,0,0,0,0,0,0,0,0,0,0,0,0,0,0,0,0,0,0,0,0,0,0,0,0,0,0,0,0,0,21,3
26,21,0,0,0,0,0,0,0,0,0,0,0,0,0,0,0,0,0,0,0,0,0,0,0,0,0,0,0,0,0,0,0,0,0,0,0,0,0,0,0,0,0,0,0,0,21,26
2,2,0,0,0,0,0,0,0,0,0,0,0,0,0,0,0,0,0,0,0,0,0,0,0,0,0,0,0,0,0,0,0,0,0,0,0,0,0,0,0,0,0,0,0,0,2,2
6,19,0,0,0,0,0,0,0,0,0,0,0,0,0,0,0,0,0,0,0,0,0,0,0,0,0,0,0,0,0,0,0,0,0,7,0,0,0,0,0,0,0,0,0,0,19,6
2,2,0,0,0,0,0,0,0,0,0,0,0,0,0,0,0,0,0,0,0,0,0,0,0,0,0,0,0,0,0,0,0,0,0,0,0,0,0,0,0,0,0,0,0,0,2,2
26,21,0,0,0,0,0,0,0,0,0,0,0,0,0,0,0,0,0,0,0,0,0,0,0,0,0,0,0,0,0,0,0,0,0,0,0,0,0,0,0,0,0,0,0,0,21,26
3,21,0,0,0,0,0,0,0,0,0,0,0,0,0,0,0,0,0,0,12,0,7,0,0,0,0,0,0,0,0,0,0,0,0,0,0,0,0,0,0,0,0,0,0,0,21,3
26,21,0,0,0,0,0,0,0,0,0,0,0,0,0,0,0,0,0,0,0,0,0,0,0,0,0,0,0,0,0,0,0,0,0,0,0,0,0,0,0,0,0,0,0,0,21,26
2,2,0,0,0,0,0,0,0,0,0,0,0,0,0,0,0,0,0,0,0,0,0,0,0,0,0,0,0,0,0,0,0,0,0,0,0,0,0,0,0,0,0,0,0,0,2,2
6,19,0,0,0,0,0,0,0,0,0,0,0,0,0,0,0,0,0,0,0,0,0,0,0,0,0,0,0,0,0,0,0,0,0,0,0,0,0,0,0,0,0,0,0,0,19,6
2,2,0,0,0,0,0,0,0,0,0,0,0,0,0,0,0,0,0,0,0,0,0,0,0,0,0,0,0,0,0,0,0,0,0,0,0,0,0,0,0,0,0,0,0,0,2,2
26,21,0,0,0,0,0,0,0,0,0,0,0,0,0,0,0,0,0,0,0,0,0,0,0,0,0,0,0,0,0,0,0,0,0,0,0,0,0,0,0,0,0,0,0,0,21,26
3,21,0,0,0,0,0,0,0,0,0,0,0,0,0,0,0,0,0,0,0,0,0,0,0,0,0,0,0,0,0,0,0,0,0,0,0,0,0,0,0,0,0,0,0,0,21,3
1,2,19,2,0,0,0,0,0,0,0,0,0,0,0,0,0,0,0,0,0,0,0,0,0,0,0,0,0,0,0,0,0,0,0,0,0,0,0,0,0,0,0,0,2,19,2,1
1,2,6,19,0,0,0,0,0,0,0,0,0,0,0,0,0,0,0,0,0,0,0,0,0,0,0,0,0,0,0,0,0,0,0,0,0,0,0,0,0,0,0,0,19,6,2,1
1,1,2,2,21,21,2,19,2,21,21,21,2,19,2,21,21,21,2,19,2,21,21,21,21,21,21,2,19,2,21,21,21,2,19,2,21,21,21,2,19,2,21,21,2,2,1,1
1,1,1,1,3,26,2,6,2,26,3,26,2,6,2,26,3,26,2,6,2,26,3,26,26,3,26,2,6,2,26,3,26,2,6,2,26,3,26,2,6,2,26,3,1,1,1,1
endlayer

layer
1,1,1,1,5,3,2,51,2,3,5,3,2,51,2,3,5,3,2,51,2,3,5,3,3,5,3,2,51,2,3,5,3,2,51,2,3,5,3,2,51,2,3,5,1,1,1,1
1,1,2,4,21,21,4,2,4,21,21,21,4,2,4,21,21,21,4,2,4,21,21,21,21,21,21,4,2,4,21,21,21,4,2,4,21,21,21,4,2,4,21,21,4,2,1,1
1,2,51,2,19,0,0,19,0,0,0,0,0,19,0,0,0,0,0,19,0,0,0,0,0,0,0,0,19,0,0,0,0,0,19,0,0,0,0,0,19,0,0,19,2,51,2,1
1,4,2,4,19,0,0,0,0,0,0,0,0,0,0,0,0,0,0,0,0,0,0,0,0,0,0,0,0,0,0,0,0,0,0,0,0,0,0,0,0,0,0,19,4,2,4,1
5,21,19,19,21,0,0,0,0,0,0,0,0,0,0,0,0,0,0,0,0,0,0,0,0,0,0,0,0,0,0,0,0,0,0,0,0,0,0,0,0,0,0,21,19,19,21,5
3,21,0,0,0,0,0,0,0,0,0,0,0,0,0,0,0,0,0,0,0,0,0,0,0,0,0,0,0,0,0,0,0,0,0,0,0,0,0,0,0,0,0,0,0,0,21,3
2,4,0,0,0,0,0,0,0,0,0,0,0,0,0,0,0,0,0,0,0,0,0,0,0,0,0,0,0,0,0,0,0,0,0,0,0,0,0,0,0,0,0,0,0,0,4,2
51,2,19,0,0,0,0,0,0,0,0,0,0,0,0,0,0,0,0,0,0,0,0,0,0,0,0,0,0,0,0,0,0,0,0,0,0,0,0,0,0,0,0,0,0,19,2,51
2,4,0,0,0,0,0,0,0,0,0,0,0,0,0,0,0,0,0,0,0,0,0,0,0,0,0,0,0,0,0,0,0,0,0,0,0,0,0,0,0,0,0,0,0,0,4,2
3,21,0,0,0,0,0,0,0,0,0,0,7,0,0,0,0,0,0,0,0,0,0,0,0,0,0,0,0,0,0,0,0,0,0,0,0,0,0,0,0,0,0,0,0,0,21,3
5,21,0,0,0,0,0,0,0,0,0,0,0,0,0,0,0,0,0,0,0,0,0,0,0,0,0,0,0,0,0,0,0,0,0,0,0,0,0,0,0,0,0,0,0,0,21,5
3,21,0,0,0,0,0,0,0,0,0,0,0,0,0,0,0,0,0,0,0,0,0,0,0,0,0,0,0,0,0,0,0,0,0,0,0,0,0,0,0,0,0,0,0,0,21,3
2,4,0,0,0,0,0,0,0,0,0,0,0,0,0,0,0,0,0,0,0,0,0,0,0,0,0,0,0,0,0,0,0,0,0,0,0,0,0,0,0,0,0,0,0,0,4,2
51,2,19,0,0,0,0,0,0,0,0,0,0,0,0,0,0,0,0,0,0,0,0,0,0,0,0,0,0,0,0,0,0,0,0,0,0,0,0,0,0,0,0,0,0,19,2,51
2,4,0,0,0,0,0,0,0,0,0,0,0,0,0,0,0,0,0,0,0,0,0,0,0,0,0,0,0,0,0,0,0,0,0,0,0,0,0,0,0,0,0,0,0,0,4,2
3,21,0,0,0,0,0,0,0,0,0,0,0,0,0,0,0,0,0,0,0,0,0,0,0,0,0,0,0,0,0,0,0,0,0,0,0,0,0,0,0,0,0,0,0,0,21,3
5,21,0,0,0,2,0,0,0,0,0,0,0,0,0,0,0,0,0,0,0,0,0,0,0,0,0,0,0,0,0,0,0,0,0,0,0,0,0,0,0,0,0,0,0,0,21,5
3,21,0,0,0,0,0,0,0,0,0,0,0,0,0,0,0,0,0,0,0,0,0,0,0,0,0,0,0,0,0,0,0,0,0,0,0,0,0,0,0,0,0,0,0,0,21,3
2,4,0,0,0,0,0,0,0,0,0,0,0,0,0,0,0,0,0,0,0,0,0,0,0,0,0,0,0,0,0,0,0,0,0,0,0,0,0,0,0,0,0,0,0,0,4,2
51,2,19,0,12,0,0,0,0,0,0,0,0,0,0,0,0,0,0,0,0,0,0,0,0,4,0,0,0,0,0,0,0,0,0,0,0,0,0,0,0,0,0,0,0,19,2,51
2,4,0,0,0,0,0,0,0,0,0,0,0,0,0,0,0,0,0,0,0,0,0,0,0,0,0,0,0,0,0,0,0,0,0,0,0,0,0,0,0,0,0,0,0,0,4,2
3,21,0,0,0,0,0,0,0,0,0,0,0,0,0,0,0,0,0,0,0,0,0,0,0,0,0,0,0,0,0,0,0,0,0,0,0,0,0,0,0,0,0,0,0,0,21,3
5,21,0,0,0,0,0,0,0,0,0,0,0,0,0,0,0,0,0,0,0,0,0,0,0,0,0,0,0,0,0,0,0,0,0,0,0,0,0,0,0,0,0,0,0,0,21,5
3,21,0,0,0,0,0,0,0,0,0,0,0,0,0,0,0,0,0,0,0,0,0,0,0,0,0,0,0,0,0,0,0,0,0,0,0,0,0,0,0,0,0,0,0,0,21,3
3,21,0,0,0,0,0,0,0,0,0,0,0,0,0,0,0,0,0,0,0,0,0,0,0,0,0,0,0,0,0,0,0,0,0,0,0,0,0,0,0,0,0,0,0,0,21,3
5,21,0,0,0,0,0,0,0,0,0,0,0,0,0,0,0,0,0,0,0,0,0,0,0,0,0,0,0,0,0,0,0,0,0,0,0,0,0,0,0,0,0,0,0,0,21,5
3,21,0,0,0,0,0,0,0,0,0,0,0,0,0,0,0,0,0,0,0,0,0,0,0,0,0,0,0,0,0,0,0,0,0,0,0,0,0,0,0,0,0,0,0,0,21,3
2,4,0,0,0,0,0,0,0,0,0,0,0,0,0,0,0,0,0,0,0,0,0,0,0,0,0,0,0,0,0,0,0,0,0,0,0,0,0,0,0,0,0,0,0,0,4,2
51,2,19,0,0,0,0,0,0,0,0,0,0,0,0,0,0,0,0,0,0,0,0,0,0,0,0,0,0,0,0,0,0,0,0,0,0,0,0,0,0,0,0,0,0,19,2,51
2,4,0,0,0,0,0,0,0,0,0,0,0,0,0,0,0,0,0,0,0,0,0,0,0,0,0,0,0,0,0,0,0,0,0,0,0,0,0,0,0,0,0,0,0,0,4,2
3,21,0,0,0,0,0,0,0,0,0,0,0,0,0,0,0,0,0,0,0,0,0,0,0,0,0,0,0,0,0,0,0,0,0,0,0,0,0,0,0,0,0,0,0,0,21,3
5,21,0,0,0,0,0,0,0,0,0,0,0,0,0,0,0,0,0,0,0,0,0,0,0,0,0,0,0,0,0,0,0,0,0,0,0,0,0,0,0,0,0,0,0,0,21,5
3,21,0,0,0,0,0,0,0,0,0,0,0,0,0,0,0,0,0,0,0,0,0,0,0,0,0,0,0,0,0,0,0,0,0,0,0,0,0,0,0,0,0,0,0,0,21,3
2,4,0,0,0,0,0,0,0,0,0,0,0,0,0,0,0,0,0,0,0,0,0,0,0,0,0,0,0,0,0,0,0,0,0,0,0,0,0,0,0,0,0,0,0,0,4,2
51,2,19,0,0,0,0,0,0,0,0,0,0,0,0,0,0,0,0,0,0,0,0,0,0,0,0,0,0,0,0,0,0,0,0,7,0,0,0,0,0,0,0,0,0,19,2,51
2,4,0,0,0,0,0,0,0,0,0,0,0,0,0,0,0,0,0,0,0,0,0,0,0,0,0,0,0,0,0,0,0,0,0,0,0,0,0,0,0,0,0,0,0,0,4,2
3,21,0,0,0,0,0,0,0,0,0,0,0,0,0,0,0,0,0,0,0,0,0,0,0,0,0,0,0,0,0,0,0,0,0,0,0,0,0,0,0,0,0,0,0,0,21,3
5,21,0,0,0,0,0,0,0,0,0,0,0,0,0,0,0,0,0,0,12,0,7,0,0,0,0,0,0,0,0,0,0,0,0,0,0,0,0,0,0,0,0,0,0,0,21,5
3,21,0,0,0,0,0,0,0,0,0,0,0,0,0,0,0,0,0,0,0,0,0,0,0,0,0,0,0,0,0,0,0,0,0,0,0,0,0,0,0,0,0,0,0,0,21,3
2,4,0,0,0,0,0,0,0,0,0,0,0,0,0,0,0,0,0,0,0,0,0,0,0,0,0,0,0,0,0,0,0,0,0,0,0,0,0,0,0,0,0,0,0,0,4,2
51,2,19,0,0,0,0,0,0,0,0,0,0,0,0,0,0,0,0,0,0,0,0,0,0,0,0,0,0,0,0,0,0,0,0,0,0,0,0,0,0,0,0,0,0,19,2,51
2,4,0,0,0,0,0,0,0,0,0,0,0,0,0,0,0,0,0,0,0,0,0,0,0,0,0,0,0,0,0,0,0,0,0,0,0,0,0,0,0,0,0,0,0,0,4,2
3,21,0,0,0,0,0,0,0,0,0,0,0,0,0,0,0,0,0,0,0,0,0,0,0,0,0,0,0,0,0,0,0,0,0,0,0,0,0,0,0,0,0,0,0,0,21,3
5,21,19,19,21,0,0,0,0,0,0,0,0,0,0,0,0,0,0,0,0,0,0,0,0,0,0,0,0,0,0,0,0,0,0,0,0,0,0,0,0,0,0,21,19,19,21,5
1,4,2,4,19,0,0,0,0,0,0,0,0,0,0,0,0,0,0,0,0,0,0,0,0,0,0,0,0,0,0,0,0,0,0,0,0,0,0,0,0,0,0,19,4,2,4,1
1,2,51,2,19,0,0,19,0,0,0,0,0,19,0,0,0,0,0,19,0,0,0,0,0,0,0,0,19,0,0,0,0,0,19,0,0,0,0,0,19,0,0,19,2,51,2,1
1,1,2,4,21,21,4,2,4,21,21,21,4,2,4,21,21,21,4,2,4,21,21,21,21,21,21,4,2,4,21,21,21,4,2,4,21,21,21,4,2,4,21,21,4,2,1,1
1,1,1,1,5,3,2,51,2,3,5,3,2,51,2,3,5,3,2,51,2,3,5,3,3,5,3,2,51,2,3,5,3,2,51,2,3,5,3,2,51,2,3,5,1,1,1,1
endlayer

layer
1,1,1,1,1,1,1,9,1,1,1,1,1,9,1,1,1,1,1,9,1,1,1,1,1,1,1,1,9,1,1,1,1,1,9,1,1,1,1,1,9,1,1,1,1,1,1,1
1,1,1,1,1,1,1,1,1,1,1,1,1,1,1,1,1,1,1,1,1,1,1,1,1,1,1,1,1,1,1,1,1,1,1,1,1,1,1,1,1,1,1,1,1,1,1,1
1,1,9,1,4,2,2,4,2,4,2,4,2,4,2,4,2,4,2,4,2,4,4,2,2,4,4,2,4,2,4,2,4,2,4,2,4,2,4,2,4,2,2,4,1,9,1,1
1,1,1,2,14,0,0,19,0,0,21,0,0,19,0,0,21,0,0,19,0,0,0,21,21,0,0,0,19,0,0,21,0,0,19,0,0,21,0,0,19,0,0,14,2,1,1,1
1,1,4,14,9,14,0,19,0,0,21,0,0,19,0,0,21,0,0,19,0,0,0,21,21,0,0,0,19,0,0,21,0,0,19,0,0,21,0,0,19,0,14,9,14,4,1,1
1,1,2,0,14,21,0,0,0,0,0,0,0,0,0,0,0,0,0,0,0,0,0,0,0,0,0,0,0,0,0,0,0,0,0,0,0,0,0,0,0,0,21,14,0,2,1,1
1,1,2,0,0,0,0,0,0,0,0,0,0,0,0,0,0,0,0,0,0,0,0,0,0,0,0,0,0,0,0,0,0,0,0,0,0,0,0,0,0,0,0,0,0,2,1,1
9,1,4,19,19,0,0,0,0,0,0,0,0,0,0,0,0,0,0,0,0,0,0,0,0,0,0,0,0,0,0,0,0,0,0,0,0,0,0,0,0,0,0,19,19,4,1,9
1,1,2,0,0,0,0,0,0,0,0,0,0,0,0,0,0,0,0,0,0,0,0,0,0,0,0,0,0,0,0,0,0,0,0,0,0,0,0,0,0,0,0,0,0,2,1,1
1,1,4,0,0,0,0,0,0,0,0,0,7,0,0,0,0,0,0,0,0,0,0,0,0,0,0,0,0,0,0,0,0,0,0,0,0,0,0,0,0,0,0,0,0,4,1,1
1,1,2,21,21,0,0,0,0,0,0,0,0,0,0,0,0,0,0,0,0,0,0,0,0,0,0,0,0,0,0,0,0,0,0,0,0,0,0,0,0,0,0,21,21,2,1,1
1,1,4,0,0,0,0,0,0,0,0,0,0,0,0,0,0,0,0,0,0,0,0,0,0,0,0,0,0,0,0,0,0,0,0,0,0,0,0,0,0,0,0,0,0,4,1,1
1,1,2,0,0,0,0,0,0,0,0,0,0,0,0,0,0,0,0,0,0,0,0,0,0,0,0,0,0,0,0,0,0,0,0,0,0,0,0,0,0,0,0,0,0,2,1,1
9,1,4,19,19,0,0,0,0,0,0,0,0,0,0,0,0,0,0,0,0,0,0,0,0,0,0,0,0,0,0,0,0,0,0,0,0,0,0,0,0,0,0,19,19,4,1,9
1,1,2,0,0,0,0,0,0,0,0,0,0,0,0,0,0,0,0,0,0,0,0,0,0,0,0,0,0,0,0,0,0,0,0,0,0,0,0,0,0,0,0,0,0,2,1,1
1,1,4,0,0,0,0,0,0,0,0,0,0,0,0,0,0,0,0,0,0,0,0,0,0,0,0,0,0,0,0,0,0,0,0,0,0,0,0,0,0,0,0,0,0,4,1,1
1,1,2,21,21,2,0,0,0,0,0,0,0,0,0,0,0,0,0,0,0,0,0,0,0,0,0,0,0,0,0,0,0,0,0,0,0,0,0,0,0,0,0,21,21,2,1,1
1,1,4,0,0,0,0,0,0,0,0,0,0,0,0,0,0,0,0,0,0,0,0,0,0,0,0,0,0,0,0,0,0,0,0,0,0,0,0,0,0,0,0,0,0,4,1,1
1,1,2,0,0,0,0,0,0,0,0,0,0,0,0,0,0,0,0,0,0,0,0,0,0,0,0,0,0,0,0,0,0,0,0,0,0,0,0,0,0,0,0,0,0,2,1,1
9,1,4,19,12,0,0,0,0,0,0,0,0,0,0,0,0,0,0,0,0,0,0,0,0,4,0,0,0,0,0,0,0,0,0,0,0,0,0,0,0,0,0,19,19,4,1,9
1,1,2,0,0,0,0,0,0,0,0,0,0,0,0,0,0,0,0,0,0,0,0,0,0,0,0,0,0,0,0,0,0,0,0,0,0,0,0,0,0,0,0,0,0,2,1,1
1,1,4,0,0,0,0,0,0,0,0,0,0,0,0,0,0,0,0,0,0,0,0,0,0,0,0,0,0,0,0,0,0,0,0,0,0,0,0,0,0,0,0,0,0,4,1,1
1,1,4,0,0,0,0,0,0,0,0,0,0,0,0,0,0,0,0,0,0,0,0,0,0,0,0,0,0,0,0,0,0,0,0,0,0,0,0,0,0,0,0,0,0,4,1,1
1,1,2,21,21,0,0,0,0,0,0,0,0,0,0,0,0,0,0,0,0,0,0,0,0,0,0,0,0,0,0,0,0,0,0,0,0,0,0,0,0,0,0,21,21,2,1,1
1,1,2,21,21,0,0,0,0,0,0,0,0,0,0,0,0,0,0,0,0,0,0,0,0,0,0,0,0,0,0,0,0,0,0,0,0,0,0,0,0,0,0,21,21,2,1,1
1,1,4,0,0,0,0,0,0,0,0,0,0,0,0,0,0,0,0,0,0,0,0,0,0,0,0,0,0,0,0,0,0,0,0,0,0,0,0,0,0,0,0,0,0,4,1,1
1,1,4,0,0,0,0,0,0,0,0,0,0,0,0,0,0,0,0,0,0,0,0,0,0,0,0,0,0,0,0,0,0,0,0,0,0,0,0,0,0,0,0,0,0,4,1,1
1,1,2,0,0,0,0,0,0,0,0,0,0,0,0,0,0,0,0,0,0,0,0,0,0,0,0,0,0,0,0,0,0,0,0,0,0,0,0,0,0,0,0,0,0,2,1,1
9,1,4,19,19,0,0,0,0,0,0,0,0,0,0,0,0,0,0,0,0,0,0,0,0,0,0,0,0,0,0,0,0,0,0,0,0,0,0,0,0,0,0,19,19,4,1,9
1,1,2,0,0,0,0,0,0,0,0,0,0,0,0,0,0,0,0,0,0,0,0,0,0,0,0,0,0,0,0,0,0,0,0,0,0,0,0,0,0,0,0,0,0,2,1,1
1,1,4,0,0,0,0,0,0,0,0,0,0,0,0,0,0,0,0,0,0,0,0,0,0,0,0,0,0,0,0,0,0,0,0,0,0,0,0,0,0,0,0,0,0,4,1,1
1,1,2,21,21,0,0,0,0,0,0,0,0,0,0,0,0,0,0,0,0,0,0,0,0,0,0,0,0,0,0,0,0,0,0,0,0,0,0,0,0,0,0,21,21,2,1,1
1,1,4,0,0,0,0,0,0,0,0,0,0,0,0,0,0,0,0,0,0,0,0,0,0,0,0,0,0,0,0,0,0,0,0,0,0,0,0,0,0,0,0,0,0,4,1,1
1,1,2,0,0,0,0,0,0,0,0,0,0,0,0,0,0,0,0,0,0,0,0,0,0,0,0,0,0,0,0,0,0,0,0,0,0,0,0,0,0,0,0,0,0,2,1,1
9,1,4,19,19,0,0,0,0,0,0,0,0,0,0,0,0,0,0,0,0,0,0,0,0,0,0,0,0,0,0,0,0,0,0,7,0,0,0,0,0,0,0,19,19,4,1,9
1,1,2,0,0,0,0,0,0,0,0,0,0,0,0,0,0,0,0,0,0,0,0,0,0,0,0,0,0,0,0,0,0,0,0,0,0,0,0,0,0,0,0,0,0,2,1,1
1,1,4,0,0,0,0,0,0,0,0,0,0,0,0,0,0,0,0,0,0,0,0,0,0,0,0,0,0,0,0,0,0,0,0,0,0,0,0,0,0,0,0,0,0,4,1,1
1,1,2,21,21,0,0,0,0,0,0,0,0,0,0,0,0,0,0,0,12,0,7,0,0,0,0,0,0,0,0,0,0,0,0,0,0,0,0,0,0,0,0,21,21,2,1,1
1,1,4,0,0,0,0,0,0,0,0,0,0,0,0,0,0,0,0,0,0,0,0,0,0,0,0,0,0,0,0,0,0,0,0,0,0,0,0,0,0,0,0,0,0,4,1,1
1,1,2,0,0,0,0,0,0,0,0,0,0,0,0,0,0,0,0,0,0,0,0,0,0,0,0,0,0,0,0,0,0,0,0,0,0,0,0,0,0,0,0,0,0,2,1,1
9,1,4,19,19,0,0,0,0,0,0,0,0,0,0,0,0,0,0,0,0,0,0,0,0,0,0,0,0,0,0,0,0,0,0,0,0,0,0,0,0,0,0,19,19,4,1,9
1,1,2,0,0,0,0,0,0,0,0,0,0,0,0,0,0,0,0,0,0,0,0,0,0,0,0,0,0,0,0,0,0,0,0,0,0,0,0,0,0,0,0,0,0,2,1,1
1,1,2,0,14,21,0,0,0,0,0,0,0,0,0,0,0,0,0,0,0,0,0,0,0,0,0,0,0,0,0,0,0,0,0,0,0,0,0,0,0,0,21,14,0,2,1,1
1,1,4,14,9,14,0,19,0,0,21,0,0,19,0,0,21,0,0,19,0,0,0,21,21,0,0,0,19,0,0,21,0,0,19,0,0,21,0,0,19,0,14,9,14,4,1,1
1,1,1,2,14,0,0,19,0,0,21,0,0,19,0,0,21,0,0,19,0,0,0,21,21,0,0,0,19,0,0,21,0,0,19,0,0,21,0,0,19,0,0,14,2,1,1,1
1,1,9,1,4,2,2,4,2,4,2,4,2,4,2,4,2,4,2,4,2,4,4,2,2,4,4,2,4,2,4,2,4,2,4,2,4,2,4,2,4,2,2,4,1,9,1,1
1,1,1,1,1,1,1,1,1,1,1,1,1,1,1,1,1,1,1,1,1,1,1,1,1,1,1,1,1,1,1,1,1,1,1,1,1,1,1,1,1,1,1,1,1,1,1,1
1,1,1,1,1,1,1,9,1,1,1,1,1,9,1,1,1,1,1,9,1,1,1,1,1,1,1,1,9,1,1,1,1,1,9,1,1,1,1,1,9,1,1,1,1,1,1,1
endlayer

layer
1,1,1,1,1,1,1,1,1,1,1,1,1,1,1,1,1,1,1,1,1,1,1,1,1,1,1,1,1,1,1,1,1,1,1,1,1,1,1,1,1,1,1,1,1,1,1,1
1,1,1,1,1,1,1,1,1,1,1,1,1,1,1,1,1,1,1,1,1,1,1,1,1,1,1,1,1,1,1,1,1,1,1,1,1,1,1,1,1,1,1,1,1,1,1,1
1,1,1,1,1,1,1,1,8,8,22,8,8,1,8,8,22,8,8,1,8,8,8,22,22,8,8,8,1,8,8,22,8,8,1,8,8,22,8,8,1,1,1,1,1,1,1,1
1,1,1,1,8,14,14,2,14,14,9,14,14,2,14,14,9,14,14,2,14,14,14,9,9,14,14,14,2,14,14,9,14,14,2,14,14,9,14,14,2,14,14,8,1,1,1,1
1,1,1,8,22,14,14,2,14,14,9,14,14,2,14,14,9,14,14,2,14,14,14,9,9,14,14,14,2,14,14,9,14,14,2,14,14,9,14,14,2,14,14,22,8,1,1,1
1,1,1,14,14,9,14,19,21,21,22,21,21,19,21,21,22,21,21,19,21,21,21,22,22,21,21,21,19,21,21,22,21,21,19,21,21,22,21,21,19,14,9,14,14,1,1,1
1,1,1,14,14,14,21,19,0,0,21,0,0,19,0,0,21,0,0,19,0,0,0,21,21,0,0,0,19,0,0,21,0,0,19,0,0,21,0,0,19,21,14,14,14,1,1,1
1,1,1,2,2,19,19,19,0,0,21,0,0,19,0,0,21,0,0,19,0,0,0,21,21,0,0,0,19,0,0,21,0,0,19,0,0,21,0,0,19,19,19,2,2,1,1,1
1,1,8,14,14,21,0,0,19,0,0,0,0,0,0,0,0,0,0,0,0,0,0,0,0,0,0,0,0,0,0,0,0,0,0,0,0,0,0,19,0,0,21,14,14,8,1,1
1,1,8,14,14,21,0,0,0,0,0,0,7,0,0,0,0,0,0,0,0,0,0,0,0,0,0,0,0,0,0,0,0,0,0,0,0,0,0,0,0,0,21,14,14,8,1,1
1,1,22,9,9,22,21,21,0,0,0,0,0,0,0,0,0,0,0,0,0,0,0,0,0,0,0,0,0,0,0,0,0,0,0,0,0,0,0,0,21,21,22,9,9,22,1,1
1,1,8,14,14,21,0,0,0,0,0,0,0,0,0,0,0,0,0,0,0,0,0,0,0,0,0,0,0,0,0,0,0,0,0,0,0,0,0,0,0,0,21,14,14,8,1,1
1,1,8,14,14,21,0,0,0,0,0,0,0,0,0,0,0,0,0,0,0,0,0,0,0,0,0,0,0,0,0,0,0,0,0,0,0,0,0,0,0,0,21,14,14,8,1,1
1,1,1,2,2,19,19,19,0,0,0,0,0,0,0,0,0,0,0,0,0,0,0,0,0,0,0,0,0,0,0,0,0,0,0,0,0,0,0,0,19,19,19,2,2,1,1,1
1,1,8,14,14,21,0,0,0,0,0,0,0,0,0,0,0,0,0,0,0,0,0,0,0,0,0,0,0,0,0,0,0,0,0,0,0,0,0,0,0,0,21,14,14,8,1,1
1,1,8,14,14,21,0,0,0,0,0,0,0,0,0,0,0,0,0,0,0,0,0,0,0,0,0,0,0,0,0,0,0,0,0,0,0,0,0,0,0,0,21,14,14,8,1,1
1,1,22,9,9,2,21,21,0,0,0,0,0,0,0,0,0,0,0,0,0,0,0,0,0,0,0,0,0,0,0,0,0,0,0,0,0,0,0,0,21,21,22,9,9,22,1,1
1,1,8,14,14,21,0,0,0,0,0,0,0,0,0,0,0,0,0,0,0,0,0,0,0,0,0,0,0,0,0,0,0,0,0,0,0,0,0,0,0,0,21,14,14,8,1,1
1,1,8,14,14,21,0,0,0,0,0,0,0,0,0,0,0,0,0,0,0,0,0,0,0,0,0,0,0,0,0,0,0,0,0,0,0,0,0,0,0,0,21,14,14,8,1,1
1,1,1,2,12,19,19,19,0,0,0,0,0,0,0,0,0,0,0,0,0,0,0,0,0,4,0,0,0,0,0,0,0,0,0,0,0,0,0,0,19,19,19,2,2,1,1,1
1,1,8,14,14,21,0,0,0,0,0,0,0,0,0,0,0,0,0,0,0,0,0,0,0,0,0,0,0,0,0,0,0,0,0,0,0,0,0,0,0,0,21,14,14,8,1,1
1,1,8,14,14,21,0,0,0,0,0,0,0,0,0,0,0,0,0,0,0,0,0,0,0,0,0,0,0,0,0,0,0,0,0,0,0,0,0,0,0,0,21,14,14,8,1,1
1,1,8,14,14,21,0,0,0,0,0,0,0,0,0,0,0,0,0,0,0,0,0,0,0,0,0,0,0,0,0,0,0,0,0,0,0,0,0,0,0,0,21,14,14,8,1,1
1,1,22,9,9,22,21,21,0,0,0,0,0,0,0,0,0,0,0,0,0,0,0,0,0,0,0,0,0,0,0,0,0,0,0,0,0,0,0,0,21,21,22,9,9,22,1,1
1,1,22,9,9,22,21,21,0,0,0,0,0,0,0,0,0,0,0,0,0,0,0,0,0,0,0,0,0,0,0,0,0,0,0,0,0,0,0,0,21,21,22,9,9,22,1,1
1,1,8,14,14,21,0,0,0,0,0,0,0,0,0,0,0,0,0,0,0,0,0,0,0,0,0,0,0,0,0,0,0,0,0,0,0,0,0,0,0,0,21,14,14,8,1,1
1,1,8,14,14,21,0,0,0,0,0,0,0,0,0,0,0,0,0,0,0,0,0,0,0,0,0,0,0,0,0,0,0,0,0,0,0,0,0,0,0,0,21,14,14,8,1,1
1,1,8,14,14,21,0,0,0,0,0,0,0,0,0,0,0,0,0,0,0,0,0,0,0,0,0,0,0,0,0,0,0,0,0,0,0,0,0,0,0,0,21,14,14,8,1,1
1,1,1,2,2,19,19,19,0,0,0,0,0,0,0,0,0,0,0,0,0,0,0,0,0,0,0,0,0,0,0,0,0,0,0,0,0,0,0,0,19,19,19,2,2,1,1,1
1,1,8,14,14,21,0,0,0,0,0,0,0,0,0,0,0,0,0,0,0,0,0,0,0,0,0,0,0,0,0,0,0,0,0,0,0,0,0,0,0,0,21,14,14,8,1,1
1,1,8,14,14,21,0,0,0,0,0,0,0,0,0,0,0,0,0,0,0,0,0,0,0,0,0,0,0,0,0,0,0,0,0,0,0,0,0,0,0,0,21,14,14,8,1,1
1,1,22,9,9,22,21,21,0,0,0,0,0,0,0,0,0,0,0,0,0,0,0,0,0,0,0,0,0,0,0,0,0,0,0,0,0,0,0,0,21,21,22,9,9,22,1,1
1,1,8,14,14,21,0,0,0,0,0,0,0,0,0,0,0,0,0,0,0,0,0,0,0,0,0,0,0,0,0,0,0,0,0,0,0,0,0,0,0,0,21,14,14,8,1,1
1,1,8,14,14,21,0,0,0,0,0,0,0,0,0,0,0,0,0,0,0,0,0,0,0,0,0,0,0,0,0,0,0,0,0,0,0,0,0,0,0,0,21,14,14,8,1,1
1,1,1,2,2,19,19,19,0,0,0,0,0,0,0,0,0,0,0,0,0,0,0,0,0,0,0,0,0,0,0,0,0,0,0,7,0,0,0,0,19,19,19,2,2,1,1,1
1,1,8,14,14,21,0,0,0,0,0,0,0,0,0,0,0,0,0,0,0,0,0,0,0,0,0,0,0,0,0,0,0,0,0,0,0,0,0,0,0,0,21,14,14,8,1,1
1,1,8,14,14,21,0,0,0,0,0,0,0,0,0,0,0,0,0,0,0,0,0,0,0,0,0,0,0,0,0,0,0,0,0,0,0,0,0,0,0,0,21,14,14,8,1,1
1,1,22,9,9,22,21,21,0,0,0,0,0,0,0,0,0,0,0,0,12,0,7,0,0,0,0,0,0,0,0,0,0,0,0,0,0,0,0,0,21,21,22,9,9,22,1,1
1,1,8,14,14,21,0,0,0,0,0,0,0,0,0,0,0,0,0,0,0,0,0,0,0,0,0,0,0,0,0,0,0,0,0,0,0,0,0,0,0,0,21,14,14,8,1,1
1,1,8,14,14,21,0,0,19,0,0,0,0,0,0,0,0,0,0,0,0,0,0,0,0,0,0,0,0,0,0,0,0,0,0,0,0,0,0,19,0,0,21,14,14,8,1,1
1,1,1,2,2,19,19,19,0,0,21,0,0,19,0,0,21,0,0,19,0,0,0,21,21,0,0,0,19,0,0,21,0,0,19,0,0,21,0,0,19,19,19,2,2,1,1,1
1,1,1,14,14,14,21,19,0,0,21,0,0,19,0,0,21,0,0,19,0,0,0,21,21,0,0,0,19,0,0,21,0,0,19,0,0,21,0,0,19,21,14,14,14,1,1,1
1,1,1,14,14,9,14,19,21,21,22,21,21,19,21,21,22,21,21,19,21,21,21,22,22,21,21,21,19,21,21,22,21,21,19,21,21,22,21,21,19,14,9,14,14,1,1,1
1,1,1,8,22,14,14,2,14,14,9,14,14,2,14,14,9,14,14,2,14,14,14,9,9,14,14,14,2,14,14,9,14,14,2,14,14,9,14,14,2,14,14,22,8,1,1,1
1,1,1,1,8,14,14,2,14,14,9,14,14,2,14,14,9,14,14,2,14,14,14,9,9,14,14,14,2,14,14,9,14,14,2,14,14,9,14,14,2,14,14,8,1,1,1,1
1,1,1,1,1,1,1,1,8,8,22,8,8,1,8,8,22,8,8,1,8,8,8,22,22,8,8,8,1,8,8,22,8,8,1,8,8,22,8,8,1,1,1,1,1,1,1,1
1,1,1,1,1,1,1,1,1,1,1,1,1,1,1,1,1,1,1,1,1,1,1,1,1,1,1,1,1,1,1,1,1,1,1,1,1,1,1,1,1,1,1,1,1,1,1,1
1,1,1,1,1,1,1,1,1,1,1,1,1,1,1,1,1,1,1,1,1,1,1,1,1,1,1,1,1,1,1,1,1,1,1,1,1,1,1,1,1,1,1,1,1,1,1,1
endlayer

layer
1,1,1,1,1,1,1,1,1,1,1,1,1,1,1,1,1,1,1,1,1,1,1,1,1,1,1,1,1,1,1,1,1,1,1,1,1,1,1,1,1,1,1,1,1,1,1,1
1,1,1,1,1,1,1,1,1,1,1,1,1,1,1,1,1,1,1,1,1,1,1,1,1,1,1,1,1,1,1,1,1,1,1,1,1,1,1,1,1,1,1,1,1,1,1,1
1,1,1,1,1,1,1,1,1,1,1,1,1,1,1,1,1,1,1,1,1,1,1,1,1,1,1,1,1,1,1,1,1,1,1,1,1,1,1,1,1,1,1,1,1,1,1,1
1,1,1,1,1,1,1,1,1,1,8,1,1,1,1,1,8,1,1,1,1,1,1,8,8,1,1,1,1,1,1,8,1,1,1,1,1,8,1,1,1,1,1,1,1,1,1,1
1,1,1,1,1,1,1,1,1,1,8,1,1,8,1,1,8,1,1,8,1,1,1,8,8,1,1,1,8,1,1,8,1,1,8,1,1,8,1,1,1,1,1,1,1,1,1,1
1,1,1,1,1,8,8,4,8,8,22,8,8,4,8,8,22,8,8,4,8,8,8,22,22,8,8,8,4,8,8,22,8,8,4,8,8,22,8,8,4,8,8,1,1,1,1,1
1,1,1,1,1,8,14,2,14,14,9,14,14,2,14,14,9,14,14,2,14,14,14,9,9,14,14,14,2,14,14,9,14,14,2,14,14,9,14,14,2,14,8,1,1,1,1,1
1,1,1,1,1,4,2,2,14,14,9,14,14,2,14,14,9,14,14,2,14,14,14,9,9,14,14,14,2,14,14,9,14,14,2,14,14,9,14,14,2,2,4,1,1,1,1,1
1,1,1,1,1,8,14,14,22,21,22,21,2,19,21,21,22,21,21,19,21,21,21,22,22,21,21,21,19,21,21,22,21,21,19,21,21,22,21,22,14,14,8,1,1,1,1,1
1,1,1,1,1,8,14,14,21,19,21,0,7,19,0,0,21,0,0,19,0,0,0,21,21,0,0,0,19,0,0,21,0,0,19,0,0,21,19,21,14,14,8,1,1,1,1,1
1,1,1,8,8,22,9,9,22,21,19,0,0,19,19,19,19,19,19,19,19,19,19,19,19,19,19,19,19,19,19,19,19,19,19,0,0,19,21,22,9,9,22,8,8,1,1,1
1,1,1,1,1,8,14,14,21,0,0,19,0,19,0,0,0,0,0,19,0,0,0,0,0,0,0,0,19,0,0,0,0,0,19,0,19,0,0,21,14,14,8,1,1,1,1,1
1,1,1,1,1,8,14,14,21,0,0,0,19,0,0,0,0,0,0,0,0,0,0,0,0,0,0,0,0,0,0,0,0,0,0,19,0,0,0,21,14,14,8,1,1,1,1,1
1,1,1,1,8,4,2,2,19,19,19,19,0,0,0,0,0,0,0,0,0,0,0,0,0,0,0,0,0,0,0,0,0,0,0,0,19,19,19,19,2,2,4,8,1,1,1,1
1,1,1,1,1,8,14,14,21,0,19,0,0,0,0,0,0,0,0,0,0,0,0,0,0,0,0,0,0,0,0,0,0,0,0,0,0,19,0,21,14,14,8,1,1,1,1,1
1,1,1,1,1,8,14,14,21,0,19,0,0,0,0,0,0,0,0,0,0,0,0,0,0,0,0,0,0,0,0,0,0,0,0,0,0,19,0,21,14,14,8,1,1,1,1,1
1,1,1,8,8,22,9,9,22,21,19,0,0,0,0,0,0,0,0,0,0,0,0,0,0,0,0,0,0,0,0,0,0,0,0,0,0,19,21,22,9,9,22,8,8,1,1,1
1,1,1,1,1,8,14,14,21,0,19,0,0,0,0,0,0,0,0,0,0,0,0,0,0,0,0,0,0,0,0,0,0,0,0,0,0,19,0,21,14,14,8,1,1,1,1,1
1,1,1,1,1,8,14,14,21,0,19,0,0,0,0,0,0,0,0,0,0,0,0,0,0,0,0,0,0,0,0,0,0,0,0,0,0,19,0,21,14,14,8,1,1,1,1,1
1,1,1,1,8,4,2,2,19,19,19,19,0,0,0,0,0,0,0,0,0,0,0,0,0,4,0,0,0,0,0,0,0,0,0,0,19,19,19,19,2,2,4,8,1,1,1,1
1,1,1,1,1,8,14,14,21,0,19,0,0,0,0,0,0,0,0,0,0,0,0,0,0,0,0,0,0,0,0,0,0,0,0,0,0,19,0,21,14,14,8,1,1,1,1,1
1,1,1,1,1,8,14,14,21,0,19,0,0,0,0,0,0,0,0,0,0,0,0,0,0,0,0,0,0,0,0,0,0,0,0,0,0,19,0,21,14,14,8,1,1,1,1,1
1,1,1,1,1,8,14,14,21,0,19,0,0,0,0,0,0,0,0,0,0,0,0,0,0,0,0,0,0,0,0,0,0,0,0,0,0,19,0,21,14,14,8,1,1,1,1,1
1,1,1,8,8,22,9,9,22,21,19,0,0,0,0,0,0,0,0,0,0,0,0,0,0,0,0,0,0,0,0,0,0,0,0,0,0,19,21,22,9,9,22,8,8,1,1,1
1,1,1,8,8,22,9,9,22,21,19,0,0,0,0,0,0,0,0,0,0,0,0,0,0,0,0,0,0,0,0,0,0,0,0,0,0,19,21,22,9,9,22,8,8,1,1,1
1,1,1,1,1,8,14,14,21,0,19,0,0,0,0,0,0,0,0,0,0,0,0,0,0,0,0,0,0,0,0,0,0,0,0,0,0,19,0,21,14,14,8,1,1,1,1,1
1,1,1,1,1,8,14,14,21,0,19,0,0,0,0,0,0,0,0,0,0,0,0,0,0,0,0,0,0,0,0,0,0,0,0,0,0,19,0,21,14,14,8,1,1,1,1,1
1,1,1,1,1,8,14,14,21,0,19,0,0,0,0,0,0,0,0,0,0,0,0,0,0,0,0,0,0,0,0,0,0,0,0,0,0,19,0,21,14,14,8,1,1,1,1,1
1,1,1,1,8,4,2,2,19,19,19,19,0,0,0,0,0,0,0,0,0,0,0,0,0,0,0,0,0,0,0,0,0,0,0,0,19,19,19,19,2,2,4,8,1,1,1,1
1,1,1,1,1,8,14,14,21,0,19,0,0,0,0,0,0,0,0,0,0,0,0,0,0,0,0,0,0,0,0,0,0,0,0,0,0,19,0,21,14,14,8,1,1,1,1,1
1,1,1,1,1,8,14,14,21,0,19,0,0,0,0,0,0,0,0,0,0,0,0,0,0,0,0,0,0,0,0,0,0,0,0,0,0,19,0,21,14,14,8,1,1,1,1,1
1,1,1,8,8,22,9,9,22,21,19,0,0,0,0,0,0,0,0,0,0,0,0,0,0,0,0,0,0,0,0,0,0,0,0,0,0,19,21,22,9,9,22,8,8,1,1,1
1,1,1,1,1,8,14,14,21,0,19,0,0,0,0,0,0,0,0,0,0,0,0,0,0,0,0,0,0,0,0,0,0,0,0,0,0,19,0,21,14,14,8,1,1,1,1,1
1,1,1,1,1,8,14,14,21,0,19,0,0,0,0,0,0,0,0,0,0,0,0,0,0,0,0,0,0,0,0,0,0,0,0,0,0,19,0,21,14,14,8,1,1,1,1,1
1,1,1,1,8,4,2,2,19,19,19,19,0,0,0,0,0,0,0,0,0,0,7,7,7,7,7,7,7,7,7,7,7,7,7,7,19,19,19,19,2,2,4,8,1,1,1,1
1,1,1,1,1,8,14,14,21,0,0,0,19,0,0,0,0,0,0,0,0,0,7,0,0,0,0,0,0,0,0,0,0,0,0,19,0,0,0,21,14,14,8,1,1,1,1,1
1,1,1,1,1,8,14,14,21,0,0,19,0,19,0,0,0,0,0,19,0,0,7,0,0,0,0,0,19,0,0,0,0,0,19,0,19,0,0,21,14,14,8,1,1,1,1,1
1,1,1,8,8,22,9,9,22,21,19,0,0,19,19,19,19,19,19,19,12,19,7,19,19,19,19,19,19,19,19,19,19,19,19,0,0,19,21,22,9,9,22,8,8,1,1,1
1,1,1,1,1,8,14,14,21,19,21,0,0,19,0,0,21,0,0,19,0,0,0,21,21,0,0,0,19,0,0,21,0,0,19,0,0,21,19,21,14,14,8,1,1,1,1,1
1,1,1,1,1,8,14,14,22,21,22,21,21,19,21,21,22,21,21,19,21,21,21,22,22,21,21,21,19,21,21,22,21,21,19,21,21,22,21,22,14,14,8,1,1,1,1,1
1,1,1,1,1,4,2,2,14,14,9,14,14,2,14,14,9,14,14,2,14,14,14,9,9,14,14,14,2,14,14,9,14,14,2,14,14,9,14,14,2,2,4,1,1,1,1,1
1,1,1,1,1,8,14,2,14,14,9,14,14,2,14,14,9,14,14,2,14,14,14,9,9,14,14,14,2,14,14,9,14,14,2,14,14,9,14,14,2,14,8,1,1,1,1,1
1,1,1,1,1,8,8,4,8,8,22,8,8,4,8,8,22,8,8,4,8,8,8,22,22,8,8,8,4,8,8,22,8,8,4,8,8,22,8,8,4,8,8,1,1,1,1,1
1,1,1,1,1,1,1,1,1,1,8,1,1,8,1,1,8,1,1,8,1,1,1,8,8,1,1,1,8,1,1,8,1,1,8,1,1,8,1,1,1,1,1,1,1,1,1,1
1,1,1,1,1,1,1,1,1,1,8,1,1,1,1,1,8,1,1,1,1,1,1,8,8,1,1,1,1,1,1,8,1,1,1,1,1,8,1,1,1,1,1,1,1,1,1,1
1,1,1,1,1,1,1,1,1,1,1,1,1,1,1,1,1,1,1,1,1,1,1,1,1,1,1,1,1,1,1,1,1,1,1,1,1,1,1,1,1,1,1,1,1,1,1,1
1,1,1,1,1,1,1,1,1,1,1,1,1,1,1,1,1,1,1,1,1,1,1,1,1,1,1,1,1,1,1,1,1,1,1,1,1,1,1,1,1,1,1,1,1,1,1,1
1,1,1,1,1,1,1,1,1,1,1,1,1,1,1,1,1,1,1,1,1,1,1,1,1,1,1,1,1,1,1,1,1,1,1,1,1,1,1,1,1,1,1,1,1,1,1,1
endlayer

layer
1,1,1,1,1,1,1,1,1,1,1,1,1,1,1,1,1,1,1,1,1,1,1,1,1,1,1,1,1,1,1,1,1,1,1,1,1,1,1,1,1,1,1,1,1,1,1,1
1,1,1,1,1,1,1,1,1,1,1,1,1,1,1,1,1,1,1,1,1,1,1,1,1,1,1,1,1,1,1,1,1,1,1,1,1,1,1,1,1,1,1,1,1,1,1,1
1,1,1,1,1,1,1,1,1,1,1,1,1,1,1,1,1,1,1,1,1,1,1,1,1,1,1,1,1,1,1,1,1,1,1,1,1,1,1,1,1,1,1,1,1,1,1,1
1,1,1,1,1,1,1,1,1,1,1,1,1,1,1,1,1,1,1,1,1,1,1,1,1,1,1,1,1,1,1,1,1,1,1,1,1,1,1,1,1,1,1,1,1,1,1,1
1,1,1,1,1,1,1,1,1,1,1,1,1,1,1,1,1,1,1,1,1,1,1,1,1,1,1,1,1,1,1,1,1,1,1,1,1,1,1,1,1,1,1,1,1,1,1,1
1,1,1,1,1,1,1,1,1,1,1,1,1,1,1,1,1,1,1,1,1,1,1,1,1,1,1,1,1,1,1,1,1,1,1,1,1,1,1,1,1,1,1,1,1,1,1,1
1,1,1,1,1,1,1,1,1,1,8,1,1,1,1,1,8,1,1,1,1,1,1,8,8,1,1,1,1,1,1,8,1,1,1,1,1,8,1,1,1,1,1,1,1,1,1,1
1,1,1,1,1,1,1,8,1,1,8,1,1,8,1,1,8,1,1,8,1,1,1,8,8,1,1,1,8,1,1,8,1,1,8,1,1,8,1,1,8,1,1,1,1,1,1,1
1,1,1,1,1,1,1,1,4,8,22,8,8,4,8,8,22,8,8,4,8,8,8,22,22,8,8,8,4,8,8,22,8,8,4,8,8,22,8,4,1,1,1,1,1,1,1,1
1,1,1,1,1,1,1,1,8,2,9,14,14,2,14,14,9,14,14,2,14,14,14,9,9,14,14,14,2,14,14,9,14,14,2,14,14,9,2,8,1,1,1,1,1,1,1,1
1,1,1,1,1,1,8,8,22,9,2,14,14,2,4,2,4,2,4,2,4,2,2,4,4,2,2,4,2,4,2,4,2,4,2,14,14,2,9,22,8,8,1,1,1,1,1,1
1,1,1,1,1,1,1,1,8,14,14,4,14,4,19,19,19,19,19,4,19,19,19,21,21,19,19,19,4,19,19,19,19,19,4,14,4,14,14,8,1,1,1,1,1,1,1,1
1,1,1,1,1,1,1,1,8,14,14,14,2,19,0,0,0,0,0,19,0,0,0,21,21,0,0,0,19,0,0,0,0,0,19,2,14,14,14,8,1,1,1,1,1,1,1,1
1,1,1,1,1,1,1,8,4,2,2,4,19,19,0,0,0,0,0,19,0,0,0,21,21,0,0,0,19,0,0,0,0,0,19,19,4,2,2,4,8,1,1,1,1,1,1,1
1,1,1,1,1,1,1,1,8,14,4,19,0,0,19,21,0,21,21,21,0,0,0,0,0,0,0,0,21,21,21,0,21,19,0,0,19,4,14,8,1,1,1,1,1,1,1,1
1,1,1,1,1,1,1,1,8,14,2,19,0,0,21,21,21,0,0,19,0,0,0,21,21,0,0,0,19,0,0,21,21,21,0,0,19,2,14,8,1,1,1,1,1,1,1,1
1,1,1,1,1,1,8,8,22,9,4,19,0,0,0,21,19,0,0,19,0,0,0,21,21,0,0,0,19,0,0,19,21,0,0,0,19,4,9,22,8,8,1,1,1,1,1,1
1,1,1,1,1,1,1,1,8,14,2,19,0,0,21,0,0,19,0,0,0,0,0,0,0,0,0,0,0,0,19,0,0,21,0,0,19,2,14,8,1,1,1,1,1,1,1,1
1,1,1,1,1,1,1,1,8,14,4,19,0,0,21,0,0,0,0,0,0,0,0,0,0,0,0,0,0,0,0,0,0,21,0,0,19,4,14,8,1,1,1,1,1,1,1,1
1,1,1,1,1,1,1,8,4,2,2,4,19,19,21,19,19,0,0,0,0,0,0,0,0,4,0,0,0,0,0,19,19,21,19,19,4,2,2,4,8,1,1,1,1,1,1,1
1,1,1,1,1,1,1,1,8,14,4,19,0,0,0,0,0,0,0,0,0,0,0,0,0,0,0,0,0,0,0,0,0,0,0,0,19,4,14,8,1,1,1,1,1,1,1,1
1,1,1,1,1,1,1,1,8,14,2,19,0,0,0,0,0,0,0,0,0,0,0,0,0,0,0,0,0,0,0,0,0,0,0,0,19,2,14,8,1,1,1,1,1,1,1,1
1,1,1,1,1,1,1,1,8,14,2,19,0,0,0,0,0,0,0,0,0,0,0,0,0,0,0,0,0,0,0,0,0,0,0,0,19,2,14,8,1,1,1,1,1,1,1,1
1,1,1,1,1,1,8,8,22,9,4,21,21,21,0,21,21,0,0,0,0,0,0,0,0,0,0,0,0,0,0,21,21,0,21,21,21,4,9,22,8,8,1,1,1,1,1,1
1,1,1,1,1,1,8,8,22,9,4,21,21,21,0,21,21,0,0,0,0,0,0,0,0,0,0,0,0,0,0,21,21,0,21,21,21,4,9,22,8,8,1,1,1,1,1,1
1,1,1,1,1,1,1,1,8,14,2,19,0,0,0,0,0,0,0,0,0,0,0,0,0,0,0,0,0,0,0,0,0,0,0,0,19,2,14,8,1,1,1,1,1,1,1,1
1,1,1,1,1,1,1,1,8,14,2,19,0,0,0,0,0,0,0,0,0,0,0,0,0,0,0,0,0,0,0,0,0,0,0,0,19,2,14,8,1,1,1,1,1,1,1,1
1,1,1,1,1,1,1,1,8,14,4,19,0,0,0,0,0,0,0,0,0,0,0,0,0,0,0,0,0,0,0,0,0,0,0,0,19,4,14,8,1,1,1,1,1,1,1,1
1,1,1,1,1,1,1,8,4,2,2,4,19,19,21,19,19,0,0,0,0,0,0,0,0,0,0,0,0,0,0,19,19,21,19,19,4,2,2,4,8,1,1,1,1,1,1,1
1,1,1,1,1,1,1,1,8,14,4,19,0,0,21,0,0,0,0,0,0,0,0,0,0,0,0,0,0,0,0,0,0,21,0,0,19,4,14,8,1,1,1,1,1,1,1,1
1,1,1,1,1,1,1,1,8,14,2,19,0,0,21,0,0,19,0,0,0,0,0,0,0,0,0,0,0,0,19,0,0,21,0,0,19,2,14,8,1,1,1,1,1,1,1,1
1,1,1,1,1,1,8,8,22,9,4,19,0,0,0,21,19,0,0,19,0,0,0,21,21,0,0,0,19,0,0,19,21,0,0,0,19,4,9,22,8,8,1,1,1,1,1,1
1,1,1,1,1,1,1,1,8,14,2,19,0,0,21,21,21,0,0,19,0,0,0,21,21,0,0,0,19,0,0,21,21,21,0,0,19,2,14,8,1,1,1,1,1,1,1,1
1,1,1,1,1,1,1,1,8,14,4,19,0,0,19,21,0,21,21,21,0,0,0,0,0,0,0,0,21,21,21,0,21,19,0,0,19,4,14,8,1,1,1,1,1,1,1,1
1,1,1,1,1,1,1,8,4,2,2,4,19,19,0,0,0,0,0,19,0,0,0,21,21,0,0,0,19,0,0,0,0,0,19,19,4,2,2,4,8,1,1,1,1,1,1,1
1,1,1,1,1,1,1,1,8,14,14,14,2,19,0,0,0,0,0,19,0,0,0,21,21,0,0,0,19,0,0,0,0,0,19,2,14,14,14,8,1,1,1,1,1,1,1,1
1,1,1,1,1,1,1,1,8,14,14,4,14,4,19,19,19,19,19,4,19,19,19,21,21,19,19,19,4,19,19,19,19,19,4,14,4,14,14,8,1,1,1,1,1,1,1,1
1,1,1,1,1,1,8,8,22,9,2,14,14,2,4,2,4,2,4,2,4,2,2,4,4,2,2,4,2,4,2,4,2,4,2,14,14,2,9,22,8,8,1,1,1,1,1,1
1,1,1,1,1,1,1,1,8,2,9,14,14,2,14,14,9,14,14,2,14,14,14,9,9,14,14,14,2,14,14,9,14,14,2,14,14,9,2,8,1,1,1,1,1,1,1,1
1,1,1,1,1,1,1,1,4,8,22,8,8,4,8,8,22,8,8,4,8,8,8,22,22,8,8,8,4,8,8,22,8,8,4,8,8,22,8,4,1,1,1,1,1,1,1,1
1,1,1,1,1,1,1,8,1,1,8,1,1,8,1,1,8,1,1,8,1,1,1,8,8,1,1,1,8,1,1,8,1,1,8,1,1,8,1,1,8,1,1,1,1,1,1,1
1,1,1,1,1,1,1,1,1,1,8,1,1,1,1,1,8,1,1,1,1,1,1,8,8,1,1,1,1,1,1,8,1,1,1,1,1,8,1,1,1,1,1,1,1,1,1,1
1,1,1,1,1,1,1,1,1,1,1,1,1,1,1,1,1,1,1,1,1,1,1,1,1,1,1,1,1,1,1,1,1,1,1,1,1,1,1,1,1,1,1,1,1,1,1,1
1,1,1,1,1,1,1,1,1,1,1,1,1,1,1,1,1,1,1,1,1,1,1,1,1,1,1,1,1,1,1,1,1,1,1,1,1,1,1,1,1,1,1,1,1,1,1,1
1,1,1,1,1,1,1,1,1,1,1,1,1,1,1,1,1,1,1,1,1,1,1,1,1,1,1,1,1,1,1,1,1,1,1,1,1,1,1,1,1,1,1,1,1,1,1,1
1,1,1,1,1,1,1,1,1,1,1,1,1,1,1,1,1,1,1,1,1,1,1,1,1,1,1,1,1,1,1,1,1,1,1,1,1,1,1,1,1,1,1,1,1,1,1,1
1,1,1,1,1,1,1,1,1,1,1,1,1,1,1,1,1,1,1,1,1,1,1,1,1,1,1,1,1,1,1,1,1,1,1,1,1,1,1,1,1,1,1,1,1,1,1,1
1,1,1,1,1,1,1,1,1,1,1,1,1,1,1,1,1,1,1,1,1,1,1,1,1,1,1,1,1,1,1,1,1,1,1,1,1,1,1,1,1,1,1,1,1,1,1,1
endlayer

layer
1,1,1,1,1,1,1,1,1,1,1,1,1,1,1,1,1,1,1,1,1,1,1,1,1,1,1,1,1,1,1,1,1,1,1,1,1,1,1,1,1,1,1,1,1,1,1,1
1,1,1,1,1,1,1,1,1,1,1,1,1,1,1,1,1,1,1,1,1,1,1,1,1,1,1,1,1,1,1,1,1,1,1,1,1,1,1,1,1,1,1,1,1,1,1,1
1,1,1,1,1,1,1,1,1,1,1,1,1,1,1,1,1,1,1,1,1,1,1,1,1,1,1,1,1,1,1,1,1,1,1,1,1,1,1,1,1,1,1,1,1,1,1,1
1,1,1,1,1,1,1,1,1,1,1,1,1,1,1,1,1,1,1,1,1,1,1,1,1,1,1,1,1,1,1,1,1,1,1,1,1,1,1,1,1,1,1,1,1,1,1,1
1,1,1,1,1,1,1,1,1,1,1,1,1,1,1,1,1,1,1,1,1,1,1,1,1,1,1,1,1,1,1,1,1,1,1,1,1,1,1,1,1,1,1,1,1,1,1,1
1,1,1,1,1,1,1,1,1,1,1,1,1,1,1,1,1,1,1,1,1,1,1,1,1,1,1,1,1,1,1,1,1,1,1,1,1,1,1,1,1,1,1,1,1,1,1,1
1,1,1,1,1,1,1,1,1,1,1,1,1,1,1,1,1,1,1,1,1,1,1,1,1,1,1,1,1,1,1,1,1,1,1,1,1,1,1,1,1,1,1,1,1,1,1,1
1,1,1,1,1,1,1,1,1,1,1,1,1,1,1,1,1,1,1,1,1,1,1,1,1,1,1,1,1,1,1,1,1,1,1,1,1,1,1,1,1,1,1,1,1,1,1,1
1,1,1,1,1,1,1,1,1,1,1,1,1,1,1,1,1,1,1,1,1,1,1,1,1,1,1,1,1,1,1,1,1,1,1,1,1,1,1,1,1,1,1,1,1,1,1,1
1,1,1,1,1,1,1,1,1,1,8,1,1,1,1,1,8,1,1,1,1,1,1,8,8,1,1,1,1,1,1,8,1,1,1,1,1,8,1,1,1,1,1,1,1,1,1,1
1,1,1,1,1,1,1,1,1,8,1,1,1,1,1,1,1,1,1,1,1,1,1,1,1,1,1,1,1,1,1,1,1,1,1,1,1,1,8,1,1,1,1,1,1,1,1,1
1,1,1,1,1,1,1,1,1,1,1,1,1,1,8,8,8,8,8,8,8,8,8,22,22,8,8,8,8,8,8,8,8,8,1,1,1,1,1,1,1,1,1,1,1,1,1,1
1,1,1,1,1,1,1,1,1,1,1,1,1,8,14,14,14,14,14,2,14,14,14,9,9,14,14,14,2,14,14,14,14,14,8,1,1,1,1,1,1,1,1,1,1,1,1,1
1,1,1,1,1,1,1,1,1,1,1,1,8,2,14,14,14,14,14,2,14,14,14,9,9,14,14,14,2,14,14,14,14,14,2,8,1,1,1,1,1,1,1,1,1,1,1,1
1,1,1,1,1,1,1,1,1,1,1,8,14,14,2,9,14,9,9,4,22,22,22,22,22,22,22,22,4,9,9,14,9,2,14,14,8,1,1,1,1,1,1,1,1,1,1,1
1,1,1,1,1,1,1,1,1,1,1,8,14,14,9,4,9,14,14,2,14,14,14,9,9,14,14,14,2,14,14,9,4,9,14,14,8,1,1,1,1,1,1,1,1,1,1,1
1,1,1,1,1,1,1,1,1,8,1,8,14,14,14,9,2,14,14,2,14,14,14,9,9,14,14,14,2,14,14,2,9,14,14,14,8,1,8,1,1,1,1,1,1,1,1,1
1,1,1,1,1,1,1,1,1,1,1,8,14,14,9,14,14,2,14,21,21,21,21,22,22,21,21,21,21,14,2,14,14,9,14,14,8,1,1,1,1,1,1,1,1,1,1,1
1,1,1,1,1,1,1,1,1,1,1,8,14,14,9,14,14,14,21,0,0,0,0,21,21,0,0,0,0,21,14,14,14,9,14,14,8,1,1,1,1,1,1,1,1,1,1,1
1,1,1,1,1,1,1,1,1,1,1,8,2,2,4,2,2,21,0,21,0,0,0,21,21,4,0,0,21,0,21,2,2,4,2,2,8,1,1,1,1,1,1,1,1,1,1,1
1,1,1,1,1,1,1,1,1,1,1,8,14,14,22,14,14,21,0,0,21,0,0,21,21,0,0,21,0,0,21,14,14,22,14,14,8,1,1,1,1,1,1,1,1,1,1,1
1,1,1,1,1,1,1,1,1,1,1,8,14,14,22,14,14,21,0,0,0,21,0,21,21,0,21,0,0,0,21,14,14,22,14,14,8,1,1,1,1,1,1,1,1,1,1,1
1,1,1,1,1,1,1,1,1,1,1,8,14,14,22,14,14,21,0,0,0,0,19,19,19,19,0,0,0,0,21,14,14,22,14,14,8,1,1,1,1,1,1,1,1,1,1,1
1,1,1,1,1,1,1,1,1,8,1,22,9,9,22,9,9,22,21,21,21,21,19,0,0,19,21,21,21,21,22,9,9,22,9,9,22,1,8,1,1,1,1,1,1,1,1,1
1,1,1,1,1,1,1,1,1,8,1,22,9,9,22,9,9,22,21,21,21,21,19,0,0,19,21,21,21,21,22,9,9,22,9,9,22,1,8,1,1,1,1,1,1,1,1,1
1,1,1,1,1,1,1,1,1,1,1,8,14,14,22,14,14,21,0,0,0,0,19,19,19,19,0,0,0,0,21,14,14,22,14,14,8,1,1,1,1,1,1,1,1,1,1,1
1,1,1,1,1,1,1,1,1,1,1,8,14,14,22,14,14,21,0,0,0,21,0,21,21,0,21,0,0,0,21,14,14,22,14,14,8,1,1,1,1,1,1,1,1,1,1,1
1,1,1,1,1,1,1,1,1,1,1,8,14,14,22,14,14,21,0,0,21,0,0,21,21,0,0,21,0,0,21,14,14,22,14,14,8,1,1,1,1,1,1,1,1,1,1,1
1,1,1,1,1,1,1,1,1,1,1,8,2,2,4,2,2,21,0,21,0,0,0,21,21,0,0,0,21,0,21,2,2,4,2,2,8,1,1,1,1,1,1,1,1,1,1,1
1,1,1,1,1,1,1,1,1,1,1,8,14,14,9,14,14,14,21,0,0,0,0,21,21,0,0,0,0,21,14,14,14,9,14,14,8,1,1,1,1,1,1,1,1,1,1,1
1,1,1,1,1,1,1,1,1,1,1,8,14,14,9,14,14,2,14,21,21,21,21,22,22,21,21,21,21,14,2,14,14,9,14,14,8,1,1,1,1,1,1,1,1,1,1,1
1,1,1,1,1,1,1,1,1,8,1,8,14,14,14,9,2,14,14,2,14,14,14,9,9,14,14,14,2,14,14,2,9,14,14,14,8,1,8,1,1,1,1,1,1,1,1,1
1,1,1,1,1,1,1,1,1,1,1,8,14,14,9,4,9,14,14,2,14,14,14,9,9,14,14,14,2,14,14,9,4,9,14,14,8,1,1,1,1,1,1,1,1,1,1,1
1,1,1,1,1,1,1,1,1,1,1,8,14,14,2,9,14,9,9,4,22,22,22,22,22,22,22,22,4,9,9,14,9,2,14,14,8,1,1,1,1,1,1,1,1,1,1,1
1,1,1,1,1,1,1,1,1,1,1,1,8,2,14,14,14,14,14,2,14,14,14,9,9,14,14,14,2,14,14,14,14,14,2,8,1,1,1,1,1,1,1,1,1,1,1,1
1,1,1,1,1,1,1,1,1,1,1,1,1,8,14,14,14,14,14,2,14,14,14,9,9,14,14,14,2,14,14,14,14,14,8,1,1,1,1,1,1,1,1,1,1,1,1,1
1,1,1,1,1,1,1,1,1,1,1,1,1,1,8,8,8,8,8,8,8,8,8,22,22,8,8,8,8,8,8,8,8,8,1,1,1,1,1,1,1,1,1,1,1,1,1,1
1,1,1,1,1,1,1,1,1,8,1,1,1,1,1,1,1,1,1,1,1,1,1,1,1,1,1,1,1,1,1,1,1,1,1,1,1,1,8,1,1,1,1,1,1,1,1,1
1,1,1,1,1,1,1,1,1,1,8,1,1,1,1,1,8,1,1,1,1,1,1,8,8,1,1,1,1,1,1,8,1,1,1,1,1,8,1,1,1,1,1,1,1,1,1,1
1,1,1,1,1,1,1,1,1,1,1,1,1,1,1,1,1,1,1,1,1,1,1,1,1,1,1,1,1,1,1,1,1,1,1,1,1,1,1,1,1,1,1,1,1,1,1,1
1,1,1,1,1,1,1,1,1,1,1,1,1,1,1,1,1,1,1,1,1,1,1,1,1,1,1,1,1,1,1,1,1,1,1,1,1,1,1,1,1,1,1,1,1,1,1,1
1,1,1,1,1,1,1,1,1,1,1,1,1,1,1,1,1,1,1,1,1,1,1,1,1,1,1,1,1,1,1,1,1,1,1,1,1,1,1,1,1,1,1,1,1,1,1,1
1,1,1,1,1,1,1,1,1,1,1,1,1,1,1,1,1,1,1,1,1,1,1,1,1,1,1,1,1,1,1,1,1,1,1,1,1,1,1,1,1,1,1,1,1,1,1,1
1,1,1,1,1,1,1,1,1,1,1,1,1,1,1,1,1,1,1,1,1,1,1,1,1,1,1,1,1,1,1,1,1,1,1,1,1,1,1,1,1,1,1,1,1,1,1,1
1,1,1,1,1,1,1,1,1,1,1,1,1,1,1,1,1,1,1,1,1,1,1,1,1,1,1,1,1,1,1,1,1,1,1,1,1,1,1,1,1,1,1,1,1,1,1,1
1,1,1,1,1,1,1,1,1,1,1,1,1,1,1,1,1,1,1,1,1,1,1,1,1,1,1,1,1,1,1,1,1,1,1,1,1,1,1,1,1,1,1,1,1,1,1,1
1,1,1,1,1,1,1,1,1,1,1,1,1,1,1,1,1,1,1,1,1,1,1,1,1,1,1,1,1,1,1,1,1,1,1,1,1,1,1,1,1,1,1,1,1,1,1,1
1,1,1,1,1,1,1,1,1,1,1,1,1,1,1,1,1,1,1,1,1,1,1,1,1,1,1,1,1,1,1,1,1,1,1,1,1,1,1,1,1,1,1,1,1,1,1,1
endlayer

layer
1,1,1,1,1,1,1,1,1,1,1,1,1,1,1,1,1,1,1,1,1,1,1,1,1,1,1,1,1,1,1,1,1,1,1,1,1,1,1,1,1,1,1,1,1,1,1,1
1,1,1,1,1,1,1,1,1,1,1,1,1,1,1,1,1,1,1,1,1,1,1,1,1,1,1,1,1,1,1,1,1,1,1,1,1,1,1,1,1,1,1,1,1,1,1,1
1,1,1,1,1,1,1,1,1,1,1,1,1,1,1,1,1,1,1,1,1,1,1,1,1,1,1,1,1,1,1,1,1,1,1,1,1,1,1,1,1,1,1,1,1,1,1,1
1,1,1,1,1,1,1,1,1,1,1,1,1,1,1,1,1,1,1,1,1,1,1,1,1,1,1,1,1,1,1,1,1,1,1,1,1,1,1,1,1,1,1,1,1,1,1,1
1,1,1,1,1,1,1,1,1,1,1,1,1,1,1,1,1,1,1,1,1,1,1,1,1,1,1,1,1,1,1,1,1,1,1,1,1,1,1,1,1,1,1,1,1,1,1,1
1,1,1,1,1,1,1,1,1,1,1,1,1,1,1,1,1,1,1,1,1,1,1,1,1,1,1,1,1,1,1,1,1,1,1,1,1,1,1,1,1,1,1,1,1,1,1,1
1,1,1,1,1,1,1,1,1,1,1,1,1,1,1,1,1,1,1,1,1,1,1,1,1,1,1,1,1,1,1,1,1,1,1,1,1,1,1,1,1,1,1,1,1,1,1,1
1,1,1,1,1,1,1,1,1,1,1,1,1,1,1,1,1,1,1,1,1,1,1,1,1,1,1,1,1,1,1,1,1,1,1,1,1,1,1,1,1,1,1,1,1,1,1,1
1,1,1,1,1,1,1,1,1,1,1,1,1,1,1,1,1,1,1,1,1,1,1,1,1,1,1,1,1,1,1,1,1,1,1,1,1,1,1,1,1,1,1,1,1,1,1,1
1,1,1,1,1,1,1,1,1,1,1,1,1,1,1,1,1,1,1,1,1,1,1,1,1,1,1,1,1,1,1,1,1,1,1,1,1,1,1,1,1,1,1,1,1,1,1,1
1,1,1,1,1,1,1,1,1,1,1,1,1,1,1,1,1,1,1,1,1,1,1,1,1,1,1,1,1,1,1,1,1,1,1,1,1,1,1,1,1,1,1,1,1,1,1,1
1,1,1,1,1,1,1,1,1,1,1,1,1,1,1,1,1,1,1,1,1,1,1,1,1,1,1,1,1,1,1,1,1,1,1,1,1,1,1,1,1,1,1,1,1,1,1,1
1,1,1,1,1,1,1,1,1,1,1,1,1,1,1,1,1,1,1,1,1,1,1,8,8,1,1,1,1,1,1,1,1,1,1,1,1,1,1,1,1,1,1,1,1,1,1,1
1,1,1,1,1,1,1,1,1,1,1,1,1,1,1,1,1,1,1,1,1,1,1,8,8,1,1,1,1,1,1,1,1,1,1,1,1,1,1,1,1,1,1,1,1,1,1,1
1,1,1,1,1,1,1,1,1,1,1,1,1,1,1,8,1,8,8,1,1,1,1,8,8,1,1,1,1,8,8,1,8,1,1,1,1,1,1,1,1,1,1,1,1,1,1,1
1,1,1,1,1,1,1,1,1,1,1,1,1,1,8,8,8,1,1,1,1,1,1,8,8,1,1,1,1,1,1,8,8,8,1,1,1,1,1,1,1,1,1,1,1,1,1,1
1,1,1,1,1,1,1,1,1,1,1,1,1,1,1,8,1,1,1,8,1,1,1,8,8,1,1,1,8,1,1,1,8,1,1,1,1,1,1,1,1,1,1,1,1,1,1,1
1,1,1,1,1,1,1,1,1,1,1,1,1,1,8,1,1,8,1,2,4,2,2,4,4,2,2,4,2,1,8,1,1,8,1,1,1,1,1,1,1,1,1,1,1,1,1,1
1,1,1,1,1,1,1,1,1,1,1,1,1,1,8,1,1,1,4,14,14,14,14,9,9,14,14,14,14,4,1,1,1,8,1,1,1,1,1,1,1,1,1,1,1,1,1,1
1,1,1,1,1,1,1,1,1,1,1,1,1,1,1,1,8,2,14,9,14,14,14,9,9,4,14,14,9,14,2,8,1,1,1,1,1,1,1,1,1,1,1,1,1,1,1,1
1,1,1,1,1,1,1,1,1,1,1,1,1,1,1,1,1,4,14,14,9,14,14,9,9,14,14,9,14,14,4,1,1,1,1,1,1,1,1,1,1,1,1,1,1,1,1,1
1,1,1,1,1,1,1,1,1,1,1,1,1,1,1,1,1,2,14,14,14,9,14,9,9,14,9,14,14,14,2,1,1,1,1,1,1,1,1,1,1,1,1,1,1,1,1,1
1,1,1,1,1,1,1,1,1,1,1,1,1,1,1,1,1,2,14,14,14,14,2,4,4,2,14,14,14,14,2,1,1,1,1,1,1,1,1,1,1,1,1,1,1,1,1,1
1,1,1,1,1,1,1,1,1,1,1,1,8,8,8,8,8,4,9,9,9,9,4,4,4,4,9,9,9,9,4,8,8,8,8,8,1,1,1,1,1,1,1,1,1,1,1,1
1,1,1,1,1,1,1,1,1,1,1,1,8,8,8,8,8,4,9,9,9,9,4,4,4,4,9,9,9,9,4,8,8,8,8,8,1,1,1,1,1,1,1,1,1,1,1,1
1,1,1,1,1,1,1,1,1,1,1,1,1,1,1,1,1,2,14,14,14,14,2,4,4,2,14,14,14,14,2,1,1,1,1,1,1,1,1,1,1,1,1,1,1,1,1,1
1,1,1,1,1,1,1,1,1,1,1,1,1,1,1,1,1,2,14,14,14,9,14,9,9,14,9,14,14,14,2,1,1,1,1,1,1,1,1,1,1,1,1,1,1,1,1,1
1,1,1,1,1,1,1,1,1,1,1,1,1,1,1,1,1,4,14,14,9,14,14,9,9,14,14,9,14,14,4,1,1,1,1,1,1,1,1,1,1,1,1,1,1,1,1,1
1,1,1,1,1,1,1,1,1,1,1,1,1,1,1,1,8,2,14,9,14,14,14,9,9,14,14,14,9,14,2,8,1,1,1,1,1,1,1,1,1,1,1,1,1,1,1,1
1,1,1,1,1,1,1,1,1,1,1,1,1,1,8,1,1,1,4,14,14,14,14,9,9,14,14,14,14,4,1,1,1,8,1,1,1,1,1,1,1,1,1,1,1,1,1,1
1,1,1,1,1,1,1,1,1,1,1,1,1,1,8,1,1,8,1,2,4,2,2,4,4,2,2,4,2,1,8,1,1,8,1,1,1,1,1,1,1,1,1,1,1,1,1,1
1,1,1,1,1,1,1,1,1,1,1,1,1,1,1,8,1,1,1,8,1,1,1,8,8,1,1,1,8,1,1,1,8,1,1,1,1,1,1,1,1,1,1,1,1,1,1,1
1,1,1,1,1,1,1,1,1,1,1,1,1,1,8,8,8,1,1,1,1,1,1,8,8,1,1,1,1,1,1,8,8,8,1,1,1,1,1,1,1,1,1,1,1,1,1,1
1,1,1,1,1,1,1,1,1,1,1,1,1,1,1,8,1,8,8,1,1,1,1,8,8,1,1,1,1,8,8,1,8,1,1,1,1,1,1,1,1,1,1,1,1,1,1,1
1,1,1,1,1,1,1,1,1,1,1,1,1,1,1,1,1,1,1,1,1,1,1,8,8,1,1,1,1,1,1,1,1,1,1,1,1,1,1,1,1,1,1,1,1,1,1,1
1,1,1,1,1,1,1,1,1,1,1,1,1,1,1,1,1,1,1,1,1,1,1,8,8,1,1,1,1,1,1,1,1,1,1,1,1,1,1,1,1,1,1,1,1,1,1,1
1,1,1,1,1,1,1,1,1,1,1,1,1,1,1,1,1,1,1,1,1,1,1,1,1,1,1,1,1,1,1,1,1,1,1,1,1,1,1,1,1,1,1,1,1,1,1,1
1,1,1,1,1,1,1,1,1,1,1,1,1,1,1,1,1,1,1,1,1,1,1,1,1,1,1,1,1,1,1,1,1,1,1,1,1,1,1,1,1,1,1,1,1,1,1,1
1,1,1,1,1,1,1,1,1,1,1,1,1,1,1,1,1,1,1,1,1,1,1,1,1,1,1,1,1,1,1,1,1,1,1,1,1,1,1,1,1,1,1,1,1,1,1,1
1,1,1,1,1,1,1,1,1,1,1,1,1,1,1,1,1,1,1,1,1,1,1,1,1,1,1,1,1,1,1,1,1,1,1,1,1,1,1,1,1,1,1,1,1,1,1,1
1,1,1,1,1,1,1,1,1,1,1,1,1,1,1,1,1,1,1,1,1,1,1,1,1,1,1,1,1,1,1,1,1,1,1,1,1,1,1,1,1,1,1,1,1,1,1,1
1,1,1,1,1,1,1,1,1,1,1,1,1,1,1,1,1,1,1,1,1,1,1,1,1,1,1,1,1,1,1,1,1,1,1,1,1,1,1,1,1,1,1,1,1,1,1,1
1,1,1,1,1,1,1,1,1,1,1,1,1,1,1,1,1,1,1,1,1,1,1,1,1,1,1,1,1,1,1,1,1,1,1,1,1,1,1,1,1,1,1,1,1,1,1,1
1,1,1,1,1,1,1,1,1,1,1,1,1,1,1,1,1,1,1,1,1,1,1,1,1,1,1,1,1,1,1,1,1,1,1,1,1,1,1,1,1,1,1,1,1,1,1,1
1,1,1,1,1,1,1,1,1,1,1,1,1,1,1,1,1,1,1,1,1,1,1,1,1,1,1,1,1,1,1,1,1,1,1,1,1,1,1,1,1,1,1,1,1,1,1,1
1,1,1,1,1,1,1,1,1,1,1,1,1,1,1,1,1,1,1,1,1,1,1,1,1,1,1,1,1,1,1,1,1,1,1,1,1,1,1,1,1,1,1,1,1,1,1,1
1,1,1,1,1,1,1,1,1,1,1,1,1,1,1,1,1,1,1,1,1,1,1,1,1,1,1,1,1,1,1,1,1,1,1,1,1,1,1,1,1,1,1,1,1,1,1,1
1,1,1,1,1,1,1,1,1,1,1,1,1,1,1,1,1,1,1,1,1,1,1,1,1,1,1,1,1,1,1,1,1,1,1,1,1,1,1,1,1,1,1,1,1,1,1,1
endlayer

layer
1,1,1,1,1,1,1,1,1,1,1,1,1,1,1,1,1,1,1,1,1,1,1,1,1,1,1,1,1,1,1,1,1,1,1,1,1,1,1,1,1,1,1,1,1,1,1,1
1,1,1,1,1,1,1,1,1,1,1,1,1,1,1,1,1,1,1,1,1,1,1,1,1,1,1,1,1,1,1,1,1,1,1,1,1,1,1,1,1,1,1,1,1,1,1,1
1,1,1,1,1,1,1,1,1,1,1,1,1,1,1,1,1,1,1,1,1,1,1,1,1,1,1,1,1,1,1,1,1,1,1,1,1,1,1,1,1,1,1,1,1,1,1,1
1,1,1,1,1,1,1,1,1,1,1,1,1,1,1,1,1,1,1,1,1,1,1,1,1,1,1,1,1,1,1,1,1,1,1,1,1,1,1,1,1,1,1,1,1,1,1,1
1,1,1,1,1,1,1,1,1,1,1,1,1,1,1,1,1,1,1,1,1,1,1,1,1,1,1,1,1,1,1,1,1,1,1,1,1,1,1,1,1,1,1,1,1,1,1,1
1,1,1,1,1,1,1,1,1,1,1,1,1,1,1,1,1,1,1,1,1,1,1,1,1,1,1,1,1,1,1,1,1,1,1,1,1,1,1,1,1,1,1,1,1,1,1,1
1,1,1,1,1,1,1,1,1,1,1,1,1,1,1,1,1,1,1,1,1,1,1,1,1,1,1,1,1,1,1,1,1,1,1,1,1,1,1,1,1,1,1,1,1,1,1,1
1,1,1,1,1,1,1,1,1,1,1,1,1,1,1,1,1,1,1,1,1,1,1,1,1,1,1,1,1,1,1,1,1,1,1,1,1,1,1,1,1,1,1,1,1,1,1,1
1,1,1,1,1,1,1,1,1,1,1,1,1,1,1,1,1,1,1,1,1,1,1,1,1,1,1,1,1,1,1,1,1,1,1,1,1,1,1,1,1,1,1,1,1,1,1,1
1,1,1,1,1,1,1,1,1,1,1,1,1,1,1,1,1,1,1,1,1,1,1,1,1,1,1,1,1,1,1,1,1,1,1,1,1,1,1,1,1,1,1,1,1,1,1,1
1,1,1,1,1,1,1,1,1,1,1,1,1,1,1,1,1,1,1,1,1,1,1,1,1,1,1,1,1,1,1,1,1,1,1,1,1,1,1,1,1,1,1,1,1,1,1,1
1,1,1,1,1,1,1,1,1,1,1,1,1,1,1,1,1,1,1,1,1,1,1,1,1,1,1,1,1,1,1,1,1,1,1,1,1,1,1,1,1,1,1,1,1,1,1,1
1,1,1,1,1,1,1,1,1,1,1,1,1,1,1,1,1,1,1,1,1,1,1,1,1,1,1,1,1,1,1,1,1,1,1,1,1,1,1,1,1,1,1,1,1,1,1,1
1,1,1,1,1,1,1,1,1,1,1,1,1,1,1,1,1,1,1,1,1,1,1,1,1,1,1,1,1,1,1,1,1,1,1,1,1,1,1,1,1,1,1,1,1,1,1,1
1,1,1,1,1,1,1,1,1,1,1,1,1,1,1,1,1,1,1,1,1,1,1,1,1,1,1,1,1,1,1,1,1,1,1,1,1,1,1,1,1,1,1,1,1,1,1,1
1,1,1,1,1,1,1,1,1,1,1,1,1,1,1,1,1,1,1,1,1,1,1,1,1,1,1,1,1,1,1,1,1,1,1,1,1,1,1,1,1,1,1,1,1,1,1,1
1,1,1,1,1,1,1,1,1,1,1,1,1,1,1,1,1,1,1,1,1,1,1,1,1,1,1,1,1,1,1,1,1,1,1,1,1,1,1,1,1,1,1,1,1,1,1,1
1,1,1,1,1,1,1,1,1,1,1,1,1,1,1,1,1,1,1,1,1,1,1,1,1,1,1,1,1,1,1,1,1,1,1,1,1,1,1,1,1,1,1,1,1,1,1,1
1,1,1,1,1,1,1,1,1,1,1,1,1,1,1,1,1,1,1,1,1,1,1,8,8,1,1,1,1,1,1,1,1,1,1,1,1,1,1,1,1,1,1,1,1,1,1,1
1,1,1,1,1,1,1,1,1,1,1,1,1,1,1,1,1,1,1,8,1,1,1,8,8,8,1,1,8,1,1,1,1,1,1,1,1,1,1,1,1,1,1,1,1,1,1,1
1,1,1,1,1,1,1,1,1,1,1,1,1,1,1,1,1,1,1,1,8,1,1,8,8,1,1,8,1,1,1,1,1,1,1,1,1,1,1,1,1,1,1,1,1,1,1,1
1,1,1,1,1,1,1,1,1,1,1,1,1,1,1,1,1,1,1,1,1,8,1,8,8,1,8,1,1,1,1,1,1,1,1,1,1,1,1,1,1,1,1,1,1,1,1,1
1,1,1,1,1,1,1,1,1,1,1,1,1,1,1,1,1,1,1,1,1,1,1,8,8,1,1,1,1,1,1,1,1,1,1,1,1,1,1,1,1,1,1,1,1,1,1,1
1,1,1,1,1,1,1,1,1,1,1,1,1,1,1,1,1,1,8,8,8,8,8,1,1,8,8,8,8,8,1,1,1,1,1,1,1,1,1,1,1,1,1,1,1,1,1,1
1,1,1,1,1,1,1,1,1,1,1,1,1,1,1,1,1,1,8,8,8,8,8,1,1,8,8,8,8,8,1,1,1,1,1,1,1,1,1,1,1,1,1,1,1,1,1,1
1,1,1,1,1,1,1,1,1,1,1,1,1,1,1,1,1,1,1,1,1,1,1,8,8,1,1,1,1,1,1,1,1,1,1,1,1,1,1,1,1,1,1,1,1,1,1,1
1,1,1,1,1,1,1,1,1,1,1,1,1,1,1,1,1,1,1,1,1,8,1,8,8,1,8,1,1,1,1,1,1,1,1,1,1,1,1,1,1,1,1,1,1,1,1,1
1,1,1,1,1,1,1,1,1,1,1,1,1,1,1,1,1,1,1,1,8,1,1,8,8,1,1,8,1,1,1,1,1,1,1,1,1,1,1,1,1,1,1,1,1,1,1,1
1,1,1,1,1,1,1,1,1,1,1,1,1,1,1,1,1,1,1,8,1,1,1,8,8,1,1,1,8,1,1,1,1,1,1,1,1,1,1,1,1,1,1,1,1,1,1,1
1,1,1,1,1,1,1,1,1,1,1,1,1,1,1,1,1,1,1,1,1,1,1,8,8,1,1,1,1,1,1,1,1,1,1,1,1,1,1,1,1,1,1,1,1,1,1,1
1,1,1,1,1,1,1,1,1,1,1,1,1,1,1,1,1,1,1,1,1,1,1,1,1,1,1,1,1,1,1,1,1,1,1,1,1,1,1,1,1,1,1,1,1,1,1,1
1,1,1,1,1,1,1,1,1,1,1,1,1,1,1,1,1,1,1,1,1,1,1,1,1,1,1,1,1,1,1,1,1,1,1,1,1,1,1,1,1,1,1,1,1,1,1,1
1,1,1,1,1,1,1,1,1,1,1,1,1,1,1,1,1,1,1,1,1,1,1,1,1,1,1,1,1,1,1,1,1,1,1,1,1,1,1,1,1,1,1,1,1,1,1,1
1,1,1,1,1,1,1,1,1,1,1,1,1,1,1,1,1,1,1,1,1,1,1,1,1,1,1,1,1,1,1,1,1,1,1,1,1,1,1,1,1,1,1,1,1,1,1,1
1,1,1,1,1,1,1,1,1,1,1,1,1,1,1,1,1,1,1,1,1,1,1,1,1,1,1,1,1,1,1,1,1,1,1,1,1,1,1,1,1,1,1,1,1,1,1,1
1,1,1,1,1,1,1,1,1,1,1,1,1,1,1,1,1,1,1,1,1,1,1,1,1,1,1,1,1,1,1,1,1,1,1,1,1,1,1,1,1,1,1,1,1,1,1,1
1,1,1,1,1,1,1,1,1,1,1,1,1,1,1,1,1,1,1,1,1,1,1,1,1,1,1,1,1,1,1,1,1,1,1,1,1,1,1,1,1,1,1,1,1,1,1,1
1,1,1,1,1,1,1,1,1,1,1,1,1,1,1,1,1,1,1,1,1,1,1,1,1,1,1,1,1,1,1,1,1,1,1,1,1,1,1,1,1,1,1,1,1,1,1,1
1,1,1,1,1,1,1,1,1,1,1,1,1,1,1,1,1,1,1,1,1,1,1,1,1,1,1,1,1,1,1,1,1,1,1,1,1,1,1,1,1,1,1,1,1,1,1,1
1,1,1,1,1,1,1,1,1,1,1,1,1,1,1,1,1,1,1,1,1,1,1,1,1,1,1,1,1,1,1,1,1,1,1,1,1,1,1,1,1,1,1,1,1,1,1,1
1,1,1,1,1,1,1,1,1,1,1,1,1,1,1,1,1,1,1,1,1,1,1,1,1,1,1,1,1,1,1,1,1,1,1,1,1,1,1,1,1,1,1,1,1,1,1,1
1,1,1,1,1,1,1,1,1,1,1,1,1,1,1,1,1,1,1,1,1,1,1,1,1,1,1,1,1,1,1,1,1,1,1,1,1,1,1,1,1,1,1,1,1,1,1,1
1,1,1,1,1,1,1,1,1,1,1,1,1,1,1,1,1,1,1,1,1,1,1,1,1,1,1,1,1,1,1,1,1,1,1,1,1,1,1,1,1,1,1,1,1,1,1,1
1,1,1,1,1,1,1,1,1,1,1,1,1,1,1,1,1,1,1,1,1,1,1,1,1,1,1,1,1,1,1,1,1,1,1,1,1,1,1,1,1,1,1,1,1,1,1,1
1,1,1,1,1,1,1,1,1,1,1,1,1,1,1,1,1,1,1,1,1,1,1,1,1,1,1,1,1,1,1,1,1,1,1,1,1,1,1,1,1,1,1,1,1,1,1,1
1,1,1,1,1,1,1,1,1,1,1,1,1,1,1,1,1,1,1,1,1,1,1,1,1,1,1,1,1,1,1,1,1,1,1,1,1,1,1,1,1,1,1,1,1,1,1,1
1,1,1,1,1,1,1,1,1,1,1,1,1,1,1,1,1,1,1,1,1,1,1,1,1,1,1,1,1,1,1,1,1,1,1,1,1,1,1,1,1,1,1,1,1,1,1,1
1,1,1,1,1,1,1,1,1,1,1,1,1,1,1,1,1,1,1,1,1,1,1,1,1,1,1,1,1,1,1,1,1,1,1,1,1,1,1,1,1,1,1,1,1,1,1,1
endlayer

