weight=1
dimensionsToSpawnIn=overworld
embed_into_distance=1
random_height_offset=0,0
unacceptable_target_blocks=sand,flowing_water,water,flowing_lava,lava,ice,packed_ice,stained_hardened_clay-9,brick_block,double_stone_slab,stonebrick,red_sandstone,red_nether_brick,red_mushroom_block,brown_mushroom_block,planks,cobblestone,end_stone,obsidian,purpur_block,iron_bars,purpur_slab,purpur_pillar,netherrack,soul_sand,quartz_ore,stained_glass,glass
dimensions=22,12,12
allowable_overhang=0
max_leveling=1
leveling_buffer=-1
preventRotation=0
preserve_water=0
preserve_lava=0
uniqueMinDistance=5000
spawnMinDistance=0
spawnMaxDistance=0

rule1=0,100,preserveBlock
rule2=0,100,minecraft:log-0
rule3=0,100,minecraft:vine-8
rule4=0,100,minecraft:vine-1
rule5=0,100,minecraft:vine-4
rule6=0,100,minecraft:ladder-2
rule7=0,100,minecraft:vine-2
rule8=0,100,minecraft:spruce_stairs-7
rule9=0,100,minecraft:wooden_slab-9
rule10=0,100,minecraft:spruce_stairs-6
rule11=0,100,minecraft:spruce_stairs-5
rule12=0,100,minecraft:spruce_stairs-4
rule13=0,100,minecraft:spruce_stairs-2
rule14=0,100,minecraft:spruce_stairs-3
rule15=0,100,minecraft:spruce_stairs-0
rule16=0,100,minecraft:cobblestone_wall-0
rule17=0,100,minecraft:spruce_stairs-1
rule18=0,100,minecraft:spruce_fence-0
rule19=0,100,minecraft:spruce_fence_gate-3
rule20=0,100,minecraft:wooden_slab-1
rule21=0,100,minecraft:spruce_fence_gate-4
rule22=0,100,minecraft:spruce_fence_gate-2
rule23=0,100,minecraft:spruce_fence_gate-0
rule24=0,100,minecraft:spruce_fence_gate-1
rule25=0,100,minecraft:log-4
rule26=0,100,minecraft:log-8
rule27=0,100,minecraft:double_wooden_slab-1
rule28=0,100,minecraft:planks-1
rule29=0,100,minecraft:log-1
rule30=0,100,minecraft:water-0

layer
1,1,1,1,1,1,1,1,1,1,1,1
1,1,1,1,1,1,1,1,1,1,1,1
1,1,2,1,1,1,1,1,1,2,1,1
1,1,1,1,1,1,1,1,1,1,1,1
1,1,1,1,1,1,1,1,1,1,1,1
1,1,1,1,1,1,1,1,1,1,2,1
1,1,1,1,1,1,1,1,1,1,1,1
1,1,1,1,1,1,1,1,1,1,1,1
1,1,1,1,1,1,1,1,1,1,1,1
1,1,2,1,1,1,1,1,1,2,1,1
1,1,1,1,1,1,1,1,1,1,1,1
1,1,1,1,1,1,1,1,1,1,1,1
endlayer

layer
1,1,1,1,1,1,1,1,1,1,1,1
1,1,1,1,1,1,1,1,1,1,1,1
1,1,2,1,1,1,1,1,1,2,1,1
1,1,1,1,1,1,1,1,1,1,1,1
1,1,1,1,1,1,1,1,1,1,1,1
1,1,1,1,1,1,1,1,1,1,2,1
1,1,1,1,1,1,1,1,1,1,1,1
1,1,1,1,1,1,1,1,1,1,1,1
1,1,1,1,1,1,1,1,1,1,1,1
1,1,2,1,1,1,1,1,1,2,1,1
1,1,1,1,1,1,1,1,1,1,1,1
1,1,1,1,1,1,1,1,1,1,1,1
endlayer

layer
1,1,1,1,1,1,1,1,1,1,1,1
1,1,3,1,1,1,1,1,1,3,1,1
1,5,2,0,0,0,0,0,0,2,4,1
1,1,0,0,0,0,0,0,0,0,1,1
1,1,0,0,0,0,0,0,0,0,3,1
1,1,0,0,0,0,0,0,0,0,2,6
1,1,0,0,0,0,0,0,0,0,7,1
1,1,0,0,0,0,0,0,0,0,1,1
1,1,0,0,0,0,0,0,0,0,1,1
1,0,2,4,0,0,0,0,0,2,0,1
1,1,7,0,1,1,1,1,1,7,1,1
1,1,1,1,1,1,1,1,1,1,1,1
endlayer

layer
0,0,0,0,0,0,0,0,0,0,0,0
0,0,3,0,0,0,0,0,0,3,0,0
0,5,2,10,9,9,9,9,8,2,4,0
0,0,11,10,0,0,0,0,8,11,0,0
0,0,9,0,0,0,0,0,0,9,3,0
0,0,9,0,0,0,0,0,0,9,2,6
0,0,9,0,0,0,0,0,0,9,7,0
0,0,9,0,0,0,0,0,0,9,0,0
0,0,12,12,0,0,0,0,8,12,0,0
0,0,2,10,9,9,9,9,8,2,4,0
0,0,7,0,0,0,0,0,0,7,0,0
0,0,0,0,0,0,0,0,0,0,0,0
endlayer

layer
0,0,0,0,0,0,0,0,0,0,0,0
0,0,3,0,0,0,0,0,0,3,0,0
0,5,2,14,10,0,0,8,13,2,4,0
0,0,15,16,0,0,0,0,16,15,0,0
0,0,11,0,0,0,0,0,0,11,3,0
0,0,0,0,0,0,0,0,0,0,2,0
0,0,0,0,0,0,0,0,0,0,7,0
0,0,12,0,0,0,0,0,0,12,0,0
0,0,17,16,0,0,0,0,16,17,0,0
0,0,2,14,10,0,0,8,13,2,4,0
0,0,7,0,0,0,0,0,0,7,0,0
0,0,0,0,0,0,0,0,0,0,0,0
endlayer

layer
0,0,0,0,0,0,0,0,0,0,0,0
0,0,3,0,0,0,0,0,0,3,0,0
0,0,2,0,14,10,8,13,0,2,4,0
0,0,0,18,0,0,0,0,18,0,0,0
0,0,15,0,0,0,0,0,0,15,0,0
0,0,11,0,0,0,0,0,0,11,2,6
0,0,12,0,0,0,0,0,0,12,7,0
0,0,17,0,0,0,0,0,0,17,0,0
0,0,0,18,0,0,0,0,18,0,0,0
0,5,2,0,14,10,8,13,0,2,0,0
0,0,7,0,0,0,0,0,0,7,0,0
0,0,0,0,0,0,0,0,0,0,0,0
endlayer

layer
0,0,0,0,0,0,0,0,0,0,0,0
0,0,3,0,0,0,0,0,0,3,0,0
0,5,2,0,0,14,13,0,0,2,4,0
0,0,0,18,0,0,0,0,18,0,0,0
0,0,0,0,0,0,0,0,0,0,3,0
0,0,15,0,0,0,0,4,0,15,2,0
0,0,17,0,5,0,0,0,0,17,7,0
0,0,0,0,0,0,0,0,0,0,0,0
0,0,0,18,0,0,0,0,18,0,0,0
0,5,2,0,0,14,13,0,0,2,4,0
0,0,7,0,0,0,0,0,0,7,0,0
0,0,0,0,0,0,0,0,0,0,0,0
endlayer

layer
0,0,0,0,0,0,0,0,0,0,0,0
0,0,3,0,0,0,0,0,0,3,0,0
0,5,2,0,0,8,10,0,0,2,0,0
0,0,0,18,3,0,0,0,18,0,0,0
0,0,0,0,0,4,5,0,0,0,3,0
0,0,12,0,0,0,0,4,0,12,2,6
0,0,11,0,5,0,0,0,0,11,7,0
0,0,0,0,0,7,5,0,0,0,0,0
0,0,0,18,0,0,0,0,18,0,0,0
0,5,2,0,0,8,10,0,0,2,4,0
0,0,7,0,0,0,0,0,0,0,0,0
0,0,0,0,0,0,0,0,0,0,0,0
endlayer

layer
0,0,0,0,0,0,0,0,0,0,0,0
0,0,3,0,0,0,0,0,0,3,0,0
0,5,2,0,8,13,14,10,0,2,4,0
0,0,0,18,3,0,0,0,18,0,0,0
0,0,12,0,0,4,5,0,0,12,3,0
0,0,17,0,0,0,0,4,0,17,2,6
0,0,15,0,5,0,0,0,0,15,7,0
0,0,11,0,0,7,5,0,0,11,0,0
0,0,0,18,0,0,0,7,18,0,0,0
0,5,2,0,8,13,14,10,0,2,4,0
0,0,7,0,0,0,0,0,0,7,0,0
0,0,0,0,0,0,0,0,0,0,0,0
endlayer

layer
0,0,0,0,0,0,0,0,0,0,0,0
0,0,3,0,0,0,0,0,0,3,0,0
0,5,2,8,13,0,0,14,10,2,4,0
0,0,12,16,3,0,0,3,16,12,0,0
0,0,17,0,0,4,5,0,0,17,0,0
0,0,0,0,0,0,0,4,0,0,2,0
0,0,0,0,5,0,0,0,0,0,0,0
0,0,15,0,0,7,5,0,0,15,0,0
0,0,11,16,0,0,0,7,16,11,0,0
0,5,2,8,13,0,0,14,10,2,4,0
0,0,7,0,0,0,0,0,0,7,0,0
0,0,0,0,0,0,0,0,0,0,0,0
endlayer

layer
0,0,0,9,9,9,9,9,9,0,0,0
0,0,3,18,19,18,18,19,18,3,0,0
0,0,2,13,20,20,20,20,14,2,4,0
9,18,17,2,3,0,0,5,2,17,18,9
9,22,20,7,0,4,5,0,7,20,21,9
9,18,20,0,0,0,0,4,0,20,2,6
9,18,20,0,5,0,0,0,0,20,18,9
9,22,20,3,0,7,5,0,3,20,23,9
9,18,15,2,4,0,0,7,2,15,18,9
0,0,2,13,20,20,20,20,14,2,4,0
0,0,7,18,24,18,18,24,18,0,0,0
0,0,0,9,9,9,9,9,9,0,0,0
endlayer

layer
0,0,0,8,12,12,12,12,10,0,0,0
0,0,25,26,26,26,26,26,26,25,0,0
0,26,2,10,9,9,9,9,8,2,26,0
12,25,11,2,3,0,0,5,2,11,25,10
8,25,9,7,2,4,5,2,7,9,25,10
8,25,9,0,5,2,2,4,0,9,25,0
8,25,9,0,5,2,2,4,0,9,25,10
8,25,9,3,2,7,5,2,3,9,25,10
11,25,12,2,4,0,0,7,2,12,25,11
0,26,2,10,9,9,9,9,8,2,26,0
0,0,25,26,26,26,26,26,26,25,0,0
0,0,0,8,11,11,11,11,10,0,0,0
endlayer

layer
0,0,14,15,15,15,15,15,15,13,0,0
0,20,27,27,27,27,27,27,27,27,20,0
15,27,28,28,28,28,28,28,28,28,27,15
14,27,28,28,28,28,28,28,28,28,27,13
14,27,28,28,28,28,28,28,28,28,27,15
14,27,28,28,28,28,28,28,28,28,27,6
14,27,28,28,28,28,28,28,28,28,27,17
14,27,28,28,28,28,28,28,28,28,27,13
14,27,28,28,28,28,28,28,28,28,27,13
17,27,28,28,28,28,28,28,28,28,27,17
0,20,27,27,27,27,27,27,27,27,20,0
0,0,14,17,17,17,17,17,17,13,0,0
endlayer

layer
0,0,0,0,0,0,0,3,0,0,0,0
0,0,3,16,29,29,29,29,16,0,0,0
0,5,29,29,30,30,30,30,29,29,0,0
0,16,29,30,30,30,30,30,30,29,16,0
0,29,30,30,30,30,30,30,30,30,29,0
5,29,30,30,30,30,30,30,30,30,29,6
5,29,30,30,30,30,30,30,30,30,29,0
5,29,30,30,30,30,30,30,30,30,29,4
0,16,29,30,30,30,30,30,30,29,16,0
0,0,29,29,30,30,30,30,29,29,0,0
0,0,7,16,29,29,29,29,16,7,0,0
0,0,0,0,7,0,0,7,0,0,0,0
endlayer

layer
0,0,0,0,0,3,3,0,0,0,0,0
0,0,0,18,29,29,29,29,18,3,0,0
0,5,29,29,30,30,30,30,29,29,0,0
0,18,29,30,30,30,30,30,30,29,18,0
0,29,30,30,30,30,30,30,30,30,29,0
5,29,30,30,30,30,30,30,30,30,29,4
5,29,30,30,30,30,30,30,30,30,29,0
5,29,30,30,30,30,30,30,30,30,29,4
0,18,29,30,30,30,30,30,30,29,18,0
0,0,29,29,30,30,30,30,29,29,4,0
0,0,7,18,29,29,29,29,18,7,0,0
0,0,0,0,0,7,7,7,0,0,0,0
endlayer

layer
0,0,0,0,3,3,3,0,0,0,0,0
0,0,3,18,29,29,29,29,18,3,0,0
0,5,29,29,30,30,30,30,29,29,4,0
0,18,29,30,30,30,30,30,30,29,18,0
5,29,30,30,30,30,30,30,30,30,29,4
5,29,30,30,30,30,30,30,30,30,29,4
0,29,30,30,30,30,30,30,30,30,29,0
0,29,30,30,30,30,30,30,30,30,29,4
0,18,29,30,30,30,30,30,30,29,18,0
0,5,29,29,30,30,30,30,29,29,0,0
0,0,0,18,29,29,29,29,18,7,0,0
0,0,0,0,7,0,7,7,0,0,0,0
endlayer

layer
0,0,0,0,3,3,3,3,0,0,0,0
0,0,3,18,29,29,29,29,18,3,0,0
0,5,29,29,30,30,30,30,29,29,4,0
0,18,29,30,30,30,30,30,30,29,18,0
5,29,30,30,30,30,30,30,30,30,29,0
5,29,30,30,30,30,30,30,30,30,29,4
5,29,30,30,30,30,30,30,30,30,29,4
5,29,30,30,30,30,30,30,30,30,29,0
0,18,29,30,30,30,30,30,30,29,18,0
0,0,29,29,30,30,30,30,29,29,4,0
0,0,7,18,29,29,29,29,18,0,0,0
0,0,0,0,0,0,7,7,0,0,0,0
endlayer

layer
0,0,0,0,3,0,3,3,0,0,0,0
0,0,3,18,29,29,29,29,18,3,0,0
0,5,29,29,30,30,30,30,29,29,0,0
0,18,29,30,30,30,30,30,30,29,18,0
5,29,30,30,30,30,30,30,30,30,29,4
5,29,30,30,30,30,30,30,30,30,29,4
0,29,30,30,30,30,30,30,30,30,29,0
5,29,30,30,30,30,30,30,30,30,29,4
0,18,29,30,30,30,30,30,30,29,18,0
0,5,29,29,30,30,30,30,29,29,4,0
0,0,7,18,29,29,29,29,18,0,0,0
0,0,0,0,0,7,7,7,0,0,0,0
endlayer

layer
0,0,0,0,0,0,0,0,0,0,0,0
0,0,0,16,29,29,29,29,16,0,0,0
0,0,29,29,0,0,0,0,29,29,0,0
0,16,29,0,0,0,0,0,0,29,16,0
0,29,0,0,0,0,0,0,0,0,29,0
0,29,0,0,0,0,0,0,0,0,29,0
0,29,0,0,0,0,0,0,0,0,29,0
0,29,0,0,0,0,0,0,0,0,29,0
0,16,29,0,0,0,0,0,0,29,16,0
0,0,29,29,0,0,0,0,29,29,0,0
0,0,0,16,29,29,29,29,16,0,0,0
0,0,0,0,0,0,0,0,0,0,0,0
endlayer

layer
0,0,0,14,15,15,15,15,13,0,0,0
0,14,15,14,29,29,29,29,15,15,15,0
0,14,29,29,0,0,0,0,29,29,13,0
15,14,29,0,0,0,0,0,0,29,15,13
14,29,0,0,0,0,0,0,0,0,29,13
14,29,0,0,0,0,0,0,0,0,29,13
14,29,0,0,0,0,0,0,0,0,29,13
14,29,0,0,0,0,0,0,0,0,29,13
17,17,29,0,0,0,0,0,0,29,13,17
0,14,29,29,0,0,0,0,29,29,13,0
0,14,17,17,29,29,29,29,13,17,13,0
0,0,0,14,17,17,17,17,13,0,0,0
endlayer

layer
0,0,0,0,0,0,0,0,0,0,0,0
0,0,0,0,20,20,20,20,0,0,0,0
0,0,20,20,27,27,27,27,20,20,0,0
0,0,20,27,9,9,9,9,27,20,0,0
0,20,27,9,9,0,0,9,9,27,20,0
0,20,27,9,0,0,0,0,9,27,20,0
0,20,27,9,0,0,0,0,9,27,20,0
0,20,27,9,9,0,0,9,9,27,20,0
0,0,20,27,9,9,9,9,27,20,0,0
0,0,20,20,27,27,27,27,20,20,0,0
0,0,0,0,20,20,20,20,0,0,0,0
0,0,0,0,0,0,0,0,0,0,0,0
endlayer

layer
0,0,0,0,0,0,0,0,0,0,0,0
0,0,0,0,0,0,0,0,0,0,0,0
0,0,0,0,0,0,0,0,0,0,0,0
0,0,0,0,20,20,20,20,0,0,0,0
0,0,0,20,20,27,27,20,20,0,0,0
0,0,0,20,27,27,27,27,20,0,0,0
0,0,0,20,27,27,27,27,20,0,0,0
0,0,0,20,20,27,27,20,20,0,0,0
0,0,0,0,20,20,20,20,0,0,0,0
0,0,0,0,0,0,0,0,0,0,0,0
0,0,0,0,0,0,0,0,0,0,0,0
0,0,0,0,0,0,0,0,0,0,0,0
endlayer

