weight=6
dimensionsToSpawnIn=overworld
embed_into_distance=1
random_height_offset=0,0
unacceptable_target_blocks=sand,flowing_water,water,flowing_lava,lava,ice,packed_ice,stained_hardened_clay-9,brick_block,double_stone_slab,stonebrick,red_sandstone,red_nether_brick,red_mushroom_block,brown_mushroom_block,planks,cobblestone,end_stone,obsidian,purpur_block,iron_bars,purpur_slab,purpur_pillar,netherrack,soul_sand,quartz_ore,stained_glass,glass
dimensions=48,11,15
allowable_overhang=0
max_leveling=1
leveling_buffer=-1
preventRotation=1
preserve_water=0
preserve_lava=0
uniqueMinDistance=0
spawnMinDistance=0
spawnMaxDistance=0

adjoining_template=templateparser/windturbine1;20;10;40
adjoining_template=templateparser/windturbine1;-20;10;-40
adjoining_template=templateparser/windturbine1;-40;10;-80

rule1=0,100,preserveBlock
rule2=0,100,chisel:technical-12
rule3=0,100,cobblestone_wall-0,cobblestone_wall-0,cobblestone_wall-0,cobblestone_wall-0,cobblestone_wall-0,cobblestone_wall-0,cobblestone_wall-1
rule4=0,100,iron_bars-0
rule5=0,100,vine-8
rule6=0,100,vine-2
rule7=0,100,vine-4
rule8=0,100,vine-1
rule9=0,100,quartz_stairs-6
rule10=0,100,quartz_block-0
rule11=0,100,quartz_stairs-7
rule12=0,100,quartz_stairs-2
rule13=0,100,quartz_stairs-3
rule14=0,100,chisel:technical-12
rule15=0,100,stone_brick_stairs-6
rule16=0,100,stone_brick_stairs-7
rule17=0,100,stone_slab-8
rule18=0,100,stone_brick_stairs-2
rule19=0,100,stone_brick_stairs-3
rule20=0,100,stone_slab-0
rule21=0,100,chisel:technicalnew-2
rule22=0,100,chisel:technical-1
rule23=0,100,chisel:technicalnew-3
rule24=0,100,chisel:blockcopper-4,chisel:technical1-0

layer
1,1,1,1,1,1,1,1,1,1,1,1,1,1,1
1,1,1,1,1,1,1,1,1,1,1,1,1,1,1
1,1,1,1,1,1,1,1,1,1,1,1,1,1,1
1,1,1,1,1,1,1,1,1,1,1,1,1,1,1
1,1,1,1,1,1,14,14,14,1,1,1,1,1,1
1,1,1,1,1,1,14,14,14,1,1,1,1,1,1
1,1,1,1,1,1,14,14,14,1,1,1,1,1,1
1,1,1,1,1,1,1,1,1,1,1,1,1,1,1
1,1,1,1,1,1,1,1,1,1,1,1,1,1,1
1,1,1,1,1,1,1,1,1,1,1,1,1,1,1
1,1,1,1,1,1,1,1,1,1,1,1,1,1,1
endlayer

layer
1,1,1,1,1,1,1,1,1,1,1,1,1,1,1
1,1,1,1,1,1,1,1,1,1,1,1,1,1,1
1,1,1,1,1,1,1,1,1,1,1,1,1,1,1
1,1,1,1,1,1,1,1,1,1,1,1,1,1,1
1,1,1,1,1,1,3,3,3,1,1,1,1,1,1
1,1,1,1,1,1,3,4,3,1,1,1,1,1,1
1,1,1,1,1,1,3,3,3,1,1,1,1,1,1
1,1,1,1,1,1,1,1,1,1,1,1,1,1,1
1,1,1,1,1,1,1,1,1,1,1,1,1,1,1
1,1,1,1,1,1,1,1,1,1,1,1,1,1,1
1,1,1,1,1,1,1,1,1,1,1,1,1,1,1
endlayer

layer
1,1,1,1,1,1,1,1,1,1,1,1,1,1,1
1,1,1,1,1,1,1,1,1,1,1,1,1,1,1
1,1,1,1,1,1,1,1,1,1,1,1,1,1,1
1,1,1,1,1,1,1,1,1,1,1,1,1,1,1
1,1,1,1,1,1,3,0,3,1,1,1,1,1,1
1,1,1,1,1,1,0,4,0,1,1,1,1,1,1
1,1,1,1,1,1,3,0,3,1,1,1,1,1,1
1,1,1,1,1,1,1,1,1,1,1,1,1,1,1
1,1,1,1,1,1,1,1,1,1,1,1,1,1,1
1,1,1,1,1,1,1,1,1,1,1,1,1,1,1
1,1,1,1,1,1,1,1,1,1,1,1,1,1,1
endlayer

layer
1,1,1,1,1,1,1,1,1,1,1,1,1,1,1
1,1,1,1,1,1,1,1,1,1,1,1,1,1,1
1,1,1,1,1,1,1,1,1,1,1,1,1,1,1
1,1,1,1,1,1,1,1,1,1,1,1,1,1,1
1,1,1,1,1,1,3,3,3,1,1,1,1,1,1
1,1,1,1,1,1,3,4,3,1,1,1,1,1,1
1,1,1,1,1,1,3,3,3,1,1,1,1,1,1
1,1,1,1,1,1,1,1,1,1,1,1,1,1,1
1,1,1,1,1,1,1,1,1,1,1,1,1,1,1
1,1,1,1,1,1,1,1,1,1,1,1,1,1,1
1,1,1,1,1,1,1,1,1,1,1,1,1,1,1
endlayer

layer
1,1,1,1,1,1,1,1,1,1,1,1,1,1,1
1,1,1,1,1,1,1,1,1,1,1,1,1,1,1
1,1,1,1,1,1,1,1,1,1,1,1,1,1,1
1,1,1,1,1,1,1,1,1,1,1,1,1,1,1
1,1,1,1,1,1,3,0,3,1,1,1,1,1,1
1,1,1,1,1,1,0,4,0,1,1,1,1,1,1
1,1,1,1,1,1,3,0,3,1,1,1,1,1,1
1,1,1,1,1,1,1,1,1,1,1,1,1,1,1
1,1,1,1,1,1,1,1,1,1,1,1,1,1,1
1,1,1,1,1,1,1,1,1,1,1,1,1,1,1
1,1,1,1,1,1,1,1,1,1,1,1,1,1,1
endlayer

layer
1,1,1,1,1,0,0,0,0,1,1,1,1,1,1
1,1,1,0,0,0,0,0,0,0,0,1,1,1,1
1,1,0,0,0,0,0,0,0,0,0,0,0,1,1
1,1,0,0,0,0,0,0,0,0,0,0,0,0,1
1,0,0,0,0,0,3,3,3,0,0,0,0,0,0
0,0,0,0,0,0,3,4,3,0,0,0,0,0,0
0,0,0,0,0,0,3,3,3,0,0,0,0,0,0
1,0,0,0,0,0,0,0,0,0,0,0,0,0,1
1,1,1,0,0,0,0,0,0,0,0,0,0,1,1
1,1,1,1,0,0,0,0,0,0,0,1,1,1,1
1,1,1,1,1,0,0,0,0,1,1,1,1,1,1
endlayer

layer
1,1,1,1,0,0,0,0,0,0,0,0,1,1,1
1,1,0,0,0,0,0,0,0,0,0,0,0,1,1
1,0,0,0,0,0,0,0,0,0,0,0,0,0,1
0,0,0,0,0,0,0,0,0,0,0,0,0,0,0
0,0,0,0,0,0,3,0,3,0,0,0,0,0,0
0,0,0,0,0,0,0,4,0,0,0,0,0,0,0
0,0,0,0,0,0,3,0,3,0,0,0,0,0,0
0,0,0,0,0,0,0,0,0,0,0,0,0,0,0
1,0,0,0,0,0,0,0,0,0,0,0,0,0,1
1,1,0,0,0,0,0,0,0,0,0,0,0,1,1
1,1,1,1,0,0,0,0,0,0,0,1,1,1,1
endlayer

layer
1,1,0,0,0,0,0,0,0,0,0,0,0,1,1
1,0,0,0,0,0,0,0,0,0,0,0,0,0,1
0,0,0,0,0,0,0,0,0,0,0,0,0,0,0
0,0,0,0,0,0,0,0,0,0,0,0,0,0,0
0,0,0,0,0,0,3,3,3,0,0,0,0,0,0
0,0,0,0,0,0,3,4,3,0,0,0,0,0,0
0,0,0,0,0,0,3,3,3,0,0,0,0,0,0
0,0,0,0,0,0,0,0,0,0,0,0,0,0,0
0,0,0,0,0,0,0,0,0,0,0,0,0,0,0
1,0,0,0,0,0,0,0,0,0,0,0,0,0,1
1,1,0,0,0,0,0,0,0,0,0,0,0,1,1
endlayer

layer
0,0,0,0,0,0,0,0,0,0,0,0,0,0,0
0,0,0,0,0,0,0,0,0,0,0,0,0,0,0
0,0,0,0,0,0,0,0,0,0,0,0,0,0,0
0,0,0,0,0,0,0,0,0,0,0,0,0,0,0
0,0,0,0,0,0,3,0,3,0,0,0,0,0,0
0,0,0,0,0,0,0,4,0,0,0,0,0,0,0
0,0,0,0,0,0,3,0,3,0,0,0,0,0,0
0,0,0,0,0,0,0,0,0,0,0,0,0,0,0
0,0,0,0,0,0,0,0,0,0,0,0,0,0,0
0,0,0,0,0,0,0,0,0,0,0,0,0,0,0
0,0,0,0,0,0,0,0,0,0,0,0,0,0,0
endlayer

layer
0,0,0,0,0,0,0,0,0,0,0,0,0,0,0
0,0,0,0,0,0,0,0,0,0,0,0,0,0,0
0,0,0,0,0,0,0,0,0,0,0,0,0,0,0
0,0,0,0,0,0,0,0,0,0,0,0,0,0,0
0,0,0,0,0,0,3,3,3,0,0,0,0,0,0
0,0,0,0,0,0,3,4,3,0,0,0,0,0,0
0,0,0,0,0,0,3,3,3,0,0,0,0,0,0
0,0,0,0,0,0,0,0,0,0,0,0,0,0,0
0,0,0,0,0,0,0,0,0,0,0,0,0,0,0
0,0,0,0,0,0,0,0,0,0,0,0,0,0,0
0,0,0,0,0,0,0,0,0,0,0,0,0,0,0
endlayer

layer
0,0,0,0,0,0,0,0,0,0,0,0,0,0,0
0,0,0,0,0,0,0,0,0,0,0,0,0,0,0
0,0,0,0,0,0,0,0,0,0,0,0,0,0,0
0,0,0,0,0,0,0,0,0,0,0,0,0,0,0
0,0,0,0,0,0,3,0,3,0,0,0,0,0,0
0,0,0,0,0,0,0,4,0,0,0,0,0,0,0
0,0,0,0,0,0,3,0,3,0,0,0,0,0,0
0,0,0,0,0,0,0,0,0,0,0,0,0,0,0
0,0,0,0,0,0,0,0,0,0,0,0,0,0,0
0,0,0,0,0,0,0,0,0,0,0,0,0,0,0
0,0,0,0,0,0,0,0,0,0,0,0,0,0,0
endlayer

layer
0,0,0,0,0,0,0,0,0,0,0,0,0,0,0
0,0,0,0,0,0,0,0,0,0,0,0,0,0,0
0,0,0,0,0,0,0,0,0,0,0,0,0,0,0
0,0,0,0,0,0,0,0,0,0,0,0,0,0,0
0,0,0,0,0,0,3,3,3,0,0,0,0,0,0
0,0,0,0,0,0,3,4,3,0,0,0,0,0,0
0,0,0,0,0,0,3,3,3,0,0,0,0,0,0
0,0,0,0,0,0,0,0,0,0,0,0,0,0,0
0,0,0,0,0,0,0,0,0,0,0,0,0,0,0
0,0,0,0,0,0,0,0,0,0,0,0,0,0,0
0,0,0,0,0,0,0,0,0,0,0,0,0,0,0
endlayer

layer
0,0,0,0,0,0,0,0,0,0,0,0,0,0,0
0,0,0,0,0,0,0,0,0,0,0,0,0,0,0
0,0,0,0,0,0,0,0,0,0,0,0,0,0,0
0,0,0,0,0,0,0,0,0,0,0,0,0,0,0
0,0,0,0,0,0,3,0,3,0,0,0,0,0,0
0,0,0,0,0,0,0,4,0,0,0,0,0,0,0
0,0,0,0,0,0,3,0,3,0,0,0,0,0,0
0,0,0,0,0,0,0,0,0,0,0,0,0,0,0
0,0,0,0,0,0,0,0,0,0,0,0,0,0,0
0,0,0,0,0,0,0,0,0,0,0,0,0,0,0
0,0,0,0,0,0,0,0,0,0,0,0,0,0,0
endlayer

layer
0,0,0,0,0,0,0,0,0,0,0,0,0,0,0
0,0,0,0,0,0,0,0,0,0,0,0,0,0,0
0,0,0,0,0,0,0,0,0,0,0,0,0,0,0
0,0,0,0,0,0,0,0,0,0,0,0,0,0,0
0,0,0,0,0,0,3,3,3,0,0,0,0,0,0
0,0,0,0,0,0,3,4,3,0,0,0,0,0,0
0,0,0,0,0,0,3,3,3,0,0,0,0,0,0
0,0,0,0,0,0,0,0,0,0,0,0,0,0,0
0,0,0,0,0,0,0,0,0,0,0,0,0,0,0
0,0,0,0,0,0,0,0,0,0,0,0,0,0,0
0,0,0,0,0,0,0,0,0,0,0,0,0,0,0
endlayer

layer
0,0,0,0,0,0,0,0,0,0,0,0,0,0,0
0,0,0,0,0,0,0,0,0,0,0,0,0,0,0
0,0,0,0,0,0,0,0,0,0,0,0,0,0,0
0,0,0,0,0,0,0,0,0,0,0,0,0,0,0
0,0,0,0,0,0,3,0,3,0,0,0,0,0,0
0,0,0,0,0,0,0,4,0,0,0,0,0,0,0
0,0,0,0,0,0,3,0,3,0,0,0,0,0,0
0,0,0,0,0,0,0,0,0,0,0,0,0,0,0
0,0,0,0,0,0,0,0,0,0,0,0,0,0,0
0,0,0,0,0,0,0,0,0,0,0,0,0,0,0
0,0,0,0,0,0,0,0,0,0,0,0,0,0,0
endlayer

layer
0,0,0,0,0,0,0,0,0,0,0,0,0,0,0
0,0,0,0,0,0,0,0,0,0,0,0,0,0,0
0,0,0,0,0,0,0,0,0,0,0,0,0,0,0
0,0,0,0,0,0,0,0,0,0,0,0,0,0,0
0,0,0,0,0,0,3,3,3,0,0,0,0,0,0
0,0,0,0,0,0,3,4,3,0,0,0,0,0,0
0,0,0,0,0,0,3,3,3,0,0,0,0,0,0
0,0,0,0,0,0,0,0,0,0,0,0,0,0,0
0,0,0,0,0,0,0,0,0,0,0,0,0,0,0
0,0,0,0,0,0,0,0,0,0,0,0,0,0,0
0,0,0,0,0,0,0,0,0,0,0,0,0,0,0
endlayer

layer
0,0,0,0,0,0,0,0,0,0,0,0,0,0,0
0,0,0,0,0,0,0,0,0,0,0,0,0,0,0
0,0,0,0,0,0,0,0,0,0,0,0,0,0,0
0,0,0,0,0,0,0,0,0,0,0,0,0,0,0
0,0,0,0,0,0,3,0,3,0,0,0,0,0,0
0,0,0,0,0,0,0,4,0,0,0,0,0,0,0
0,0,0,0,0,0,3,0,3,0,0,0,0,0,0
0,0,0,0,0,0,0,0,0,0,0,0,0,0,0
0,0,0,0,0,0,0,0,0,0,0,0,0,0,0
0,0,0,0,0,0,0,0,0,0,0,0,0,0,0
0,0,0,0,0,0,0,0,0,0,0,0,0,0,0
endlayer

layer
0,0,0,0,0,0,0,0,0,0,0,0,0,0,0
0,0,0,0,0,0,0,0,0,0,0,0,0,0,0
0,0,0,0,0,0,0,0,0,0,0,0,0,0,0
0,0,0,0,0,0,0,0,0,0,0,0,0,0,0
0,0,0,0,0,0,3,3,3,0,0,0,0,0,0
0,0,0,0,0,0,3,4,3,0,0,0,0,0,0
0,0,0,0,0,0,3,3,3,0,0,0,0,0,0
0,0,0,0,0,0,0,0,0,0,0,0,0,0,0
0,0,0,0,0,0,0,0,0,0,0,0,0,0,0
0,0,0,0,0,0,0,0,0,0,0,0,0,0,0
0,0,0,0,0,0,0,0,0,0,0,0,0,0,0
endlayer

layer
0,0,0,0,0,0,0,0,0,0,0,0,0,0,0
0,0,0,0,0,0,0,0,0,0,0,0,0,0,0
0,0,0,0,0,0,0,0,0,0,0,0,0,0,0
0,0,0,0,0,0,0,0,0,0,0,0,0,0,0
0,0,0,0,0,0,3,0,3,0,0,0,0,0,0
0,0,0,0,0,0,0,4,0,0,0,0,0,0,0
0,0,0,0,0,0,3,0,3,0,0,0,0,0,0
0,0,0,0,0,0,0,0,0,0,0,0,0,0,0
0,0,0,0,0,0,0,0,0,0,0,0,0,0,0
0,0,0,0,0,0,0,0,0,0,0,0,0,0,0
0,0,0,0,0,0,0,0,0,0,0,0,0,0,0
endlayer

layer
0,0,0,0,0,0,0,0,0,0,0,0,0,0,0
0,0,0,0,0,0,0,0,0,0,0,0,0,0,0
0,0,0,0,0,0,0,0,0,0,0,0,0,0,0
0,0,0,0,0,0,0,0,0,0,0,0,0,0,0
0,0,0,0,0,0,3,3,3,0,0,0,0,0,0
0,0,0,0,0,0,3,4,3,0,0,0,0,0,0
0,0,0,0,0,0,3,3,3,0,0,0,0,0,0
0,0,0,0,0,0,0,0,0,0,0,0,0,0,0
0,0,0,0,0,0,0,0,0,0,0,0,0,0,0
0,0,0,0,0,0,0,0,0,0,0,0,0,0,0
0,0,0,0,0,0,0,0,0,0,0,0,0,0,0
endlayer

layer
0,0,0,0,0,0,0,0,0,0,0,0,0,0,0
0,0,0,0,0,0,0,0,0,0,0,0,0,0,0
0,0,0,0,0,0,0,0,0,0,0,0,0,0,0
0,0,0,0,0,0,0,0,0,0,0,0,0,0,0
0,0,0,0,0,0,3,0,3,0,0,0,0,0,0
0,0,0,0,0,0,0,4,0,0,0,0,0,0,0
0,0,0,0,0,0,3,0,3,0,0,0,0,0,0
0,0,0,0,0,0,0,0,0,0,0,0,0,0,0
0,0,0,0,0,0,0,0,0,0,0,0,0,0,0
0,0,0,0,0,0,0,0,0,0,0,0,0,0,0
0,0,0,0,0,0,0,0,0,0,0,0,0,0,0
endlayer

layer
0,0,0,0,0,0,0,0,0,0,0,0,0,0,0
0,0,0,0,0,0,0,0,0,0,0,0,0,0,0
0,0,0,0,0,0,0,0,0,0,0,0,0,0,0
0,0,0,0,0,0,0,0,0,0,0,0,0,0,0
0,0,0,0,0,0,3,3,3,0,0,0,0,0,0
0,0,0,0,0,0,3,4,3,0,0,0,0,0,0
0,0,0,0,0,0,3,3,3,0,0,0,0,0,0
0,0,0,0,0,0,0,0,0,0,0,0,0,0,0
0,0,0,0,0,0,0,0,0,0,0,0,0,0,0
0,0,0,0,0,0,0,0,0,0,0,0,0,0,0
0,0,0,0,0,0,0,0,0,0,0,0,0,0,0
endlayer

layer
0,0,0,0,0,0,0,0,0,0,0,0,0,0,0
0,0,0,0,0,0,0,0,0,0,0,0,0,0,0
0,0,0,0,0,0,0,0,0,0,0,0,0,0,0
0,0,0,0,0,0,0,0,0,0,0,0,0,0,0
0,0,0,0,0,0,3,0,3,0,0,0,0,0,0
0,0,0,0,0,0,0,4,0,0,0,0,0,0,0
0,0,0,0,0,0,3,0,3,0,0,0,0,0,0
0,0,0,0,0,0,0,0,0,0,0,0,0,0,0
0,0,0,0,0,0,0,0,0,0,0,0,0,0,0
0,0,0,0,0,0,0,0,0,0,0,0,0,0,0
0,0,0,0,0,0,0,0,0,0,0,0,0,0,0
endlayer

layer
0,0,0,0,0,0,0,0,0,0,0,0,0,0,0
0,0,0,0,0,0,0,0,0,0,0,0,0,0,0
0,0,0,0,0,0,0,0,0,0,0,0,0,0,0
0,0,0,0,0,0,0,0,0,0,0,0,0,0,0
0,0,0,0,0,0,3,3,3,0,0,0,0,0,0
0,0,0,0,0,0,3,4,3,0,0,0,0,0,0
0,0,0,0,0,0,3,3,3,0,0,0,0,0,0
0,0,0,0,0,0,0,0,0,0,0,0,0,0,0
0,0,0,0,0,0,0,0,0,0,0,0,0,0,0
0,0,0,0,0,0,0,0,0,0,0,0,0,0,0
0,0,0,0,0,0,0,0,0,0,0,0,0,0,0
endlayer

layer
0,0,0,0,0,0,0,0,0,0,0,0,0,0,0
0,0,0,0,0,0,0,0,0,0,0,0,0,0,0
0,0,0,0,0,0,0,0,0,0,0,0,0,0,0
0,0,0,0,0,0,0,0,0,0,0,0,0,0,0
0,0,0,0,0,0,3,0,3,0,0,0,0,0,0
0,0,0,0,0,0,0,4,0,0,0,0,0,0,0
0,0,0,0,0,0,3,0,3,0,0,0,0,0,0
0,0,0,0,0,0,0,0,0,0,0,0,0,0,0
0,0,0,0,0,0,0,0,0,0,0,0,0,0,0
0,0,0,0,0,0,0,0,0,0,0,0,0,0,0
0,0,0,0,0,0,0,0,0,0,0,0,0,0,0
endlayer

layer
0,0,0,0,0,0,0,0,0,0,0,0,0,0,0
0,0,0,0,0,0,0,0,0,0,0,0,0,0,0
0,0,0,0,0,0,0,0,0,0,0,0,0,0,0
0,0,0,0,0,0,0,0,0,0,0,0,0,0,0
0,0,0,0,0,0,3,3,3,0,0,0,0,0,0
0,0,0,0,0,0,3,4,3,0,0,0,0,0,0
0,0,0,0,0,0,3,3,3,0,0,0,0,0,0
0,0,0,0,0,0,0,0,0,0,0,0,0,0,0
0,0,0,0,0,5,0,0,0,0,0,0,0,0,0
0,0,0,0,0,0,0,0,0,0,0,0,0,0,0
0,0,0,0,0,0,0,0,0,0,0,0,0,0,0
endlayer

layer
0,0,0,0,0,0,0,0,0,0,0,0,0,0,0
0,0,0,0,0,0,0,0,0,0,0,0,0,0,0
0,0,0,0,0,0,0,0,0,0,0,0,0,0,0
0,0,0,0,0,0,0,0,0,0,0,0,0,0,0
0,0,0,0,0,0,3,0,3,0,0,0,0,0,0
0,0,0,0,0,0,0,4,0,0,0,0,0,0,0
0,0,0,0,0,0,3,0,3,0,0,0,0,0,0
0,0,0,0,0,0,0,0,0,0,0,0,0,0,0
0,0,0,0,0,5,0,0,0,0,0,0,5,0,0
0,0,0,0,0,0,0,0,0,0,0,0,0,0,0
0,6,0,0,0,0,0,0,0,0,0,6,0,0,0
endlayer

layer
0,0,0,0,0,0,0,0,0,0,0,0,0,0,0
0,0,0,0,0,0,0,0,0,0,0,0,0,0,0
0,0,0,0,0,0,0,0,0,0,0,0,0,0,0
0,0,0,0,0,0,0,0,0,0,0,0,0,0,0
0,0,0,0,0,0,3,3,3,0,0,0,0,0,0
0,0,0,0,0,0,3,4,3,0,0,0,0,0,0
0,0,0,0,0,0,3,3,3,0,0,0,0,0,0
0,0,0,0,0,0,0,0,0,0,0,0,0,0,0
0,0,0,0,0,5,0,0,0,0,0,0,5,0,0
0,0,0,0,0,0,0,0,0,0,0,0,0,0,0
0,6,0,0,0,6,0,0,0,0,0,6,0,0,0
endlayer

layer
0,0,0,0,0,0,0,0,0,0,0,0,0,0,0
0,0,0,0,0,0,0,0,0,0,0,0,0,0,0
0,0,0,0,0,0,0,0,0,0,0,0,0,0,0
0,0,0,0,0,0,0,0,0,0,0,0,0,0,0
0,0,0,0,0,0,3,0,3,0,0,0,0,0,0
0,0,0,0,0,0,0,4,0,0,0,0,0,0,0
0,0,0,0,0,0,3,0,3,0,0,0,0,0,0
0,0,0,0,0,0,0,0,0,0,0,0,0,0,0
0,0,0,0,5,5,0,0,0,0,0,0,5,0,0
0,0,0,0,0,0,0,0,0,0,0,0,0,0,0
0,6,0,0,0,6,0,0,0,0,0,6,0,0,0
endlayer

layer
0,0,0,0,0,0,0,0,0,0,0,0,0,0,0
0,0,0,0,0,0,0,0,0,0,0,0,0,0,0
0,0,0,0,0,0,0,0,0,0,0,0,0,0,0
0,0,0,0,0,0,0,0,0,0,0,0,0,0,0
0,0,0,0,0,0,3,3,3,0,0,0,0,0,0
0,0,0,0,0,0,3,4,3,0,0,0,0,0,0
0,0,0,0,0,0,3,3,3,0,0,0,0,0,0
0,0,0,0,0,0,0,0,0,0,0,0,0,0,0
0,5,0,0,5,5,0,0,0,0,0,0,5,0,0
0,0,0,0,0,0,0,0,0,0,0,0,0,0,0
0,6,0,0,0,6,0,0,0,0,6,6,0,6,0
endlayer

layer
0,0,0,0,0,0,0,0,0,0,0,0,0,0,0
0,0,0,0,0,0,0,0,0,0,0,0,0,0,0
0,0,0,0,0,0,0,0,0,0,0,0,0,0,0
0,0,0,0,0,0,0,0,0,0,0,0,0,0,0
0,0,0,0,0,0,3,0,3,0,0,0,0,0,0
0,0,0,0,0,7,0,4,0,0,0,0,0,0,0
0,0,0,0,0,0,3,0,3,0,0,0,0,0,0
0,0,0,0,0,0,0,0,0,0,0,0,0,0,0
0,5,0,0,5,5,0,0,0,0,0,0,5,0,0
0,0,0,0,0,0,0,0,0,0,0,0,0,0,0
0,6,0,0,0,6,0,0,0,0,6,6,0,6,0
endlayer

layer
0,0,0,0,0,0,0,0,0,0,0,0,0,0,0
0,0,0,0,0,0,0,0,0,0,0,0,0,0,0
0,0,0,0,0,0,0,0,0,0,0,0,0,0,0
0,0,0,0,0,0,0,5,0,0,0,0,0,0,0
0,0,0,0,0,0,3,3,3,0,0,0,0,0,0
0,0,0,0,0,7,3,4,3,0,0,0,0,0,0
0,0,0,0,0,0,3,3,3,8,0,0,0,0,0
0,0,0,0,0,0,0,0,0,0,0,0,0,0,0
0,5,0,0,5,5,0,0,0,5,0,0,5,0,0
0,0,0,0,0,0,0,0,0,0,0,0,0,0,0
0,6,6,0,0,6,0,0,0,0,6,6,0,6,0
endlayer

layer
0,0,0,0,0,0,0,0,0,0,0,0,0,0,0
0,0,0,0,0,0,0,0,0,0,0,0,0,0,0
0,0,0,0,0,0,0,0,0,0,0,0,0,0,0
0,0,0,0,0,0,5,5,0,0,0,0,0,0,0
0,0,0,0,0,0,3,0,3,0,0,0,0,0,0
0,0,0,0,0,7,0,4,0,0,0,0,0,0,0
0,0,0,0,0,0,3,0,3,8,0,0,0,0,0
0,0,0,0,0,0,0,0,0,0,0,0,0,0,0
0,5,0,0,5,5,0,0,0,5,0,0,5,0,0
0,0,0,0,0,0,0,0,0,0,0,0,0,0,0
0,6,6,0,6,6,0,0,0,0,6,6,0,6,0
endlayer

layer
0,0,0,0,0,0,0,0,0,0,0,0,0,0,0
0,0,0,0,0,0,0,0,0,0,0,0,0,0,0
0,0,0,0,0,0,7,0,0,0,0,0,0,0,0
0,0,0,0,0,0,5,5,0,0,0,0,0,0,0
0,0,0,0,0,0,3,3,3,0,0,0,0,0,0
0,0,0,0,0,7,3,4,3,0,0,0,0,0,0
0,0,0,0,0,0,3,3,3,8,0,0,0,0,0
0,0,0,0,0,0,6,0,0,0,0,0,0,0,0
0,5,0,0,5,5,0,0,0,5,0,0,5,0,0
0,0,0,0,0,0,0,0,0,0,0,0,0,9,0
0,6,6,0,6,6,0,0,0,0,6,6,0,6,0
endlayer

layer
0,0,0,0,0,0,0,0,0,0,0,0,0,0,0
0,0,0,0,0,0,0,0,0,0,0,0,0,0,0
0,0,0,0,0,0,7,0,0,0,0,0,0,0,0
0,0,0,0,0,0,5,5,0,0,0,0,0,0,0
0,0,0,0,0,0,3,0,3,0,0,0,0,0,0
0,0,0,0,0,7,0,4,0,0,0,0,0,0,0
0,0,0,0,0,0,3,0,3,8,0,0,0,0,0
0,0,0,0,0,0,6,0,0,0,0,0,0,0,0
0,5,0,0,5,5,0,0,0,5,5,0,5,0,0
11,10,9,0,0,0,0,0,0,0,0,0,11,10,0
0,6,6,6,6,6,0,0,0,0,6,6,0,6,0
endlayer

layer
0,0,0,0,0,0,0,0,0,0,0,0,0,0,0
0,0,0,0,0,0,0,0,0,0,0,0,0,0,0
0,0,0,0,0,0,7,0,0,0,0,0,0,0,0
0,0,0,0,0,0,5,5,0,0,0,0,0,0,0
0,0,0,0,0,0,3,3,3,0,0,0,0,0,0
0,0,0,0,0,7,3,4,3,0,0,0,0,0,0
0,0,0,0,0,0,3,3,3,8,0,0,0,0,0
0,0,0,0,0,0,6,0,0,0,0,0,0,0,0
0,0,5,0,5,5,0,0,0,5,5,5,5,0,0
0,13,10,9,0,0,0,0,0,0,0,3,10,12,0
0,0,6,6,6,6,0,0,0,0,6,6,0,0,0
endlayer

layer
0,0,0,0,0,0,0,0,0,0,0,0,0,0,0
0,0,0,0,0,0,0,0,8,0,0,0,0,0,0
0,0,0,0,0,0,7,0,0,0,0,0,0,0,0
0,0,0,0,0,0,5,5,0,0,0,0,0,0,0
0,0,0,0,0,0,3,0,3,0,0,0,0,0,0
0,0,0,0,0,7,0,4,0,0,0,0,0,0,0
0,0,0,0,0,0,3,0,3,8,0,0,0,0,0
0,0,0,0,0,0,6,0,0,0,0,0,0,0,0
0,0,0,0,5,5,0,0,0,5,5,5,0,0,0
0,0,3,10,9,0,0,0,0,0,3,10,12,0,0
0,0,0,6,6,6,0,0,0,0,6,6,0,0,0
endlayer

layer
0,0,0,0,0,0,0,5,0,0,0,0,0,0,0
0,0,0,0,0,0,0,0,8,0,0,0,0,0,0
0,0,0,0,0,0,7,0,0,0,0,0,0,0,0
0,0,0,0,0,0,5,5,0,0,0,0,0,0,0
0,0,0,0,0,0,3,3,3,0,0,0,0,0,0
0,0,0,0,0,7,3,4,3,0,0,0,0,0,0
0,0,0,0,0,0,3,3,3,8,0,0,0,0,0
0,0,0,0,0,0,6,0,0,0,0,0,0,0,0
0,0,0,0,5,5,0,0,0,5,5,0,0,0,0
0,0,0,3,10,9,0,0,0,3,10,12,0,0,0
0,0,0,0,6,6,0,0,0,0,6,6,0,0,0
endlayer

layer
0,0,0,0,0,0,0,5,0,0,0,0,0,0,0
0,0,0,0,0,0,0,0,8,0,0,0,0,0,0
0,0,0,0,0,0,7,0,0,0,0,0,0,0,0
0,0,0,0,0,0,5,5,0,0,0,0,0,0,0
0,0,0,0,0,0,14,14,14,0,0,0,0,0,0
0,0,0,0,0,7,14,2,14,0,0,0,0,0,0
0,0,0,0,0,0,14,14,14,8,0,0,0,0,0
0,0,0,0,0,0,6,0,0,0,0,0,0,0,0
0,0,0,0,0,5,0,0,0,5,5,0,0,0,0
0,0,0,0,3,10,9,0,3,10,12,0,0,0,0
0,0,0,0,0,6,0,0,0,0,0,6,0,0,0
endlayer

layer
0,0,0,0,0,0,0,5,0,0,0,0,0,0,0
0,0,0,0,0,0,0,0,8,0,0,0,0,0,0
0,0,0,0,0,0,7,0,0,0,0,0,0,0,0
0,0,0,0,0,0,0,0,0,0,0,0,0,0,0
0,0,0,0,0,0,16,2,15,0,0,0,0,0,0
0,0,0,0,0,0,16,24,15,0,0,0,0,0,0
0,0,0,0,0,0,16,2,15,0,0,0,0,0,0
0,0,0,0,0,0,0,17,0,0,0,0,0,0,0
0,0,5,0,0,5,0,0,0,0,5,0,0,0,0
7,0,0,0,0,3,3,3,3,12,0,0,0,0,0
0,0,0,0,0,0,0,0,0,0,0,6,0,6,0
endlayer

layer
0,0,0,0,0,0,0,5,0,0,0,0,0,0,0
0,0,0,0,0,0,0,2,8,0,0,0,0,0,0
0,0,0,0,0,0,7,2,0,0,0,0,0,0,0
0,0,0,0,0,0,0,3,0,0,0,0,0,0,0
0,0,0,0,0,0,19,23,18,0,0,0,0,0,0
0,0,0,0,0,0,19,22,18,0,0,0,0,0,0
0,0,0,0,0,0,19,21,18,0,0,0,0,0,0
0,0,0,0,0,0,0,21,0,0,0,0,0,0,0
0,0,5,0,0,5,0,3,0,0,5,5,0,0,0
7,0,0,0,0,0,3,2,3,0,0,0,0,0,0
0,0,0,6,0,0,0,0,0,0,0,6,0,6,0
endlayer

layer
0,0,0,0,0,0,0,0,0,0,0,0,0,0,0
0,0,0,0,0,0,0,0,0,0,0,0,0,0,0
0,0,0,0,0,0,0,0,0,0,0,0,0,0,0
0,0,0,0,0,0,0,0,0,0,0,0,0,0,0
0,0,0,0,0,0,0,20,0,0,0,0,0,0,0
0,0,0,0,0,0,0,20,0,0,0,0,0,0,0
0,0,0,0,0,0,0,20,0,0,0,0,0,0,0
0,0,0,0,0,0,0,20,0,0,0,0,0,0,0
0,0,5,0,0,5,0,0,0,0,5,5,0,5,0
7,0,0,0,0,11,3,3,3,3,0,0,0,0,0
0,0,6,6,0,0,0,0,0,0,6,6,0,6,0
endlayer

layer
0,0,0,0,0,0,0,0,0,0,0,0,0,0,0
0,0,0,0,0,0,0,0,0,0,0,0,0,0,0
0,0,0,0,0,0,0,0,0,0,0,0,0,0,0
0,0,0,0,0,0,0,0,0,0,0,0,0,0,0
0,0,0,0,0,0,0,0,0,0,0,0,0,0,0
0,0,0,0,0,0,0,0,0,0,0,0,0,0,0
0,0,0,0,0,0,0,0,0,0,0,0,0,0,0
0,0,0,0,0,0,0,0,0,0,0,0,0,0,0
0,5,5,0,0,5,0,0,0,0,5,5,0,5,0
7,0,0,0,11,10,3,0,13,10,3,0,0,0,0
0,0,6,6,0,0,0,0,0,0,6,6,0,6,0
endlayer

layer
0,0,0,0,0,0,0,0,0,0,0,0,0,0,0
0,0,0,0,0,0,0,0,0,0,0,0,0,0,0
0,0,0,0,0,0,0,0,0,0,0,0,0,0,0
0,0,0,0,0,0,0,0,0,0,0,0,0,0,0
0,0,0,0,0,0,0,0,0,0,0,0,0,0,0
0,0,0,0,0,0,0,0,0,0,0,0,0,0,0
0,0,0,0,0,0,0,0,0,0,0,0,0,0,0
0,0,0,0,0,0,0,0,0,0,0,0,0,0,0
0,5,5,0,0,0,0,0,0,0,5,5,0,5,0
7,0,0,11,10,3,0,0,0,13,10,3,0,0,0
0,0,6,6,0,0,0,0,0,0,6,6,0,6,0
endlayer

layer
0,0,0,0,0,0,0,0,0,0,0,0,0,0,0
0,0,0,0,0,0,0,0,0,0,0,0,0,0,0
0,0,0,0,0,0,0,0,0,0,0,0,0,0,0
0,0,0,0,0,0,0,0,0,0,0,0,0,0,0
0,0,0,0,0,0,0,0,0,0,0,0,0,0,0
0,0,0,0,0,0,0,0,0,0,0,0,0,0,0
0,0,0,0,0,0,0,0,0,0,0,0,0,0,0
0,0,0,0,0,0,0,0,0,0,0,0,0,0,0
0,5,5,0,0,0,0,0,0,0,0,5,0,5,0
7,0,11,10,3,0,0,0,0,0,13,10,3,0,0
0,0,6,6,0,0,0,0,0,0,0,6,0,6,0
endlayer

layer
0,0,0,0,0,0,0,0,0,0,0,0,0,0,0
0,0,0,0,0,0,0,0,0,0,0,0,0,0,0
0,0,0,0,0,0,0,0,0,0,0,0,0,0,0
0,0,0,0,0,0,0,0,0,0,0,0,0,0,0
0,0,0,0,0,0,0,0,0,0,0,0,0,0,0
0,0,0,0,0,0,0,0,0,0,0,0,0,0,0
0,0,0,0,0,0,0,0,0,0,0,0,0,0,0
0,0,0,0,0,0,0,0,0,0,0,0,0,0,0
0,5,5,0,0,0,0,0,0,0,0,0,0,5,0
7,11,10,3,0,0,0,0,0,0,0,13,10,9,0
0,0,6,0,0,0,0,0,0,0,0,0,0,6,0
endlayer

layer
0,0,0,0,0,0,0,0,0,0,0,0,0,0,0
0,0,0,0,0,0,0,0,0,0,0,0,0,0,0
0,0,0,0,0,0,0,0,0,0,0,0,0,0,0
0,0,0,0,0,0,0,0,0,0,0,0,0,0,0
0,0,0,0,0,0,0,0,0,0,0,0,0,0,0
0,0,0,0,0,0,0,0,0,0,0,0,0,0,0
0,0,0,0,0,0,0,0,0,0,0,0,0,0,0
0,0,0,0,0,0,0,0,0,0,0,0,0,0,0
0,5,0,0,0,0,0,0,0,0,0,0,0,5,0
7,10,12,0,0,0,0,0,0,0,0,0,13,10,12
0,0,0,0,0,0,0,0,0,0,0,0,0,6,0
endlayer

layer
0,0,0,0,0,0,0,0,0,0,0,0,0,0,0
0,0,0,0,0,0,0,0,0,0,0,0,0,0,0
0,0,0,0,0,0,0,0,0,0,0,0,0,0,0
0,0,0,0,0,0,0,0,0,0,0,0,0,0,0
0,0,0,0,0,0,0,0,0,0,0,0,0,0,0
0,0,0,0,0,0,0,0,0,0,0,0,0,0,0
0,0,0,0,0,0,0,0,0,0,0,0,0,0,0
0,0,0,0,0,0,0,0,0,0,0,0,0,0,0
0,0,0,0,0,0,0,0,0,0,0,0,0,0,0
0,13,0,0,0,0,0,0,0,0,0,0,0,0,0
0,0,0,0,0,0,0,0,0,0,0,0,0,0,0
endlayer

