weight=5
dimensionsToSpawnIn=overworld
embed_into_distance=9
acceptable_target_blocks=water
unacceptable_target_blocks=flowing_lava,lava,ice,packed_ice,stained_hardened_clay-9,brick_block,double_stone_slab,stonebrick,red_sandstone,red_nether_brick,red_mushroom_block,brown_mushroom_block,planks,cobblestone,end_stone,obsidian,purpur_block,iron_bars,purpur_slab,purpur_pillar,netherrack,soul_sand,quartz_ore,stained_glass,glass
dimensions=17,8,7
allowable_overhang=2
max_leveling=9
leveling_buffer=-1
preserve_water=0
preserve_lava=0
preserve_plants=0
uniqueMinDistance=7000

rule1=0,100,preserveBlock
rule2=0,100,chisel:brownstone-4
rule3=0,100,chisel:blockcopper-4
rule4=0,100,chisel:technical-15
rule5=0,100,chisel:technicalnew-2
rule6=0,100,chisel:technical1-0
rule7=0,100,air
rule8=0,100,minecraft:cobblestone_wall-0
rule9=0,100,chisel:brownstone-8
rule10=0,100,chisel:ironpane-3
rule11=0,100,chisel:technical-1
rule12=0,100,chisel:brownstone-0
rule13=0,100,chisel:technicalnew-3
rule14=0,100,chisel:factory-13
rule15=0,100,minecraft:stone_slab-5
rule16=0,100,minecraft:stonebrick-0,minecraft:stonebrick-1,minecraft:stonebrick-2
rule17=0,100,chisel:prismarine-15

layer
1,1,1,1,1,1,1
1,1,1,1,1,1,1
1,2,2,1,2,2,1
1,2,1,1,1,2,1
1,1,1,1,1,1,1
1,2,1,1,1,2,1
1,2,2,1,2,2,1
1,1,1,1,1,1,1
endlayer

layer
1,1,1,1,1,1,1
1,1,1,1,1,1,1
1,2,2,1,2,2,1
1,2,1,1,1,2,1
1,1,1,1,1,1,1
1,2,1,1,1,2,1
1,2,2,1,2,2,1
1,1,1,1,1,1,1
endlayer

layer
1,1,1,1,1,1,1
1,1,1,1,1,1,1
1,2,2,1,2,2,1
1,2,1,1,1,2,1
1,1,1,1,1,1,1
1,2,1,1,1,2,1
1,2,2,1,2,2,1
1,1,1,1,1,1,1
endlayer

layer
1,1,1,1,1,1,1
1,1,1,1,1,1,1
1,2,2,1,2,2,1
1,2,1,1,1,2,1
1,1,1,1,1,1,1
1,2,1,1,1,2,1
1,2,2,1,2,2,1
1,1,1,1,1,1,1
endlayer

layer
1,1,1,1,1,1,1
1,1,1,1,1,1,1
1,2,2,1,2,2,1
1,2,1,1,1,2,1
1,1,1,1,1,1,1
1,2,1,1,1,2,1
1,2,2,1,2,2,1
1,1,1,1,1,1,1
endlayer

layer
1,1,1,1,1,1,1
1,1,1,1,1,1,1
1,2,2,1,2,2,1
1,2,1,1,1,2,1
1,1,1,1,1,1,1
1,2,1,1,1,2,1
1,2,2,1,2,2,1
1,1,1,1,1,1,1
endlayer

layer
1,1,1,1,1,1,1
1,1,2,2,2,2,2
1,2,2,2,2,2,2
2,2,2,2,2,2,2
2,2,2,3,2,2,2
2,2,2,2,2,2,2
1,2,2,2,2,2,1
1,1,2,2,2,1,1
endlayer

layer
1,1,1,1,2,2,2
1,1,2,2,2,2,2
1,2,1,1,1,1,2
2,1,1,4,1,1,2
2,1,4,5,4,1,2
2,1,1,4,1,1,2
1,6,1,1,1,6,1
1,1,6,6,6,1,1
endlayer

layer
1,1,1,1,2,1,2
1,1,2,2,2,1,2
1,2,7,7,8,7,2
2,7,7,4,7,7,2
2,7,4,5,4,7,2
2,7,7,4,7,7,2
1,2,7,7,7,2,1
1,1,2,2,2,1,1
endlayer

layer
1,1,1,1,9,1,9
1,1,9,9,9,1,9
1,9,1,10,8,1,9
9,1,1,10,1,1,9
9,10,10,11,10,10,9
9,1,1,10,1,1,9
1,9,1,10,1,9,1
1,1,9,9,9,1,1
endlayer

layer
1,1,1,1,1,1,1
1,1,10,12,10,1,1
1,1,1,1,1,1,1
10,1,1,1,1,1,10
12,1,1,8,1,1,12
10,1,1,1,1,1,10
1,1,1,1,1,1,1
1,1,10,12,10,1,1
endlayer

layer
1,1,1,1,1,1,1
1,12,10,12,10,12,1
12,12,12,12,12,12,12
10,12,12,12,12,12,10
12,12,12,8,12,12,12
10,12,12,12,12,12,10
12,12,12,12,12,12,12
1,12,10,12,10,12,1
endlayer

layer
1,1,1,1,1,1,1
1,12,10,12,10,12,1
12,12,12,13,12,12,12
10,12,13,14,13,12,10
12,13,14,8,14,13,12
10,12,13,14,13,12,10
12,12,12,13,12,12,12
1,12,10,12,10,12,1
endlayer

layer
1,1,1,1,1,1,1
1,12,10,12,10,12,1
12,12,12,13,12,12,12
10,12,13,14,13,12,10
12,13,14,8,14,13,12
10,12,13,14,13,12,10
12,12,12,13,12,12,12
1,12,10,12,10,12,1
endlayer

layer
1,1,1,1,1,1,1
1,1,15,1,15,1,1
1,15,15,16,15,15,1
15,15,16,16,16,15,15
1,16,16,16,16,16,1
15,15,16,16,16,15,15
1,15,15,16,15,15,1
1,1,15,1,15,1,1
endlayer

layer
1,1,1,1,1,1,1
1,1,1,1,1,1,1
1,1,1,1,1,1,1
1,1,17,1,1,1,1
1,1,1,1,1,1,1
1,1,1,1,17,1,1
1,1,1,1,1,1,1
1,1,1,1,1,1,1
endlayer

layer
1,1,1,1,1,1,1
1,1,1,1,1,1,1
1,1,1,1,1,1,1
1,1,8,1,1,1,1
1,1,1,1,1,1,1
1,1,1,1,8,1,1
1,1,1,1,1,1,1
1,1,1,1,1,1,1
endlayer

