biomesToSpawnIn=ocean,deep ocean,kelp forest,ocean oil field,oceanic abyss,coral reef
weight=1
acceptable_target_blocks=stone,dirt,sand,gravel,clay
unacceptable_target_blocks=grass
embed_into_distance=2
dimensions=8,29,5
allowable_overhang=12
max_leveling=2
leveling_buffer=-1
preserve_water=1
preserve_plants=1

rule1=0,100,preserveBlock
rule2=0,100,chisel:factory-14
rule3=0,100,chisel:factory-5,preserveBlock
rule4=0,50,chisel:factory-14
rule5=0,50,chisel:factory-14
rule6=0,50,chisel:factory-14

layer
1,1,1,1,1
1,1,1,1,1
1,1,2,1,1
1,2,2,2,1
1,2,3,2,1
1,2,3,2,1
1,2,3,2,1
1,2,3,2,1
1,2,3,2,1
1,2,3,2,1
1,2,3,2,1
1,4,3,2,1
1,4,3,5,1
1,4,3,5,1
1,4,3,5,1
1,4,3,5,1
1,2,3,2,1
1,2,3,2,1
1,2,3,2,1
1,2,3,2,1
1,2,3,2,1
1,1,2,1,1
1,1,2,1,1
1,1,2,1,1
1,1,2,1,1
1,1,2,1,1
1,1,1,1,1
1,1,2,1,1
1,1,2,1,1
endlayer

layer
1,1,1,1,1
1,1,2,1,1
1,2,2,2,1
1,2,2,2,1
2,1,1,1,2
5,1,1,1,2
5,1,1,1,2
2,1,1,1,2
2,1,1,1,5
2,1,1,1,5
4,1,1,1,5
4,1,1,1,5
4,1,1,1,5
4,1,2,1,5
4,1,1,1,5
4,1,1,1,5
4,1,1,1,5
4,1,1,1,2
2,1,1,1,2
2,1,1,1,2
2,3,1,3,2
1,2,1,6,1
1,2,3,6,1
1,2,2,2,1
1,2,2,2,1
1,1,2,1,1
1,1,1,1,1
1,1,2,1,1
1,1,2,1,1
endlayer

layer
1,1,2,1,1
1,2,2,2,1
1,2,2,2,1
2,2,2,2,2
5,1,1,1,2
5,1,1,1,6
5,1,1,1,6
5,1,1,1,2
2,1,1,1,2
2,1,1,1,2
2,1,1,1,5
2,1,1,1,5
2,1,1,1,5
2,1,2,1,5
2,1,1,1,5
2,1,1,1,5
2,1,1,1,2
2,1,1,1,2
2,1,1,1,2
2,1,1,1,2
2,1,1,1,2
2,1,1,1,2
2,6,1,2,2
1,5,5,2,1
1,1,2,1,1
1,1,2,1,1
1,1,2,1,1
1,1,2,1,1
1,1,6,1,1
endlayer

layer
1,1,2,1,1
1,2,2,2,1
1,2,2,6,1
2,2,2,2,6
2,1,1,1,6
5,1,1,1,6
5,1,1,1,6
5,1,1,1,6
5,1,1,1,6
5,1,1,1,2
2,1,1,1,2
2,1,1,1,2
2,1,1,1,2
2,1,2,1,2
6,1,1,1,2
6,1,1,1,2
6,1,1,1,2
6,1,1,1,2
6,1,1,1,5
6,1,1,1,5
6,1,1,1,5
6,6,2,5,5
1,2,5,5,1
1,1,1,1,1
1,1,1,1,1
1,1,2,1,1
1,1,2,1,1
1,1,6,1,1
1,1,6,1,1
endlayer

layer
1,1,1,1,1
1,1,6,1,1
1,2,6,6,1
1,2,6,6,1
1,2,6,6,1
1,2,6,6,1
1,2,2,6,1
1,4,2,2,1
1,2,4,4,1
1,2,4,2,1
1,2,4,2,1
1,2,2,2,1
1,2,1,2,1
1,2,2,6,1
1,2,2,6,1
1,2,2,2,1
1,2,2,2,1
1,2,2,5,1
1,2,2,5,1
1,6,2,5,1
1,6,6,5,1
1,1,1,1,1
1,1,1,1,1
1,1,1,1,1
1,1,1,1,1
1,1,1,1,1
1,1,6,1,1
1,1,6,1,1
1,1,6,1,1
endlayer

layer
1,1,1,1,1
1,1,1,1,1
1,1,1,1,1
1,1,1,1,1
1,1,1,1,1
1,1,1,1,1
1,1,1,1,1
1,1,1,1,1
1,1,1,1,1
1,1,1,1,1
1,1,4,1,1
1,2,2,2,1
1,2,1,2,1
1,5,2,6,1
1,1,6,1,1
1,1,1,1,1
1,1,1,1,1
1,1,1,1,1
1,1,1,1,1
1,1,1,1,1
1,1,1,1,1
1,1,1,1,1
1,1,1,1,1
1,1,1,1,1
1,1,1,1,1
1,1,1,1,1
1,1,1,1,1
1,1,6,1,1
1,1,6,1,1
endlayer

layer
1,1,1,1,1
1,1,1,1,1
1,1,1,1,1
1,1,1,1,1
1,1,1,1,1
1,1,1,1,1
1,1,1,1,1
1,1,1,1,1
1,1,1,1,1
1,1,1,1,1
1,1,4,1,1
1,5,1,2,1
1,5,1,6,1
1,5,1,6,1
1,1,6,1,1
1,1,1,1,1
1,1,1,1,1
1,1,1,1,1
1,1,1,1,1
1,1,1,1,1
1,1,1,1,1
1,1,1,1,1
1,1,1,1,1
1,1,1,1,1
1,1,1,1,1
1,1,1,1,1
1,1,1,1,1
1,1,1,1,1
1,1,1,1,1
endlayer

layer
1,1,1,1,1
1,1,1,1,1
1,1,1,1,1
1,1,1,1,1
1,1,1,1,1
1,1,1,1,1
1,1,1,1,1
1,1,1,1,1
1,1,1,1,1
1,1,1,1,1
1,1,6,1,1
1,5,1,6,1
1,5,1,6,1
1,1,1,1,1
1,1,1,1,1
1,1,1,1,1
1,1,1,1,1
1,1,1,1,1
1,1,1,1,1
1,1,1,1,1
1,1,1,1,1
1,1,1,1,1
1,1,1,1,1
1,1,1,1,1
1,1,1,1,1
1,1,1,1,1
1,1,1,1,1
1,1,1,1,1
1,1,1,1,1
endlayer

