biomesToSpawnIn=ocean,deep ocean,kelp forest,ocean oil field,oceanic abyss,coral reef
weight=1
acceptable_target_blocks=stone,dirt,sand,gravel,clay
unacceptable_target_blocks=grass
embed_into_distance=2
dimensions=6,17,5
allowable_overhang=12
max_leveling=1
leveling_buffer=-1
preserve_water=1
preserve_plants=1

rule1=0,100,preserveBlock
rule2=0,100,chisel:factory-14,chisel:factory-14,chisel:factory-14,chisel:factory-14,chisel:factory-14,chisel:factory-14,chisel:factory-14,chisel:factory-14,preserveBlock,preserveBlock,preserveBlock
rule3=0,100,chisel:factory-14,chisel:factory-14,chisel:factory-14,chisel:factory-14,chisel:factory-14,chisel:factory-14,chisel:factory-5,preserveBlock,preserveBlock
rule5=0,50,chisel:factory-14
rule6=0,50,chisel:factory-14
rule7=0,50,chisel:factory-14
rule8=0,50,chisel:factory-14

layer
1,1,1,1,1
1,1,1,1,1
1,1,1,1,1
1,1,2,1,1
1,2,3,2,1
1,2,4,2,1
1,2,4,2,1
2,3,4,3,2
2,4,4,4,2
2,4,4,4,2
2,4,4,4,2
2,4,4,4,2
2,4,4,4,2
2,4,4,4,2
2,4,4,4,2
2,4,4,4,2
2,2,2,2,2
endlayer

layer
1,1,1,1,1
1,1,1,1,1
1,1,3,1,1
1,1,3,1,1
1,3,1,3,1
1,3,1,3,1
1,3,1,3,1
3,1,1,1,3
3,1,1,1,3
3,1,1,1,3
3,1,1,1,3
3,1,1,1,3
3,1,1,1,3
3,1,1,1,3
3,1,1,1,3
3,1,1,1,5
2,3,3,3,2
endlayer

layer
1,1,1,1,1
1,1,3,1,1
1,1,6,1,1
1,3,6,3,1
1,6,3,3,1
1,6,3,3,1
3,3,7,3,3
3,3,7,6,3
7,7,3,6,3
7,3,3,3,6
7,3,3,3,6
7,7,3,3,6
7,3,3,3,6
3,3,3,3,6
5,3,3,3,3
5,5,3,3,3
5,5,1,5,5
endlayer

layer
1,1,5,1,1
1,1,5,1,1
1,5,1,5,1
1,5,1,5,1
5,1,1,1,5
5,1,1,1,5
5,1,1,1,5
1,1,1,1,1
1,1,1,1,1
1,7,3,6,1
1,3,6,6,1
1,7,3,6,1
1,3,1,3,1
1,5,1,6,1
1,5,1,3,1
1,1,1,1,1
1,1,1,1,1
endlayer

layer
1,1,1,1,1
1,1,1,1,1
1,1,1,1,1
1,1,1,1,1
1,1,1,1,1
1,1,1,1,1
1,1,1,1,1
1,1,1,1,1
1,1,1,1,1
1,1,1,1,1
1,1,1,1,1
1,1,1,1,1
1,3,1,3,1
1,1,1,1,1
1,1,1,1,1
1,1,1,1,1
1,1,1,1,1
endlayer

layer
1,1,1,1,1
1,1,1,1,1
1,1,1,1,1
1,1,1,1,1
1,1,1,1,1
1,1,1,1,1
1,1,1,1,1
1,1,1,1,1
1,1,1,1,1
1,1,1,1,1
1,1,1,1,1
1,8,8,8,1
1,8,8,8,1
1,8,8,8,1
1,1,1,1,1
1,1,1,1,1
1,1,1,1,1
endlayer

