weight=5
dimensionsToSpawnIn=overworld
embed_into_distance=1
random_height_offset=0,0
acceptable_target_blocks=
unacceptable_target_blocks=flowing_water,water,flowing_lava,lava,ice,packed_ice,stained_hardened_clay-9,brick_block,double_stone_slab,stonebrick,red_sandstone,red_nether_brick,red_mushroom_block,brown_mushroom_block,planks,cobblestone,end_stone,obsidian,purpur_block,iron_bars,purpur_slab,purpur_pillar,netherrack,soul_sand,quartz_ore,stained_glass,glass
dimensions=17,32,7
allowable_overhang=0
max_leveling=2
leveling_buffer=-1
preventRotation=0
preserve_water=0
preserve_lava=0
uniqueMinDistance=5000
spawnMinDistance=0
spawnMaxDistance=0

rule1=0,100,preserveBlock
rule2=0,100,minecraft:cobblestone_wall-0
rule3=0,100,minecraft:stonebrick-0
rule4=0,100,minecraft:stone_slab-0
rule5=0,100,chisel:technical-12
rule6=0,100,preserveBlock
rule7=0,100,minecraft:stone_brick_stairs-0
rule8=0,100,minecraft:stone_brick_stairs-5
rule9=0,100,minecraft:ladder-4
rule10=0,100,minecraft:stone_brick_stairs-4
rule11=0,100,minecraft:stone_brick_stairs-1
rule12=0,100,chisel:factory-1
rule13=0,100,minecraft:hopper-5
rule14=0,100,minecraft:hopper-4
rule15=0,100,minecraft:stone_slab-8
rule16=0,100,minecraft:stone_slab-5
rule17=0,100,chisel:technicalnew-2
rule18=0,100,chisel:iron-8
rule19=0,100,minecraft:stained_glass_pane-7
rule20=0,100,ChestGenHook:gameplay/fishing/junk:9-2,ChestGenHook:gameplay/fishing/junk:9-2,ChestGenHook:gameplay/fishing/junk:9-2,IInventory;minecraft:chest;minecraft:brown_mushroom#1#0#1+minecraft:poisonous_potato#1#0#7+minecraft:rotten_flesh#1#0#12+minecraft:poisonous_potato#2#0#14+minecraft:potion#{CustomPotionEffects:[{Ambient:0b,CurativeItems:[{id:"minecraft:milk_bucket",Count:1b,Damage:0s}],ShowParticles:1b,Duration:1200,Id:10b,Amplifier:0b},{Ambient:0b,CurativeItems:[{id:"minecraft:milk_bucket",Count:1b,Damage:0s}],ShowParticles:1b,Duration:3600,Id:9b,Amplifier:1b}],RepairCost:0,Potion:"minecraft:water",display:{Name:"Wine"}}#0#15+minecraft:web#1#0#18+minecraft:rotten_flesh#3#0#20+minecraft:poisonous_potato#1#0#25+minecraft:slime_ball#1#0#26-2,IInventory;minecraft:chest;minecraft:potion#{CustomPotionEffects:[{Ambient:0b,CurativeItems:[{id:"minecraft:milk_bucket",Count:1b,Damage:0s}],ShowParticles:1b,Duration:1800,Id:26b,Amplifier:1b},{Ambient:0b,CurativeItems:[{id:"minecraft:milk_bucket",Count:1b,Damage:0s}],ShowParticles:1b,Duration:2400,Id:9b,Amplifier:2b}],RepairCost:0,Potion:"minecraft:water",display:{Name:"Whiskey"}}#0#0+minecraft:poisonous_potato#4#0#2+minecraft:rotten_flesh#2#0#4+minecraft:brown_mushroom#1#0#6+minecraft:brown_mushroom#1#0#14+minecraft:web#1#0#17+minecraft:slime_ball#1#0#18+minecraft:rotten_flesh#1#0#21-2,IInventory;minecraft:chest;minecraft:potion#{CustomPotionEffects:[{Ambient:0b,CurativeItems:[{id:"minecraft:milk_bucket",Count:1b,Damage:0s}],ShowParticles:1b,Duration:1200,Id:10b,Amplifier:0b},{Ambient:0b,CurativeItems:[{id:"minecraft:milk_bucket",Count:1b,Damage:0s}],ShowParticles:1b,Duration:3600,Id:9b,Amplifier:1b}],RepairCost:0,Potion:"minecraft:water",display:{Name:"Wine"}}#0#0+minecraft:poisonous_potato#1#0#2+minecraft:rotten_flesh#1#0#5+minecraft:rotten_flesh#1#0#8+minecraft:poisonous_potato#1#0#10+minecraft:potion#{CustomPotionEffects:[{Ambient:0b,CurativeItems:[{id:"minecraft:milk_bucket",Count:1b,Damage:0s}],ShowParticles:1b,Duration:1800,Id:26b,Amplifier:1b},{Ambient:0b,CurativeItems:[{id:"minecraft:milk_bucket",Count:1b,Damage:0s}],ShowParticles:1b,Duration:2400,Id:9b,Amplifier:2b}],RepairCost:0,Potion:"minecraft:water",display:{Name:"Whiskey"}}#0#12+minecraft:poisonous_potato#1#0#15+minecraft:web#1#0#18+minecraft:rotten_flesh#1#0#21+minecraft:slime_ball#1#0#24+minecraft:brown_mushroom#1#0#26-2,IInventory;minecraft:chest;minecraft:web#1#0#0+minecraft:rotten_flesh#1#0#2+minecraft:poisonous_potato#1#0#6+minecraft:brown_mushroom#1#0#9+minecraft:rotten_flesh#3#0#17+minecraft:potion#{CustomPotionEffects:[{Ambient:0b,CurativeItems:[{id:"minecraft:milk_bucket",Count:1b,Damage:0s}],ShowParticles:1b,Duration:10800,Id:1b,Amplifier:0b},{Ambient:0b,CurativeItems:[{id:"minecraft:milk_bucket",Count:1b,Damage:0s}],ShowParticles:1b,Duration:4800,Id:3b,Amplifier:0b}],RepairCost:0,Potion:"minecraft:water",display:{Name:"Energy Drink"}}#0#20+minecraft:poisonous_potato#1#0#22+minecraft:slime_ball#1#0#23-2,IInventory;minecraft:chest;minecraft:rotten_flesh#1#0#3+minecraft:brown_mushroom#1#0#6+minecraft:poisonous_potato#3#0#10+minecraft:rotten_flesh#1#0#13+minecraft:potion#{CustomPotionEffects:[{Ambient:0b,CurativeItems:[{id:"minecraft:milk_bucket",Count:1b,Damage:0s}],ShowParticles:1b,Duration:1200,Id:10b,Amplifier:0b},{Ambient:0b,CurativeItems:[{id:"minecraft:milk_bucket",Count:1b,Damage:0s}],ShowParticles:1b,Duration:3600,Id:9b,Amplifier:1b}],RepairCost:0,Potion:"minecraft:water",display:{Name:"Wine"}}#0#16+minecraft:slime_ball#1#0#18+minecraft:brown_mushroom#1#0#21+minecraft:rotten_flesh#1#0#25+minecraft:web#1#0#26-2
rule21=0,100,minecraft:stone_brick_stairs-6
rule22=0,100,minecraft:stone_brick_stairs-7
rule23=0,100,minecraft:iron_bars-0
rule24=0,100,ChestGenHook:chests/abandoned_mineshaft:1-3,ChestGenHook:chests/abandoned_mineshaft:1-3,ChestGenHook:chests/abandoned_mineshaft:1-3,ChestGenHook:chests/abandoned_mineshaft:1-3,ChestGenHook:chests/abandoned_mineshaft:1-3,IInventory;minecraft:chest;minecraft:dirt#5#0#0+minecraft:iron_nugget#9#0#1+minecraft:gravel#1#0#3+minecraft:gravel#3#0#4+minecraft:brown_mushroom#1#0#6+minecraft:potion#{CustomPotionEffects:[{Ambient:0b,CurativeItems:[{id:"minecraft:milk_bucket",Count:1b,Damage:0s}],ShowParticles:1b,Duration:18000,Id:15b,Amplifier:0b}],RepairCost:0,Potion:"minecraft:water",display:{Name:"Methanol"}}#0#12+minecraft:iron_nugget#1#0#13+minecraft:iron_nugget#3#0#16+minecraft:dirt#1#0#17+minecraft:gravel#1#0#19+minecraft:brown_mushroom#1#0#20+minecraft:bucket#1#0#23+minecraft:iron_nugget#1#0#25+minecraft:dirt#1#0#26-3,IInventory;minecraft:chest;minecraft:gravel#1#0#0+minecraft:dirt#4#0#3+minecraft:iron_nugget#1#0#6+minecraft:gravel#1#0#8+minecraft:potion#{CustomPotionEffects:[{Ambient:0b,CurativeItems:[{id:"minecraft:milk_bucket",Count:1b,Damage:0s}],ShowParticles:1b,Duration:9600,Id:9b,Amplifier:0b},{Ambient:0b,CurativeItems:[{id:"minecraft:milk_bucket",Count:1b,Damage:0s}],ShowParticles:1b,Duration:7200,Id:19b,Amplifier:0b}],RepairCost:0,Potion:"minecraft:water",display:{Name:"Bleach"}}#0#14+minecraft:dirt#1#0#15+minecraft:iron_nugget#1#0#17+minecraft:brown_mushroom#1#0#18+minecraft:bucket#1#0#19+minecraft:dirt#4#0#20+minecraft:iron_nugget#3#0#22+minecraft:brown_mushroom#1#0#24+minecraft:gravel#1#0#25-3,IInventory;minecraft:chest;minecraft:gravel#1#0#1+minecraft:brown_mushroom#1#0#3+minecraft:dirt#1#0#4+minecraft:iron_nugget#1#0#11+minecraft:dirt#1#0#15+minecraft:brown_mushroom#1#0#18+minecraft:dirt#4#0#19+minecraft:iron_nugget#3#0#20+minecraft:gravel#2#0#21+minecraft:bucket#1#0#22+minecraft:dirt#3#0#25+minecraft:potion#{CustomPotionEffects:[{Ambient:0b,CurativeItems:[{id:"minecraft:milk_bucket",Count:1b,Damage:0s}],ShowParticles:1b,Duration:18000,Id:15b,Amplifier:0b}],RepairCost:0,Potion:"minecraft:water",display:{Name:"Methanol"}}#0#26-3,IInventory;minecraft:chest;minecraft:iron_nugget#3#0#0+minecraft:dirt#1#0#2+minecraft:iron_nugget#1#0#5+minecraft:dirt#1#0#7+minecraft:dirt#6#0#10+minecraft:iron_nugget#1#0#12+minecraft:brown_mushroom#1#0#13+minecraft:brown_mushroom#1#0#14+minecraft:bucket#1#0#18+minecraft:potion#{CustomPotionEffects:[{Ambient:0b,CurativeItems:[{id:"minecraft:milk_bucket",Count:1b,Damage:0s}],ShowParticles:1b,Duration:9600,Id:9b,Amplifier:0b},{Ambient:0b,CurativeItems:[{id:"minecraft:milk_bucket",Count:1b,Damage:0s}],ShowParticles:1b,Duration:7200,Id:19b,Amplifier:0b}],RepairCost:0,Potion:"minecraft:water",display:{Name:"Bleach"}}#0#20+minecraft:dirt#1#0#22+minecraft:gravel#2#0#26-3,IInventory;minecraft:chest;minecraft:potion#{CustomPotionEffects:[{Ambient:0b,CurativeItems:[{id:"minecraft:milk_bucket",Count:1b,Damage:0s}],ShowParticles:1b,Duration:18000,Id:15b,Amplifier:0b}],RepairCost:0,Potion:"minecraft:water",display:{Name:"Methanol"}}#0#0+minecraft:dirt#8#0#1+minecraft:dirt#1#0#7+minecraft:brown_mushroom#1#0#11+minecraft:gravel#1#0#12+minecraft:gravel#1#0#18+minecraft:gravel#1#0#19+minecraft:dirt#3#0#23+minecraft:brown_mushroom#1#0#24+minecraft:bucket#1#0#25+minecraft:iron_nugget#3#0#26-3
rule25=0,100,chisel:blockiron-6,chisel:blockinvar-6,chisel:blocksteel-6,chisel:blocktin-6,chisel:blockaluminum-6,chisel:planks-spruce-12,chisel:planks-oak-12,chisel:planks-dark-oak-12
rule26=0,100,chisel:blockiron-6,chisel:blockinvar-6,chisel:blocksteel-6,chisel:blocktin-6,chisel:blockaluminum-6,chisel:planks-spruce-12,chisel:planks-oak-12,chisel:planks-dark-oak-12
rule27=0,100,IInventory;minecraft:chest;minecraft:cobblestone#1#0#0+minecraft:coal_ore#2#0#3+minecraft:coal_ore#1#0#4+minecraft:gravel#1#0#5+minecraft:flint#2#0#6+minecraft:gravel#1#0#8+minecraft:iron_ore#3#0#10+minecraft:cobblestone#1#0#12+minecraft:gravel#3#0#14+minecraft:gravel#1#0#15+minecraft:iron_ore#5#0#16+minecraft:coal_ore#1#0#18+minecraft:flint#1#0#19+minecraft:cobblestone#1#0#20+minecraft:iron_ore#2#0#22+minecraft:cobblestone#1#0#23+minecraft:gold_ore#3#0#24+minecraft:flint#6#0#25-4,IInventory;minecraft:chest;minecraft:flint#1#0#1+minecraft:coal_ore#2#0#3+minecraft:cobblestone#1#0#5+minecraft:cobblestone#1#0#7+minecraft:cobblestone#1#0#8+minecraft:gravel#3#0#9+minecraft:iron_ore#3#0#11+minecraft:iron_ore#1#0#13+minecraft:flint#5#0#14+minecraft:gold_ore#2#0#15+minecraft:iron_ore#2#0#17+minecraft:coal_ore#1#0#18+minecraft:gravel#1#0#19+minecraft:gravel#2#0#20+minecraft:cobblestone#1#0#21+minecraft:coal_ore#1#0#23+minecraft:iron_ore#4#0#24+minecraft:flint#4#0#25-4,IInventory;minecraft:chest;minecraft:iron_ore#1#0#1+minecraft:gravel#1#0#2+minecraft:flint#3#0#3+minecraft:gold_ore#2#0#4+minecraft:iron_ore#3#0#6+minecraft:coal_ore#1#0#8+minecraft:flint#5#0#9+minecraft:gravel#1#0#11+minecraft:cobblestone#1#0#13+minecraft:cobblestone#1#0#14+minecraft:coal_ore#1#0#15+minecraft:gravel#2#0#16+minecraft:cobblestone#1#0#19+minecraft:coal_ore#1#0#20+minecraft:iron_ore#4#0#21+minecraft:gravel#1#0#23+minecraft:flint#7#0#24-4,IInventory;minecraft:chest;minecraft:coal_ore#1#0#1+minecraft:flint#3#0#3+minecraft:gravel#2#0#5+minecraft:gravel#1#0#8+minecraft:flint#6#0#10+minecraft:cobblestone#1#0#11+minecraft:cobblestone#1#0#12+minecraft:iron_ore#3#0#13+minecraft:gravel#1#0#15+minecraft:coal_ore#1#0#18+minecraft:gravel#5#0#20+minecraft:iron_ore#1#0#21+minecraft:cobblestone#1#0#23+minecraft:gold_ore#1#0#24+minecraft:flint#5#0#25+minecraft:iron_ore#5#0#26-4,IInventory;minecraft:chest;minecraft:cobblestone#1#0#0+minecraft:gravel#1#0#3+minecraft:flint#1#0#5+minecraft:iron_ore#2#0#7+minecraft:flint#4#0#9+minecraft:gravel#1#0#11+minecraft:flint#5#0#12+minecraft:gold_ore#1#0#13+minecraft:gravel#1#0#14+minecraft:gravel#1#0#15+minecraft:cobblestone#1#0#16+minecraft:iron_ore#2#0#19+minecraft:cobblestone#1#0#20+minecraft:cobblestone#1#0#22+minecraft:iron_ore#2#0#24+minecraft:flint#7#0#26-4
rule28=0,100,minecraft:stone_brick_stairs-2
rule29=0,100,minecraft:stone_brick_stairs-3

layer
1,1,1,1,1,1,1
1,1,1,1,1,1,1
1,1,1,1,1,1,1
1,1,1,1,1,1,1
1,1,1,1,1,1,1
1,1,1,1,1,1,1
1,1,1,1,1,1,1
1,1,1,1,1,1,1
1,1,1,1,1,1,1
1,1,1,1,1,1,1
1,1,1,1,1,1,1
1,1,1,1,1,1,1
1,1,1,1,1,1,1
1,1,2,1,1,1,2
1,1,3,1,1,1,3
1,1,4,1,1,1,4
1,1,3,1,1,1,3
1,1,3,1,1,1,3
1,1,3,1,1,1,3
1,1,4,1,1,1,4
1,1,3,1,1,1,3
1,1,2,1,1,1,2
1,1,1,1,1,1,1
1,1,1,1,1,1,1
1,1,1,1,1,1,1
1,1,1,1,1,1,1
1,1,1,1,1,1,1
1,1,1,1,1,1,1
1,1,1,1,1,1,1
1,1,1,1,1,1,1
1,1,1,1,1,1,1
1,1,1,1,1,1,1
endlayer

layer
1,1,1,1,1,1,1
1,1,1,1,1,1,1
1,1,1,1,1,1,1
1,1,1,1,1,1,1
1,1,1,1,1,1,1
1,1,1,1,1,1,1
1,1,1,1,1,1,1
1,1,1,1,1,1,1
1,1,1,1,1,1,1
1,1,1,1,1,1,1
1,1,1,1,1,1,1
1,1,1,1,1,1,1
1,1,1,1,1,1,1
1,1,2,1,1,1,2
1,1,3,1,1,1,3
1,1,4,1,1,1,4
1,1,3,5,5,5,3
1,1,3,0,6,0,3
1,1,3,5,5,5,3
1,1,4,1,1,1,4
1,1,3,1,1,1,3
1,1,2,1,1,1,2
1,1,1,1,1,1,1
1,1,1,1,1,1,1
1,1,1,1,1,1,1
1,1,1,1,1,1,1
1,1,1,1,1,1,1
1,1,1,1,1,1,1
1,1,1,1,1,1,1
1,1,1,1,1,1,1
1,1,1,1,1,1,1
1,1,1,1,1,1,1
endlayer

layer
1,1,1,0,0,0,1
1,1,1,0,0,0,1
1,1,1,0,0,0,1
1,1,1,0,0,0,1
1,1,1,0,0,0,1
1,1,1,0,0,0,1
1,1,1,0,0,0,1
1,1,1,1,1,1,1
1,1,1,1,1,1,1
1,1,1,1,1,1,1
1,1,1,1,1,1,1
1,1,1,1,1,1,1
1,1,1,1,1,1,1
1,1,2,0,0,0,2
1,1,7,0,0,0,7
1,1,8,0,0,0,8
1,1,5,0,0,0,5
1,1,9,0,0,0,0
1,1,5,0,0,0,5
1,1,10,0,0,0,10
1,1,11,0,0,0,11
1,1,2,0,0,0,2
1,1,1,1,1,1,1
1,1,1,1,1,1,1
1,1,1,1,1,1,1
1,1,1,1,1,1,1
1,1,1,1,1,1,1
1,1,1,1,1,1,1
1,1,1,1,1,1,1
1,1,1,1,1,1,1
1,1,1,1,1,1,1
1,1,1,1,1,1,1
endlayer

layer
1,1,1,0,0,0,1
1,1,0,0,0,0,0
1,1,0,0,8,0,0
1,1,0,0,0,0,0
1,1,0,0,8,0,0
1,1,0,0,0,0,0
1,1,0,0,0,0,0
1,0,0,0,0,0,0
1,0,0,0,0,0,0
1,0,0,0,0,0,0
1,0,0,0,0,0,0
0,0,0,0,0,0,0
0,0,0,0,0,0,0
0,0,0,0,0,0,0
0,0,0,0,0,0,0
0,0,7,0,0,0,7
0,0,5,0,0,0,5
0,0,9,0,0,0,0
0,0,5,0,0,0,5
0,0,11,0,0,0,11
0,0,0,0,0,0,0
0,0,0,0,0,0,0
1,0,0,0,0,0,0
1,0,0,0,0,0,0
1,0,0,0,0,0,0
1,1,0,0,0,0,0
1,1,0,0,0,0,0
1,1,0,0,0,0,0
1,1,0,0,0,0,0
1,1,0,0,0,0,0
1,1,0,0,0,0,0
1,1,0,0,0,0,0
endlayer

layer
1,1,0,0,0,0,0
1,0,0,0,3,0,0
1,0,0,0,12,0,0
1,0,0,0,5,0,0
1,0,0,0,12,0,0
1,0,0,0,3,0,0
1,0,0,0,0,0,0
1,0,0,0,0,0,0
0,0,0,0,0,0,0
0,0,0,0,0,0,0
0,0,0,0,0,0,0
0,0,0,0,0,0,0
0,0,0,0,0,0,0
0,0,0,0,0,0,0
0,0,0,0,0,0,0
0,0,0,0,0,0,0
0,0,5,0,0,0,5
0,0,9,0,0,0,0
0,0,5,0,0,0,5
0,0,0,0,0,0,0
0,0,0,0,0,0,0
0,0,0,0,0,0,0
0,0,0,0,0,0,0
0,0,0,0,0,0,0
0,0,0,0,0,0,0
1,0,0,0,0,0,0
1,0,0,0,0,0,0
1,0,0,0,0,0,0
1,0,0,5,5,5,0
1,1,0,5,13,5,0
1,1,0,5,14,5,0
1,1,0,12,5,12,0
endlayer

layer
0,0,0,0,10,0,0
0,0,0,0,12,0,0
0,0,0,0,5,0,0
0,0,0,15,5,15,0
0,0,0,15,5,15,0
0,0,0,15,12,15,0
0,0,0,12,11,12,0
0,0,0,12,15,12,0
0,0,0,12,15,12,0
0,0,0,5,5,5,0
0,0,0,5,0,5,0
0,0,0,5,0,5,0
0,0,0,5,5,5,0
0,0,0,5,0,5,0
0,0,0,5,0,5,0
0,0,0,5,5,5,0
15,15,12,5,0,5,12
15,15,9,5,0,5,0
15,15,12,5,0,5,12
0,0,0,5,5,5,0
0,0,0,5,0,5,0
0,0,0,5,0,5,0
0,0,0,5,5,5,0
0,0,0,5,0,5,0
0,0,0,5,0,5,0
0,0,0,5,5,5,0
0,0,0,5,0,5,0
0,0,0,5,15,5,0
0,0,0,5,4,5,0
1,0,0,0,0,0,0
1,0,0,10,0,10,0
1,0,0,11,16,11,0
endlayer

layer
0,0,0,0,0,0,0
0,0,0,0,5,0,0
0,0,0,0,5,0,0
0,0,0,12,12,12,0
0,0,0,0,5,0,0
0,0,0,0,5,0,0
0,0,0,17,0,17,0
0,0,0,17,18,17,0
0,0,0,17,18,17,0
0,0,0,5,4,5,0
0,0,0,0,4,0,0
0,0,0,15,4,15,0
0,0,0,5,4,5,0
0,0,0,0,4,0,0
0,0,0,0,4,0,0
0,0,0,5,4,5,0
19,19,17,0,4,0,17
12,20,0,0,4,0,0
12,12,17,0,4,0,17
0,0,0,5,4,5,0
0,0,0,0,4,0,0
0,0,0,0,4,0,0
0,0,0,5,4,5,0
0,0,0,15,4,15,0
0,0,0,0,4,0,0
0,0,0,5,4,5,0
0,0,0,0,4,0,0
0,0,0,0,0,0,0
0,0,0,5,0,5,0
0,0,0,10,0,10,0
0,0,0,11,0,11,0
0,0,0,0,0,0,0
endlayer

layer
0,0,0,0,10,0,0
0,0,0,0,12,0,0
0,0,0,0,5,0,0
0,0,0,4,5,4,0
0,0,0,4,5,4,0
0,0,0,4,12,4,0
0,0,0,12,11,12,0
0,0,0,12,4,12,0
0,0,0,12,4,12,0
0,0,0,5,5,5,0
0,0,0,5,0,5,0
0,0,22,5,0,5,21
0,0,0,5,5,5,0
0,0,0,5,0,5,0
0,0,0,5,0,5,0
0,0,0,5,5,5,0
19,19,12,5,0,5,12
12,0,0,5,0,5,0
12,12,12,5,0,5,12
0,0,0,5,5,5,0
0,0,0,5,0,5,0
0,0,0,5,0,5,0
0,0,0,5,5,5,0
0,0,22,5,0,5,21
0,0,0,5,0,5,0
0,0,0,5,5,5,0
0,0,0,5,0,5,0
0,0,0,5,0,5,0
0,0,0,5,0,5,0
0,0,0,11,11,11,0
0,0,0,0,0,0,0
0,0,0,0,0,0,0
endlayer

layer
0,0,0,0,0,0,0
0,0,0,0,3,0,0
0,0,0,0,12,0,0
0,0,0,0,5,0,0
0,0,0,0,12,0,0
0,0,0,0,3,0,0
0,0,0,0,0,0,0
0,0,0,0,0,0,0
0,0,0,0,0,0,0
0,0,0,0,0,0,0
0,0,0,0,0,0,0
0,0,2,0,0,0,2
0,0,0,0,0,0,0
0,0,0,0,0,0,0
0,0,0,0,0,0,0
0,0,0,0,0,0,0
4,4,5,0,0,0,5
4,4,4,0,0,0,0
4,4,5,0,0,0,5
0,0,0,0,0,0,0
0,0,0,0,0,0,0
0,0,0,0,0,0,0
0,0,0,0,0,0,0
0,0,2,0,0,0,2
0,0,0,0,0,0,0
0,0,0,0,0,0,0
0,0,0,0,0,0,0
0,0,0,0,0,0,0
0,0,0,0,0,0,0
0,0,0,0,0,0,0
0,0,0,0,0,0,0
0,0,0,0,0,0,0
endlayer

layer
0,0,0,0,0,0,0
0,0,0,0,0,0,0
0,0,0,0,7,0,0
0,0,0,0,0,0,0
0,0,0,0,7,0,0
0,0,0,0,0,0,0
0,0,0,0,0,0,0
0,0,0,0,0,0,0
0,0,0,0,0,0,0
0,0,0,0,0,0,0
0,0,0,0,0,0,0
0,0,23,0,0,0,23
0,0,0,0,0,0,0
0,0,0,0,0,0,0
0,0,0,0,0,0,0
0,0,0,0,0,0,0
0,0,5,0,0,0,5
0,0,0,0,0,0,0
0,0,5,0,0,0,5
0,0,0,0,0,0,0
0,0,0,0,0,0,0
0,0,0,0,0,0,0
0,0,0,0,0,0,0
0,0,23,0,0,0,23
0,0,0,0,0,0,0
0,0,0,0,0,0,0
0,0,0,0,0,0,0
0,0,0,0,0,0,0
0,0,0,0,0,0,0
0,0,0,0,0,0,0
0,0,0,0,0,0,0
0,0,0,0,0,0,0
endlayer

layer
0,0,0,0,0,0,0
0,0,0,0,0,0,0
0,0,0,0,0,0,0
0,0,0,0,0,0,0
0,0,0,0,0,0,0
0,0,0,0,0,0,0
0,0,0,0,0,0,0
0,0,0,0,0,0,0
0,0,0,0,0,0,0
0,0,0,0,0,0,0
0,0,0,0,0,0,0
0,0,23,0,0,0,23
0,0,0,0,0,0,0
0,0,0,0,0,0,0
0,0,0,0,0,0,0
0,0,0,0,0,0,0
0,0,5,0,0,0,5
0,0,0,0,0,0,0
0,0,5,0,0,0,5
0,0,0,0,0,0,0
0,0,0,0,0,0,0
0,0,0,0,0,0,0
0,0,0,0,0,0,0
0,0,23,0,0,0,23
0,0,0,0,0,0,0
0,0,0,0,0,0,0
0,0,0,0,0,0,0
0,0,0,0,0,0,0
0,0,0,0,0,0,0
0,0,0,0,0,0,0
0,0,0,0,0,0,0
0,0,0,0,0,0,0
endlayer

layer
0,0,0,0,0,0,0
0,0,0,0,0,0,0
0,0,0,0,0,0,0
0,0,0,0,0,0,0
0,0,0,0,0,0,0
0,0,0,0,0,0,0
0,0,0,0,0,0,0
0,0,0,0,0,0,0
0,0,0,0,0,0,0
0,0,0,0,0,0,0
0,0,0,0,0,0,0
0,0,23,0,0,0,23
0,0,0,0,0,0,0
0,0,0,0,0,0,0
0,0,0,0,0,0,0
0,0,0,0,0,0,0
0,0,5,0,0,0,5
0,0,0,0,0,0,0
0,0,5,0,0,0,5
0,0,0,0,0,0,0
0,0,0,0,0,0,0
0,0,0,0,0,0,0
0,0,0,0,0,0,0
0,0,23,0,0,0,23
0,0,0,0,0,0,0
0,0,0,0,0,0,0
0,0,0,0,0,0,0
0,0,0,0,0,0,0
0,0,0,0,0,0,0
0,0,0,0,0,0,0
0,0,0,0,0,0,0
0,0,0,0,0,0,0
endlayer

layer
0,0,0,0,0,0,0
0,0,0,0,0,0,0
0,0,0,0,0,0,0
0,0,0,0,0,0,0
0,0,0,0,0,0,0
0,0,0,0,0,0,0
0,0,0,0,0,0,0
0,0,0,0,0,0,0
0,0,0,0,0,0,0
0,0,0,0,0,0,0
0,0,0,0,0,0,0
0,0,23,0,0,0,23
0,0,0,0,0,0,0
0,0,0,0,0,0,0
0,0,0,0,0,0,0
0,0,0,0,0,0,0
0,0,5,5,5,5,5
0,0,0,0,0,0,0
0,0,5,5,5,5,5
0,0,12,15,15,15,12
0,0,5,15,15,15,5
0,0,5,15,15,15,5
0,0,5,15,15,15,5
0,0,12,5,5,5,12
0,0,0,0,0,0,0
0,0,0,0,0,0,0
0,0,0,0,0,0,0
0,0,0,0,0,0,0
0,0,0,0,0,0,0
0,0,0,0,0,0,0
0,0,0,0,0,0,0
0,0,0,0,0,0,0
endlayer

layer
0,0,0,0,0,0,0
0,0,0,0,0,0,0
0,0,0,0,0,0,0
0,0,0,0,0,0,0
0,0,0,0,0,0,0
0,0,0,0,0,0,0
0,0,0,0,0,0,0
0,0,0,0,0,0,0
0,0,0,0,0,0,0
0,0,0,0,0,0,0
0,0,0,0,0,0,0
0,0,23,0,0,0,23
0,0,0,0,0,0,0
0,0,0,0,0,0,0
0,0,0,0,0,0,0
0,0,10,0,0,0,10
0,0,11,0,0,0,11
0,0,0,0,0,0,0
0,0,5,0,0,0,5
0,0,23,20,0,24,23
0,0,23,26,0,25,23
0,0,23,26,0,25,23
0,0,23,26,27,25,23
0,0,23,23,23,23,23
0,0,0,0,0,0,0
0,0,0,0,0,0,0
0,0,0,0,0,0,0
0,0,0,0,0,0,0
0,0,0,0,0,0,0
0,0,0,0,0,0,0
0,0,0,0,0,0,0
0,0,0,0,0,0,0
endlayer

layer
0,0,0,0,0,0,0
0,0,0,0,0,0,0
0,0,0,0,0,0,0
0,0,0,0,0,0,0
0,0,0,0,0,0,0
0,0,0,0,0,0,0
0,0,0,0,0,0,0
0,0,0,0,0,0,0
0,0,0,0,0,0,0
0,0,0,0,0,0,0
0,0,0,0,0,0,0
0,0,7,7,7,7,7
0,0,5,0,0,0,5
0,0,5,0,0,0,5
0,0,5,0,0,0,5
0,0,11,11,11,11,11
0,0,0,0,0,0,0
0,0,0,0,0,0,0
0,0,5,0,0,0,5
0,0,0,0,0,0,0
0,0,0,0,0,0,0
0,0,0,0,0,0,0
0,0,0,0,0,0,0
0,0,0,0,0,0,0
0,0,0,0,0,0,0
0,0,0,0,0,0,0
0,0,0,0,0,0,0
0,0,0,0,0,0,0
0,0,0,0,0,0,0
0,0,0,0,0,0,0
0,0,0,0,0,0,0
0,0,0,0,0,0,0
endlayer

layer
0,0,0,0,0,0,0
0,0,0,0,0,0,0
0,0,0,0,0,0,0
0,0,0,0,0,0,0
0,0,0,0,0,0,0
0,0,0,0,0,0,0
0,0,0,0,0,0,0
0,0,0,0,0,0,0
0,0,0,0,0,0,0
0,0,0,0,0,0,0
0,0,0,0,0,0,0
0,0,0,0,0,0,0
0,0,0,0,0,0,0
0,0,0,0,0,0,0
0,0,0,0,0,0,0
0,0,4,0,0,0,4
0,0,15,0,0,0,15
0,0,0,0,0,0,0
0,0,5,0,0,0,5
0,0,0,0,0,0,0
0,0,0,0,0,0,0
0,0,0,0,0,0,0
0,0,0,0,0,0,0
0,0,0,0,0,0,0
0,0,0,0,0,0,0
0,0,0,0,0,0,0
0,0,0,0,0,0,0
0,0,0,0,0,0,0
0,0,0,0,0,0,0
0,0,0,0,0,0,0
0,0,0,0,0,0,0
0,0,0,0,0,0,0
endlayer

layer
0,0,0,0,0,0,0
0,0,0,0,0,0,0
0,0,0,0,0,0,0
0,0,0,0,0,0,0
0,0,0,0,0,0,0
0,0,0,0,0,0,0
0,0,0,0,0,0,0
0,0,0,0,0,0,0
0,0,0,0,0,0,0
0,0,0,0,0,0,0
0,0,0,0,0,0,0
0,0,0,0,0,0,0
0,0,0,0,0,0,0
0,0,0,0,0,0,0
0,0,0,0,0,0,0
0,0,0,0,0,0,0
0,0,0,0,0,0,0
0,0,4,0,0,0,4
0,0,29,5,5,5,28
0,0,0,0,0,0,0
0,0,0,0,0,0,0
0,0,0,0,0,0,0
0,0,0,0,0,0,0
0,0,0,0,0,0,0
0,0,0,0,0,0,0
0,0,0,0,0,0,0
0,0,0,0,0,0,0
0,0,0,0,0,0,0
0,0,0,0,0,0,0
0,0,0,0,0,0,0
0,0,0,0,0,0,0
0,0,0,0,0,0,0
endlayer

