weight=2
dimensionsToSpawnIn=overworld
embed_into_distance=1
random_height_offset=0,0
unacceptable_target_blocks=sand,flowing_water,water,flowing_lava,lava,ice,packed_ice,stained_hardened_clay-9,brick_block,double_stone_slab,stonebrick,red_sandstone,red_nether_brick,red_mushroom_block,brown_mushroom_block,planks,cobblestone,end_stone,obsidian,purpur_block,iron_bars,purpur_slab,purpur_pillar,netherrack,soul_sand,quartz_ore,stained_glass,glass
dimensions=23,11,5
allowable_overhang=0
max_leveling=1
leveling_buffer=-1
preventRotation=0
preserve_water=0
preserve_lava=0
uniqueMinDistance=0
spawnMinDistance=0
spawnMaxDistance=0

rule1=0,100,preserveBlock
rule2=0,100,minecraft:stone-6
rule3=0,100,minecraft:stone_brick_stairs-0
rule4=0,100,minecraft:stone_brick_stairs-2
rule5=0,100,minecraft:stone_brick_stairs-3
rule6=0,100,minecraft:stone_brick_stairs-1
rule7=0,100,minecraft:cobblestone_wall-0
rule8=0,100,preserveBlock
rule9=0,100,chisel:factory-1
rule10=0,100,minecraft:iron_bars-0
rule11=0,100,minecraft:vine-8
rule12=0,100,minecraft:vine-1
rule13=0,100,minecraft:vine-4
rule14=0,100,minecraft:vine-2
rule15=0,100,minecraft:stone_slab-8

layer
1,1,1,1,1
1,1,1,1,1
1,1,1,1,1
1,2,2,2,1
2,2,2,2,2
2,2,2,2,2
2,2,2,2,2
1,2,2,2,1
1,1,1,1,1
1,1,1,1,1
1,1,1,1,1
endlayer

layer
1,1,1,1,1
1,1,1,1,1
1,1,1,1,1
1,3,3,3,1
5,2,2,2,4
5,2,2,2,4
5,2,2,2,4
1,6,6,6,1
1,1,1,1,1
1,1,1,1,1
1,1,1,1,1
endlayer

layer
1,1,1,1,1
1,1,1,1,1
1,1,1,1,1
1,1,1,1,1
1,7,2,7,1
1,2,8,2,1
1,7,2,7,1
1,1,1,1,1
1,1,1,1,1
1,1,1,1,1
1,1,1,1,1
endlayer

layer
1,1,1,1,1
1,1,1,1,1
1,1,1,1,1
1,1,1,1,1
1,7,3,7,1
1,5,9,4,1
1,7,6,7,1
1,1,1,1,1
1,1,1,1,1
1,1,1,1,1
1,1,1,1,1
endlayer

layer
1,1,1,1,1
1,1,1,1,1
1,1,1,1,1
1,1,1,1,1
1,10,11,10,1
1,13,9,12,1
1,10,14,10,1
1,1,1,1,1
1,1,1,1,1
1,1,1,1,1
1,1,1,1,1
endlayer

layer
0,0,0,0,0
0,0,0,0,0
0,0,0,0,0
0,0,0,0,0
0,0,15,15,0
0,13,9,0,0
0,0,15,15,0
0,0,0,0,0
0,0,0,0,0
0,0,0,0,0
0,0,0,0,0
endlayer

layer
0,0,0,10,10
0,0,0,10,0
0,0,0,10,10
0,0,0,10,0
0,0,7,10,10
0,13,9,10,0
0,0,7,10,10
0,0,0,10,0
0,0,0,10,10
0,0,0,10,0
0,0,0,10,10
endlayer

layer
0,0,0,10,10
0,0,0,10,0
0,0,0,10,10
0,0,0,10,0
0,0,10,10,10
0,13,9,10,0
0,0,10,10,10
0,0,0,10,0
0,0,0,10,10
0,0,0,10,0
0,0,0,10,10
endlayer

layer
0,0,0,10,10
0,0,0,10,0
0,0,0,10,10
0,0,0,10,0
0,0,7,10,10
0,13,9,10,0
0,0,7,10,10
0,0,0,10,0
0,0,0,10,10
0,0,0,10,0
0,0,0,10,10
endlayer

layer
0,0,0,0,0
0,0,0,0,0
0,0,0,0,0
0,0,0,0,0
0,0,15,15,0
0,13,9,10,0
0,0,15,15,0
0,0,0,0,0
0,0,0,0,0
0,0,0,0,0
0,0,0,0,0
endlayer

layer
0,0,0,10,10
0,0,0,10,0
0,0,0,10,10
0,0,0,10,0
0,0,7,10,10
0,13,9,10,0
0,0,7,10,10
0,0,0,10,0
0,0,0,10,10
0,0,0,10,0
0,0,0,10,10
endlayer

layer
0,0,0,10,10
0,0,0,10,0
0,0,0,10,10
0,0,0,10,0
0,0,10,10,10
0,13,9,10,0
0,0,10,10,10
0,0,0,10,0
0,0,0,10,10
0,0,0,10,0
0,0,0,10,10
endlayer

layer
0,0,0,10,10
0,0,0,10,0
0,0,0,10,10
0,0,0,10,0
0,0,7,10,10
0,13,9,10,0
0,0,7,10,10
0,0,0,10,0
0,0,0,10,10
0,0,0,10,0
0,0,0,10,10
endlayer

layer
0,0,0,0,0
0,0,0,0,0
0,0,0,0,0
0,0,0,0,0
0,0,15,15,0
0,13,9,10,0
0,0,15,15,0
0,0,0,0,0
0,0,0,0,0
0,0,0,0,0
0,0,0,0,0
endlayer

layer
0,0,0,10,10
0,0,0,10,0
0,0,0,10,10
0,0,0,10,0
0,0,7,10,10
0,13,9,10,0
0,0,7,10,10
0,0,0,10,0
0,0,0,10,10
0,0,0,10,0
0,0,0,10,10
endlayer

layer
0,0,0,10,10
0,0,0,10,0
0,0,0,10,10
0,0,0,10,0
0,0,10,10,10
0,13,9,10,0
0,0,10,10,10
0,0,0,10,0
0,0,0,10,10
0,0,0,10,0
0,0,0,10,10
endlayer

layer
0,0,0,10,10
0,0,0,10,0
0,0,0,10,10
0,0,0,10,0
0,0,7,10,10
0,13,9,10,0
0,0,7,10,10
0,0,0,10,0
0,0,0,10,10
0,0,0,10,0
0,0,0,10,10
endlayer

layer
0,0,0,0,0
0,0,0,0,0
0,0,0,0,0
0,0,0,0,0
0,0,11,0,0
0,13,2,12,0
0,0,14,0,0
0,0,0,0,0
0,0,0,0,0
0,0,0,0,0
0,0,0,0,0
endlayer

layer
0,0,0,0,0
0,0,0,0,0
0,0,0,0,0
0,0,0,0,0
0,0,0,0,0
0,0,7,0,0
0,0,0,0,0
0,0,0,0,0
0,0,0,0,0
0,0,0,0,0
0,0,0,0,0
endlayer

layer
0,0,0,0,0
0,0,0,0,0
0,0,0,0,0
0,0,0,0,0
0,0,0,0,0
0,0,7,0,0
0,0,0,0,0
0,0,0,0,0
0,0,0,0,0
0,0,0,0,0
0,0,0,0,0
endlayer

layer
0,0,0,0,0
0,0,0,0,0
0,0,0,0,0
0,0,0,0,0
0,0,0,0,0
0,0,10,0,0
0,0,0,0,0
0,0,0,0,0
0,0,0,0,0
0,0,0,0,0
0,0,0,0,0
endlayer

layer
0,0,0,0,0
0,0,0,0,0
0,0,0,0,0
0,0,0,0,0
0,0,0,0,0
0,0,10,0,0
0,0,0,0,0
0,0,0,0,0
0,0,0,0,0
0,0,0,0,0
0,0,0,0,0
endlayer

layer
0,0,0,0,0
0,0,0,0,0
0,0,0,0,0
0,0,0,0,0
0,0,0,0,0
0,0,10,0,0
0,0,0,0,0
0,0,0,0,0
0,0,0,0,0
0,0,0,0,0
0,0,0,0,0
endlayer

