weight=10
dimensionsToSpawnIn=overworld
embed_into_distance=4
acceptable_target_blocks=stone,grass,dirt,sand
unacceptable_target_blocks=flowing_water,water,flowing_lava,lava,ice,packed_ice,stained_hardened_clay-9,brick_block,double_stone_slab,stonebrick,red_sandstone,red_nether_brick,red_mushroom_block,brown_mushroom_block,planks,cobblestone,end_stone,obsidian,purpur_block,iron_bars,purpur_slab,purpur_pillar,netherrack,soul_sand,quartz_ore,stained_glass,glass
dimensions=10,12,12
allowable_overhang=2
max_leveling=2
leveling_buffer=1
preserve_water=0
preserve_lava=0
preserve_plants=0

rule1=1,85,chisel:brownstone-1,chisel:brownstone-1,chisel:brownstone-1,chisel:brownstone-1,chisel:brownstone-1,chisel:brownstone-0,iron_bars-0,iron_bars-0,iron_bars-0,iron_bars-0
rule2=2,70,chisel:brownstone-1,chisel:brownstone-1,chisel:brownstone-1,chisel:brownstone-1,chisel:brownstone-1,chisel:brownstone-0,iron_bars-0,iron_bars-0,iron_bars-0,iron_bars-0
rule3=0,100,preserveBlock

layer
3,3,3,3,3,3,3,3,3,3,3,3
3,1,1,3,1,3,3,1,3,1,1,3
3,1,1,3,3,3,3,3,3,1,1,3
3,3,3,3,3,3,3,3,3,3,3,3
3,1,3,3,1,3,3,1,3,3,1,3
3,3,3,3,3,3,3,3,3,3,3,3
3,3,3,3,3,3,3,3,3,3,3,3
3,1,3,3,1,3,3,1,3,3,1,3
3,3,3,3,3,3,3,3,3,3,3,3
3,1,1,3,3,3,3,3,3,1,1,3
3,1,1,3,1,3,3,1,3,1,1,3
3,3,3,3,3,3,3,3,3,3,3,3
endlayer

layer
3,3,3,3,3,3,3,3,3,3,3,3
3,1,1,3,1,3,3,1,3,1,1,3
3,1,1,3,3,3,3,3,3,1,1,3
3,3,3,3,3,3,3,3,3,3,3,3
3,1,3,3,1,3,3,1,3,3,1,3
3,3,3,3,3,3,3,3,3,3,3,3
3,3,3,3,3,3,3,3,3,3,3,3
3,1,3,3,1,3,3,1,3,3,1,3
3,3,3,3,3,3,3,3,3,3,3,3
3,1,1,3,3,3,3,3,3,1,1,3
3,1,1,3,1,3,3,1,3,1,1,3
3,3,3,3,3,3,3,3,3,3,3,3
endlayer

layer
3,3,3,3,3,3,3,3,3,3,3,3
3,1,1,3,1,3,3,1,3,1,1,3
3,1,1,3,3,3,3,3,3,1,1,3
3,3,3,3,3,3,3,3,3,3,3,3
3,1,3,3,1,3,3,1,3,3,1,3
3,3,3,3,3,3,3,3,3,3,3,3
3,3,3,3,3,3,3,3,3,3,3,3
3,1,3,3,1,3,3,1,3,3,1,3
3,3,3,3,3,3,3,3,3,3,3,3
3,1,1,3,3,3,3,3,3,1,1,3
3,1,1,3,1,3,3,1,3,1,1,3
3,3,3,3,3,3,3,3,3,3,3,3
endlayer

layer
3,3,3,3,3,3,3,3,3,3,3,3
3,1,1,3,1,3,3,1,3,1,1,3
3,1,1,3,3,3,3,3,3,1,1,3
3,3,3,3,3,3,3,3,3,3,3,3
3,1,3,3,1,3,3,1,3,3,1,3
3,3,3,3,3,3,3,3,3,3,3,3
3,3,3,3,3,3,3,3,3,3,3,3
3,1,3,3,1,3,3,1,3,3,1,3
3,3,3,3,3,3,3,3,3,3,3,3
3,1,1,3,3,3,3,3,3,1,1,3
3,1,1,3,1,3,3,1,3,1,1,3
3,3,3,3,3,3,3,3,3,3,3,3
endlayer

layer
3,3,3,3,3,3,3,3,3,3,3,3
3,1,1,3,1,3,3,1,3,1,1,3
3,1,1,3,3,3,3,3,3,1,1,3
3,3,3,3,3,3,3,3,3,3,3,3
3,1,3,3,1,3,3,1,3,3,1,3
3,3,3,3,3,3,3,3,3,3,3,3
3,3,3,3,3,3,3,3,3,3,3,3
3,1,3,3,1,3,3,1,3,3,1,3
3,3,3,3,3,3,3,3,3,3,3,3
3,1,1,3,3,3,3,3,3,1,1,3
3,1,1,3,1,3,3,1,3,1,1,3
3,3,3,3,3,3,3,3,3,3,3,3
endlayer

layer
0,0,0,0,0,0,0,0,0,0,0,0
0,1,1,0,1,0,0,1,0,1,1,0
0,1,1,0,0,0,0,0,0,1,1,0
0,0,0,0,0,0,0,0,0,0,0,0
0,1,0,0,1,0,0,1,0,0,1,0
0,0,0,0,0,0,0,0,0,0,0,0
0,0,0,0,0,0,0,0,0,0,0,0
0,1,0,0,1,0,0,1,0,0,1,0
0,0,0,0,0,0,0,0,0,0,0,0
0,1,1,0,0,0,0,0,0,1,1,0
0,1,1,0,1,0,0,1,0,1,1,0
0,0,0,0,0,0,0,0,0,0,0,0
endlayer

layer
0,0,0,0,0,0,0,0,0,0,0,0
0,1,1,0,1,0,0,1,0,1,1,0
0,1,1,0,0,0,0,0,0,1,1,0
0,0,0,0,0,0,0,0,0,0,0,0
0,1,0,0,1,0,0,1,0,0,1,0
0,0,0,0,0,0,0,0,0,0,0,0
0,0,0,0,0,0,0,0,0,0,0,0
0,1,0,0,1,0,0,1,0,0,1,0
0,0,0,0,0,0,0,0,0,0,0,0
0,1,1,0,0,0,0,0,0,1,1,0
0,1,1,0,1,0,0,1,0,1,1,0
0,0,0,0,0,0,0,0,0,0,0,0
endlayer

layer
0,0,0,0,0,0,0,0,0,0,0,0
0,1,1,0,1,2,2,1,0,1,1,0
0,1,1,0,0,0,0,0,0,1,1,0
0,0,0,0,0,0,0,0,0,0,0,0
0,1,0,0,1,2,2,1,0,0,1,0
0,2,0,0,0,0,0,0,0,0,2,0
0,2,0,0,0,0,0,0,0,0,2,0
0,1,0,0,1,2,2,1,0,0,1,0
0,0,0,0,0,0,0,0,0,0,0,0
0,1,1,0,0,0,0,0,0,1,1,0
0,1,1,0,1,2,2,1,0,1,1,0
0,0,0,0,0,0,0,0,0,0,0,0
endlayer

layer
0,0,0,0,0,0,0,0,0,0,0,0
0,1,1,0,0,0,0,0,0,1,1,0
0,1,1,0,0,0,0,0,0,1,1,0
0,0,0,0,0,0,0,0,0,0,0,0
0,0,0,0,1,0,0,1,0,0,0,0
0,0,0,0,2,0,0,2,0,0,0,0
0,0,0,0,2,0,0,2,0,0,0,0
0,0,0,0,1,0,0,1,0,0,0,0
0,0,0,0,0,0,0,0,0,0,0,0
0,1,1,0,0,0,0,0,0,1,1,0
0,1,1,0,0,0,0,0,0,1,1,0
0,0,0,0,0,0,0,0,0,0,0,0
endlayer

layer
0,0,0,0,0,0,0,0,0,0,0,0
0,0,0,0,0,0,0,0,0,0,0,0
0,1,1,0,0,0,0,0,0,1,1,0
0,2,2,0,0,0,0,0,0,2,2,0
0,2,2,0,0,0,0,0,0,2,2,0
0,2,2,0,1,2,2,1,0,2,2,0
0,2,2,0,1,2,2,1,0,2,2,0
0,2,2,0,0,0,0,0,0,2,2,0
0,2,2,0,0,0,0,0,0,2,2,0
0,1,1,0,0,0,0,0,0,1,1,0
0,0,0,0,0,0,0,0,0,0,0,0
0,0,0,0,0,0,0,0,0,0,0,0
endlayer
