weight=5
dimensionsToSpawnIn=overworld
embed_into_distance=8
random_height_offset=0,0
unacceptable_target_blocks=flowing_water,water,flowing_lava,lava,ice,packed_ice,stained_hardened_clay-9,brick_block,double_stone_slab,stonebrick,red_sandstone,red_nether_brick,red_mushroom_block,brown_mushroom_block,planks,cobblestone,end_stone,obsidian,purpur_block,iron_bars,purpur_slab,purpur_pillar,netherrack,soul_sand,quartz_ore,stained_glass,glass
dimensions=29,23,23
allowable_overhang=0
max_leveling=7
leveling_buffer=-1
preventRotation=0
preserve_water=0
preserve_lava=0
uniqueMinDistance=5000
spawnMinDistance=0
spawnMaxDistance=0

rule1=0,100,preserveBlock
rule2=0,100,chisel:brownstone-1,chisel:brownstone-1,chisel:brownstone-1,chisel:brownstone-1,chisel:brownstone-0
rule3=0,100,minecraft:monster_egg-4,monster_egg-2,monster_egg-2,monster_egg-2,monster_egg-3,stonebrick-2,stonebrick-1,stonebrick-0,stonebrick-0,stonebrick-0,stonebrick-2,stonebrick-1,stonebrick-0,stonebrick-0,preserveBlock
rule4=0,100,minecraft:water-0,minecraft:water-0,chisel:limestone2-7
rule5=0,100,minecraft:air
rule6=0,100,chisel:brownstone-1,chisel:brownstone-1,chisel:brownstone-1,chisel:brownstone-1,chisel:brownstone-0,minecraft:iron_bars-0,minecraft:iron_bars-0,minecraft:iron_bars-0,minecraft:iron_bars-0,preserveBlock,preserveBlock,preserveBlock,preserveBlock
rule7=0,100,chisel:factory-1
rule8=0,100,minecraft:cobblestone_wall-0,minecraft:cobblestone_wall-1
rule9=0,100,chisel:technical1-0
rule10=0,100,minecraft:vine-8
rule11=0,100,minecraft:vine-2
rule12=0,100,minecraft:vine-4
rule13=0,100,minecraft:vine-1
rule14=0,100,minecraft:vine-12
rule15=0,100,minecraft:vine-9
rule16=0,100,minecraft:vine-6
rule17=0,100,minecraft:vine-3

layer
1,1,1,1,1,1,1,1,3,3,3,3,3,3,3,1,1,1,1,1,1,1,1
1,1,1,1,1,1,3,3,3,3,3,3,3,3,3,3,3,1,1,1,1,1,1
1,1,1,1,3,3,3,3,3,3,3,3,3,3,3,3,3,3,3,1,1,1,1
1,1,1,3,3,3,3,3,3,3,3,3,3,3,3,3,3,3,3,3,1,1,1
1,1,3,3,3,3,3,3,3,3,3,3,3,3,3,3,3,3,3,3,3,1,1
1,1,3,3,3,3,3,3,3,3,3,3,3,3,3,3,3,3,3,3,3,1,1
1,3,3,3,3,3,3,3,3,3,3,3,3,3,3,3,3,3,3,3,3,3,1
1,3,3,3,3,3,3,3,3,3,3,3,3,3,3,3,3,3,3,3,3,3,1
3,3,3,3,3,3,3,3,3,3,3,3,3,3,3,3,3,3,3,3,3,3,3
3,3,3,3,3,3,3,3,3,3,3,3,3,3,3,3,3,3,3,3,3,3,3
3,3,3,3,3,3,3,3,3,3,3,3,3,3,3,3,3,3,3,3,3,3,3
3,3,3,3,3,3,3,3,3,3,3,3,3,3,3,3,3,3,3,3,3,3,3
3,3,3,3,3,3,3,3,3,3,3,3,3,3,3,3,3,3,3,3,3,3,3
3,3,3,3,3,3,3,3,3,3,3,3,3,3,3,3,3,3,3,3,3,3,3
3,3,3,3,3,3,3,3,3,3,3,3,3,3,3,3,3,3,3,3,3,3,3
1,3,3,3,3,3,3,3,3,3,3,3,3,3,3,3,3,3,3,3,3,3,1
1,3,3,3,3,3,3,3,3,3,3,3,3,3,3,3,3,3,3,3,3,3,1
1,1,3,3,3,3,3,3,3,3,3,3,3,3,3,3,3,3,3,3,3,1,1
1,1,3,3,3,3,3,3,3,3,3,3,3,3,3,3,3,3,3,3,3,1,1
1,1,1,3,3,3,3,3,3,3,3,3,3,3,3,3,3,3,3,3,1,1,1
1,1,1,1,3,3,3,3,3,3,3,3,3,3,3,3,3,3,3,1,1,1,1
1,1,1,1,1,1,3,3,3,3,3,3,3,3,3,3,3,1,1,1,1,1,1
1,1,1,1,1,1,1,1,3,3,3,3,3,3,3,1,1,1,1,1,1,1,1
endlayer

layer
1,1,1,1,1,1,1,1,3,3,3,3,3,3,3,1,1,1,1,1,1,1,1
1,1,1,1,1,1,3,3,3,3,3,3,3,3,3,3,3,1,1,1,1,1,1
1,1,1,1,3,3,3,3,3,3,3,3,3,3,3,3,3,3,3,1,1,1,1
1,1,1,3,3,3,3,3,3,3,3,3,3,3,3,3,3,3,3,3,1,1,1
1,1,3,3,3,3,3,3,3,3,3,3,3,3,3,3,3,3,3,3,3,1,1
1,1,3,3,3,3,3,3,3,3,3,3,3,3,3,3,3,3,3,3,3,1,1
1,3,3,3,3,3,3,3,3,3,3,3,3,3,3,3,3,3,3,3,3,3,1
1,3,3,3,3,3,3,3,3,3,3,3,3,3,3,3,3,3,3,3,3,3,1
3,3,3,3,3,3,3,3,3,3,3,3,3,3,3,3,3,3,3,3,3,3,3
3,3,3,3,3,3,3,3,3,3,3,3,3,3,3,3,3,3,3,3,3,3,3
3,3,3,3,3,3,3,3,3,3,3,3,3,3,3,3,3,3,3,3,3,3,3
3,3,3,3,3,3,3,3,3,3,3,3,3,3,3,3,3,3,3,3,3,3,3
3,3,3,3,3,3,3,3,3,3,3,3,3,3,3,3,3,3,3,3,3,3,3
3,3,3,3,3,3,3,3,3,3,3,3,3,3,3,3,3,3,3,3,3,3,3
3,3,3,3,3,3,3,3,3,3,3,3,3,3,3,3,3,3,3,3,3,3,3
1,3,3,3,3,3,3,3,3,3,3,3,3,3,3,3,3,3,3,3,3,3,1
1,3,3,3,3,3,3,3,3,3,3,3,3,3,3,3,3,3,3,3,3,3,1
1,1,3,3,3,3,3,3,3,3,3,3,3,3,3,3,3,3,3,3,3,1,1
1,1,3,3,3,3,3,3,3,3,3,3,3,3,3,3,3,3,3,3,3,1,1
1,1,1,3,3,3,3,3,3,3,3,3,3,3,3,3,3,3,3,3,1,1,1
1,1,1,1,3,3,3,3,3,3,3,3,3,3,3,3,3,3,3,1,1,1,1
1,1,1,1,1,1,3,3,3,3,3,3,3,3,3,3,3,1,1,1,1,1,1
1,1,1,1,1,1,1,1,3,3,3,3,3,3,3,1,1,1,1,1,1,1,1
endlayer

layer
1,1,1,1,1,1,1,1,3,3,3,3,3,3,3,1,1,1,1,1,1,1,1
1,1,1,1,1,1,3,3,3,3,3,3,3,3,3,3,3,1,1,1,1,1,1
1,1,1,1,3,3,3,3,3,3,3,3,3,3,3,3,3,3,3,1,1,1,1
1,1,1,3,3,3,3,3,3,3,3,3,3,3,3,3,3,3,3,3,1,1,1
1,1,3,3,3,3,3,3,3,3,3,3,3,3,3,3,3,3,3,3,3,1,1
1,1,3,3,3,3,3,3,3,3,3,3,3,3,3,3,3,3,3,3,3,1,1
1,3,3,3,3,3,3,3,3,3,3,3,3,3,3,3,3,3,3,3,3,3,1
1,3,3,3,3,3,3,3,3,3,3,3,3,3,3,3,3,3,3,3,3,3,1
3,3,3,3,3,3,3,3,3,3,3,3,3,3,3,3,3,3,3,3,3,3,3
3,3,3,3,3,3,3,3,3,3,3,3,3,3,3,3,3,3,3,3,3,3,3
3,3,3,3,3,3,3,3,3,3,3,3,3,3,3,3,3,3,3,3,3,3,3
3,3,3,3,3,3,3,3,3,3,3,3,3,3,3,3,3,3,3,3,3,3,3
3,3,3,3,3,3,3,3,3,3,3,3,3,3,3,3,3,3,3,3,3,3,3
3,3,3,3,3,3,3,3,3,3,3,3,3,3,3,3,3,3,3,3,3,3,3
3,3,3,3,3,3,3,3,3,3,3,3,3,3,3,3,3,3,3,3,3,3,3
1,3,3,3,3,3,3,3,3,3,3,3,3,3,3,3,3,3,3,3,3,3,1
1,3,3,3,3,3,3,3,3,3,3,3,3,3,3,3,3,3,3,3,3,3,1
1,1,3,3,3,3,3,3,3,3,3,3,3,3,3,3,3,3,3,3,3,1,1
1,1,3,3,3,3,3,3,3,3,3,3,3,3,3,3,3,3,3,3,3,1,1
1,1,1,3,3,3,3,3,3,3,3,3,3,3,3,3,3,3,3,3,1,1,1
1,1,1,1,3,3,3,3,3,3,3,3,3,3,3,3,3,3,3,1,1,1,1
1,1,1,1,1,1,3,3,3,3,3,3,3,3,3,3,3,1,1,1,1,1,1
1,1,1,1,1,1,1,1,3,3,3,3,3,3,3,1,1,1,1,1,1,1,1
endlayer

layer
1,1,1,1,1,1,1,1,3,3,3,3,3,3,3,1,1,1,1,1,1,1,1
1,1,1,1,1,1,3,3,3,3,3,3,3,3,3,3,3,1,1,1,1,1,1
1,1,1,1,3,3,3,3,3,3,3,3,3,3,3,3,3,3,3,1,1,1,1
1,1,1,3,3,3,3,3,3,3,3,3,3,3,3,3,3,3,3,3,1,1,1
1,1,3,3,3,3,3,3,3,3,3,3,3,3,3,3,3,3,3,3,3,1,1
1,1,3,3,3,3,3,3,3,3,3,3,3,3,3,3,3,3,3,3,3,1,1
1,3,3,3,3,3,3,3,3,3,3,3,3,3,3,3,3,3,3,3,3,3,1
1,3,3,3,3,3,3,3,3,3,3,3,3,3,3,3,3,3,3,3,3,3,1
3,3,3,3,3,3,3,3,3,3,3,3,3,3,3,3,3,3,3,3,3,3,3
3,3,3,3,3,3,3,3,3,3,3,3,3,3,3,3,3,3,3,3,3,3,3
3,3,3,3,3,3,3,3,3,3,3,3,3,3,3,3,3,3,3,3,3,3,3
3,3,3,3,3,3,3,3,3,3,3,3,3,3,3,3,3,3,3,3,3,3,3
3,3,3,3,3,3,3,3,3,3,3,3,3,3,3,3,3,3,3,3,3,3,3
3,3,3,3,3,3,3,3,3,3,3,3,3,3,3,3,3,3,3,3,3,3,3
3,3,3,3,3,3,3,3,3,3,3,3,3,3,3,3,3,3,3,3,3,3,3
1,3,3,3,3,3,3,3,3,3,3,3,3,3,3,3,3,3,3,3,3,3,1
1,3,3,3,3,3,3,3,3,3,3,3,3,3,3,3,3,3,3,3,3,3,1
1,1,3,3,3,3,3,3,3,3,3,3,3,3,3,3,3,3,3,3,3,1,1
1,1,3,3,3,3,3,3,3,3,3,3,3,3,3,3,3,3,3,3,3,1,1
1,1,1,3,3,3,3,3,3,3,3,3,3,3,3,3,3,3,3,3,1,1,1
1,1,1,1,3,3,3,3,3,3,3,3,3,3,3,3,3,3,3,1,1,1,1
1,1,1,1,1,1,3,3,3,3,3,3,3,3,3,3,3,1,1,1,1,1,1
1,1,1,1,1,1,1,1,3,3,3,3,3,3,3,1,1,1,1,1,1,1,1
endlayer

layer
1,1,1,1,1,1,1,1,3,3,3,3,3,3,3,1,1,1,1,1,1,1,1
1,1,1,1,1,1,3,3,3,3,3,3,3,3,3,3,3,1,1,1,1,1,1
1,1,1,1,3,3,3,3,3,3,3,3,3,3,3,3,3,3,3,1,1,1,1
1,1,1,3,3,3,3,3,3,3,3,3,3,3,3,3,3,3,3,3,1,1,1
1,1,3,3,3,3,3,3,3,3,3,3,3,3,3,3,3,3,3,3,3,1,1
1,1,3,3,3,3,3,3,3,3,3,3,3,3,3,3,3,3,3,3,3,1,1
1,3,3,3,3,3,3,3,3,3,3,3,3,3,3,3,3,3,3,3,3,3,1
1,3,3,3,3,3,3,3,3,3,3,3,3,3,3,3,3,3,3,3,3,3,1
3,3,3,3,3,3,3,3,3,3,3,3,3,3,3,3,3,3,3,3,3,3,3
3,3,3,3,3,3,3,3,3,3,3,3,3,3,3,3,3,3,3,3,3,3,3
3,3,3,3,3,3,3,3,3,3,3,3,3,3,3,3,3,3,3,3,3,3,3
3,3,3,3,3,3,3,3,3,3,3,3,3,3,3,3,3,3,3,3,3,3,3
3,3,3,3,3,3,3,3,3,3,3,3,3,3,3,3,3,3,3,3,3,3,3
3,3,3,3,3,3,3,3,3,3,3,3,3,3,3,3,3,3,3,3,3,3,3
3,3,3,3,3,3,3,3,3,3,3,3,3,3,3,3,3,3,3,3,3,3,3
1,3,3,3,3,3,3,3,3,3,3,3,3,3,3,3,3,3,3,3,3,3,1
1,3,3,3,3,3,3,3,3,3,3,3,3,3,3,3,3,3,3,3,3,3,1
1,1,3,3,3,3,3,3,3,3,3,3,3,3,3,3,3,3,3,3,3,1,1
1,1,3,3,3,3,3,3,3,3,3,3,3,3,3,3,3,3,3,3,3,1,1
1,1,1,3,3,3,3,3,3,3,3,3,3,3,3,3,3,3,3,3,1,1,1
1,1,1,1,3,3,3,3,3,3,3,3,3,3,3,3,3,3,3,1,1,1,1
1,1,1,1,1,1,3,3,3,3,3,3,3,3,3,3,3,1,1,1,1,1,1
1,1,1,1,1,1,1,1,3,3,3,3,3,3,3,1,1,1,1,1,1,1,1
endlayer

layer
1,1,1,1,1,1,1,1,2,2,2,2,2,2,2,1,1,1,1,1,1,1,1
1,1,1,1,1,1,2,2,3,3,3,3,3,3,3,2,2,1,1,1,1,1,1
1,1,1,1,2,2,3,3,3,3,3,3,3,3,3,3,3,2,2,1,1,1,1
1,1,1,2,3,3,3,3,3,3,3,3,3,3,3,3,3,3,3,2,1,1,1
1,1,2,3,3,3,3,3,3,3,3,3,3,3,3,3,3,3,3,3,2,1,1
1,1,2,3,3,3,3,3,3,3,3,3,3,3,3,3,3,3,3,3,2,1,1
1,2,3,3,3,3,3,3,3,3,3,3,3,3,3,3,3,3,3,3,3,2,1
1,2,3,3,3,3,3,3,3,3,3,3,3,3,3,3,3,3,3,3,3,2,1
2,3,3,3,3,3,3,3,4,4,4,4,4,4,4,3,3,3,3,3,3,3,2
2,3,3,3,3,3,3,3,4,4,4,4,4,4,4,3,3,3,3,3,3,3,2
2,3,3,3,3,3,3,3,4,4,4,4,4,4,4,3,3,3,3,3,3,3,2
2,3,3,3,3,3,3,3,4,4,4,4,4,4,4,3,3,3,3,3,3,3,2
2,3,3,3,3,3,3,3,4,4,4,4,4,4,4,3,3,3,3,3,3,3,2
2,3,3,3,3,3,3,3,4,4,4,4,4,4,4,3,3,3,3,3,3,3,2
2,3,3,3,3,3,3,3,4,4,4,4,4,4,4,3,3,3,3,3,3,3,2
1,2,3,3,3,3,3,3,3,3,3,3,3,3,3,3,3,3,3,3,3,2,1
1,2,3,3,3,3,3,3,3,3,3,3,3,3,3,3,3,3,3,3,3,2,1
1,1,2,3,3,3,3,3,3,3,3,3,3,3,3,3,3,3,3,3,2,1,1
1,1,2,3,3,3,3,3,3,3,3,3,3,3,3,3,3,3,3,3,2,1,1
1,1,1,2,3,3,3,3,3,3,3,3,3,3,3,3,3,3,3,2,1,1,1
1,1,1,1,2,2,3,3,3,3,3,3,3,3,3,3,3,2,2,1,1,1,1
1,1,1,1,1,1,2,2,3,3,3,3,3,3,3,2,2,1,1,1,1,1,1
1,1,1,1,1,1,1,1,2,2,2,2,2,2,2,1,1,1,1,1,1,1,1
endlayer

layer
1,1,1,1,1,1,1,1,2,2,2,2,2,2,2,1,1,1,1,1,1,1,1
1,1,1,1,1,1,2,2,3,3,3,3,3,3,3,2,2,1,1,1,1,1,1
1,1,1,1,2,2,3,3,3,3,3,3,3,3,3,3,3,2,2,1,1,1,1
1,1,1,2,3,3,3,3,3,3,3,3,3,3,3,3,3,3,3,2,1,1,1
1,1,2,3,3,3,3,3,3,3,3,3,3,3,3,3,3,3,3,3,2,1,1
1,1,2,3,3,3,3,3,3,3,3,3,3,3,3,3,3,3,3,3,2,1,1
1,2,3,3,3,3,3,3,3,3,3,3,3,3,3,3,3,3,3,3,3,2,1
1,2,3,3,3,3,3,3,3,3,3,3,3,3,3,3,3,3,3,3,3,2,1
2,3,3,3,3,3,3,3,5,6,6,5,5,6,5,3,3,3,3,3,3,3,2
2,3,3,3,3,3,3,3,6,5,5,5,6,5,5,3,3,3,3,3,3,3,2
2,3,3,3,3,3,3,3,5,6,5,6,5,5,6,3,3,3,3,3,3,3,2
2,3,3,3,3,3,3,3,6,5,6,5,6,6,6,3,3,3,3,3,3,3,2
2,3,3,3,3,3,3,3,6,6,6,6,6,6,5,3,3,3,3,3,3,3,2
2,3,3,3,3,3,3,3,6,6,6,6,6,5,6,3,3,3,3,3,3,3,2
2,3,3,3,3,3,3,3,6,6,6,6,6,5,6,3,3,3,3,3,3,3,2
1,2,3,3,3,3,3,3,3,3,3,3,3,3,3,3,3,3,3,3,3,2,1
1,2,3,3,3,3,3,3,3,3,3,3,3,3,3,3,3,3,3,3,3,2,1
1,1,2,3,3,3,3,3,3,3,3,3,3,3,3,3,3,3,3,3,2,1,1
1,1,2,3,3,3,3,3,3,3,3,3,3,3,3,3,3,3,3,3,2,1,1
1,1,1,2,3,3,3,3,3,3,3,3,3,3,3,3,3,3,3,2,1,1,1
1,1,1,1,2,2,3,3,3,3,3,3,3,3,3,3,3,2,2,1,1,1,1
1,1,1,1,1,1,2,2,3,3,3,3,3,3,3,2,2,1,1,1,1,1,1
1,1,1,1,1,1,1,1,2,2,2,2,2,2,2,1,1,1,1,1,1,1,1
endlayer

layer
1,1,1,1,1,1,1,1,2,2,2,2,2,2,2,1,1,1,1,1,1,1,1
1,1,1,1,1,1,2,2,3,3,3,7,3,3,3,2,2,1,1,1,1,1,1
1,1,1,1,2,2,3,3,3,3,3,3,3,3,3,3,3,2,2,1,1,1,1
1,1,1,2,3,3,3,3,3,3,3,3,3,3,3,3,3,3,3,2,1,1,1
1,1,2,3,3,3,3,3,3,3,3,3,3,3,3,3,3,3,3,3,2,1,1
1,1,2,3,3,3,3,3,3,3,3,3,3,3,3,3,3,3,3,3,2,1,1
1,2,3,3,3,3,3,3,3,3,3,3,3,3,3,3,3,3,3,3,3,2,1
1,2,3,3,3,3,3,3,3,3,3,3,3,3,3,3,3,3,3,3,3,2,1
2,3,3,3,3,3,3,3,5,5,5,5,5,5,5,3,3,3,3,3,3,3,2
2,3,3,3,3,3,3,3,5,5,5,5,5,5,5,3,3,3,3,3,3,3,2
2,3,3,3,3,3,3,3,5,5,5,5,5,5,5,3,3,3,3,3,3,3,2
2,7,3,3,3,3,3,3,5,5,5,5,5,5,5,3,3,3,3,3,3,7,2
2,3,3,3,3,3,3,3,6,6,6,5,5,5,5,3,3,3,3,3,3,3,2
2,3,3,3,3,3,3,3,6,6,6,6,5,5,5,3,3,3,3,3,3,3,2
2,3,3,3,3,3,3,3,6,6,6,6,5,5,5,3,3,3,3,3,3,3,2
1,2,3,3,3,3,3,3,3,3,3,3,3,3,3,3,3,3,3,3,3,2,1
1,2,3,3,3,3,3,3,3,3,3,3,3,3,3,3,3,3,3,3,3,2,1
1,1,2,3,3,3,3,3,3,3,3,3,3,3,3,3,3,3,3,3,2,1,1
1,1,2,3,3,3,3,3,3,3,3,3,3,3,3,3,3,3,3,3,2,1,1
1,1,1,2,3,3,3,3,3,3,3,3,3,3,3,3,3,3,3,2,1,1,1
1,1,1,1,2,2,3,3,3,3,3,3,3,3,3,3,3,2,2,1,1,1,1
1,1,1,1,1,1,2,2,3,3,3,7,3,3,3,2,2,1,1,1,1,1,1
1,1,1,1,1,1,1,1,2,2,2,2,2,2,2,1,1,1,1,1,1,1,1
endlayer

layer
1,1,1,1,1,1,1,1,8,1,1,8,1,1,8,1,1,1,1,1,1,1,1
1,1,1,1,1,1,8,1,9,9,9,7,9,9,9,1,8,1,1,1,1,1,1
1,1,1,1,8,1,9,9,1,1,1,7,1,1,1,9,9,1,8,1,1,1,1
1,1,1,1,9,9,1,1,6,1,1,7,6,1,1,1,1,9,9,1,1,1,1
1,1,8,9,1,6,6,6,6,6,6,7,6,6,1,1,1,1,1,9,8,1,1
1,1,1,9,6,6,6,6,6,1,6,7,6,6,1,6,1,1,1,9,1,1,1
1,8,9,1,6,6,6,6,6,6,1,7,6,6,6,1,1,6,6,1,9,8,1
1,1,9,1,1,6,6,6,6,1,1,6,1,1,1,1,6,6,1,1,9,1,1
8,9,1,6,6,6,6,6,1,1,1,1,1,1,1,1,6,6,1,1,1,9,8
1,9,6,6,6,6,6,6,1,1,1,1,1,1,1,1,6,1,6,1,1,9,1
1,9,6,6,6,6,6,6,1,1,1,1,1,1,1,1,1,1,1,1,1,9,1
8,7,7,7,7,7,7,1,1,1,1,1,1,1,1,1,7,7,7,7,7,7,8
1,9,6,1,6,6,6,6,1,1,1,1,1,1,1,1,1,1,1,1,1,9,1
1,9,1,6,6,6,6,6,6,6,6,1,1,1,1,1,1,1,1,1,1,9,1
8,9,1,1,6,6,6,6,6,6,1,1,1,1,1,1,1,1,1,1,1,9,8
1,1,9,1,1,6,6,6,6,6,1,1,1,1,1,1,1,1,1,1,9,1,1
1,8,9,6,1,6,6,6,6,6,1,7,1,1,1,1,1,1,1,1,9,8,1
1,1,1,9,1,1,1,6,6,6,1,7,1,1,1,1,1,1,1,9,1,1,1
1,1,8,9,10,10,1,6,6,6,1,7,1,1,1,1,1,1,1,9,8,1,1
1,1,1,1,9,9,1,6,1,1,1,7,1,1,1,1,1,9,9,1,1,1,1
1,1,1,1,8,1,9,9,1,10,10,7,1,1,1,9,9,1,8,1,1,1,1
1,1,1,1,1,1,8,1,9,9,9,7,9,9,9,1,8,1,1,1,1,1,1
1,1,1,1,1,1,1,1,8,1,1,8,1,1,8,11,1,1,1,1,1,1,1
endlayer

layer
1,1,1,1,1,1,1,1,8,1,1,8,1,1,8,1,1,1,1,1,1,1,1
1,1,1,1,1,1,8,1,9,9,9,9,9,9,9,1,8,1,1,1,1,1,1
1,1,1,1,8,1,9,9,1,1,1,1,1,1,1,9,9,1,8,1,1,1,1
1,1,1,1,9,9,1,1,1,1,1,1,1,1,1,1,1,9,9,1,1,1,1
1,1,8,9,1,1,1,1,1,1,1,1,1,1,1,1,1,1,1,9,8,1,1
1,1,1,9,1,1,1,1,1,1,1,1,1,1,1,1,1,1,1,9,1,1,1
1,8,9,1,1,1,1,1,1,1,1,7,1,1,1,1,1,1,1,1,9,8,1
1,1,9,1,1,1,1,1,1,1,1,1,1,1,1,1,1,1,1,1,9,1,1
8,1,1,1,1,1,1,1,1,1,1,1,1,1,1,1,1,1,1,1,1,9,8
1,9,1,1,1,1,1,1,1,1,1,1,1,1,1,1,1,1,1,1,1,9,1
1,9,1,1,1,1,1,1,1,1,1,1,1,1,1,1,1,1,1,1,12,9,1
8,9,13,1,1,1,7,7,1,1,1,1,1,1,7,7,7,1,1,1,12,9,8
1,9,13,1,1,1,1,1,1,1,1,1,1,1,1,1,1,1,1,1,1,9,1
1,9,13,1,1,1,1,1,1,1,1,1,1,1,1,1,1,1,1,1,1,9,1
8,9,1,1,1,1,1,1,1,1,1,1,1,1,1,1,1,1,1,1,1,9,8
1,1,9,1,1,1,1,1,1,1,1,1,1,1,1,1,1,1,1,1,9,1,1
1,8,9,1,1,1,1,1,1,1,1,7,1,1,1,1,1,1,1,14,9,8,1
1,1,1,9,13,1,1,1,1,1,1,1,1,1,1,1,1,1,12,9,1,1,1
1,1,8,9,15,1,1,1,1,1,1,1,1,1,1,1,1,1,1,9,8,1,1
1,1,1,1,9,9,1,1,1,1,1,1,1,1,1,1,1,9,9,1,1,1,1
1,1,1,1,8,1,9,9,10,10,1,1,1,1,1,9,9,1,8,1,1,1,1
1,1,1,1,1,1,8,1,9,9,9,9,9,9,9,1,8,1,1,1,1,1,1
1,1,1,1,1,1,1,1,8,1,1,8,1,1,8,11,11,1,1,1,1,1,1
endlayer

layer
1,1,1,1,1,1,1,1,2,2,2,2,2,2,2,1,1,1,1,1,1,1,1
1,1,1,1,1,1,2,2,1,1,1,1,1,1,1,2,2,1,1,1,1,1,1
1,1,1,1,2,2,1,1,1,1,1,1,1,1,11,1,1,2,2,1,1,1,1
1,1,1,1,1,1,1,1,1,1,1,1,1,1,1,11,1,1,1,2,1,1,1
1,1,1,1,1,1,1,1,1,1,1,1,1,1,1,1,1,1,1,1,2,1,1
1,1,1,1,1,1,1,1,1,1,1,1,1,1,1,1,1,1,1,1,2,1,1
1,1,1,1,1,1,1,1,1,1,1,1,1,1,1,1,1,1,1,1,1,2,1
1,2,1,1,1,1,1,1,1,1,1,1,1,1,1,1,1,1,1,1,1,2,1
2,1,1,1,1,1,1,1,1,1,1,1,1,1,1,1,1,1,1,1,1,1,2
2,1,1,1,1,1,1,1,1,1,1,1,1,1,1,1,1,1,1,1,1,1,2
2,1,1,1,1,1,1,1,1,1,1,1,1,1,1,1,1,1,1,1,1,1,2
2,1,1,1,1,1,1,1,1,1,1,1,1,1,1,1,1,1,1,1,1,1,2
2,1,1,1,1,1,1,1,1,1,1,1,1,1,1,1,1,1,1,1,1,1,2
2,1,1,1,1,1,1,1,1,1,1,1,1,1,1,1,1,1,1,1,1,1,2
2,1,1,1,1,1,1,1,1,1,1,1,1,1,1,1,1,1,1,1,1,1,2
1,2,1,1,1,1,1,1,1,1,1,1,1,1,1,1,1,1,1,1,1,2,1
1,2,1,1,1,1,1,1,1,1,1,1,1,1,1,1,1,1,1,10,1,2,1
1,1,2,1,1,1,1,1,1,1,1,1,1,1,1,1,1,1,1,1,2,1,1
1,1,2,1,15,1,1,1,1,1,1,1,1,1,1,1,1,1,1,1,2,1,1
1,1,1,2,1,1,1,1,1,1,1,1,1,1,1,1,1,1,1,2,1,1,1
1,1,1,1,2,2,1,1,1,1,1,1,1,1,1,1,1,2,2,1,1,1,1
1,1,1,1,1,1,2,2,1,1,1,1,1,1,1,2,2,1,1,1,1,1,1
1,1,1,1,1,1,1,1,2,2,2,2,2,2,2,11,11,1,1,1,1,1,1
endlayer

layer
1,1,1,1,1,1,1,1,2,2,2,2,2,2,2,1,1,1,1,1,1,1,1
1,1,1,1,1,1,2,2,1,1,1,1,1,1,1,2,2,1,1,1,1,1,1
1,1,1,1,2,1,1,1,1,1,1,1,1,1,16,11,1,2,2,1,1,1,1
1,1,1,2,1,1,1,1,1,1,1,1,1,1,1,11,1,1,1,2,1,1,1
1,1,1,1,1,1,1,1,1,1,1,1,1,1,1,1,1,1,1,1,2,1,1
1,1,1,1,1,1,1,1,1,1,1,1,1,1,1,1,1,1,1,1,2,1,1
1,2,1,1,1,1,1,1,1,1,1,1,1,1,1,1,1,1,1,1,1,2,1
1,2,1,1,1,1,1,1,1,1,1,1,1,1,1,1,1,1,1,1,1,2,1
2,1,1,1,1,1,1,1,1,1,1,1,1,1,1,1,1,1,1,1,1,1,2
2,1,1,1,1,1,1,1,1,1,1,1,1,1,1,1,1,1,1,1,1,1,2
2,1,1,1,1,1,1,1,1,1,1,1,1,1,1,1,1,1,1,1,1,1,2
2,1,13,1,1,1,1,1,1,1,1,1,1,1,1,1,1,1,1,1,1,1,2
2,1,1,1,1,1,1,1,1,1,1,1,1,1,1,1,1,1,1,1,1,1,2
2,1,1,1,1,1,1,1,1,1,1,1,1,1,1,1,1,1,1,1,1,1,2
2,1,1,1,1,1,1,1,1,1,1,1,1,1,1,1,1,1,1,1,1,1,2
1,2,1,1,1,1,1,1,1,1,1,1,1,1,1,1,1,1,1,1,1,2,1
1,2,1,1,1,1,1,1,1,1,1,1,1,1,1,1,1,1,1,10,1,2,1
1,1,2,1,13,1,1,1,1,1,1,1,1,1,1,1,1,1,12,1,2,1,1
1,1,2,1,15,1,1,1,1,1,1,1,1,1,1,1,1,1,1,1,2,1,1
1,1,1,2,1,1,1,1,1,1,1,1,1,1,1,1,1,1,1,2,1,1,1
1,1,1,1,2,2,1,1,1,1,1,1,1,1,1,1,1,2,2,1,1,1,1
1,1,1,1,1,1,2,2,1,1,1,1,1,1,1,2,2,13,1,1,1,1,1
1,1,1,1,1,1,1,1,2,2,2,2,2,2,2,11,11,1,1,1,1,1,1
endlayer

layer
1,1,1,1,1,1,1,1,10,1,1,9,1,1,1,1,1,1,1,1,1,1,1
1,1,1,1,1,1,1,9,2,2,2,2,2,2,2,9,1,1,1,1,1,1,1
1,1,1,1,1,1,1,1,1,1,1,1,1,1,16,2,2,1,1,1,1,1,1
1,1,1,1,2,2,1,1,1,1,1,1,1,1,1,11,1,2,2,15,1,1,1
1,1,1,1,1,1,1,1,1,1,1,1,1,1,1,1,1,1,1,2,13,1,1
1,1,1,1,1,1,1,1,1,1,1,1,1,1,1,1,1,1,1,2,13,1,1
1,1,1,1,1,1,1,1,1,1,1,1,1,1,1,1,1,1,1,1,2,1,1
1,9,2,1,1,1,1,1,1,1,1,1,1,1,1,1,1,1,1,1,2,9,1
1,2,1,1,1,1,1,1,1,1,1,1,1,1,1,1,1,1,1,1,1,2,1
1,2,1,1,1,1,1,1,1,1,1,1,1,1,1,1,1,1,1,1,12,2,1
10,2,1,1,1,1,1,1,1,1,1,1,1,1,1,1,1,1,1,1,1,2,1
9,2,13,1,1,1,1,1,1,1,1,1,1,1,1,1,1,1,1,1,12,2,9
1,2,1,1,1,1,1,1,1,1,1,1,1,1,1,1,1,1,1,1,1,2,1
1,2,1,1,1,1,1,1,1,1,1,1,1,1,1,1,1,1,1,1,1,2,1
1,2,1,1,1,1,1,1,1,1,1,1,1,1,1,1,1,1,1,1,1,2,1
1,9,2,1,1,1,1,1,1,1,1,1,1,1,1,1,1,1,1,1,2,9,1
1,1,2,1,1,1,1,1,1,1,1,1,1,1,1,1,1,10,1,14,2,1,1
1,1,1,2,13,1,1,1,1,1,1,1,1,1,1,1,1,1,12,2,1,1,1
1,1,1,2,15,1,1,1,1,1,1,1,1,1,1,1,1,1,1,2,1,1,1
1,1,1,1,2,2,1,1,1,1,1,1,1,1,1,1,1,2,2,1,1,1,1
1,1,1,1,1,1,2,2,1,1,1,1,1,1,1,2,2,1,1,1,1,1,1
1,1,1,1,1,1,1,9,2,2,2,2,2,2,2,9,13,1,1,1,1,1,1
1,1,1,1,1,1,1,1,1,1,1,9,1,1,1,11,1,1,1,1,1,1,1
endlayer

layer
1,1,1,1,1,1,1,1,10,10,1,9,1,1,1,1,1,1,1,1,1,1,1
1,1,1,1,1,1,1,9,2,2,2,2,2,2,2,9,1,1,1,1,1,1,1
1,1,1,1,1,1,1,2,1,1,1,1,1,1,16,2,2,1,1,1,1,1,1
1,1,1,1,1,1,1,1,1,1,1,1,11,1,1,1,1,2,2,15,1,1,1
1,1,1,1,1,1,1,1,1,1,1,1,1,1,1,1,1,1,1,2,13,1,1
1,1,1,1,1,1,1,1,1,1,1,1,1,1,1,1,1,1,12,2,1,1,1
1,1,1,1,1,1,1,1,1,1,1,1,1,1,1,1,1,1,1,1,2,1,1
1,9,1,1,1,1,1,1,1,1,1,1,1,1,1,1,1,1,1,1,2,9,1
1,2,1,1,1,1,1,1,1,1,1,1,1,1,1,1,1,1,1,1,1,2,1
1,2,1,1,1,1,1,1,1,1,1,1,1,1,1,1,1,1,1,1,12,2,1
10,2,1,1,1,1,1,1,1,1,1,1,1,1,1,1,1,1,1,1,1,2,1
9,2,13,1,1,1,1,1,1,1,1,1,1,1,1,1,1,1,1,1,12,2,9
1,2,1,1,1,1,1,1,1,1,1,1,1,1,1,1,1,1,1,1,1,2,1
1,2,1,1,1,1,1,1,1,1,1,1,1,1,1,1,1,1,1,1,1,2,1
1,2,1,1,1,1,1,1,1,1,1,1,1,1,1,1,1,1,1,1,1,2,13
1,9,2,1,1,1,1,1,1,1,1,1,1,1,1,1,1,1,1,1,2,9,1
1,1,6,1,1,1,1,1,1,1,1,1,1,1,1,1,1,10,1,12,2,1,1
1,1,1,6,1,1,1,1,1,1,1,1,1,1,1,1,1,1,1,2,1,1,1
1,1,1,6,1,1,1,1,1,1,1,1,1,1,1,1,1,1,1,2,1,1,1
1,1,1,1,2,2,1,1,1,1,1,1,1,1,12,1,1,2,2,1,1,1,1
1,1,1,1,1,1,2,2,1,10,1,1,1,1,1,2,2,1,1,1,1,1,1
1,1,1,1,1,1,1,9,2,2,2,2,2,2,2,9,13,1,1,1,1,1,1
1,1,1,1,1,1,1,1,1,1,1,9,1,1,1,11,1,1,1,1,1,1,1
endlayer

layer
1,1,1,1,1,1,1,1,1,1,1,1,1,1,1,1,1,1,1,1,1,1,1
1,1,1,1,1,1,1,1,1,1,1,9,10,10,1,1,1,1,1,1,1,1,1
1,1,1,1,1,1,1,9,2,2,2,2,2,2,2,9,13,1,1,1,1,1,1
1,1,1,1,1,1,2,1,1,1,1,1,11,1,1,2,2,1,1,1,1,1,1
1,1,1,12,1,1,1,1,1,1,1,1,1,1,1,1,1,2,2,1,1,1,1
1,1,1,1,1,1,1,1,1,1,1,1,1,1,1,1,1,1,2,1,1,1,1
1,1,1,1,1,1,1,1,1,1,1,1,1,1,1,1,1,1,1,2,1,1,1
1,1,9,1,1,1,1,1,1,1,1,1,1,1,1,1,1,1,1,2,9,1,1
1,1,2,1,1,1,1,1,1,1,1,1,1,1,1,1,1,1,1,1,2,1,1
1,1,1,1,1,1,1,1,1,1,1,1,1,1,1,1,1,1,1,1,2,1,1
1,1,2,1,1,1,1,1,1,1,1,1,1,1,1,1,1,1,1,1,2,10,1
1,9,2,1,1,1,1,1,1,1,1,1,1,1,1,1,1,1,1,1,2,9,1
1,1,2,1,1,1,1,1,1,1,1,1,1,1,1,1,1,1,1,1,2,1,1
1,1,2,1,1,1,1,1,1,1,1,1,1,1,1,1,1,1,1,1,2,1,1
1,1,2,1,1,1,1,1,1,1,1,1,1,1,1,1,1,1,1,1,2,1,1
1,1,9,1,1,1,1,1,1,1,1,1,1,1,1,1,1,1,1,2,9,1,1
1,1,1,1,1,1,1,1,1,1,1,1,1,1,1,1,1,10,1,2,1,1,1
1,1,1,1,1,1,1,1,1,1,1,1,1,1,1,1,1,1,2,17,1,1,1
1,1,1,1,1,1,1,1,1,1,1,1,1,1,1,1,1,2,2,13,1,1,1
1,1,1,1,6,6,1,1,1,1,1,1,1,1,12,2,2,1,1,1,1,1,1
1,1,1,1,1,1,6,9,2,2,2,2,2,2,2,9,1,1,1,1,1,1,1
1,1,1,1,1,1,1,1,1,1,16,9,1,1,1,1,1,1,1,1,1,1,1
1,1,1,1,1,1,1,1,1,1,1,1,1,1,1,1,1,1,1,1,1,1,1
endlayer

layer
1,1,1,1,1,1,1,1,1,1,1,1,1,1,1,1,1,1,1,1,1,1,1
1,1,1,1,1,1,1,1,1,1,1,9,10,10,1,1,1,1,1,1,1,1,1
1,1,1,1,1,1,1,9,2,2,2,2,2,2,2,9,1,1,1,1,1,1,1
1,1,1,1,1,1,2,2,1,1,1,1,11,1,1,2,2,1,1,1,1,1,1
1,1,1,12,2,1,1,1,1,1,1,1,1,1,1,1,1,2,2,1,1,1,1
1,1,1,1,2,1,1,1,1,1,1,1,1,1,1,1,1,1,2,1,1,1,1
1,1,1,1,1,1,1,1,1,1,1,1,1,1,1,1,1,1,1,2,1,1,1
1,1,9,2,1,1,1,1,1,1,1,1,1,1,1,1,1,1,1,2,9,1,1
1,1,2,1,1,1,1,1,1,1,1,1,1,1,1,1,1,1,1,1,2,1,1
1,1,2,1,1,1,1,1,1,1,1,1,1,1,1,1,1,1,1,1,2,1,1
1,1,2,1,1,1,1,1,1,1,1,1,1,1,1,1,1,1,1,1,2,10,1
1,9,2,1,1,1,1,1,1,1,1,1,1,1,1,1,1,1,1,1,2,9,1
1,1,2,1,1,1,1,1,1,1,1,1,1,1,1,1,1,1,1,1,2,1,1
1,12,2,1,1,1,1,1,1,1,1,1,1,1,1,1,1,1,1,1,2,1,1
1,1,2,1,1,1,1,1,1,1,1,1,1,1,1,1,1,1,1,1,2,1,1
1,1,1,1,1,1,1,1,1,1,1,1,1,1,1,1,1,1,1,2,9,1,1
1,1,1,1,1,1,1,1,1,1,1,1,1,1,1,1,1,10,1,2,1,1,1
1,1,1,1,1,1,1,1,1,1,1,1,1,1,1,1,1,1,2,17,1,1,1
1,1,1,1,1,1,1,1,1,1,1,1,1,1,1,1,1,2,2,13,1,1,1
1,1,1,1,1,1,1,1,1,1,1,1,1,1,12,2,2,1,1,1,1,1,1
1,1,1,1,1,1,1,9,2,2,2,2,2,2,2,9,1,1,1,1,1,1,1
1,1,1,1,1,1,1,1,1,1,11,9,1,1,1,1,1,1,1,1,1,1,1
1,1,1,1,1,1,1,1,1,1,1,1,1,1,1,1,1,1,1,1,1,1,1
endlayer

layer
1,1,1,1,1,1,1,1,1,1,1,1,1,1,1,1,1,1,1,1,1,1,1
1,1,1,1,1,1,1,1,1,1,1,1,1,1,1,1,1,1,1,1,1,1,1
1,1,1,1,1,1,1,1,1,10,1,9,1,1,1,1,1,1,1,1,1,1,1
1,1,1,1,1,1,1,9,1,2,2,2,2,2,2,9,13,1,1,1,1,1,1
1,1,1,1,1,10,2,2,1,1,1,1,1,1,1,2,2,1,1,1,1,1,1
1,1,1,1,1,2,17,1,1,1,1,1,1,1,1,1,1,2,1,1,1,1,1
1,1,1,10,2,11,1,1,1,1,1,1,1,1,1,1,1,16,2,10,1,1,1
1,1,1,9,1,1,1,1,1,1,1,1,1,1,1,1,1,1,2,9,13,1,1
1,1,1,2,1,1,1,1,1,1,1,1,1,1,1,1,1,1,1,2,1,1,1
1,1,1,2,1,1,1,1,1,1,1,1,1,1,1,1,1,1,1,2,1,1,1
1,1,10,2,1,1,1,1,1,1,1,1,1,1,1,1,1,1,12,2,1,1,1
1,1,9,2,1,1,1,1,1,1,1,1,1,1,1,1,1,1,1,2,9,13,1
1,1,1,2,1,1,1,1,1,1,1,1,1,1,1,1,1,1,1,2,1,1,1
1,1,1,2,1,1,1,1,1,1,1,1,1,1,1,1,1,1,1,2,1,1,1
1,1,1,2,1,1,1,1,1,1,1,1,1,1,1,1,1,1,1,2,1,1,1
1,1,1,1,1,1,1,1,1,1,1,1,1,1,1,1,1,1,2,9,1,1,1
1,1,1,1,1,1,1,1,1,1,1,1,1,1,1,1,1,10,2,17,1,1,1
1,1,1,1,1,1,1,1,1,1,1,1,1,1,1,1,1,2,1,1,1,1,1
1,1,1,1,1,1,1,1,1,1,1,1,1,1,1,2,2,1,1,1,1,1,1
1,1,1,1,1,1,1,6,2,2,2,2,2,2,2,9,1,1,1,1,1,1,1
1,1,1,1,1,1,1,1,1,1,11,9,11,1,1,1,1,1,1,1,1,1,1
1,1,1,1,1,1,1,1,1,1,1,1,1,1,1,1,1,1,1,1,1,1,1
1,1,1,1,1,1,1,1,1,1,1,1,1,1,1,1,1,1,1,1,1,1,1
endlayer

layer
1,1,1,1,1,1,1,1,1,1,1,1,1,1,1,1,1,1,1,1,1,1,1
1,1,1,1,1,1,1,1,1,1,1,1,1,1,1,1,1,1,1,1,1,1,1
1,1,1,1,1,1,1,1,1,10,1,9,1,1,1,10,1,1,1,1,1,1,1
1,1,1,1,1,1,1,9,2,2,2,2,2,2,2,9,13,1,1,1,1,1,1
1,1,1,1,1,14,2,2,1,1,1,1,1,1,1,2,2,1,1,1,1,1,1
1,1,1,1,1,2,17,1,1,1,1,11,1,1,1,1,1,2,1,1,1,1,1
1,1,1,14,2,11,1,1,1,1,1,1,1,1,1,1,1,16,2,10,1,1,1
1,1,1,9,2,1,1,1,1,1,1,1,1,1,1,1,1,1,2,9,13,1,1
1,1,1,2,1,1,1,1,1,1,1,1,1,1,1,1,1,1,1,2,13,1,1
1,1,1,2,1,1,1,1,1,1,1,1,1,1,1,1,1,1,1,2,1,1,1
1,1,1,2,1,1,1,1,1,1,1,1,1,1,1,1,1,1,12,2,1,1,1
1,1,1,6,1,1,1,1,1,1,1,1,1,1,1,1,1,1,1,2,9,13,1
1,1,1,2,1,1,1,1,1,1,1,1,1,1,1,1,1,1,1,2,1,1,1
1,1,1,6,1,1,1,1,1,1,1,1,1,1,1,1,1,1,1,2,1,1,1
1,1,1,6,1,1,1,1,1,1,1,1,1,1,1,1,1,1,1,2,1,1,1
1,1,1,1,1,1,1,1,1,1,1,1,1,1,1,1,1,1,2,9,13,1,1
1,1,1,1,1,1,1,1,1,1,1,1,1,1,1,1,1,1,2,17,1,1,1
1,1,1,1,1,1,1,1,1,1,1,1,1,1,1,1,1,2,1,1,1,1,1
1,1,1,1,1,1,1,1,1,1,1,1,1,1,1,2,2,1,1,1,1,1,1
1,1,1,1,1,1,1,6,2,2,2,2,2,2,2,9,13,1,1,1,1,1,1
1,1,1,1,1,1,1,1,1,1,11,9,11,1,1,1,1,1,1,1,1,1,1
1,1,1,1,1,1,1,1,1,1,1,1,1,1,1,1,1,1,1,1,1,1,1
1,1,1,1,1,1,1,1,1,1,1,1,1,1,1,1,1,1,1,1,1,1,1
endlayer

layer
1,1,1,1,1,1,1,1,1,1,1,1,1,1,1,1,1,1,1,1,1,1,1
1,1,1,1,1,1,1,1,1,1,1,1,1,1,1,1,1,1,1,1,1,1,1
1,1,1,1,1,1,1,1,1,10,14,9,1,1,1,10,1,1,1,1,1,1,1
1,1,1,1,1,1,1,9,2,2,2,2,2,2,2,9,13,1,1,1,1,1,1
1,1,1,1,1,14,2,2,1,1,1,1,1,1,1,2,2,1,1,1,1,1,1
1,1,1,1,1,2,17,1,1,1,1,11,1,1,1,1,1,2,1,1,1,1,1
1,1,1,1,2,1,1,1,1,1,1,1,1,1,1,1,1,16,2,10,1,1,1
1,1,1,9,2,1,1,1,1,1,1,1,1,1,1,1,1,1,2,9,13,1,1
1,1,1,2,1,1,1,1,1,1,1,1,1,1,1,1,1,1,1,2,13,1,1
1,1,1,2,1,1,1,1,1,1,1,1,1,1,1,1,1,1,1,2,1,1,1
1,1,1,6,1,1,1,1,1,1,1,1,1,1,1,1,1,1,12,2,1,1,1
1,1,1,1,1,1,1,1,1,1,1,1,1,1,1,1,1,1,1,2,9,1,1
1,1,1,6,1,1,1,1,1,1,1,1,1,1,1,1,1,1,1,2,1,1,1
1,1,1,1,1,1,1,1,1,1,1,1,1,1,1,1,1,1,1,2,1,1,1
1,1,1,1,1,1,1,1,1,1,1,1,1,1,1,1,1,1,1,2,1,1,1
1,1,1,1,1,1,1,1,1,1,1,1,1,1,1,1,1,1,2,9,13,1,1
1,1,1,1,1,1,1,1,1,1,1,1,1,1,1,1,1,1,2,17,1,1,1
1,1,1,1,1,1,1,1,1,1,1,1,1,1,1,1,1,2,1,1,1,1,1
1,1,1,1,1,1,1,1,1,1,1,1,1,1,1,2,2,1,1,1,1,1,1
1,1,1,1,1,1,1,6,2,2,2,2,2,2,2,9,13,1,1,1,1,1,1
1,1,1,1,1,1,1,1,1,1,11,9,11,1,1,1,1,1,1,1,1,1,1
1,1,1,1,1,1,1,1,1,1,1,1,1,1,1,1,1,1,1,1,1,1,1
1,1,1,1,1,1,1,1,1,1,1,1,1,1,1,1,1,1,1,1,1,1,1
endlayer

layer
1,1,1,1,1,1,1,1,1,1,1,1,1,1,1,1,1,1,1,1,1,1,1
1,1,1,1,1,1,1,1,1,1,1,1,1,1,1,1,1,1,1,1,1,1,1
1,1,1,1,1,1,1,1,10,1,10,9,1,1,1,1,1,1,1,1,1,1,1
1,1,1,1,1,1,1,9,2,2,2,2,2,2,2,9,13,1,1,1,1,1,1
1,1,1,1,1,14,2,2,1,1,1,1,1,1,1,2,2,1,1,1,1,1,1
1,1,1,1,1,2,17,1,1,1,1,11,1,1,1,1,1,2,1,1,1,1,1
1,1,1,1,2,1,1,1,1,1,1,1,1,1,1,1,1,11,2,10,1,1,1
1,1,1,9,2,1,1,1,1,1,1,1,1,1,1,1,1,1,2,9,13,1,1
1,1,1,2,1,1,1,1,1,1,1,1,1,1,1,1,1,1,1,2,13,1,1
1,1,1,2,1,1,1,1,1,1,1,1,1,1,1,1,1,1,1,2,1,1,1
1,1,1,6,1,1,1,1,1,1,1,1,1,1,1,1,1,1,12,2,1,1,1
1,1,1,1,1,1,1,1,1,1,1,1,1,1,1,1,1,1,1,2,9,1,1
1,1,1,1,1,1,1,1,1,1,1,1,1,1,1,1,1,1,1,2,1,1,1
1,1,1,1,1,1,1,1,1,1,1,1,1,1,1,1,1,1,1,2,1,1,1
1,1,1,1,1,1,1,1,1,1,1,1,1,1,1,1,1,10,1,2,1,1,1
1,1,1,1,1,1,1,1,1,1,1,1,1,1,1,1,1,1,2,9,13,1,1
1,1,1,1,1,1,1,1,1,1,1,1,1,1,1,1,1,1,2,11,1,1,1
1,1,1,1,1,1,1,1,1,1,1,1,1,1,1,1,1,2,1,1,1,1,1
1,1,1,1,1,1,1,1,1,1,1,1,1,1,1,2,2,1,1,1,1,1,1
1,1,1,1,1,1,1,6,2,2,2,2,2,2,2,9,13,1,1,1,1,1,1
1,1,1,1,1,1,1,1,1,1,11,9,13,1,1,1,1,1,1,1,1,1,1
1,1,1,1,1,1,1,1,1,1,1,1,1,1,1,1,1,1,1,1,1,1,1
1,1,1,1,1,1,1,1,1,1,1,1,1,1,1,1,1,1,1,1,1,1,1
endlayer

layer
1,1,1,1,1,1,1,1,1,1,1,1,1,1,1,1,1,1,1,1,1,1,1
1,1,1,1,1,1,1,1,1,1,1,1,1,1,1,1,1,1,1,1,1,1,1
1,1,1,1,1,1,1,1,10,1,12,1,1,1,1,1,1,1,1,1,1,1,1
1,1,1,1,1,1,1,1,1,1,1,9,1,1,1,1,15,1,1,1,1,1,1
1,1,1,1,1,1,1,9,2,2,2,2,2,2,2,9,1,1,1,1,1,1,1
1,1,1,1,1,1,2,2,1,1,1,11,11,1,1,2,2,1,1,1,1,1,1
1,1,1,1,1,2,1,1,1,1,1,1,1,1,1,11,1,2,1,1,1,1,1
1,1,1,1,9,2,1,1,1,1,1,1,1,1,1,1,1,2,9,1,1,1,1
1,1,1,1,2,1,1,1,1,1,1,1,1,1,1,1,1,11,2,1,1,1,1
1,1,1,1,6,1,1,1,1,1,1,1,1,1,1,1,1,1,2,1,1,1,1
1,1,1,1,1,1,1,1,1,1,1,1,1,1,1,1,1,1,2,1,15,1,1
1,1,1,1,1,1,1,1,1,1,1,1,1,1,1,1,1,1,2,9,1,1,1
1,1,1,1,1,1,1,1,1,1,1,1,1,1,1,1,1,1,2,1,1,1,1
1,1,1,1,1,1,1,1,1,1,1,1,1,1,1,1,1,1,2,1,1,1,1
1,1,1,1,1,1,1,1,1,1,1,1,1,1,1,1,1,10,2,1,13,1,1
1,1,1,1,1,1,1,1,1,1,1,1,1,1,1,1,1,2,9,1,13,1,1
1,1,1,1,1,1,1,1,1,1,1,1,1,1,1,1,1,2,1,1,1,1,1
1,1,1,1,1,1,1,1,1,10,1,1,1,1,1,2,2,1,1,1,1,1,1
1,1,1,1,1,1,1,1,6,2,2,2,2,2,2,9,1,1,1,1,1,1,1
1,1,1,1,1,1,1,1,1,6,1,9,1,1,1,1,1,1,1,1,1,1,1
1,1,1,1,1,1,1,1,1,1,1,1,1,1,1,1,1,1,1,1,1,1,1
1,1,1,1,1,1,1,1,1,1,1,1,1,1,1,1,1,1,1,1,1,1,1
1,1,1,1,1,1,1,1,1,1,1,1,1,1,1,1,1,1,1,1,1,1,1
endlayer

layer
1,1,1,1,1,1,1,1,1,1,1,1,1,1,1,1,1,1,1,1,1,1,1
1,1,1,1,1,1,1,1,1,1,1,1,1,1,1,1,1,1,1,1,1,1,1
1,1,1,1,1,1,1,1,10,1,12,1,1,1,1,1,1,1,1,1,1,1,1
1,1,1,1,1,1,1,1,1,1,1,9,1,1,1,1,15,1,1,1,1,1,1
1,1,1,1,1,1,1,9,2,2,2,2,2,2,2,9,1,1,1,1,1,1,1
1,1,1,1,1,1,2,2,1,1,1,11,11,1,1,2,2,1,1,1,1,1,1
1,1,1,1,1,2,1,1,1,1,1,1,1,1,1,11,1,2,1,1,1,1,1
1,1,1,1,9,2,1,1,1,1,1,1,1,1,1,1,1,2,9,1,1,1,1
1,1,1,1,2,1,1,1,1,1,1,1,1,1,1,1,1,11,2,1,1,1,1
1,1,1,1,6,1,1,1,1,1,1,1,1,1,1,1,1,1,2,1,1,1,1
1,1,1,1,1,1,1,1,1,1,1,1,1,1,1,1,1,1,2,1,15,13,1
1,1,1,1,1,1,1,1,1,1,1,1,1,1,1,1,1,1,2,9,1,1,1
1,1,1,1,1,1,1,1,1,1,1,1,1,1,1,1,1,1,2,1,1,1,1
1,1,1,1,1,1,1,1,1,1,1,1,1,1,1,1,1,1,2,1,1,1,1
1,1,1,1,1,1,1,1,1,1,1,1,1,1,1,1,1,10,2,1,13,1,1
1,1,1,1,1,1,1,1,1,1,1,1,1,1,1,1,1,2,9,1,13,1,1
1,1,1,1,1,1,1,1,1,1,1,1,1,1,1,10,10,2,1,1,1,1,1
1,1,1,1,1,1,1,1,1,10,1,1,1,1,12,2,2,1,13,1,1,1,1
1,1,1,1,1,1,1,1,6,2,2,2,2,2,2,9,1,1,1,1,1,1,1
1,1,1,1,1,1,1,1,1,1,1,9,1,1,1,1,1,1,1,1,1,1,1
1,1,1,1,1,1,1,1,1,1,1,1,1,1,1,1,1,1,1,1,1,1,1
1,1,1,1,1,1,1,1,1,1,1,1,1,1,1,1,1,1,1,1,1,1,1
1,1,1,1,1,1,1,1,1,1,1,1,1,1,1,1,1,1,1,1,1,1,1
endlayer

layer
1,1,1,1,1,1,1,1,1,1,1,1,1,1,1,1,1,1,1,1,1,1,1
1,1,1,1,1,1,1,1,1,1,12,1,1,1,1,1,1,1,1,1,1,1,1
1,1,1,1,1,1,1,1,10,1,12,1,1,1,1,10,1,1,1,1,1,1,1
1,1,1,1,1,1,1,1,1,1,1,9,1,1,1,1,15,1,1,1,1,1,1
1,1,1,1,1,1,1,9,2,2,2,2,2,2,2,9,1,1,1,1,1,1,1
1,1,1,1,1,1,2,2,1,1,1,11,11,1,1,2,2,1,1,1,1,1,1
1,1,1,1,1,1,6,1,1,1,1,1,1,1,1,11,1,2,1,1,1,1,1
1,1,1,1,1,2,1,1,1,1,1,1,1,1,1,1,1,2,9,1,1,1,1
1,1,1,1,1,6,1,1,1,1,1,1,1,1,1,1,1,11,2,1,13,1,1
1,1,1,1,1,1,1,1,1,1,1,1,1,1,1,1,1,1,2,1,13,1,1
1,1,1,1,1,1,1,1,1,1,1,1,1,1,1,1,1,1,2,1,15,15,1
1,1,1,1,1,1,1,1,1,1,1,1,1,1,1,1,1,1,2,9,1,13,1
1,1,1,1,1,1,1,1,1,1,1,1,1,1,1,1,1,1,2,1,1,1,1
1,1,1,1,1,1,1,1,1,1,1,1,1,1,1,1,1,1,2,1,1,1,1
1,1,1,1,1,1,1,1,1,1,1,1,1,1,1,1,1,10,2,1,13,1,1
1,1,1,1,1,1,1,1,1,1,1,1,1,1,1,1,1,2,9,1,13,1,1
1,1,1,1,1,1,1,1,1,1,1,1,1,1,1,10,14,2,1,1,1,1,1
1,1,1,1,1,1,1,1,1,1,1,1,1,1,12,2,2,1,13,1,1,1,1
1,1,1,1,1,1,1,1,1,6,2,2,2,2,2,9,1,1,1,1,1,1,1
1,1,1,1,1,1,1,1,1,1,1,9,1,1,1,1,1,1,1,1,1,1,1
1,1,1,1,1,1,1,1,1,1,1,1,1,1,1,1,1,1,1,1,1,1,1
1,1,1,1,1,1,1,1,1,1,1,1,1,1,1,1,1,1,1,1,1,1,1
1,1,1,1,1,1,1,1,1,1,1,1,1,1,1,1,1,1,1,1,1,1,1
endlayer

layer
1,1,1,1,1,1,1,1,1,1,1,1,1,1,1,1,1,1,1,1,1,1,1
1,1,1,1,1,1,1,1,1,1,0,10,1,1,1,1,1,1,1,1,1,1,1
1,1,1,1,1,1,12,1,10,1,12,1,1,1,1,10,1,1,1,1,1,1,1
1,1,1,1,1,1,1,1,1,1,1,9,1,1,1,1,15,1,1,1,1,1,1
1,1,1,1,1,1,1,9,2,2,2,2,2,2,2,9,1,1,1,1,1,1,1
1,1,1,1,1,1,1,6,1,1,11,1,1,1,1,2,2,1,1,1,1,1,1
1,1,1,1,1,1,1,1,1,1,1,1,1,1,1,11,1,2,1,1,10,1,1
1,1,1,1,1,1,1,1,1,1,1,1,1,1,1,1,1,2,9,1,1,13,1
1,1,1,1,1,1,1,1,1,1,1,1,1,1,1,1,1,11,2,1,13,1,1
1,1,1,1,1,1,1,1,1,1,1,1,1,1,1,1,1,1,2,1,13,1,1
1,1,1,1,1,1,1,1,1,1,1,1,1,1,1,1,1,1,2,1,15,15,1
1,1,1,1,1,1,1,1,1,1,1,1,1,1,1,1,1,1,2,9,1,13,1
1,1,1,1,1,1,1,1,1,1,1,1,1,1,1,1,1,1,2,1,1,13,1
1,1,1,1,1,1,1,1,1,1,1,1,1,1,1,1,1,1,2,1,1,1,1
1,1,1,1,1,1,1,1,1,1,1,1,1,1,1,1,1,10,2,1,13,1,1
1,1,1,1,1,1,1,1,1,1,1,1,1,1,1,1,1,2,9,1,13,1,1
1,1,1,1,1,1,1,1,1,1,1,1,1,1,1,1,14,2,1,1,1,1,1
1,1,1,1,1,1,1,1,1,1,1,1,1,1,1,2,2,1,13,1,1,1,1
1,1,1,1,1,1,1,1,1,1,6,1,1,2,2,9,1,1,1,1,1,1,1
1,1,1,1,1,1,1,1,1,1,1,9,1,1,1,1,1,1,1,1,1,1,1
1,1,1,1,1,1,1,1,1,1,1,1,1,1,1,11,1,1,1,1,1,1,1
1,1,1,1,1,1,1,1,1,1,1,1,1,1,1,1,1,1,1,1,1,1,1
1,1,1,1,1,1,1,1,1,1,1,1,1,1,1,1,1,1,1,1,1,1,1
endlayer

layer
1,1,1,1,1,1,1,1,1,1,1,1,1,1,1,1,1,1,1,1,1,1,1
1,1,1,1,1,1,1,1,1,1,10,10,1,1,1,1,1,1,1,1,1,1,1
1,1,1,1,1,1,12,1,10,1,12,9,1,1,1,10,1,1,1,1,1,1,1
1,1,1,1,1,1,1,9,2,2,2,2,2,2,2,9,15,1,1,1,1,1,1
1,1,1,1,1,1,1,1,6,1,1,1,1,1,1,2,2,1,1,1,1,1,1
1,1,1,1,1,1,1,1,1,1,1,1,1,1,1,1,1,2,1,1,10,1,1
1,1,1,1,1,1,1,1,1,1,1,1,1,1,1,1,1,1,2,1,10,1,1
1,1,1,1,1,1,1,1,1,1,1,1,1,1,1,1,1,1,2,9,1,13,1
1,1,1,1,1,1,1,1,1,1,1,1,1,1,1,1,1,1,1,2,13,1,1
1,1,1,1,1,1,1,1,1,1,1,1,1,1,1,1,1,1,1,2,13,1,1
1,1,1,1,1,1,1,1,1,1,1,1,1,1,1,1,1,1,1,2,15,15,1
1,1,1,1,1,1,1,1,1,1,1,1,1,1,1,1,1,1,1,2,9,13,1
1,1,1,1,1,1,1,1,1,1,1,1,1,1,1,1,1,1,1,2,1,13,1
1,1,1,1,1,1,1,1,1,1,1,1,1,1,1,1,1,1,1,2,1,1,1
1,1,1,1,1,1,1,1,1,1,1,1,1,1,1,1,1,1,1,2,13,1,1
1,1,1,1,1,1,1,1,1,1,1,1,1,1,1,1,1,1,2,9,13,1,1
1,1,1,1,1,1,1,1,1,1,1,1,1,1,1,1,1,6,2,1,11,1,1
1,1,1,1,1,1,1,1,1,1,1,1,1,1,1,1,6,2,13,1,1,1,1
1,1,1,1,1,1,1,1,1,1,1,1,1,1,1,2,2,1,1,1,1,1,1
1,1,1,1,1,1,1,1,1,1,1,1,6,2,2,9,1,1,1,1,1,1,1
1,1,1,1,1,1,1,1,1,1,1,1,1,1,11,11,1,1,1,1,1,1,1
1,1,1,1,1,1,1,1,1,1,1,1,1,1,1,1,1,1,1,1,1,1,1
1,1,1,1,1,1,1,1,1,1,1,1,1,1,1,1,1,1,1,1,1,1,1
endlayer

layer
1,1,1,1,1,1,1,1,1,1,1,1,1,1,1,1,1,1,1,1,1,1,1
1,1,1,1,1,1,1,1,1,1,10,1,1,1,1,1,1,1,1,1,1,1,1
1,1,1,1,1,1,12,1,1,1,1,9,1,1,1,1,1,1,1,1,1,1,1
1,1,1,1,1,1,1,9,2,2,1,1,1,1,6,6,10,1,1,1,1,1,1
1,1,1,1,1,1,1,1,1,1,1,1,1,1,1,1,2,1,1,1,1,1,1
1,1,1,1,1,1,1,1,1,1,1,1,1,1,1,1,1,2,1,1,10,1,1
1,1,1,1,1,1,1,1,1,1,1,1,1,1,1,1,1,1,2,1,10,13,1
1,1,1,1,1,1,1,1,1,1,1,1,1,1,1,1,1,1,2,9,1,13,1
1,1,1,1,1,1,1,1,1,1,1,1,1,1,1,1,1,1,1,2,1,1,1
1,1,1,1,1,1,1,1,1,1,1,1,1,1,1,1,1,1,1,2,1,1,1
1,1,1,1,1,1,1,1,1,1,1,1,1,1,1,1,1,1,1,2,15,15,1
1,1,1,1,1,1,1,1,1,1,1,1,1,1,1,1,1,1,1,2,9,1,1
1,1,1,1,1,1,1,1,1,1,1,1,1,1,1,1,1,1,1,2,1,13,1
1,1,1,1,1,1,1,1,1,1,1,1,1,1,1,1,1,1,1,2,1,1,1
1,1,1,1,1,1,1,1,1,1,1,1,1,1,1,1,1,1,1,2,13,1,1
1,1,1,1,1,1,1,1,1,1,1,1,1,1,1,1,1,1,6,9,13,1,1
1,1,1,1,1,1,1,1,1,1,1,1,1,1,1,1,1,1,1,1,11,1,1
1,1,1,1,1,1,1,1,1,1,1,1,1,1,1,1,1,6,1,1,1,1,1
1,1,1,1,1,1,1,1,1,1,1,1,1,1,1,1,1,1,1,1,1,1,1
1,1,1,1,1,1,1,1,1,1,1,1,1,6,6,1,1,1,1,1,1,1,1
1,1,1,1,1,1,1,1,1,1,1,1,1,1,1,1,1,1,1,1,1,1,1
1,1,1,1,1,1,1,1,1,1,1,1,1,1,1,1,1,1,1,1,1,1,1
1,1,1,1,1,1,1,1,1,1,1,1,1,1,1,1,1,1,1,1,1,1,1
endlayer

layer
1,1,1,1,1,1,1,1,1,1,1,1,1,1,1,1,1,1,1,1,1,1,1
1,1,1,1,1,1,1,1,1,1,10,1,1,1,1,1,1,1,1,1,1,1,1
1,1,1,1,1,1,12,9,2,2,2,1,1,1,1,1,1,1,1,1,1,1,1
1,1,1,1,1,1,2,2,1,6,1,1,1,1,1,1,2,1,1,1,1,1,1
1,1,1,1,1,1,6,1,1,1,1,1,1,1,1,1,6,2,1,1,1,1,1
1,1,1,1,1,1,1,1,1,1,1,1,1,1,1,1,1,1,2,1,10,1,1
1,1,1,1,1,1,1,1,1,1,1,1,1,1,1,1,1,1,1,2,10,13,1
1,1,1,1,1,1,1,1,1,1,1,1,1,1,1,1,1,1,1,2,9,13,1
1,1,1,1,1,1,1,1,1,1,1,1,1,1,1,1,1,1,1,1,2,1,1
1,1,1,1,1,1,1,1,1,1,1,1,1,1,1,1,1,1,1,1,2,1,1
1,1,1,1,1,1,1,1,1,1,1,1,1,1,1,1,1,1,1,1,2,15,1
1,1,1,1,1,1,1,1,1,1,1,1,1,1,1,1,1,1,1,1,2,9,1
1,1,1,1,1,1,1,1,1,1,1,1,1,1,1,1,1,1,1,1,2,13,1
1,1,1,1,1,1,1,1,1,1,1,1,1,1,1,1,1,1,1,1,2,1,1
1,1,1,1,1,1,1,1,1,1,1,1,1,1,1,1,1,1,1,1,2,1,1
1,1,1,1,1,1,1,1,1,1,1,1,1,1,1,1,1,1,1,2,9,13,1
1,1,1,1,1,1,1,1,1,1,1,1,1,1,1,1,1,1,1,1,11,1,1
1,1,1,1,1,1,1,1,1,1,1,1,1,1,1,1,1,1,1,1,1,1,1
1,1,1,1,1,1,1,1,1,1,1,1,1,1,1,1,1,1,1,1,1,1,1
1,1,1,1,1,1,1,1,1,1,1,1,1,1,1,1,1,1,1,1,1,1,1
1,1,1,1,1,1,1,1,1,1,1,1,1,1,1,1,1,1,1,1,1,1,1
1,1,1,1,1,1,1,1,1,1,1,1,1,1,1,1,1,1,1,1,1,1,1
1,1,1,1,1,1,1,1,1,1,1,1,1,1,1,1,1,1,1,1,1,1,1
endlayer

layer
1,1,1,1,1,1,1,1,1,1,1,1,1,1,1,1,1,1,1,1,1,1,1
1,1,1,1,1,1,1,1,1,1,1,1,1,1,1,1,1,1,1,1,1,1,1
1,1,1,1,1,12,1,9,2,2,6,1,1,1,1,1,1,1,1,1,1,1,1
1,1,1,1,1,1,2,1,1,1,1,1,1,1,1,1,1,1,1,1,1,1,1
1,1,1,1,1,1,6,1,1,1,1,1,1,1,1,1,1,6,1,1,1,1,1
1,1,1,1,1,1,1,1,1,1,1,1,1,1,1,1,1,1,2,1,10,1,1
1,1,1,1,1,1,1,1,1,1,1,1,1,1,1,1,1,1,1,2,1,13,1
1,1,1,1,1,1,1,1,1,1,1,1,1,1,1,1,1,1,1,2,9,13,1
1,1,1,1,1,1,1,1,1,1,1,1,1,1,1,1,1,1,1,1,2,1,1
1,1,1,1,1,1,1,1,1,1,1,1,1,1,1,1,1,1,1,1,2,1,1
1,1,1,1,1,1,1,1,1,1,1,1,1,1,1,1,1,1,1,1,2,13,1
1,1,1,1,1,1,1,1,1,1,1,1,1,1,1,1,1,1,1,1,2,9,1
1,1,1,1,1,1,1,1,1,1,1,1,1,1,1,1,1,1,1,1,2,17,1
1,1,1,1,1,1,1,1,1,1,1,1,1,1,1,1,1,1,1,1,2,1,1
1,1,1,1,1,1,1,1,1,1,1,1,1,1,1,1,1,1,1,1,2,1,1
1,1,1,1,1,1,1,1,1,1,1,1,1,1,1,1,1,1,1,6,9,13,1
1,1,1,1,1,1,1,1,1,1,1,1,1,1,1,1,1,1,1,1,1,1,1
1,1,1,1,1,1,1,1,1,1,1,1,1,1,1,1,1,1,1,1,1,1,1
1,1,1,1,1,1,1,1,1,1,1,1,1,1,1,1,1,1,1,1,1,1,1
1,1,1,1,1,1,1,1,1,1,1,1,1,1,1,1,1,1,1,1,1,1,1
1,1,1,1,1,1,1,1,1,1,1,1,1,1,1,1,1,1,1,1,1,1,1
1,1,1,1,1,1,1,1,1,1,1,1,1,1,1,1,1,1,1,1,1,1,1
1,1,1,1,1,1,1,1,1,1,1,1,1,1,1,1,1,1,1,1,1,1,1
endlayer

layer
1,1,1,1,1,1,1,1,1,1,1,1,1,1,1,1,1,1,1,1,1,1,1
1,1,1,1,1,1,1,1,2,1,1,1,1,1,1,1,1,1,1,1,1,1,1
1,1,1,1,1,12,2,1,1,6,1,1,1,1,1,1,1,1,1,1,1,1,1
1,1,1,1,1,1,6,1,1,1,1,1,1,1,1,1,1,1,1,1,1,1,1
1,1,1,1,1,1,1,1,1,1,1,1,1,1,1,1,1,1,2,1,1,1,1
1,1,1,1,1,1,1,1,1,1,1,1,1,1,1,1,1,1,6,2,10,1,1
1,1,1,1,1,1,1,1,1,1,1,1,1,1,1,1,1,1,1,1,2,13,1
1,1,1,1,1,1,1,1,1,1,1,1,1,1,1,1,1,1,1,1,2,13,1
1,1,1,1,1,1,1,1,1,1,1,1,1,1,1,1,1,1,1,1,1,2,1
1,1,1,1,1,1,1,1,1,1,1,1,1,1,1,1,1,1,1,1,1,2,1
1,1,1,1,1,1,1,1,1,1,1,1,1,1,1,1,1,1,1,1,1,2,1
1,1,1,1,1,1,1,1,1,1,1,1,1,1,1,1,1,1,1,1,1,2,1
1,1,1,1,1,1,1,1,1,1,1,1,1,1,1,1,1,1,1,1,1,2,1
1,1,1,1,1,1,1,1,1,1,1,1,1,1,1,1,1,1,1,1,1,1,1
1,1,1,1,1,1,1,1,1,1,1,1,1,1,1,1,1,1,1,1,1,2,1
1,1,1,1,1,1,1,1,1,1,1,1,1,1,1,1,1,1,1,1,1,1,1
1,1,1,1,1,1,1,1,1,1,1,1,1,1,1,1,1,1,1,1,1,1,1
1,1,1,1,1,1,1,1,1,1,1,1,1,1,1,1,1,1,1,1,1,1,1
1,1,1,1,1,1,1,1,1,1,1,1,1,1,1,1,1,1,1,1,1,1,1
1,1,1,1,1,1,1,1,1,1,1,1,1,1,1,1,1,1,1,1,1,1,1
1,1,1,1,1,1,1,1,1,1,1,1,1,1,1,1,1,1,1,1,1,1,1
1,1,1,1,1,1,1,1,1,1,1,1,1,1,1,1,1,1,1,1,1,1,1
1,1,1,1,1,1,1,1,1,1,1,1,1,1,1,1,1,1,1,1,1,1,1
endlayer

