weight=2
dimensionsToSpawnIn=overworld
embed_into_distance=1
random_height_offset=0,0
unacceptable_target_blocks=sand,flowing_water,water,flowing_lava,lava,ice,packed_ice,stained_hardened_clay-9,brick_block,double_stone_slab,stonebrick,red_sandstone,red_nether_brick,red_mushroom_block,brown_mushroom_block,planks,cobblestone,end_stone,obsidian,purpur_block,iron_bars,purpur_slab,purpur_pillar,netherrack,soul_sand,quartz_ore,stained_glass,glass
dimensions=22,11,11
allowable_overhang=0
max_leveling=1
leveling_buffer=-1
preventRotation=0
preserve_water=0
preserve_lava=0
uniqueMinDistance=1000
spawnMinDistance=0
spawnMaxDistance=0

rule1=0,100,preserveBlock
rule2=0,100,minecraft:stone-6
rule3=0,100,minecraft:stone_slab-0
rule4=0,100,chisel:factory-1
rule5=0,100,minecraft:cobblestone_wall-0,minecraft:cobblestone_wall-1
rule6=0,100,chisel:factory-14
rule7=0,100,minecraft:vine-8
rule8=0,100,minecraft:vine-1
rule9=0,100,minecraft:vine-4
rule10=0,100,minecraft:vine-2
rule11=0,100,minecraft:stone_slab-8
rule12=0,100,chisel:technical-12
rule13=0,100,minecraft:iron_bars-0
rule14=0,100,minecraft:stone_brick_stairs-4
rule15=0,100,minecraft:stone_brick_stairs-7
rule16=0,100,minecraft:stone_brick_stairs-6
rule17=0,100,minecraft:stone_brick_stairs-5
rule18=0,100,minecraft:concrete-8
rule19=0,100,minecraft:double_stone_slab-0
rule20=0,100,minecraft:vine-9
rule21=0,100,chisel:blockcopper-4,chisel:technical1-0,chisel:technical1-0

layer
1,1,1,1,1,1,1,1,1,1,1
1,2,2,2,1,1,1,2,2,2,1
1,2,2,2,2,2,2,2,2,2,1
1,2,2,2,2,2,2,2,2,2,1
1,1,2,2,2,2,2,2,2,1,1
1,1,2,2,2,2,2,2,2,1,1
1,1,2,2,2,2,2,2,2,1,1
1,2,2,2,2,2,2,2,2,2,1
1,2,2,2,2,2,2,2,2,2,1
1,2,2,2,1,1,1,2,2,2,1
1,1,1,1,1,1,1,1,1,1,1
endlayer

layer
1,1,1,1,1,1,1,1,1,1,1
1,3,3,3,1,1,1,3,3,3,1
1,3,2,3,3,3,3,3,2,3,1
1,3,3,4,3,5,3,4,3,3,1
1,1,3,3,6,6,6,3,3,1,1
1,1,3,5,6,6,6,5,3,1,1
1,1,3,3,6,6,6,3,3,1,1
1,3,3,4,3,5,3,4,3,3,1
1,3,2,3,3,3,3,3,2,3,1
1,3,3,3,1,1,1,3,3,3,1
1,1,1,1,1,1,1,1,1,1,1
endlayer

layer
1,1,1,1,1,1,1,1,1,1,1
1,1,1,1,1,1,1,1,1,1,1
1,1,2,1,1,1,1,1,2,1,1
1,1,1,4,3,5,3,4,1,1,1
1,1,1,3,6,6,6,3,1,1,1
1,1,1,5,6,6,6,5,1,1,1
1,1,1,3,6,6,6,3,1,1,1
1,1,1,4,3,5,3,4,1,1,1
1,1,2,1,1,1,1,1,2,1,1
1,1,1,1,1,1,1,1,1,1,1
1,1,1,1,1,1,1,1,1,1,1
endlayer

layer
1,1,1,1,1,1,1,1,1,1,1
1,1,1,1,1,1,1,1,1,1,1
1,1,2,1,1,1,1,1,2,1,1
1,1,1,4,3,5,3,4,1,1,1
1,1,1,3,6,6,6,3,1,1,1
1,1,1,5,6,6,6,5,1,1,1
1,1,1,3,6,6,6,3,1,1,1
1,1,1,4,3,5,3,4,1,1,1
1,1,2,1,1,1,1,1,2,1,1
1,1,1,1,1,1,1,1,1,1,1
1,1,1,1,1,1,1,1,1,1,1
endlayer

layer
1,1,1,0,0,0,0,0,1,1,1
1,0,7,0,7,0,0,7,7,0,1
1,9,2,7,0,5,0,9,2,8,1
0,0,9,4,3,5,3,4,8,0,0
0,9,0,3,6,6,6,3,0,0,0
0,0,5,5,6,6,6,5,5,0,0
0,9,0,3,6,6,6,3,0,0,0
0,0,7,4,3,5,3,4,8,0,0
1,9,2,10,0,5,0,9,2,0,1
1,0,10,0,0,0,0,0,10,0,1
1,1,1,0,0,0,0,0,1,1,1
endlayer

layer
1,0,0,0,0,0,0,0,0,0,1
0,0,7,0,7,5,0,7,7,0,0
0,9,2,11,11,5,11,11,2,8,0
0,0,11,4,4,4,4,4,11,8,0
0,9,11,4,4,4,4,4,11,0,0
0,5,5,4,4,4,4,4,5,5,0
0,9,11,4,4,4,4,4,11,0,0
0,9,11,4,4,4,4,4,11,8,0
0,9,2,11,11,5,11,11,2,8,0
0,0,10,0,10,5,0,10,10,0,0
1,0,0,0,0,0,0,0,0,0,1
endlayer

layer
0,0,0,0,0,0,0,0,0,0,0
0,0,7,0,7,5,7,7,7,0,0
0,9,2,2,2,2,2,2,2,8,0
0,0,2,0,0,0,0,6,2,8,0
0,9,2,0,0,0,0,0,2,0,0
0,5,2,0,0,0,0,0,2,5,0
0,9,2,0,0,0,0,0,2,8,0
0,9,2,0,0,0,0,0,2,8,0
0,9,2,2,2,2,2,2,2,8,0
0,0,10,10,10,5,10,10,10,0,0
0,0,0,0,0,0,0,0,0,0,0
endlayer

layer
0,0,0,0,0,0,0,0,0,0,0
0,0,0,7,7,5,0,7,0,0,0
0,0,5,12,12,5,12,12,5,0,0
0,9,12,6,6,6,6,6,12,8,0
0,0,12,6,0,0,0,6,12,8,0
0,5,5,6,0,0,0,6,5,5,0
0,9,12,6,0,0,0,6,12,8,0
0,0,12,6,6,6,6,6,12,8,0
0,0,5,12,12,5,12,12,5,0,0
0,0,0,0,10,5,10,0,0,0,0
0,0,0,0,0,0,0,0,0,0,0
endlayer

layer
0,0,0,0,0,0,0,0,0,0,0
0,0,0,0,0,0,0,0,0,0,0
0,0,13,7,0,5,0,7,13,0,0
0,0,9,6,3,5,3,6,8,0,0
0,0,0,3,4,4,4,3,0,0,0
0,0,5,5,4,4,4,5,5,0,0
0,0,0,3,4,4,4,3,0,0,0
0,0,0,6,3,5,3,6,8,0,0
0,0,13,10,0,5,0,10,13,0,0
0,0,0,0,0,0,0,0,0,0,0
0,0,0,0,0,0,0,0,0,0,0
endlayer

layer
0,0,0,0,0,0,0,0,0,0,0
0,0,0,0,0,0,0,0,0,0,0
0,0,0,7,0,0,0,7,0,0,0
0,0,0,6,3,5,3,6,0,0,0
0,0,0,3,4,4,4,3,0,0,0
0,0,0,5,4,4,4,5,0,0,0
0,0,0,3,4,4,4,3,0,0,0
0,0,9,6,3,5,3,6,8,0,0
0,0,0,0,0,0,0,10,0,0,0
0,0,0,0,0,0,0,0,0,0,0
0,0,0,0,0,0,0,0,0,0,0
endlayer

layer
0,0,0,0,0,0,0,0,0,0,0
0,0,0,0,0,0,0,0,0,0,0
0,0,0,7,0,0,0,0,0,0,0
0,0,9,6,3,5,3,6,8,0,0
0,0,0,3,4,4,4,3,0,0,0
0,0,0,5,4,4,4,5,0,0,0
0,0,0,3,4,4,4,3,0,0,0
0,0,9,6,3,5,3,6,8,0,0
0,0,0,0,0,0,0,10,0,0,0
0,0,0,0,0,0,0,0,0,0,0
0,0,0,0,0,0,0,0,0,0,0
endlayer

layer
0,0,0,0,0,0,0,0,0,0,0
0,0,0,0,0,0,0,0,0,0,0
0,0,0,14,0,5,0,14,0,0,0
0,0,15,6,3,5,3,6,0,0,0
0,0,0,3,4,4,4,3,0,0,0
0,0,5,5,4,4,4,5,5,0,0
0,0,0,3,4,4,4,3,0,0,0
0,0,15,6,3,5,3,6,16,0,0
0,0,0,17,0,5,0,17,0,0,0
0,0,0,0,0,0,0,0,0,0,0
0,0,0,0,0,0,0,0,0,0,0
endlayer

layer
0,0,0,0,0,0,0,0,0,0,0
0,0,0,0,3,3,3,0,0,0,0
0,0,3,3,3,5,3,3,3,0,0
0,0,3,6,6,6,6,6,3,0,0
0,3,3,6,12,6,12,6,3,3,0
0,3,5,6,6,4,6,6,5,3,0
0,3,3,6,12,6,12,6,3,3,0
0,0,3,6,6,6,6,6,3,0,0
0,0,3,3,3,5,3,3,3,0,0
0,0,0,0,3,3,3,0,0,0,0
0,0,0,0,0,0,0,0,0,0,0
endlayer

layer
0,0,0,0,0,0,0,0,0,0,0
0,0,0,0,0,0,0,0,0,0,0
0,0,0,0,0,5,0,0,0,0,0
0,0,0,5,5,5,5,5,0,0,0
0,0,0,5,12,5,12,5,0,0,0
0,0,5,5,5,4,5,5,5,0,0
0,0,0,5,12,5,12,5,0,0,0
0,0,0,5,5,5,5,5,0,0,0
0,0,0,0,0,5,0,0,0,0,0
0,0,0,0,0,0,0,0,0,0,0
0,0,0,0,0,0,0,0,0,0,0
endlayer

layer
0,0,0,0,0,0,9,0,0,0,0
0,0,0,0,0,0,0,0,0,0,0
0,0,0,0,0,0,0,9,0,0,0
0,0,0,5,0,0,0,5,0,0,0
0,0,0,0,12,0,12,0,10,0,0
0,0,0,0,0,4,0,0,0,0,0
0,0,0,0,12,0,12,0,0,0,0
0,0,0,5,0,0,0,5,0,0,0
0,0,0,0,0,0,0,0,0,0,0
0,0,0,0,0,0,0,0,0,0,0
0,0,0,0,0,0,0,0,0,0,0
endlayer

layer
0,0,0,0,0,0,9,0,0,7,0
0,0,0,0,0,0,9,0,0,0,8
0,0,0,0,0,10,0,9,0,0,0
0,0,0,5,5,0,5,5,0,0,0
0,0,0,5,12,12,12,5,10,0,0
0,0,0,0,12,12,12,0,0,0,0
0,0,0,5,12,12,12,5,0,0,0
0,0,0,5,5,0,5,5,0,0,0
0,0,0,0,0,0,0,0,0,0,0
0,0,0,0,0,0,0,0,0,0,0
0,0,0,0,0,0,0,0,0,0,0
endlayer

layer
0,0,0,0,0,0,9,18,18,7,0
0,0,0,0,0,9,9,18,18,18,8
0,0,0,0,0,10,0,9,18,18,18
0,0,0,0,5,5,5,0,0,18,18
0,0,0,5,0,0,11,5,10,10,0
0,0,0,5,3,2,0,5,0,0,0
0,0,0,5,19,3,0,5,0,0,0
0,0,0,0,5,5,5,0,0,0,0
0,0,0,0,0,0,0,0,0,0,0
0,0,0,0,0,0,0,0,0,0,0
0,0,0,0,0,0,0,0,0,0,0
endlayer

layer
0,0,0,0,0,0,18,13,0,0,0
0,0,0,0,0,9,18,18,8,0,0
0,0,0,0,0,10,0,18,0,20,0
0,0,0,0,0,0,11,0,18,18,13
0,0,0,0,0,0,2,11,10,18,18
0,0,0,0,0,19,0,0,0,0,10
0,0,0,0,0,0,0,10,0,10,0
0,0,0,0,0,0,0,0,0,0,0
0,0,0,0,0,0,0,0,0,0,0
0,0,0,0,0,0,0,0,0,0,0
0,0,0,0,0,0,0,0,0,0,0
endlayer

layer
0,0,0,0,0,18,13,13,0,0,0
0,0,0,0,9,18,18,13,0,0,0
0,0,0,0,0,10,18,0,0,8,0
0,0,0,0,0,0,2,12,7,13,13
0,0,0,0,0,0,3,2,18,18,13
0,0,0,0,0,0,0,0,10,18,18
0,0,0,0,0,0,0,10,0,10,0
0,0,0,0,0,0,0,0,0,0,0
0,0,0,0,0,0,0,0,0,0,0
0,0,0,0,0,0,0,0,0,0,0
0,0,0,0,0,0,0,0,0,0,0
endlayer

layer
0,0,0,0,0,18,8,13,13,0,0
0,0,0,0,9,18,8,0,7,0,0
0,0,0,0,9,18,7,0,12,8,13
0,0,0,0,0,9,18,0,0,0,13
0,0,0,0,0,10,10,18,0,0,0
0,0,0,0,0,0,0,9,18,18,18
0,0,0,0,0,0,0,10,0,10,0
0,0,0,0,0,0,0,0,0,0,0
0,0,0,0,0,0,0,0,0,0,0
0,0,0,0,0,0,0,0,0,0,0
0,0,0,0,0,0,0,0,0,0,0
endlayer

layer
0,0,0,0,0,0,0,0,13,13,0
0,0,0,0,0,18,0,0,0,12,13
0,0,0,0,9,18,8,0,0,0,13
0,0,0,0,0,18,18,0,0,0,0
0,0,0,0,0,10,18,18,7,7,0
0,0,0,0,0,0,0,18,18,18,0
0,0,0,0,0,0,0,10,0,10,0
0,0,0,0,0,0,0,0,0,0,0
0,0,0,0,0,0,0,0,0,0,0
0,0,0,0,0,0,0,0,0,0,0
0,0,0,0,0,0,0,0,0,0,0
endlayer

layer
0,0,0,0,0,0,0,0,0,13,21
0,0,0,0,0,0,0,0,13,13,13
0,0,0,0,9,18,8,13,13,13,0
0,0,0,0,0,18,13,13,13,0,0
0,0,0,0,0,9,18,13,7,0,0
0,0,0,0,0,0,0,18,18,0,0
0,0,0,0,0,0,0,0,0,0,0
0,0,0,0,0,0,0,0,0,0,0
0,0,0,0,0,0,0,0,0,0,0
0,0,0,0,0,0,0,0,0,0,0
0,0,0,0,0,0,0,0,0,0,0
endlayer

