weight=3
dimensionsToSpawnIn=overworld
embed_into_distance=1
random_height_offset=0,0
unacceptable_target_blocks=sand,flowing_water,water,flowing_lava,lava,ice,packed_ice,stained_hardened_clay-9,brick_block,double_stone_slab,stonebrick,red_sandstone,red_nether_brick,red_mushroom_block,brown_mushroom_block,planks,cobblestone,end_stone,obsidian,purpur_block,iron_bars,purpur_slab,purpur_pillar,netherrack,soul_sand,quartz_ore,stained_glass,glass
dimensions=20,11,11
allowable_overhang=0
max_leveling=1
leveling_buffer=-1
preventRotation=0
preserve_water=0
preserve_lava=0
uniqueMinDistance=1000
spawnMinDistance=0
spawnMaxDistance=0

rule1=0,100,preserveBlock
rule2=0,100,minecraft:monster_egg-4,monster_egg-2,monster_egg-2,monster_egg-2,monster_egg-3,stonebrick-2,stonebrick-1,stonebrick-0,stonebrick-0,stonebrick-0,stonebrick-2,stonebrick-1,stonebrick-0,stonebrick-0,stonebrick-0
rule3=0,100,chisel:technical-12
rule4=0,100,minecraft:stone_brick_stairs-0
rule5=0,100,minecraft:stone_slab-0
rule6=0,100,minecraft:stone-6
rule7=0,100,ChestGenHook:entities/witch:9-3,ChestGenHook:entities/witch:9-3,ChestGenHook:entities/witch:9-3,ChestGenHook:entities/witch:9-3,ChestGenHook:entities/witch:9-3,ChestGenHook:entities/zombie_pigman:9-3,ChestGenHook:entities/zombie_pigman:9-3,ChestGenHook:entities/zombie_pigman:9-3,ChestGenHook:entities/zombie_pigman:9-3,ChestGenHook:entities/zombie_pigman:9-3,IInventory;minecraft:chest;minecraft:redstone_torch#3#0#0+minecraft:redstone#1#0#2+minecraft:repeater#1#0#3+minecraft:gold_nugget#1#0#4+minecraft:stone_button#1#0#5+minecraft:gold_nugget#1#0#6+minecraft:stone_button#1#0#10+minecraft:gold_nugget#1#0#11+minecraft:redstone#1#0#13+minecraft:stone_button#1#0#14+minecraft:web#1#0#15+minecraft:redstone_torch#3#0#16+minecraft:redstone#1#0#17+minecraft:light_weighted_pressure_plate#1#0#18+minecraft:redstone#1#0#19+minecraft:stone_button#1#0#21+minecraft:redstone_torch#1#0#22+minecraft:repeater#1#0#23+minecraft:redstone#1#0#25+minecraft:gold_nugget#1#0#26-3,IInventory;minecraft:chest;minecraft:web#1#0#0+minecraft:redstone_torch#2#0#1+minecraft:gold_nugget#1#0#3+minecraft:redstone#1#0#5+minecraft:redstone#1#0#6+minecraft:stone_button#1#0#8+minecraft:stone_button#1#0#10+minecraft:gold_nugget#1#0#11+minecraft:repeater#1#0#12+minecraft:gold_nugget#1#0#14+minecraft:redstone_torch#3#0#16+minecraft:gold_nugget#1#0#18+minecraft:comparator#1#0#19+minecraft:redstone#1#0#21+minecraft:redstone_torch#1#0#22+minecraft:stone_button#1#0#23+minecraft:repeater#1#0#24+minecraft:light_weighted_pressure_plate#1#0#26-3,IInventory;minecraft:chest;minecraft:repeater#1#0#0+minecraft:light_weighted_pressure_plate#1#0#2+minecraft:redstone#1#0#3+minecraft:gold_nugget#1#0#5+minecraft:redstone_torch#1#0#7+minecraft:repeater#1#0#8+minecraft:stone_button#1#0#9+minecraft:redstone#1#0#10+minecraft:redstone_torch#1#0#12+minecraft:stone_button#1#0#13+minecraft:web#1#0#14+minecraft:gold_nugget#1#0#15+minecraft:gold_nugget#1#0#18+minecraft:redstone_torch#1#0#20+minecraft:gold_nugget#1#0#21+minecraft:redstone#1#0#22+minecraft:redstone_torch#2#0#24+minecraft:redstone#1#0#25+minecraft:stone_button#1#0#26-3,IInventory;minecraft:chest;minecraft:redstone#1#0#0+minecraft:repeater#1#0#2+minecraft:redstone_torch#1#0#3+minecraft:gold_nugget#1#0#5+minecraft:gold_nugget#1#0#6+minecraft:redstone#1#0#7+minecraft:stone_button#1#0#9+minecraft:redstone#1#0#10+minecraft:gold_nugget#1#0#12+minecraft:comparator#1#0#13+minecraft:stone_button#1#0#14+minecraft:repeater#1#0#16+minecraft:web#1#0#17+minecraft:redstone_torch#3#0#18+minecraft:stone_button#1#0#20+minecraft:redstone#1#0#21+minecraft:light_weighted_pressure_plate#1#0#22+minecraft:redstone_torch#1#0#24+minecraft:gold_nugget#1#0#26-3,IInventory;minecraft:chest;minecraft:redstone#1#0#0+minecraft:redstone#1#0#1+minecraft:comparator#1#0#3+minecraft:redstone_torch#1#0#6+minecraft:light_weighted_pressure_plate#1#0#8+minecraft:redstone_torch#1#0#10+minecraft:gold_nugget#1#0#11+minecraft:stone_button#1#0#13+minecraft:stone_button#1#0#14+minecraft:repeater#1#0#16+minecraft:gold_nugget#1#0#18+minecraft:repeater#1#0#19+minecraft:light_weighted_pressure_plate#1#0#21+minecraft:redstone_torch#3#0#22+minecraft:web#1#0#23+minecraft:redstone#1#0#25-3,air,air,air,air,air,air,air,air,air,air,air,air,air,air,air,air,air,air,air,air,air,air,air,air,air,air,air,air
rule8=0,100,minecraft:stone_brick_stairs-2
rule9=0,100,minecraft:stone_brick_stairs-3
rule10=0,100,MobSpawner:Zombie,MobSpawner:Silverfish
rule11=0,100,minecraft:iron_door-1
rule12=0,100,minecraft:stone_brick_stairs-1
rule13=0,100,minecraft:iron_door-9
rule14=0,100,chisel:factory-1
rule15=0,100,minecraft:vine-8
rule16=0,100,minecraft:vine-9
rule17=0,100,minecraft:vine-12
rule18=0,100,minecraft:vine-1
rule19=0,100,minecraft:vine-4
rule20=0,100,minecraft:vine-2
rule21=0,100,minecraft:stone_slab-5
rule22=0,100,minecraft:cobblestone_wall-0
rule23=0,100,minecraft:stone_brick_stairs-4
rule24=0,100,minecraft:stone_brick_stairs-6
rule25=0,100,minecraft:stone_brick_stairs-7
rule26=0,100,minecraft:stone_brick_stairs-5
rule27=0,100,minecraft:stone_slab-8
rule28=0,100,chisel:blocktin-4,chisel:technical1-0

layer
1,1,1,1,2,2,2,1,1,1,1
1,3,3,2,2,2,2,2,3,3,1
1,3,2,2,2,2,2,2,2,3,1
1,2,2,2,2,2,2,2,2,2,1
2,2,2,2,2,2,2,2,2,2,2
2,2,2,2,2,2,2,2,2,2,2
2,2,2,2,2,2,2,2,2,2,2
1,2,2,2,2,2,2,2,2,2,1
1,3,2,2,2,2,2,2,2,3,1
1,3,3,2,2,2,2,2,3,3,1
1,1,1,1,2,2,2,1,1,1,1
endlayer

layer
1,1,1,1,4,1,4,1,1,1,1
1,1,1,5,6,6,6,5,1,1,1
1,1,6,6,6,6,6,6,6,1,1
1,5,6,6,0,0,7,6,6,5,1
9,6,6,0,0,0,0,0,6,6,8
0,11,0,0,0,10,0,0,6,6,1
9,6,6,0,0,0,0,0,6,6,8
1,5,6,6,0,0,7,6,6,5,1
1,1,6,6,6,6,6,6,6,1,1
1,1,1,5,6,6,6,5,1,1,1
1,1,1,1,12,1,12,1,1,1,1
endlayer

layer
1,1,1,1,1,1,1,1,1,1,1
1,1,1,1,6,6,6,1,1,1,1
1,1,5,6,6,6,6,6,5,1,1
1,1,6,6,0,0,0,6,6,1,1
1,6,6,0,0,0,0,0,6,6,1
1,13,0,0,0,0,0,0,6,6,1
1,6,6,0,0,0,0,0,6,6,1
1,1,6,6,0,0,0,6,6,1,1
1,1,5,6,6,6,6,6,5,1,1
1,1,1,1,6,6,6,1,1,1,1
1,1,1,1,1,1,1,1,1,1,1
endlayer

layer
1,1,1,1,0,0,0,1,1,1,1
1,1,0,0,4,5,4,0,0,1,1
1,0,5,5,14,14,14,5,5,0,1
1,0,5,14,0,0,0,14,5,0,1
0,9,14,0,0,0,0,0,14,8,0
0,5,14,0,0,0,0,0,14,5,0
0,9,14,0,0,0,0,0,14,8,0
1,0,5,14,0,0,0,14,5,0,1
1,0,5,5,14,14,14,5,5,0,1
1,1,0,0,12,5,12,0,0,1,1
1,1,1,1,0,0,0,1,1,1,1
endlayer

layer
1,0,0,0,0,0,0,0,0,0,1
0,0,0,0,15,15,0,0,0,0,0
0,0,0,17,14,14,14,16,0,0,0
0,0,15,14,0,0,0,14,18,0,0
0,19,14,0,0,0,0,0,14,18,0
0,0,14,0,0,0,0,0,14,18,0
0,19,14,0,0,0,0,0,14,18,0
0,0,20,14,0,0,0,14,20,0,0
0,0,0,20,14,14,14,20,0,0,0
0,0,0,0,20,0,20,0,0,0,0
1,0,0,0,0,0,0,0,0,0,1
endlayer

layer
0,0,0,0,0,0,0,0,0,0,0
0,0,0,0,15,15,15,0,0,0,0
0,0,0,17,14,14,14,18,0,0,0
0,0,15,14,0,0,0,14,15,0,0
0,19,14,0,0,0,0,0,14,18,0
0,19,14,0,0,0,0,0,14,18,0
0,19,14,0,0,0,0,0,14,18,0
0,0,20,14,0,0,0,14,20,0,0
0,0,0,20,14,14,14,0,0,0,0
0,0,0,0,20,20,20,0,0,0,0
0,0,0,0,0,0,0,0,0,0,0
endlayer

layer
0,0,0,0,0,0,0,0,0,0,0
0,0,0,0,0,15,15,0,0,0,0
0,0,0,0,21,21,21,0,0,0,0
0,0,19,22,14,14,14,22,15,0,0
0,19,21,14,0,0,0,14,21,0,0
0,0,21,14,0,0,0,14,21,0,0
0,19,21,14,0,0,0,14,21,0,0
0,0,20,22,14,14,14,22,0,0,0
0,0,0,0,21,21,21,0,0,0,0
0,0,0,0,0,20,0,0,0,0,0
0,0,0,0,0,0,0,0,0,0,0
endlayer

layer
0,0,0,0,0,0,0,15,0,0,0
0,0,0,0,15,15,15,0,0,0,0
0,0,0,0,23,23,23,18,0,0,0
0,0,19,22,14,14,14,22,15,0,0
0,19,25,14,0,0,0,14,24,0,0
0,0,25,14,0,0,0,14,24,0,0
0,19,25,14,0,0,0,14,24,0,0
0,0,20,22,14,14,14,22,0,0,0
0,0,0,19,26,26,26,0,0,0,0
0,0,0,0,0,20,0,0,0,0,0
0,0,0,0,0,0,0,0,0,0,0
endlayer

layer
0,0,0,0,0,0,0,15,0,0,0
0,0,0,0,15,15,15,0,0,0,0
15,0,0,15,3,3,3,18,0,0,0
0,0,19,3,22,14,22,3,15,0,0
0,19,3,22,14,14,14,22,3,0,0
0,0,3,14,14,14,14,14,3,18,0
0,19,3,22,14,14,14,22,3,0,0
0,0,20,3,22,14,22,3,20,0,0
0,0,0,19,3,3,3,20,0,0,0
0,0,0,0,20,20,0,0,0,0,0
0,0,0,0,0,0,0,0,0,0,0
endlayer

layer
0,0,0,0,0,0,0,15,0,0,0
0,0,0,0,0,0,0,0,0,0,0
15,0,0,0,27,27,27,0,0,0,0
19,0,0,27,22,23,22,27,0,0,0
0,0,27,22,14,14,14,22,27,0,0
0,0,27,25,14,14,14,24,27,0,0
0,0,27,22,14,14,14,22,27,0,0
19,0,0,27,22,26,22,27,0,0,0
0,0,0,0,27,27,27,0,0,0,18
0,0,0,0,0,0,0,0,0,0,0
0,0,0,0,0,0,0,0,0,0,0
endlayer

layer
0,15,0,0,0,0,0,15,0,0,0
0,0,0,0,25,23,24,0,0,0,0
15,0,0,0,6,6,6,23,0,0,0
19,0,0,6,6,6,6,6,24,0,0
0,23,6,6,6,12,6,6,6,23,0
0,25,6,6,8,21,9,6,6,24,0
0,26,6,6,6,4,6,6,6,26,0
19,0,25,6,6,6,6,6,24,0,0
0,0,0,26,6,6,6,26,0,0,18
0,0,0,0,25,26,24,0,0,0,0
0,0,0,20,0,0,0,0,0,0,0
endlayer

layer
0,15,15,15,25,6,24,15,0,0,0
19,0,25,6,6,6,6,6,24,0,0
15,23,6,8,12,12,12,9,6,23,0
19,6,12,21,0,0,0,21,12,6,18
23,6,8,0,0,0,0,0,9,6,23
6,6,8,0,0,0,0,0,9,6,6
26,6,8,0,0,0,0,0,9,6,26
19,6,4,21,0,0,0,21,4,6,18
0,26,6,8,4,4,4,9,6,26,18
19,0,25,6,6,6,6,6,24,0,0
0,0,0,20,25,6,24,0,0,20,0
endlayer

layer
0,15,15,6,6,6,6,6,15,0,0
19,6,6,5,5,5,5,5,6,6,18
15,6,22,0,0,0,0,0,22,6,15
6,5,0,0,0,0,0,0,0,5,6
6,5,0,0,0,0,0,0,0,5,6
6,5,0,0,0,0,0,0,0,5,6
6,5,0,0,0,0,0,0,0,5,6
6,5,0,0,0,0,0,0,0,5,6
19,6,22,0,0,0,0,0,22,6,18
19,6,6,5,5,5,5,5,6,6,0
0,20,19,6,6,6,6,6,18,20,0
endlayer

layer
0,0,0,0,0,0,0,0,0,0,0
0,0,0,0,0,0,0,0,0,0,0
0,0,22,0,0,0,0,0,22,0,0
0,0,0,0,0,0,0,0,0,0,0
0,0,0,0,0,0,0,0,0,0,0
0,0,0,0,0,0,0,0,0,0,0
0,0,0,0,0,0,0,0,0,0,0
0,0,0,0,0,0,0,0,0,0,0
0,0,22,0,0,0,0,0,22,0,0
0,0,0,0,0,0,0,0,0,0,0
0,0,0,0,0,0,0,0,0,0,0
endlayer

layer
0,0,0,0,0,0,0,0,0,0,0
0,0,0,0,0,0,0,0,0,0,0
0,0,22,22,0,0,0,22,22,0,0
0,0,0,22,0,0,0,22,0,0,0
0,0,0,0,0,0,0,0,0,0,0
0,0,0,0,0,0,0,0,0,0,0
0,0,0,0,0,0,0,0,0,0,0
0,0,0,22,0,0,0,22,0,0,0
0,0,22,22,0,0,0,22,22,0,0
0,0,0,0,0,0,0,0,0,0,0
0,0,0,0,0,0,0,0,0,0,0
endlayer

layer
0,0,0,0,0,0,0,0,0,0,0
0,0,0,0,0,0,0,0,0,0,0
0,0,0,0,0,0,0,0,0,0,0
0,0,0,22,0,0,0,22,0,0,0
0,0,0,0,0,0,0,0,0,0,0
0,0,0,0,0,0,0,0,0,0,0
0,0,0,0,0,0,0,0,0,0,0
0,0,0,22,0,0,0,22,0,0,0
0,0,0,0,0,0,0,0,0,0,0
0,0,0,0,0,0,0,0,0,0,0
0,0,0,0,0,0,0,0,0,0,0
endlayer

layer
0,0,0,0,0,0,0,0,0,0,0
0,0,0,0,0,0,0,0,0,0,0
0,0,0,0,0,0,0,0,0,0,0
0,0,0,22,22,0,22,22,0,0,0
0,0,0,0,22,0,22,0,0,0,0
0,0,0,0,0,0,0,0,0,0,0
0,0,0,0,22,0,22,0,0,0,0
0,0,0,22,22,0,22,22,0,0,0
0,0,0,0,0,0,0,0,0,0,0
0,0,0,0,0,0,0,0,0,0,0
0,0,0,0,0,0,0,0,0,0,0
endlayer

layer
0,0,0,0,0,0,0,0,0,0,0
0,0,0,0,0,0,0,0,0,0,0
0,0,0,0,0,0,0,0,0,0,0
0,0,0,0,0,0,0,0,0,0,0
0,0,0,0,22,23,22,0,0,0,0
0,0,0,0,22,22,22,0,0,0,0
0,0,0,0,22,0,22,0,0,0,0
0,0,0,0,0,0,0,0,0,0,0
0,0,0,0,0,0,0,0,0,0,0
0,0,0,0,0,0,0,0,0,0,0
0,0,0,0,0,0,0,0,0,0,0
endlayer

layer
0,0,0,0,0,0,0,0,0,0,0
0,0,0,0,0,0,0,0,0,0,0
0,0,0,0,0,0,0,0,0,0,0
0,0,0,0,0,0,0,0,0,0,0
0,0,0,0,0,4,0,0,0,0,0
0,0,0,0,19,28,18,0,0,0,0
0,0,0,0,0,20,0,0,0,0,0
0,0,0,0,0,0,0,0,0,0,0
0,0,0,0,0,0,0,0,0,0,0
0,0,0,0,0,0,0,0,0,0,0
0,0,0,0,0,0,0,0,0,0,0
endlayer

layer
0,0,0,0,0,0,0,0,0,0,0
0,0,0,0,0,0,0,0,0,0,0
0,0,0,0,0,0,0,0,0,0,0
0,0,0,0,0,0,0,0,0,0,0
0,0,0,0,0,0,0,0,0,0,0
0,0,0,0,0,12,0,0,0,0,0
0,0,0,0,0,0,0,0,0,0,0
0,0,0,0,0,0,0,0,0,0,0
0,0,0,0,0,0,0,0,0,0,0
0,0,0,0,0,0,0,0,0,0,0
0,0,0,0,0,0,0,0,0,0,0
endlayer

