weight=2
dimensionsToSpawnIn=overworld
embed_into_distance=1
random_height_offset=0,0
unacceptable_target_blocks=flowing_water,water,flowing_lava,lava,ice,packed_ice,stained_hardened_clay-9,brick_block,double_stone_slab,stonebrick,red_sandstone,red_nether_brick,red_mushroom_block,brown_mushroom_block,planks,cobblestone,end_stone,obsidian,purpur_block,iron_bars,purpur_slab,purpur_pillar,netherrack,soul_sand,quartz_ore,stained_glass,glass
dimensions=5,9,11
allowable_overhang=0
max_leveling=1
leveling_buffer=-1
preventRotation=1
preserve_water=0
preserve_lava=0
uniqueMinDistance=0
spawnMinDistance=0
spawnMaxDistance=0

rule1=0,100,preserveBlock
rule2=0,100,chisel:technical-15
rule3=0,100,minecraft:dark_oak_fence-0
rule4=0,100,minecraft:quartz_stairs-1
rule5=0,100,minecraft:daylight_detector_inverted-0
rule6=0,100,minecraft:stone_slab-7

layer
1,1,1,1,1,1,1,1,1,1,1
2,1,1,1,1,1,1,1,1,1,2
1,1,1,1,1,1,1,1,1,1,1
1,1,1,1,1,1,1,1,1,1,1
2,1,1,1,1,1,1,1,1,1,2
1,1,1,1,1,1,1,1,1,1,1
1,1,1,1,1,1,1,1,1,1,1
2,1,1,1,1,1,1,1,1,1,2
1,1,1,1,1,1,1,1,1,1,1
endlayer

layer
1,1,1,1,1,1,1,1,1,1,1
3,1,1,1,1,1,1,1,1,1,3
1,1,1,1,1,1,1,1,1,1,1
1,1,1,1,1,1,1,1,1,1,1
3,1,1,1,1,1,1,1,1,1,3
1,1,1,1,1,1,1,1,1,1,1
1,1,1,1,1,1,1,1,1,1,1
3,1,1,1,1,1,1,1,1,1,3
1,1,1,1,1,1,1,1,1,1,1
endlayer

layer
0,0,0,0,0,0,0,0,0,0,0
3,0,0,0,0,0,0,0,0,0,3
0,0,0,0,0,0,0,0,0,0,0
0,0,0,0,0,0,0,0,0,0,0
3,0,0,0,0,0,0,0,0,0,3
0,0,0,0,0,0,0,0,0,0,0
4,5,5,5,5,5,5,5,5,5,4
6,5,5,5,5,5,5,5,5,5,6
6,5,5,5,5,5,5,5,5,5,6
endlayer

layer
0,0,0,0,0,0,0,0,0,0,0
3,0,0,0,0,0,0,0,0,0,3
0,0,0,0,0,0,0,0,0,0,0
4,5,5,5,5,5,5,5,5,5,4
6,5,5,5,5,5,5,5,5,5,6
6,5,5,5,5,5,5,5,5,5,6
0,0,0,0,0,0,0,0,0,0,0
0,0,0,0,0,0,0,0,0,0,0
0,0,0,0,0,0,0,0,0,0,0
endlayer

layer
6,5,5,5,5,5,5,5,5,5,6
6,5,5,5,5,5,5,5,5,5,6
6,5,5,5,5,5,5,5,5,5,6
0,0,0,0,0,0,0,0,0,0,0
0,0,0,0,0,0,0,0,0,0,0
0,0,0,0,0,0,0,0,0,0,0
0,0,0,0,0,0,0,0,0,0,0
0,0,0,0,0,0,0,0,0,0,0
0,0,0,0,0,0,0,0,0,0,0
endlayer

